Workbook
Name nonparticipating_forecastzone_scale_factor: #REF!
Name nonparticipating_forecastzone_scale_factor: #REF!
Name nonparticipating_forecastzone_scale_factor: 'Energy Usage'!#REF!
Name Space_Function: Data!$A$2:$A$76

Sheet Notes
A1: Data Sources
A2: Dataset | B2: Dodge 2023
A3: Prototype | B3: CEC prototype (CBECC 2022.3.1) | C3: https://bees.noresco.com/software2022.html
B4: TRC Multifamily Prototypes study (2019) | C4: https://title24stakeholders.com/wp-content/uploads/2019/06/SCE-MFModeling_MultifamilyPrototypesReport_2019-06-07_clean.pdf
A5: Codes | B5: Title 24, part 6 (1986, 2001, 2007, 2013, 2022, 2025)
B6: ASHRAE 90.1 (2022)
B7: ASHRAE Handbook of Fundamentals (Ch. 15 Tables 4 and 10)
B8: CFR Title 10 (2010, 2024)
A9: Others | B9: 2019 Outdoor Lighting CASE Report | C9: https://title24stakeholders.com/wp-content/uploads/2016/10/T24-2019-CASE-Study-Results-Report-Outdoor-Sources_Final_with-Attachments.pdf
B10: PNNL 20405, 2011 | C10: https://www.pnnl.gov/main/publications/external/technical_reports/PNNL-20405.pdf
B11: 2024 CASE Report: A Comprehensive, High Efficiency Solution for Water Heating in Multifamily Buildings | C11: https://www.energy.ca.gov/sites/default/files/2024-06/CEC-500-2024-054.pdf
B12: 2022 CASE Report: Multifamily Domestic Hot Water Distribution | C12: https://title24stakeholders.com/wp-content/uploads/2020/09/2022_T24_Final-CASE-Report-MF-DHW-Dist.pdf
B13: Maguire & Roberts 2020 (NREL/CP-5500-71633): Deriving Simulation Parameters for Storage-Type Water Heaters Using Ratings Data Produced from the Uniform Energy Factor Test Procedure | C13: https://docs.nrel.gov/docs/fy21osti/71633.pdf
B14: OpenStudio-HPXML waterheater.rb (tank UA / Maguire method) | C14: https://github.com/NREL/OpenStudio-HPXML/blob/master/HPXMLtoOpenStudio/resources/waterheater.rb
A17: Construction Rate
A30: Notes

Sheet Prototype
A1: NORESCO, Updated September 2026
A2: ApartmentMidRise
A3: Characteristic | B3: Value | C3: Data Sources
A4: Building Type | B4: Mid-Rise Apartment
A5: Building Category | B5: Nonresidential
A6: Version | B6: v2-0
A7: Vintages | B7: 4 Vintages: Pre-1978 , 1978-1997 ,1998-2007 , 2008-2018 New Construction (2019+) | C7: Following the vintage‑bin analysis performed for the nonresidential prototypes. A summary of the findings is presented in the following paper, with a link provided in the Notes tab: Yousefi, F., Athalye, R. (2025). “Determining Vintage Bins for Prototype Development: An Analysis of California Commercial Buildings.” ASHRAE Annual Conference.
A8: Shape | C8: CEC Prototype model TRC Multifamily Prototypes study (2019) https://title24stakeholders.com/wp-content/uploads/2019/06/SCE-MFModeling_MultifamilyPrototypesReport_2019-06-07_clean.pdf
A9: Total Floor Area (ft2) | B9: =Zones!J40 -> 141013.76 | C9: CEC Prototype model TRC Multifamily Prototypes study (2019)
A10: Aspect Ratio | B10: =180/155 -> 1.1612903
A11: Number of Floors | B11: 5 above-ground floors including one underground parking garage (180 ft x 155 ft)
A12: Roof type | B12: Flat roof
A13: WWR (above grade) | B13: South: 22.0%, East: 22.0%, North: 22.0%, West: 22.0% Total 22.0%
A14: Window dimensions | B14: 5 * 3
A15: Shading Geometry | B15: -
A16: Floor to floor height (feet) | B16: Residential: 10 Non-residential: 10 Parking: 15
A17: Floor to ceiling height (feet) | B17: Residential: 9 Non-residential: 10 Parking: 14
A18: Glazing sill height (feet) | B18: 3.1 ft (in first floor), 2.95 ft. (in upper floors)
A19: Number of dwelling units | B19: 88 | C19: 22 per residential floor × 4 floors. Mix per floor from TRC/plans: 2 studio, 10 one-bed, 8 two-bed, 2 three-bed.
A22: Above grade wall area (ft²) | B22: 42304.13
A23: Gross wall area (ft²) | B23: 51685.04
A24: Roof area (ft²) | B24: 27902.72
A25: Underground Gross Wall Area (ft²) | B25: =B23-B22 -> 9380.91

Sheet Zones
A1: ="Proposed Layout - "&Prototype!A2 -> Proposed Layout - ApartmentMidRise
A2: Space Type [Primarily from: T24, 2022 Appendix 5.4A] - See Notes column | B2: Space/Thermal Zone | C2: Res/NR | D2: Schedule Category | E2: No. of Dwelling Units | F2: Dwelling Unit Type | G2: Thermal Zone (HVAC Zone) | H2: Conditioned [Y/N] | I2: Area Fraction | J2: Area (ft²) | K2: Volume (ft³) | L2: Multipliers | M2: People | N2: People (persons/1,000 ft²) | O2: Notes | R2: Spaces and Zoning layout
A3: Convention, Conference, Multipurpose and Meeting Area | B3: F1 BUSINESS CENTER | C3: NR | D3: ResidentialCommon | E3: NA | F3: NA | G3: AHU1 | H3: Y | I3: =J3*L3/$J$40 -> 0.002553226 | J3: 360.04 | K3: 3600.53 | L3: 1 | M3: =N3*J3*L3/1000 -> 24.003867 | N3: 66.67 | O3: Dwellings: occupants/unit — ACM 2025 §6.5.4 Max(Nbr+1, 2) Parking garage: 0 (unoccupied for internal loads; App 5.4A 5/1000 not used) Other nonresidential: persons/1,000 ft² — App 5.4A / Table 120.1-A
A4: Corridor Area | B4: F1 CORRIDOR | C4: NR | D4: ResidentialCommon | E4: NA | F4: NA | G4: AHU2 | H4: Y | I4: =J4*L4/$J$40 -> 0.01361704 | J4: 1920.19 | K4: 19202.81 | L4: 1 | M4: =N4*J4*L4/1000 -> 19.2019 | N4: 10
A5: Exercise/Fitness Center and Gymnasium Areas | B5: F1 FITNESS CENTER | C5: NR | D5: ResidentialCommon | E5: NA | F5: NA | G5: AHU3 | H5: Y | I5: =J5*L5/$J$40 -> 0.0063829941 | J5: 900.09 | K5: 9001.32 | L5: 1 | M5: =N5*J5*L5/1000 -> 18.0018 | N5: 20
A6: Office Area (>250 square feet) | B6: F1 LEASING OFFICE | C6: NR | D6: ResidentialCommon | E6: NA | F6: NA | G6: AHU4 | H6: Y | I6: =J6*L6/$J$40 -> 0.0024467825 | J6: 345.03 | K6: 3450.51 | L6: 1 | M6: =N6*J6*L6/1000 -> 3.4503 | N6: 10
A7: Lobby, Main Entry | B7: F1 LOUNGE | C7: NR | D7: ResidentialCommon | E7: NA | F7: NA | G7: AHU5 | H7: Y | I7: =J7*L7/$J$40 -> 0.007446791 | J7: 1050.1 | K7: 10501.54 | L7: 1 | M7: =N7*J7*L7/1000 -> 70.04167 | N7: 66.7
A8: Electrical, Mechanical, Telephone Rooms | B8: F1 MECHANICAL ROOM | C8: NR | D8: ResidentialCommon | E8: NA | F8: NA | G8: AHU6 | H8: Y | I8: =J8*L8/$J$40 -> 0.0030638145 | J8: 432.04 | K8: 4320.63 | L8: 1 | M8: =N8*J8*L8/1000 -> 1.29612 | N8: 3
A9: Retail Sales Area (Retail Merchandise Sales) | B9: F1 RETAIL N-NW | C9: NR | D9: Retail | E9: NA | F9: NA | G9: AHU7 | H9: Y | I9: =J9*L9/$J$40 -> 0.04244678 | J9: 5985.58 | K9: 59858.76 | L9: 1 | M9: =N9*J9*L9/1000 -> 99.759667 | N9: 16.666667
A10: Retail Sales Area (Retail Merchandise Sales) | B10: F1 RETAIL NE | C10: NR | D10: Retail | E10: NA | F10: NA | G10: AHU8 | H10: Y | I10: =J10*L10/$J$40 -> 0.030638287 | J10: 4320.42 | K10: 43206.32 | L10: 1 | M10: =N10*J10*L10/1000 -> 72.007 | N10: 16.666667
A11: Retail Sales Area (Retail Merchandise Sales) | B11: F1 RETAIL SE | C11: NR | D11: Retail | E11: NA | F11: NA | G11: AHU9 | H11: Y | I11: =J11*L11/$J$40 -> 0.020425524 | J11: 2880.28 | K11: 28804.22 | L11: 1 | M11: =N11*J11*L11/1000 -> 48.004667 | N11: 16.666667
A12: Retail Sales Area (Retail Merchandise Sales) | B12: F1 RETAIL SW | C12: NR | D12: Retail | E12: NA | F12: NA | G12: AHU10 | H12: Y | I12: =J12*L12/$J$40 -> 0.03140424 | J12: 4428.43 | K12: 44286.48 | L12: 1 | M12: =N12*J12*L12/1000 -> 73.807167 | N12: 16.666667
A13: Residential Living Spaces | B13: F2-4 1-BED CORE EAST | C13: Res | D13: ResidentialLiving | E13: 6 | F13: 1-Bed Type | G13: AHU11 | H13: Y | I13: =J13*L13/$J$40 -> 0.030638287 | J13: 1440.14 | K13: 14402.11 | L13: 3 | M13: =E13*N13 -> 12 | N13: =MAX(2,1+IF(ISNUMBER(SEARCH("Studio",F13)),0,IF(ISNUMBER(SEARCH("3-Bed",F13)),3,IF(ISNUMBER(SEARCH("2-Bed",F13)),2,1)))) -> 2
A14: Residential Living Spaces | B14: F2-4 1-BED CORE N | C14: Res | D14: ResidentialLiving | E14: 3 | F14: 1-Bed Type | G14: AHU12 | H14: Y | I14: =J14*L14/$J$40 -> 0.015319143 | J14: 720.07 | K14: 7201.05 | L14: 3 | M14: =E14*N14 -> 6 | N14: =MAX(2,1+IF(ISNUMBER(SEARCH("Studio",F14)),0,IF(ISNUMBER(SEARCH("3-Bed",F14)),3,IF(ISNUMBER(SEARCH("2-Bed",F14)),2,1)))) -> 2
A15: Residential Living Spaces | B15: F2-4 1-BED CORE WEST | C15: Res | D15: ResidentialLiving | E15: 6 | F15: 1-Bed Type | G15: AHU13 | H15: Y | I15: =J15*L15/$J$40 -> 0.030638287 | J15: 1440.14 | K15: 14402.11 | L15: 3 | M15: =E15*N15 -> 12 | N15: =MAX(2,1+IF(ISNUMBER(SEARCH("Studio",F15)),0,IF(ISNUMBER(SEARCH("3-Bed",F15)),3,IF(ISNUMBER(SEARCH("2-Bed",F15)),2,1)))) -> 2
A16: Residential Living Spaces | B16: F2-4 1-BED NORTH | C16: Res | D16: ResidentialLiving | E16: 15 | F16: 1-Bed Type | G16: AHU14 | H16: Y | I16: =J16*L16/$J$40 -> 0.079148872 | J16: 3720.36 | K16: 37205.45 | L16: 3 | M16: =E16*N16 -> 30 | N16: =MAX(2,1+IF(ISNUMBER(SEARCH("Studio",F16)),0,IF(ISNUMBER(SEARCH("3-Bed",F16)),3,IF(ISNUMBER(SEARCH("2-Bed",F16)),2,1)))) -> 2
A17: Residential Living Spaces | B17: F2-4 2-BED CORE NE-NW | C17: Res | D17: ResidentialLiving | E17: 6 | F17: 2-Bed Type | G17: AHU15 | H17: Y | I17: =J17*L17/$J$40 -> 0.04595743 | J17: 2160.21 | K17: 21603.16 | L17: 3 | M17: =E17*N17 -> 18 | N17: =MAX(2,1+IF(ISNUMBER(SEARCH("Studio",F17)),0,IF(ISNUMBER(SEARCH("3-Bed",F17)),3,IF(ISNUMBER(SEARCH("2-Bed",F17)),2,1)))) -> 3
A18: Residential Living Spaces | B18: F2-4 2-BED EAST | C18: Res | D18: ResidentialLiving | E18: 9 | F18: 2-Bed Type | G18: AHU16 | H18: Y | I18: =J18*L18/$J$40 -> 0.068936251 | J18: 3240.32 | K18: 32404.74 | L18: 3 | M18: =E18*N18 -> 27 | N18: =MAX(2,1+IF(ISNUMBER(SEARCH("Studio",F18)),0,IF(ISNUMBER(SEARCH("3-Bed",F18)),3,IF(ISNUMBER(SEARCH("2-Bed",F18)),2,1)))) -> 3
A19: Residential Living Spaces | B19: F2-4 2-BED WEST | C19: Res | D19: ResidentialLiving | E19: 9 | F19: 2-Bed Type | G19: AHU17 | H19: Y | I19: =J19*L19/$J$40 -> 0.068936251 | J19: 3240.32 | K19: 32404.74 | L19: 3 | M19: =E19*N19 -> 27 | N19: =MAX(2,1+IF(ISNUMBER(SEARCH("Studio",F19)),0,IF(ISNUMBER(SEARCH("3-Bed",F19)),3,IF(ISNUMBER(SEARCH("2-Bed",F19)),2,1)))) -> 3
A20: Residential Living Spaces | B20: F2-4 3-BED NE | C20: Res | D20: ResidentialLiving | E20: 3 | F20: 3-Bed Type | G20: AHU18 | H20: Y | I20: =J20*L20/$J$40 -> 0.030000051 | J20: 1410.14 | K20: 14102.06 | L20: 3 | M20: =E20*N20 -> 12 | N20: =MAX(2,1+IF(ISNUMBER(SEARCH("Studio",F20)),0,IF(ISNUMBER(SEARCH("3-Bed",F20)),3,IF(ISNUMBER(SEARCH("2-Bed",F20)),2,1)))) -> 4
A21: Residential Living Spaces | B21: F2-4 3-BED NW | C21: Res | D21: ResidentialLiving | E21: 3 | F21: 3-Bed Type | G21: AHU19 | H21: Y | I21: =J21*L21/$J$40 -> 0.030000051 | J21: 1410.14 | K21: 14102.06 | L21: 3 | M21: =E21*N21 -> 12 | N21: =MAX(2,1+IF(ISNUMBER(SEARCH("Studio",F21)),0,IF(ISNUMBER(SEARCH("3-Bed",F21)),3,IF(ISNUMBER(SEARCH("2-Bed",F21)),2,1)))) -> 4
A22: Corridor Area | B22: F2-4 CORRIDOR | C22: NR | D22: ResidentialCommon | E22: NA | F22: NA | G22: AHU20 | H22: Y | I22: =J22*L22/$J$40 -> 0.054893579 | J22: 2580.25 | K22: 25803.78 | L22: 3 | M22: =N22*J22*L22/1000 -> 77.4075 | N22: 10
A23: Laundry Area | B23: F2-4 LAUNDRY | C23: NR | D23: ResidentialCommon | E23: NA | F23: NA | G23: AHU21 | H23: Y | I23: =J23*L23/$J$40 -> 0.003829839 | J23: 180.02 | K23: 1800.26 | L23: 3 | M23: =N23*J23*L23/1000 -> 5.4006 | N23: 10
A24: Residential Living Spaces | B24: F2-4 STUDIO SE | C24: Res | D24: ResidentialLiving | E24: 3 | F24: Studio Type | G24: AHU22 | H24: Y | I24: =J24*L24/$J$40 -> 0.011489304 | J24: 540.05 | K24: 5400.79 | L24: 3 | M24: =E24*N24 -> 6 | N24: =MAX(2,1+IF(ISNUMBER(SEARCH("Studio",F24)),0,IF(ISNUMBER(SEARCH("3-Bed",F24)),3,IF(ISNUMBER(SEARCH("2-Bed",F24)),2,1)))) -> 2
A25: Residential Living Spaces | B25: F2-4 STUDIO SW | C25: Res | D25: ResidentialLiving | E25: 3 | F25: Studio Type | G25: AHU23 | H25: Y | I25: =J25*L25/$J$40 -> 0.011489304 | J25: 540.05 | K25: 5400.79 | L25: 3 | M25: =E25*N25 -> 6 | N25: =MAX(2,1+IF(ISNUMBER(SEARCH("Studio",F25)),0,IF(ISNUMBER(SEARCH("3-Bed",F25)),3,IF(ISNUMBER(SEARCH("2-Bed",F25)),2,1)))) -> 2
A26: Residential Living Spaces | B26: F5 1-BED CORE EAST | C26: Res | D26: ResidentialLiving | E26: 2 | F26: 1-Bed Type | G26: AHU24 | H26: Y | I26: =J26*L26/$J$40 -> 0.010212762 | J26: 1440.14 | K26: 14402.11 | L26: 1 | M26: =E26*N26 -> 4 | N26: =MAX(2,1+IF(ISNUMBER(SEARCH("Studio",F26)),0,IF(ISNUMBER(SEARCH("3-Bed",F26)),3,IF(ISNUMBER(SEARCH("2-Bed",F26)),2,1)))) -> 2
A27: Residential Living Spaces | B27: F5 1-BED CORE N | C27: Res | D27: ResidentialLiving | E27: 1 | F27: 1-Bed Type | G27: AHU25 | H27: Y | I27: =J27*L27/$J$40 -> 0.0051063811 | J27: 720.07 | K27: 7201.05 | L27: 1 | M27: =E27*N27 -> 2 | N27: =MAX(2,1+IF(ISNUMBER(SEARCH("Studio",F27)),0,IF(ISNUMBER(SEARCH("3-Bed",F27)),3,IF(ISNUMBER(SEARCH("2-Bed",F27)),2,1)))) -> 2
A28: Residential Living Spaces | B28: F5 1-BED CORE WEST | C28: Res | D28: ResidentialLiving | E28: 2 | F28: 1-Bed Type | G28: AHU26 | H28: Y | I28: =J28*L28/$J$40 -> 0.010212762 | J28: 1440.14 | K28: 14402.11 | L28: 1 | M28: =E28*N28 -> 4 | N28: =MAX(2,1+IF(ISNUMBER(SEARCH("Studio",F28)),0,IF(ISNUMBER(SEARCH("3-Bed",F28)),3,IF(ISNUMBER(SEARCH("2-Bed",F28)),2,1)))) -> 2
A29: Residential Living Spaces | B29: F5 1-BED NORTH | C29: Res | D29: ResidentialLiving | E29: 5 | F29: 1-Bed Type | G29: AHU27 | H29: Y | I29: =J29*L29/$J$40 -> 0.026382957 | J29: 3720.36 | K29: 37205.45 | L29: 1 | M29: =E29*N29 -> 10 | N29: =MAX(2,1+IF(ISNUMBER(SEARCH("Studio",F29)),0,IF(ISNUMBER(SEARCH("3-Bed",F29)),3,IF(ISNUMBER(SEARCH("2-Bed",F29)),2,1)))) -> 2
A30: Residential Living Spaces | B30: F5 2-BED CORE NE-NW | C30: Res | D30: ResidentialLiving | E30: 2 | F30: 2-Bed Type | G30: AHU28 | H30: Y | I30: =J30*L30/$J$40 -> 0.015319143 | J30: 2160.21 | K30: 21603.16 | L30: 1 | M30: =E30*N30 -> 6 | N30: =MAX(2,1+IF(ISNUMBER(SEARCH("Studio",F30)),0,IF(ISNUMBER(SEARCH("3-Bed",F30)),3,IF(ISNUMBER(SEARCH("2-Bed",F30)),2,1)))) -> 3
A31: Residential Living Spaces | B31: F5 2-BED EAST | C31: Res | D31: ResidentialLiving | E31: 3 | F31: 2-Bed Type | G31: AHU29 | H31: Y | I31: =J31*L31/$J$40 -> 0.02297875 | J31: 3240.32 | K31: 32404.74 | L31: 1 | M31: =E31*N31 -> 9 | N31: =MAX(2,1+IF(ISNUMBER(SEARCH("Studio",F31)),0,IF(ISNUMBER(SEARCH("3-Bed",F31)),3,IF(ISNUMBER(SEARCH("2-Bed",F31)),2,1)))) -> 3
A32: Residential Living Spaces | B32: F5 2-BED WEST | C32: Res | D32: ResidentialLiving | E32: 3 | F32: 2-Bed Type | G32: AHU30 | H32: Y | I32: =J32*L32/$J$40 -> 0.02297875 | J32: 3240.32 | K32: 32404.74 | L32: 1 | M32: =E32*N32 -> 9 | N32: =MAX(2,1+IF(ISNUMBER(SEARCH("Studio",F32)),0,IF(ISNUMBER(SEARCH("3-Bed",F32)),3,IF(ISNUMBER(SEARCH("2-Bed",F32)),2,1)))) -> 3
A33: Residential Living Spaces | B33: F5 3-BED NE | C33: Res | D33: ResidentialLiving | E33: 1 | F33: 3-Bed Type | G33: AHU31 | H33: Y | I33: =J33*L33/$J$40 -> 0.010000017 | J33: 1410.14 | K33: 14102.06 | L33: 1 | M33: =E33*N33 -> 4 | N33: =MAX(2,1+IF(ISNUMBER(SEARCH("Studio",F33)),0,IF(ISNUMBER(SEARCH("3-Bed",F33)),3,IF(ISNUMBER(SEARCH("2-Bed",F33)),2,1)))) -> 4
A34: Residential Living Spaces | B34: F5 3-BED NW | C34: Res | D34: ResidentialLiving | E34: 1 | F34: 3-Bed Type | G34: AHU32 | H34: Y | I34: =J34*L34/$J$40 -> 0.010000017 | J34: 1410.14 | K34: 14102.06 | L34: 1 | M34: =E34*N34 -> 4 | N34: =MAX(2,1+IF(ISNUMBER(SEARCH("Studio",F34)),0,IF(ISNUMBER(SEARCH("3-Bed",F34)),3,IF(ISNUMBER(SEARCH("2-Bed",F34)),2,1)))) -> 4
A35: Corridor Area | B35: F5 CORRIDOR | C35: NR | D35: ResidentialCommon | E35: NA | F35: NA | G35: AHU33 | H35: Y | I35: =J35*L35/$J$40 -> 0.01829786 | J35: 2580.25 | K35: 25803.78 | L35: 1 | M35: =N35*J35*L35/1000 -> 25.8025 | N35: 10
A36: Laundry Area | B36: F5 LAUNDRY | C36: NR | D36: ResidentialCommon | E36: NA | F36: NA | G36: AHU34 | H36: Y | I36: =J36*L36/$J$40 -> 0.001276613 | J36: 180.02 | K36: 1800.26 | L36: 1 | M36: =N36*J36*L36/1000 -> 1.8002 | N36: 10
A37: Residential Living Spaces | B37: F5 STUDIO SE | C37: Res | D37: ResidentialLiving | E37: 1 | F37: Studio Type | G37: AHU35 | H37: Y | I37: =J37*L37/$J$40 -> 0.0038297681 | J37: 540.05 | K37: 5400.79 | L37: 1 | M37: =E37*N37 -> 2 | N37: =MAX(2,1+IF(ISNUMBER(SEARCH("Studio",F37)),0,IF(ISNUMBER(SEARCH("3-Bed",F37)),3,IF(ISNUMBER(SEARCH("2-Bed",F37)),2,1)))) -> 2
A38: Residential Living Spaces | B38: F5 STUDIO SW | C38: Res | D38: ResidentialLiving | E38: 1 | F38: Studio Type | G38: AHU36 | H38: Y | I38: =J38*L38/$J$40 -> 0.0038297681 | J38: 540.05 | K38: 5400.79 | L38: 1 | M38: =E38*N38 -> 2 | N38: =MAX(2,1+IF(ISNUMBER(SEARCH("Studio",F38)),0,IF(ISNUMBER(SEARCH("3-Bed",F38)),3,IF(ISNUMBER(SEARCH("2-Bed",F38)),2,1)))) -> 2
A39: Parking Garage Area (Parking Zone and Ramps) | B39: PARKING GARAGE | C39: NR | D39: ResidentialCommon | E39: NA | F39: NA | G39: none | H39: N | I39: =J39*L39/$J$40 -> 0.19787232 | J39: 27902.72 | K39: 390657.19 | L39: 1 | M39: =N39*J39*L39/1000 -> 0 | N39: 0
A40: Total (11 Space Types) | B40: Total (37 Spaces) | E40: Total (88 Dwelling Units) | F40: Total (4 Dwelling Unit Types) | G40: Total (37 Thermal Zones) | H40: Total (36 Conditioned Zones, 1 Unconditioned Zones) | I40: =SUM(I3:I39) -> 1 | J40: =SUMPRODUCT(J3:J39,L3:L39) -> 141013.76 | K40: =SUM(K3:K39) -> 1069356.5 | M40: =SUM(M3:M39) -> 763.98496
...

Sheet Envelope
A1: ="Envelope - "&Prototype!A2 -> Envelope - ApartmentMidRise
A2: Element | B2: Prototype | C2: Assembly Type | D2: Construction | E2: Thermal Properties | F2: Vintage | G2: Selected T24 | H2: Notes | I2: CZ1 | J2: CZ2 | K2: CZ3 | L2: CZ4 | M2: CZ5 | N2: CZ6 | O2: CZ7 | P2: CZ8 | Q2: CZ9 | R2: CZ10 | S2: CZ11 | T2: CZ12 | U2: CZ13 | V2: CZ14 | W2: CZ15 | X2: CZ16
A3: External Wall (Floor 1) | B3: =Prototype!$A$2 -> ApartmentMidRise | C3: ExtWall_MassHeavy_Nonres | D3: 8-in cast-in-place concrete wall + insulation + air/water barrier + exterior cladding + gypsum board Insulation only where the vintage U-factor requires it; Pre-1978 is uninsulated (Appendix A R-0). | E3: U-factor IP | F3: Pre 1978 | G3: N/A | H3: ASHRAE 90.1-2022 Appendix A Table A3.1-1 (above-grade concrete/masonry U-factors), 8 in. NWC 145 lb/ft³ solid, No Framing R-0: U-0.740. | I3: 0.74 | J3: 0.74 | K3: 0.74 | L3: 0.74 | M3: 0.74 | N3: 0.74 | O3: 0.74 | P3: 0.74 | Q3: 0.74 | R3: 0.74 | S3: 0.74 | T3: 0.74 | U3: 0.74 | V3: 0.74 | W3: 0.74 | X3: 0.74
F4: 1978-1997 | G4: 1986 | H4: Title 24 1986 Table 2-53W (Alternative Component Packages, high-rise office), Package A, opaque wall HC 10.0–14.99 Btu/°F·ft² | I4: 0.213 | J4: 0.227 | K4: 0.227 | L4: 0.217 | M4: 0.217 | N4: 0.256 | O4: 0.256 | P4: 0.256 | Q4: 0.256 | R4: 0.256 | S4: 0.238 | T4: 0.238 | U4: 0.238 | V4: 0.208 | W4: 0.208 | X4: 0.213
F5: 1998-2007 | G5: 2001 | H5: Table 1-H Mass HC≥15 (2001). CZ groups 1&16 / 3-5 / 6-9 / 2&10-13 / 14-15. | I5: 0.36 | J5: 0.65 | K5: 0.65 | L5: 0.65 | M5: 0.65 | N5: 0.69 | O5: 0.69 | P5: 0.69 | Q5: 0.69 | R5: 0.65 | S5: 0.65 | T5: 0.65 | U5: 0.65 | V5: 0.4 | W5: 0.4 | X5: 0.36
F6: 2008-2018 | G6: 2013 | H6: Table 140.3-B Walls — Mass, Heavy (2013) | I6: 0.253 | J6: 0.65 | K6: 0.65 | L6: 0.65 | M6: 0.65 | N6: 0.69 | O6: 0.69 | P6: 0.69 | Q6: 0.69 | R6: 0.65 | S6: 0.184 | T6: 0.253 | U6: 0.211 | V6: 0.184 | W6: 0.184 | X6: 0.16
F7: 2019+ | G7: 2025 | H7: Table 140.3-B Walls - Mass, Heavy (2025) | I7: 0.211 | J7: 0.65 | K7: 0.65 | L7: 0.65 | M7: 0.65 | N7: 0.69 | O7: 0.69 | P7: 0.69 | Q7: 0.69 | R7: 0.65 | S7: 0.16 | T7: 0.211 | U7: 0.184 | V7: 0.16 | W7: 0.16 | X7: 0.153
A8: External Wall (Floors 2-5) | B8: =Prototype!$A$2 -> ApartmentMidRise | C8: ExtWall_WoodFramed_Res | D8: Wood-frame walls + insulation + Gypsum board | E8: U-factor IP | F8: Pre 1978 | G8: N/A | H8: ASHRAE 90.1 Table A3.4.3.1, 3.5", R-0 | I8: 0.292 | J8: 0.292 | K8: 0.292 | L8: 0.292 | M8: 0.292 | N8: 0.292 | O8: 0.292 | P8: 0.292 | Q8: 0.292 | R8: 0.292 | S8: 0.292 | T8: 0.292 | U8: 0.292 | V8: 0.292 | W8: 0.292 | X8: 0.292
F9: 1978-1997 | G9: 1986 | H9: Title 24 1986 Table 2-53 BB, wall density less than 25 | I9: 0.095 | J9: 0.095 | K9: 0.095 | L9: 0.095 | M9: 0.095 | N9: 0.095 | O9: 0.095 | P9: 0.095 | Q9: 0.095 | R9: 0.095 | S9: 0.095 | T9: 0.095 | U9: 0.095 | V9: 0.095 | W9: 0.095 | X9: 0.095
F10: 1998-2007 | G10: 2001 | H10: TABLE 1-I wood frame (2001 high-rise residential). CZ1 and CZ16 = 0.063. | I10: 0.063 | J10: 0.084 | K10: 0.092 | L10: 0.092 | M10: 0.092 | N10: 0.092 | O10: 0.092 | P10: 0.092 | Q10: 0.092 | R10: 0.084 | S10: 0.084 | T10: 0.084 | U10: 0.084 | V10: 0.084 | W10: 0.084 | X10: 0.063
F11: 2008-2018 | G11: 2013 | H11: TABLE 140.3-C Wood-framed and Other (2013 high-rise residential). Not 140.3-B and not Mass, Heavy (F2-5 construction is wood). | I11: 0.059 | J11: 0.059 | K11: 0.059 | L11: 0.059 | M11: 0.059 | N11: 0.059 | O11: 0.059 | P11: 0.059 | Q11: 0.059 | R11: 0.059 | S11: 0.042 | T11: 0.059 | U11: 0.059 | V11: 0.042 | W11: 0.042 | X11: 0.042
F12: 2019+ | G12: 2025 | H12: TABLE 170.2-A framed (wood, metal) and other — >1-hr fire rating | I12: 0.059 | J12: 0.059 | K12: 0.059 | L12: 0.059 | M12: 0.059 | N12: 0.065 | O12: 0.065 | P12: 0.059 | Q12: 0.059 | R12: 0.059 | S12: 0.051 | T12: 0.059 | U12: 0.059 | V12: 0.051 | W12: 0.051 | X12: 0.051
A13: Roof | B13: =Prototype!$A$2 -> ApartmentMidRise | C13: FlatRoof_WoodFramedAndOther_Res | D13: Roof membrane or shingles + roof insulation + wood decking/sheathing + wood framing | E13: U-factor IP | F13: Pre 1978 | G13: N/A | H13: Considering 30 years for roof/ insulation replacement. | I13: 0.037 | J13: 0.051 | K13: 0.051 | L13: 0.051 | M13: 0.051 | N13: 0.051 | O13: 0.051 | P13: 0.051 | Q13: 0.051 | R13: 0.051 | S13: 0.037 | T13: 0.037 | U13: 0.037 | V13: 0.037 | W13: 0.037 | X13: 0.037
F14: 1978-1997 | G14: N/A | I14: 0.037 | J14: 0.051 | K14: 0.051 | L14: 0.051 | M14: 0.051 | N14: 0.051 | O14: 0.051 | P14: 0.051 | Q14: 0.051 | R14: 0.051 | S14: 0.037 | T14: 0.037 | U14: 0.037 | V14: 0.037 | W14: 0.037 | X14: 0.037
F15: 1998-2007 | G15: 2001 | H15: TABLE 1-I | I15: 0.037 | J15: 0.037 | K15: 0.051 | L15: 0.051 | M15: 0.051 | N15: 0.051 | O15: 0.051 | P15: 0.051 | Q15: 0.051 | R15: 0.037 | S15: 0.037 | T15: 0.037 | U15: 0.037 | V15: 0.037 | W15: 0.037 | X15: 0.037
F16: 2008-2018 | G16: 2013 | H16: TABLE 140.3-C | I16: 0.034 | J16: 0.028 | K16: 0.039 | L16: 0.028 | M16: 0.039 | N16: 0.039 | O16: 0.039 | P16: 0.028 | Q16: 0.028 | R16: 0.028 | S16: 0.028 | T16: 0.028 | U16: 0.028 | V16: 0.028 | W16: 0.028 | X16: 0.028
F17: 2019+ | G17: 2025 | H17: TABLE 170.2-A ENVELOPE COMPONENT PACKAGE – Multifamily Standard Building Design | I17: 0.028 | J17: 0.028 | K17: 0.034 | L17: 0.028 | M17: 0.034 | N17: 0.034 | O17: 0.039 | P17: 0.028 | Q17: 0.028 | R17: 0.028 | S17: 0.028 | T17: 0.028 | U17: 0.028 | V17: 0.028 | W17: 0.028 | X17: 0.028
A18: Windows_Dwelling Units (Floors 2-5) | B18: =Prototype!$A$2 -> ApartmentMidRise | C18: FixedAndOperableWindow_Res | D18: 100% single pane for Pre-1978 and 1978-1997 (as-built). Title 24 fenestration U/SHGC starts at 1998-2007 (2001 Tables 1-H / 1-I). | E18: U factor | F18: Pre 1978 | G18: N/A | H18: ASHRAE Handbook of Fundamentals Ch. 15 Table 4: U 1.12 (fixed metal) / 1.23 (operable). Weighted with Envelope $C$56 operable fraction. No 2013 double-pane blend. | I18: 1.1475 | J18: 1.1475 | K18: 1.1475 | L18: 1.1475 | M18: 1.1475 | N18: 1.1475 | O18: 1.1475 | P18: 1.1475 | Q18: 1.1475 | R18: 1.1475 | S18: 1.1475 | T18: 1.1475 | U18: 1.1475 | V18: 1.1475 | W18: 1.1475 | X18: 1.1475
F19: 1978-1997 | G19: N/A | I19: 1.1475 | J19: 1.1475 | K19: 1.1475 | L19: 1.1475 | M19: 1.1475 | N19: 1.1475 | O19: 1.1475 | P19: 1.1475 | Q19: 1.1475 | R19: 1.1475 | S19: 1.1475 | T19: 1.1475 | U19: 1.1475 | V19: 1.1475 | W19: 1.1475 | X19: 1.1475
D20: Double pane | F20: 1998-2007 | G20: 2001 | H20: Table 1-I | I20: 0.49 | J20: 0.49 | K20: 0.49 | L20: 0.49 | M20: 0.49 | N20: 0.49 | O20: 0.49 | P20: 0.49 | Q20: 0.49 | R20: 0.49 | S20: 0.49 | T20: 0.49 | U20: 0.49 | V20: 0.49 | W20: 0.49 | X20: 0.49
F21: 2008-2018 | G21: 2013 | H21: Table 140.3-C | I21: 0.385 | J21: 0.385 | K21: 0.385 | L21: 0.385 | M21: 0.385 | N21: 0.385 | O21: 0.385 | P21: 0.385 | Q21: 0.385 | R21: 0.385 | S21: 0.385 | T21: 0.385 | U21: 0.385 | V21: 0.385 | W21: 0.385 | X21: 0.385
F22: 2019+ | G22: 2025 | H22: TABLE 170.2-A All Other Fenestration (not fixed/operable blend) | I22: 0.28 | J22: 0.3 | K22: 0.28 | L22: 0.28 | M22: 0.28 | N22: 0.34 | O22: 0.34 | P22: 0.3 | Q22: 0.3 | R22: 0.3 | S22: 0.28 | T22: 0.3 | U22: 0.28 | V22: 0.28 | W22: 0.28 | X22: 0.28
D23: 100% single pane for Pre-1978 and 1978-1997 (as-built). Title 24 fenestration U/SHGC starts at 1998-2007 (2001 Tables 1-H / 1-I). | E23: SHGC | F23: Pre 1978 | G23: N/A | H23: ASHRAE Handbook of Fundamentals Ch. 15 Table 10: SHGC 0.79 (fixed) / 0.78 (operable). Weighted with Envelope $C$56. No 2013 double-pane blend. | I23: 0.7875 | J23: 0.7875 | K23: 0.7875 | L23: 0.7875 | M23: 0.7875 | N23: 0.7875 | O23: 0.7875 | P23: 0.7875 | Q23: 0.7875 | R23: 0.7875 | S23: 0.7875 | T23: 0.7875 | U23: 0.7875 | V23: 0.7875 | W23: 0.7875 | X23: 0.7875
F24: 1978-1997 | G24: N/A | I24: 0.7875 | J24: 0.7875 | K24: 0.7875 | L24: 0.7875 | M24: 0.7875 | N24: 0.7875 | O24: 0.7875 | P24: 0.7875 | Q24: 0.7875 | R24: 0.7875 | S24: 0.7875 | T24: 0.7875 | U24: 0.7875 | V24: 0.7875 | W24: 0.7875 | X24: 0.7875
D25: Double pane | F25: 1998-2007 | G25: 2001 | H25: TABLE 1-I 21-30% WWR (prototype 22%). Non-north row 116; CZ1 uses north (row 117) per Table 1-I note. | I25: 0.36 | J25: 0.4 | K25: 0.61 | L25: 0.61 | M25: 0.61 | N25: 0.61 | O25: 0.61 | P25: 0.61 | Q25: 0.61 | R25: 0.4 | S25: 0.4 | T25: 0.4 | U25: 0.4 | V25: 0.43 | W25: 0.43 | X25: 0.47
F26: 2008-2018 | G26: 2013 | H26: Table 140.3-C | I26: 0.2425 | J26: 0.2425 | K26: 0.2425 | L26: 0.2425 | M26: 0.2425 | N26: 0.2425 | O26: 0.2425 | P26: 0.2425 | Q26: 0.2425 | R26: 0.2425 | S26: 0.2425 | T26: 0.2425 | U26: 0.2425 | V26: 0.2425 | W26: 0.2425 | X26: 0.2425
F27: 2019+ | G27: 2025 | H27: TABLE 170.2-A All Other Fenestration RSHGC (NR in CZ1, 3, 5, 16) | I27: NR | J27: 0.23 | K27: NR | L27: 0.23 | M27: NR | N27: 0.23 | O27: 0.23 | P27: 0.23 | Q27: 0.23 | R27: 0.23 | S27: 0.23 | T27: 0.23 | U27: 0.23 | V27: 0.23 | W27: 0.23 | X27: NR
A28: Windows_Nonres (Floor 1) | B28: =Prototype!$A$2 -> ApartmentMidRise | C28: FixedWindow_NonRes | D28: 100% single pane for Pre-1978 and 1978-1997 (as-built). Title 24 fenestration U/SHGC starts at 1998-2007 (2001 Tables 1-H / 1-I). | E28: U factor | F28: Pre 1978 | G28: N/A | H28: ASHRAE Handbook of Fundamentals Ch. 15 Table 4: U-1.12 (100% fixed metal, Nonres). No 2013 double-pane blend. | I28: 1.12 | J28: 1.12 | K28: 1.12 | L28: 1.12 | M28: 1.12 | N28: 1.12 | O28: 1.12 | P28: 1.12 | Q28: 1.12 | R28: 1.12 | S28: 1.12 | T28: 1.12 | U28: 1.12 | V28: 1.12 | W28: 1.12 | X28: 1.12
F29: 1978-1997 | G29: N/A | I29: 1.12 | J29: 1.12 | K29: 1.12 | L29: 1.12 | M29: 1.12 | N29: 1.12 | O29: 1.12 | P29: 1.12 | Q29: 1.12 | R29: 1.12 | S29: 1.12 | T29: 1.12 | U29: 1.12 | V29: 1.12 | W29: 1.12 | X29: 1.12
D30: Double pane | F30: 1998-2007 | G30: 2001 | H30: Table 1-H window U-factor (2001). CZ3-9 = 0.81; other CZs = 0.49. Values from Envelope row 85. | I30: 0.49 | J30: 0.49 | K30: 0.81 | L30: 0.81 | M30: 0.81 | N30: 0.81 | O30: 0.81 | P30: 0.81 | Q30: 0.81 | R30: 0.49 | S30: 0.49 | T30: 0.49 | U30: 0.49 | V30: 0.49 | W30: 0.49 | X30: 0.49
F31: 2008-2018 | G31: 2013 | H31: Table 140.3-B | I31: 0.36 | J31: 0.36 | K31: 0.36 | L31: 0.36 | M31: 0.36 | N31: 0.36 | O31: 0.36 | P31: 0.36 | Q31: 0.36 | R31: 0.36 | S31: 0.36 | T31: 0.36 | U31: 0.36 | V31: 0.36 | W31: 0.36 | X31: 0.36
F32: 2019+ | G32: 2025 | H32: Table 140.3-B | I32: 0.36 | J32: 0.36 | K32: 0.36 | L32: 0.36 | M32: 0.36 | N32: 0.36 | O32: 0.36 | P32: 0.36 | Q32: 0.34 | R32: 0.36 | S32: 0.34 | T32: 0.34 | U32: 0.34 | V32: 0.34 | W32: 0.34 | X32: 0.36
D33: 100% single pane for Pre-1978 and 1978-1997 (as-built). Title 24 fenestration U/SHGC starts at 1998-2007 (2001 Tables 1-H / 1-I). | E33: SHGC | F33: Pre 1978 | G33: N/A | H33: ASHRAE Handbook of Fundamentals Ch. 15 Table 10: SHGC 0.79 (100% fixed, Nonres). No 2013 double-pane blend. | I33: 0.79 | J33: 0.79 | K33: 0.79 | L33: 0.79 | M33: 0.79 | N33: 0.79 | O33: 0.79 | P33: 0.79 | Q33: 0.79 | R33: 0.79 | S33: 0.79 | T33: 0.79 | U33: 0.79 | V33: 0.79 | W33: 0.79 | X33: 0.79
F34: 1978-1997 | G34: N/A | I34: 0.79 | J34: 0.79 | K34: 0.79 | L34: 0.79 | M34: 0.79 | N34: 0.79 | O34: 0.79 | P34: 0.79 | Q34: 0.79 | R34: 0.79 | S34: 0.79 | T34: 0.79 | U34: 0.79 | V34: 0.79 | W34: 0.79 | X34: 0.79
D35: Double pane | F35: 1998-2007 | G35: 2001 | H35: Table 1-H 21-30% WWR (prototype 22%). Non-north row 120; CZ1 uses north (row 121) per Table 1-H note. | I35: 0.43 | J35: 0.47 | K35: 0.61 | L35: 0.61 | M35: 0.61 | N35: 0.61 | O35: 0.61 | P35: 0.61 | Q35: 0.61 | R35: 0.47 | S35: 0.47 | T35: 0.47 | U35: 0.47 | V35: 0.47 | W35: 0.47 | X35: 0.47
F36: 2008-2018 | G36: 2013 | H36: Table 140.3-B (100% fixed, 0% operable) | I36: 0.25 | J36: 0.25 | K36: 0.25 | L36: 0.25 | M36: 0.25 | N36: 0.25 | O36: 0.25 | P36: 0.25 | Q36: 0.25 | R36: 0.25 | S36: 0.25 | T36: 0.25 | U36: 0.25 | V36: 0.25 | W36: 0.25 | X36: 0.25
F37: 2019+ | G37: 2025 | H37: Table 140.3-B (100% fixed, 0% operable) | I37: 0.25 | J37: 0.25 | K37: 0.25 | L37: 0.25 | M37: 0.25 | N37: 0.25 | O37: 0.25 | P37: 0.25 | Q37: 0.22 | R37: 0.25 | S37: 0.22 | T37: 0.22 | U37: 0.22 | V37: 0.22 | W37: 0.22 | X37: 0.25
A38: * Based on PNNL scorecard assumption.
C40: Infiltration
D41: Building | E41: Zones | F41: Vintage | G41: Source | H41: Res/NR | I41: ACH50
...

Sheet HVAC System
A1: ="HVAC system - "&Prototype!A2 -> HVAC system - ApartmentMidRise
A2: Vintage | B2: Space Type | C2: Heating | D2: Cooling | E2: Air Distribution | F2: Source
A3: Existing | B3: Residential Tenant and common | C3: SZAC (Furnace) | D3: SZAC (DX) | E3: CAV | F3: ResStock 2022 & T24 (2008, 2013)
B4: Non-Residential Tenant (Retail) | C4: PVAV (Gas Boiler & hot water reheat) | D4: PVAV (DX) | E4: VAV | F4: ResStock 2022 & T24 (2008, 2013)
A5: New Construction | B5: Residential Tenant and common | C5: SZHP (DX) | D5: SZHP (DX) | E5: CAV | F5: T24 2025 | G5: ACM 2025 Table 26: dwelling units (>3 habitable floors) SZHP CAV, no economizer; CZ2-15 electric-resistance supplemental heat; CZ1/16 gas furnace supplemental. Common areas are a separate Table 26 row (economizer language differs). Tenant vs common not split into two HVAC rows this pass.
B6: Non-Residential Tenant (Retail) | C6: PVAV (Gas Boiler & hot water reheat) | D6: PVAV (DX) | E6: VAV
A7: *Based on NR ACM 2025 - Table 26
A10: Efficiency of HVAC System (Efficiency is capacity-dependent. The following table provides a general estimate of system efficiency based on preliminary simulations in one climate zone, or assuming cooling load based on rule of thumb)
A11: Vintage | B11: Upgrade/Installed year | C11: Heating | D11: Cooling | E11: Source
A12: Pre 1978 | B12: 2008 | C12: Efficiency 80% (78% AFUE) | D12: EER=9 (<65,000 Btu/h) RES SEER: 13 | E12: T24, 2008 / 10 CFR Part 430, §430.32(c)(2)
A13: 1978-1997
A14: 1998-2007
A15: 2008-2018 | B15: 2013 | C15: Efficiency 80% (78% AFUE) | D15: EER=9 (<65,000 Btu/h) RES: SEER 13 (<65k) | E15: CFR Energy 2010:Title 10- Table 9
A16: New Construction | B16: 2025 | C16: RES: HSPF2:7.5 For SZHPDF: Furnace efficiency: 80% | D16: SEER2: 14.3 | E16: Title 20, 2023 Table E-6
C17: Non-Res: For ≥65k and <135k Btu/h: 11.0 EER and 14.1 IEER Heating (gas boiler) efficiency is not listed and was not invented. Retail NC system remains PVAV with gas boiler (row 6). | D17: 11.0 EER, 14.1 IEER Dual Fuel: 10.8 EER, 13.9 IEER | E17: Title 24, 2025 able 110.2 footnote a
A20: Fan power
A21: Vintage | B21: Approach | C21: System | D21: Total Static Pressure (TSP) (in w.c.) | E21: Fan Efficiency [ACM 2025] | F21: Motor Efficiency | G21: Fan Power Index (W/cfm) | H21: Data Source
A22: Existing | B22: PNNL 90.1-2011, TSP | C22: SZAC CAV, residential tenant and common | D22: 1.33 | E22: 0.65 | F22: ASHRAE 90.1, 2004, Table 10.8 * | H22: Fan power formula: PNNL 20405, 2010, section 5.2.2.5 TSP and fan efficiency: PNNL 20405, 2010, Table 5.11, 90.1-04ac values Motor and drive efficiency: ASHRAE 90.1, 2004, Table 10.8 | I22: PNNL 20405, 2010, Table 5.11
C23: VAV, retail, design airflow > 4,648 cfm | D23: 5.58
A24: Brake horsepower (bhp) = (Supply cfm × TSP in w.c.) / (6356 × fan efficiency)
A25: Fan power (w/cfm) = (bhp × 746) / ( supply cfm × motor efficiency )
A26: New Construction | B26: ACM 2025 | C26: SZHP, residential tenant and common — indoor-unit fan | D26: TSP = fan power × motor efficiency × fan efficiency × 6356 / 746 | E26: 0.65 | F26: 2025 ACM Table 12 ** | G26: 0.35 | H26: w/cfm: [T24, 2025, Section 140.4(a)3 D] Motor efficiency: [ACM 2025, Table 12]
C27: PVAV, retail (System 5), >10,000 cfm | D27: TSP = fan power × motor efficiency × fan efficiency × 6356 / 746 | G27: 0.964 | H27: Fan power index: [ACM 2025, Table 13] Motor efficiency: [ACM 2025, Table 12]
A29: * According to PNNL 20405 section 5.2.2.5, the full-load efficiency of the motor serving the fan is taken from ASHRAE 90.1, 2004, Table 10.8, based on motor nameplate and assuming enclosed motors operating at 1,800 rotations per minute (rpm) Motor nameplate size (bhp) = brake horsepower (bhp) × 1.1 ( using a 10% oversizing factor)
A30: ** The full‑load efficiency of the motor serving the fan is taken from ACM 2025 Table 12 based on the cfm of the fan. Brake horsepower (bhp) = (Supply cfm from sizing run × fan power in W/cfm) / 746. Note: 0.35 W/cfm is the indoor-unit fan (T24 2025 §140.4(a)3 D), same allowance as OfficeMedium VRF and Hotel Large four-pipe fan coil. Not an ACM Table 13 system index. Note: HVAC system is PVAV, not System 6. ACM System 5 >10,000 cfm = 0.964 (Hotel Small). >5,000–10,000 cfm = 1.022.
A31: Background Data [To be deleted prior to publication]

Sheet Thermostat
A1: ="Thermostat Setpoints - "&Prototype!A2&": ResidentialLiving" -> Thermostat Setpoints - ApartmentMidRise : ResidentialLiving
A2: Setpoint | B2: CZ1 | C2: CZ2 | D2: CZ3 | E2: CZ4 | F2: CZ5 | G2: CZ6 | H2: CZ7 | I2: CZ8 | J2: CZ9 | K2: CZ10 | L2: CZ11 | M2: CZ12 | N2: CZ13 | O2: CZ14 | P2: CZ15 | Q2: CZ16 | R2: Source
A3: Heating Setpoint (F) | B3: 68 | C3: 68 | D3: 68 | E3: 68 | F3: 68 | G3: 68 | H3: 68 | I3: 68 | J3: 68 | K3: 68 | L3: 68 | M3: 68 | N3: 68 | O3: 68 | P3: 68 | Q3: 68 | R3: T24 2025 - Appendix 5.4B
A4: Heating Setback (F) | B4: 60 | C4: 60 | D4: 60 | E4: 60 | F4: 60 | G4: 60 | H4: 60 | I4: 60 | J4: 60 | K4: 60 | L4: 60 | M4: 60 | N4: 60 | O4: 60 | P4: 60 | Q4: 60
A5: Cooling Setpoint (F) | B5: 78 | C5: 78 | D5: 78 | E5: 78 | F5: 78 | G5: 78 | H5: 78 | I5: 78 | J5: 78 | K5: 78 | L5: 78 | M5: 78 | N5: 78 | O5: 78 | P5: 78 | Q5: 78 | R5: T24 2025 - Appendix 5.4B
A6: Cooling Setback (F) | B6: 78 | C6: 78 | D6: 78 | E6: 78 | F6: 78 | G6: 78 | H6: 78 | I6: 78 | J6: 78 | K6: 78 | L6: 78 | M6: 78 | N6: 78 | O6: 78 | P6: 78 | Q6: 78
A8: ="Thermostat Setpoints - "&Prototype!A2 & ":Retail" -> Thermostat Setpoints - ApartmentMidRise :Retail
A9: Setpoint | B9: CZ1 | C9: CZ2 | D9: CZ3 | E9: CZ4 | F9: CZ5 | G9: CZ6 | H9: CZ7 | I9: CZ8 | J9: CZ9 | K9: CZ10 | L9: CZ11 | M9: CZ12 | N9: CZ13 | O9: CZ14 | P9: CZ15 | Q9: CZ16 | R9: Source
A10: Heating Setpoint (F) | B10: 70 | C10: 70 | D10: 70 | E10: 70 | F10: 70 | G10: 70 | H10: 70 | I10: 70 | J10: 70 | K10: 70 | L10: 70 | M10: 70 | N10: 70 | O10: 70 | P10: 70 | Q10: 70 | R10: T24 2022 - Appendix 5.4B
A11: Heating Setback (F) | B11: 60 | C11: 60 | D11: 60 | E11: 60 | F11: 60 | G11: 60 | H11: 60 | I11: 60 | J11: 60 | K11: 60 | L11: 60 | M11: 60 | N11: 60 | O11: 60 | P11: 60 | Q11: 60
A12: Cooling Setpoint (F) | B12: 75 | C12: 75 | D12: 75 | E12: 75 | F12: 75 | G12: 75 | H12: 75 | I12: 75 | J12: 75 | K12: 75 | L12: 75 | M12: 75 | N12: 75 | O12: 75 | P12: 75 | Q12: 75
A13: Cooling Setback (F) | B13: 85 | C13: 85 | D13: 85 | E13: 85 | F13: 85 | G13: 85 | H13: 85 | I13: 85 | J13: 85 | K13: 85 | L13: 85 | M13: 85 | N13: 85 | O13: 85 | P13: 85 | Q13: 85
A14: ="Thermostat Setpoints - "&Prototype!A2&": ResidentialCommon" -> Thermostat Setpoints - ApartmentMidRise : ResidentialCommon
A15: Heating Setpoint (F) | B15: 68 | C15: 68 | D15: 68 | E15: 68 | F15: 68 | G15: 68 | H15: 68 | I15: 68 | J15: 68 | K15: 68 | L15: 68 | M15: 68 | N15: 68 | O15: 68 | P15: 68 | Q15: 68 | R15: T24 2025 Appendix 5.4B ResidentialCommon
A16: Heating Setback (F) | B16: 68 | C16: 68 | D16: 68 | E16: 68 | F16: 68 | G16: 68 | H16: 68 | I16: 68 | J16: 68 | K16: 68 | L16: 68 | M16: 68 | N16: 68 | O16: 68 | P16: 68 | Q16: 68
A17: Cooling Setpoint (F) | B17: 78 | C17: 78 | D17: 78 | E17: 78 | F17: 78 | G17: 78 | H17: 78 | I17: 78 | J17: 78 | K17: 78 | L17: 78 | M17: 78 | N17: 78 | O17: 78 | P17: 78 | Q17: 78
A18: Cooling Setback (F) | B18: 78 | C18: 78 | D18: 78 | E18: 78 | F18: 78 | G18: 78 | H18: 78 | I18: 78 | J18: 78 | K18: 78 | L18: 78 | M18: 78 | N18: 78 | O18: 78 | P18: 78 | Q18: 78
A20: One App 5.4B ResidentialLiving profile (68°F occupied / 60°F hours 1–6 and 23–24). ACM 2025 does not publish a multi-unit thermostat diversity set for this prototype. Stochastic or deep-setback mixes were not added.

Sheet Ventilation
A1: ="Outdoor Airflow Rate - "&Prototype!A2 -> Outdoor Airflow Rate - ApartmentMidRise
A2: Space Thermal Zone | B2: Number of People | C2: Floor Area (ft2) | D2: cfm/person (T24, 2025, Equation 120.1-F and Table 120.1-A) | E2: cfm (whole-dwelling continuous mechanical ventilation rate) Res: Equation 160.2-B | F2: cfm/ft² (T24, 2025, Equation 120.1-F and Table 120.1-A) | G2: Required Exhaust Rate-CFM/ft²- (T24, 2025, Table 120.1-B – Minimum Exhaust Rates) | H2: Total cfm Driven by People | I2: Total cfm Driven by Area | J2: Total cfm Driven by Exhaust | K2: Total cfm | L2: Note
A3: =Zones!B3 -> F1 BUSINESS CENTER | B3: =Zones!M3 -> 24.003867 | C3: =Zones!J3 -> 360.04 | D3: 15 | F3: 0.15 | H3: =B3*D3 -> 360.058 | I3: =C3*F3 -> 54.006 | K3: =MAX(H3:J3) -> 360.058
A4: =Zones!B4 -> F1 CORRIDOR | B4: =Zones!M4 -> 19.2019 | C4: =Zones!J4 -> 1920.19 | D4: 15 | F4: 0.15 | H4: =B4*D4 -> 288.0285 | I4: =C4*F4 -> 288.0285 | K4: =MAX(H4:J4) -> 288.0285
A5: =Zones!B5 -> F1 FITNESS CENTER | B5: =Zones!M5 -> 18.0018 | C5: =Zones!J5 -> 900.09 | D5: 15 | F5: 0.15 | H5: =B5*D5 -> 270.027 | I5: =C5*F5 -> 135.0135 | K5: =MAX(H5:J5) -> 270.027
A6: =Zones!B6 -> F1 LEASING OFFICE | B6: =Zones!M6 -> 3.4503 | C6: =Zones!J6 -> 345.03 | D6: 15 | F6: 0.15 | H6: =B6*D6 -> 51.7545 | I6: =C6*F6 -> 51.7545 | K6: =MAX(H6:J6) -> 51.7545
A7: =Zones!B7 -> F1 LOUNGE | B7: =Zones!M7 -> 70.04167 | C7: =Zones!J7 -> 1050.1 | D7: 15 | F7: 0.15 | H7: =B7*D7 -> 1050.625 | I7: =C7*F7 -> 157.515 | K7: =MAX(H7:J7) -> 1050.625
A8: =Zones!B8 -> F1 MECHANICAL ROOM | B8: =Zones!M8 -> 1.29612 | C8: =Zones!J8 -> 432.04 | D8: 15 | F8: 0.15 | H8: =B8*D8 -> 19.4418 | I8: =C8*F8 -> 64.806 | K8: =MAX(H8:J8) -> 64.806
A9: =Zones!B9 -> F1 RETAIL N-NW | B9: =Zones!M9 -> 99.759667 | C9: =Zones!J9 -> 5985.58 | D9: 15 | F9: 0.2 | H9: =B9*D9 -> 1496.395 | I9: =C9*F9 -> 1197.116 | K9: =MAX(H9:J9) -> 1496.395 | L9: Retail merchandise: Table 120.1-A / App 5.4C Retail-Sales Ra = 0.20 cfm/ft².
A10: =Zones!B10 -> F1 RETAIL NE | B10: =Zones!M10 -> 72.007 | C10: =Zones!J10 -> 4320.42 | D10: 15 | F10: 0.2 | H10: =B10*D10 -> 1080.105 | I10: =C10*F10 -> 864.084 | K10: =MAX(H10:J10) -> 1080.105
A11: =Zones!B11 -> F1 RETAIL SE | B11: =Zones!M11 -> 48.004667 | C11: =Zones!J11 -> 2880.28 | D11: 15 | F11: 0.2 | H11: =B11*D11 -> 720.07 | I11: =C11*F11 -> 576.056 | K11: =MAX(H11:J11) -> 720.07
A12: =Zones!B12 -> F1 RETAIL SW | B12: =Zones!M12 -> 73.807167 | C12: =Zones!J12 -> 4428.43 | D12: 15 | F12: 0.2 | H12: =B12*D12 -> 1107.1075 | I12: =C12*F12 -> 885.686 | K12: =MAX(H12:J12) -> 1107.1075
A13: =Zones!B13 -> F2-4 1-BED CORE EAST | B13: =Zones!M13 -> 12 | C13: =Zones!J13 -> 1440.14 | D13: NA | E13: =0.03*C13*Zones!L13+7.5*Zones!E13*(1+IF(ISNUMBER(SEARCH("Studio",Zones!F13)),0,IF(ISNUMBER(SEARCH("3-Bed",Zones!F13)),3,IF(ISNUMBER(SEARCH("2-Bed",Zones!F13)),2,1)))) -> 219.6126 | I13: =E13 -> 219.6126 | J13: =I13 -> 219.6126 | K13: =MAX(H13:J13) -> 219.6126 | L13: Eq 160.2-B: 0.03×CFA_total + 7.5×N_units×(N_br+1). Studio N_br=0. CFA_total = zone area × floor multiplier. Natural ventilation is not modeled (operable fraction Envelope C56 is fenestration weighting only).
A14: =Zones!B14 -> F2-4 1-BED CORE N | B14: =Zones!M14 -> 6 | C14: =Zones!J14 -> 720.07 | D14: NA | E14: =0.03*C14*Zones!L14+7.5*Zones!E14*(1+IF(ISNUMBER(SEARCH("Studio",Zones!F14)),0,IF(ISNUMBER(SEARCH("3-Bed",Zones!F14)),3,IF(ISNUMBER(SEARCH("2-Bed",Zones!F14)),2,1)))) -> 109.8063 | I14: =E14 -> 109.8063 | J14: =I14 -> 109.8063 | K14: =MAX(H14:J14) -> 109.8063 | L14: Balanced IAQ fan - only applies to new construction
A15: =Zones!B15 -> F2-4 1-BED CORE WEST | B15: =Zones!M15 -> 12 | C15: =Zones!J15 -> 1440.14 | D15: NA | E15: =0.03*C15*Zones!L15+7.5*Zones!E15*(1+IF(ISNUMBER(SEARCH("Studio",Zones!F15)),0,IF(ISNUMBER(SEARCH("3-Bed",Zones!F15)),3,IF(ISNUMBER(SEARCH("2-Bed",Zones!F15)),2,1)))) -> 219.6126 | I15: =E15 -> 219.6126 | J15: =I15 -> 219.6126 | K15: =MAX(H15:J15) -> 219.6126 | L15: Balanced IAQ fan - only applies to new construction
A16: =Zones!B16 -> F2-4 1-BED NORTH | B16: =Zones!M16 -> 30 | C16: =Zones!J16 -> 3720.36 | D16: NA | E16: =0.03*C16*Zones!L16+7.5*Zones!E16*(1+IF(ISNUMBER(SEARCH("Studio",Zones!F16)),0,IF(ISNUMBER(SEARCH("3-Bed",Zones!F16)),3,IF(ISNUMBER(SEARCH("2-Bed",Zones!F16)),2,1)))) -> 559.8324 | I16: =E16 -> 559.8324 | J16: =I16 -> 559.8324 | K16: =MAX(H16:J16) -> 559.8324 | L16: Balanced IAQ fan - only applies to new construction
A17: =Zones!B17 -> F2-4 2-BED CORE NE-NW | B17: =Zones!M17 -> 18 | C17: =Zones!J17 -> 2160.21 | D17: NA | E17: =0.03*C17*Zones!L17+7.5*Zones!E17*(1+IF(ISNUMBER(SEARCH("Studio",Zones!F17)),0,IF(ISNUMBER(SEARCH("3-Bed",Zones!F17)),3,IF(ISNUMBER(SEARCH("2-Bed",Zones!F17)),2,1)))) -> 329.4189 | I17: =E17 -> 329.4189 | J17: =I17 -> 329.4189 | K17: =MAX(H17:J17) -> 329.4189 | L17: Balanced IAQ fan - only applies to new construction
A18: =Zones!B18 -> F2-4 2-BED EAST | B18: =Zones!M18 -> 27 | C18: =Zones!J18 -> 3240.32 | D18: NA | E18: =0.03*C18*Zones!L18+7.5*Zones!E18*(1+IF(ISNUMBER(SEARCH("Studio",Zones!F18)),0,IF(ISNUMBER(SEARCH("3-Bed",Zones!F18)),3,IF(ISNUMBER(SEARCH("2-Bed",Zones!F18)),2,1)))) -> 494.1288 | I18: =E18 -> 494.1288 | J18: =I18 -> 494.1288 | K18: =MAX(H18:J18) -> 494.1288 | L18: Balanced IAQ fan - only applies to new construction
A19: =Zones!B19 -> F2-4 2-BED WEST | B19: =Zones!M19 -> 27 | C19: =Zones!J19 -> 3240.32 | D19: NA | E19: =0.03*C19*Zones!L19+7.5*Zones!E19*(1+IF(ISNUMBER(SEARCH("Studio",Zones!F19)),0,IF(ISNUMBER(SEARCH("3-Bed",Zones!F19)),3,IF(ISNUMBER(SEARCH("2-Bed",Zones!F19)),2,1)))) -> 494.1288 | I19: =E19 -> 494.1288 | J19: =I19 -> 494.1288 | K19: =MAX(H19:J19) -> 494.1288 | L19: Balanced IAQ fan - only applies to new construction
A20: =Zones!B20 -> F2-4 3-BED NE | B20: =Zones!M20 -> 12 | C20: =Zones!J20 -> 1410.14 | D20: NA | E20: =0.03*C20*Zones!L20+7.5*Zones!E20*(1+IF(ISNUMBER(SEARCH("Studio",Zones!F20)),0,IF(ISNUMBER(SEARCH("3-Bed",Zones!F20)),3,IF(ISNUMBER(SEARCH("2-Bed",Zones!F20)),2,1)))) -> 216.9126 | I20: =E20 -> 216.9126 | J20: =I20 -> 216.9126 | K20: =MAX(H20:J20) -> 216.9126 | L20: Balanced IAQ fan - only applies to new construction
A21: =Zones!B21 -> F2-4 3-BED NW | B21: =Zones!M21 -> 12 | C21: =Zones!J21 -> 1410.14 | D21: NA | E21: =0.03*C21*Zones!L21+7.5*Zones!E21*(1+IF(ISNUMBER(SEARCH("Studio",Zones!F21)),0,IF(ISNUMBER(SEARCH("3-Bed",Zones!F21)),3,IF(ISNUMBER(SEARCH("2-Bed",Zones!F21)),2,1)))) -> 216.9126 | I21: =E21 -> 216.9126 | J21: =I21 -> 216.9126 | K21: =MAX(H21:J21) -> 216.9126 | L21: Balanced IAQ fan - only applies to new construction
A22: =Zones!B22 -> F2-4 CORRIDOR | B22: =Zones!M22 -> 77.4075 | C22: =Zones!J22 -> 2580.25 | D22: 15 | F22: 0.15 | H22: =B22*D22 -> 1161.1125 | I22: =C22*F22 -> 387.0375 | K22: =MAX(H22:J22) -> 1161.1125
A23: =Zones!B23 -> F2-4 LAUNDRY | B23: =Zones!M23 -> 5.4006 | C23: =Zones!J23 -> 180.02 | D23: 15 | F23: 0.15 | H23: =B23*D23 -> 81.009 | I23: =C23*F23 -> 27.003 | K23: =MAX(H23:J23) -> 81.009
A24: =Zones!B24 -> F2-4 STUDIO SE | B24: =Zones!M24 -> 6 | C24: =Zones!J24 -> 540.05 | D24: NA | E24: =0.03*C24*Zones!L24+7.5*Zones!E24*(1+IF(ISNUMBER(SEARCH("Studio",Zones!F24)),0,IF(ISNUMBER(SEARCH("3-Bed",Zones!F24)),3,IF(ISNUMBER(SEARCH("2-Bed",Zones!F24)),2,1)))) -> 71.1045 | I24: =E24 -> 71.1045 | J24: =I24 -> 71.1045 | K24: =MAX(H24:J24) -> 71.1045 | L24: Balanced IAQ fan - only applies to new construction
A25: =Zones!B25 -> F2-4 STUDIO SW | B25: =Zones!M25 -> 6 | C25: =Zones!J25 -> 540.05 | D25: NA | E25: =0.03*C25*Zones!L25+7.5*Zones!E25*(1+IF(ISNUMBER(SEARCH("Studio",Zones!F25)),0,IF(ISNUMBER(SEARCH("3-Bed",Zones!F25)),3,IF(ISNUMBER(SEARCH("2-Bed",Zones!F25)),2,1)))) -> 71.1045 | I25: =E25 -> 71.1045 | J25: =I25 -> 71.1045 | K25: =MAX(H25:J25) -> 71.1045 | L25: Balanced IAQ fan - only applies to new construction
A26: =Zones!B26 -> F5 1-BED CORE EAST | B26: =Zones!M26 -> 4 | C26: =Zones!J26 -> 1440.14 | D26: NA | E26: =0.03*C26*Zones!L26+7.5*Zones!E26*(1+IF(ISNUMBER(SEARCH("Studio",Zones!F26)),0,IF(ISNUMBER(SEARCH("3-Bed",Zones!F26)),3,IF(ISNUMBER(SEARCH("2-Bed",Zones!F26)),2,1)))) -> 73.2042 | I26: =E26 -> 73.2042 | J26: =I26 -> 73.2042 | K26: =MAX(H26:J26) -> 73.2042 | L26: Balanced IAQ fan - only applies to new construction
A27: =Zones!B27 -> F5 1-BED CORE N | B27: =Zones!M27 -> 2 | C27: =Zones!J27 -> 720.07 | D27: NA | E27: =0.03*C27*Zones!L27+7.5*Zones!E27*(1+IF(ISNUMBER(SEARCH("Studio",Zones!F27)),0,IF(ISNUMBER(SEARCH("3-Bed",Zones!F27)),3,IF(ISNUMBER(SEARCH("2-Bed",Zones!F27)),2,1)))) -> 36.6021 | I27: =E27 -> 36.6021 | J27: =I27 -> 36.6021 | K27: =MAX(H27:J27) -> 36.6021 | L27: Balanced IAQ fan - only applies to new construction
A28: =Zones!B28 -> F5 1-BED CORE WEST | B28: =Zones!M28 -> 4 | C28: =Zones!J28 -> 1440.14 | D28: NA | E28: =0.03*C28*Zones!L28+7.5*Zones!E28*(1+IF(ISNUMBER(SEARCH("Studio",Zones!F28)),0,IF(ISNUMBER(SEARCH("3-Bed",Zones!F28)),3,IF(ISNUMBER(SEARCH("2-Bed",Zones!F28)),2,1)))) -> 73.2042 | I28: =E28 -> 73.2042 | J28: =I28 -> 73.2042 | K28: =MAX(H28:J28) -> 73.2042 | L28: Balanced IAQ fan - only applies to new construction
A29: =Zones!B29 -> F5 1-BED NORTH | B29: =Zones!M29 -> 10 | C29: =Zones!J29 -> 3720.36 | D29: NA | E29: =0.03*C29*Zones!L29+7.5*Zones!E29*(1+IF(ISNUMBER(SEARCH("Studio",Zones!F29)),0,IF(ISNUMBER(SEARCH("3-Bed",Zones!F29)),3,IF(ISNUMBER(SEARCH("2-Bed",Zones!F29)),2,1)))) -> 186.6108 | I29: =E29 -> 186.6108 | J29: =I29 -> 186.6108 | K29: =MAX(H29:J29) -> 186.6108 | L29: Balanced IAQ fan - only applies to new construction
A30: =Zones!B30 -> F5 2-BED CORE NE-NW | B30: =Zones!M30 -> 6 | C30: =Zones!J30 -> 2160.21 | D30: NA | E30: =0.03*C30*Zones!L30+7.5*Zones!E30*(1+IF(ISNUMBER(SEARCH("Studio",Zones!F30)),0,IF(ISNUMBER(SEARCH("3-Bed",Zones!F30)),3,IF(ISNUMBER(SEARCH("2-Bed",Zones!F30)),2,1)))) -> 109.8063 | I30: =E30 -> 109.8063 | J30: =I30 -> 109.8063 | K30: =MAX(H30:J30) -> 109.8063 | L30: Balanced IAQ fan - only applies to new construction
A31: =Zones!B31 -> F5 2-BED EAST | B31: =Zones!M31 -> 9 | C31: =Zones!J31 -> 3240.32 | D31: NA | E31: =0.03*C31*Zones!L31+7.5*Zones!E31*(1+IF(ISNUMBER(SEARCH("Studio",Zones!F31)),0,IF(ISNUMBER(SEARCH("3-Bed",Zones!F31)),3,IF(ISNUMBER(SEARCH("2-Bed",Zones!F31)),2,1)))) -> 164.7096 | I31: =E31 -> 164.7096 | J31: =I31 -> 164.7096 | K31: =MAX(H31:J31) -> 164.7096 | L31: Balanced IAQ fan - only applies to new construction
A32: =Zones!B32 -> F5 2-BED WEST | B32: =Zones!M32 -> 9 | C32: =Zones!J32 -> 3240.32 | D32: NA | E32: =0.03*C32*Zones!L32+7.5*Zones!E32*(1+IF(ISNUMBER(SEARCH("Studio",Zones!F32)),0,IF(ISNUMBER(SEARCH("3-Bed",Zones!F32)),3,IF(ISNUMBER(SEARCH("2-Bed",Zones!F32)),2,1)))) -> 164.7096 | I32: =E32 -> 164.7096 | J32: =I32 -> 164.7096 | K32: =MAX(H32:J32) -> 164.7096 | L32: Balanced IAQ fan - only applies to new construction
A33: =Zones!B33 -> F5 3-BED NE | B33: =Zones!M33 -> 4 | C33: =Zones!J33 -> 1410.14 | D33: NA | E33: =0.03*C33*Zones!L33+7.5*Zones!E33*(1+IF(ISNUMBER(SEARCH("Studio",Zones!F33)),0,IF(ISNUMBER(SEARCH("3-Bed",Zones!F33)),3,IF(ISNUMBER(SEARCH("2-Bed",Zones!F33)),2,1)))) -> 72.3042 | I33: =E33 -> 72.3042 | J33: =I33 -> 72.3042 | K33: =MAX(H33:J33) -> 72.3042 | L33: Balanced IAQ fan - only applies to new construction
A34: =Zones!B34 -> F5 3-BED NW | B34: =Zones!M34 -> 4 | C34: =Zones!J34 -> 1410.14 | D34: NA | E34: =0.03*C34*Zones!L34+7.5*Zones!E34*(1+IF(ISNUMBER(SEARCH("Studio",Zones!F34)),0,IF(ISNUMBER(SEARCH("3-Bed",Zones!F34)),3,IF(ISNUMBER(SEARCH("2-Bed",Zones!F34)),2,1)))) -> 72.3042 | I34: =E34 -> 72.3042 | J34: =I34 -> 72.3042 | K34: =MAX(H34:J34) -> 72.3042 | L34: Balanced IAQ fan - only applies to new construction
A35: =Zones!B35 -> F5 CORRIDOR | B35: =Zones!M35 -> 25.8025 | C35: =Zones!J35 -> 2580.25 | D35: 15 | F35: 0.15 | H35: =B35*D35 -> 387.0375 | I35: =C35*F35 -> 387.0375 | K35: =MAX(H35:J35) -> 387.0375
A36: =Zones!B36 -> F5 LAUNDRY | B36: =Zones!M36 -> 1.8002 | C36: =Zones!J36 -> 180.02 | D36: 15 | F36: 0.15 | H36: =B36*D36 -> 27.003 | I36: =C36*F36 -> 27.003 | K36: =MAX(H36:J36) -> 27.003
A37: =Zones!B37 -> F5 STUDIO SE | B37: =Zones!M37 -> 2 | C37: =Zones!J37 -> 540.05 | D37: NA | E37: =0.03*C37*Zones!L37+7.5*Zones!E37*(1+IF(ISNUMBER(SEARCH("Studio",Zones!F37)),0,IF(ISNUMBER(SEARCH("3-Bed",Zones!F37)),3,IF(ISNUMBER(SEARCH("2-Bed",Zones!F37)),2,1)))) -> 23.7015 | I37: =E37 -> 23.7015 | J37: =I37 -> 23.7015 | K37: =MAX(H37:J37) -> 23.7015 | L37: Balanced IAQ fan - only applies to new construction
A38: =Zones!B38 -> F5 STUDIO SW | B38: =Zones!M38 -> 2 | C38: =Zones!J38 -> 540.05 | D38: NA | E38: =0.03*C38*Zones!L38+7.5*Zones!E38*(1+IF(ISNUMBER(SEARCH("Studio",Zones!F38)),0,IF(ISNUMBER(SEARCH("3-Bed",Zones!F38)),3,IF(ISNUMBER(SEARCH("2-Bed",Zones!F38)),2,1)))) -> 23.7015 | I38: =E38 -> 23.7015 | J38: =I38 -> 23.7015 | K38: =MAX(H38:J38) -> 23.7015 | L38: Balanced IAQ fan - only applies to new construction
A39: =Zones!B39 -> PARKING GARAGE | B39: =Zones!M39 -> 0 | C39: =Zones!J39 -> 27902.72 | D39: 0 | F39: 0 | G39: 0.75 | H39: =B39*D39 -> 0 | I39: =C39*F39 -> 0 | J39: =C39*G39 -> 20927.04 | K39: =MAX(H39:J39) -> 20927.04 | L39: Parking garage: Table 120.1-B exhaust 0.75 cfm/ft² only. Person and area OA removed (App 5.4C Exhaust - Parking garages).

Sheet Water Heater
A1: ="Water Heater - "&Prototype!A2 -> Water Heater - ApartmentMidRise
A2: Vintage | B2: WH Type | C2: Efficiency | D2: Number of WH | E2: Tank volume (gal) | F2: Tank loss | G2: Source | H2: Note
A3: Existing | B3: Gas consumer storage (in-unit) | C3: 0.8 | D3: =B51 -> 88 | E3: ="See Existing in-unit CZ table, col F (gal/unit); building = 88 x F" -> See Existing in-unit CZ table, col F (gal/unit); building = 88 x F | F3: =IF(F62<=55,0.692-0.0013*F62,0.8072-0.0003*F62) -> 0.653 | G3: C3 is recovery efficiency (capacity / RE). E3 is 10 CFR 430.32 high-draw UEF from the CZ tank (col F). CZ G/I/J follow the school HPWH layout: G = standby %/hr = I/(0.0834×F); I is Off/On-cycle UA (Btu/h·°F) from Maguire & Roberts 2020; J is the unit. EnergyPlus {W/K} = I × $B$139 (0.527527); use I in both Off-Cycle and On-Cycle fields. Not Title 20 Table F-4 and not DEER commercial HPWH 4.37. | H3: One water heater per apartment (88), not a central plant. Not all identical: 48 studio/1-bed (2 people, 0.36 gal/h), 32 two-bed (3 people, 0.54 gal/h), 8 three-bed (4 people, 0.72 gal/h). The CZ table uses the 3-bed peak.
A4: New Construction | B4: Gas consumer instantaneous (in-unit) | C4: 0.81 | D4: =D3 -> 88 | E4: 0 | F4: n/a
A5: * Individual dwelling-unit water heaters (not central §170.2(d)3 storage + recirculation + solar). 88 units. Existing = consumer storage catalog. NC = ACM §6.11.2 instantaneous. Retail/laundry/amenities = one commercial plant (NR catalog + 75 gal/h minimum).
A8: Peak Hot Water Consumption
A9: Space | B9: Plant (In-unit dwelling vs Common commercial) | C9: Total Area (ft²) | D9: Number of People | E9: Hot Water Usage Specification (gal/hr per person) [T24, 2022, Appendix 5.4A , sheet: "2022 SpaceFuncData-Input"] | F9: Peak Hot Water Usage (gal/hr) | G9: Peak Hot Water Usage (gal/min) | H9: Notes
A10: =Zones!B3 -> F1 BUSINESS CENTER | B10: Common | C10: =Zones!J3*Zones!L3 -> 360.04 | D10: =Zones!M3 -> 24.003867 | E10: 0.18 | F10: =D10*E10 -> 4.320696 | G10: =F10/60 -> 0.0720116 | H10: In-unit = dwelling DHW (consumer heater in each apartment). Common = retail/laundry/amenity DHW on a separate commercial plant. Dwelling gal/h-person is 0.18 throughout. Corridor 0, lounge/office 0.09, laundry 0.578 per Jason APTM58 / school App 5.4A kitchen-locker rate.
A11: =Zones!B4 -> F1 CORRIDOR | B11: Common | C11: =Zones!J4*Zones!L4 -> 1920.19 | D11: =Zones!M4 -> 19.2019 | E11: 0 | F11: =D11*E11 -> 0 | G11: =F11/60 -> 0
A12: =Zones!B5 -> F1 FITNESS CENTER | B12: Common | C12: =Zones!J5*Zones!L5 -> 900.09 | D12: =Zones!M5 -> 18.0018 | E12: 0.18 | F12: =D12*E12 -> 3.240324 | G12: =F12/60 -> 0.0540054
A13: =Zones!B6 -> F1 LEASING OFFICE | B13: Common | C13: =Zones!J6*Zones!L6 -> 345.03 | D13: =Zones!M6 -> 3.4503 | E13: 0.09 | F13: =D13*E13 -> 0.310527 | G13: =F13/60 -> 0.00517545
A14: =Zones!B7 -> F1 LOUNGE | B14: Common | C14: =Zones!J7*Zones!L7 -> 1050.1 | D14: =Zones!M7 -> 70.04167 | E14: 0.09 | F14: =D14*E14 -> 6.3037503 | G14: =F14/60 -> 0.1050625
A15: =Zones!B8 -> F1 MECHANICAL ROOM | B15: Common | C15: =Zones!J8*Zones!L8 -> 432.04 | D15: =Zones!M8 -> 1.29612 | E15: 0 | F15: =D15*E15 -> 0 | G15: =F15/60 -> 0
A16: =Zones!B9 -> F1 RETAIL N-NW | B16: Common | C16: =Zones!J9*Zones!L9 -> 5985.58 | D16: =Zones!M9 -> 99.759667 | E16: 0.18 | F16: =D16*E16 -> 17.95674 | G16: =F16/60 -> 0.299279
A17: =Zones!B10 -> F1 RETAIL NE | B17: Common | C17: =Zones!J10*Zones!L10 -> 4320.42 | D17: =Zones!M10 -> 72.007 | E17: 0.18 | F17: =D17*E17 -> 12.96126 | G17: =F17/60 -> 0.216021
A18: =Zones!B11 -> F1 RETAIL SE | B18: Common | C18: =Zones!J11*Zones!L11 -> 2880.28 | D18: =Zones!M11 -> 48.004667 | E18: 0.18 | F18: =D18*E18 -> 8.64084 | G18: =F18/60 -> 0.144014
A19: =Zones!B12 -> F1 RETAIL SW | B19: Common | C19: =Zones!J12*Zones!L12 -> 4428.43 | D19: =Zones!M12 -> 73.807167 | E19: 0.18 | F19: =D19*E19 -> 13.28529 | G19: =F19/60 -> 0.2214215
A20: =Zones!B13 -> F2-4 1-BED CORE EAST | B20: In-unit | C20: =Zones!J13*Zones!L13 -> 4320.42 | D20: =Zones!M13 -> 12 | E20: 0.18 | F20: =D20*E20 -> 2.16 | G20: =F20/60 -> 0.036
A21: =Zones!B14 -> F2-4 1-BED CORE N | B21: In-unit | C21: =Zones!J14*Zones!L14 -> 2160.21 | D21: =Zones!M14 -> 6 | E21: 0.18 | F21: =D21*E21 -> 1.08 | G21: =F21/60 -> 0.018
A22: =Zones!B15 -> F2-4 1-BED CORE WEST | B22: In-unit | C22: =Zones!J15*Zones!L15 -> 4320.42 | D22: =Zones!M15 -> 12 | E22: 0.18 | F22: =D22*E22 -> 2.16 | G22: =F22/60 -> 0.036
... A46: =Zones!B39 -> PARKING GARAGE | B46: Common | C46: =Zones!J39*Zones!L39 -> 27902.72 | D46: =Zones!M39 -> 0 | E46: 0 | F46: =D46*E46 -> 0 | G46: =F46/60 -> 0
A48: Total | B48: In-unit peak, one dwelling (gal/h) | F48: =_xlfn.AGGREGATE(14,6,$F$10:$F$46/Zones!$E$3:$E$39/($B$10:$B$46="In-unit"),1) -> 0.72 | H48: Largest apartment only (3-bed, 0.72 gal/h). Not the sum of all apartments. No 75 gal/h minimum on in-unit heaters.
A49: Total | B49: Common / retail (commercial plant gal/h) | F49: =_xlfn.LET(_xlpm.g,SUMIF($B$10:$B$46,"Common",$F$10:$F$46),IF(_xlpm.g>0,MAX(75,_xlpm.g),0)) -> 75 | H49: ACM 2025 §5.9.2 minimum peak 75 gal/h applied only if common DHW > 0.
A51: Number of dwelling units | B51: 88 | C51: Prototype A18 / Zones E
A52: Peak gal/h per dwelling unit | B52: =F48 -> 0.72
A53: NC input per dwelling (Btu/h) | B53: 200000 | C53: ACM §6.11.2 consumer instantaneous
A54: NC prototype total input (Btu/h) | B54: =B53*B51 -> 17600000
A55: Design supply temperature (°F) | B55: 135 | C55: T24 2022 Appendix 5.4B
A56: WH system factor | B56: 0.6 | C56: 2025 ACM §5.9.2 Rated Capacity
A57: Water mass conversion (lb/gal) | B57: 8.2877 | C57: 2025 ACM §5.9.2 Rated Capacity
A58: Reheat multiplier | B58: 0.4 | C58: 2025 ACM §5.9.2 Storage Volume
A60: Climate Zone Water Heater Sizing — Existing in-unit consumer storage (per dwelling)
A61: Climate Zone | B61: Minimum Monthly Mains Temp (°F) [T24 2022 - Appendix 5.4B] | C61: Heat Output (Btu/hr) [ACM, 2025, 5.9.2: Rated capacity section] | D61: WH Capacity (Btu/hr) [ACM, 2025, 5.9.2: Rated capacity section] | E61: Required Energy Input (Btu/hr) | F61: Storage Volume (gal) | G61: Standby Loss (%/hr) [Maguire & Roberts 2020 / OpenStudio-HPXML. Not Title 20 Table F-4] | I61: Off/On Cycle Loss Coefficient to Ambient Temp | K61: Source/Note
A62: CZ01 | B62: 47.9 | C62: =$B$52*($B$55-B62)*$B$57 -> 519.73824 | D62: =C62*$B$56 -> 311.84295 | E62: =_xlfn.LET(_xlpm.x,IFERROR(_xlfn.XLOOKUP(D62/$C$3,$A$120:$A$128,$A$120:$A$128,"",1),""),IF(_xlpm.x="","Exceeds consumer input list",_xlpm.x)) -> 30000 | F62: =_xlfn.LET(_xlpm.x,IFERROR(_xlfn.XLOOKUP(MAX(30,$B$52*$B$58),$E$120:$E$124,$E$120:$E$124,"",1),""),IF(_xlpm.x="","Exceeds consumer tank list",_xlpm.x)) -> 30 | G62: =IF(AND(ISNUMBER(I62),F62>0),I62/(0.0834*F62),NA()) -> 3.3813726 | H62: %/hr | I62: =_xlfn.LET(_xlpm.re,$C$3,_xlpm.vr,F62,_xlpm.qin,E62,_xlpm.uef,IF(_xlpm.vr<=55,0.692-0.0013*_xlpm.vr,0.8072-0.0003*_xlpm.vr),_xlpm.qload,$B$134*$B$138*$B$139*($B$135-$B$136),_xlpm.dT,$B$135-$B$137,((_xlpm.re/_xlpm.uef)-1)/(_xlpm.dT*(24/_xlpm.qload)-_xlpm.dT/(_xlpm.qin*_xlpm.uef))) -> 8.4601943 | J62: Btu/h·°F | K62: Same CZ column layout as SchoolK8 HPWH / OfficeSmall. I is tank UA (Btu/h·°F) from Maguire & Roberts 2020 / OpenStudio-HPXML (consumer UEF test). G = I/(0.0834×F) %/hr (same conversion as school HPWH). J is Btu/h·°F. EnergyPlus Off-Cycle and On-Cycle {W/K} = I×0.527527 (cell B139); same number in both fields. Not DEER commercial HPWH UA 4.37 and not Title 20 Table F-4.
A63: CZ02 | B63: 50.8 | C63: =$B$52*($B$55-B63)*$B$57 -> 502.43352 | D63: =C63*$B$56 -> 301.46011 | E63: =_xlfn.LET(_xlpm.x,IFERROR(_xlfn.XLOOKUP(D63/$C$3,$A$120:$A$128,$A$120:$A$128,"",1),""),IF(_xlpm.x="","Exceeds consumer input list",_xlpm.x)) -> 30000 | F63: =_xlfn.LET(_xlpm.x,IFERROR(_xlfn.XLOOKUP(MAX(30,$B$52*$B$58),$E$120:$E$124,$E$120:$E$124,"",1),""),IF(_xlpm.x="","Exceeds consumer tank list",_xlpm.x)) -> 30 | G63: =IF(AND(ISNUMBER(I63),F63>0),I63/(0.0834*F63),NA()) -> 3.3813726 | H63: %/hr | I63: =_xlfn.LET(_xlpm.re,$C$3,_xlpm.vr,F63,_xlpm.qin,E63,_xlpm.uef,IF(_xlpm.vr<=55,0.692-0.0013*_xlpm.vr,0.8072-0.0003*_xlpm.vr),_xlpm.qload,$B$134*$B$138*$B$139*($B$135-$B$136),_xlpm.dT,$B$135-$B$137,((_xlpm.re/_xlpm.uef)-1)/(_xlpm.dT*(24/_xlpm.qload)-_xlpm.dT/(_xlpm.qin*_xlpm.uef))) -> 8.4601943 | J63: Btu/h·°F
A64: CZ03 | B64: 52.2 | C64: =$B$52*($B$55-B64)*$B$57 -> 494.07952 | D64: =C64*$B$56 -> 296.44771 | E64: =_xlfn.LET(_xlpm.x,IFERROR(_xlfn.XLOOKUP(D64/$C$3,$A$120:$A$128,$A$120:$A$128,"",1),""),IF(_xlpm.x="","Exceeds consumer input list",_xlpm.x)) -> 30000 | F64: =_xlfn.LET(_xlpm.x,IFERROR(_xlfn.XLOOKUP(MAX(30,$B$52*$B$58),$E$120:$E$124,$E$120:$E$124,"",1),""),IF(_xlpm.x="","Exceeds consumer tank list",_xlpm.x)) -> 30 | G64: =IF(AND(ISNUMBER(I64),F64>0),I64/(0.0834*F64),NA()) -> 3.3813726 | H64: %/hr | I64: =_xlfn.LET(_xlpm.re,$C$3,_xlpm.vr,F64,_xlpm.qin,E64,_xlpm.uef,IF(_xlpm.vr<=55,0.692-0.0013*_xlpm.vr,0.8072-0.0003*_xlpm.vr),_xlpm.qload,$B$134*$B$138*$B$139*($B$135-$B$136),_xlpm.dT,$B$135-$B$137,((_xlpm.re/_xlpm.uef)-1)/(_xlpm.dT*(24/_xlpm.qload)-_xlpm.dT/(_xlpm.qin*_xlpm.uef))) -> 8.4601943 | J64: Btu/h·°F
A65: CZ04 | B65: 52.7 | C65: =$B$52*($B$55-B65)*$B$57 -> 491.09595 | D65: =C65*$B$56 -> 294.65757 | E65: =_xlfn.LET(_xlpm.x,IFERROR(_xlfn.XLOOKUP(D65/$C$3,$A$120:$A$128,$A$120:$A$128,"",1),""),IF(_xlpm.x="","Exceeds consumer input list",_xlpm.x)) -> 30000 | F65: =_xlfn.LET(_xlpm.x,IFERROR(_xlfn.XLOOKUP(MAX(30,$B$52*$B$58),$E$120:$E$124,$E$120:$E$124,"",1),""),IF(_xlpm.x="","Exceeds consumer tank list",_xlpm.x)) -> 30 | G65: =IF(AND(ISNUMBER(I65),F65>0),I65/(0.0834*F65),NA()) -> 3.3813726 | H65: %/hr | I65: =_xlfn.LET(_xlpm.re,$C$3,_xlpm.vr,F65,_xlpm.qin,E65,_xlpm.uef,IF(_xlpm.vr<=55,0.692-0.0013*_xlpm.vr,0.8072-0.0003*_xlpm.vr),_xlpm.qload,$B$134*$B$138*$B$139*($B$135-$B$136),_xlpm.dT,$B$135-$B$137,((_xlpm.re/_xlpm.uef)-1)/(_xlpm.dT*(24/_xlpm.qload)-_xlpm.dT/(_xlpm.qin*_xlpm.uef))) -> 8.4601943 | J65: Btu/h·°F
