Workbook
Name nonparticipating_forecastzone_scale_factor: #REF!
Name nonparticipating_forecastzone_scale_factor: 'Energy Usage'!#REF!
Name Space_Function: Data!$A$2:$A$76

Sheet Notes
A1: Data Sources
A2: Dataset | B2: Dodge 2023
B3: CBECS 2018
B4: ResStock 2023
A5: Prototype | B5: CEC prototype (CBECC 2022.3.1) | C5: https://bees.noresco.com/software2022.html
B6: PNNL prototype (90.1-2022) | C6: https://www.energycodes.gov/prototype-building-models#Commercial
A9: Codes | B9: Title 24, part 6, referred to as T24 (1986, 1992, 2001, 2007, 2013, 2016, 2019, 2022, 2025)
B10: ASHRAE 90.1 (2022)
B11: CFR Title 10 (2009) | C11: https://www.govinfo.gov/content/pkg/FR-2009-03-23/pdf/FR-2009-03-23.pdf
B12: CFR Title 10 ( 2013) | C12: https://www.govinfo.gov/content/pkg/CFR-2013-title10-vol3/pdf/CFR-2013-title10-vol3-part431.pdf
B13: CFR Title 10 ( 2024) | C13: https://www.govinfo.gov/content/pkg/CFR-2024-title10-vol3/pdf/CFR-2024-title10-vol3-part431-subpartF.pdf
A15: Others | B15: ACM (2013, 2019, 2022, 2025)
B16: Title 24, 2022 - Appendix 5.4A and Appendix 5.4B | C16: https://www.energy.ca.gov/publications/2022/2022-nonresidential-and-multifamily-alternative-calculation-method-reference
B17: 2022 Reduced infiltration CASE report | C17: https://title24stakeholders.com/wp-content/uploads/2020/10/2022-T24-Final-CASE-Report_Reduce-Infiltration.pdf
B18: 2019 Outdoor Lighting CASE Report | C18: https://title24stakeholders.com/wp-content/uploads/2016/10/T24-2019-CASE-Study-Results-Report-Outdoor-Sources_Final_with-Attachments.pdf
B19: PNNL 20405, 2010 | C19: https://www.pnnl.gov/main/publications/external/technical_reports/PNNL-20405.pdf
A21: Construction Rate
A34: Notes

Sheet Prototype
A1: NORESCO, Updated November 2025
A2: ApartmentHighRise
A3: Characteristic | B3: Value | C3: Data Sources
A4: Building Type | B4: High-Rise Apartment
A5: Building Category | B5: Nonresidential
A6: Vintages | B6: 4 Vintages: Pre-1978 , 1978-1997 ,1998-2007 , 2008-2018 New Construction (2019+) | C6: Based on the vintage bin analysis | D6: NonRes-Vintage bins-Draft Report-30Nov2023-Final.docx
A7: Shape | C7: CEC Prototype model TRC Multifamily Prototypes study (2019)
A8: Total Floor Area (ft2) | B8: =Zones!J35 -> 150494.91 | C8: CEC Prototype model TRC Multifamily Prototypes study (2019)
A9: Aspect Ratio | B9: =190/66 -> 2.8787879
A10: Number of Floors | B10: 10 above-ground floors plus two underground parking garage (190 ft x 66 ft)
A11: Roof type | B11: Flat roof
A12: WWR (above grade) | B12: South: 37.0%, East: 37.0%, North: 37.0%, West: 37.0% Total 37.0%
A13: Window dimensions | B13: 5 * 3
A14: Shading Geometry | B14: -
A15: Floor to floor height (feet) | B15: Residential: 10 Non-residential: 10 Parking: 15
A16: Floor to ceiling height (feet) | B16: Residential: 9 Non-residential: 10 Parking: 14
A17: Glazing sill height (feet) | B17: 3.1 ft (in first floor), 3.0 ft. (in upper floors)
A21: Above grade wall area (ft²) | B21: 51205
A22: Gross wall area (ft²) | B22: 61446
A23: Roof area (ft²) | B23: 12541.22
A24: Underground Gross Wall Area (ft²) | B24: =B22-B21 -> 10241

Sheet Zones
A1: ="Proposed Layout - "&Prototype!A2 -> Proposed Layout - ApartmentHighRise
A2: Space Type | B2: Space/Thermal Zone | C2: Res/NR | D2: Schedule Category | E2: No. of Dwelling Units | F2: Dwelling Unit Type | G2: HVAC System Name (HVAC Zone) | H2: Conditioned [Y/N] | I2: Area Fraction | J2: Area (ft²) | K2: Volume [ft³] | L2: Multipliers | M2: People | N2: People (Persons/1,000 ft²) [T24, 2025,Table 120.1-A]
A3: Convention, Conference, Multipurpose and Meeting Area | B3: F1 BUSINESS CENTER | C3: NR | D3: ResidentialCommon | E3: NA | F3: NA | G3: AHU1 | H3: Y | I3: =J3*L3/$J$35 -> 0.0031898089 | J3: 480.05 | K3: 4800.7 | L3: 1 | M3: =N3*J3/1000 -> 32.019335 | N3: 66.7 | P3: Spaces and Zoning layout | T3: Spaces and Zoning layout
A4: Exercise/Fitness Center and Gymnasium Areas | B4: F1 FITNESS CENTER | C4: NR | D4: ResidentialCommon | E4: NA | F4: NA | G4: AHU2 | H4: Y | I4: =J4*L4/$J$35 -> 0.0055821157 | J4: 840.08 | K4: 8401.23 | L4: 1 | M4: =N4*J4/1000 -> 16.8016 | N4: 20
A5: Office Area (>250 square feet) | B5: F1 LEASING OFFICE | C5: NR | D5: ResidentialCommon | E5: NA | F5: NA | G5: AHU3 | H5: Y | I5: =J5*L5/$J$35 -> 0.0011961866 | J5: 180.02 | K5: 1800.26 | L5: 1 | M5: =N5*J5/1000 -> 1.8002 | N5: 10
A6: Lobby, Main Entry | B6: F1 LOUNGE | C6: NR | D6: ResidentialCommon | E6: NA | F6: NA | G6: AHU4 | H6: Y | I6: =J6*L6/$J$35 -> 0.010207322 | J6: 1536.15 | K6: 15362.25 | L6: 1 | M6: =N6*J6/1000 -> 102.46121 | N6: 66.7
A7: Retail Space | B7: F1 RETAIL E CORE | C7: NR | D7: Retail | E7: NA | F7: NA | G7: AHU5 | H7: Y | I7: =J7*L7/$J$35 -> 0.021052606 | J7: 3168.31 | K7: 31684.64 | L7: 1 | M7: =N7*J7/1000 -> 52.910777 | N7: 16.7
A8: Retail Space | B8: F1 RETAIL E OUTER | C8: NR | D8: Retail | E8: NA | F8: NA | G8: AHU6 | H8: Y | I8: =J8*L8/$J$35 -> 0.01052627 | J8: 1584.15 | K8: 15842.32 | L8: 1 | M8: =N8*J8/1000 -> 26.455305 | N8: 16.7
A9: Retail Space | B9: F1 RETAIL W CORE | C9: NR | D9: Retail | E9: NA | F9: NA | G9: AHU7 | H9: Y | I9: =J9*L9/$J$35 -> 0.021052606 | J9: 3168.31 | K9: 31684.64 | L9: 1 | M9: =N9*J9/1000 -> 52.910777 | N9: 16.7
A10: Retail Space | B10: F1 RETAIL W OUTER | C10: NR | D10: Retail | E10: NA | F10: NA | G10: AHU8 | H10: Y | I10: =J10*L10/$J$35 -> 0.01052627 | J10: 1584.15 | K10: 15842.32 | L10: 1 | M10: =N10*J10/1000 -> 26.455305 | N10: 16.7
A11: High-Rise Residential Living Spaces | B11: F10 1-BED N | C11: Res | D11: ResidentialLiving | E11: =L11 -> 1 | F11: 1-Bed Type | G11: AHU9 | H11: Y | I11: =J11*L11/$J$35 -> 0.010366796 | J11: 1560.15 | K11: 15602.28 | L11: 1 | M11: =N11*J11/1000 -> 7.80075 | N11: 5
A12: High-Rise Residential Living Spaces | B12: F10 1-BED SE | C12: Res | D12: ResidentialLiving | E12: =L12 -> 1 | F12: 1-Bed Type | G12: AHU10 | H12: Y | I12: =J12*L12/$J$35 -> 0.010366796 | J12: 1560.15 | K12: 15602.28 | L12: 1 | M12: =N12*J12/1000 -> 7.80075 | N12: 5
A13: High-Rise Residential Living Spaces | B13: F10 1-BED SW | C13: Res | D13: ResidentialLiving | E13: =L13 -> 1 | F13: 1-Bed Type | G13: AHU11 | H13: Y | I13: =J13*L13/$J$35 -> 0.010366796 | J13: 1560.15 | K13: 15602.28 | L13: 1 | M13: =N13*J13/1000 -> 7.80075 | N13: 5
A14: High-Rise Residential Living Spaces | B14: F10 2-BED N CORE | C14: Res | D14: ResidentialLiving | E14: =L14 -> 1 | F14: 2-Bed Type | G14: AHU12 | H14: N | I14: =J14*L14/$J$35 -> 0.0071770534 | J14: 1080.11 | K14: 10801.58 | L14: 1 | M14: =N14*J14/1000 -> 5.40055 | N14: 5
A15: High-Rise Residential Living Spaces | B15: F10 2-BED NE | C15: Res | D15: ResidentialLiving | E15: =L15 -> 1 | F15: 2-Bed Type | G15: AHU13 | H15: Y | I15: =J15*L15/$J$35 -> 0.0071770534 | J15: 1080.11 | K15: 10801.58 | L15: 1 | M15: =N15*J15/1000 -> 5.40055 | N15: 5
A16: High-Rise Residential Living Spaces | B16: F10 2-BED NW | C16: Res | D16: ResidentialLiving | E16: =L16 -> 1 | F16: 2-Bed Type | G16: AHU14 | H16: Y | I16: =J16*L16/$J$35 -> 0.0071770534 | J16: 1080.11 | K16: 10801.58 | L16: 1 | M16: =N16*J16/1000 -> 5.40055 | N16: 5
A17: High-Rise Residential Living Spaces | B17: F10 2-BED SE | C17: Res | D17: ResidentialLiving | E17: =L17 -> 1 | F17: 2-Bed Type | G17: AHU15 | H17: Y | I17: =J17*L17/$J$35 -> 0.0071770534 | J17: 1080.11 | K17: 10801.58 | L17: 1 | M17: =N17*J17/1000 -> 5.40055 | N17: 5
A18: High-Rise Residential Living Spaces | B18: F10 2-BED SW | C18: Res | D18: ResidentialLiving | E18: =L18 -> 1 | F18: 2-Bed Type | G18: AHU16 | H18: Y | I18: =J18*L18/$J$35 -> 0.0071770534 | J18: 1080.11 | K18: 10801.58 | L18: 1 | M18: =N18*J18/1000 -> 5.40055 | N18: 5
A19: Corridor Area | B19: F10 CORRIDOR | C19: NR | D19: ResidentialCommon | E19: NA | F19: NA | G19: AHU17 | H19: Y | I19: =J19*L19/$J$35 -> 0.007974489 | J19: 1200.12 | K19: 12001.76 | L19: 1 | M19: =N19*J19/1000 -> 12.0012 | N19: 10
A20: Laundry Area | B20: F10 LAUNDRY | C20: NR | D20: ResidentialCommon | E20: NA | F20: NA | G20: AHU18 | H20: Y | I20: =J20*L20/$J$35 -> 0.0011961866 | J20: 180.02 | K20: 1800.26 | L20: 1 | M20: =N20*J20/1000 -> 1.8002 | N20: 10
A21: High-Rise Residential Living Spaces | B21: F10 STUDIO N | C21: Res | D21: ResidentialLiving | E21: =L21 -> 1 | F21: Studio Type | G21: AHU19 | H21: Y | I21: =J21*L21/$J$35 -> 0.0071770534 | J21: 1080.11 | K21: 10801.58 | L21: 1 | M21: =N21*J21/1000 -> 5.40055 | N21: 5
A22: High-Rise Residential Living Spaces | B22: F2-9 1-BED N | C22: Res | D22: ResidentialLiving | E22: =L22 -> 8 | F22: 1-Bed Type | G22: AHU20 | H22: Y | I22: =J22*L22/$J$35 -> 0.082934366 | J22: 1560.15 | K22: 15602.28 | L22: 8 | M22: =N22*J22/1000 -> 7.80075 | N22: 5
A23: High-Rise Residential Living Spaces | B23: F2-9 1-BED SE | C23: Res | D23: ResidentialLiving | E23: =L23 -> 8 | F23: 1-Bed Type | G23: AHU21 | H23: Y | I23: =J23*L23/$J$35 -> 0.082934366 | J23: 1560.15 | K23: 15602.28 | L23: 8 | M23: =N23*J23/1000 -> 7.80075 | N23: 5
A24: High-Rise Residential Living Spaces | B24: F2-9 1-BED SW | C24: Res | D24: ResidentialLiving | E24: =L24 -> 8 | F24: 2-Bed Type | G24: AHU22 | H24: Y | I24: =J24*L24/$J$35 -> 0.082934366 | J24: 1560.15 | K24: 15602.28 | L24: 8 | M24: =N24*J24/1000 -> 7.80075 | N24: 5
A25: High-Rise Residential Living Spaces | B25: F2-9 2-BED N CORE | C25: Res | D25: ResidentialLiving | E25: =L25 -> 8 | F25: 2-Bed Type | G25: AHU23 | H25: Y | I25: =J25*L25/$J$35 -> 0.057416427 | J25: 1080.11 | K25: 10801.58 | L25: 8 | M25: =N25*J25/1000 -> 5.40055 | N25: 5
A26: High-Rise Residential Living Spaces | B26: F2-9 2-BED NE | C26: Res | D26: ResidentialLiving | E26: =L26 -> 8 | F26: 2-Bed Type | G26: AHU24 | H26: Y | I26: =J26*L26/$J$35 -> 0.057416427 | J26: 1080.11 | K26: 10801.58 | L26: 8 | M26: =N26*J26/1000 -> 5.40055 | N26: 5
A27: High-Rise Residential Living Spaces | B27: F2-9 2-BED NW | C27: Res | D27: ResidentialLiving | E27: =L27 -> 8 | F27: 2-Bed Type | G27: AHU25 | H27: Y | I27: =J27*L27/$J$35 -> 0.057416427 | J27: 1080.11 | K27: 10801.58 | L27: 8 | M27: =N27*J27/1000 -> 5.40055 | N27: 5
A28: High-Rise Residential Living Spaces | B28: F2-9 2-BED SE | C28: Res | D28: ResidentialLiving | E28: =L28 -> 8 | F28: 2-Bed Type | G28: AHU26 | H28: Y | I28: =J28*L28/$J$35 -> 0.057416427 | J28: 1080.11 | K28: 10801.58 | L28: 8 | M28: =N28*J28/1000 -> 5.40055 | N28: 5
A29: High-Rise Residential Living Spaces | B29: F2-9 2-BED SW | C29: Res | D29: ResidentialLiving | E29: =L29 -> 8 | F29: 2-Bed Type | G29: AHU27 | H29: Y | I29: =J29*L29/$J$35 -> 0.057416427 | J29: 1080.11 | K29: 10801.58 | L29: 8 | M29: =N29*J29/1000 -> 5.40055 | N29: 5
A30: Corridor Area | B30: F2-9 CORRIDOR | C30: NR | D30: ResidentialCommon | E30: NA | F30: NA | G30: AHU28 | H30: Y | I30: =J30*L30/$J$35 -> 0.063795912 | J30: 1200.12 | K30: 12001.76 | L30: 8 | M30: =N30*J30/1000 -> 12.0012 | N30: 10
A31: Laundry Area | B31: F2-9 LAUNDRY | C31: NR | D31: ResidentialCommon | E31: NA | F31: NA | G31: AHU29 | H31: Y | I31: =J31*L31/$J$35 -> 0.0095694931 | J31: 180.02 | K31: 1800.26 | L31: 8 | M31: =N31*J31/1000 -> 1.8002 | N31: 10
A32: High-Rise Residential Living Spaces | B32: F2-9 STUDIO N | C32: Res | D32: ResidentialLiving | E32: =L32 -> 8 | F32: Studio Type | G32: AHU30 | H32: Y | I32: =J32*L32/$J$35 -> 0.057416427 | J32: 1080.11 | K32: 10801.58 | L32: 8 | M32: =N32*J32/1000 -> 5.40055 | N32: 5
A33: Parking Garage Area (Parking Zone and Ramps) | B33: L1 PARKING GARAGE | C33: NR | D33: ResidentialCommon | E33: =L33 -> 1 | F33: NA | G33: none | H33: N | I33: =J33*L33/$J$35 -> 0.083333184 | J33: 12541.22 | K33: 125418.36 | L33: 1 | M33: =N33*J33/1000 -> 62.7061 | N33: 5
A34: Parking Garage Area (Parking Zone and Ramps) | B34: L2 PARKING GARAGE | C34: NR | D34: ResidentialCommon | E34: =L34 -> 1 | F34: NA | G34: none | H34: N | I34: =J34*L34/$J$35 -> 0.083333184 | J34: 12541.22 | K34: 125418.36 | L34: 1 | M34: =N34*J34/1000 -> 62.7061 | N34: 5
A35: Total (11 Space Types) | B35: Total (32 Spaces) | E35: Total (83 Dwelling Units) | F35: Total (4 Dwelling Unit Types) | G35: Total (112 Thermal Zones) | H35: Total (30 Conditioned Zones, 1 Unconditioned Zones) | I35: =SUM(I3:I34) -> 1 | J35: =SUMPRODUCT(J3:J34,L3:L34) -> 150494.91 | K35: =SUM(K3:K34) -> 627091.76 | M35: =SUM(M3:M34) -> 576.4406
A42: Background Data [To be deleted prior to publication]
B48: Zone Summary
E50: Area [ft2] | F50: Conditioned (Y/N) | G50: Part of Total Floor Area (Y/N) | H50: Volume [ft3] | I50: Multipliers | J50: Above Ground Gross Wall Area [ft2] | K50: Underground Gross Wall Area [ft2] | L50: Window Glass Area [ft2] | M50: Opening Area [ft2] | N50: Lighting [Btu/h-ft2] | O50: People [ft2 per person]
B51: THERMAL ZONE: F1 BUSINESS CENTER | E51: 480.05 | F51: Yes | G51: Yes | H51: 4800.7 | I51: 1 | J51: 160.02 | K51: 0 | L51: 16 | M51: 16 | N51: 2.2176 | O51: 200.02 | P51: Plug and Process [Btu/h-ft2]
B52: THERMAL ZONE: F1 FITNESS CENTER | E52: 840.08 | F52: Yes | G52: Yes | H52: 8401.23 | I52: 1 | J52: 280.03 | K52: 0 | L52: 28 | M52: 28 | N52: 1.7058 | O52: 100.01 | P52: 5.1175
...

Sheet Envelope
A1: ="Envelope - "&Prototype!A2 -> Envelope - ApartmentHighRise
A2: Element | B2: Prototype | C2: Assembly Type | D2: Construction | E2: Thermal Properties | F2: Vintage | G2: Selected T24 | I2: Note | J2: CZ1 | K2: CZ2 | L2: CZ3 | M2: CZ4 | N2: CZ5 | O2: CZ6 | P2: CZ7 | Q2: CZ8 | R2: CZ9 | S2: CZ10 | T2: CZ11 | U2: CZ12 | V2: CZ13 | W2: CZ14 | X2: CZ15 | Y2: CZ16
A3: External Wall_Podium (F1) | B3: =Prototype!$A$2 -> ApartmentHighRise | C3: ExtWall_MassLight_Nonres | D3: 8-in cast-in-place concrete wall + insulation + air/water barrier + exterior cladding + gypsum board | E3: U-factor IP | F3: Pre 1978 | G3: N/A | I3: ASHRAE 90.1, 2022, Table A3.3.3.1, 3.5", R-0 | J3: 0.352 | K3: 0.352 | L3: 0.352 | M3: 0.352 | N3: 0.352 | O3: 0.352 | P3: 0.352 | Q3: 0.352 | R3: 0.352 | S3: 0.352 | T3: 0.352 | U3: 0.352 | V3: 0.352 | W3: 0.352 | X3: 0.352 | Y3: 0.352
F4: 1978-1997 | G4: 1986 | I4: Copied from High-rise office alternative requirements (Table 2-53W): Package A with heat capacity around 10 (Btu/F-ft²) | J4: 0.213 | K4: 0.227 | L4: 0.227 | M4: 0.217 | N4: 0.217 | O4: 0.256 | P4: 0.256 | Q4: 0.256 | R4: 0.256 | S4: 0.256 | T4: 0.238 | U4: 0.238 | V4: 0.238 | W4: 0.208 | X4: 0.208 | Y4: 0.213
F5: 1998-2007 | G5: 2001 | I5: Table 1-H | J5: 0.182 | K5: 0.182 | L5: 0.189 | M5: 0.189 | N5: 0.189 | O5: 0.189 | P5: 0.189 | Q5: 0.189 | R5: 0.189 | S5: 0.182 | T5: 0.182 | U5: 0.182 | V5: 0.182 | W5: 0.182 | X5: 0.182 | Y5: 0.182
F6: 2008-2018 | G6: 2013 | I6: Table 140.3-B | J6: 0.098 | K6: 0.062 | L6: 0.082 | M6: 0.062 | N6: 0.062 | O6: 0.098 | P6: 0.098 | Q6: 0.062 | R6: 0.062 | S6: 0.062 | T6: 0.062 | U6: 0.062 | V6: 0.062 | W6: 0.062 | X6: 0.062 | Y6: 0.062
F7: 2019+ | G7: 2025 | I7: Table 140.3-B (Nonres) | J7: 0.06 | K7: 0.055 | L7: 0.071 | M7: 0.055 | N7: 0.055 | O7: 0.06 | P7: 0.06 | Q7: 0.055 | R7: 0.055 | S7: 0.055 | T7: 0.055 | U7: 0.055 | V7: 0.055 | W7: 0.055 | X7: 0.055 | Y7: 0.055
A8: External Wall | B8: =Prototype!$A$2 -> ApartmentHighRise | C8: ExtWall_MetalFramed_Res | D8: Steel-frame walls + insulation + Gypsum board | E8: U-factor IP | F8: Pre 1978 | G8: N/A | I8: ASHRAE 90.1 Table A3.4.3.1, 3.5", R-0 | J8: 0.292 | K8: 0.292 | L8: 0.292 | M8: 0.292 | N8: 0.292 | O8: 0.292 | P8: 0.292 | Q8: 0.292 | R8: 0.292 | S8: 0.292 | T8: 0.292 | U8: 0.292 | V8: 0.292 | W8: 0.292 | X8: 0.292 | Y8: 0.292
F9: 1978-1997 | G9: 1986 | I9: Title 24 1984 Table 2-53 BB, wall density less than 25 | J9: 0.095 | K9: 0.095 | L9: 0.095 | M9: 0.095 | N9: 0.095 | O9: 0.095 | P9: 0.095 | Q9: 0.095 | R9: 0.095 | S9: 0.095 | T9: 0.095 | U9: 0.095 | V9: 0.095 | W9: 0.095 | X9: 0.095 | Y9: 0.095
F10: 1998-2007 | G10: 2001 | I10: TABLE 1-I | J10: 0.14 | K10: 0.175 | L10: 0.181 | M10: 0.181 | N10: 0.181 | O10: 0.181 | P10: 0.181 | Q10: 0.181 | R10: 0.181 | S10: 0.175 | T10: 0.175 | U10: 0.175 | V10: 0.175 | W10: 0.175 | X10: 0.175 | Y10: 0.14
F11: 2008-2018 | G11: 2013 | I11: TABLE 140.3-B | J11: 0.105 | K11: 0.105 | L11: 0.105 | M11: 0.105 | N11: 0.105 | O11: 0.105 | P11: 0.105 | Q11: 0.105 | R11: 0.105 | S11: 0.105 | T11: 0.105 | U11: 0.105 | V11: 0.105 | W11: 0.105 | X11: 0.105 | Y11: 0.105
F12: 2019+ | G12: 2025 | I12: TABLE 170.2-A ENVELOPE COMPONENT PACKAGE – Multifamily Standard Building Design Assuming - >1hr fire rating | J12: 0.051 | K12: 0.051 | L12: 0.051 | M12: 0.051 | N12: 0.051 | O12: 0.065 | P12: 0.065 | Q12: 0.051 | R12: 0.051 | S12: 0.051 | T12: 0.051 | U12: 0.051 | V12: 0.051 | W12: 0.051 | X12: 0.051 | Y12: 0.051
A13: Roof | B13: =Prototype!$A$2 -> ApartmentHighRise | C13: FlatRoof_WoodFramedAndOther_Res | D13: Roof membrane or shingles + roof insulation + wood decking/sheathing + wood framing | E13: U-factor IP | F13: Pre 1978 | G13: N/A | I13: Considering 30 years for roof/ insulation replacement. | J13: 0.037 | K13: 0.051 | L13: 0.051 | M13: 0.051 | N13: 0.051 | O13: 0.051 | P13: 0.051 | Q13: 0.051 | R13: 0.051 | S13: 0.051 | T13: 0.037 | U13: 0.037 | V13: 0.037 | W13: 0.037 | X13: 0.037 | Y13: 0.037
F14: 1978-1997 | G14: 1992 | J14: 0.037 | K14: 0.051 | L14: 0.051 | M14: 0.051 | N14: 0.051 | O14: 0.051 | P14: 0.051 | Q14: 0.051 | R14: 0.051 | S14: 0.051 | T14: 0.037 | U14: 0.037 | V14: 0.037 | W14: 0.037 | X14: 0.037 | Y14: 0.037
F15: 1998-2007 | G15: 2001 | I15: TABLE 1-I | J15: 0.037 | K15: 0.037 | L15: 0.051 | M15: 0.051 | N15: 0.051 | O15: 0.051 | P15: 0.051 | Q15: 0.051 | R15: 0.051 | S15: 0.037 | T15: 0.037 | U15: 0.037 | V15: 0.037 | W15: 0.037 | X15: 0.037 | Y15: 0.037
F16: 2008-2018 | G16: 2013 | I16: TABLE 140.3-C | J16: 0.034 | K16: 0.028 | L16: 0.039 | M16: 0.028 | N16: 0.039 | O16: 0.039 | P16: 0.039 | Q16: 0.028 | R16: 0.028 | S16: 0.028 | T16: 0.028 | U16: 0.028 | V16: 0.028 | W16: 0.028 | X16: 0.028 | Y16: 0.028
F17: 2019+ | G17: 2025 | I17: TABLE 170.2-A ENVELOPE COMPONENT PACKAGE – Multifamily Standard Building Design | J17: 0.028 | K17: 0.028 | L17: 0.034 | M17: 0.028 | N17: 0.034 | O17: 0.034 | P17: 0.039 | Q17: 0.028 | R17: 0.028 | S17: 0.028 | T17: 0.028 | U17: 0.028 | V17: 0.028 | W17: 0.028 | X17: 0.028 | Y17: 0.028
A18: Windows_ Dwelling Units | B18: =Prototype!$A$2 -> ApartmentHighRise | C18: FixedAndOperableWindow_Res | D18: CBECS 2018 shows that ~58% of Large Hotels that were built before 2000 are single pane | E18: U-factor | F18: Pre 1978 | G18: N/A | I18: ASHRAE Handbook of Fundamentals for single pane & T24, 2013 for double pane (58%-42%) | J18: =0.42*J21+0.58*((1-$C$59)*1.12+$C$59*1.23) -> 0.82725 | K18: =0.42*K21+0.58*((1-$C$59)*1.12+$C$59*1.23) -> 0.82725 | L18: =0.42*L21+0.58*((1-$C$59)*1.12+$C$59*1.23) -> 0.82725 | M18: =0.42*M21+0.58*((1-$C$59)*1.12+$C$59*1.23) -> 0.82725 | N18: =0.42*N21+0.58*((1-$C$59)*1.12+$C$59*1.23) -> 0.82725 | O18: =0.42*O21+0.58*((1-$C$59)*1.12+$C$59*1.23) -> 0.82725 | P18: =0.42*P21+0.58*((1-$C$59)*1.12+$C$59*1.23) -> 0.82725 | Q18: =0.42*Q21+0.58*((1-$C$59)*1.12+$C$59*1.23) -> 0.82725 | ... Y18: =0.42*Y21+0.58*((1-$C$59)*1.12+$C$59*1.23) -> 0.82725
F19: 1978-1997 | G19: N/A | J19: =0.42*J21+0.58*((1-$C$59)*1.12+$C$59*1.23) -> 0.82725 | K19: =0.42*K21+0.58*((1-$C$59)*1.12+$C$59*1.23) -> 0.82725 | L19: =0.42*L21+0.58*((1-$C$59)*1.12+$C$59*1.23) -> 0.82725 | M19: =0.42*M21+0.58*((1-$C$59)*1.12+$C$59*1.23) -> 0.82725 | N19: =0.42*N21+0.58*((1-$C$59)*1.12+$C$59*1.23) -> 0.82725 | O19: =0.42*O21+0.58*((1-$C$59)*1.12+$C$59*1.23) -> 0.82725 | P19: =0.42*P21+0.58*((1-$C$59)*1.12+$C$59*1.23) -> 0.82725 | Q19: =0.42*Q21+0.58*((1-$C$59)*1.12+$C$59*1.23) -> 0.82725 | ... Y19: =0.42*Y21+0.58*((1-$C$59)*1.12+$C$59*1.23) -> 0.82725
D20: Double pane | F20: 1998-2007 | G20: 2001 | I20: Table 1-I | J20: =(1-$C$59)*L78+$C$59*L98 -> 0.49 | K20: =(1-$C$59)*M78+$C$59*M98 -> 0.49 | L20: =(1-$C$59)*N78+$C$59*N98 -> 0.49 | M20: =(1-$C$59)*O78+$C$59*O98 -> 0.49 | N20: =(1-$C$59)*P78+$C$59*P98 -> 0.49 | O20: =(1-$C$59)*Q78+$C$59*Q98 -> 0.49 | P20: =(1-$C$59)*R78+$C$59*R98 -> 0.49 | Q20: =(1-$C$59)*S78+$C$59*S98 -> 0.49 | ... Y20: =(1-$C$59)*AA78+$C$59*AA98 -> 0.49
F21: 2008-2018 | G21: 2013 | I21: Table 140.3-C | J21: =(1-$C$59)*L79+$C$59*L99 -> 0.385 | K21: =(1-$C$59)*M79+$C$59*M99 -> 0.385 | L21: =(1-$C$59)*N79+$C$59*N99 -> 0.385 | M21: =(1-$C$59)*O79+$C$59*O99 -> 0.385 | N21: =(1-$C$59)*P79+$C$59*P99 -> 0.385 | O21: =(1-$C$59)*Q79+$C$59*Q99 -> 0.385 | P21: =(1-$C$59)*R79+$C$59*R99 -> 0.385 | Q21: =(1-$C$59)*S79+$C$59*S99 -> 0.385 | ... Y21: =(1-$C$59)*AA79+$C$59*AA99 -> 0.385
F22: 2019+ | G22: 2025 | I22: TABLE 170.2-A (High rise residential in multifamily section) | J22: =(1-$C$59)*L80+$C$59*L100 -> 0.325 | K22: =(1-$C$59)*M80+$C$59*M100 -> 0.34 | L22: =(1-$C$59)*N80+$C$59*N100 -> 0.325 | M22: =(1-$C$59)*O80+$C$59*O100 -> 0.325 | N22: =(1-$C$59)*P80+$C$59*P100 -> 0.325 | O22: =(1-$C$59)*Q80+$C$59*Q100 -> 0.37 | P22: =(1-$C$59)*R80+$C$59*R100 -> 0.37 | Q22: =(1-$C$59)*S80+$C$59*S100 -> 0.34 | ... Y22: =(1-$C$59)*AA80+$C$59*AA100 -> 0.325
D23: CBECS 2018 shows that ~58% of Large Hotels that were built before 2000 are single pane | E23: SHGC | F23: Pre 1978 | G23: N/A | I23: =I18 -> ASHRAE Handbook of Fundamentals for single pane & T24, 2013 for double pane (58%-42%) | J23: =0.42*J26+0.58*((1-$C$59)*0.79+$C$59*0.78) -> 0.5586 | K23: =0.42*K26+0.58*((1-$C$59)*0.79+$C$59*0.78) -> 0.5586 | L23: =0.42*L26+0.58*((1-$C$59)*0.79+$C$59*0.78) -> 0.5586 | M23: =0.42*M26+0.58*((1-$C$59)*0.79+$C$59*0.78) -> 0.5586 | N23: =0.42*N26+0.58*((1-$C$59)*0.79+$C$59*0.78) -> 0.5586 | O23: =0.42*O26+0.58*((1-$C$59)*0.79+$C$59*0.78) -> 0.5586 | P23: =0.42*P26+0.58*((1-$C$59)*0.79+$C$59*0.78) -> 0.5586 | Q23: =0.42*Q26+0.58*((1-$C$59)*0.79+$C$59*0.78) -> 0.5586 | ... Y23: =0.42*Y26+0.58*((1-$C$59)*0.79+$C$59*0.78) -> 0.5586
F24: 1978-1997 | G24: N/A | J24: =0.42*J26+0.58*((1-$C$59)*0.79+$C$59*0.78) -> 0.5586 | K24: =0.42*K26+0.58*((1-$C$59)*0.79+$C$59*0.78) -> 0.5586 | L24: =0.42*L26+0.58*((1-$C$59)*0.79+$C$59*0.78) -> 0.5586 | M24: =0.42*M26+0.58*((1-$C$59)*0.79+$C$59*0.78) -> 0.5586 | N24: =0.42*N26+0.58*((1-$C$59)*0.79+$C$59*0.78) -> 0.5586 | O24: =0.42*O26+0.58*((1-$C$59)*0.79+$C$59*0.78) -> 0.5586 | P24: =0.42*P26+0.58*((1-$C$59)*0.79+$C$59*0.78) -> 0.5586 | Q24: =0.42*Q26+0.58*((1-$C$59)*0.79+$C$59*0.78) -> 0.5586 | ... Y24: =0.42*Y26+0.58*((1-$C$59)*0.79+$C$59*0.78) -> 0.5586
D25: Double pane | F25: 1998-2007 | G25: 2001 | I25: TABLE 1-I (based on non north with WWR 30-40%) | J25: =L121 -> 0.3 | K25: =M121 -> 0.26 | L25: =N121 -> 0.26 | M25: =O121 -> 0.26 | N25: =P121 -> 0.26 | O25: =Q121 -> 0.31 | P25: =R121 -> 0.31 | Q25: =S121 -> 0.31 | ... Y25: =AA121 -> 0.3
F26: 2008-2018 | G26: 2013 | I26: Table 140.3-C | J26: =(1-$C$59)*L84+$C$59*L104 -> 0.2425 | K26: =(1-$C$59)*M84+$C$59*M104 -> 0.2425 | L26: =(1-$C$59)*N84+$C$59*N104 -> 0.2425 | M26: =(1-$C$59)*O84+$C$59*O104 -> 0.2425 | N26: =(1-$C$59)*P84+$C$59*P104 -> 0.2425 | O26: =(1-$C$59)*Q84+$C$59*Q104 -> 0.2425 | P26: =(1-$C$59)*R84+$C$59*R104 -> 0.2425 | Q26: =(1-$C$59)*S84+$C$59*S104 -> 0.2425 | ... Y26: =(1-$C$59)*AA84+$C$59*AA104 -> 0.2425
F27: 2019+ | G27: 2025 | I27: TABLE 170.2-A (High rise residential in multifamily section) Table 110.6-B: Climate zones 1, 3, 5 and 16 | J27: =(1-$C$59)*L85+$C$59*L105 -> 0.5275 | K27: =(1-$C$59)*M85+$C$59*M105 -> 0.2275 | L27: =(1-$C$59)*N85+$C$59*N105 -> 0.5275 | M27: =(1-$C$59)*O85+$C$59*O105 -> 0.2275 | N27: =(1-$C$59)*P85+$C$59*P105 -> 0.5275 | O27: =(1-$C$59)*Q85+$C$59*Q105 -> 0.2275 | P27: =(1-$C$59)*R85+$C$59*R105 -> 0.2275 | Q27: =(1-$C$59)*S85+$C$59*S105 -> 0.2275 | ... Y27: =(1-$C$59)*AA85+$C$59*AA105 -> 0.5275
A28: Windows_ Nonres (F1) | B28: =Prototype!$A$2 -> ApartmentHighRise | C28: FixedWindow_NonRes | D28: CBECS 2018 shows that ~58% of Large Hotels that were built before 2000 are single pane | E28: U-factor | F28: Pre 1978 | G28: N/A | I28: =I18 -> ASHRAE Handbook of Fundamentals for single pane & T24, 2013 for double pane (58%-42%) | J28: =1.12*0.58+J$31*0.42 -> 0.8008 | K28: =1.12*0.58+K$31*0.42 -> 0.8008 | L28: =1.12*0.58+L$31*0.42 -> 0.8008 | M28: =1.12*0.58+M$31*0.42 -> 0.8008 | N28: =1.12*0.58+N$31*0.42 -> 0.8008 | O28: =1.12*0.58+O$31*0.42 -> 0.8008 | P28: =1.12*0.58+P$31*0.42 -> 0.8008 | Q28: =1.12*0.58+Q$31*0.42 -> 0.8008 | ... Y28: =1.12*0.58+Y$31*0.42 -> 0.8008
F29: 1978-1997 | G29: N/A | J29: =1.12*0.58+J$31*0.42 -> 0.8008 | K29: =1.12*0.58+K$31*0.42 -> 0.8008 | L29: =1.12*0.58+L$31*0.42 -> 0.8008 | M29: =1.12*0.58+M$31*0.42 -> 0.8008 | N29: =1.12*0.58+N$31*0.42 -> 0.8008 | O29: =1.12*0.58+O$31*0.42 -> 0.8008 | P29: =1.12*0.58+P$31*0.42 -> 0.8008 | Q29: =1.12*0.58+Q$31*0.42 -> 0.8008 | ... Y29: =1.12*0.58+Y$31*0.42 -> 0.8008
D30: Double pane | F30: 1998-2007 | G30: 2001 | I30: Table1-H | J30: =L88 -> 0.49 | K30: =M88 -> 0.49 | L30: =N88 -> 0.81 | M30: =O88 -> 0.81 | N30: =P88 -> 0.81 | O30: =Q88 -> 0.81 | P30: =R88 -> 0.81 | Q30: =S88 -> 0.81 | ... Y30: =AA88 -> 0.49
F31: 2008-2018 | G31: 2013 | I31: Table 140.3-B | J31: =L89 -> 0.36 | K31: =M89 -> 0.36 | L31: =N89 -> 0.36 | M31: =O89 -> 0.36 | N31: =P89 -> 0.36 | O31: =Q89 -> 0.36 | P31: =R89 -> 0.36 | Q31: =S89 -> 0.36 | ... Y31: =AA89 -> 0.36
F32: 2019+ | G32: 2025 | I32: Table 140.3-B | J32: =L90 -> 0.36 | K32: =M90 -> 0.36 | L32: =N90 -> 0.36 | M32: =O90 -> 0.36 | N32: =P90 -> 0.36 | O32: =Q90 -> 0.36 | P32: =R90 -> 0.36 | Q32: =S90 -> 0.36 | ... Y32: =AA90 -> 0.36
D33: CBECS 2018 shows that ~58% of Large Hotels that were built before 2000 are single pane | E33: SHGC | F33: Pre 1978 | G33: N/A | I33: =I18 -> ASHRAE Handbook of Fundamentals for single pane & T24, 2013 for double pane (58%-42%) | J33: =0.79*0.58+J$36*0.42 -> 0.5632 | K33: =0.79*0.58+K$36*0.42 -> 0.5632 | L33: =0.79*0.58+L$36*0.42 -> 0.5632 | M33: =0.79*0.58+M$36*0.42 -> 0.5632 | N33: =0.79*0.58+N$36*0.42 -> 0.5632 | O33: =0.79*0.58+O$36*0.42 -> 0.5632 | P33: =0.79*0.58+P$36*0.42 -> 0.5632 | Q33: =0.79*0.58+Q$36*0.42 -> 0.5632 | ... Y33: =0.79*0.58+Y$36*0.42 -> 0.5632
F34: 1978-1997 | G34: N/A | J34: =0.79*0.58+J$36*0.42 -> 0.5632 | K34: =0.79*0.58+K$36*0.42 -> 0.5632 | L34: =0.79*0.58+L$36*0.42 -> 0.5632 | M34: =0.79*0.58+M$36*0.42 -> 0.5632 | N34: =0.79*0.58+N$36*0.42 -> 0.5632 | O34: =0.79*0.58+O$36*0.42 -> 0.5632 | P34: =0.79*0.58+P$36*0.42 -> 0.5632 | Q34: =0.79*0.58+Q$36*0.42 -> 0.5632 | ... Y34: =0.79*0.58+Y$36*0.42 -> 0.5632
D35: Double pane | F35: 1998-2007 | G35: 2001 | I35: Table 1-H (based on non north with WWR 30-40% ) | J35: =L125 -> 0.43 | K35: =M125 -> 0.31 | L35: =N125 -> 0.41 | M35: =O125 -> 0.41 | N35: =P125 -> 0.41 | O35: =Q125 -> 0.34 | P35: =R125 -> 0.34 | Q35: =S125 -> 0.34 | ... Y35: =AA125 -> 0.43
F36: 2008-2018 | G36: 2013 | I36: Table 140.3-B (100% fixed, 0% operable) | J36: =L94 -> 0.25 | K36: =M94 -> 0.25 | L36: =N94 -> 0.25 | M36: =O94 -> 0.25 | N36: =P94 -> 0.25 | O36: =Q94 -> 0.25 | P36: =R94 -> 0.25 | Q36: =S94 -> 0.25 | ... Y36: =AA94 -> 0.25
F37: 2019+ | G37: 2025 | I37: Table 140.3-B (100% fixed, 0% operable) | J37: =L95 -> 0.25 | K37: =M95 -> 0.25 | L37: =N95 -> 0.25 | M37: =O95 -> 0.25 | N37: =P95 -> 0.25 | O37: =Q95 -> 0.25 | P37: =R95 -> 0.25 | Q37: =S95 -> 0.25 | ... Y37: =AA95 -> 0.25
A38: * Based on PNNL scorecard assumption.
E41: Infiltration
F42: Vintage | G42: Source | H42: Res/NR | I42: ACH50
...

Sheet HVAC System
A1: ="HVAC system - "&Prototype!A2 -> HVAC system - ApartmentHighRise
A2: Vintage | C2: Heating | D2: Cooling | E2: Air Distribution | F2: Source
A3: Existing | B3: Residential Tenent | C3: Gas Boiler | D3: Chiller | E3: FPFC | F3: ResStock 2022 & T24 (2008, 2013) Engineering judgment
B4: Residential common (corridors/laundry) | E4: VAV
B5: Non-Residential Tenent (Retail) | C5: VAV (Gas Boiler & hot water reheat) | E5: VAV
A6: New Construction | B6: Residential Tenent | C6: SZHP (DX) | D6: SZHP (DX) | E6: CAV | F6: T24 2025
B7: Residential common (corridors/laundry) | C7: VAV (Gas Boiler & hot water reheat) | D7: Chiller | E7: VAV
B8: Non-Residential Tenent (Retail) | E8: VAV
A9: *Based on NR ACM 2025 - Table 26
A12: Efficiency of HVAC system
A13: Vintage | B13: Upgrade/Installed year | C13: Heating | D13: Cooling | E13: Source
A14: Pre 1978 | B14: 2008 | C14: Gas boiler: Efficiency 80% | D14: Air cooled chiller EER=9.56 | E14: Chiller: Table 110.2-D (converting COP 2.8 to W) Boiler: T24, Table 110.2-K
A15: 1978-1997
A16: 1998-2007
A17: 2008-2018 | B17: 2013 | C17: Gas boiler: Efficiency 80% | D17: EER=9.56 | E17: CFR Energy 2010:Title 10- Table 9
A18: New Construction | B18: 2025 | C18: RES: HSPF:7.5 For SZHPDF: Furnace efficiency: 80% | D18: SEER2: 14.3 | E18: Title 20, 2023 Table E-6
C19: Non-Res | D19: 11.0 EER, 14.1 IEER Dual Fuel: 10.8 EER, 13.9 IEER | E19: Title 24, 2025 able 110.2 footnote a
A22: Fan power
A23: Vintage | B23: Approach | C23: System | D23: Total Static Pressure (TSP) (in w.c.) [PNNL 20405, 2010, Table 5.11] | E23: Fan Efficiency [ACM 2025] | F23: Fan Motor and Drive Efficiency [ACM 2025, Table 14] | G23: W/cfm [ACM 2025, Table 15] | H23: Data Source | I23: Note
A24: Existing | B24: PNNL TSP | C24: VAV System >4,648 cfm | D24: 5.58 | E24: 0.65 | F24: The full-load efficiency of the motor serving the fan- will be determined based on ACM 2025, Table 14 | H24: ACM 2025, PNNL 2010 TSD
C25: SZAC/SZHP | D25: 1.33 | E25: 0.65
A26: Break horse power (bhp)=(Supply cfm*TSP in w.c.)/(6356*Fan efficiency)
A27: Fan power (w/cfm) = bhp/motor and drive efficiency *746
A28: New Construction | B28: ACM 2025 | C28: VAV System >4,648 cfm | D28: =G28*F28*E28/746*6356 -> 5.0490582 | E28: 0.65 | F28: 0.9 | G28: 1.013 | H28: ACM 2025 - Table 14 | I28: 5,000 <cfm; ≤ 10,000 cfm
C29: SZAC | D29: =G29*F28*E28/746*6356 -> 3.8877249 | G29: 0.78
C30: SZHP | D30: =G30*F28*E28/746*6356 -> 3.5886692 | G30: 0.72
A33: Background Data [To be deleted prior to publication]

Sheet Thermostat
A1: ="Thermostat Setpoints - "&Prototype!A2 & ":ResidentialLiving & ResidentialCommon" -> Thermostat Setpoints - ApartmentHighRise:ResidentialLiving & ResidentialCommon
A2: Setpoint | B2: CZ1 | C2: CZ2 | D2: CZ3 | E2: CZ4 | F2: CZ5 | G2: CZ6 | H2: CZ7 | I2: CZ8 | J2: CZ9 | K2: CZ10 | L2: CZ11 | M2: CZ12 | N2: CZ13 | O2: CZ14 | P2: CZ15 | Q2: CZ16 | R2: Source
A3: School Heating Setpoint (F) | B3: 68 | C3: 68 | D3: 68 | E3: 68 | F3: 68 | G3: 68 | H3: 68 | I3: 68 | J3: 68 | K3: 68 | L3: 68 | M3: 68 | N3: 68 | O3: 68 | P3: 68 | Q3: 68 | R3: T24 2025 - Appendix 5.4B
A4: School Heating Setback (F) | B4: 60 | C4: 60 | D4: 60 | E4: 60 | F4: 60 | G4: 60 | H4: 60 | I4: 60 | J4: 60 | K4: 60 | L4: 60 | M4: 60 | N4: 60 | O4: 60 | P4: 60 | Q4: 60
A5: School Cooling Setpoint (F) | B5: 78 | C5: 78 | D5: 78 | E5: 78 | F5: 78 | G5: 78 | H5: 78 | I5: 78 | J5: 78 | K5: 78 | L5: 78 | M5: 78 | N5: 78 | O5: 78 | P5: 78 | Q5: 78 | R5: T24 2025 - Appendix 5.4B
A6: School Cooling Setback (F) | B6: 78 | C6: 78 | D6: 78 | E6: 78 | F6: 78 | G6: 78 | H6: 78 | I6: 78 | J6: 78 | K6: 78 | L6: 78 | M6: 78 | N6: 78 | O6: 78 | P6: 78 | Q6: 78
A8: ="Thermostat Setpoints - "&Prototype!A2 & ":Retail" -> Thermostat Setpoints - ApartmentHighRise:Retail
A9: Setpoint | B9: CZ1 | C9: CZ2 | D9: CZ3 | E9: CZ4 | F9: CZ5 | G9: CZ6 | H9: CZ7 | I9: CZ8 | J9: CZ9 | K9: CZ10 | L9: CZ11 | M9: CZ12 | N9: CZ13 | O9: CZ14 | P9: CZ15 | Q9: CZ16 | R9: Source
A10: Heating Setpoint (F) | B10: 70 | C10: 70 | D10: 70 | E10: 70 | F10: 70 | G10: 70 | H10: 70 | I10: 70 | J10: 70 | K10: 70 | L10: 70 | M10: 70 | N10: 70 | O10: 70 | P10: 70 | Q10: 70 | R10: T24 2022 - Appendix 5.4B
A11: Heating Setback (F) | B11: 60 | C11: 60 | D11: 60 | E11: 60 | F11: 60 | G11: 60 | H11: 60 | I11: 60 | J11: 60 | K11: 60 | L11: 60 | M11: 60 | N11: 60 | O11: 60 | P11: 60 | Q11: 60
A12: Cooling Setpoint (F) | B12: 75 | C12: 75 | D12: 75 | E12: 75 | F12: 75 | G12: 75 | H12: 75 | I12: 75 | J12: 75 | K12: 75 | L12: 75 | M12: 75 | N12: 75 | O12: 75 | P12: 75 | Q12: 75
A13: Cooling Setback (F) | B13: 85 | C13: 85 | D13: 85 | E13: 85 | F13: 85 | G13: 85 | H13: 85 | I13: 85 | J13: 85 | K13: 85 | L13: 85 | M13: 85 | N13: 85 | O13: 85 | P13: 85 | Q13: 85

Sheet Ventilation
A1: ="Outdoor Airflow Rate - "&Prototype!A2 -> Outdoor Airflow Rate - ApartmentHighRise
A2: Space Thermal Zone | B2: Number of People | C2: Floor Area (ft2) | D2: cfm/person (T24, 2025, Equation 120.1-F and Table 120.1-A) | E2: cfm (whole-dwelling continuous mechanical ventilation rate) Res: Equation 160.2-B | F2: cfm/ft² (T24, 2025, Equation 120.1-F and Table 120.1-A) | G2: Required Exhaust Rate-CFM/ft²- (T24, 2025, Table 120.1-B – Minimum Exhaust Rates) | H2: Total cfm Driven by People | I2: Total cfm Driven by Area | J2: Total cfm Driven by Exhaust | K2: Total cfm | L2: Note
A3: =Zones!B3 -> F1 BUSINESS CENTER | B3: =Zones!M3 -> 32.019335 | C3: =Zones!J3 -> 480.05 | D3: 15 | F3: 0.15 | H3: =B3*D3 -> 480.29003 | I3: =C3*F3 -> 72.0075 | K3: =MAX(H3:J3) -> 480.29003
A4: =Zones!B4 -> F1 FITNESS CENTER | B4: =Zones!M4 -> 16.8016 | C4: =Zones!J4 -> 840.08 | D4: 15 | F4: 0.15 | H4: =B4*D4 -> 252.024 | I4: =C4*F4 -> 126.012 | K4: =MAX(H4:J4) -> 252.024
A5: =Zones!B5 -> F1 LEASING OFFICE | B5: =Zones!M5 -> 1.8002 | C5: =Zones!J5 -> 180.02 | D5: 15 | F5: 0.15 | H5: =B5*D5 -> 27.003 | I5: =C5*F5 -> 27.003 | K5: =MAX(H5:J5) -> 27.003
A6: =Zones!B6 -> F1 LOUNGE | B6: =Zones!M6 -> 102.46121 | C6: =Zones!J6 -> 1536.15 | D6: 15 | F6: 0.15 | H6: =B6*D6 -> 1536.9181 | I6: =C6*F6 -> 230.4225 | K6: =MAX(H6:J6) -> 1536.9181
A7: =Zones!B7 -> F1 RETAIL E CORE | B7: =Zones!M7 -> 52.910777 | C7: =Zones!J7 -> 3168.31 | D7: 15 | F7: 0.15 | H7: =B7*D7 -> 793.66165 | I7: =C7*F7 -> 475.2465 | K7: =MAX(H7:J7) -> 793.66165
A8: =Zones!B8 -> F1 RETAIL E OUTER | B8: =Zones!M8 -> 26.455305 | C8: =Zones!J8 -> 1584.15 | D8: 15 | F8: 0.15 | H8: =B8*D8 -> 396.82957 | I8: =C8*F8 -> 237.6225 | K8: =MAX(H8:J8) -> 396.82957
A9: =Zones!B9 -> F1 RETAIL W CORE | B9: =Zones!M9 -> 52.910777 | C9: =Zones!J9 -> 3168.31 | D9: 15 | F9: 0.15 | H9: =B9*D9 -> 793.66165 | I9: =C9*F9 -> 475.2465 | K9: =MAX(H9:J9) -> 793.66165
A10: =Zones!B10 -> F1 RETAIL W OUTER | B10: =Zones!M10 -> 26.455305 | C10: =Zones!J10 -> 1584.15 | D10: 15 | F10: 0.15 | H10: =B10*D10 -> 396.82957 | I10: =C10*F10 -> 237.6225 | K10: =MAX(H10:J10) -> 396.82957
A11: =Zones!B11 -> F10 1-BED N | B11: =Zones!M11 -> 7.80075 | C11: =Zones!J11 -> 1560.15 | D11: NA | E11: =0.03*C11+7.5*(1+Zones!E11) -> 61.8045 | I11: =E11 -> 61.8045 | K11: =MAX(H11:J11) -> 61.8045 | L11: Balanced IAQ fan - only applies to new construction
A12: =Zones!B12 -> F10 1-BED SE | B12: =Zones!M12 -> 7.80075 | C12: =Zones!J12 -> 1560.15 | D12: NA | E12: =0.03*C12+7.5*(1+Zones!E12) -> 61.8045 | I12: =E12 -> 61.8045 | K12: =MAX(H12:J12) -> 61.8045 | L12: Balanced IAQ fan - only applies to new construction
A13: =Zones!B13 -> F10 1-BED SW | B13: =Zones!M13 -> 7.80075 | C13: =Zones!J13 -> 1560.15 | D13: NA | E13: =0.03*C13+7.5*(1+Zones!E13) -> 61.8045 | I13: =E13 -> 61.8045 | K13: =MAX(H13:J13) -> 61.8045 | L13: Balanced IAQ fan - only applies to new construction
A14: =Zones!B14 -> F10 2-BED N CORE | B14: =Zones!M14 -> 5.40055 | C14: =Zones!J14 -> 1080.11 | D14: NA | E14: =0.03*C14+7.5*(1+Zones!E14) -> 47.4033 | I14: =E14 -> 47.4033 | K14: =MAX(H14:J14) -> 47.4033 | L14: Balanced IAQ fan - only applies to new construction
A15: =Zones!B15 -> F10 2-BED NE | B15: =Zones!M15 -> 5.40055 | C15: =Zones!J15 -> 1080.11 | D15: NA | E15: =0.03*C15+7.5*(1+Zones!E15) -> 47.4033 | I15: =E15 -> 47.4033 | K15: =MAX(H15:J15) -> 47.4033 | L15: Balanced IAQ fan - only applies to new construction
A16: =Zones!B16 -> F10 2-BED NW | B16: =Zones!M16 -> 5.40055 | C16: =Zones!J16 -> 1080.11 | D16: NA | E16: =0.03*C16+7.5*(1+Zones!E16) -> 47.4033 | I16: =E16 -> 47.4033 | K16: =MAX(H16:J16) -> 47.4033 | L16: Balanced IAQ fan - only applies to new construction
A17: =Zones!B17 -> F10 2-BED SE | B17: =Zones!M17 -> 5.40055 | C17: =Zones!J17 -> 1080.11 | D17: NA | E17: =0.03*C17+7.5*(1+Zones!E17) -> 47.4033 | I17: =E17 -> 47.4033 | K17: =MAX(H17:J17) -> 47.4033 | L17: Balanced IAQ fan - only applies to new construction
A18: =Zones!B18 -> F10 2-BED SW | B18: =Zones!M18 -> 5.40055 | C18: =Zones!J18 -> 1080.11 | D18: NA | E18: =0.03*C18+7.5*(1+Zones!E18) -> 47.4033 | I18: =E18 -> 47.4033 | K18: =MAX(H18:J18) -> 47.4033 | L18: Balanced IAQ fan - only applies to new construction
A19: =Zones!B19 -> F10 CORRIDOR | B19: =Zones!M19 -> 12.0012 | C19: =Zones!J19 -> 1200.12 | D19: 15 | F19: 0.15 | H19: =B19*D19 -> 180.018 | I19: =C19*F19 -> 180.018 | K19: =MAX(H19:J19) -> 180.018
A20: =Zones!B20 -> F10 LAUNDRY | B20: =Zones!M20 -> 1.8002 | C20: =Zones!J20 -> 180.02 | D20: 15 | F20: 0.15 | H20: =B20*D20 -> 27.003 | I20: =C20*F20 -> 27.003 | K20: =MAX(H20:J20) -> 27.003
A21: =Zones!B21 -> F10 STUDIO N | B21: =Zones!M21 -> 5.40055 | C21: =Zones!J21 -> 1080.11 | D21: NA | E21: =0.03*C21+7.5*(1+Zones!E21) -> 47.4033 | I21: =E21 -> 47.4033 | K21: =MAX(H21:J21) -> 47.4033 | L21: Balanced IAQ fan - only applies to new construction
A22: =Zones!B22 -> F2-9 1-BED N | B22: =Zones!M22 -> 7.80075 | C22: =Zones!J22 -> 1560.15 | D22: NA | E22: =0.03*C22+7.5*(1+Zones!E22) -> 114.3045 | I22: =E22 -> 114.3045 | K22: =MAX(H22:J22) -> 114.3045 | L22: Balanced IAQ fan - only applies to new construction
A23: =Zones!B23 -> F2-9 1-BED SE | B23: =Zones!M23 -> 7.80075 | C23: =Zones!J23 -> 1560.15 | D23: NA | E23: =0.03*C23+7.5*(1+Zones!E23) -> 114.3045 | I23: =E23 -> 114.3045 | K23: =MAX(H23:J23) -> 114.3045 | L23: Balanced IAQ fan - only applies to new construction
A24: =Zones!B24 -> F2-9 1-BED SW | B24: =Zones!M24 -> 7.80075 | C24: =Zones!J24 -> 1560.15 | D24: NA | E24: =0.03*C24+7.5*(1+Zones!E24) -> 114.3045 | I24: =E24 -> 114.3045 | K24: =MAX(H24:J24) -> 114.3045 | L24: Balanced IAQ fan - only applies to new construction
A25: =Zones!B25 -> F2-9 2-BED N CORE | B25: =Zones!M25 -> 5.40055 | C25: =Zones!J25 -> 1080.11 | D25: NA | E25: =0.03*C25+7.5*(1+Zones!E25) -> 99.9033 | I25: =E25 -> 99.9033 | K25: =MAX(H25:J25) -> 99.9033 | L25: Balanced IAQ fan - only applies to new construction
A26: =Zones!B26 -> F2-9 2-BED NE | B26: =Zones!M26 -> 5.40055 | C26: =Zones!J26 -> 1080.11 | D26: NA | E26: =0.03*C26+7.5*(1+Zones!E26) -> 99.9033 | I26: =E26 -> 99.9033 | K26: =MAX(H26:J26) -> 99.9033 | L26: Balanced IAQ fan - only applies to new construction
A27: =Zones!B27 -> F2-9 2-BED NW | B27: =Zones!M27 -> 5.40055 | C27: =Zones!J27 -> 1080.11 | D27: NA | E27: =0.03*C27+7.5*(1+Zones!E27) -> 99.9033 | I27: =E27 -> 99.9033 | K27: =MAX(H27:J27) -> 99.9033 | L27: Balanced IAQ fan - only applies to new construction
A28: =Zones!B28 -> F2-9 2-BED SE | B28: =Zones!M28 -> 5.40055 | C28: =Zones!J28 -> 1080.11 | D28: NA | E28: =0.03*C28+7.5*(1+Zones!E28) -> 99.9033 | I28: =E28 -> 99.9033 | K28: =MAX(H28:J28) -> 99.9033 | L28: Balanced IAQ fan - only applies to new construction
A29: =Zones!B29 -> F2-9 2-BED SW | B29: =Zones!M29 -> 5.40055 | C29: =Zones!J29 -> 1080.11 | D29: NA | E29: =0.03*C29+7.5*(1+Zones!E29) -> 99.9033 | I29: =E29 -> 99.9033 | K29: =MAX(H29:J29) -> 99.9033 | L29: Balanced IAQ fan - only applies to new construction
A30: =Zones!B30 -> F2-9 CORRIDOR | B30: =Zones!M30 -> 12.0012 | C30: =Zones!J30 -> 1200.12 | D30: NA | F30: 0.15 | I30: =C30*F30 -> 180.018 | K30: =MAX(H30:J30) -> 180.018
A31: =Zones!B31 -> F2-9 LAUNDRY | B31: =Zones!M31 -> 1.8002 | C31: =Zones!J31 -> 180.02 | D31: 15 | F31: 0.15 | H31: =B31*D31 -> 27.003 | I31: =C31*F31 -> 27.003 | K31: =MAX(H31:J31) -> 27.003
A32: =Zones!B32 -> F2-9 STUDIO N | B32: =Zones!M32 -> 5.40055 | C32: =Zones!J32 -> 1080.11 | D32: NA | E32: =0.03*C32+7.5*(1+Zones!E32) -> 99.9033 | F32: 0.15 | I32: =E32 -> 99.9033 | K32: =MAX(H32:J32) -> 99.9033 | L32: Balanced IAQ fan - only applies to new construction
A33: =Zones!B33 -> L1 PARKING GARAGE | B33: =Zones!M33 -> 62.7061 | C33: =Zones!J33 -> 12541.22 | D33: 15 | E33: =0.03*C33+7.5*(1+Zones!E33) -> 391.2366 | F33: 0.15 | H33: =B33*D33 -> 940.5915 | I33: =C33*F33 -> 1881.183 | K33: =MAX(H33:J33) -> 1881.183
A34: =Zones!B34 -> L2 PARKING GARAGE | B34: =Zones!M34 -> 62.7061 | C34: =Zones!J34 -> 12541.22 | D34: 15 | E34: =0.03*C34+7.5*(1+Zones!E34) -> 391.2366 | F34: 0.15 | H34: =B34*D34 -> 940.5915 | I34: =C34*F34 -> 1881.183 | K34: =MAX(H34:J34) -> 1881.183

Sheet Water Heater
A1: ="Water Heater - "&Prototype!A2 -> Water Heater - ApartmentHighRise
A2: Vintage | B2: WH Type | C2: Efficiency | D2: Tank volume (gal) | E2: Tank loss | F2: Source | G2: Note
A3: Existing | B3: Gas | C3: 0.8 | D3: =F46 -> 39.75017 | E3: =G46 -> 751.43403 | F3: 2024 CASE Report: A Comprehensive, High Efficiency Solution for Water Heating in Multifamily Buildings 2022 CASE Report: Multifamily Domestic Hot Water Distribution Engineering Judgment
A4: New Construction | B4: Gas | C4: 0.8 | D4: =D3 -> 39.75017 | E4: =G48 -> 751.43403
A5: * Title 24 2025: §170.2(d)3: Gas Storage with recirculation and solar water heating system)
A8: Peak Hot Water Consumption
A9: Space | B9: Baseline WH Type [T24, 2022, Appendix 5.4A , sheet: "2022 SpaceFuncData-Input"] | C9: Total Area (ft²) | D9: Number of People | E9: Hot Water Usage Specification (gal/hr per person) [T24, 2022, Appendix 5.4A , sheet: "2022 SpaceFuncData-Input"] | F9: Peak Hot Water Usage (gal/hr) | G9: Peak Hot Water Usage (gal/min)
A10: =Zones!B3 -> F1 BUSINESS CENTER | B10: Gas | C10: =Zones!J3*Zones!L3 -> 480.05 | D10: =Zones!M3*Zones!L3 -> 32.019335 | E10: 0.18 | F10: =D10*E10 -> 5.7634803 | G10: =F10/60 -> 0.096058005
A11: =Zones!B4 -> F1 FITNESS CENTER | B11: Gas | C11: =Zones!J4*Zones!L4 -> 840.08 | D11: =Zones!M4*Zones!L4 -> 16.8016 | E11: 0.18 | F11: =D11*E11 -> 3.024288 | G11: =F11/60 -> 0.0504048
A12: =Zones!B5 -> F1 LEASING OFFICE | B12: Gas | C12: =Zones!J5*Zones!L5 -> 180.02 | D12: =Zones!M5*Zones!L5 -> 1.8002 | E12: 0.18 | F12: =D12*E12 -> 0.324036 | G12: =F12/60 -> 0.0054006
A13: =Zones!B6 -> F1 LOUNGE | B13: Gas | C13: =Zones!J6*Zones!L6 -> 1536.15 | D13: =Zones!M6*Zones!L6 -> 102.46121 | E13: 0.18 | F13: =D13*E13 -> 18.443017 | G13: =F13/60 -> 0.30738362
A14: =Zones!B7 -> F1 RETAIL E CORE | B14: Gas | C14: =Zones!J7*Zones!L7 -> 3168.31 | D14: =Zones!M7*Zones!L7 -> 52.910777 | E14: 0.18 | F14: =D14*E14 -> 9.5239399 | G14: =F14/60 -> 0.15873233
A15: =Zones!B8 -> F1 RETAIL E OUTER | B15: Gas | C15: =Zones!J8*Zones!L8 -> 1584.15 | D15: =Zones!M8*Zones!L8 -> 26.455305 | E15: 0.18 | F15: =D15*E15 -> 4.7619549 | G15: =F15/60 -> 0.079365915
A16: =Zones!B9 -> F1 RETAIL W CORE | B16: Gas | C16: =Zones!J9*Zones!L9 -> 3168.31 | D16: =Zones!M9*Zones!L9 -> 52.910777 | E16: 0.18 | F16: =D16*E16 -> 9.5239399 | G16: =F16/60 -> 0.15873233
A17: =Zones!B10 -> F1 RETAIL W OUTER | C17: =Zones!J10*Zones!L10 -> 1584.15 | D17: =Zones!M10*Zones!L10 -> 26.455305 | F17: =D17*E17 -> 0 | G17: =F17/60 -> 0
A18: =Zones!B11 -> F10 1-BED N | B18: Gas | C18: =Zones!J11*Zones!L11 -> 1560.15 | D18: =Zones!M11*Zones!L11 -> 7.80075 | E18: 0.18 | F18: =D18*E18 -> 1.404135 | G18: =F18/60 -> 0.02340225
A19: =Zones!B12 -> F10 1-BED SE | B19: Gas | C19: =Zones!J12*Zones!L12 -> 1560.15 | D19: =Zones!M12*Zones!L12 -> 7.80075 | E19: 0.18 | F19: =D19*E19 -> 1.404135 | G19: =F19/60 -> 0.02340225
A20: =Zones!B13 -> F10 1-BED SW | B20: Gas | C20: =Zones!J13*Zones!L13 -> 1560.15 | D20: =Zones!M13*Zones!L13 -> 7.80075 | E20: 0.18 | F20: =D20*E20 -> 1.404135 | G20: =F20/60 -> 0.02340225
A21: =Zones!B14 -> F10 2-BED N CORE | C21: =Zones!J14*Zones!L14 -> 1080.11 | D21: =Zones!M14*Zones!L14 -> 5.40055 | F21: =D21*E21 -> 0 | G21: =F21/60 -> 0
A22: =Zones!B15 -> F10 2-BED NE | C22: =Zones!J15*Zones!L15 -> 1080.11 | D22: =Zones!M15*Zones!L15 -> 5.40055 | F22: =D22*E22 -> 0 | G22: =F22/60 -> 0
A23: =Zones!B16 -> F10 2-BED NW | B23: Gas | C23: =Zones!J16*Zones!L16 -> 1080.11 | D23: =Zones!M16*Zones!L16 -> 5.40055 | E23: 0.18 | F23: =D23*E23 -> 0.972099 | G23: =F23/60 -> 0.01620165
A24: =Zones!B17 -> F10 2-BED SE | C24: =Zones!J17*Zones!L17 -> 1080.11 | D24: =Zones!M17*Zones!L17 -> 5.40055 | F24: =D24*E24 -> 0 | G24: =F24/60 -> 0
A25: =Zones!B18 -> F10 2-BED SW | C25: =Zones!J18*Zones!L18 -> 1080.11 | D25: =Zones!M18*Zones!L18 -> 5.40055 | F25: =D25*E25 -> 0 | G25: =F25/60 -> 0
A26: =Zones!B19 -> F10 CORRIDOR | B26: Gas | C26: =Zones!J19*Zones!L19 -> 1200.12 | D26: =Zones!M19*Zones!L19 -> 12.0012 | E26: 0.18 | F26: =D26*E26 -> 2.160216 | G26: =F26/60 -> 0.0360036
A27: =Zones!B20 -> F10 LAUNDRY | C27: =Zones!J20*Zones!L20 -> 180.02 | D27: =Zones!M20*Zones!L20 -> 1.8002 | F27: =D27*E27 -> 0 | G27: =F27/60 -> 0
A28: =Zones!B21 -> F10 STUDIO N | C28: =Zones!J21*Zones!L21 -> 1080.11 | D28: =Zones!M21*Zones!L21 -> 5.40055 | E28: 0 | F28: =D28*E28 -> 0 | G28: =F28/60 -> 0
A29: =Zones!B22 -> F2-9 1-BED N | B29: Gas | C29: =Zones!J22*Zones!L22 -> 12481.2 | D29: =Zones!M22*Zones!L22 -> 62.406 | E29: 0.18 | F29: =D29*E29 -> 11.23308 | G29: =F29/60 -> 0.187218
A30: =Zones!B23 -> F2-9 1-BED SE | C30: =Zones!J23*Zones!L23 -> 12481.2 | D30: =Zones!M23*Zones!L23 -> 62.406 | E30: 0 | F30: =D30*E30 -> 0 | G30: =F30/60 -> 0
A31: =Zones!B24 -> F2-9 1-BED SW | C31: =Zones!J24*Zones!L24 -> 12481.2 | D31: =Zones!M24*Zones!L24 -> 62.406 | F31: =D31*E31 -> 0 | G31: =F31/60 -> 0
A32: =Zones!B25 -> F2-9 2-BED N CORE | B32: Gas | C32: =Zones!J25*Zones!L25 -> 8640.88 | D32: =Zones!M25*Zones!L25 -> 43.2044 | E32: 0.18 | F32: =D32*E32 -> 7.776792 | G32: =F32/60 -> 0.1296132
A33: =Zones!B26 -> F2-9 2-BED NE | C33: =Zones!J26*Zones!L26 -> 8640.88 | D33: =Zones!M26*Zones!L26 -> 43.2044 | E33: 0 | F33: =D33*E33 -> 0 | G33: =F33/60 -> 0
A34: =Zones!B27 -> F2-9 2-BED NW | C34: =Zones!J27*Zones!L27 -> 8640.88 | D34: =Zones!M27*Zones!L27 -> 43.2044 | E34: 0 | F34: =D34*E34 -> 0 | G34: =F34/60 -> 0
A35: =Zones!B28 -> F2-9 2-BED SE | B35: Gas | C35: =Zones!J28*Zones!L28 -> 8640.88 | D35: =Zones!M28*Zones!L28 -> 43.2044 | E35: 0.18 | F35: =D35*E35 -> 7.776792 | G35: =F35/60 -> 0.1296132
A36: =Zones!B29 -> F2-9 2-BED SW | C36: =Zones!J29*Zones!L29 -> 8640.88 | D36: =Zones!M29*Zones!L29 -> 43.2044 | E36: 0 | F36: =D36*E36 -> 0 | G36: =F36/60 -> 0
A37: =Zones!B30 -> F2-9 CORRIDOR | C37: =Zones!J30*Zones!L30 -> 9600.96 | D37: =Zones!M30*Zones!L30 -> 96.0096 | E37: 0 | F37: =D37*E37 -> 0 | G37: =F37/60 -> 0
A38: =Zones!B31 -> F2-9 LAUNDRY | B38: Gas | C38: =Zones!J31*Zones!L31 -> 1440.16 | D38: =Zones!M31*Zones!L31 -> 14.4016 | E38: 0.18 | F38: =D38*E38 -> 2.592288 | G38: =F38/60 -> 0.0432048
A39: =Zones!B32 -> F2-9 STUDIO N | C39: =Zones!J32*Zones!L32 -> 8640.88 | D39: =Zones!M32*Zones!L32 -> 43.2044 | F39: =D39*E39 -> 0 | G39: =F39/60 -> 0
A40: =Zones!B33 -> L1 PARKING GARAGE | C40: =Zones!J33*Zones!L33 -> 12541.22 | D40: =Zones!M33*Zones!L33 -> 62.7061 | E40: 0 | F40: =D40*E40 -> 0 | G40: =F40/60 -> 0
A41: =Zones!B34 -> L2 PARKING GARAGE | B41: Gas | C41: =Zones!J34*Zones!L34 -> 12541.22 | D41: =Zones!M34*Zones!L34 -> 62.7061 | E41: 0.18 | F41: =D41*E41 -> 11.287098 | G41: =F41/60 -> 0.1881183
A43: Water Heater Capacity, Tank Capacity, and Tank Loss
...

Sheet Interior Lights
A1: ="Interior Lighting - "&Prototype!A2 -> Interior Lighting - ApartmentHighRise
A2: Space Type | B2: New Construction | E2: Existing
B3: LPD (W/ft²) | C3: Additional LPD for Portable Lighting (W/ft²) | D3: Source | E3: LPD (W/ft²) | F3: Additional LPD for Portable Lighting (W/ft²) | G3: Source
A4: =Zones!A3 -> Convention, Conference, Multipurpose and Meeting Area | B4: 0.75 | C4: NA | D4: T24, 2025, Table 170.2-M (Area category method) | E4: 0.85 | F4: NA | G4: T24, 2016, Table 140.6 C (Area category method)
A5: =Zones!A4 -> Exercise/Fitness Center and Gymnasium Areas | B5: 0.5 | E5: 1
A6: =Zones!A5 -> Office Area (>250 square feet) | B6: 0.65 | E6: 0.65
A7: =Zones!A6 -> Lobby, Main Entry | B7: 0.7 | E7: 0.95
A8: =Zones!A19 -> Corridor Area | B8: 0.4 | E8: 0.6
A9: =Zones!A20 -> Laundry Area | B9: 0.45 | E9: 0.45
A10: =Zones!A7 -> Retail Space | B10: 0.95 | E10: 1
A11: =Zones!A33 -> Parking Garage Area (Parking Zone and Ramps) | B11: 0.1 | E11: 0.14
A12: =Zones!A11 -> High-Rise Residential Living Spaces | B12: 0.79 | D12: CEC 2025 Single-Family ACM Appendix E - Table 2 and 8 | E12: 0.79 | G12: CEC 2016 Single-Family ACM Section 2.2.12
A14: *Annual kWh=100+0.1775×CFA (ft²)(Eq. 1)
A16: Background Data [To be deleted prior to publication]

Sheet Ext Lighting
A1: ="Exterior Lighting - "&Prototype!A2 -> Exterior Lighting - ApartmentHighRise
A2: Motion Controlled Luminaires (W) | B2: Non-motion Controlled Luminaires (W) | C2: Total (W) | D2: Source
A3: =G16 -> 2087.6895 | B3: =G17 -> 873.34644 | C3: =B3+A3 -> 2961.0359 | D3: T24, 2022 & 2025 2019 Outdoor Lighting CASE report PNNL 90.1-2010 TSD
A8: Exterior Lighting
A9: Items (Assume LZ2) | B9: Assumptions [2019 Outdoor Lighting CASE Report & PNNL 90.1-2010 TSD] | D9: Unit | E9: Lighting Power Allowance [T24, 2025, Table 140.7-A & 140.7-B] | F9: Unit | G9: Exterior Lighting Power (W)
A10: IWA (Initial Wage Allowance) | E10: 200 | F10: (W) | G10: =$E10 -> 200
A11: Parking area | B11: 400 ft² for every parking space 1.5 parking space per living unit for residential 1 parking space per 360 ft² of gross building area | C11: =400*B25*1.5+B23/B24/360*400 -> 86921.657 | D11: (ft²) | E11: 0.019 | F11: (W/ft²) | G11: =$E11*C11 -> 1651.5115
A12: Building Entrance | B12: 2 building entrance for NR (1 per 10,000 ft² footprint) | C12: 2 | D12: (count) | E12: 15 | F12: (W/ea) | G12: =E12*C12 -> 30
A13: Hardscape Ornamental Light | B13: 0.1 ft² per ft² of gross building area for hardscape ornamental light | C13: =B23*0.1 -> 15049.491 | D13: (ft²) | E13: 0.007 | F13: (W/ft²) | G13: =E13*C13 -> 105.34644
A14: Building façade | B14: 0.1 W per ft² of facade area Façade Area = Perimeter × 0.5 × 30 ft (30 ft is the max height that is lit) * The 0.5 factor assumes that only half of the perimeter walls are lit. -Formula ia developed based on the 2019 Outdoor Lighting CASE report | C14: =B22*0.5*30 -> 7680 | D14: (ft²) | E14: 0.1 | F14: (W/ft²) | G14: =E14*C14 -> 768
A15: Sales canopy | B15: 0.1 ft2 per ft2 of gross bldg area | C15: =(B23/B24)*0.1 -> 1504.9491 | D15: (ft²) | E15: 0.137 | F15: (W/ft²) | G15: =E15*C15 -> 206.17803
A16: Motion controlled Luminaires | G16: =G11+G10+G15+G12 -> 2087.6895
A17: Non-motion-controlled Luminaires | G17: =G13+G14 -> 873.34644
A18: Total | G18: =G16+G17 -> 2961.0359
A20: *Developed based on 2019 Outdoor Lighting CASE Report
A22: Perimeter (ft) | B22: =(190+66)*2 -> 512
A23: Total floor area (ft²) | B23: =Zones!J35 -> 150494.91
A24: Floors (above floor) | B24: 10
A25: Number of dwelling units | B25: 117
A28: Background Data [To be deleted prior to publication]
A31: Existing Prototypes:
A32: Exterior lighting load (W)
A33: PNNL 90.1 2022, San Diego | B33: CPUC 2024
A34: 9571 | B34: No
A39: T24, part6, 2025, 130.2(c)3

Sheet Equipment
A1: ="Equipment - "&Prototype!A2 -> Equipment - ApartmentHighRise
A2: Space Type | B2: Plug load Intensity (W/ft2) | C2: Source
A3: =Zones!A3 -> Convention, Conference, Multipurpose and Meeting Area | B3: 1 | C3: Plug load and schedules project with CEC, 2025
A4: =Zones!A4 -> Exercise/Fitness Center and Gymnasium Areas | B4: 0.5
A5: =Zones!A5 -> Office Area (>250 square feet) | B5: 1.5
A6: =Zones!A6 -> Lobby, Main Entry | B6: 0.5
A7: =Zones!A7 -> Retail Space | B7: 0.7
A8: =Zones!A19 -> Corridor Area | B8: 0
A9: =Zones!A20 -> Laundry Area | B9: 3
A10: =Zones!A33 -> Parking Garage Area (Parking Zone and Ramps) | B10: 0
A11: =Zones!A13 -> High-Rise Residential Living Spaces | B11: 0.5 | C11: Plug load and schedules project with CBECC-COM, 2019
A14: Elevator
A15: Vintages | B15: No of Elevator | C15: Design Load (W) | D15: Source
A16: New Construction and Existing | B16: =ROUND((Prototype!B8*0.7/50000)+ROUND(12/2,0),0) -> 8 | C16: 10597.39 | D16: Design Load based on PNNL ASHRAE 90.1 2022 HighRise Apartment prototype --- per T24 2025 §120.6 (f)
A19: Assumptions for elevators:
A20: One elevator for approximately 50,000 ft² in use. | F20: https://buildingandinteriors.com/find-the-magic-number-elevators-per-building/
A21: For every two floors or two and a half floors, one more elevator was added.
A22: An in-use rate of 70% for the floor area was assumed, based on engineering judgment.
A23: Calculated number of Elevators: | C23: =ROUND((Prototype!B8*0.7/50000)+ROUND(12/2,0),0) -> 8 | D23: Same as PNNL assumptions
A24: Calculate Elevator load (kw)based on ACM 2022: | C24: =C23*C25 -> 80 | D24: 76 kW is PNNL ASHRE 90.1 2019 elevator load | F24: =10597.39/1000 -> 10.59739
A25: ACM 2022 suggestion for elevator load (kW): | C25: 10
A26: Elevator load will be defined as exterior load not equipment load (Same as PNNL ASHRAE 90.1 Large Hotel prototype).

Sheet Schedules
A1: ="Schedules - "& Prototype!A2 -> Schedules - ApartmentHighRise
A2: Zone | B2: Schedule Category | C2: Schedule | D2: Source | E2: Day | F2: Hour
F3: 1 | G3: 2 | H3: 3 | I3: 4 | J3: 5 | K3: 6 | L3: 7 | M3: 8 | N3: 9 | O3: 10 | P3: 11 | Q3: 12 | R3: 13 | S3: 14 | T3: 15 | U3: 16 | V3: 17 | W3: 18 | X3: 19 | Y3: 20 | Z3: 21 | AA3: 22 | AB3: 23 | AC3: 24
A4: Living Area | B4: ResidentialLiving | C4: Occupancy | D4: T24 2022 - Appendix 5.4B [ResidentialLiving] | E4: Weekday | F4: 0.9 | G4: 0.9 | H4: 0.9 | I4: 0.9 | J4: 0.9 | K4: 0.9 | L4: 0.7 | M4: 0.4 | N4: 0.4 | O4: 0.2 | P4: 0.2 | Q4: 0.2 | R4: 0.2 | S4: 0.2 | T4: 0.2 | U4: 0.3 | V4: 0.5 | W4: 0.5 | X4: 0.5 | Y4: 0.7 | Z4: 0.7 | AA4: 0.8 | AB4: 0.9 | AC4: 0.9
E5: Saturday | F5: 0.9 | G5: 0.9 | H5: 0.9 | I5: 0.9 | J5: 0.9 | K5: 0.9 | L5: 0.7 | M5: 0.4 | N5: 0.4 | O5: 0.2 | P5: 0.2 | Q5: 0.2 | R5: 0.2 | S5: 0.2 | T5: 0.2 | U5: 0.3 | V5: 0.5 | W5: 0.5 | X5: 0.5 | Y5: 0.7 | Z5: 0.7 | AA5: 0.8 | AB5: 0.9 | AC5: 0.9
E6: Sunday | F6: 0.9 | G6: 0.9 | H6: 0.9 | I6: 0.9 | J6: 0.9 | K6: 0.9 | L6: 0.7 | M6: 0.4 | N6: 0.4 | O6: 0.2 | P6: 0.2 | Q6: 0.2 | R6: 0.2 | S6: 0.2 | T6: 0.2 | U6: 0.3 | V6: 0.5 | W6: 0.5 | X6: 0.5 | Y6: 0.7 | Z6: 0.7 | AA6: 0.8 | AB6: 0.9 | AC6: 0.9
A7: Living Area | B7: =B4 -> ResidentialLiving | C7: Lights | D7: T24 2022 - Appendix 5.4B [ResidentialLiving] | E7: Weekday | F7: 0.1 | G7: 0.1 | H7: 0.1 | I7: 0.1 | J7: 0.1 | K7: 0.3 | L7: 0.45 | M7: 0.45 | N7: 0.45 | O7: 0.45 | P7: 0.3 | Q7: 0.3 | R7: 0.3 | S7: 0.3 | T7: 0.3 | U7: 0.3 | V7: 0.3 | W7: 0.3 | X7: 0.6 | Y7: 0.8 | Z7: 0.9 | AA7: 0.8 | AB7: 0.6 | AC7: 0.3
E8: Saturday | F8: 0.1 | G8: 0.1 | H8: 0.1 | I8: 0.1 | J8: 0.1 | K8: 0.3 | L8: 0.45 | M8: 0.45 | N8: 0.45 | O8: 0.45 | P8: 0.3 | Q8: 0.3 | R8: 0.3 | S8: 0.3 | T8: 0.3 | U8: 0.3 | V8: 0.3 | W8: 0.3 | X8: 0.6 | Y8: 0.8 | Z8: 0.9 | AA8: 0.8 | AB8: 0.6 | AC8: 0.3
E9: Sunday | F9: 0.1 | G9: 0.1 | H9: 0.1 | I9: 0.1 | J9: 0.1 | K9: 0.3 | L9: 0.45 | M9: 0.45 | N9: 0.45 | O9: 0.45 | P9: 0.3 | Q9: 0.3 | R9: 0.3 | S9: 0.3 | T9: 0.3 | U9: 0.3 | V9: 0.3 | W9: 0.3 | X9: 0.6 | Y9: 0.8 | Z9: 0.9 | AA9: 0.8 | AB9: 0.6 | AC9: 0.3
A10: Living Area | B10: =B4 -> ResidentialLiving | C10: ElecEquipment | D10: T24 2022 - Appendix 5.4B [ResidentialLiving] | E10: Weekday | F10: 0.1 | G10: 0.1 | H10: 0.1 | I10: 0.1 | J10: 0.1 | K10: 0.3 | L10: 0.45 | M10: 0.45 | N10: 0.45 | O10: 0.45 | P10: 0.3 | Q10: 0.3 | R10: 0.3 | S10: 0.3 | T10: 0.3 | U10: 0.3 | V10: 0.3 | W10: 0.3 | X10: 0.6 | Y10: 0.8 | Z10: 0.9 | AA10: 0.8 | AB10: 0.6 | AC10: 0.3
E11: Saturday | F11: 0.1 | G11: 0.1 | H11: 0.1 | I11: 0.1 | J11: 0.1 | K11: 0.3 | L11: 0.45 | M11: 0.45 | N11: 0.45 | O11: 0.45 | P11: 0.3 | Q11: 0.3 | R11: 0.3 | S11: 0.3 | T11: 0.3 | U11: 0.3 | V11: 0.3 | W11: 0.3 | X11: 0.6 | Y11: 0.8 | Z11: 0.9 | AA11: 0.8 | AB11: 0.6 | AC11: 0.3
E12: Sunday | F12: 0.1 | G12: 0.1 | H12: 0.1 | I12: 0.1 | J12: 0.1 | K12: 0.3 | L12: 0.45 | M12: 0.45 | N12: 0.45 | O12: 0.45 | P12: 0.3 | Q12: 0.3 | R12: 0.3 | S12: 0.3 | T12: 0.3 | U12: 0.3 | V12: 0.3 | W12: 0.3 | X12: 0.6 | Y12: 0.8 | Z12: 0.9 | AA12: 0.8 | AB12: 0.6 | AC12: 0.3
A13: Living Area | B13: =B4 -> ResidentialLiving | C13: HVACAvail | D13: T24 2022 - Appendix 5.4B [ResidentialLiving] | E13: Weekday | F13: 1 | G13: 1 | H13: 1 | I13: 1 | J13: 1 | K13: 1 | L13: 1 | M13: 1 | N13: 1 | O13: 1 | P13: 1 | Q13: 1 | R13: 1 | S13: 1 | T13: 1 | U13: 1 | V13: 1 | W13: 1 | X13: 1 | Y13: 1 | Z13: 1 | AA13: 1 | AB13: 1 | AC13: 1
E14: Saturday | F14: 1 | G14: 1 | H14: 1 | I14: 1 | J14: 1 | K14: 1 | L14: 1 | M14: 1 | N14: 1 | O14: 1 | P14: 1 | Q14: 1 | R14: 1 | S14: 1 | T14: 1 | U14: 1 | V14: 1 | W14: 1 | X14: 1 | Y14: 1 | Z14: 1 | AA14: 1 | AB14: 1 | AC14: 1
E15: Sunday | F15: 1 | G15: 1 | H15: 1 | I15: 1 | J15: 1 | K15: 1 | L15: 1 | M15: 1 | N15: 1 | O15: 1 | P15: 1 | Q15: 1 | R15: 1 | S15: 1 | T15: 1 | U15: 1 | V15: 1 | W15: 1 | X15: 1 | Y15: 1 | Z15: 1 | AA15: 1 | AB15: 1 | AC15: 1
A16: Living Area | B16: =B4 -> ResidentialLiving | C16: ServiceHotWater | D16: T24 2022 - Appendix 5.4B [ResidentialLiving] | E16: Weekday | F16: 0.131 | G16: 0.075 | H16: 0.084 | I16: 0.103 | J16: 0.187 | K16: 0.411 | L16: 0.832 | M16: 1 | N16: 0.832 | O16: 0.617 | P16: 0.486 | Q16: 0.355 | R16: 0.336 | S16: 0.308 | T16: 0.299 | U16: 0.243 | V16: 0.393 | W16: 0.449 | X16: 0.486 | Y16: 0.439 | Z16: 0.393 | AA16: 0.364 | AB16: 0.336 | AC16: 0.206
E17: Saturday | F17: 0.217 | G17: 0.12 | H17: 0.108 | I17: 0.096 | J17: 0.181 | K17: 0.277 | L17: 0.313 | M17: 0.566 | N17: 0.928 | O17: 1 | P17: 0.892 | Q17: 0.735 | R17: 0.614 | S17: 0.518 | T17: 0.47 | U17: 0.47 | V17: 0.627 | W17: 0.699 | X17: 0.675 | Y17: 0.627 | Z17: 0.566 | AA17: 0.53 | AB17: 0.482 | AC17: 0.337
E18: Sunday | F18: 0.217 | G18: 0.12 | H18: 0.108 | I18: 0.096 | J18: 0.181 | K18: 0.277 | L18: 0.313 | M18: 0.566 | N18: 0.928 | O18: 1 | P18: 0.892 | Q18: 0.735 | R18: 0.614 | S18: 0.518 | T18: 0.47 | U18: 0.47 | V18: 0.627 | W18: 0.699 | X18: 0.675 | Y18: 0.627 | Z18: 0.566 | AA18: 0.53 | AB18: 0.482 | AC18: 0.337
A19: Living Area | B19: =B4 -> ResidentialLiving | C19: GasEquipment | D19: T24 2022 - Appendix 5.4B [ResidentialLiving] | E19: Weekday | F19: 0 | G19: 0 | H19: 0 | I19: 0 | J19: 0 | K19: 0 | L19: 0.5 | M19: 0.5 | N19: 0 | O19: 0 | P19: 0 | Q19: 0.2 | R19: 0.2 | S19: 0 | T19: 0 | U19: 0 | V19: 0.5 | W19: 0.5 | X19: 0.5 | Y19: 0 | Z19: 0 | AA19: 0 | AB19: 0 | AC19: 0
E20: Saturday | F20: 0 | G20: 0 | H20: 0 | I20: 0 | J20: 0 | K20: 0 | L20: 0.5 | M20: 0.5 | N20: 0 | O20: 0 | P20: 0 | Q20: 0.2 | R20: 0.2 | S20: 0 | T20: 0 | U20: 0 | V20: 0.5 | W20: 0.5 | X20: 0.5 | Y20: 0 | Z20: 0 | AA20: 0 | AB20: 0 | AC20: 0
E21: Sunday | F21: 0 | G21: 0 | H21: 0 | I21: 0 | J21: 0 | K21: 0 | L21: 0.5 | M21: 0.5 | N21: 0 | O21: 0 | P21: 0 | Q21: 0.2 | R21: 0.2 | S21: 0 | T21: 0 | U21: 0 | V21: 0.5 | W21: 0.5 | X21: 0.5 | Y21: 0 | Z21: 0 | AA21: 0 | AB21: 0 | AC21: 0
A22: Living Area | B22: =B4 -> ResidentialLiving | C22: HtgSetpt | D22: T24 2022 - Appendix 5.4B [ResidentialLiving] | E22: Weekday | F22: =IF(F13=0,Thermostat!$B$4,Thermostat!$B$3) -> 68 | G22: =IF(G13=0,Thermostat!$B$4,Thermostat!$B$3) -> 68 | H22: =IF(H13=0,Thermostat!$B$4,Thermostat!$B$3) -> 68 | I22: =IF(I13=0,Thermostat!$B$4,Thermostat!$B$3) -> 68 | J22: =IF(J13=0,Thermostat!$B$4,Thermostat!$B$3) -> 68 | K22: =IF(K13=0,Thermostat!$B$4,Thermostat!$B$3) -> 68 | L22: =IF(L13=0,Thermostat!$B$4,Thermostat!$B$3) -> 68 | M22: =IF(M13=0,Thermostat!$B$4,Thermostat!$B$3) -> 68 | ... AC22: =IF(AC13=0,Thermostat!$B$4,Thermostat!$B$3) -> 68
E23: Saturday | F23: =IF(F14=0,Thermostat!$B$4,Thermostat!$B$3) -> 68 | G23: =IF(G14=0,Thermostat!$B$4,Thermostat!$B$3) -> 68 | H23: =IF(H14=0,Thermostat!$B$4,Thermostat!$B$3) -> 68 | I23: =IF(I14=0,Thermostat!$B$4,Thermostat!$B$3) -> 68 | J23: =IF(J14=0,Thermostat!$B$4,Thermostat!$B$3) -> 68 | K23: =IF(K14=0,Thermostat!$B$4,Thermostat!$B$3) -> 68 | L23: =IF(L14=0,Thermostat!$B$4,Thermostat!$B$3) -> 68 | M23: =IF(M14=0,Thermostat!$B$4,Thermostat!$B$3) -> 68 | ... AC23: =IF(AC14=0,Thermostat!$B$4,Thermostat!$B$3) -> 68
E24: Sunday | F24: =IF(F15=0,Thermostat!$B$4,Thermostat!$B$3) -> 68 | G24: =IF(G15=0,Thermostat!$B$4,Thermostat!$B$3) -> 68 | H24: =IF(H15=0,Thermostat!$B$4,Thermostat!$B$3) -> 68 | I24: =IF(I15=0,Thermostat!$B$4,Thermostat!$B$3) -> 68 | J24: =IF(J15=0,Thermostat!$B$4,Thermostat!$B$3) -> 68 | K24: =IF(K15=0,Thermostat!$B$4,Thermostat!$B$3) -> 68 | L24: =IF(L15=0,Thermostat!$B$4,Thermostat!$B$3) -> 68 | M24: =IF(M15=0,Thermostat!$B$4,Thermostat!$B$3) -> 68 | ... AC24: =IF(AC15=0,Thermostat!$B$4,Thermostat!$B$3) -> 68
