Workbook
Name nonparticipating_forecastzone_scale_factor: '[1]Energy Usage'!#REF!
Name nonparticipating_forecastzone_scale_factor: 'Energy Usage'!#REF!
Name Space_Function: Data!$A$2:$A$76

Sheet Notes
A1: Data Sources
A2: Dataset | B2: Dodge 2023
B3: CEUS 2022
B4: CBECS 2018
B5: ComStock 2023
A7: Prototype | B7: CEC Hospital prototype (CBECC 2022.3.1) | C7: https://bees.noresco.com/software2022.html
B8: PNNL Hospital prototype (90.1-2022 2019, 2013) | C8: https://www.energycodes.gov/prototype-building-models#Commercial
B9: DEER Hospital prototype (June 2024) | C9: https://github.com/sound-data/DEER-Prototypes-EnergyPlus
A11: Codes | B11: Title 24, part 6, referred to as T24 (1984, 2001, 2007, 2013, 2016, 2022, 2025)
B12: ASHRAE 90.1 (2022)
B13: ASHRAE 62.1 (2022)
B14: CFR Title 10 (2008, 2010, 2025)
B15: ASHRAE 170/OSHPD
B16: 2022 California Mechanical Code (Title 24, Part 4)
B17: ACM 2022
B18: T24 2022 - Appendix 5.4A and Appendix 5.4B
C19: https://www.energy.ca.gov/publications/2022/2022-nonresidential-and-multifamily-alternative-calculation-method-reference
A20: Others | B20: 2022 Reduced infiltration CASE report | C20: https://title24stakeholders.com/wp-content/uploads/2020/10/2022-T24-Final-CASE-Report_Reduce-Infiltration.pdf
B21: 2019 Outdoor Lighting CASE Report | C21: https://title24stakeholders.com/wp-content/uploads/2016/10/T24-2019-CASE-Study-Results-Report-Outdoor-Sources_Final_with-Attachments.pdf
B22: PNNL 20405, 2010 | C22: https://www.pnnl.gov/main/publications/external/technical_reports/PNNL-20405.pdf
B23: Air leakage Memo, NORESCO, 2025 | C23: https://2050partners.sharepoint.com/:w:/r/sites/CalBEMCollaborativeEfforts/Shared%20Documents/Working%20Group%201%20-%20Streamlined%20Process/D%20-%20Complexity%20of%20Compliance/Prototype%20Unification/Project%20Development/Phase%202%20(Collect%20Inputs)%20Development/NR/Air%20Leakage%20Memo/Infiltration_rate_report_14May2025-Short-Version.docx?d=w3bef8f747fac44f2a70cd76617660066&csf=1&web=1&e=wh5Dm4
B24: 2019 High Efficiency Fume Hoods in Laboratory Spaces CASE Report | C24: https://title24stakeholders.com/wp-content/uploads/2017/09/2019-T24-CASE-Report_Fume-Hoods_Final_September-2017.pdf?
A26: Construction Rate
A39: Notes
A40: Hospital | B40: A hospital, as defined across CEC, PNNL, and CPUC prototypes, is a large, full-service inpatient healthcare facility that operates 24/7, providing acute medical care, surgical services, and diagnostic treatment. It includes patient rooms, operating suites, labs, and support areas, and is typically served by 100% outdoor air HVAC systems with strict ventilation and pressurization controls.
A41: EIA, 2018 CBECS | B41: On average, hospitals were 264,800 square feet per building, but outpatient health care buildings averaged 13,700 square feet.
A42: Source | B42: https://www.eia.gov/consumption/commercial/

Sheet Prototype
A1: NORESCO, Updated August 2025
A2: Hospital
A3: Characteristic | B3: Value | C3: Data Sources
A4: Building Type | B4: Hospital
A5: Building Category | B5: Nonresidential
A6: Vintages | B6: 4 Vintages: Pre-1978 , 1978-1997 ,1998-2007 , 2008-2018 New Construction (2019+) | C6: Based on the vintage bin analysis | D6: NonRes-Vintage bins-Draft Report-30Nov2023-Final.docx
A7: Shape | C7: The analysis uses prototype geometry originally developed by PNNL. The CEC prototypes also adopt this geometry as a foundation.
A8: Total Floor Area (ft²) | B8: 241500 (230 ft x 175 ft for each floor) | C8: Same as CEC and PNNL
A9: Aspect Ratio | B9: 1.31 | C9: Same as CEC and PNNL
A10: Number of Floors | B10: 5 (plus basement) | C10: Same as CEC and PNNL
A11: Roof type | B11: Flat roof | C11: Same as CEC and PNNL
A12: WWR | B12: North: 12%, East: 13%, South: 15%, West: 24% Average Total: 16% | C12: Same as CEC and PNNL
A13: Shading Geometry | B13: No Shades | C13: Same as CEC and PNNL
A14: Floor to floor height (feet) | B14: Ground floor: 8 ft Upper floors: 14 ft | C14: Same as CEC and PNNL
A15: Floor to ceiling height (feet) | B15: No ceiling; plenum is modeled | C15: Same as CEC and PNNL
A16: Glazing sill height (feet) | B16: 3 ft (4 ft high windows) | C16: Same as CEC and PNNL
A19: Above grade wall area (ft²) | B19: 56720
A20: Gross wall area (ft²) | B20: 63203
A21: Roof area (ft²) | B21: 40254
A22: Underground Gross Wall Area (ft²) | B22: 6482

Sheet Zones
A1: ="Proposed Layout - "&Prototype!A2 -> Proposed Layout - Hospital
A2: Space Type | B2: Space/Thermal Zone | C2: HVAC System Name / AHU Name | D2: Schedule Category | E2: Conditioned (Y/N) | F2: Area Fraction | G2: Area (ft²) | H2: Volume (ft³) | I2: Multipliers | J2: Total Area (ft²) | K2: Number of People | L2: People (Persons/1,000 ft²) [T24, 2025,Table 120.1-A] | M2: Note
A3: Office Area (>250 square feet) | B3: Basement | C3: VAV 1 | D3: Office | E3: Yes | F3: =J3/$J$58 -> 0.1666661 | G3: 40253.93 | H3: 322126.45 | I3: 1 | J3: =I3*G3 -> 40253.93 | K3: =L3*G3/1000 -> 201.26965 | L3: 5
A4: Corridor Area | B4: Corridor_flr_1 | C4: VAV 1 | D4: Health | E4: Yes | F4: =J4/$J$58 -> 0.025362241 | G4: 6125.6 | H4: 85784.61 | I4: 1 | J4: =I4*G4 -> 6125.6 | K4: =L4*G4/1000 -> 30.628 | L4: 5
A5: Corridor Area | B5: Corridor_flr_2 | C5: VAV 1 | D5: Health | E5: Yes | F5: =J5/$J$58 -> 0.025362241 | G5: 6125.6 | H5: 85784.61 | I5: 1 | J5: =I5*G5 -> 6125.6 | K5: =L5*G5/1000 -> 30.628 | L5: 5
A6: Corridor Area | B6: Corridor_flr_5 | C6: VAV 2 | D6: Health | E6: Yes | F6: =J6/$J$58 -> 0.022360184 | G6: 5400.53 | H6: 75630.51 | I6: 1 | J6: =I6*G6 -> 5400.53 | K6: =L6*G6/1000 -> 27.00265 | L6: 5
A7: Corridor Area | B7: Corridor_nw_flr_3 | C7: VAV 2 | D7: Health | E7: Yes | F7: =J7/$J$58 -> 0.025258732 | G7: 6100.6 | H7: 85434.47 | I7: 1 | J7: =I7*G7 -> 6100.6 | K7: =L7*G7/1000 -> 30.503 | L7: 5
A8: Corridor Area | B8: Corridor_nw_flr_4 | C8: VAV 2 | D8: Health | E8: Yes | F8: =J8/$J$58 -> 0.025258732 | G8: 6100.6 | H8: 85434.47 | I8: 1 | J8: =I8*G8 -> 6100.6 | K8: =L8*G8/1000 -> 30.503 | L8: 5
A9: Corridor Area | B9: Corridor_se_flr_3 | C9: VAV 2 | D9: Health | E9: Yes | F9: =J9/$J$58 -> 0.025258732 | G9: 6100.6 | H9: 85434.47 | I9: 1 | J9: =I9*G9 -> 6100.6 | K9: =L9*G9/1000 -> 30.503 | L9: 5
A10: Corridor Area | B10: Corridor_se_flr_4 | C10: VAV 2 | D10: Health | E10: Yes | F10: =J10/$J$58 -> 0.025258732 | G10: 6100.6 | H10: 85434.47 | I10: 1 | J10: =I10*G10 -> 6100.6 | K10: =L10*G10/1000 -> 30.503 | L10: 5
A11: Dining Area (Cafeteria/Fast Food) | B11: Dining_flr_5 | C11: VAV 2 | D11: Restaurant | E11: Yes | F11: =J11/$J$58 -> 0.031055786 | G11: 7500.73 | H11: 105042.38 | I11: 1 | J11: =I11*G11 -> 7500.73 | K11: =L11*G11/1000 -> 247.52409 | L11: 33
A12: Healthcare Facility and Hospitals (Exam/Treatment Room) | B12: Er_exam1_mult4_flr_1 | C12: VAV ER | D12: Health24/7 | E12: Yes | F12: =J12/$J$58 -> 0.004968939 | G12: 300.03 | H12: 4201.7 | I12: 4 | J12: =I12*G12 -> 1200.12 | K12: =L12*G12/1000 -> 1.50015 | L12: 5 | M12: Table 120.1-A- 2025 T24-Misc-All Other
A13: Healthcare Facility and Hospitals (Exam/Treatment Room) | B13: Er_exam3_mult4_flr_1 | C13: VAV ER | D13: Health24/7 | E13: Yes | F13: =J13/$J$58 -> 0.004968939 | G13: 300.03 | H13: 4201.7 | I13: 4 | J13: =I13*G13 -> 1200.12 | K13: =L13*G13/1000 -> 1.50015 | L13: 5
A14: Healthcare Facility and Hospitals (Nurse's Station) | B14: Er_nursestn_lobby_flr_1 | C14: VAV 1 | D14: Health24/7 | E14: Yes | F14: =J14/$J$58 -> 0.055072283 | G14: 13301.3 | H14: 186275.15 | I14: 1 | J14: =I14*G14 -> 13301.3 | K14: =L14*G14/1000 -> 66.5065 | L14: 5
A15: Healthcare Facility and Hospitals (Exam/Treatment Room) | B15: Er_trauma1_flr_1 | C15: VAV ER | D15: Health24/7 | E15: Yes | F15: =J15/$J$58 -> 0.0012422347 | G15: 300.03 | H15: 4201.7 | I15: 1 | J15: =I15*G15 -> 300.03 | K15: =L15*G15/1000 -> 1.50015 | L15: 5
A16: Healthcare Facility and Hospitals (Exam/Treatment Room) | B16: Er_trauma2_flr_1 | C16: VAV ER | D16: Health24/7 | E16: Yes | F16: =J16/$J$58 -> 0.0012422347 | G16: 300.03 | H16: 4201.7 | I16: 1 | J16: =I16*G16 -> 300.03 | K16: =L16*G16/1000 -> 1.50015 | L16: 5
A17: Healthcare Facility and Hospitals (Exam/Treatment Room) | B17: Er_triage_mult4_flr_1 | C17: VAV ER | D17: Health24/7 | E17: Yes | F17: =J17/$J$58 -> 0.004968939 | G17: 300.03 | H17: 4201.7 | I17: 4 | J17: =I17*G17 -> 1200.12 | K17: =L17*G17/1000 -> 1.50015 | L17: 5
A18: Healthcare Facility and Hospitals (Recovery Room) | B18: Icu_flr_2 | C18: VAV ICU | D18: Health24/7 | E18: Yes | F18: =J18/$J$58 -> 0.027543221 | G18: 6652.36 | H18: 93161.52 | I18: 1 | J18: =I18*G18 -> 6652.36 | K18: =L18*G18/1000 -> 33.2618 | L18: 5 | M18: Intensive Care Unit, for lighting we can go with the general lighting for the patient room but for other EPD and ventilation refer to the CA mechanical code
A19: Healthcare Facility and Hospitals (Nurse's Station) | B19: Icu_nursestn_lobby_flr_2 | C19: VAV 1 | D19: Health24/7 | E19: Yes | F19: =J19/$J$58 -> 0.029807589 | G19: 7199.26 | H19: 100820.51 | I19: 1 | J19: =I19*G19 -> 7199.26 | K19: =L19*G19/1000 -> 35.9963 | L19: 5
A20: Healthcare Facility and Hospitals (Recovery Room) | B20: Ic_patroom1_mult5_flr_2 | C20: VAV ICU | D20: Health24/7 | E20: Yes | F20: =J20/$J$58 -> 0.0046583285 | G20: 225.02 | H20: 3151.27 | I20: 5 | J20: =I20*G20 -> 1125.1 | K20: =L20*G20/1000 -> 1.1251 | L20: 5
A21: Healthcare Facility and Hospitals (Recovery Room) | B21: Ic_patroom2_flr_2 | C21: VAV ICU | D21: Health24/7 | E21: Yes | F21: =J21/$J$58 -> 0.0012422347 | G21: 300.03 | H21: 4201.7 | I21: 1 | J21: =I21*G21 -> 300.03 | K21: =L21*G21/1000 -> 1.50015 | L21: 5
A22: Healthcare Facility and Hospitals (Recovery Room) | B22: Ic_patroom3_mult6_flr_2 | C22: VAV ICU | D22: Health24/7 | E22: Yes | F22: =J22/$J$58 -> 0.0055899942 | G22: 225.02 | H22: 3151.27 | I22: 6 | J22: =I22*G22 -> 1350.12 | K22: =L22*G22/1000 -> 1.1251 | L22: 5
A23: Kitchen/Food Preparation Area | B23: Kitchen_flr_5 | C23: CAV Kitchen | D23: Kitchen | E23: Yes | F23: =J23/$J$58 -> 0.041407742 | G23: 10000.98 | H23: 140056.5 | I23: 1 | J23: =I23*G23 -> 10000.98 | K23: =L23*G23/1000 -> 30.00294 | L23: 3
A24: Laboratory, Scientific | B24: Lab_flr_3 | C24: VAV Laboratory | D24: Health | E24: Yes | F24: =J24/$J$58 -> 0.011801209 | G24: 2850.28 | H24: 39916.1 | I24: 1 | J24: =I24*G24 -> 2850.28 | K24: =L24*G24/1000 -> 14.2514 | L24: 5 | M24: Change it back to 5 same as CEC and PNNL
A25: Laboratory, Scientific | B25: Lab_flr_4 | C25: VAV Laboratory | D25: Health | E25: Yes | F25: =J25/$J$58 -> 0.011801209 | G25: 2850.28 | H25: 39916.1 | I25: 1 | J25: =I25*G25 -> 2850.28 | K25: =L25*G25/1000 -> 14.2514 | L25: 5
A26: Lobby, Main Entry | B26: Lobby_records_flr_1 | C26: VAV 1 | D26: Health | E26: Yes | F26: =J26/$J$58 -> 0.065733648 | G26: 15876.28 | H26: 222335.92 | I26: 1 | J26: =I26*G26 -> 15876.28 | K26: =L26*G26/1000 -> 523.91724 | L26: 33
A27: Healthcare Facility and Hospitals (Nurse's Station) | B27: Nursestn_lobby_flr_3 | C27: VAV 2 | D27: Health24/7 | E27: Yes | F27: =J27/$J$58 -> 0.040372526 | G27: 9750.95 | H27: 136555.09 | I27: 1 | J27: =I27*G27 -> 9750.95 | K27: =L27*G27/1000 -> 48.75475 | L27: 5
A28: Healthcare Facility and Hospitals (Nurse's Station) | B28: Nursestn_lobby_flr_4 | C28: VAV 2 | D28: Health24/7 | E28: Yes | F28: =J28/$J$58 -> 0.040372526 | G28: 9750.95 | H28: 136555.09 | I28: 1 | J28: =I28*G28 -> 9750.95 | K28: =L28*G28/1000 -> 48.75475 | L28: 5
A29: Healthcare Facility and Hospitals (Nurse's Station) | B29: Nursestn_lobby_flr_5 | C29: VAV 2 | D29: Health24/7 | E29: Yes | F29: =J29/$J$58 -> 0.046376639 | G29: 11201.09 | H29: 156863.28 | I29: 1 | J29: =I29*G29 -> 11201.09 | K29: =L29*G29/1000 -> 56.00545 | L29: 5
A30: Office Area (>250 square feet) | B30: Office1_flr_5 | C30: VAV 2 | D30: Office | E30: Yes | F30: =J30/$J$58 -> 0.0031063942 | G30: 750.27 | H30: 10507.01 | I30: 1 | J30: =I30*G30 -> 750.27 | K30: =L30*G30/1000 -> 3.75135 | L30: 5
A31: Office Area (<250 square feet) | B31: Office1_mult5_flr_1 | C31: VAV 1 | D31: Office | E31: Yes | F31: =J31/$J$58 -> 0.0031054833 | G31: 150.01 | H31: 2100.85 | I31: 5 | J31: =I31*G31 -> 750.05 | K31: =L31*G31/1000 -> 0.75005 | L31: 5
A32: Office Area (>250 square feet) | B32: Office2_mult5_flr_5 | C32: VAV 2 | D32: Office | E32: Yes | F32: =J32/$J$58 -> 0.015527831 | G32: 750.07 | H32: 10502.39 | I32: 5 | J32: =I32*G32 -> 3750.35 | K32: =L32*G32/1000 -> 3.75035 | L32: 5
A33: Office Area (>250 square feet) | B33: Office3_flr_5 | C33: VAV 2 | D33: Office | E33: Yes | F33: =J33/$J$58 -> 0.0031055661 | G33: 750.07 | H33: 10504.24 | I33: 1 | J33: =I33*G33 -> 750.07 | K33: =L33*G33/1000 -> 3.75035 | L33: 5
A34: Office Area (<250 square feet) | B34: Office4_mult6_flr_5 | C34: VAV 2 | D34: Office | E34: Yes | F34: =J34/$J$58 -> 0.00372658 | G34: 150.01 | H34: 2100.85 | I34: 6 | J34: =I34*G34 -> 900.06 | K34: =L34*G34/1000 -> 0.75005 | L34: 5
A35: Healthcare Facility and Hospitals (Operating Room) | B35: Or1_flr_2 | C35: VAV OR | D35: Health | E35: Yes | F35: =J35/$J$58 -> 0.0024844695 | G35: 600.06 | H35: 8403.39 | I35: 1 | J35: =I35*G35 -> 600.06 | K35: =L35*G35/1000 -> 3.0003 | L35: 5
A36: Healthcare Facility and Hospitals (Operating Room) | B36: Or2_mult5_flr_2 | C36: VAV OR | D36: Health | E36: Yes | F36: =J36/$J$58 -> 0.012422347 | G36: 600.06 | H36: 8403.39 | I36: 5 | J36: =I36*G36 -> 3000.3 | K36: =L36*G36/1000 -> 3.0003 | L36: 5
... A57: Healthcare Facility and Hospitals (Imaging Room) | B57: Radiology_flr_4 | C57: VAV 2 | D57: Health | E57: Yes | F57: =J57/$J$58 -> 0.021739046 | G57: 5250.51 | H57: 73529.66 | I57: 1 | J57: =I57*G57 -> 5250.51 | K57: =L57*G57/1000 -> 26.25255 | L57: 5
A58: Total (12 Space types) | B58: Total ( 162 spaces) | C58: Total ( Thermal Zones) | E58: Total ( 162 Conditioned zones) | J58: =SUM(J3:J57) -> 241524.4 | K58: =SUM(K3:K57) -> 1705.1352
A61: Occupancy rate of the patient rooms: | B61: 0.55
A62: Source: A report published by California Health Care Foundation, 2022
...

Sheet Envelope
A1: ="Envelope - "&Prototype!A2 -> Envelope - Hospital
A2: Element | B2: Prototype | C2: Assembly Type | D2: Construction | E2: Thermal Properties | F2: Vintage | G2: Selected T24 | H2: Note | I2: CZ1 | J2: CZ2 | K2: CZ3 | L2: CZ4 | M2: CZ5 | N2: CZ6 | O2: CZ7 | P2: CZ8 | Q2: CZ9 | R2: CZ10 | S2: CZ11 | T2: CZ12 | U2: CZ13 | V2: CZ14 | W2: CZ15 | X2: CZ16
A3: External Wall | B3: Hospital | C3: ExtWall_MetalFramed_NonRes | D3: Metal frame + insulation + gypsum board (Same as CEC and DEER. PNNL has Mass wall)) | E3: U-factor IP | F3: Pre 1978 | G3: N/A | H3: ASHRAE 90.1,2022 Table A3.3.3.1, 3.5", R-0 | I3: 0.352 | J3: 0.352 | K3: 0.352 | L3: 0.352 | M3: 0.352 | N3: 0.352 | O3: 0.352 | P3: 0.352 | Q3: 0.352 | R3: 0.352 | S3: 0.352 | T3: 0.352 | U3: 0.352 | V3: 0.352 | W3: 0.352 | X3: 0.352
F4: 1978-1997 | G4: 1986 | H4: Copied from High-rise office alternative requirements (Table 2-53W): Package A with heat capacity around 10 (Btu/F-ft²) | I4: 0.213 | J4: 0.227 | K4: 0.227 | L4: 0.217 | M4: 0.256 | N4: 0.256 | O4: 0.256 | P4: 0.256 | Q4: 0.256 | R4: 0.256 | S4: 0.238 | T4: 0.238 | U4: 0.238 | V4: 0.208 | W4: 0.208 | X4: 0.213
F5: 1998-2007 | G5: 2001 | H5: Table 1-H | I5: 0.182 | J5: 0.182 | K5: 0.189 | L5: 0.189 | M5: 0.189 | N5: 0.189 | O5: 0.189 | P5: 0.189 | Q5: 0.189 | R5: 0.182 | S5: 0.182 | T5: 0.182 | U5: 0.182 | V5: 0.182 | W5: 0.182 | X5: 0.182
F6: 2008-2018 | G6: 2013 | H6: Table 140.3-B | I6: 0.098 | J6: 0.062 | K6: 0.082 | L6: 0.062 | M6: 0.062 | N6: 0.098 | O6: 0.098 | P6: 0.062 | Q6: 0.062 | R6: 0.062 | S6: 0.062 | T6: 0.062 | U6: 0.062 | V6: 0.062 | W6: 0.062 | X6: 0.062
F7: 2019+ | G7: 2025 | H7: Table 140.3-B | I7: 0.06 | J7: 0.055 | K7: 0.071 | L7: 0.055 | M7: 0.055 | N7: 0.06 | O7: 0.06 | P7: 0.055 | Q7: 0.055 | R7: 0.055 | S7: 0.055 | T7: 0.055 | U7: 0.055 | V7: 0.055 | W7: 0.055 | X7: 0.055
A8: Roof | B8: Hospital | C8: FlatRoof_WoodFramedAndOther_NonRes | D8: Built-up Roof (Metal Decking Roof) Roof membrane + roof insulation + metal decking (Same as PNNL and DEER-Metal roof- CEC has wood-framed roof) | E8: U-factor IP | F8: Pre 1978 | G8: N/A | H8: Considering 30 years for roof/ insulation replacement. | I8: 0.057 | J8: 0.057 | K8: 0.057 | L8: 0.057 | M8: 0.057 | N8: 0.078 | O8: 0.078 | P8: 0.078 | Q8: 0.078 | R8: 0.078 | S8: 0.057 | T8: 0.057 | U8: 0.057 | V8: 0.057 | W8: 0.057 | X8: 0.057
F9: 1978-1997 | G9: 1992 | I9: 0.057 | J9: 0.057 | K9: 0.057 | L9: 0.057 | M9: 0.057 | N9: 0.078 | O9: 0.078 | P9: 0.078 | Q9: 0.078 | R9: 0.078 | S9: 0.057 | T9: 0.057 | U9: 0.057 | V9: 0.057 | W9: 0.057 | X9: 0.057
F10: 1998-2007 | G10: 2001 | H10: Table 1-H | I10: 0.057 | J10: 0.057 | K10: 0.057 | L10: 0.057 | M10: 0.057 | N10: 0.078 | O10: 0.078 | P10: 0.078 | Q10: 0.078 | R10: 0.057 | S10: 0.057 | T10: 0.057 | U10: 0.057 | V10: 0.057 | W10: 0.057 | X10: 0.057
F11: 2008-2018 | G11: 2013 | H11: Table 140.3-B | I11: 0.049 | J11: 0.039 | K11: 0.039 | L11: 0.039 | M11: 0.049 | N11: 0.075 | O11: 0.067 | P11: 0.067 | Q11: 0.039 | R11: 0.039 | S11: 0.039 | T11: 0.039 | U11: 0.039 | V11: 0.039 | W11: 0.039 | X11: 0.039
F12: 2019+ | G12: 2025 | H12: Table 140.3-B | I12: 0.038 | J12: 0.038 | K12: 0.038 | L12: 0.038 | M12: 0.038 | N12: 0.038 | O12: 0.038 | P12: 0.038 | Q12: 0.038 | R12: 0.038 | S12: 0.038 | T12: 0.038 | U12: 0.038 | V12: 0.038 | W12: 0.038 | X12: 0.038
A13: Windows | B13: Hospital | C13: FixedWindow_NonRes | D13: Single pane | E13: U-factor IP | F13: Pre 1978 | G13: N/A | H13: ASHRAE Handbook of Fundamentals (Table 4-Ch15) for single pane & T24, 2013 for double pane(33%-67%)* | I13: =0.338*1.12+0.67*0.36 -> 0.61976 | J13: =0.338*1.12+0.67*0.36 -> 0.61976 | K13: =0.338*1.12+0.67*0.36 -> 0.61976 | L13: =0.338*1.12+0.67*0.36 -> 0.61976 | M13: =0.338*1.12+0.67*0.36 -> 0.61976 | N13: =0.338*1.12+0.67*0.36 -> 0.61976 | O13: =0.338*1.12+0.67*0.36 -> 0.61976 | P13: =0.338*1.12+0.67*0.36 -> 0.61976 | ... X13: =0.338*1.12+0.67*0.36 -> 0.61976
F14: 1978-1997 | G14: N/A | I14: =0.338*1.12+0.67*0.36 -> 0.61976 | J14: =0.338*1.12+0.67*0.36 -> 0.61976 | K14: =0.338*1.12+0.67*0.36 -> 0.61976 | L14: =0.338*1.12+0.67*0.36 -> 0.61976 | M14: =0.338*1.12+0.67*0.36 -> 0.61976 | N14: =0.338*1.12+0.67*0.36 -> 0.61976 | O14: =0.338*1.12+0.67*0.36 -> 0.61976 | P14: =0.338*1.12+0.67*0.36 -> 0.61976 | ... X14: =0.338*1.12+0.67*0.36 -> 0.61976
D15: Double pane | F15: 1998-2007 | G15: 2001 | H15: Table 1-H | I15: 0.49 | J15: 0.49 | K15: 0.81 | L15: 0.81 | M15: 0.81 | N15: 0.81 | O15: 0.81 | P15: 0.81 | Q15: 0.81 | R15: 0.49 | S15: 0.49 | T15: 0.49 | U15: 0.49 | V15: 0.49 | W15: 0.49 | X15: 0.49
F16: 2008-2018 | G16: 2013 | H16: Table 140.3-B | I16: 0.36 | J16: 0.36 | K16: 0.36 | L16: 0.36 | M16: 0.36 | N16: 0.36 | O16: 0.36 | P16: 0.36 | Q16: 0.36 | R16: 0.36 | S16: 0.36 | T16: 0.36 | U16: 0.36 | V16: 0.36 | W16: 0.36 | X16: 0.36
F17: 2019+ | G17: 2025 | H17: Table 140.3-B | I17: 0.36 | J17: 0.36 | K17: 0.36 | L17: 0.36 | M17: 0.36 | N17: 0.36 | O17: 0.36 | P17: 0.36 | Q17: 0.34 | R17: 0.36 | S17: 0.34 | T17: 0.34 | U17: 0.34 | V17: 0.34 | W17: 0.34 | X17: 0.36
B18: Hospital | C18: FixedWindow_NonRes | D18: Single pane | E18: SHGC | F18: Pre 1978 | G18: N/A | H18: ASHRAE Handbook of Fundamentals (Table 10-Ch15) for single pane & T24, 2013 for double pane(33%-67%)* | I18: =0.79*0.33+0.67*I21 -> 0.4282 | J18: =0.79*0.33+0.67*J21 -> 0.4282 | K18: =0.79*0.33+0.67*K21 -> 0.4282 | L18: =0.79*0.33+0.67*L21 -> 0.4282 | M18: =0.79*0.33+0.67*M21 -> 0.4282 | N18: =0.79*0.33+0.67*N21 -> 0.4282 | O18: =0.79*0.33+0.67*O21 -> 0.4282 | P18: =0.79*0.33+0.67*P21 -> 0.4282 | ... X18: =0.79*0.33+0.67*X21 -> 0.4282
F19: 1978-1997 | G19: N/A | I19: =0.79*0.33+0.67*I21 -> 0.4282 | J19: =0.79*0.33+0.67*J21 -> 0.4282 | K19: =0.79*0.33+0.67*K21 -> 0.4282 | L19: =0.79*0.33+0.67*L21 -> 0.4282 | M19: =0.79*0.33+0.67*M21 -> 0.4282 | N19: =0.79*0.33+0.67*N21 -> 0.4282 | O19: =0.79*0.33+0.67*O21 -> 0.4282 | P19: =0.79*0.33+0.67*P21 -> 0.4282 | ... X19: =0.79*0.33+0.67*X21 -> 0.4282
D20: Double pane | F20: 1998-2007 | G20: 2001 | H20: Table 1-H - WWR:10-20% / SHGC non-north | I20: 0.43 | J20: 0.36 | K20: 0.55 | L20: 0.55 | M20: 0.55 | N20: 0.61 | O20: 0.61 | P20: 0.61 | Q20: 0.61 | R20: 0.36 | S20: 0.36 | T20: 0.36 | U20: 0.36 | V20: 0.36 | W20: 0.36 | X20: 0.43
F21: 2008-2018 | G21: 2013 | H21: Table 140.3-B | I21: 0.25 | J21: 0.25 | K21: 0.25 | L21: 0.25 | M21: 0.25 | N21: 0.25 | O21: 0.25 | P21: 0.25 | Q21: 0.25 | R21: 0.25 | S21: 0.25 | T21: 0.25 | U21: 0.25 | V21: 0.25 | W21: 0.25 | X21: 0.25
F22: 2019+ | G22: 2025 | H22: Table 140.3-B | I22: 0.25 | J22: 0.25 | K22: 0.25 | L22: 0.25 | M22: 0.25 | N22: 0.25 | O22: 0.25 | P22: 0.25 | Q22: 0.22 | R22: 0.25 | S22: 0.22 | T22: 0.22 | U22: 0.22 | V22: 0.22 | W22: 0.22 | X22: 0.25
E25: Infiltration
F26: Vintage | G26: I_75 6-sdied Infiltration rate @ 75 pa | H26: Note | I26: I-design (cfm/ft²) (4-sided Infiltration rate at normal pressure) (Design flow rate approach and Flow/Exterior Wall Area calculation method)
E27: Infiltration | F27: Pre 1978 | G27: 1.1 | H27: 2022 CASE report (Table 38) | I27: 0.3121
F28: 1978-1997 | G28: 1.1 | H28: 2022 CASE report (Table 38) | I28: 0.3121
F29: 1998-2007 | G29: 1.1 | H29: 2022 CASE report (Table 38) | I29: 0.3121
F30: 2008-2018 | G30: 1 | H30: 2022 CASE report (Table 38) & T24, 2008-2016 (Table 140.3-B)--Air barrier is required in CZ 10-16 | I30: 0.2856
F31: 2019+ | G31: 0.6 | H31: 2022 CASE report (Table 38) & T24, 2025 (Table 140.3-B)-Air barrier is required in all CZs | I31: 0.1703
E32: Source: Title 24 air barrier requirements (all editions) and the standardized infiltration rate reported in the 2022 CASE report and Dodge 2023 data
E33: Air Leakage Memo: | G33: Infiltration_rate_report_14May2025-Short-Version.docx

Sheet HVAC System
A1: ="HVAC system - "&Prototype!A2 -> HVAC system - Hospital
A2: Vintage | B2: Zones | C2: Heating | D2: Cooling | E2: Air Distribution | F2: Other Systems | G2: Source | H2: Note
A3: Existing | B3: Kitchen | C3: Gas Boiler | D3: Chiller | E3: CAV | F3: CAV exhaust system with rooftop makeup air units, no energy recovery and no Demand Control | G3: CEUS 2022(Other system based on T24 and Engineering judgement)
B4: All other conditioned zones | C4: Gas Boiler | D4: Chiller | E4: CAV + Hydronic Reheat | G4: CEUS 2022(Other system based on T24 and Engineering judgement)
A5: New Construction | B5: Kitchen | C5: Gas Boiler | D5: Chiller | E5: VAV | F5: A VAV dedicated MAU with tempered outside air, with exhaust hood and demand control ventilation | G5: T24 2025 ACM 2025, Table 2 and 3 | H5: System 13 a - Built-up kitchen MAU
B6: All other conditioned zones (ER, ICU, Labs, OR, Patient Rms) | C6: Gas Boiler | D6: Chiller | E6: VAV + Hydronic Reheat | G6: T24 2025 ACM 2025, Table 2 and 3 | H6: System 6 – VAV
A11: Efficiency of HVAC system (Efficiency is capacity-dependent. The following Table provides a general estimate of system efficiency based on what we saw in the existing prototype runs, or assuming cooling load based on rule of thumb)
B12: Upgrade/Installed year | C12: Water Cooled Chiller | D12: Gas Boiler | E12: Heat Rejection (Cooling Tower) | F12: Sources | G12: Note
A13: Pre 1978 | B13: 2008 | C13: Water Cooled, Electrically Operated, Centrifugal--≥ 300 tons and < 600 tons - 5.55 COP 5.90 IPLV | D13: n/a | E13: Axial fan Open-circuit cooling tower--95°F entering water 85°F leaving water 75°F entering air wb--≥ 38.2 gpm/hp | F13: T24, 2008, Table 112-D (for chiller COP) – Table 112-G (for boiler thermal efficiency)
A14: 1978-1997
A15: 1998-2007
A16: 2008-2018 | B16: 2013 | C16: Water Cooled, Electrically Operated, Centrifugal--≥ 300 tons and < 600 tons --≤ 0.576 kW/ton ≤ 0.549 IPLV (Path A) | D16: 82% Ec | E16: Axial fan Open-circuit cooling tower--95°F entering water 85°F leaving water 75°F entering air wb--≥ 42.1 gpm/hp | F16: T24, 2013 , Table 110.2-D (for chiller COP) - Table 110.2-J (for Boiler thermal efficiency)
A17: New Construction | B17: 2025 | C17: Water Cooled, Electrically Operated, Centrifugal--≥ 300 tons and < 400 ton--≤ 0.560 kW/ton ≤ 0.520 IPLV (Path A) | D17: Gas-Fired Boiler > 2,500,000 Btu/h and ≤10,000,000 Btu/h-- 85% Ec | E17: Axial fan Open-circuit cooling tower--95°F entering water 85°F leaving water 75°F entering air wb--≥ 42.1 gpm/hp | F17: T24, 2025 , Table 110.2-D (for chiller COP) - Table 110.2-J (for Boiler thermal efficiency)
C19: * Ec = combustion efficiency
A24: Fan power
A25: Vintage | B25: Approach | C25: System | D25: Total Static Pressure (TSP) in w.c. [PNNL 20405, 2010, Table 5.11] | E25: Fan Efficiency [ACM, 2025] | F25: Fan Motor and Drive Efficiency [ACM 2025, Table 13] | G25: W/cfm [ACM 2025, Table 14 and 15] | H25: Data Source | I25: Note
A26: Existing | B26: PNNL TSP | C26: Kitchen System CAVMAU | D26: 4.09 | E26: 0.65 | F26: 0.9 | H26: ACM 2025, PNNL 2010 TSD
C27: All Other Zones-FPFC (on/off) | D27: 1.33
A28: Brake horse power (bhp)=(Supply cfm*TSP in w.c.)/(6356*Fan efficiency)
A29: Fan power (w/cfm) = bhp/motor and drive efficiency *746
A30: New Construction | B30: ACM 2025 | C30: Kitchen System - VAVMAU System 6-VAV, >10,000 cfm | D30: =G30*E30*F30/746*6356 -> 4.7200968 | E30: 0.65 | F30: 0.9 | G30: 0.947 | H30: 2025 ACM
C31: All Other Zones System 6-VAV, >10,000 cfm | D31: =G31*E30*F30/746*6356 -> 4.7200968 | G31: 0.947
A33: Fan total eff (E+ input) = 0.65 x Motor_eff
A34: TSP (E+ input) in w.c. = Motor_eff/746 x (6356 x Fan_eff) x W/cfm
A35: Fan_eff=0.65
A37: Background Data [To be deleted prior to publication]
A39: CEUS 2022 data | B39: Heating | F39: Cooling | H39: Air Distribution | I39: Water Heater
B40: Floorspace Heated | C40: Primary Heating | D40: Fuel Type | F40: Floorspace Cooled | G40: Primary Cooling | H40: Primary Air Dis | I40: Fuel Type
C41: The default is the floorspace method unless otherwise specified | D41: Elec | E41: Gas | G41: The default is the floorspace method unless otherwise specified | H41: The default is the floorspace method unless otherwise specified | I41: Elec | J41: Gas
A42: Health Care | B42: 0.99 | C42: Floorspace method: | D42: 0.17 | E42: 0.81 | F42: 0.98 | G42: Floorspace method: | H42: Floorspace method: | I42: 0.1 | J42: 0.85
C43: Boiler/ Hydronic (43.9%) | G43: Central Plant (Chiller) (43.5%) | H43: Single Duct CAV (53.4%)
C44: Package System / Heat Pump (40.8%) | G44: Package System / Heat Pump (40.7%) | H44: Fan Coil/Unit Ventilator (21.3%)
C45: Site method: | G45: Site method: | H45: Site method:
C46: Boiler/ Hydronic (6.8%) | G46: Central Plant (Chiller) (6.5%) | H46: Single Duct CAV (91.4%)
C47: Package System / Heat Pump (72.1%) | G47: Package System / Heat Pump (71.5%) | H47: Fan Coil/Unit Ventilator (5.7%)

Sheet Ventilation
A1: =O3 -> Outdoor Airflow Rate - Hospital
A2: Space Type | B2: Space/Thermal Zone | C2: Number of People | D2: Floor Area (ft²) | E2: cfm/person [T24, 2025, Equation 120.1-F and Table 120.1-A] | F2: cfm/ft² [T24, 2025, Equation 120.1-F and Table 120.1-A] | G2: Required exhaust rate (cfm/ft) [T24, 2025, Table 120.1-B – minimum exhaust rates] | H2: Min OA Ventilation Requirement (cfm/ft) [Table 4-A, 2022 California Mechanical Code] | I2: Total cfm driven by people | J2: Total cfm driven by area | K2: Total cfm driven by exhaust | L2: Total cfm | M2: Note
A3: Office Area (>250 square feet) | B3: Basement | C3: =Zones!K3 -> 201.26965 | D3: =Zones!J3 -> 40253.93 | E3: 15 | F3: =VLOOKUP(A3,O$4:S$17,5) -> 0.15 | H3: =VLOOKUP(A3,O$4:V$17,8) -> 0 | I3: =E3*C3 -> 3019.0447 | J3: =F3*D3 -> 6038.0895 | L3: =MAX(I3:K3) -> 6038.0895 | O3: ="Outdoor Airflow Rate - "&Prototype!A2 -> Outdoor Airflow Rate - Hospital
A4: Corridor Area | B4: Corridor_flr_1 | C4: =Zones!K4 -> 30.628 | D4: =Zones!J4 -> 6125.6 | E4: 15 | F4: =VLOOKUP(A4,O$4:S$17,5) -> 0.15 | H4: =VLOOKUP(A4,O$4:V$17,8) -> 0 | I4: =E4*C4 -> 459.42 | J4: =F4*D4 -> 918.84 | L4: =MAX(I4:K4) -> 918.84 | O4: Space Type | P4: Total Area (ft²) | Q4: Min. occupancy load (persons/1000 ft²) | R4: Total Number of Occupants | S4: cfm/ft² (Table 120.1-A – Minimum Ventilation Rates) | T4: Required Exhaust Rate-cfm/ft² (Table 120.1-B – Minimum Exhaust Rates) | U4: Min OA Ventilation Requirement-ACH-(Table 4-A, 2022 California Mechanical Code) | V4: Min OA Ventilation Requirement-cfm/ft²-(Table 4-A, 2022 California Mechanical Code) | W4: cfm
A5: Corridor Area | B5: Corridor_flr_2 | C5: =Zones!K5 -> 30.628 | D5: =Zones!J5 -> 6125.6 | E5: 15 | F5: =VLOOKUP(A5,O$4:S$17,5) -> 0.15 | H5: =VLOOKUP(A5,O$4:V$17,8) -> 0 | I5: =E5*C5 -> 459.42 | J5: =F5*D5 -> 918.84 | L5: =MAX(I5:K5) -> 918.84 | O5: =Zones!A3 -> Office Area (>250 square feet) | P5: =SUMIF(Zones!A$3:A$57, "*Office Area (>250 square feet)*", Zones!J$3:J$57) -> 45504.62 | Q5: =Zones!L3 -> 5 | R5: =(P5/1000)*Q5 -> 227.5231 | S5: 0.15 | T5: 0 | W5: =MAX(R5*15,P5*S5,P5*T5,P5*V5) -> 6825.693
A6: Corridor Area | B6: Corridor_flr_5 | C6: =Zones!K6 -> 27.00265 | D6: =Zones!J6 -> 5400.53 | E6: 15 | F6: =VLOOKUP(A6,O$4:S$17,5) -> 0.15 | H6: =VLOOKUP(A6,O$4:V$17,8) -> 0 | I6: =E6*C6 -> 405.03975 | J6: =F6*D6 -> 810.0795 | L6: =MAX(I6:K6) -> 810.0795 | O6: =Zones!A4 -> Corridor Area | P6: =SUMIF(Zones!A$3:A$57, "*Corridor Area*", Zones!J$3:J$57) -> 42054.13 | Q6: =Zones!L4 -> 5 | R6: =(P6/1000)*Q6 -> 210.27065 | S6: 0.15 | T6: 0 | W6: =MAX(R6*15,P6*S6,P6*T6,P6*V6) -> 6308.1195
A7: Corridor Area | B7: Corridor_nw_flr_3 | C7: =Zones!K7 -> 30.503 | D7: =Zones!J7 -> 6100.6 | E7: 15 | F7: =VLOOKUP(A7,O$4:S$17,5) -> 0.15 | H7: =VLOOKUP(A7,O$4:V$17,8) -> 0 | I7: =E7*C7 -> 457.545 | J7: =F7*D7 -> 915.09 | L7: =MAX(I7:K7) -> 915.09 | O7: =Zones!A11 -> Dining Area (Cafeteria/Fast Food) | P7: =SUMIF(Zones!A$3:A$57, "*Dining Area (Cafeteria/Fast Food)*", Zones!J$3:J$57) -> 7500.73 | Q7: =Zones!L11 -> 33 | R7: =(P7/1000)*Q7 -> 247.52409 | S7: 0.15 | T7: 0 | W7: =MAX(R7*15,P7*S7,P7*T7,P7*V7) -> 3712.8614
A8: Corridor Area | B8: Corridor_nw_flr_4 | C8: =Zones!K8 -> 30.503 | D8: =Zones!J8 -> 6100.6 | E8: 15 | F8: =VLOOKUP(A8,O$4:S$17,5) -> 0.15 | H8: =VLOOKUP(A8,O$4:V$17,8) -> 0 | I8: =E8*C8 -> 457.545 | J8: =F8*D8 -> 915.09 | L8: =MAX(I8:K8) -> 915.09 | O8: =Zones!A12 -> Healthcare Facility and Hospitals (Exam/Treatment Room) | P8: =SUMIF(Zones!A$3:A$57, "*Healthcare Facility and Hospitals (Exam/Treatment Room)*", Zones!J$3:J$57) -> 4200.42 | Q8: =Zones!L12 -> 5 | R8: =(P8/1000)*Q8 -> 21.0021 | T8: 0 | U8: 2 | V8: =(U8*14)/60 -> 0.46666667 | W8: =MAX(R8*15,P8*S8,P8*T8,P8*V8) -> 1960.196
A9: Corridor Area | B9: Corridor_se_flr_3 | C9: =Zones!K9 -> 30.503 | D9: =Zones!J9 -> 6100.6 | E9: 15 | F9: =VLOOKUP(A9,O$4:S$17,5) -> 0.15 | H9: =VLOOKUP(A9,O$4:V$17,8) -> 0 | I9: =E9*C9 -> 457.545 | J9: =F9*D9 -> 915.09 | L9: =MAX(I9:K9) -> 915.09 | O9: =Zones!A14 -> Healthcare Facility and Hospitals (Nurse's Station) | P9: =SUMIF(Zones!A$3:A$57, "*Healthcare Facility and Hospitals (Nurse's Station)*", Zones!J$3:J$57) -> 62104.61 | Q9: =Zones!L14 -> 5 | R9: =(P9/1000)*Q9 -> 310.52305 | T9: 0 | U9: 2 | V9: =(U9*14)/60 -> 0.46666667 | W9: =MAX(R9*15,P9*S9,P9*T9,P9*V9)+3137 -> 32119.151 | X9: *Negative pressure
A10: Corridor Area | B10: Corridor_se_flr_4 | C10: =Zones!K10 -> 30.503 | D10: =Zones!J10 -> 6100.6 | E10: 15 | F10: =VLOOKUP(A10,O$4:S$17,5) -> 0.15 | H10: =VLOOKUP(A10,O$4:V$17,8) -> 0 | I10: =E10*C10 -> 457.545 | J10: =F10*D10 -> 915.09 | L10: =MAX(I10:K10) -> 915.09 | O10: =Zones!A18 -> Healthcare Facility and Hospitals (Recovery Room) | P10: =SUMIF(Zones!A$3:A$57, "*Healthcare Facility and Hospitals (Recovery Room)*", Zones!J$3:J$57) -> 9427.61 | Q10: =Zones!L18 -> 5 | R10: =(P10/1000)*Q10 -> 47.13805 | T10: 0 | U10: 2 | V10: =(U10*14)/60 -> 0.46666667 | W10: =MAX(R10*15,P10*S10,P10*T10,P10*V10) -> 4399.5513 | X10: *Positive, No recirculation
A11: Dining Area (Cafeteria/Fast Food) | B11: Dining_flr_5 | C11: =Zones!K11 -> 247.52409 | D11: =Zones!J11 -> 7500.73 | E11: 15 | F11: =VLOOKUP(A11,O$4:S$17,5) -> 0.15 | H11: =VLOOKUP(A11,O$4:V$17,8) -> 0 | I11: =E11*C11 -> 3712.8614 | J11: =F11*D11 -> 1125.1095 | L11: =MAX(I11:K11) -> 3712.8614 | O11: =Zones!A24 -> Laboratory, Scientific | P11: =SUMIF(Zones!A$3:A$57, "*Laboratory-General Health*", Zones!J$3:J$57) -> 0 | Q11: =Zones!L24 -> 5 | R11: =(P11/1000)*Q11 -> 0 | T11: 1 | U11: 2 | V11: =(U11*14)/60 -> 0.46666667 | W11: =MAX(R11*15,P11*S11,P11*T11,P11*V11)+E67+E68 -> 3000 | X11: *Negative pressure
A12: Healthcare Facility and Hospitals (Exam/Treatment Room) | B12: Er_exam1_mult4_flr_1 | C12: =Zones!K12 -> 1.50015 | D12: =Zones!J12 -> 1200.12 | E12: 15 | F12: =VLOOKUP(A12,O$4:S$17,5) -> 0 | H12: 0.46666667 | I12: =E12*C12 -> 22.50225 | J12: =H12*D12 -> 560.056 | L12: =MAX(I12:K12) -> 560.056 | O12: =Zones!A35 -> Healthcare Facility and Hospitals (Operating Room) | P12: =SUMIF(Zones!A$3:A$57, "*Healthcare Facility and Hospitals (Operating Room)*", Zones!J$3:J$57) -> 6600.65 | Q12: =Zones!L35 -> 5 | R12: =(P12/1000)*Q12 -> 33.00325 | U12: 4 | V12: =(U12*14)/60 -> 0.93333333 | W12: =MAX(R12*15,P12*S12,P12*T12,P12*V12) -> 6160.6067
A13: Healthcare Facility and Hospitals (Exam/Treatment Room) | B13: Er_exam3_mult4_flr_1 | C13: =Zones!K13 -> 1.50015 | D13: =Zones!J13 -> 1200.12 | E13: 15 | F13: =VLOOKUP(A13,O$4:S$17,5) -> 0 | H13: 0.46666667 | I13: =E13*C13 -> 22.50225 | J13: =H13*D13 -> 560.056 | L13: =MAX(I13:K13) -> 560.056 | O13: =Zones!A56 -> Healthcare Facility and Hospitals (Physical Therapy Room) | P13: =SUMIF(Zones!A$3:A$57, "*Healthcare Facility and Hospitals (Physical Therapy Room)*", Zones!J$3:J$57) -> 5250.51 | Q13: =Zones!L56 -> 5 | R13: =(P13/1000)*Q13 -> 26.25255 | U13: 2 | V13: =(U13*14)/60 -> 0.46666667 | W13: =MAX(R13*15,P13*S13,P13*T13,P13*V13) -> 2450.238
A14: Healthcare Facility and Hospitals (Nurse's Station) | B14: Er_nursestn_lobby_flr_1 | C14: =Zones!K14 -> 66.5065 | D14: =Zones!J14 -> 13301.3 | E14: 15 | F14: =VLOOKUP(A14,O$4:S$17,5) -> 0 | H14: 0.46666667 | I14: =E14*C14 -> 997.5975 | J14: =H14*D14 -> 6207.2733 | L14: =MAX(I14:K14) -> 6207.2733 | O14: =Zones!A57 -> Healthcare Facility and Hospitals (Imaging Room) | P14: =SUMIF(Zones!A$3:A$57, "*Healthcare Facility and Hospitals (Imaging Room)*", Zones!J$3:J$57) -> 5250.51 | Q14: =Zones!L57 -> 5 | R14: =(P14/1000)*Q14 -> 26.25255 | U14: 2 | V14: =(U14*14)/60 -> 0.46666667 | W14: =MAX(R14*15,P14*S14,P14*T14,P14*V14) -> 2450.238
A15: Healthcare Facility and Hospitals (Exam/Treatment Room) | B15: Er_trauma1_flr_1 | C15: =Zones!K15 -> 1.50015 | D15: =Zones!J15 -> 300.03 | E15: 15 | F15: =VLOOKUP(A15,O$4:S$17,5) -> 0 | H15: 0.7 | I15: =E15*C15 -> 22.50225 | J15: =H15*D15 -> 210.021 | L15: =MAX(I15:K15) -> 210.021 | O15: =Zones!A40 -> Healthcare Facility and Hospitals (Patient Room) | P15: =SUMIF(Zones!A$3:A$57, "*Healthcare Facility and Hospitals (Patient Room)*", Zones!J$3:J$57) -> 20402.68 | Q15: 5 | R15: =(P15/1000)*Q15 -> 102.0134 | U15: 2 | V15: =(U15*14)/60 -> 0.46666667 | W15: =MAX(R15*15,P15*S15,P15*T15,P15*V15) -> 9521.2507
A16: Healthcare Facility and Hospitals (Exam/Treatment Room) | B16: Er_trauma2_flr_1 | C16: =Zones!K16 -> 1.50015 | D16: =Zones!J16 -> 300.03 | E16: 15 | F16: =VLOOKUP(A16,O$4:S$17,5) -> 0 | H16: 0.7 | I16: =E16*C16 -> 22.50225 | J16: =H16*D16 -> 210.021 | L16: =MAX(I16:K16) -> 210.021 | O16: =Zones!A26 -> Lobby, Main Entry | P16: =SUMIF(Zones!A$3:A$57, "*Lobby, Main Entry*", Zones!J$3:J$57) -> 15876.28 | Q16: =Zones!L26 -> 33 | R16: =(P16/1000)*Q16 -> 523.91724 | S16: 0.15 | W16: =MAX(R16*15,P16*S16,P16*T16,P16*V16) -> 7858.7586
A17: Healthcare Facility and Hospitals (Exam/Treatment Room) | B17: Er_triage_mult4_flr_1 | C17: =Zones!K17 -> 1.50015 | D17: =Zones!J17 -> 1200.12 | E17: 15 | F17: =VLOOKUP(A17,O$4:S$17,5) -> 0 | G17: =3697/D17 -> 3.0805253 | H17: 0.46666667 | I17: =E17*C17 -> 22.50225 | J17: =H17*D17 -> 560.056 | K17: =G17*D17 -> 3697 | L17: =MAX(I17:K17) -> 3697 | M17: According to CEC model, exhaust required | O17: =Zones!A23 -> Kitchen/Food Preparation Area | P17: =SUMIF(Zones!A$3:A$57, "*Kitchen/Food Preparation Area*", Zones!J$3:J$57) -> 10000.98 | Q17: =Zones!L23 -> 3 | R17: =(P17/1000)*Q17 -> 30.00294 | S17: 0.15 | T17: 0.7 | W17: =MAX(R17*15,P17*S17,P17*T17,P17*V17) -> 7000.686
A18: Healthcare Facility and Hospitals (Recovery Room) | B18: Icu_flr_2 | C18: =Zones!K18 -> 33.2618 | D18: =Zones!J18 -> 6652.36 | E18: 15 | F18: =VLOOKUP(A18,O$4:S$17,5) -> 0 | H18: 0.46666667 | I18: =E18*C18 -> 498.927 | J18: =H18*D18 -> 3104.4347 | L18: =MAX(I18:K18) -> 3104.4347 | O18: Total | P18: =SUM(P5:P17) -> 234173.73 | R18: =SUM(R5:R17) -> 1805.423 | W18: =SUM(W5:W17) -> 93767.35
A19: Healthcare Facility and Hospitals (Nurse's Station) | B19: Icu_nursestn_lobby_flr_2 | C19: =Zones!K19 -> 35.9963 | D19: =Zones!J19 -> 7199.26 | E19: 15 | F19: =VLOOKUP(A19,O$4:S$17,5) -> 0 | H19: 0.46666667 | I19: =E19*C19 -> 539.9445 | J19: =H19*D19 -> 3359.6547 | L19: =MAX(I19:K19) -> 3359.6547
A20: Healthcare Facility and Hospitals (Recovery Room) | B20: Ic_patroom1_mult5_flr_2 | C20: =Zones!K20 -> 1.1251 | D20: =Zones!J20 -> 1125.1 | E20: 15 | F20: =VLOOKUP(A20,O$4:S$17,5) -> 0 | H20: 0.46666667 | I20: =E20*C20 -> 16.8765 | J20: =H20*D20 -> 525.04667 | L20: =MAX(I20:K20) -> 525.04667
A21: Healthcare Facility and Hospitals (Recovery Room) | B21: Ic_patroom2_flr_2 | C21: =Zones!K21 -> 1.50015 | D21: =Zones!J21 -> 300.03 | E21: 15 | F21: =VLOOKUP(A21,O$4:S$17,5) -> 0 | H21: 0.46666667 | I21: =E21*C21 -> 22.50225 | J21: =H21*D21 -> 140.014 | L21: =MAX(I21:K21) -> 140.014
A22: Healthcare Facility and Hospitals (Recovery Room) | B22: Ic_patroom3_mult6_flr_2 | C22: =Zones!K22 -> 1.1251 | D22: =Zones!J22 -> 1350.12 | E22: 15 | F22: =VLOOKUP(A22,O$4:S$17,5) -> 0 | H22: 0.46666667 | I22: =E22*C22 -> 16.8765 | J22: =H22*D22 -> 630.056 | L22: =MAX(I22:K22) -> 630.056
A23: Kitchen/Food Preparation Area | B23: Kitchen_flr_5 | C23: =Zones!K23 -> 30.00294 | D23: =Zones!J23 -> 10000.98 | E23: 15 | F23: 0.15 | G23: 0.7 | I23: =E23*C23 -> 450.0441 | J23: =F23*D23 -> 1500.147 | K23: =G23*D23 -> 7000.686 | L23: =MAX(I23:K23) -> 7000.686 | M23: Exhaust required according to Code
A24: Laboratory-General Health | B24: Lab_flr_3 | C24: =Zones!K24 -> 14.2514 | D24: =Zones!J24 -> 2850.28 | E24: 15 | F24: =VLOOKUP(A24,O$4:S$17,5) -> 0 | G24: 1 | H24: 0.46666667 | I24: =E24*C24 -> 213.771 | J24: =H24*D24 -> 1330.1307 | K24: =G24*D24 -> 2850.28 | L24: =MAX(I24:K24)+E67 -> 4350.28 | M24: Exhaust required according to Code Per ASHRAE 62.1: Table 6.5-General Lab Exhaust
A25: Laboratory-General Health | B25: Lab_flr_4 | C25: =Zones!K25 -> 14.2514 | D25: =Zones!J25 -> 2850.28 | E25: 15 | F25: =VLOOKUP(A25,O$4:S$17,5) -> 0 | G25: 1 | H25: 0.46666667 | I25: =E25*C25 -> 213.771 | J25: =H25*D25 -> 1330.1307 | K25: =G25*D25 -> 2850.28 | L25: =MAX(I25:K25)+E68 -> 4350.28 | M25: Exhaust required according to Code Per ASHRAE 62.1: Table 6.5-General Lab Exhaust
A26: Lobby, Main Entry | B26: Lobby_records_flr_1 | C26: =Zones!K26 -> 523.91724 | D26: =Zones!J26 -> 15876.28 | E26: 15 | F26: =VLOOKUP(A26,O$4:S$17,5) -> 0.15 | H26: =VLOOKUP(A26,O$4:V$17,8) -> 0 | I26: =E26*C26 -> 7858.7586 | J26: =F26*D26 -> 2381.442 | K26: =G26*D26 -> 0 | L26: =MAX(I26:K26) -> 7858.7586
A27: Healthcare Facility and Hospitals (Nurse's Station) | B27: Nursestn_lobby_flr_3 | C27: =Zones!K27 -> 48.75475 | D27: =Zones!J27 -> 9750.95 | E27: 15 | F27: =VLOOKUP(A27,O$4:S$17,5) -> 0 | G27: =4551/D27 -> 0.46672376 | H27: 0.46666667 | I27: =E27*C27 -> 731.32125 | J27: =H27*D27 -> 4550.4433 | K27: =G27*D27 -> 4551 | L27: =MAX(I27:K27) -> 4551 | M27: According to CEC Model
A28: Healthcare Facility and Hospitals (Nurse's Station) | B28: Nursestn_lobby_flr_4 | C28: =Zones!K28 -> 48.75475 | D28: =Zones!J28 -> 9750.95 | E28: 15 | F28: =VLOOKUP(A28,O$4:S$17,5) -> 0 | G28: =4551/D28 -> 0.46672376 | H28: 0.46666667 | I28: =E28*C28 -> 731.32125 | J28: =H28*D28 -> 4550.4433 | K28: =G28*D28 -> 4551 | L28: =MAX(I28:K28) -> 4551 | M28: According to CEC Model
A29: Healthcare Facility and Hospitals (Nurse's Station) | B29: Nursestn_lobby_flr_5 | C29: =Zones!K29 -> 56.00545 | D29: =Zones!J29 -> 11201.09 | E29: 15 | F29: =VLOOKUP(A29,O$4:S$17,5) -> 0 | H29: 0.46666667 | I29: =E29*C29 -> 840.08175 | J29: =H29*D29 -> 5227.1753 | K29: =G29*D29 -> 0 | L29: =MAX(I29:K29) -> 5227.1753
A30: Office Area (>250 square feet) | B30: Office1_flr_5 | C30: =Zones!K30 -> 3.75135 | D30: =Zones!J30 -> 750.27 | E30: 15 | F30: =VLOOKUP(A30,O$4:S$17,5) -> 0.15 | H30: =VLOOKUP(A30,O$4:V$17,8) -> 0 | I30: =E30*C30 -> 56.27025 | J30: =F30*D30 -> 112.5405 | K30: =G30*D30 -> 0 | L30: =MAX(I30:K30) -> 112.5405
A31: Office Area (>250 square feet) | B31: Office1_mult5_flr_1 | C31: =Zones!K31 -> 0.75005 | D31: =Zones!J31 -> 750.05 | E31: 15 | F31: =VLOOKUP(A31,O$4:S$17,5) -> 0.15 | H31: =VLOOKUP(A31,O$4:V$17,8) -> 0 | I31: =E31*C31 -> 11.25075 | J31: =F31*D31 -> 112.5075 | K31: =G31*D31 -> 0 | L31: =MAX(I31:K31) -> 112.5075
A32: Office Area (>250 square feet) | B32: Office2_mult5_flr_5 | C32: =Zones!K32 -> 3.75035 | D32: =Zones!J32 -> 3750.35 | E32: 15 | F32: =VLOOKUP(A32,O$4:S$17,5) -> 0.15 | H32: =VLOOKUP(A32,O$4:V$17,8) -> 0 | I32: =E32*C32 -> 56.25525 | J32: =F32*D32 -> 562.5525 | K32: =G32*D32 -> 0 | L32: =MAX(I32:K32) -> 562.5525
A33: Office Area (>250 square feet) | B33: Office3_flr_5 | C33: =Zones!K33 -> 3.75035 | D33: =Zones!J33 -> 750.07 | E33: 15 | F33: =VLOOKUP(A33,O$4:S$17,5) -> 0.15 | H33: =VLOOKUP(A33,O$4:V$17,8) -> 0 | I33: =E33*C33 -> 56.25525 | J33: =F33*D33 -> 112.5105 | K33: =G33*D33 -> 0 | L33: =MAX(I33:K33) -> 112.5105
A34: Office Area (>250 square feet) | B34: Office4_mult6_flr_5 | C34: =Zones!K34 -> 0.75005 | D34: =Zones!J34 -> 900.06 | E34: 15 | F34: =VLOOKUP(A34,O$4:S$17,5) -> 0.15 | H34: =VLOOKUP(A34,O$4:V$17,8) -> 0 | I34: =E34*C34 -> 11.25075 | J34: =F34*D34 -> 135.009 | K34: =G34*D34 -> 0 | L34: =MAX(I34:K34) -> 135.009
A35: Healthcare Facility and Hospitals (Operating Room) | B35: Or1_flr_2 | C35: =Zones!K35 -> 3.0003 | D35: =Zones!J35 -> 600.06 | E35: 15 | F35: =VLOOKUP(A35,O$4:S$17,5) -> 0 | H35: 0.9333333 | I35: =E35*C35 -> 45.0045 | J35: =H35*D35 -> 560.05598 | K35: =G35*D35 -> 0 | L35: =MAX(I35:K35) -> 560.05598
A36: Healthcare Facility and Hospitals (Operating Room) | B36: Or2_mult5_flr_2 | C36: =Zones!K36 -> 3.0003 | D36: =Zones!J36 -> 3000.3 | E36: 15 | F36: =VLOOKUP(A36,O$4:S$17,5) -> 0 | H36: 0.9333333 | I36: =E36*C36 -> 45.0045 | J36: =H36*D36 -> 2800.2799 | K36: =G36*D36 -> 0 | L36: =MAX(I36:K36) -> 2800.2799
A37: Healthcare Facility and Hospitals (Operating Room) | B37: Or3_flr_2 | C37: =Zones!K37 -> 3.0003 | D37: =Zones!J37 -> 600.06 | E37: 15 | F37: =VLOOKUP(A37,O$4:S$17,5) -> 0 | H37: 0.9333333 | I37: =E37*C37 -> 45.0045 | J37: =H37*D37 -> 560.05598 | K37: =G37*D37 -> 0 | L37: =MAX(I37:K37) -> 560.05598
A38: Healthcare Facility and Hospitals (Operating Room) | B38: Or4_flr_2 | C38: =Zones!K38 -> 12.00115 | D38: =Zones!J38 -> 2400.23 | E38: 15 | F38: =VLOOKUP(A38,O$4:S$17,5) -> 0 | H38: 0.9333333 | I38: =E38*C38 -> 180.01725 | J38: =H38*D38 -> 2240.2146 | K38: =G38*D38 -> 0 | L38: =MAX(I38:K38) -> 2240.2146
A39: Healthcare Facility and Hospitals (Nurse's Station) | B39: Or_nursestn_lobby_flr_2 | C39: =Zones!K39 -> 54.5053 | D39: =Zones!J39 -> 10901.06 | E39: 15 | F39: =VLOOKUP(A39,O$4:S$17,5) -> 0 | H39: 0.46666667 | I39: =E39*C39 -> 817.5795 | J39: =H39*D39 -> 5087.1613 | K39: =G39*D39 -> 0 | L39: =MAX(I39:K39) -> 5087.1613
A40: Healthcare Facility and Hospitals (Patient Room) | B40: Patroom1_mult10_flr_3 | C40: =Zones!K40 -> 1.1251 | D40: =Zones!J40 -> 2250.2 | E40: 15 | F40: =VLOOKUP(A40,O$4:S$17,5) -> 0 | H40: 0.46666667 | I40: =E40*C40 -> 16.8765 | J40: =H40*D40 -> 1050.0933 | K40: =G40*D40 -> 0 | L40: =MAX(I40:K40) -> 1050.0933
...

Sheet Thermostat
A1: ="Thermostat Setpoints - "&Prototype!A2 -> Thermostat Setpoints - Hospital
A2: Setpoint | B2: CZ1 | C2: CZ2 | D2: CZ3 | E2: CZ4 | F2: CZ5 | G2: CZ6 | H2: CZ7 | I2: CZ8 | J2: CZ9 | K2: CZ10 | L2: CZ11 | M2: CZ12 | N2: CZ13 | O2: CZ14 | P2: CZ15 | Q2: CZ16 | R2: Source | S2: Note
A3: Health Heating Setpoint (F) | B3: 70 | C3: 70 | D3: 70 | E3: 70 | F3: 70 | G3: 70 | H3: 70 | I3: 70 | J3: 70 | K3: 70 | L3: 70 | M3: 70 | N3: 70 | O3: 70 | P3: 70 | Q3: 70 | R3: T24 2022 - Appendix 5.4B | S3: CEC and PNNL Healthcare-Hospital prototypes use the same setpoints without setbacks; however, the DEER model applies a 10° F setback from midnight to 5:00 AM.
A4: Health Heating Setback (F) | B4: 70 | C4: 70 | D4: 70 | E4: 70 | F4: 70 | G4: 70 | H4: 70 | I4: 70 | J4: 70 | K4: 70 | L4: 70 | M4: 70 | N4: 70 | O4: 70 | P4: 70 | Q4: 70
A5: Health Cooling Setpoint (F) | B5: 75 | C5: 75 | D5: 75 | E5: 75 | F5: 75 | G5: 75 | H5: 75 | I5: 75 | J5: 75 | K5: 75 | L5: 75 | M5: 75 | N5: 75 | O5: 75 | P5: 75 | Q5: 75
A6: Health Cooling Setback (F) | B6: 75 | C6: 75 | D6: 75 | E6: 75 | F6: 75 | G6: 75 | H6: 75 | I6: 75 | J6: 75 | K6: 75 | L6: 75 | M6: 75 | N6: 75 | O6: 75 | P6: 75 | Q6: 75
A7: Kitchen Heating Setpoint (F) | B7: 66 | C7: 66 | D7: 66 | E7: 66 | F7: 66 | G7: 66 | H7: 66 | I7: 66 | J7: 66 | K7: 66 | L7: 66 | M7: 66 | N7: 66 | O7: 66 | P7: 66 | Q7: 66 | R7: PNNL 09.1, 2022 Restaurant prototype
A8: Kitchen Heating Setback (F) | B8: 60 | C8: 60 | D8: 60 | E8: 60 | F8: 60 | G8: 60 | H8: 60 | I8: 60 | J8: 60 | K8: 60 | L8: 60 | M8: 60 | N8: 60 | O8: 60 | P8: 60 | Q8: 60
A9: Kitchen Cooling Setpoint (F) | B9: 79 | C9: 79 | D9: 79 | E9: 79 | F9: 79 | G9: 79 | H9: 79 | I9: 79 | J9: 79 | K9: 79 | L9: 79 | M9: 79 | N9: 79 | O9: 79 | P9: 79 | Q9: 79
A10: Kitchen Cooling Setback (F) | B10: 86 | C10: 86 | D10: 86 | E10: 86 | F10: 86 | G10: 86 | H10: 86 | I10: 86 | J10: 86 | K10: 86 | L10: 86 | M10: 86 | N10: 86 | O10: 86 | P10: 86 | Q10: 86
A11: UnOccupied Heating Setpoint (F) | B11: =B3-4 -> 66 | C11: =C3-4 -> 66 | D11: =D3-4 -> 66 | E11: =E3-4 -> 66 | F11: =F3-4 -> 66 | G11: =G3-4 -> 66 | H11: =H3-4 -> 66 | I11: =I3-4 -> 66 | ... Q11: =Q3-4 -> 66 | R11: T24 2022 - Appendix 5.4B
A12: UnOccupied Heating Setback (F) | B12: =B4-4 -> 66 | C12: =C4-4 -> 66 | D12: =D4-4 -> 66 | E12: =E4-4 -> 66 | F12: =F4-4 -> 66 | G12: =G4-4 -> 66 | H12: =H4-4 -> 66 | I12: =I4-4 -> 66 | ... Q12: =Q4-4 -> 66
A13: UnOccupied Cooling Setpoint (F) | B13: =B5+4 -> 79 | C13: =C5+4 -> 79 | D13: =D5+4 -> 79 | E13: =E5+4 -> 79 | F13: =F5+4 -> 79 | G13: =G5+4 -> 79 | H13: =H5+4 -> 79 | I13: =I5+4 -> 79 | ... Q13: =Q5+4 -> 79
A14: UnOccupied Cooling Setback (F) | B14: =B6+4 -> 79 | C14: =C6+4 -> 79 | D14: =D6+4 -> 79 | E14: =E6+4 -> 79 | F14: =F6+4 -> 79 | G14: =G6+4 -> 79 | H14: =H6+4 -> 79 | I14: =I6+4 -> 79 | ... Q14: =Q6+4 -> 79
A20: Background Data [To be deleted prior to publication]
B21: Heating | E21: Cooling
B22: Weekday | C22: Saturday | D22: Sunday | E22: Weekday | F22: Ssturday | G22: Sunday
A23: DEER | B23: 0:00 to 5:00 | C23: 0:00 to 5:00 | D23: 0:00 to 24:00 | E23: 0:00 to 5:00 | F23: 0:00 to 5:00 | G23: 0:00 to 24:00
B24: 15.56 | C24: 15.56 | D24: 15.56 | E24: 29.22 | F24: 29.22 | G24: 29.22
B25: 5:00 to 24:00 | C25: 5:00 to 19:00 | E25: 5:00 to 24:00 | F25: 5:00 to 19:00
B26: 21.11 | C26: 21.11 | E26: 23.88 | F26: 23.88
A29: T24, Appendix JA5-4 : Occupant Controlled Smart Thermostat (OCST)
A46: Kitchen Heating Setpoint (F) | B46: 66 | C46: 66 | D46: 66 | E46: 66 | F46: 66 | G46: 66 | H46: 66 | I46: 66 | J46: 66 | K46: 66 | L46: 66 | M46: 66 | N46: 66 | O46: 66 | P46: 66 | Q46: 66 | R46: PNNL 09.1, 2022 Restaurant prototype
A47: Kitchen Heating Setback (F) | B47: 60 | C47: 60 | D47: 60 | E47: 60 | F47: 60 | G47: 60 | H47: 60 | I47: 60 | J47: 60 | K47: 60 | L47: 60 | M47: 60 | N47: 60 | O47: 60 | P47: 60 | Q47: 60
A48: Kitchen Cooling Setpoint (F) | B48: 79 | C48: 79 | D48: 79 | E48: 79 | F48: 79 | G48: 79 | H48: 79 | I48: 79 | J48: 79 | K48: 79 | L48: 79 | M48: 79 | N48: 79 | O48: 79 | P48: 79 | Q48: 79
A49: Kitchen Cooling Setback (F) | B49: 86 | C49: 86 | D49: 86 | E49: 86 | F49: 86 | G49: 86 | H49: 86 | I49: 86 | J49: 86 | K49: 86 | L49: 86 | M49: 86 | N49: 86 | O49: 86 | P49: 86 | Q49: 86

Sheet Water Heater
A1: ="Water Heater - "&Prototype!A2 -> Water Heater - Hospital
A2: Vintage | B2: WH Type | C2: Efficiency | D2: Tank Volume (gal) | E2: Tank Loss | G2: Note
A3: Existing | B3: Gas | C3: 0.8 | D3: =F72 -> 143.77303 | E3: =G74 -> 1542.3745 | F3: (Btu/hr)
A4: New Construction | B4: Gas | C4: 0.8 | D4: =F70 -> 143.77303 | E4: =G70 -> 1542.3745 | F4: (Btu/hr)
A7: Peak Hot Water Consumption
A8: Space Name | B8: Baseline WH Type [CEUS 2022] | C8: Total Area (ft²) | D8: Number of People | E8: Hot Water Usage Specification (gal/hr per person) [T24, 2022, Appendix 5.4A , sheet: "2022 SpaceFuncData-Input"] | F8: Peak Hot Water Usage (gal/hr) | G8: Peak Hot Water Usage (gal/min)
A9: Basement | B9: Gas | C9: =Zones!G3 -> 40253.93 | D9: =Zones!K3 -> 201.26965 | E9: =VLOOKUP(Zones!A3,'Water Heater'!$A$128:$E$141,5,FALSE) -> 0.18 | F9: =E9*D9 -> 36.228537 | G9: =F9/60 -> 0.60380895
A10: Corridor_flr_1 | B10: Gas | C10: =Zones!G4 -> 6125.6 | D10: =Zones!K4 -> 30.628 | E10: =VLOOKUP(Zones!A4,'Water Heater'!$A$128:$E$141,5,FALSE) -> 0 | F10: =E10*D10 -> 0 | G10: =F10/60 -> 0
A11: Corridor_flr_2 | B11: Gas | C11: =Zones!G5 -> 6125.6 | D11: =Zones!K5 -> 30.628 | E11: =VLOOKUP(Zones!A5,'Water Heater'!$A$128:$E$141,5,FALSE) -> 0 | F11: =E11*D11 -> 0 | G11: =F11/60 -> 0
A12: Corridor_flr_5 | B12: Gas | C12: =Zones!G6 -> 5400.53 | D12: =Zones!K6 -> 27.00265 | E12: =VLOOKUP(Zones!A6,'Water Heater'!$A$128:$E$141,5,FALSE) -> 0 | F12: =E12*D12 -> 0 | G12: =F12/60 -> 0
A13: Corridor_nw_flr_3 | B13: Gas | C13: =Zones!G7 -> 6100.6 | D13: =Zones!K7 -> 30.503 | E13: =VLOOKUP(Zones!A7,'Water Heater'!$A$128:$E$141,5,FALSE) -> 0 | F13: =E13*D13 -> 0 | G13: =F13/60 -> 0
A14: Corridor_nw_flr_4 | B14: Gas | C14: =Zones!G8 -> 6100.6 | D14: =Zones!K8 -> 30.503 | E14: =VLOOKUP(Zones!A8,'Water Heater'!$A$128:$E$141,5,FALSE) -> 0 | F14: =E14*D14 -> 0 | G14: =F14/60 -> 0
A15: Corridor_se_flr_3 | B15: Gas | C15: =Zones!G9 -> 6100.6 | D15: =Zones!K9 -> 30.503 | E15: =VLOOKUP(Zones!A9,'Water Heater'!$A$128:$E$141,5,FALSE) -> 0 | F15: =E15*D15 -> 0 | G15: =F15/60 -> 0
A16: Corridor_se_flr_4 | B16: Gas | C16: =Zones!G10 -> 6100.6 | D16: =Zones!K10 -> 30.503 | E16: =VLOOKUP(Zones!A10,'Water Heater'!$A$128:$E$141,5,FALSE) -> 0 | F16: =E16*D16 -> 0 | G16: =F16/60 -> 0
A17: Dining_flr_5 | B17: Gas | C17: =Zones!G11 -> 7500.73 | D17: =Zones!K11 -> 247.52409 | E17: =VLOOKUP(Zones!A11,'Water Heater'!$A$128:$E$141,5,FALSE) -> 0.578 | F17: =E17*D17 -> 143.06892 | G17: =F17/60 -> 2.3844821
A18: Er_exam1_mult4_flr_1 | B18: Gas | C18: =Zones!G12 -> 300.03 | D18: =Zones!K12 -> 1.50015 | E18: =VLOOKUP(Zones!A12,'Water Heater'!$A$128:$E$141,5,FALSE) -> 0.24 | F18: =E18*D18 -> 0.360036 | G18: =F18/60 -> 0.0060006
A19: Er_exam3_mult4_flr_1 | B19: Gas | C19: =Zones!G13 -> 300.03 | D19: =Zones!K13 -> 1.50015 | E19: =VLOOKUP(Zones!A13,'Water Heater'!$A$128:$E$141,5,FALSE) -> 0.24 | F19: =E19*D19 -> 0.360036 | G19: =F19/60 -> 0.0060006
A20: Er_nursestn_lobby_flr_1 | B20: Gas | C20: =Zones!G14 -> 13301.3 | D20: =Zones!K14 -> 66.5065 | E20: =VLOOKUP(Zones!A14,'Water Heater'!$A$128:$E$141,5,FALSE) -> 0.24 | F20: =E20*D20 -> 15.96156 | G20: =F20/60 -> 0.266026
... A36: Office1_flr_5 | B36: Gas | C36: =Zones!G30 -> 750.27 | D36: =Zones!K30 -> 3.75135 | E36: =VLOOKUP(Zones!A30,'Water Heater'!$A$128:$E$141,5,FALSE) -> 0.18 | F36: =E36*D36 -> 0.675243 | G36: =F36/60 -> 0.01125405
A37: Office1_mult5_flr_1 | B37: Gas | C37: =Zones!G31 -> 150.01 | D37: =Zones!K31 -> 0.75005 | E37: 0.18 | F37: =E37*D37 -> 0.135009 | G37: =F37/60 -> 0.00225015
A38: Office2_mult5_flr_5 | B38: Gas | C38: =Zones!G32 -> 750.07 | D38: =Zones!K32 -> 3.75035 | E38: =VLOOKUP(Zones!A32,'Water Heater'!$A$128:$E$141,5,FALSE) -> 0.18 | F38: =E38*D38 -> 0.675063 | G38: =F38/60 -> 0.01125105
A39: Office3_flr_5 | B39: Gas | C39: =Zones!G33 -> 750.07 | D39: =Zones!K33 -> 3.75035 | E39: =VLOOKUP(Zones!A33,'Water Heater'!$A$128:$E$141,5,FALSE) -> 0.18 | F39: =E39*D39 -> 0.675063 | G39: =F39/60 -> 0.01125105
A40: Office4_mult6_flr_5 | B40: Gas | C40: =Zones!G34 -> 150.01 | D40: =Zones!K34 -> 0.75005 | E40: 0.18 | F40: =E40*D40 -> 0.135009 | G40: =F40/60 -> 0.00225015
A41: Or1_flr_2 | B41: Gas | C41: =Zones!G35 -> 600.06 | D41: =Zones!K35 -> 3.0003 | E41: =VLOOKUP(Zones!A35,'Water Heater'!$A$128:$E$141,5,FALSE) -> 0.24 | F41: =E41*D41 -> 0.720072 | G41: =F41/60 -> 0.0120012
A42: Or2_mult5_flr_2 | B42: Gas | C42: =Zones!G36 -> 600.06 | D42: =Zones!K36 -> 3.0003 | E42: =VLOOKUP(Zones!A36,'Water Heater'!$A$128:$E$141,5,FALSE) -> 0.24 | F42: =E42*D42 -> 0.720072 | G42: =F42/60 -> 0.0120012
A43: Or3_flr_2 | B43: Gas | C43: =Zones!G37 -> 600.06 | D43: =Zones!K37 -> 3.0003 | E43: =VLOOKUP(Zones!A37,'Water Heater'!$A$128:$E$141,5,FALSE) -> 0.24 | F43: =E43*D43 -> 0.720072 | G43: =F43/60 -> 0.0120012
A44: Or4_flr_2 | B44: Gas | C44: =Zones!G38 -> 2400.23 | D44: =Zones!K38 -> 12.00115 | E44: =VLOOKUP(Zones!A38,'Water Heater'!$A$128:$E$141,5,FALSE) -> 0.24 | F44: =E44*D44 -> 2.880276 | G44: =F44/60 -> 0.0480046
A45: Or_nursestn_lobby_flr_2 | B45: Gas | C45: =Zones!G39 -> 10901.06 | D45: =Zones!K39 -> 54.5053 | E45: =VLOOKUP(Zones!A39,'Water Heater'!$A$128:$E$141,5,FALSE) -> 0.24 | F45: =E45*D45 -> 13.081272 | G45: =F45/60 -> 0.2180212
A46: Patroom1_mult10_flr_3 | B46: Gas | C46: =Zones!G40 -> 225.02 | D46: =Zones!K40 -> 1.1251 | E46: =VLOOKUP(Zones!A40,'Water Heater'!$A$128:$E$141,5,FALSE) -> 0.24 | F46: =E46*D46 -> 0.270024 | G46: =F46/60 -> 0.0045004
A47: Patroom1_mult10_flr_4 | B47: Gas | C47: =Zones!G41 -> 225.02 | D47: =Zones!K41 -> 1.1251 | E47: =VLOOKUP(Zones!A41,'Water Heater'!$A$128:$E$141,5,FALSE) -> 0.24 | F47: =E47*D47 -> 0.270024 | G47: =F47/60 -> 0.0045004
A48: Patroom2_flr_3 | B48: Gas | C48: =Zones!G42 -> 375.04 | D48: =Zones!K42 -> 1.8752 | E48: =VLOOKUP(Zones!A42,'Water Heater'!$A$128:$E$141,5,FALSE) -> 0.24 | F48: =E48*D48 -> 0.450048 | G48: =F48/60 -> 0.0075008
A49: Patroom2_flr_4 | B49: Gas | C49: =Zones!G43 -> 375.04 | D49: =Zones!K43 -> 1.8752 | E49: =VLOOKUP(Zones!A43,'Water Heater'!$A$128:$E$141,5,FALSE) -> 0.24 | F49: =E49*D49 -> 0.450048 | G49: =F49/60 -> 0.0075008
A50: Patroom3_mult10_flr_3 | B50: Gas | C50: =Zones!G44 -> 217.54 | D50: =Zones!K44 -> 1.0877 | E50: =VLOOKUP(Zones!A44,'Water Heater'!$A$128:$E$141,5,FALSE) -> 0.24 | F50: =E50*D50 -> 0.261048 | G50: =F50/60 -> 0.0043508
A51: Patroom3_mult10_flr_4 | B51: Gas | C51: =Zones!G45 -> 217.54 | D51: =Zones!K45 -> 1.0877 | E51: =VLOOKUP(Zones!A45,'Water Heater'!$A$128:$E$141,5,FALSE) -> 0.24 | F51: =E51*D51 -> 0.261048 | G51: =F51/60 -> 0.0043508
A52: Patroom4_flr_3 | B52: Gas | C52: =Zones!G46 -> 375.04 | D52: =Zones!K46 -> 1.8752 | E52: =VLOOKUP(Zones!A46,'Water Heater'!$A$128:$E$141,5,FALSE) -> 0.24 | F52: =E52*D52 -> 0.450048 | G52: =F52/60 -> 0.0075008
... A63: Radiology_flr_4 | B63: Gas | C63: =Zones!G57 -> 5250.51 | D63: =Zones!K57 -> 26.25255 | E63: =VLOOKUP(Zones!A57,'Water Heater'!$A$128:$E$141,5,FALSE) -> 0.24 | F63: =E63*D63 -> 6.300612 | G63: =F63/60 -> 0.1050102
A64: Total | C64: =SUM(C9:C63) -> 214116.18 | D64: =SUM(D9:D63) -> 1705.1352 | F64: =SUM(F9:F63) -> 359.43257 | G64: =SUM(G9:G63) -> 5.9905428
A68: Water Heater Capacity, Tank Capacity, and Tank Loss
A69: WH Type | B69: Peak Hot Water Usage (gal/hr) | C69: Heat Output (Btu/hr) [ACM, 2025, 5.9.2: Rated capacity section] | D69: WH Capacity (Btu/hr) [ACM, 2025, 5.9.2: Rated capacity section] | E69: Required Energy Input (Btu/hr) | F69: Storage Volume (gal) | G69: Standby Loss | I69: Off/On Cycle Loss Coefficient to Ambient Temp (Btu/h-F) | J69: Source
A70: Gas Storage WH | B70: =SUMIF($B$9:$B$63, "*Gas*",$F$9:$F$63) -> 359.43257 | C70: =B70*(135-55)*8.2877*1 -> 238309.55 | D70: =C70*0.6 -> 142985.73 | E70: =D70/0.8 -> 178732.16 | F70: =(B70*F72)/B72 -> 143.77303 | G70: =(E70/800)+110*SQRT(F70) -> 1542.3745 | H70: Btu/hr | I70: =G70/B82 -> 23.020515 | J70: Standby loss equation: Title 20, §1605.1 Table F-4 WH capacity equation: ACM, 2025, 5.9.2: Rated capacity section)
...

Sheet Ext Lighting
A1: ="Exterior Lighting - "&Prototype!A2 -> Exterior Lighting - Hospital
A2: Motion Controlled Luminaires (W) | B2: Non-motion Controlled Luminaires (W) | C2: Total (W) | D2: Source
A3: =G14 -> 8349.061 | B3: =G15 -> 1383.959 | C3: =A3+B3 -> 9733.02 | D3: T24, 2022 & 2025 2019 Outdoor Lighting CASE report PNNL 90.1-2010 TSD
A6: ="Exterior Lighting " -> Exterior Lighting
A7: Items (Assume LZ2) | B7: Assumptions [2019 Outdoor Lighting CASE Report & PNNL 90.1-2010 TSD] | D7: Unit | E7: Lighting Power Allowance [T24, 2025, Table 140.7-A & 140.7-B] | F7: Unit | G7: Exterior Lighting Power (W)
A8: IWA (Initial Wattage Allowance) | E8: 200 | F8: (W) | G8: =$E8 -> 200
A9: Parking area | B9: 400 ft² for every parking space 1 parking space per 830 ft² of gross building area | C9: 386198 | D9: (ft²) | E9: 0.019 | F9: (W/ft²) | G9: =$E9*C9 -> 7337.762
A10: Building Entrance | B10: 14 building entrance per PNNL Model | C10: 10 | D10: (count) | E10: 15 | F10: (W/ea) | G10: =E10*C10 -> 150
A11: Hardscape Ornamental Light | B11: 0.1 ft² per 1 ft² of gross building area for hardscape ornamental light | C11: 24137 | D11: (ft²) | E11: 0.007 | F11: (W/ft²) | G11: =E11*C11 -> 168.959
A12: Building façade | B12: 0.1 W per 1 ft² of facade area Façade Area = Perimeter × 0.5 × 28 ft (30 ft is the max height that is lit) * The 0.5 factor assumes that only half of the perimeter walls are lit. -Formula ia developed based on the 2019 Outdoor Lighting CASE report | C12: =B21*0.5*30 -> 12150 | D12: (ft²) | E12: 0.1 | F12: (W/ft²) | G12: =E12*C12 -> 1215
A13: Non-sales canopy | C13: 4827 | D13: (ft²) | E13: 0.137 | F13: (W/ft²) | G13: =E13*C13 -> 661.299
A14: Motion Controlled Luminaires (W) | G14: =G9+G8+G13+G10 -> 8349.061
A15: Non-motion-controlled Luminaires | G15: =G11+G12 -> 1383.959
A16: Total | G16: =G14+G15 -> 9733.02
A20: Total floor area (ft²) | B20: =Prototype!B8 -> 241500 (230 ft x 175 ft for each floor)
A21: Perimeter | B21: 810
A22: Floors | B22: 3
A29: Background Data [To be deleted prior to publication]

Sheet Interior Lights
A1: ="Interior Lighting - "&Prototype!B4 -> Interior Lighting - Hospital
A2: Space Type | B2: New Construction | E2: Existing
B3: LPD (W/ft²) | C3: Additional LPD for PorTable Lighting (W/ft²) | D3: Source | E3: LPD (W/ft²) | F3: Additional LPD for PorTable Lighting (W/ft²) | G3: Source
A4: =Ventilation!O5 -> Office Area (>250 square feet) | B4: 0.6 | D4: T24, 2025, Table 140.6-C (Area category method) | E4: 0.65 | G4: T24, 2019, Table 140.6-C (Area category method)
A5: =Ventilation!O6 -> Corridor Area | B5: 0.4 | E5: 0.6
A6: =Ventilation!O7 -> Dining Area (Cafeteria/Fast Food) | B6: 0.45 | E6: 0.4
A7: =Ventilation!O8 -> Healthcare Facility and Hospitals (Exam/Treatment Room) | B7: 1.15 | E7: 1.15
A8: =Ventilation!O9 -> Healthcare Facility and Hospitals (Nurse's Station) | B8: 0.85 | E8: 0.75
A9: =Ventilation!O10 -> Healthcare Facility and Hospitals (Recovery Room) | B9: 0.9 | E9: 0.9
A10: =Ventilation!O11 -> Laboratory, Scientific | B10: 0.9 | E10: 1
A11: =Ventilation!O12 -> Healthcare Facility and Hospitals (Operating Room) | B11: 1.9 | E11: 1.9
A12: =Ventilation!O13 -> Healthcare Facility and Hospitals (Physical Therapy Room) | B12: 0.75 | E12: 0.85
A13: =Ventilation!O14 -> Healthcare Facility and Hospitals (Imaging Room) | B13: 0.6 | E13: 1
A14: =Ventilation!O15 -> Healthcare Facility and Hospitals (Patient Room) | B14: 0.7 | E14: 0.55
A15: =Ventilation!O16 -> Lobby, Main Entry | B15: 0.7 | E15: 0.85
A16: =Ventilation!O17 -> Kitchen/Food Preparation Area | B16: 0.95 | E16: 0.95
A17: =Zones!A31 -> Office Area (<250 square feet) | B17: 0.65 | E17: 0.7

Sheet Equipment
A1: ="Equipment - "&Prototype!A2 -> Equipment - Hospital
A2: Spaces | B2: Plug load Power Density (W/ft²) | C2: Gas Power Density (Btu/hr-ft²) | D2: Refrigeration Power Density (W/ft²) | E2: Source | F2: Note
A3: =Ventilation!O5 -> Office Area (>250 square feet) | B3: 0.7 | E3: T24 2022 - Appendix 5.4A | F3: Plug load and schedules project with CEC, 2025
A4: =Ventilation!O6 -> Corridor Area | B4: 0
A5: =Ventilation!O7 -> Dining Area (Cafeteria/Fast Food) | B5: 0.5 | D5: 0.25 | F5: CEC: Refrig Load = 0.25 w/ft²
A6: =Ventilation!O8 -> Healthcare Facility and Hospitals (Exam/Treatment Room) | B6: 1.5 | C6: 1.1259 | F6: Appendix 5.4A: Gas equipment=1.1259 Btu/h-ft²--CEC model (Hospital) has the Gas equipment for 3.59 Btu/h-ft²
