Workbook
Name nonparticipating_forecastzone_scale_factor: '[1]Energy Usage'!#REF!
Name nonparticipating_forecastzone_scale_factor: 'Energy Usage'!#REF!
Name Space_Function: Data!$A$2:$A$76

Sheet Notes
A1: Data Sources
A2: Dataset | B2: Dodge 2023
B3: CEUS 2022
B4: ComStock 2023
A6: Prototype | B6: CEC Laboratory prototype (CBECC 2022.3.1) | C6: https://bees.noresco.com/software2022.html
B7: DEER Manufacturing-BioTech prototype (June 2024) | C7: https://github.com/sound-data/DEER-Prototypes-EnergyPlus
A9: Codes | B9: Title 24, part 6, referred to as T24 (1984, 2001, 2007, 2013, 2016, 2022, 2025)
B10: ASHRAE 90.1 (2022)
B11: CFR Title 10 (2008, 2010, 2025)
B12: ACM 2022
B13: T24 2022 - Appendix 5.4A and Appendix 5.4B | C13: https://www.energy.ca.gov/publications/2022/2022-nonresidential-and-multifamily-alternative-calculation-method-reference
A15: Other | B15: 2022 Reduced infiltration CASE report | C15: https://title24stakeholders.com/wp-content/uploads/2020/10/2022-T24-Final-CASE-Report_Reduce-Infiltration.pdf
B16: 2019 Outdoor Lighting CASE Report | C16: https://title24stakeholders.com/wp-content/uploads/2016/10/T24-2019-CASE-Study-Results-Report-Outdoor-Sources_Final_with-Attachments.pdf
B17: 2019 High Efficiency Fume Hoods in Laboratory Spaces CASE Report | C17: https://title24stakeholders.com/wp-content/uploads/2017/09/2019-T24-CASE-Report_Fume-Hoods_Final_September-2017.pdf?
B18: PNNL 20405, 2010 | C18: file:///N:/Prj_SUS/2023/S23668%20SCE%20CA%20Prototypes%20Development/Technical/NR/0_Input%20data/Lighting/PNNL-20405.pdf
B19: Air leakage Memo, NORESCO, 2025 | C19: Infiltration_rate_report_14May2025-Short-Version.docx
B20: Proposed Updates to Equipment Power Densities and Building Schedules for the 2028 Energy Code, referred to as "Plug load and schedules project with CEC, 2025" (Docket Number =25-BSTD-03 & TN=265693) | C20: https://efiling.energy.ca.gov/GetDocument.aspx?tn=265693&DocumentContentId=102545
A22: Construction Rate
A35: Notes
A36: 2025 T24 | B36: Laboratory is a space or room where hazardous materials are used for activities such as testing, analysis, instruction, research, or developmental activities. Laboratory Suite is a Group L occupancy space within a building or structure, which may include multiple laboratories, offices, storage, equipment rooms or similar support functions. Laboratory, Scientific Area is a room or area where research, experiments, and measurement in medical and physical sciences are performed requiring examination of fine details. The area may include workbenches, countertops, scientific instruments, and associated floor spaces. Scientific laboratory does not refer to film, computer, and other laboratories where scientific experiments are not performed.

Sheet Prototype
A1: NORESCO, Updated August 2025
A2: Laboratory
A3: Characteristic | B3: Value | C3: Data Sources
A4: Building Type | B4: Laboratory
A5: Building Category | B5: Nonresidential
A6: Vintages | B6: 4 Vintages: Pre-1978 , 1978-1997 ,1998-2007 , 2008-2018 New Construction (2019+) | C6: Based on the vintage bin analysis | D6: NonRes-Vintage bins-Draft Report-30Nov2023-Final.docx
A7: Shape | B7: #VALUE! | C7: The analysis uses prototype geometry originally developed by CEC.
A8: Total Floor Area (ft²) | B8: 53633 | C8: Same as CEC
A9: Aspect Ratio | B9: 1.5 | C9: Same as CEC
A10: Number of Floors | B10: 3 | C10: Same as CEC
A11: Roof type | B11: Flat | C11: Same as CEC
A12: WWR | B12: 33% | C12: Same as CEC
A13: Shading Geometry | B13: No Shades | C13: Same as CEC
A14: Floor to floor height (feet) | B14: 13 | C14: Same as CEC
A15: Floor to ceiling height (feet) | B15: 9 (4 ft above-ceiling plenum) | C15: Same as CEC
A16: Glazing sill height (feet) | B16: 3.35 ft (top of the window is 7.64 ft high with 4.29 ft high glass) | C16: Same as CEC
A20: Above grade wall area (ft²) | B20: 21287.463
A21: Gross wall area (ft²) | B21: 21287.463
A22: Roof area (ft²) | B22: 17875.949
A23: Underground Gross Wall Area (ft²) | B23: 0
A28: Existing prototypes:
A29: DEER Manufacturing-BioTech model | C29: PNNL | D29: CEC Lab Model
A30: #VALUE! | C30: n/a | D30: #VALUE!
A31: Total Floor Area (ft²) | C31: 0 | D31: 53633

Sheet Zones
A1: ="Proposed Layout - "&Prototype!B4 -> Proposed Layout - Laboratory
A2: Space Type | B2: Space/Thermal Zone | C2: HVAC System Name/AHU Name | D2: Schedule Category | E2: Conditioned (Y/N) | F2: Area Fraction | G2: Area (ft²) | H2: Volume (ft³) | I2: Multipliers | J2: Number of People | K2: People (Persons/1,000 ft²) [T24, 2025,Table 120.1-A]
A3: Laboratory, Scientific | B3: Core_bottom | C3: AHU-1 | D3: Lab | E3: Yes | F3: =G3/$G$21 -> 0.19741078 | G3: 10587.74 | H3: 95294.29 | I3: 1 | J3: =K3*G3/1000 -> 264.6935 | K3: 25
A4: Laboratory, Scientific | B4: Core_mid | C4: AHU-2 | D4: Lab | E4: Yes | F4: =G4/$G$21 -> 0.19741078 | G4: 10587.74 | H4: 95294.29 | I4: 1 | J4: =K4*G4/1000 -> 264.6935 | K4: 25
A5: Laboratory, Scientific | B5: Core_top | C5: AHU-3 | D5: Lab | E5: Yes | F5: =G5/$G$21 -> 0.19741078 | G5: 10587.74 | H5: 95294.29 | I5: 1 | J5: =K5*G5/1000 -> 264.6935 | K5: 25
A6: Plenum | B6: Firstfloor_plenum | C6: n/a | D6: n/a | E6: No | F6: =G6/$G$21 -> 0.33333333 | G6: 17877.68 | H6: 71514.2 | I6: 1 | J6: =K6*G6/1000 -> 0 | K6: 0
A7: Plenum | B7: Midfloor_plenum | C7: n/a | D7: n/a | E7: No | F7: =G7/$G$21 -> 0.33333333 | G7: 17877.68 | H7: 71514.2 | I7: 1 | J7: =K7*G7/1000 -> 0 | K7: 0
A8: Office Area (>250 square feet) | B8: Perimeter_bot_zn_1 | C8: AHU-1 | D8: Office | E8: Yes | F8: =G8/$G$21 -> 0.041615765 | G8: 2231.98 | H8: 20088.81 | I8: 1 | J8: =K8*G8/1000 -> 11.1599 | K8: 5
A9: Office Area (>250 square feet) | B9: Perimeter_bot_zn_2 | C9: AHU-1 | D9: Office | E9: Yes | F9: =G9/$G$21 -> 0.026346446 | G9: 1413.04 | H9: 12717.98 | I9: 1 | J9: =K9*G9/1000 -> 7.0652 | K9: 5
A10: Office Area (>250 square feet) | B10: Perimeter_bot_zn_3 | C10: AHU-1 | D10: Office | E10: Yes | F10: =G10/$G$21 -> 0.041615765 | G10: 2231.98 | H10: 20088.81 | I10: 1 | J10: =K10*G10/1000 -> 11.1599 | K10: 5
A11: Office Area (>250 square feet) | B11: Perimeter_bot_zn_4 | C11: AHU-1 | D11: Office | E11: Yes | F11: =G11/$G$21 -> 0.026344582 | G11: 1412.94 | H11: 12717.05 | I11: 1 | J11: =K11*G11/1000 -> 7.0647 | K11: 5
A12: Laboratory, Scientific | B12: Perimeter_mid_zn_1 | C12: AHU-2 | D12: Lab | E12: Yes | F12: =G12/$G$21 -> 0.041615765 | G12: 2231.98 | H12: 20088.81 | I12: 1 | J12: =K12*G12/1000 -> 55.7995 | K12: 25
A13: Laboratory, Scientific | B13: Perimeter_mid_zn_2 | C13: AHU-2 | D13: Lab | E13: Yes | F13: =G13/$G$21 -> 0.026346446 | G13: 1413.04 | H13: 12717.98 | I13: 1 | J13: =K13*G13/1000 -> 35.326 | K13: 25
A14: Laboratory, Scientific | B14: Perimeter_mid_zn_3 | C14: AHU-2 | D14: Lab | E14: Yes | F14: =G14/$G$21 -> 0.041615765 | G14: 2231.98 | H14: 20088.81 | I14: 1 | J14: =K14*G14/1000 -> 55.7995 | K14: 25
... A20: Plenum | B20: Topfloor_plenum | C20: n/a | D20: n/a | E20: No | F20: =G20/$G$21 -> 0.33333333 | G20: 17877.68 | H20: 71514.2 | I20: 1 | J20: =K20*G20/1000 -> 0 | K20: 0
A21: Total (2 Space types) | B21: Total ( 18 spaces) | C21: Total ( Thermal Zones) | E21: Total (15 Conditioned zones) | G21: =SUM(G3:G20)-G6-G7-G20 -> 53633.04 | J21: =SUM(J3:J20) -> 1049.2284
A33: Background Data [To be deleted prior to publication]

Sheet Envelope
A1: ="Envelope - "&Prototype!B4 -> Envelope - Laboratory
A2: Element | B2: Prototype | C2: Assembly Type | D2: Construction | E2: Thermal properties | F2: Vintage | G2: Selected T24 | H2: Note | I2: CZ1 | J2: CZ2 | K2: CZ3 | L2: CZ4 | M2: CZ5 | N2: CZ6 | O2: CZ7 | P2: CZ8 | Q2: CZ9 | R2: CZ10 | S2: CZ11 | T2: CZ12 | U2: CZ13 | V2: CZ14 | W2: CZ15 | X2: CZ16
A3: External Wall | B3: =Prototype!A2 -> Laboratory | C3: ExtWall_MetalFramed_NonRes | D3: Metal frame + insulation + Gypsum board | E3: U-value IP | F3: Pre 1978 | G3: N/A | H3: ASHRAE 90.1, 2022 Table A3.3.3.1, 3.5", R-0 | I3: 0.352 | J3: 0.352 | K3: 0.352 | L3: 0.352 | M3: 0.352 | N3: 0.352 | O3: 0.352 | P3: 0.352 | Q3: 0.352 | R3: 0.352 | S3: 0.352 | T3: 0.352 | U3: 0.352 | V3: 0.352 | W3: 0.352 | X3: 0.352
F4: 1978-1997 | G4: 1986 | H4: Similar to Low-rise office: Package A/ Heat Capacity was considered ~10 (BTU/F/ft²) | I4: 0.21276596 | J4: 0.22727273 | K4: 0.22727273 | L4: 0.2173913 | M4: 0.25641026 | N4: 0.25641026 | O4: 0.25641026 | P4: 0.25641026 | Q4: 0.25641026 | R4: 0.25641026 | S4: 0.23809524 | T4: 0.23809524 | U4: 0.23809524 | V4: 0.20833333 | W4: 0.20833333 | X4: 0.21276596
F5: 1998-2007 | G5: 2001 | H5: Table 1-H | I5: 0.182 | J5: 0.182 | K5: 0.189 | L5: 0.189 | M5: 0.189 | N5: 0.189 | O5: 0.189 | P5: 0.189 | Q5: 0.189 | R5: 0.182 | S5: 0.182 | T5: 0.182 | U5: 0.182 | V5: 0.182 | W5: 0.182 | X5: 0.182
F6: 2008-2018 | G6: 2013 | H6: Table 140.3-B | I6: 0.098 | J6: 0.062 | K6: 0.082 | L6: 0.062 | M6: 0.062 | N6: 0.098 | O6: 0.098 | P6: 0.062 | Q6: 0.062 | R6: 0.062 | S6: 0.062 | T6: 0.062 | U6: 0.062 | V6: 0.062 | W6: 0.062 | X6: 0.062
F7: 2019+ | G7: 2025 | H7: Table 140.3-B | I7: 0.06 | J7: 0.055 | K7: 0.071 | L7: 0.055 | M7: 0.055 | N7: 0.06 | O7: 0.06 | P7: 0.055 | Q7: 0.055 | R7: 0.055 | S7: 0.055 | T7: 0.055 | U7: 0.055 | V7: 0.055 | W7: 0.055 | X7: 0.055
A8: Roof | B8: =$B$3 -> Laboratory | C8: FlatRoof_WoodFramedAndOther_NonRes | D8: Built-up Roof roof membrane+roof insulation+metal decking | E8: U-value IP | F8: Pre 1978 | G8: N/A | H8: Considering 30 years for roof/ insulation replacement. | I8: 0.057 | J8: 0.057 | K8: 0.057 | L8: 0.057 | M8: 0.057 | N8: 0.078 | O8: 0.078 | P8: 0.078 | Q8: 0.078 | R8: 0.078 | S8: 0.057 | T8: 0.057 | U8: 0.057 | V8: 0.057 | W8: 0.057 | X8: 0.057
F9: 1978-1997 | G9: 1992 | I9: 0.057 | J9: 0.057 | K9: 0.057 | L9: 0.057 | M9: 0.057 | N9: 0.078 | O9: 0.078 | P9: 0.078 | Q9: 0.078 | R9: 0.078 | S9: 0.057 | T9: 0.057 | U9: 0.057 | V9: 0.057 | W9: 0.057 | X9: 0.057
F10: 1998-2007 | G10: 2001 | H10: Table 1-H | I10: 0.057 | J10: 0.057 | K10: 0.057 | L10: 0.057 | M10: 0.057 | N10: 0.078 | O10: 0.078 | P10: 0.078 | Q10: 0.078 | R10: 0.057 | S10: 0.057 | T10: 0.057 | U10: 0.057 | V10: 0.057 | W10: 0.057 | X10: 0.057
F11: 2008-2018 | G11: 2013 | H11: Table 140.3-B | I11: 0.049 | J11: 0.039 | K11: 0.039 | L11: 0.039 | M11: 0.049 | N11: 0.075 | O11: 0.067 | P11: 0.067 | Q11: 0.039 | R11: 0.039 | S11: 0.039 | T11: 0.039 | U11: 0.039 | V11: 0.039 | W11: 0.039 | X11: 0.039
F12: 2019+ | G12: 2025 | H12: Table 140.3-B | I12: 0.038 | J12: 0.038 | K12: 0.038 | L12: 0.038 | M12: 0.038 | N12: 0.038 | O12: 0.038 | P12: 0.038 | Q12: 0.038 | R12: 0.038 | S12: 0.038 | T12: 0.038 | U12: 0.038 | V12: 0.038 | W12: 0.038 | X12: 0.038
A13: Windows | B13: =$B$3 -> Laboratory | C13: FixedWindow_NonRes | D13: Single pane | E13: U-value IP | F13: Pre 1978 | G13: N/A | H13: ASHRAE Handbook of Fundamentals (Table 4-Ch15) for single pane & T24, 2013 for double pane (33%-67%)* | I13: =0.33*1.12+0.67*0.36 -> 0.6108 | J13: =0.33*1.12+0.67*0.36 -> 0.6108 | K13: =0.33*1.12+0.67*0.36 -> 0.6108 | L13: =0.33*1.12+0.67*0.36 -> 0.6108 | M13: =0.33*1.12+0.67*0.36 -> 0.6108 | N13: =0.33*1.12+0.67*0.36 -> 0.6108 | O13: =0.33*1.12+0.67*0.36 -> 0.6108 | P13: =0.33*1.12+0.67*0.36 -> 0.6108 | ... X13: =0.33*1.12+0.67*0.36 -> 0.6108
F14: 1978-1997 | G14: N/A | I14: =0.33*1.12+0.67*0.36 -> 0.6108 | J14: =0.33*1.12+0.67*0.36 -> 0.6108 | K14: =0.33*1.12+0.67*0.36 -> 0.6108 | L14: =0.33*1.12+0.67*0.36 -> 0.6108 | M14: =0.33*1.12+0.67*0.36 -> 0.6108 | N14: =0.33*1.12+0.67*0.36 -> 0.6108 | O14: =0.33*1.12+0.67*0.36 -> 0.6108 | P14: =0.33*1.12+0.67*0.36 -> 0.6108 | ... X14: =0.33*1.12+0.67*0.36 -> 0.6108
D15: Double pane | F15: 1998-2007 | G15: 2001 | H15: Table 1-H | I15: 0.49 | J15: 0.49 | K15: 0.81 | L15: 0.81 | M15: 0.81 | N15: 0.81 | O15: 0.81 | P15: 0.81 | Q15: 0.81 | R15: 0.49 | S15: 0.49 | T15: 0.49 | U15: 0.49 | V15: 0.49 | W15: 0.49 | X15: 0.49
F16: 2008-2018 | G16: 2013 | H16: Table 140.3-B | I16: 0.36 | J16: 0.36 | K16: 0.36 | L16: 0.36 | M16: 0.36 | N16: 0.36 | O16: 0.36 | P16: 0.36 | Q16: 0.36 | R16: 0.36 | S16: 0.36 | T16: 0.36 | U16: 0.36 | V16: 0.36 | W16: 0.36 | X16: 0.36
F17: 2019+ | G17: 2025 | H17: Table 140.3-B | I17: 0.36 | J17: 0.36 | K17: 0.36 | L17: 0.36 | M17: 0.36 | N17: 0.36 | O17: 0.36 | P17: 0.36 | Q17: 0.34 | R17: 0.36 | S17: 0.34 | T17: 0.34 | U17: 0.34 | V17: 0.34 | W17: 0.34 | X17: 0.36
B18: =$B$3 -> Laboratory | C18: FixedWindow_NonRes | D18: Single pane | E18: SHGC | F18: Pre 1978 | G18: N/A | H18: ASHRAE Handbook of Fundamentals (Table 10-Ch15) for single pane & T24, 2013 for double pane (33%-67%)* | I18: =0.79*0.33+0.67*I21 -> 0.4282 | J18: =0.79*0.33+0.67*J21 -> 0.4282 | K18: =0.79*0.33+0.67*K21 -> 0.4282 | L18: =0.79*0.33+0.67*L21 -> 0.4282 | M18: =0.79*0.33+0.67*M21 -> 0.4282 | N18: =0.79*0.33+0.67*N21 -> 0.4282 | O18: =0.79*0.33+0.67*O21 -> 0.4282 | P18: =0.79*0.33+0.67*P21 -> 0.4282 | ... X18: =0.79*0.33+0.67*X21 -> 0.4282
F19: 1978-1997 | G19: N/A | I19: =0.79*0.33+0.67*I21 -> 0.4282 | J19: =0.79*0.33+0.67*J21 -> 0.4282 | K19: =0.79*0.33+0.67*K21 -> 0.4282 | L19: =0.79*0.33+0.67*L21 -> 0.4282 | M19: =0.79*0.33+0.67*M21 -> 0.4282 | N19: =0.79*0.33+0.67*N21 -> 0.4282 | O19: =0.79*0.33+0.67*O21 -> 0.4282 | P19: =0.79*0.33+0.67*P21 -> 0.4282 | ... X19: =0.79*0.33+0.67*X21 -> 0.4282
D20: Double pane | F20: 1998-2007 | G20: 2001 | H20: Table 1-H - WWR:31-40% / SHGC non-north | I20: 0.43 | J20: 0.36 | K20: 0.41 | L20: 0.41 | M20: 0.41 | N20: 0.34 | O20: 0.34 | P20: 0.34 | Q20: 0.34 | R20: 0.31 | S20: 0.31 | T20: 0.31 | U20: 0.31 | V20: 0.31 | W20: 0.31 | X20: 0.43
F21: 2008-2018 | G21: 2013 | H21: Table 140.3-B | I21: 0.25 | J21: 0.25 | K21: 0.25 | L21: 0.25 | M21: 0.25 | N21: 0.25 | O21: 0.25 | P21: 0.25 | Q21: 0.25 | R21: 0.25 | S21: 0.25 | T21: 0.25 | U21: 0.25 | V21: 0.25 | W21: 0.25 | X21: 0.25
F22: 2019+ | G22: 2025 | H22: Table 140.3-B | I22: 0.25 | J22: 0.25 | K22: 0.25 | L22: 0.25 | M22: 0.25 | N22: 0.25 | O22: 0.25 | P22: 0.25 | Q22: 0.22 | R22: 0.25 | S22: 0.22 | T22: 0.22 | U22: 0.22 | V22: 0.22 | W22: 0.22 | X22: 0.25
E25: Infiltration
F26: Vintage | G26: I_75 6-sdied Infiltration rate @ 75 pa | H26: Note | I26: I-design (cfm/ft²) (4-sided Infiltration rate at normal pressure) (Design flow rate approach and Flow/Exterior Wall Area calculation method)
E27: Infiltration | F27: Pre 1978 | G27: 1.1 | H27: 2022 CASE report (Table 38) | I27: 0.3301
F28: 1978-1997 | G28: 1.1 | H28: 2022 CASE report (Table 38) | I28: 0.3301
F29: 1998-2007 | G29: 1.1 | H29: 2022 CASE report (Table 38) | I29: 0.3301
F30: 2008-2018 | G30: 1 | H30: 2022 CASE report (Table 38) & T24, 2008-2016 (Table 140.3-B)--Air barrier is required in CZ 10-16 | I30: 0.3021
F31: 2019+ | G31: 0.6 | H31: 2022 CASE report (Table 38) & T24, 2025 (Table 140.3-B)--Air barrier is required in all CZs | I31: 0.1801
E32: Source: T24 air barrier requirements (all editions) and the standardized infiltration rate reported in the 2022 CASE report and Dodge 2023 data
E33: Air Leakage Memo: | G33: Infiltration_rate_report_14May2025-Short-Version.docx

Sheet HVAC System
A1: ="HVAC system - "&Prototype!B4 -> HVAC system - Laboratory
A2: Vintage | B2: Zones | C2: Heating | D2: Cooling | E2: Air Distribution | F2: Source | G2: Note
A3: Exisiting | B3: Conditioned zones | C3: Gas Boiler | D3: DX | E3: Multi zone VAV with hydronic reheat | F3: Engineering Judgement | G3: 100% outdoor air for labs, but no required energy recovery
A4: New Construction | B4: Conditioned zones | C4: Central air-to-water HP | D4: Central air-cooled Chiller | E4: VAV ( Each zone has a chilled water or hot water changeover coil with a 6-way valve for cooling or heating) | F4: T24 2025 ACM 2025, Table 2 and 3 | G4: System 14a – Aircooled 4pipe VAV with Exhaust heat recovery
A9: Efficiency of HVAC system
A10: Vintage | B10: Upgrade/Installed year | C10: Air-Cooled Chiller | D10: Gas Boiler | E10: Air-to-Water HP | F10: Sources | G10: Note
A11: Pre 1978 | B11: 2008 | C11: Air-cooled Chiller >150 Tons--2.8 COP, 3.05 IPLV | D11: Gas-Fired Boiler ≥ 300,000 Btu/h and ≤ 2,500,000 Btu/h-- 80% Et | E11: n/a | F11: T24, Part 6, 2008 , Table 112-D (for Water Chilling Packages)
A12: 1978-1997
A13: 1998-2007
A14: 2008-2018 | B14: 2013 | C14: Air-cooled Chiller >150 Tons--≥ 9.562 EER, ≥ 12.500 IPLV | D14: Gas-Fired Boiler ≥ 300,000 Btu/h and ≤ 2,500,000 Btu/h-- 80% Et | E14: n/a | F14: T24, Part 6, 2013 , Table 110.2-D (for Water Chilling Packages) -Table 110.2-k (for Gas Fired Boiler)
A15: New Construction | B15: 2025 | C15: Air-cooled Chiller >150 Tons--≥ 10.100 EER, ≥ 14.000 IPLV | D15: n/a | E15: Air Cooled (Heating Mode) Split system and single package≥ 135,000 Btu/h and < 240,000 Btu/h 3.3 COP | F15: T24, Part 6, 2013 , Table 110.2-D (for Water Chilling Packages) - Table 110.2-B (for HP efficiecny)
C17: * Et = Combustion efficiency | D17: * Et = Thermal efficiency
A19: Fan power
A20: Vintage | B20: Approach | C20: System | D20: Total Static Pressure (TSP) in w.c. (PNNL 20405, 2010, Table 5.11) | E20: Fan Efficiency (ACM, 2025) | F20: Fan Motor and Drive Efficiency [ACM 2025, Table 13] | G20: W/cfm [ACM 2025, Table 14 and 15] | H20: Data Source | I20: Note
A21: Existing | B21: PNNL TSP | C21: System 6 VAV >5,000 cfm | D21: 5.58 | E21: 0.65 | F21: 0.9 | H21: PNNL 2010 TSD
A22: Brake horse power (bhp)=(Supply cfm*TSP in w.c.)/(6356*Fan efficiency)
A23: Fan power (w/cfm) = bhp/motor and drive efficiency *746
A24: New Construction | B24: ACM 2025 | C24: Multi Zone VAV System >5,000 cfm; < 10,000 cfm | D24: =G24*E24*F24/746*6356 -> 5.0490582 | E24: 0.65 | F24: 0.9 | G24: 1.013 | H24: 2025 ACM
F25: * 0.9 is an average fan efficiency according to ACM 2025, Table 13
A26: Fan total eff (E+ input) = 0.65 x Motor_eff
A27: TSP (E+ input) in w.c. = Motor_eff/746 x (6356 x Fan_eff) x W/cfm
A28: Fan_eff=0.65
A32: Background Data [To be deleted prior to publication]

Sheet Thermostat
A1: ="Thermostat Setpoints - "&Prototype!A2 -> Thermostat Setpoints - Laboratory
A2: Setpoint | B2: CZ1 | C2: CZ2 | D2: CZ3 | E2: CZ4 | F2: CZ5 | G2: CZ6 | H2: CZ7 | I2: CZ8 | J2: CZ9 | K2: CZ10 | L2: CZ11 | M2: CZ12 | N2: CZ13 | O2: CZ14 | P2: CZ15 | Q2: CZ16 | R2: Source
A3: Lab Heating Setpoint (F) | B3: 70 | C3: 70 | D3: 70 | E3: 70 | F3: 70 | G3: 70 | H3: 70 | I3: 70 | J3: 70 | K3: 70 | L3: 70 | M3: 70 | N3: 70 | O3: 70 | P3: 70 | Q3: 70 | R3: T24 2022 - Appendix 5.4B
A4: Lab Heating Setback (F) | B4: 70 | C4: 70 | D4: 70 | E4: 70 | F4: 70 | G4: 70 | H4: 70 | I4: 70 | J4: 70 | K4: 70 | L4: 70 | M4: 70 | N4: 70 | O4: 70 | P4: 70 | Q4: 70
A5: Lab Cooling Setpoint (F) | B5: 75 | C5: 75 | D5: 75 | E5: 75 | F5: 75 | G5: 75 | H5: 75 | I5: 75 | J5: 75 | K5: 75 | L5: 75 | M5: 75 | N5: 75 | O5: 75 | P5: 75 | Q5: 75
A6: Lab Cooling Setback (F) | B6: 75 | C6: 75 | D6: 75 | E6: 75 | F6: 75 | G6: 75 | H6: 75 | I6: 75 | J6: 75 | K6: 75 | L6: 75 | M6: 75 | N6: 75 | O6: 75 | P6: 75 | Q6: 75
A7: Office Heating Setpoint (F) | B7: 70 | C7: 70 | D7: 70 | E7: 70 | F7: 70 | G7: 70 | H7: 70 | I7: 70 | J7: 70 | K7: 70 | L7: 70 | M7: 70 | N7: 70 | O7: 70 | P7: 70 | Q7: 70
A8: Office Heating Setback (F) | B8: 60 | C8: 60 | D8: 60 | E8: 60 | F8: 60 | G8: 60 | H8: 60 | I8: 60 | J8: 60 | K8: 60 | L8: 60 | M8: 60 | N8: 60 | O8: 60 | P8: 60 | Q8: 60
A9: Office Cooling Setpoint (F) | B9: 75 | C9: 75 | D9: 75 | E9: 75 | F9: 75 | G9: 75 | H9: 75 | I9: 75 | J9: 75 | K9: 75 | L9: 75 | M9: 75 | N9: 75 | O9: 75 | P9: 75 | Q9: 75
A10: Office Cooling Setback (F) | B10: 85 | C10: 85 | D10: 85 | E10: 85 | F10: 85 | G10: 85 | H10: 85 | I10: 85 | J10: 85 | K10: 85 | L10: 85 | M10: 85 | N10: 85 | O10: 85 | P10: 85 | Q10: 85
A38: Office Cooling Setback (F) | B38: 85 | C38: 85 | D38: 85 | E38: 85 | F38: 85 | G38: 85 | H38: 85 | I38: 85 | J38: 85 | K38: 85 | L38: 85 | M38: 85 | N38: 85 | O38: 85 | P38: 85 | Q38: 85
A40: Source: PNNL Healthcare-Outpaitiet prototype use this setpoints: Administration zones: 72°F Cooling/70°F Heating, Critical zones: 72°F Cooling/70°F Heating, Operating rooms: 65°F Cooling/65°F Heating
A41: PNNL Healthcare-Outpaitiet prototype use this setbacks: 77°F Cooling/65°F Heating, Critical zones: no setback, Operating rooms: 72°F Cooling/65°F Heating

Sheet Ventilation
A1: ="Outdoor Airflow Rate - "&Prototype!A2 -> Outdoor Airflow Rate - Laboratory
A2: Space Type | B2: Space/Thermal Zone | C2: Number of People | D2: Floor Area (ft²) | E2: cfm/person (T24, 2025, Equation 120.1-F and Table 120.1-A) | F2: cfm/ft² (T24, 2025, Equation 120.1-F and Table 120.1-A) | G2: Required exhaust rate-CFM/ft²- (T24, part 6 2025, Table 120.1-B – minimum exhaust rates) | H2: Total cfm driven by people | I2: Total cfm driven by area | J2: Total cfm driven by exhaust | K2: Total cfm | L2: Notes
A3: =Zones!A3 -> Laboratory, Scientific | B3: =Zones!B3 -> Core_bottom | C3: =Zones!J3 -> 264.6935 | D3: =Zones!G3 -> 10587.74 | E3: 15 | F3: =VLOOKUP(A3,A$55:E$58,5, FALSE) -> 0.15 | G3: =F56 -> 1 | H3: =C3*E3 -> 3970.4025 | I3: =D3*F3 -> 1588.161 | J3: =G3*D3 -> 10587.74 | K3: =MAX(H3,I3,J3) -> 10587.74
A4: =Zones!A4 -> Laboratory, Scientific | B4: =Zones!B4 -> Core_mid | C4: =Zones!J4 -> 264.6935 | D4: =Zones!G4 -> 10587.74 | E4: 15 | F4: =VLOOKUP(A4,A$55:E$58,5, FALSE) -> 0.15 | G4: =F56 -> 1 | H4: =C4*E4 -> 3970.4025 | I4: =D4*F4 -> 1588.161 | J4: =G4*D4 -> 10587.74 | K4: =MAX(H4,I4,J4) -> 10587.74
A5: =Zones!A5 -> Laboratory, Scientific | B5: =Zones!B5 -> Core_top | C5: =Zones!J5 -> 264.6935 | D5: =Zones!G5 -> 10587.74 | E5: 15 | F5: =VLOOKUP(A5,A$55:E$58,5, FALSE) -> 0.15 | G5: =F56 -> 1 | H5: =C5*E5 -> 3970.4025 | I5: =D5*F5 -> 1588.161 | J5: =G5*D5 -> 10587.74 | K5: =MAX(H5,I5,J5) -> 10587.74
A6: =Zones!A6 -> Plenum | B6: =Zones!B6 -> Firstfloor_plenum | C6: =Zones!J6 -> 0 | D6: =Zones!G6 -> 17877.68 | E6: 0 | F6: 0 | G6: =S6 -> 0 | H6: =C6*E6 -> 0 | I6: =D6*F6 -> 0 | J6: =G6*D6 -> 0 | K6: =MAX(H6,I6,J6) -> 0
A7: =Zones!A7 -> Plenum | B7: =Zones!B7 -> Midfloor_plenum | C7: =Zones!J7 -> 0 | D7: =Zones!G7 -> 17877.68 | E7: 0 | F7: 0 | G7: =S7 -> 0 | H7: =C7*E7 -> 0 | I7: =D7*F7 -> 0 | J7: =G7*D7 -> 0 | K7: =MAX(H7,I7,J7) -> 0
A8: =Zones!A8 -> Office Area (>250 square feet) | B8: =Zones!B8 -> Perimeter_bot_zn_1 | C8: =Zones!J8 -> 11.1599 | D8: =Zones!G8 -> 2231.98 | E8: 15 | F8: =VLOOKUP(A8,A$55:E$58,5, FALSE) -> 0.15 | G8: =S8 -> 0 | H8: =C8*E8 -> 167.3985 | I8: =D8*F8 -> 334.797 | J8: =G8*D8 -> 0 | K8: =MAX(H8,I8,J8) -> 334.797
A9: =Zones!A9 -> Office Area (>250 square feet) | B9: =Zones!B9 -> Perimeter_bot_zn_2 | C9: =Zones!J9 -> 7.0652 | D9: =Zones!G9 -> 1413.04 | E9: 15 | F9: =VLOOKUP(A9,A$55:E$58,5, FALSE) -> 0.15 | G9: =S9 -> 0 | H9: =C9*E9 -> 105.978 | I9: =D9*F9 -> 211.956 | J9: =G9*D9 -> 0 | K9: =MAX(H9,I9,J9) -> 211.956
A10: =Zones!A10 -> Office Area (>250 square feet) | B10: =Zones!B10 -> Perimeter_bot_zn_3 | C10: =Zones!J10 -> 11.1599 | D10: =Zones!G10 -> 2231.98 | E10: 15 | F10: =VLOOKUP(A10,A$55:E$58,5, FALSE) -> 0.15 | G10: =S10 -> 0 | H10: =C10*E10 -> 167.3985 | I10: =D10*F10 -> 334.797 | J10: =G10*D10 -> 0 | K10: =MAX(H10,I10,J10) -> 334.797
A11: =Zones!A11 -> Office Area (>250 square feet) | B11: =Zones!B11 -> Perimeter_bot_zn_4 | C11: =Zones!J11 -> 7.0647 | D11: =Zones!G11 -> 1412.94 | E11: 15 | F11: =VLOOKUP(A11,A$55:E$58,5, FALSE) -> 0.15 | G11: =S11 -> 0 | H11: =C11*E11 -> 105.9705 | I11: =D11*F11 -> 211.941 | J11: =G11*D11 -> 0 | K11: =MAX(H11,I11,J11) -> 211.941
A12: =Zones!A12 -> Laboratory, Scientific | B12: =Zones!B12 -> Perimeter_mid_zn_1 | C12: =Zones!J12 -> 55.7995 | D12: =Zones!G12 -> 2231.98 | E12: 15 | F12: =VLOOKUP(A12,A$55:E$58,5, FALSE) -> 0.15 | G12: =F56 -> 1 | H12: =C12*E12 -> 836.9925 | I12: =D12*F12 -> 334.797 | J12: =G12*D12 -> 2231.98 | K12: =MAX(H12,I12,J12) -> 2231.98
A13: =Zones!A13 -> Laboratory, Scientific | B13: =Zones!B13 -> Perimeter_mid_zn_2 | C13: =Zones!J13 -> 35.326 | D13: =Zones!G13 -> 1413.04 | E13: 15 | F13: =VLOOKUP(A13,A$55:E$58,5, FALSE) -> 0.15 | G13: =F56 -> 1 | H13: =C13*E13 -> 529.89 | I13: =D13*F13 -> 211.956 | J13: =G13*D13 -> 1413.04 | K13: =MAX(H13,I13,J13) -> 1413.04
A14: =Zones!A14 -> Laboratory, Scientific | B14: =Zones!B14 -> Perimeter_mid_zn_3 | C14: =Zones!J14 -> 55.7995 | D14: =Zones!G14 -> 2231.98 | E14: 15 | F14: =VLOOKUP(A14,A$55:E$58,5, FALSE) -> 0.15 | G14: =F56 -> 1 | H14: =C14*E14 -> 836.9925 | I14: =D14*F14 -> 334.797 | J14: =G14*D14 -> 2231.98 | K14: =MAX(H14,I14,J14) -> 2231.98
A15: =Zones!A15 -> Laboratory, Scientific | B15: =Zones!B15 -> Perimeter_mid_zn_4 | C15: =Zones!J15 -> 35.3235 | D15: =Zones!G15 -> 1412.94 | E15: 15 | F15: =VLOOKUP(A15,A$55:E$58,5, FALSE) -> 0.15 | G15: =F56 -> 1 | H15: =C15*E15 -> 529.8525 | I15: =D15*F15 -> 211.941 | J15: =G15*D15 -> 1412.94 | K15: =MAX(H15,I15,J15) -> 1412.94
A16: =Zones!A16 -> Office Area (>250 square feet) | B16: =Zones!B16 -> Perimeter_top_zn_1 | C16: =Zones!J16 -> 11.1599 | D16: =Zones!G16 -> 2231.98 | E16: 15 | F16: =VLOOKUP(A16,A$55:E$58,5, FALSE) -> 0.15 | G16: =S16 -> 0 | H16: =C16*E16 -> 167.3985 | I16: =D16*F16 -> 334.797 | J16: =G16*D16 -> 0 | K16: =MAX(H16,I16,J16) -> 334.797
A17: =Zones!A17 -> Office Area (>250 square feet) | B17: =Zones!B17 -> Perimeter_top_zn_2 | C17: =Zones!J17 -> 7.0652 | D17: =Zones!G17 -> 1413.04 | E17: 15 | F17: =VLOOKUP(A17,A$55:E$58,5, FALSE) -> 0.15 | G17: =S17 -> 0 | H17: =C17*E17 -> 105.978 | I17: =D17*F17 -> 211.956 | J17: =G17*D17 -> 0 | K17: =MAX(H17,I17,J17) -> 211.956
A18: =Zones!A18 -> Office Area (>250 square feet) | B18: =Zones!B18 -> Perimeter_top_zn_3 | C18: =Zones!J18 -> 11.1599 | D18: =Zones!G18 -> 2231.98 | E18: 15 | F18: =VLOOKUP(A18,A$55:E$58,5, FALSE) -> 0.15 | G18: =S18 -> 0 | H18: =C18*E18 -> 167.3985 | I18: =D18*F18 -> 334.797 | J18: =G18*D18 -> 0 | K18: =MAX(H18,I18,J18) -> 334.797
A19: =Zones!A19 -> Office Area (>250 square feet) | B19: =Zones!B19 -> Perimeter_top_zn_4 | C19: =Zones!J19 -> 7.0647 | D19: =Zones!G19 -> 1412.94 | E19: 15 | F19: =VLOOKUP(A19,A$55:E$58,5, FALSE) -> 0.15 | G19: =S19 -> 0 | H19: =C19*E19 -> 105.9705 | I19: =D19*F19 -> 211.941 | J19: =G19*D19 -> 0 | K19: =MAX(H19,I19,J19) -> 211.941
A20: =Zones!A20 -> Plenum | B20: =Zones!B20 -> Topfloor_plenum | C20: =Zones!J20 -> 0 | D20: =Zones!G20 -> 17877.68 | E20: 0 | F20: 0 | G20: =S20 -> 0 | H20: =C20*E20 -> 0 | I20: =D20*F20 -> 0 | J20: =G20*D20 -> 0 | K20: =MAX(H20,I20,J20) -> 0
A21: =Zones!A21 -> Total (2 Space types) | B21: =Zones!B21 -> Total ( 18 spaces) | C21: =Zones!J21 -> 1049.2284 | D21: =Zones!G21 -> 53633.04 | J21: =SUM(J3:J20) -> 39053.16 | K21: =SUM(K3:K20) -> 41240.142
A28: Exhaust Hood
A29: Type of hood | B29: Space | C29: Max Exhaust Flow Rate (cfm/ft) [T24, 2025, Table 140.9-C] | D29: Hood length (ft) | E29: Hood Exhaust Rate (cfm) | F29: Note | G29: Source
A30: Fume Hood | B30: =B3 -> Core_bottom | C30: 250 | D30: =D3/1000 -> 10.58774 | E30: =C30*D30 -> 2646.935 | F30: ~1 fume hood per 500–1,500 ft² for research or academic lab buildings | G30: 2019 High Efficiency Fume Hoods in Laboratory Spaces CASE Report
A31: Fume Hood | B31: =B4 -> Core_mid | C31: 250 | D31: =D4/1000 -> 10.58774 | E31: =C31*D31 -> 2646.935
A32: Fume Hood | B32: =B5 -> Core_top | C32: 250 | D32: =D5/1000 -> 10.58774 | E32: =C32*D32 -> 2646.935
A33: Fume Hood | B33: =B12 -> Perimeter_mid_zn_1 | C33: 250 | D33: =D12/1000 -> 2.23198 | E33: =C33*D33 -> 557.995
A34: Fume Hood | B34: =B13 -> Perimeter_mid_zn_2 | C34: 250 | D34: =D13/1000 -> 1.41304 | E34: =C34*D34 -> 353.26
A35: Fume Hood | B35: =B14 -> Perimeter_mid_zn_3 | C35: 250 | D35: =D14/1000 -> 2.23198 | E35: =C35*D35 -> 557.995
A36: Fume Hood | B36: =B15 -> Perimeter_mid_zn_4 | C36: 250 | D36: =D15/1000 -> 1.41294 | E36: =C36*D36 -> 353.235
A40: *ANSI Z9.5 is the American National Standard for Laboratory Ventilation, and Section 6.4 focuses on how and where lab exhaust air must be discharged to ensure safety, health, and code compliance.
A41: *2025 California Title 24, Part 6, the prescriptive exhaust requirements for laboratory spaces are detailed in Section 140.9(c).
A44: Background Data [To be deleted prior to publication]
A47: Requirement | B47: Description | C47: Criterion | D47: Value / Standard
A48: Airflow Modulation | B48: Reduce to minimum 10 ACH or pressurization limit | C48: Pressure relationship | D48: Negative relative to adjacent spaces
A49: Variable Exhaust/Makeup Air | B49: Coordinated VAV systems for pressurization | C49: Pressure differential target | D49: 0.01–0.05 in. w.c.
A50: Fan Power Limit | B50: ≤ 0.65 W/CFM (standard); ≤ 0.85 W/CFM (with filtration) | C50: Infiltration modeling | D50: Not the primary OA source; modeled as tightly controlled
A51: Sash Closure Controls | B51: Auto-close after 5 min inactivity with safety features | C51: Envelope air barrier | D51: Required per T24 standards
A52: Makeup Air Compliance | B52: Must meet Section 140.4(o) standards | C52: Standard reference | D52: ANSI Z9.5-2022, ASHRAE 62.1, ASHRAE 90.1
A54: ="Outdoor Airflow Rate - "&Prototype!B4 -> Outdoor Airflow Rate - Laboratory
...

Sheet Water Heater
A1: Water Heater - Laboratory
A2: Vintage | B2: WH Type | C2: Efficiency | D2: Tank Volume (gal) | E2: Tank Loss | F2: Unit | G2: Note
A3: Existing | B3: Gas | C3: 0.8 | D3: =F33 -> 75.544445 | E3: =G37 -> 1073.4712 | F3: (Btu/hr)
A4: New Construction | B4: Gas | C4: 0.8 | D4: =F33 -> 75.544445 | E4: =G33 -> 1073.4712 | F4: (Btu/hr)
A7: Peak Hot Water Consumption
A8: Space Name | B8: Baseline WH Type [CEUS 2022] | C8: Total Area (ft²) | D8: Number of People | E8: Hot Water Usage Specification (gal/hr per person) [T24, 2022, Appendix 5.4A , sheet: "2022 SpaceFuncData-Input"] | F8: Peak Hot Water Usage (gal/hr) | G8: Peak Hot Water Usage (gal/min)
A9: =Zones!B3 -> Core_bottom | B9: Gas | C9: =[2]Zones!F3 -> 10587.74 | D9: =[2]Zones!I3 -> 264.6935 | E9: 0.18 | F9: =E9*D9 -> 47.64483 | G9: =F9/60 -> 0.7940805
A10: =Zones!B4 -> Core_mid | B10: Gas | C10: =[2]Zones!F4 -> 10587.74 | D10: =[2]Zones!I4 -> 264.6935 | E10: 0.18 | F10: =E10*D10 -> 47.64483 | G10: =F10/60 -> 0.7940805
A11: =Zones!B5 -> Core_top | B11: Gas | C11: =[2]Zones!F5 -> 10587.74 | D11: =[2]Zones!I5 -> 264.6935 | E11: 0.18 | F11: =E11*D11 -> 47.64483 | G11: =F11/60 -> 0.7940805
A12: =Zones!B6 -> Firstfloor_plenum | B12: Gas | C12: =[2]Zones!F6 -> 17877.68 | D12: =[2]Zones!I6 -> 0 | E12: 0 | F12: =E12*D12 -> 0 | G12: =F12/60 -> 0
A13: =Zones!B7 -> Midfloor_plenum | B13: Gas | C13: =[2]Zones!F7 -> 17877.68 | D13: =[2]Zones!I7 -> 0 | E13: 0 | F13: =E13*D13 -> 0 | G13: =F13/60 -> 0
A14: =Zones!B8 -> Perimeter_bot_zn_1 | B14: Gas | C14: =[2]Zones!F8 -> 2231.98 | D14: =[2]Zones!I8 -> 11.1599 | E14: 0.18 | F14: =E14*D14 -> 2.008782 | G14: =F14/60 -> 0.0334797
A15: =Zones!B9 -> Perimeter_bot_zn_2 | B15: Gas | C15: =[2]Zones!F9 -> 1413.04 | D15: =[2]Zones!I9 -> 7.0652 | E15: 0.18 | F15: =E15*D15 -> 1.271736 | G15: =F15/60 -> 0.0211956
A16: =Zones!B10 -> Perimeter_bot_zn_3 | B16: Gas | C16: =[2]Zones!F10 -> 2231.98 | D16: =[2]Zones!I10 -> 11.1599 | E16: 0.18 | F16: =E16*D16 -> 2.008782 | G16: =F16/60 -> 0.0334797
A17: =Zones!B11 -> Perimeter_bot_zn_4 | B17: Gas | C17: =[2]Zones!F11 -> 1412.94 | D17: =[2]Zones!I11 -> 7.0647 | E17: 0.18 | F17: =E17*D17 -> 1.271646 | G17: =F17/60 -> 0.0211941
A18: =Zones!B12 -> Perimeter_mid_zn_1 | B18: Gas | C18: =[2]Zones!F12 -> 2231.98 | D18: =[2]Zones!I12 -> 55.7995 | E18: 0.18 | F18: =E18*D18 -> 10.04391 | G18: =F18/60 -> 0.1673985
A19: =Zones!B13 -> Perimeter_mid_zn_2 | B19: Gas | C19: =[2]Zones!F13 -> 1413.04 | D19: =[2]Zones!I13 -> 35.326 | E19: 0.18 | F19: =E19*D19 -> 6.35868 | G19: =F19/60 -> 0.105978
A20: =Zones!B14 -> Perimeter_mid_zn_3 | B20: Gas | C20: =[2]Zones!F14 -> 2231.98 | D20: =[2]Zones!I14 -> 55.7995 | E20: 0.18 | F20: =E20*D20 -> 10.04391 | G20: =F20/60 -> 0.1673985
... A26: =Zones!B20 -> Topfloor_plenum | B26: Gas | C26: =[2]Zones!F20 -> 17877.68 | D26: =[2]Zones!I20 -> 0 | E26: 0 | F26: =E26*D26 -> 0 | G26: =F26/60 -> 0
A27: Total | C27: =SUM(C9:C26) -> 107266.08 | D27: =SUM(D9:D26) -> 1049.2284 | F27: =SUM(F9:F26) -> 188.86111 | G27: =F27/60 -> 3.1476852
A31: Water Heater Capacity, Tank Capacity, and Tank Loss
A32: WH Type | B32: Peak Hot Water Usage (gal/hr) | C32: Heat Output (Btu/hr) [ACM, 2025, 5.9.2: Rated capacity section] | D32: WH Capacity (Btu/hr) [ACM, 2025, 5.9.2: Rated capacity section] | E32: Required Energy Input (Btu/hr) | F32: Storage Volume (gal) | G32: Standby Loss | H32: Unit | I32: Off/On Cycle Loss Coefficient to Ambient Temp (Btu/h-F) | J32: Source
A33: Gas Storage WH | B33: =SUMIF(B9:B26, "*Gas*", F9:F26) -> 188.86111 | C33: =B33*(135-55)*8.2877*1 -> 125217.94 | D33: =C33*0.6 -> 75130.763 | E33: =D33/0.8 -> 93913.454 | F33: =(B33*F35)/B35 -> 75.544445 | G33: =(E33/800)+110*SQRT(F33) -> 1073.4712 | H33: Btu/hr | I33: =G33/B44 -> 16.021958 | J33: Standby loss equation: Title 20, §1605.1 Table F-4 WH capacity equation: ACM, 2025, 5.9.2: Rated capacity section)
A34: Electric resistance WH | B34: =SUMIF(B9:B23, "*Electric*", F9:F23) -> 0 | C34: =B34*(135-55)*8.2877*1 -> 0 | D34: =C34*0.85 -> 0 | E34: =D34/1 -> 0 | F34: =(B34*F35)/B35 -> 0 | H34: %/hr | I34: =0.0834*G34*F34 -> 0
A35: Total | B35: =B33+B34 -> 188.86111 | C35: =B35*(135-55)*8.2877*1 -> 125217.94 | D35: =C35*0.6 -> 75130.763 | E35: =D35/0.8 -> 93913.454 | F35: =B35*1*0.4 -> 75.544445
A37: Design supply temperature (F) | B37: 135 | C37: Ref: T24 2022 - Appendix 5.4B | F37: Standby Loss for Existing | G37: =(E35/800)+110*SQRT(F35) -> 1073.4712 | H37: Btu/hr | I37: =G37/B44 -> 16.021958
A38: Cold Water supply temperature (F) | B38: 55 | C38: Ref: ACM, 2025, 5.9.2: Rated capacity section
A39: WH system factor | B39: 0.6 | C39: Ref: ACM, 2025, 5.9.2: Rated capacity section
A40: Reheat multiplier | B40: 0.4
A41: * The 0.40 multiplier is a storage sizing factor used to account for the fact that the water heater doesn't need to store the full peak hour demand—it can reheat water during that time. This factor assumes that the heater will recover part of the hot water used during the peak hour, so only 40% of the peak hour demand needs to be stored at any given moment.
A42: **For Gas Water Heater: UA(Btu/h-°F)​=Q˙​SL​ (Btu/h)/ΔT (∘F)​
A43: Ambient temp | B43: 68
A44: Delta T | B44: =B37-B43 -> 67
A45: ** For Electric Water Heater: UA(Btu/h-°F)​= 0.0834 *SL​ (%/hr)*V gal
A47: Background Data [To be deleted prior to publication]

Sheet Ext Lighting
A1: ="Exterior Lighting - "&Prototype!B4 -> Exterior Lighting - Laboratory
A2: Motion Controlled Luminaires (W) | B2: Non-motion Controlled Luminaires (W) | C2: Total (W) | D2: Source
A3: =G15 -> 1719.836 | B3: =G16 -> 856.541 | C3: =A3+B3 -> 2576.377 | D3: T24, 2022 & 2025 2019 Outdoor Lighting CASE report PNNL 90.1-2010 TSD
A7: ="Exterior Lighting" -> Exterior Lighting
A8: Items (Assume LZ2) | B8: Assumptions (2019 Outdoor Lighting CASE Report & PNNL 90.1-2010 TSD) | D8: Unit | E8: Lighting Power Allowance (T24, part 6, 2025, Table 140.7-A & 140.7-B) | F8: Unit | G8: Exterior Lighting Power (W)
A9: IWA (Initial Wattage Allowance) | E9: 200 | F9: (W) | G9: =$E9 -> 200
A10: Parking area | B10: 400 ft² for every parking space 1 parking space per 830 ft² of gross building area | C10: =B21/250*400 -> 85812.8 | D10: (ft²) | E10: 0.019 | F10: (W/ft²) | G10: =$E10*65520 -> 1244.88
A11: Building Entrance | B11: 14 building entrance per PNNL Model | C11: 2 | D11: (count) | E11: 15 | F11: (W/ea) | G11: =E11*C11 -> 30
A12: Hardscape Ornamental Light | B12: 0.1 ft² per 1 ft² of gross building area for hardscape ornamental light | C12: 5363 | D12: (ft²) | E12: 0.007 | F12: (W/ft²) | G12: =E12*C12 -> 37.541
A13: Building façade | B13: 0.1 W per 1 ft² of facade area Façade Area = Perimeter × 0.5 × 28 ft (30 ft is the max height that is lit) * The 0.5 factor assumes that only half of the perimeter walls are lit. -Formula ia developed based on the 2019 Outdoor Lighting CASE report | C13: =B22*0.5*30 -> 8190 | D13: (ft²) | E13: 0.1 | F13: (W/ft²) | G13: =E13*C13 -> 819
A14: Non-sales canopy | C14: 1788 | D14: (ft²) | E14: 0.137 | F14: (W/ft²) | G14: =E14*C14 -> 244.956
A15: Motion Controlled Luminaires (W) | G15: =G10+G9+G14+G11 -> 1719.836
A16: Non-motion-controlled Luminaires | G16: =G12+G13 -> 856.541
A17: Total | G17: =G15+G16 -> 2576.377
A21: Total floor area | B21: =Prototype!B8 -> 53633
A22: Perimeter | B22: 546
A23: Floors | B23: 3
A29: Background Data [To be deleted prior to publication]

Sheet Equipment
A1: ="Equipment - "&Prototype!B4 -> Equipment - Laboratory
A2: Spaces | B2: Plug load Intensity (W/ft²) | C2: Gas Power Density (Btu/hr-ft²) | D2: Refrigeration Power Density (W/ft²) | E2: Source | F2: Note
A3: =Ventilation!A56 -> Laboratory, Scientific | B3: 2 | C3: 13 | D3: 0.28 | E3: T24 2022 - Appendix 5.4A | F3: Appendix 5.4A: Gas equipment=13 Btu/h-ft²--CEC model (Lab) has the Gas equipment for 51 Btu/h-ft² and Refrig load for 0.28 w/ft²---CPUC supports this data
A4: =Ventilation!A57 -> Office Area (>250 square feet) | B4: 0.7 | F4: Plug load and schedules project with CEC, 2025
A5: =Zones!A6 -> Plenum | B5: 0
A9: Elevator
A10: Vintage | B10: No. of Elevators | C10: Cab Lighting Power Density (W/ft²) | D10: Lighting Shutoff | E10: Cab Fan Control | F10: Fan Power Limit (W/cfm) | G10: Regenerative Drive Threshold | H10: Design load (w) | I10: Note
A11: Existing | B11: =C19 -> 3 | C11: 1.65 | D11: n/a | E11: n/a | F11: n/a | G11: n/a | H11: =D29 -> 16488.22 | I11: Design Load based on PNNL ASHRAE 90.1 2013 Laboratory prototype
A12: New Construction | B12: =C19 -> 3 | C12: 0.6 | D12: Automatic shut‑off after ≤ 5 min no‑occupancy | E12: When the elevator cab is stopped and unoccupied with doors closed for over 15 minutes, the cab interior lighting and ventilation fans shall be switched off until elevator cab operation resumes. | F12: 0.33 | G12: n/a | H12: =B29 -> 8623.13 | I12: Design Load based on PNNL ASHRAE 90.1 2022 Laboratory prototype --- per T24 2025 §120.6 (f)---Cab Lighting power density is Exempt (covered process)
A15: Assumptions for elevators:
A16: One elevator for approximately 50,000 square feet in use.
A17: For every two floors or two and a half floors, one more elevator was added.
A18: An in-use rate of 70% for the floor area was assumed, based on engineering judgment.
A19: Calculated number of Elevators: | C19: =ROUND((Prototype!B8*0.7/50000)+ROUND(3/2,0),0) -> 3 | D19: Same as PNNL assumptions
A20: Calculate Elevator load (kw)based on ACM 2022: | C20: =C19*C21 -> 30
A21: ACM 2022 suggestion for elevator load (kw): | C21: 10
A22: Elevator load will be defined as exterior load not equipment load
A24: Elevator Load= Elevator Lift+ Elevator Light+Fan | B24: 2022 | C24: 2019 | D24: 2013
A25: Elevator Lift (W) | B25: 8517.82 | C25: 16363.22 | D25: 16363.22
A26: Elevator Fan | B26: 105.31 | C26: 125 | D26: 125
A27: Elevator Light | B27: 0.7 W/ft² | C27: 1.5 w/ft² | D27: 1.65 w/ft²
A29: based on PNNL ASHRAE 90.1 Office Medium prototype | B29: =B25+B26 -> 8623.13 | C29: =C25+C26 -> 16488.22 | D29: =D25+D26 -> 16488.22
A31: Background Data [To be deleted prior to publication]

Sheet Interior Lights
A1: ="Interior Lighting - "&Prototype!B4 -> Interior Lighting - Laboratory
A2: Space Type | B2: New Construction | E2: Existing
B3: Lighting density (W/ft²) | C3: Additional lighting power for porTable lighting (W/ft²) | D3: Source | E3: LPD (W/ft²) | F3: Additional LPD for PorTable Lighting (W/ft²) | G3: Source
A4: =Zones!A3 -> Laboratory, Scientific | B4: 0.9 | D4: T24, part 6, 2025, Table 140.6 C (Area category method) | E4: 1.4 | G4: T24, part 6, 2016, Table 140.6 C (Area category method)
A5: =Ventilation!A57 -> Office Area (>250 square feet) | B5: 0.6 | E5: 0.75
A6: =Zones!A6 -> Plenum | B6: 0 | E6: 0

Sheet Schedules
A1: ="Schedules - "&Prototype!B4 -> Schedules - Laboratory
A2: Zone | B2: Schedule | C2: Source | D2: Zone | E2: Type | F2: Hour
F3: 1 | G3: 2 | H3: 3 | I3: 4 | J3: 5 | K3: 6 | L3: 7 | M3: 8 | N3: 9 | O3: 10 | P3: 11 | Q3: 12 | R3: 13 | S3: 14 | T3: 15 | U3: 16 | V3: 17 | W3: 18 | X3: 19 | Y3: 20 | Z3: 21 | AA3: 22 | AB3: 23 | AC3: 24
A4: Level 2 and 3 Lab Zones | B4: Lab | C4: Occupancy | D4: T24 2022 - Appendix 5.4B, [Lab] | E4: Weekday | F4: 0.05 | G4: 0.05 | H4: 0.05 | I4: 0.05 | J4: 0.05 | K4: 0.05 | L4: 0.05 | M4: 0.1 | N4: 0.2 | O4: 0.9 | P4: 0.9 | Q4: 0.45 | R4: 0.45 | S4: 0.9 | T4: 0.9 | U4: 0.9 | V4: 0.9 | W4: 0.9 | X4: 0.3 | Y4: 0.1 | Z4: 0.1 | AA4: 0.1 | AB4: 0.05 | AC4: 0.05
E5: Saturday | F5: 0.05 | G5: 0.05 | H5: 0.05 | I5: 0.05 | J5: 0.05 | K5: 0.05 | L5: 0.05 | M5: 0.1 | N5: 0.1 | O5: 0.3 | P5: 0.3 | Q5: 0.3 | R5: 0.3 | S5: 0.1 | T5: 0.1 | U5: 0.1 | V5: 0.1 | W5: 0.1 | X5: 0.05 | Y5: 0.05 | Z5: 0.05 | AA5: 0.05 | AB5: 0.05 | AC5: 0.05
E6: Sunday | F6: 0.05 | G6: 0.05 | H6: 0.05 | I6: 0.05 | J6: 0.05 | K6: 0.05 | L6: 0.05 | M6: 0.1 | N6: 0.1 | O6: 0.3 | P6: 0.3 | Q6: 0.3 | R6: 0.3 | S6: 0.1 | T6: 0.1 | U6: 0.1 | V6: 0.1 | W6: 0.1 | X6: 0.05 | Y6: 0.05 | Z6: 0.05 | AA6: 0.05 | AB6: 0.05 | AC6: 0.05
A7: Level 2 and 3 Lab Zones | B7: Lab | C7: Lights | D7: T24 2022 - Appendix 5.4B, [Lab] | E7: Weekday | F7: 0.2 | G7: 0.2 | H7: 0.2 | I7: 0.2 | J7: 0.2 | K7: 0.2 | L7: 0.3 | M7: 0.5 | N7: 0.9 | O7: 0.9 | P7: 0.9 | Q7: 0.9 | R7: 0.8 | S7: 0.9 | T7: 0.9 | U7: 0.9 | V7: 0.9 | W7: 0.9 | X7: 0.5 | Y7: 0.5 | Z7: 0.3 | AA7: 0.3 | AB7: 0.2 | AC7: 0.2
E8: Saturday | F8: 0.1 | G8: 0.1 | H8: 0.1 | I8: 0.1 | J8: 0.1 | K8: 0.1 | L8: 0.1 | M8: 0.1 | N8: 0.4 | O8: 0.4 | P8: 0.4 | Q8: 0.4 | R8: 0.2 | S8: 0.2 | T8: 0.2 | U8: 0.2 | V8: 0.2 | W8: 0.1 | X8: 0.1 | Y8: 0.1 | Z8: 0.1 | AA8: 0.1 | AB8: 0.1 | AC8: 0.1
E9: Sunday | F9: 0.1 | G9: 0.1 | H9: 0.1 | I9: 0.1 | J9: 0.1 | K9: 0.1 | L9: 0.1 | M9: 0.1 | N9: 0.4 | O9: 0.4 | P9: 0.4 | Q9: 0.4 | R9: 0.2 | S9: 0.2 | T9: 0.2 | U9: 0.2 | V9: 0.2 | W9: 0.1 | X9: 0.1 | Y9: 0.1 | Z9: 0.1 | AA9: 0.1 | AB9: 0.1 | AC9: 0.1
A10: Level 2 and 3 Lab Zones | B10: Lab | C10: ElecEquipment | D10: T24 2022 - Appendix 5.4B, [Lab] | E10: Weekday | F10: 0.2 | G10: 0.2 | H10: 0.2 | I10: 0.2 | J10: 0.2 | K10: 0.2 | L10: 0.3 | M10: 0.4 | N10: 0.5 | O10: 0.7 | P10: 0.8 | Q10: 0.5 | R10: 0.6 | S10: 0.7 | T10: 0.9 | U10: 0.8 | V10: 0.5 | W10: 0.4 | X10: 0.3 | Y10: 0.2 | Z10: 0.2 | AA10: 0.2 | AB10: 0.2 | AC10: 0.2
E11: Saturday | F11: 0 | G11: 0 | H11: 0 | I11: 0 | J11: 0 | K11: 0 | L11: 0 | M11: 0 | N11: 0 | O11: 0 | P11: 0 | Q11: 0 | R11: 0 | S11: 0 | T11: 0 | U11: 0 | V11: 0 | W11: 0 | X11: 0 | Y11: 0 | Z11: 0 | AA11: 0 | AB11: 0 | AC11: 0
E12: Sunday | F12: 0 | G12: 0 | H12: 0 | I12: 0 | J12: 0 | K12: 0 | L12: 0 | M12: 0 | N12: 0 | O12: 0 | P12: 0 | Q12: 0 | R12: 0 | S12: 0 | T12: 0 | U12: 0 | V12: 0 | W12: 0 | X12: 0 | Y12: 0 | Z12: 0 | AA12: 0 | AB12: 0 | AC12: 0
A13: Level 2 and 3 Lab Zones | B13: Lab | C13: ServiceHotWater | D13: T24 2022 - Appendix 5.4B, [Lab] | E13: Weekday | F13: 0 | G13: 0 | H13: 0 | I13: 0 | J13: 0 | K13: 0 | L13: 0 | M13: 0 | N13: 0 | O13: 0 | P13: 0 | Q13: 0 | R13: 0 | S13: 0 | T13: 0 | U13: 0 | V13: 0 | W13: 0 | X13: 0 | Y13: 0 | Z13: 0 | AA13: 0 | AB13: 0 | AC13: 0
E14: Saturday | F14: 0 | G14: 0 | H14: 0 | I14: 0 | J14: 0 | K14: 0 | L14: 0 | M14: 0 | N14: 0 | O14: 0 | P14: 0 | Q14: 0 | R14: 0 | S14: 0 | T14: 0 | U14: 0 | V14: 0 | W14: 0 | X14: 0 | Y14: 0 | Z14: 0 | AA14: 0 | AB14: 0 | AC14: 0
E15: Sunday | F15: 0 | G15: 0 | H15: 0 | I15: 0 | J15: 0 | K15: 0 | L15: 0 | M15: 0 | N15: 0 | O15: 0 | P15: 0 | Q15: 0 | R15: 0 | S15: 0 | T15: 0 | U15: 0 | V15: 0 | W15: 0 | X15: 0 | Y15: 0 | Z15: 0 | AA15: 0 | AB15: 0 | AC15: 0
A16: Level 2 and 3 Lab Zones | B16: Lab | C16: GasEquipment | D16: T24 2022 - Appendix 5.4B, [Lab] | E16: Weekday | F16: 0 | G16: 0 | H16: 0 | I16: 0 | J16: 0 | K16: 0 | L16: 0 | M16: 0.1 | N16: 0.2 | O16: 0.9 | P16: 0.9 | Q16: 0.45 | R16: 0.45 | S16: 0.9 | T16: 0.9 | U16: 0.9 | V16: 0.9 | W16: 0.9 | X16: 0.1 | Y16: 0.1 | Z16: 0 | AA16: 0 | AB16: 0 | AC16: 0
E17: Saturday | F17: 0 | G17: 0 | H17: 0 | I17: 0 | J17: 0 | K17: 0 | L17: 0 | M17: 0.1 | N17: 0.1 | O17: 0.3 | P17: 0.3 | Q17: 0.3 | R17: 0.3 | S17: 0.1 | T17: 0.1 | U17: 0.1 | V17: 0.1 | W17: 0.1 | X17: 0 | Y17: 0 | Z17: 0 | AA17: 0 | AB17: 0 | AC17: 0
E18: Sunday | F18: 0 | G18: 0 | H18: 0 | I18: 0 | J18: 0 | K18: 0 | L18: 0 | M18: 0.1 | N18: 0.1 | O18: 0.3 | P18: 0.3 | Q18: 0.3 | R18: 0.3 | S18: 0.1 | T18: 0.1 | U18: 0.1 | V18: 0.1 | W18: 0.1 | X18: 0 | Y18: 0 | Z18: 0 | AA18: 0 | AB18: 0 | AC18: 0
A19: Level 2 and 3 Lab Zones | B19: Lab | C19: Refrigeration | D19: T24 2022 - Appendix 5.4B, [Lab] | E19: Weekday | F19: 0.9 | G19: 0.9 | H19: 0.9 | I19: 0.9 | J19: 0.9 | K19: 0.9 | L19: 0.9 | M19: 0.9 | N19: 0.9 | O19: 0.9 | P19: 0.9 | Q19: 0.9 | R19: 0.9 | S19: 0.9 | T19: 0.9 | U19: 0.9 | V19: 0.9 | W19: 0.9 | X19: 0.9 | Y19: 0.9 | Z19: 0.9 | AA19: 0.9 | AB19: 0.9 | AC19: 0.9
E20: Saturday | F20: 0.9 | G20: 0.9 | H20: 0.9 | I20: 0.9 | J20: 0.9 | K20: 0.9 | L20: 0.9 | M20: 0.9 | N20: 0.9 | O20: 0.9 | P20: 0.9 | Q20: 0.9 | R20: 0.9 | S20: 0.9 | T20: 0.9 | U20: 0.9 | V20: 0.9 | W20: 0.9 | X20: 0.9 | Y20: 0.9 | Z20: 0.9 | AA20: 0.9 | AB20: 0.9 | AC20: 0.9
E21: Sunday | F21: 0.9 | G21: 0.9 | H21: 0.9 | I21: 0.9 | J21: 0.9 | K21: 0.9 | L21: 0.9 | M21: 0.9 | N21: 0.9 | O21: 0.9 | P21: 0.9 | Q21: 0.9 | R21: 0.9 | S21: 0.9 | T21: 0.9 | U21: 0.9 | V21: 0.9 | W21: 0.9 | X21: 0.9 | Y21: 0.9 | Z21: 0.9 | AA21: 0.9 | AB21: 0.9 | AC21: 0.9
A22: Level 2 and 3 Lab Zones | B22: Lab | C22: Infiltration | D22: T24 2022 - Appendix 5.4B, [Lab] | E22: Weekday | F22: 0.25 | G22: 0.25 | H22: 0.25 | I22: 0.25 | J22: 0.25 | K22: 0.25 | L22: 0.25 | M22: 0.25 | N22: 0.25 | O22: 0.25 | P22: 0.25 | Q22: 0.25 | R22: 0.25 | S22: 0.25 | T22: 0.25 | U22: 0.25 | V22: 0.25 | W22: 0.25 | X22: 0.25 | Y22: 0.25 | Z22: 0.25 | AA22: 0.25 | AB22: 0.25 | AC22: 0.25
E23: Saturday | F23: 0.25 | G23: 0.25 | H23: 0.25 | I23: 0.25 | J23: 0.25 | K23: 0.25 | L23: 0.25 | M23: 0.25 | N23: 0.25 | O23: 0.25 | P23: 0.25 | Q23: 0.25 | R23: 0.25 | S23: 0.25 | T23: 0.25 | U23: 0.25 | V23: 0.25 | W23: 0.25 | X23: 0.25 | Y23: 0.25 | Z23: 0.25 | AA23: 0.25 | AB23: 0.25 | AC23: 0.25
E24: Sunday | F24: 0.25 | G24: 0.25 | H24: 0.25 | I24: 0.25 | J24: 0.25 | K24: 0.25 | L24: 0.25 | M24: 0.25 | N24: 0.25 | O24: 0.25 | P24: 0.25 | Q24: 0.25 | R24: 0.25 | S24: 0.25 | T24: 0.25 | U24: 0.25 | V24: 0.25 | W24: 0.25 | X24: 0.25 | Y24: 0.25 | Z24: 0.25 | AA24: 0.25 | AB24: 0.25 | AC24: 0.25
A25: Level 2 and 3 Lab Zones | B25: Lab | C25: HVACAvail | D25: T24 2022 - Appendix 5.4B, [Lab] | E25: Weekday | F25: 1 | G25: 1 | H25: 1 | I25: 1 | J25: 1 | K25: 1 | L25: 1 | M25: 1 | N25: 1 | O25: 1 | P25: 1 | Q25: 1 | R25: 1 | S25: 1 | T25: 1 | U25: 1 | V25: 1 | W25: 1 | X25: 1 | Y25: 1 | Z25: 1 | AA25: 1 | AB25: 1 | AC25: 1
E26: Saturday | F26: 1 | G26: 1 | H26: 1 | I26: 1 | J26: 1 | K26: 1 | L26: 1 | M26: 1 | N26: 1 | O26: 1 | P26: 1 | Q26: 1 | R26: 1 | S26: 1 | T26: 1 | U26: 1 | V26: 1 | W26: 1 | X26: 1 | Y26: 1 | Z26: 1 | AA26: 1 | AB26: 1 | AC26: 1
E27: Sunday | F27: 1 | G27: 1 | H27: 1 | I27: 1 | J27: 1 | K27: 1 | L27: 1 | M27: 1 | N27: 1 | O27: 1 | P27: 1 | Q27: 1 | R27: 1 | S27: 1 | T27: 1 | U27: 1 | V27: 1 | W27: 1 | X27: 1 | Y27: 1 | Z27: 1 | AA27: 1 | AB27: 1 | AC27: 1
A28: Level 2 and 3 Lab Zones | B28: Lab | C28: ExhaustCAV | D28: T24 2022 - Appendix 5.4B, [Lab] | E28: Weekday | F28: 0.9 | G28: 0.9 | H28: 0.9 | I28: 0.9 | J28: 0.9 | K28: 0.9 | L28: 0.9 | M28: 0.9 | N28: 0.9 | O28: 0.9 | P28: 0.9 | Q28: 0.9 | R28: 0.9 | S28: 0.9 | T28: 0.9 | U28: 0.9 | V28: 0.9 | W28: 0.9 | X28: 0.9 | Y28: 0.9 | Z28: 0.9 | AA28: 0.9 | AB28: 0.9 | AC28: 0.9
E29: Saturday | F29: 0.9 | G29: 0.9 | H29: 0.9 | I29: 0.9 | J29: 0.9 | K29: 0.9 | L29: 0.9 | M29: 0.9 | N29: 0.9 | O29: 0.9 | P29: 0.9 | Q29: 0.9 | R29: 0.9 | S29: 0.9 | T29: 0.9 | U29: 0.9 | V29: 0.9 | W29: 0.9 | X29: 0.9 | Y29: 0.9 | Z29: 0.9 | AA29: 0.9 | AB29: 0.9 | AC29: 0.9
E30: Sunday | F30: 0.9 | G30: 0.9 | H30: 0.9 | I30: 0.9 | J30: 0.9 | K30: 0.9 | L30: 0.9 | M30: 0.9 | N30: 0.9 | O30: 0.9 | P30: 0.9 | Q30: 0.9 | R30: 0.9 | S30: 0.9 | T30: 0.9 | U30: 0.9 | V30: 0.9 | W30: 0.9 | X30: 0.9 | Y30: 0.9 | Z30: 0.9 | AA30: 0.9 | AB30: 0.9 | AC30: 0.9
A31: Level 2 and 3 Lab Zones | B31: Lab | C31: ExhaustVAVManualSashCtrl | D31: T24 2022 - Appendix 5.4B, [Lab] | E31: Weekday | F31: 0.5 | G31: 0.5 | H31: 0.5 | I31: 0.5 | J31: 0.5 | K31: 0.5 | L31: 0.5 | M31: 0.5 | N31: 0.51 | O31: 0.56 | P31: 0.56 | Q31: 0.53 | R31: 0.53 | S31: 0.56 | T31: 0.56 | U31: 0.56 | V31: 0.56 | W31: 0.56 | X31: 0.52 | Y31: 0.5 | Z31: 0.5 | AA31: 0.5 | AB31: 0.5 | AC31: 0.5
E32: Saturday | F32: 0.5 | G32: 0.5 | H32: 0.5 | I32: 0.5 | J32: 0.5 | K32: 0.5 | L32: 0.5 | M32: 0.5 | N32: 0.5 | O32: 0.52 | P32: 0.52 | Q32: 0.52 | R32: 0.52 | S32: 0.5 | T32: 0.5 | U32: 0.5 | V32: 0.5 | W32: 0.5 | X32: 0.5 | Y32: 0.5 | Z32: 0.5 | AA32: 0.5 | AB32: 0.5 | AC32: 0.5
E33: Sunday | F33: 0.5 | G33: 0.5 | H33: 0.5 | I33: 0.5 | J33: 0.5 | K33: 0.5 | L33: 0.5 | M33: 0.5 | N33: 0.5 | O33: 0.52 | P33: 0.52 | Q33: 0.52 | R33: 0.52 | S33: 0.5 | T33: 0.5 | U33: 0.5 | V33: 0.5 | W33: 0.5 | X33: 0.5 | Y33: 0.5 | Z33: 0.5 | AA33: 0.5 | AB33: 0.5 | AC33: 0.5
A34: Level 2 and 3 Lab Zones | B34: Lab | C34: ExhaustVAVAutoSashCtrl | D34: T24 2022 - Appendix 5.4B, [Lab] | E34: Weekday | F34: 0.2 | G34: 0.2 | H34: 0.2 | I34: 0.2 | J34: 0.2 | K34: 0.2 | L34: 0.2 | M34: 0.21 | N34: 0.22 | O34: 0.33 | P34: 0.33 | Q34: 0.26 | R34: 0.26 | S34: 0.33 | T34: 0.33 | U34: 0.33 | V34: 0.33 | W34: 0.33 | X34: 0.24 | Y34: 0.21 | Z34: 0.21 | AA34: 0.21 | AB34: 0.2 | AC34: 0.2
E35: Saturday | F35: 0.2 | G35: 0.2 | H35: 0.2 | I35: 0.2 | J35: 0.2 | K35: 0.2 | L35: 0.2 | M35: 0.21 | N35: 0.21 | O35: 0.24 | P35: 0.24 | Q35: 0.24 | R35: 0.24 | S35: 0.21 | T35: 0.21 | U35: 0.21 | V35: 0.21 | W35: 0.21 | X35: 0.2 | Y35: 0.2 | Z35: 0.2 | AA35: 0.2 | AB35: 0.2 | AC35: 0.2
E36: Sunday | F36: 0.2 | G36: 0.2 | H36: 0.2 | I36: 0.2 | J36: 0.2 | K36: 0.2 | L36: 0.2 | M36: 0.21 | N36: 0.21 | O36: 0.24 | P36: 0.24 | Q36: 0.24 | R36: 0.24 | S36: 0.21 | T36: 0.21 | U36: 0.21 | V36: 0.21 | W36: 0.21 | X36: 0.2 | Y36: 0.2 | Z36: 0.2 | AA36: 0.2 | AB36: 0.2 | AC36: 0.2
A37: Office Zones | B37: Lab | C37: HtgSetpt | D37: T24 2022 - Appendix 5.4B, [Office] | E37: Weekday | F37: =IF(F25=1,Thermostat!$B$3,Thermostat!$B$4) -> 70 | G37: =IF(G25=1,Thermostat!$B$3,Thermostat!$B$4) -> 70 | H37: =IF(H25=1,Thermostat!$B$3,Thermostat!$B$4) -> 70 | I37: =IF(I25=1,Thermostat!$B$3,Thermostat!$B$4) -> 70 | J37: =IF(J25=1,Thermostat!$B$3,Thermostat!$B$4) -> 70 | K37: =IF(K25=1,Thermostat!$B$3,Thermostat!$B$4) -> 70 | L37: =IF(L25=1,Thermostat!$B$3,Thermostat!$B$4) -> 70 | M37: =IF(M25=1,Thermostat!$B$3,Thermostat!$B$4) -> 70 | ... AC37: =IF(AC25=1,Thermostat!$B$3,Thermostat!$B$4) -> 70
E38: Saturday | F38: =IF(F26=1,Thermostat!$B$3,Thermostat!$B$4) -> 70 | G38: =IF(G26=1,Thermostat!$B$3,Thermostat!$B$4) -> 70 | H38: =IF(H26=1,Thermostat!$B$3,Thermostat!$B$4) -> 70 | I38: =IF(I26=1,Thermostat!$B$3,Thermostat!$B$4) -> 70 | J38: =IF(J26=1,Thermostat!$B$3,Thermostat!$B$4) -> 70 | K38: =IF(K26=1,Thermostat!$B$3,Thermostat!$B$4) -> 70 | L38: =IF(L26=1,Thermostat!$B$3,Thermostat!$B$4) -> 70 | M38: =IF(M26=1,Thermostat!$B$3,Thermostat!$B$4) -> 70 | ... AC38: =IF(AC26=1,Thermostat!$B$3,Thermostat!$B$4) -> 70
E39: Sunday | F39: =IF(F27=1,Thermostat!$B$3,Thermostat!$B$4) -> 70 | G39: =IF(G27=1,Thermostat!$B$3,Thermostat!$B$4) -> 70 | H39: =IF(H27=1,Thermostat!$B$3,Thermostat!$B$4) -> 70 | I39: =IF(I27=1,Thermostat!$B$3,Thermostat!$B$4) -> 70 | J39: =IF(J27=1,Thermostat!$B$3,Thermostat!$B$4) -> 70 | K39: =IF(K27=1,Thermostat!$B$3,Thermostat!$B$4) -> 70 | L39: =IF(L27=1,Thermostat!$B$3,Thermostat!$B$4) -> 70 | M39: =IF(M27=1,Thermostat!$B$3,Thermostat!$B$4) -> 70 | ... AC39: =IF(AC27=1,Thermostat!$B$3,Thermostat!$B$4) -> 70
A40: Office Zones | B40: Lab | C40: ClgSetpt | D40: T24 2022 - Appendix 5.4B, [Office] | E40: Weekday | F40: =IF(F25=1,Thermostat!$B$5,Thermostat!$B$6) -> 75 | G40: =IF(G25=1,Thermostat!$B$5,Thermostat!$B$6) -> 75 | H40: =IF(H25=1,Thermostat!$B$5,Thermostat!$B$6) -> 75 | I40: =IF(I25=1,Thermostat!$B$5,Thermostat!$B$6) -> 75 | J40: =IF(J25=1,Thermostat!$B$5,Thermostat!$B$6) -> 75 | K40: =IF(K25=1,Thermostat!$B$5,Thermostat!$B$6) -> 75 | L40: =IF(L25=1,Thermostat!$B$5,Thermostat!$B$6) -> 75 | M40: =IF(M25=1,Thermostat!$B$5,Thermostat!$B$6) -> 75 | ... AC40: =IF(AC25=1,Thermostat!$B$5,Thermostat!$B$6) -> 75
...

Sheet Energy Usage
A1: CalBEM Energy Consumption - Laboratory | O1: ="Energy Consumption - "&Prototype!A2 -> Energy Consumption - Laboratory
A2: Prototype | B2: CZ | C2: CalBEM Electricity EUI (KBTU/ft²) | D2: CalBEM Gas EUI (KBTU/ft²) | E2: CalBEM Total EUI (KBTU/ft²) | F2: New Construction Electricity EUI (KBTU/ft²) | G2: New Construction Gas EUI (KBTU/ft²) | H2: New Construction Total EUI (KBTU/ft²) | I2: National Average | J2: Acceptable Range (25% Higher) | K2: Acceptable Range (25% Lower) | L2: National Average Acceptable EUI Range | O2: Prototype | P2: CZ | Q2: Total Floorspace (Thousand of ft²) | R2: CEUS 2023 Electricity EUI (kBtu/ft²) | S2: CEUS 2023 Gas EUI (kBtu/ft²) | T2: CEUS 2023 Total EUI (kBtu/ft²) | U2: Acceptable Range (20% Higher) | V2: Acceptable Range (20% Lower) | W2: CEUS 2022 Acceptable EUI Range
A3: Laboratory | B3: 1 | C3: 53.8575 | D3: 70.1975 | E3: 124.055 | F3: 53.56 | G3: 23.04 | H3: 76.6 | I3: 135.3 | J3: =(I3*1.25) -> 169.125 | K3: =(I3*0.75) -> 101.475 | L3: =J3-K3 -> 67.65 | O3: =A3 -> Laboratory | P3: 1 | U3: =T3*1.2 -> 0 | V3: =T3*0.8 -> 0 | W3: =U3-V3 -> 0
B4: 2 | C4: 60.3 | D4: 62.895 | E4: 123.195 | F4: 58.43 | G4: 22.57 | H4: 81 | I4: 135.3 | J4: =(I4*1.25) -> 169.125 | K4: =(I4*0.75) -> 101.475 | L4: =J4-K4 -> 67.65 | P4: 2 | U4: =T4*1.2 -> 0 | V4: =T4*0.8 -> 0 | W4: =U4-V4 -> 0
B5: 3 | C5: 58.4125 | D5: 52.9175 | E5: 111.33 | F5: 53.43 | G5: 22.21 | H5: 75.64 | I5: 135.3 | J5: =(I5*1.25) -> 169.125 | K5: =(I5*0.75) -> 101.475 | L5: =J5-K5 -> 67.65 | P5: 3 | U5: =T5*1.2 -> 0 | V5: =T5*0.8 -> 0 | W5: =U5-V5 -> 0
B6: 4 | C6: 64.845 | D6: 59.3725 | E6: 124.2175 | F6: 62.68 | G6: 22.39 | H6: 85.07 | I6: 135.3 | J6: =(I6*1.25) -> 169.125 | K6: =(I6*0.75) -> 101.475 | L6: =J6-K6 -> 67.65 | P6: 4 | U6: =T6*1.2 -> 0 | V6: =T6*0.8 -> 0 | W6: =U6-V6 -> 0
B7: 5 | C7: 58.9725 | D7: 55.7775 | E7: 114.75 | F7: 54.53 | G7: 21.88 | H7: 76.41 | I7: 135.3 | J7: =(I7*1.25) -> 169.125 | K7: =(I7*0.75) -> 101.475 | L7: =J7-K7 -> 67.65 | P7: 5 | U7: =T7*1.2 -> 0 | V7: =T7*0.8 -> 0 | W7: =U7-V7 -> 0
B8: 6 | C8: 64.785 | D8: 39.7125 | E8: 104.4975 | F8: 55.44 | G8: 21.23 | H8: 76.67 | I8: 135.3 | J8: =(I8*1.25) -> 169.125 | K8: =(I8*0.75) -> 101.475 | L8: =J8-K8 -> 67.65 | P8: 6 | U8: =T8*1.2 -> 0 | V8: =T8*0.8 -> 0 | W8: =U8-V8 -> 0
B9: 7 | C9: 65.2925 | D9: 38.7675 | E9: 104.06 | F9: 55.62 | G9: 21.15 | H9: 76.77 | I9: 135.3 | J9: =(I9*1.25) -> 169.125 | K9: =(I9*0.75) -> 101.475 | L9: =J9-K9 -> 67.65 | P9: 7 | U9: =T9*1.2 -> 0 | V9: =T9*0.8 -> 0 | W9: =U9-V9 -> 0
B10: 8 | C10: 68.7675 | D10: 41.7525 | E10: 110.52 | F10: 60.21 | G10: 21.33 | H10: 81.54 | I10: 135.3 | J10: =(I10*1.25) -> 169.125 | K10: =(I10*0.75) -> 101.475 | L10: =J10-K10 -> 67.65 | P10: 8 | U10: =T10*1.2 -> 0 | V10: =T10*0.8 -> 0 | W10: =U10-V10 -> 0
B11: 9 | C11: 68.185 | D11: 43.0275 | E11: 111.2125 | F11: 60.35 | G11: 21.45 | H11: 81.8 | I11: 135.3 | J11: =(I11*1.25) -> 169.125 | K11: =(I11*0.75) -> 101.475 | L11: =J11-K11 -> 67.65 | P11: 9 | U11: =T11*1.2 -> 0 | V11: =T11*0.8 -> 0 | W11: =U11-V11 -> 0
B12: 10 | C12: 69.5925 | D12: 43.5075 | E12: 113.1 | F12: 62.98 | G12: 21.49 | H12: 84.47 | I12: 135.3 | J12: =(I12*1.25) -> 169.125 | K12: =(I12*0.75) -> 101.475 | L12: =J12-K12 -> 67.65 | P12: 10 | U12: =T12*1.2 -> 0 | V12: =T12*0.8 -> 0 | W12: =U12-V12 -> 0
B13: 11 | C13: 69.5675 | D13: 56.075 | E13: 125.6425 | F13: 65.31 | G13: 22.97 | H13: 88.28 | I13: 135.3 | J13: =(I13*1.25) -> 169.125 | K13: =(I13*0.75) -> 101.475 | L13: =J13-K13 -> 67.65 | P13: 11 | U13: =T13*1.2 -> 0 | V13: =T13*0.8 -> 0 | W13: =U13-V13 -> 0
B14: 12 | C14: 64.3525 | D14: 56.4075 | E14: 120.76 | F14: 60.78 | G14: 22.46 | H14: 83.24 | I14: 135.3 | J14: =(I14*1.25) -> 169.125 | K14: =(I14*0.75) -> 101.475 | L14: =J14-K14 -> 67.65 | P14: 12 | U14: =T14*1.2 -> 0 | V14: =T14*0.8 -> 0 | W14: =U14-V14 -> 0
B15: 13 | C15: 70.1525 | D15: 50.3725 | E15: 120.525 | F15: 65.49 | G15: 22.32 | H15: 87.81 | I15: 135.3 | J15: =(I15*1.25) -> 169.125 | K15: =(I15*0.75) -> 101.475 | L15: =J15-K15 -> 67.65 | P15: 13 | U15: =T15*1.2 -> 0 | V15: =T15*0.8 -> 0 | W15: =U15-V15 -> 0
... B18: 16 | C18: 59.1625 | D18: 66.8025 | E18: 125.965 | F18: 67.03 | G18: 23.99 | H18: 91.02 | I18: 135.3 | J18: =(I18*1.25) -> 169.125 | K18: =(I18*0.75) -> 101.475 | L18: =J18-K18 -> 67.65 | P18: 16 | U18: =T18*1.2 -> 0 | V18: =T18*0.8 -> 0 | W18: =U18-V18 -> 0
O20: Ref: CEUS 2022 Report
O21: And converted FZ level data to CZ level
O22: CEUS has only one category for healthcare.

Sheet Weights
A1: ="% of Floor Area per CZ and Vintage Bin - "&Prototype!A2 -> % of Floor Area per CZ and Vintage Bin - Laboratory | J1: ="% of Floor Area per CZ and Vintage Bin - "&Prototype!A2 -> % of Floor Area per CZ and Vintage Bin - Laboratory
A2: Prototype | B2: CZ | C2: Vintage Bin | J2: Prototype | K2: Vintage Bin | L2: CZ
C3: Pre-1978 | D3: 1978-1997 | E3: 1998-2007 | F3: 2008-2018 | G3: Not available | L3: 1 | M3: 2 | N3: 3 | O3: 4 | P3: 5 | Q3: 6 | R3: 7 | S3: 8 | T3: 9 | U3: 10 | V3: 11 | W3: 12 | X3: 13 | Y3: 14 | Z3: 15 | AA3: 16
A4: =Prototype!B4 -> Laboratory | B4: 1 | H4: =SUM(C4:G4) -> 0 | J4: =Prototype!B4 -> Laboratory | K4: Pre-1978 | AB4: =SUM(L4:AA4) -> 0
B5: 2 | H5: =SUM(C5:G5) -> 0 | K5: 1978-1997 | AB5: =SUM(L5:AA5) -> 0
B6: 3 | H6: =SUM(C6:G6) -> 0 | K6: 1998-2007 | AB6: =SUM(L6:AA6) -> 0
B7: 4 | H7: =SUM(C7:G7) -> 0 | K7: 2008-2018 | AB7: =SUM(L7:AA7) -> 0
B8: 5 | H8: =SUM(C8:G8) -> 0 | K8: Not available | AB8: =SUM(L8:AA8) -> 0
B9: 6 | H9: =SUM(C9:G9) -> 0 | K9: Total
B10: 7 | H10: =SUM(C10:G10) -> 0
B11: 8 | H11: =SUM(C11:G11) -> 0
B12: 9 | H12: =SUM(C12:G12) -> 0
B13: 10 | H13: =SUM(C13:G13) -> 0
B14: 11 | H14: =SUM(C14:G14) -> 0
B15: 12 | H15: =SUM(C15:G15) -> 0
B16: 13 | H16: =SUM(C16:G16) -> 0
B17: 14 | H17: =SUM(C17:G17) -> 0
B18: 15 | H18: =SUM(C18:G18) -> 0
B19: 16 | H19: =SUM(C19:G19) -> 0
B20: Statewide
A22: Ref: CEUS 2022 dataset
A29: Background Data [To be deleted prior to publication]

Sheet PV
A1: ="PV - "&Prototype!B4 -> PV - Laboratory
A2: TBD

Sheet EV Charger
A1: ="EV Charger - "&Prototype!B4 -> EV Charger - Laboratory
A2: TBD
A11: Background Data [To be deleted prior to publication]

Sheet Data
A1: Space Function | B1: Exhaust Required? | C1: Electric Equipment Load Intensity | D1: Electric Equipment Load Intensity | E1: LPD
A2: Aging Eye/Low-vision (Corridor Area) | E2: 2013 | F2: 2016 | G2: 2019 | H2: 2025
A3: Aging Eye/Low-vision (Dining)
A4: Aging Eye/Low-vision (Lobby, Main Entry)
A5: Aging Eye/Low-vision (Lounge/Waiting Area)
A6: Aging Eye/Low-vision (Multipurpose Room)
A7: Aging Eye/Low-vision (Religious Worship Area)
A8: Aging Eye/Low-vision (Restroom)
A9: Aging Eye/Low-vision (Stairwell)
A10: Audience Seating Area
A11: Auditorium Area
A12: Auto Repair / Maintenance Area
A13: Barber, Beauty Salon, Spa Area
A14: Civic Meeting Place Area
... A17: Convention, Conference, Multipurpose and Meeting Area
A18: Copy Room | B18: Yes
A19: Corridor Area
A20: Dining Area (Bar/Lounge and Fine Dining)
A21: Dining Area (Cafeteria/Fast Food)
A22: Dining Area (Family and Leisure)
A23: Electrical, Mechanical, Telephone Rooms
A24: Exercise/Fitness Center and Gymnasium Areas
A25: Financial Transaction Area
A26: Healthcare Facility and Hospitals (Exam/Treatment Room)
A27: Healthcare Facility and Hospitals (Imaging Room)
A28: Healthcare Facility and Hospitals (Medical Supply Room)
A29: Healthcare Facility and Hospitals (Nursery)
A30: Healthcare Facility and Hospitals (Nurse's Station)
... A35: Hotel Function Area
A36: Kitchen/Food Preparation Area | B36: Yes
A37: Kitchenette or Residential Kitchen | B37: Yes
A38: Laboratory, Scientific | B38: Yes
A39: Laundry Area | B39: Yes
A40: Library (Reading Area)
A41: Library (Stacks Area)
A42: Lobby, Main Entry
A43: Locker Room | B43: Yes
A44: Lounge, Breakroom, or Waiting Area
A45: Manufacturing, Commercial & Industrial Work Area (Low Bay)
A46: Manufacturing, Commercial & Industrial Work Area (High Bay)
...
