Workbook
Name nonparticipating_forecastzone_scale_factor: 'Energy Usage'!#REF!
Name Space_Function: Data!$A$2:$A$76

Sheet Comments
A1: Comments | B1: By | C1: Date | D1: Action
A2: How about considering punched windows not one large window? | B2: Liam Buckley | C2: TAG meeting 2/24/2025 | D2: There is other improvement we can apply to our models that could have a greater impact than replacing ribbon window with punched windows. For example, more accurate schedules. Additionally, many medium/large office buildings have already been constructed with ribbon windows, making them a common feature in these types of buildings. We reviewed some of the Comstock models and found that they are also developed with ribbon windows.
A3: It's more realistic to seperate corner zones and assined them with their own CAV system ( for vintage 1&2) or with VAV | B3: Liam Buckley | C3: TAG meeting 2/24/2025 | D3: We will investigate the impact of separating corner spaces after completing the development of the first set of medium office prototypes in CZ12. We are considering two options : - Separating corner parts of the perimeter closed office zones at the west-south and east-south corners and defining them as new corner zones. - Dividing conference spaces into two and relocating them to the corners, then defining them as separate zones."
A4: conference spaces are expected to have different schedules than office spaces | B4: ? | C4: TAG meeting 2/24/2025
A9: Considering two enterance for the Medium Office prototype
A10: generating a set of dynamic occupancy schedules to bring random variations to the occupancy schedules. The Occupancy Simulator developed by Lawrence Berkeley National Laboratory (Chen et al. 2018) can be used to generate the dynamic and stochastic occupancy schedules | D10: https://publications.ibpsa.org/proceedings/simbuild/2020/papers/simbuild2020_C064.pdf
A11: Add Schedule for IT room

Sheet Notes
A1: Data Sources
A2: Dataset | B2: Dodge 2023
B3: CEUS 2022 | C3: https://www.energy.ca.gov/publications/2023/2022-california-commercial-end-use-survey-ceus-final-report
B4: CBECS 2018 | C4: https://www.eia.gov/consumption/commercial/data/2018/index.php?view=microdata
B5: Comstock 2023 | C5: https://data.openei.org/s3_viewer?bucket=oedi-data-lake&prefix=nrel-pds-building-stock%2Fend-use-load-profiles-for-us-building-stock%2F2023%2Fcomstock_amy2018_release_2%2Fmetadata_and_annual_results%2Fby_state%2Fstate%3DCA%2F
A6: Prototype | B6: CEC Medium Office prototype (CBECC 2022.3.1) | C6: https://bees.noresco.com/software2022.html
B7: PNNL Medium Office prototype (90.1-2022) | C7: https://www.energycodes.gov/prototype-building-models#Commercial
B8: DEER Large Office prototype (June 2023) | C8: https://github.com/sound-data/DEER-Prototypes-EnergyPlus
B9: ORNL 2019 Medium Office prototype zoning | C9: https://web.eecs.utk.edu/~jnew1/publications/2019_IBPSA_OpenStudioOffice.pdf
A10: Codes | B10: Title 24, part 6, referred to as T24 (1984, 2001, 2008, 2010, 2013, 2022, 2025)
B11: ASHRAE 90.1 (2022)
B12: CFR Title 10 ( 2024) | C12: https://www.govinfo.gov/content/pkg/CFR-2024-title10-vol3/pdf/CFR-2024-title10-vol3-part431-subpartF.pdf
A13: Others | B13: ACM (2022)
B14: Title 24, 2022 - Appendix 5.4A and Appendix 5.4B | C14: https://www.energy.ca.gov/publications/2022/2022-nonresidential-and-multifamily-alternative-calculation-method-reference
B15: 2022 Reduced infiltration CASE report | C15: https://title24stakeholders.com/wp-content/uploads/2020/10/2022-T24-Final-CASE-Report_Reduce-Infiltration.pdf
B16: 2019 Outdoor Lighting CASE Report | C16: https://title24stakeholders.com/wp-content/uploads/2016/10/T24-2019-CASE-Study-Results-Report-Outdoor-Sources_Final_with-Attachments.pdf
B17: PNNL 20405, 2010 | C17: https://www.pnnl.gov/main/publications/external/technical_reports/PNNL-20405.pdf
B18: Air leakage Memo, NORESCO, 2025 | C18: Infiltration_rate_report_14May2025-Short-Version.docx
B19: Proposed Updates to Equipment Power Densities and Building Schedules for the 2028 Energy Code, referred to as "Plug load and schedules project with CEC, 2025" (Docket Number =25-BSTD-03 & TN=265693) | C19: https://efiling.energy.ca.gov/GetDocument.aspx?tn=265693&DocumentContentId=102545
A22: Construction Rate
A35: Notes
B36: Saturation is defined as the % of total floorspace for each combination of end-use and fuel-type. | F36: 1978-84 | G36: 1985-97 | H36: 1992-1997
A37: 1986 is the representative year for the 1984-1997 vintage bin | B37: Most medium offices in this vintage bin were built after 1984 (more than 54% ) and the CA energy code did not noticeably changed between 1984 to 1992) . Edition 1986 included 6 prescriptive packages per CZ for office buildings compared to 1984 with 3 packages per CZ. Also "Heat Capacity" for external wall is considered between 10.0 to 14.99 (BTU/F/ft2) Package A was selected for the thermal properties Medium office was considered as low rise office | E37: Construction rate (Dodge 2023 data for new medium offices) | F37: 0.46189629 | G37: 0.53810371 | H37: 0.12391054
A38: 2001 is the representative year for the 1998-2007 vintage bin | B38: Wall and roof prescriptive criteria from 1998 to 2005 remain unchanged except for CZ2 and 6 in 2001 version (the percentage of change is less than 10%). Since the construction rate between 1998-2005 is greater than the 2006-2007 period, the envelope properties of 1998 -2005 were chosen for envelope properties. The windows requirement considerably changed in the 2001 code and makes this year (2001) as the nominated year for this vintage. It should be noticed that, only one Title 24 should be chosen within each vintage bin for building envelope properties since the entire envelope is built at once. We can't choose 1998 for walls and 2001 for windows. Wall and roof prescriptive criteria from 1998 to 2005 remain unchanged except for CZ2 and 6 in 2001 version (the percentage of change is less than 10%).
A39: 2013 is the representative year for the 2008-2018 vintage bin | B39: Wall properties remain unchanged from the 2008 code to the 2016 code but the roof did changed. Although the 2016 code introduced improvement for roof in nearly all CZ and for wall in a few CZ, and construction activity surged between 2017 and 2018, the extende period from 2008 to 2016 resulted in a higher construction rate during that time . As a result, it was decided to select the code that was effective during 2008-2016. The 2013 code modified the solar reflectance requirement for low-sloped roof products ( by approximately 15%), and enhanced window properties. Therefore, the 2013 code was chosen as the representative code. Additionally, construction activity from 2014-2018 was higher compared to 2008-2013 period.

Sheet Prototype
A1: NORESCO, Updated November 2025
A2: OfficeMedium
A3: Characteristic | B3: Value | C3: Data Sources
A4: Building Type | B4: Medium Office
A5: Building Category | B5: Nonresidential
A6: Vintages | B6: 4 Vintages: Pre-1978 , 1978-1997 ,1998-2007 , 2008-2018 New Construction (2019+) | C6: Based on vintage bin analysis | D6: NonRes-Vintage bins-Draft Report-30Nov2023-Final.docx
A7: Shape | C7: Rectangular shape is supported by CBECS, CEC, and PNNL
A8: Total Floor Area (ft2) | B8: 53,628 (163.7 ft x 109.2 ft) | C8: Supported by Dodge 2023 data (Same as CEC and PNNL)
A9: Aspect Ratio | B9: 1.5 | C9: Same as CEC and PNNL
A10: Number of Floors | B10: 3 | C10: Supported by Dodge 2023 data (Same as CEC and PNNL) DEER doesn't offer medium office prototype
A11: Roof type | B11: Flat | C11: Supported by CBECS 2018 data (Same as CEC and PNNL)
A12: Window dimensions | B12: 33% (Window Dimensions: 163.8 ft x 4.29 ft on the long side of facade 109.2 ft x 4.29 ft on the short side of the façade) | C12: Same as CEC and PNNL CBECS: 26-50% Comstock:11-25% CEC prototype: 33% same as PNNL DEER: 33% for Large Office prototype
A13: Shading Geometry | B13: No Shades | C13: Same as CEC and PNNL
A14: Floor to floor height (feet) | B14: 13 | C14: Same as CEC and PNNL
A15: Floor to ceiling height (feet) | B15: 9 (4 ft above-ceiling plenum) | C15: Same as CEC and PNNL
A16: Glazing sill height (feet) | B16: 3.35 ft (top of the window is 7.64 ft high with 4.29 ft high glass) | C16: Same as CEC and PNNL

Sheet Zones
A1: Proposed OfficeMedium | N1: Layout
A2: Space/Thermal Zone | B2: Space Type | C2: HVAC System Name/AHU Name | D2: Schedule Category | E2: Conditioned (Y/N) | F2: Area Fraction | G2: Area (ft²) | H2: Volume (ft³) | I2: Multipliers | J2: Number of People | K2: People (Persons/1,000 ft²) [T24, 2025,Table 120.1-A] | L2: Note
A3: Open_Office_Core_FloorG | B3: Office Area (>250 square feet) | D3: Office | E3: Yes | F3: =G3/$G$57 -> 0.079864791 | G3: 4283 | H3: =G3*9 -> 38547 | I3: 1 | J3: =K3*G3/1000 -> 21.415 | K3: 5
A4: Open_Office_N_FloorG | B4: Office Area (>250 square feet) | D4: Office | E4: Yes | F4: =G4/$G$57 -> 0.042850403 | G4: 2297.9873 | H4: =G4*9 -> 20681.886 | I4: 1 | J4: =K4*G4/1000 -> 11.489937 | K4: 5
A5: Closed_Office_W_FloorG | B5: Office Area (>250 square feet) | D5: Office | E5: Yes | F5: =G5/$G$57 -> 0.030541079 | G5: 1637.8612 | H5: =G5*9 -> 14740.75 | I5: 1 | J5: =K5*G5/1000 -> 8.1893058 | K5: 5
A6: Closed_Office_E_FloorG | B6: Office Area (>250 square feet) | D6: Office | E6: Yes | F6: =G6/$G$57 -> 0.030541079 | G6: 1637.8612 | H6: =G6*9 -> 14740.75 | I6: 1 | J6: =K6*G6/1000 -> 8.1893058 | K6: 5
A7: Open_Office_S_FloorG | B7: Office Area (>250 square feet) | D7: Office | E7: Yes | F7: =G7/$G$57 -> 0.022119126 | G7: 1186.2075 | H7: =G7*9 -> 10675.868 | I7: 1 | J7: =K7*G7/1000 -> 5.9310376 | K7: 5
A8: Conference_FloorG | B8: Convention, Conference, Multipurpose and Meeting Area | D8: Office | E8: Yes | F8: =G8/$G$57 -> 0.020731278 | G8: 1111.7798 | H8: =G8*9 -> 10006.018 | I8: 1 | J8: =K8*G8/1000 -> 36.688734 | K8: 33 | L8: Number of People: ORNL: 54, T24:33
A9: Lobby/Lounge_FloorG | B9: Lobby, Main Entry | D9: Office | E9: Yes | F9: =G9/$G$57 -> 0.019750368 | G9: 1059.1755 | H9: =G9*9 -> 9532.5792 | I9: 1 | J9: =K9*G9/1000 -> 10.591755 | K9: 10 | L9: People: 10 according to ASHRAE 62.1 Table 6-1 for main entry lobbies T24: 33 for main Entry lobbies & 5 for reception area
A10: Storage_FloorG | B10: Storage (General) | D10: Office | E10: Yes | F10: =G10/$G$57 -> 0.018332841 | G10: 983.15611 | H10: =G10*9 -> 8848.405 | I10: 1 | K10: -
A11: Mechanical/Electrical_FloorG | B11: Electrical, Mechanical, Telephone Rooms | D11: Office | E11: Yes | F11: =G11/$G$57 -> 0.006663486 | G11: 357.35034 | H11: =G11*9 -> 3216.1531 | I11: 1 | K11: -
A12: IT-Room_FloorG | B12: IT Room (EPD 12) | D12: Data | E12: Yes | F12: =G12/$G$57 -> 0.0033366309 | G12: 178.9373 | H12: =G12*9 -> 1610.4357 | I12: 1 | J12: ? | K12: -
A13: Restroom_FloorG | B13: Restrooms | D13: Office | E13: Yes | F13: =G13/$G$57 -> 0.012000749 | G13: 643.57783 | H13: =G13*9 -> 5792.2004 | I13: 1 | K13: -
A14: Break_FloorG | B14: Lounge, Breakroom, or Waiting Area | D14: Office | E14: Yes | F14: =G14/$G$57 -> 0.0043324823 | G14: 232.34295 | H14: =G14*9 -> 2091.0866 | I14: 1 | J14: =K14*G14/1000 -> 7.6673175 | K14: 33 | L14: Number of People: T24: 33 for Breakroom
A15: Stairway_FloorG | B15: Stairwell | D15: Office | E15: Yes | F15: =G15/$G$57 -> 0.012332934 | G15: 661.39226 | H15: =G15*9 -> 5952.5303 | I15: 1 | K15: -
A16: Corridor_W_FloorG | B16: Corridor Area | D16: Office | E16: Yes | F16: =G16/$G$57 -> 0.0055940783 | G16: 300 | H16: =G16*9 -> 2700 | I16: 1 | J16: =K16*G16/1000 -> 1.5 | K16: 5
A17: Corridor_N_FloorG | B17: Corridor Area | D17: Office | E17: Yes | F17: =G17/$G$57 -> 0.00937889 | G17: 502.9724 | H17: =G17*9 -> 4526.7516 | I17: 1 | J17: =K17*G17/1000 -> 2.514862 | K17: 5 | N17: Layout of Spaces | O17: Spaces
A18: Corridor_E_FloorG | B18: Corridor Area | D18: Office | E18: Yes | F18: =G18/$G$57 -> 0.0055793025 | G18: 299.2076 | H18: =G18*9 -> 2692.8684 | I18: 1 | J18: =K18*G18/1000 -> 1.496038 | K18: 5
A19: Corridor_S_FloorG | B19: Corridor Area | D19: Office | E19: Yes | F19: =G19/$G$57 -> 0.00937889 | G19: 502.9724 | H19: =G19*9 -> 4526.7516 | I19: 1 | J19: =K19*G19/1000 -> 2.514862 | K19: 5
A20: Plenum_FloorG | B20: Plenum | D20: Office | E20: No | G20: 17875.932 | H20: =G20*4 -> 71503.73 | I20: 1 | K20: -
A21: =LEFT(A3,LEN(A3)-1)&"M" -> Open_Office_Core_FloorM | B21: Office Area (>250 square feet) | D21: Office | E21: =E3 -> Yes | F21: =G21/$G$57 -> 0.079864791 | G21: 4283 | H21: =H3 -> 38547 | I21: =I3 -> 1 | J21: =K21*G21/1000 -> 21.415 | K21: =K3 -> 5
A22: =LEFT(A4,LEN(A4)-1)&"M" -> Open_Office_N_FloorM | B22: Office Area (>250 square feet) | D22: Office | E22: =E4 -> Yes | F22: =G22/$G$57 -> 0.042850403 | G22: 2297.9873 | H22: =H4 -> 20681.886 | I22: =I4 -> 1 | J22: =K22*G22/1000 -> 11.489937 | K22: =K4 -> 5
A23: =LEFT(A5,LEN(A5)-1)&"M" -> Closed_Office_W_FloorM | B23: Office Area (>250 square feet) | D23: Office | E23: =E5 -> Yes | F23: =G23/$G$57 -> 0.030541079 | G23: 1637.8612 | H23: =H5 -> 14740.75 | I23: =I5 -> 1 | J23: =K23*G23/1000 -> 8.1893058 | K23: =K5 -> 5
A24: =LEFT(A6,LEN(A6)-1)&"M" -> Closed_Office_E_FloorM | B24: Office Area (>250 square feet) | D24: Office | E24: =E6 -> Yes | F24: =G24/$G$57 -> 0.030541079 | G24: 1637.8612 | H24: =H6 -> 14740.75 | I24: =I6 -> 1 | J24: =K24*G24/1000 -> 8.1893058 | K24: =K6 -> 5
A25: =LEFT(A7,LEN(A7)-1)&"M" -> Open_Office_S_FloorM | B25: Office Area (>250 square feet) | D25: Office | E25: =E7 -> Yes | F25: =G25/$G$57 -> 0.022119126 | G25: 1186.2075 | H25: =H7 -> 10675.868 | I25: =I7 -> 1 | J25: =K25*G25/1000 -> 5.9310376 | K25: =K7 -> 5
A26: =LEFT(A8,LEN(A8)-1)&"M" -> Conference_FloorM | B26: Convention, Conference, Multipurpose and Meeting Area | D26: Office | E26: =E8 -> Yes | F26: =G26/$G$57 -> 0.020731278 | G26: 1111.7798 | H26: =H8 -> 10006.018 | I26: =I8 -> 1 | J26: =K26*G26/1000 -> 36.688734 | K26: =K8 -> 33
A27: =LEFT(A9,LEN(A9)-1)&"M" -> Lobby/Lounge_FloorM | B27: Lobby, Main Entry | D27: Office | E27: =E9 -> Yes | F27: =G27/$G$57 -> 0.019750368 | G27: 1059.1755 | H27: =H9 -> 9532.5792 | I27: =I9 -> 1 | J27: =K27*G27/1000 -> 10.591755 | K27: =K9 -> 10 | L27: People: 10 according to ASHRAE 62.1 Table 6-1
A28: =LEFT(A10,LEN(A10)-1)&"M" -> Storage_FloorM | B28: Storage (General) | D28: Office | E28: =E10 -> Yes | F28: =G28/$G$57 -> 0.018332841 | G28: 983.15611 | H28: =H10 -> 8848.405 | I28: =I10 -> 1 | K28: =K10 -> -
A29: =LEFT(A11,LEN(A11)-1)&"M" -> Mechanical/Electrical_FloorM | B29: Electrical, Mechanical, Telephone Rooms | D29: Office | E29: =E11 -> Yes | F29: =G29/$G$57 -> 0.006663486 | G29: 357.35034 | H29: =H11 -> 3216.1531 | I29: =I11 -> 1 | K29: =K11 -> -
A30: =LEFT(A12,LEN(A12)-1)&"M" -> IT-Room_FloorM | B30: IT Room (EPD 12) | D30: Data | E30: =E12 -> Yes | F30: =G30/$G$57 -> 0.0033366309 | G30: 178.9373 | H30: =H12 -> 1610.4357 | I30: =I12 -> 1 | K30: =K12 -> -
A31: =LEFT(A13,LEN(A13)-1)&"M" -> Restroom_FloorM | B31: Restrooms | D31: Office | E31: =E13 -> Yes | F31: =G31/$G$57 -> 0.012000749 | G31: 643.57783 | H31: =H13 -> 5792.2004 | I31: =I13 -> 1 | K31: =K13 -> -
A32: =LEFT(A14,LEN(A14)-1)&"M" -> Break_FloorM | B32: Lounge, Breakroom, or Waiting Area | D32: Office | E32: =E14 -> Yes | F32: =G32/$G$57 -> 0.0043324823 | G32: 232.34295 | H32: =H14 -> 2091.0866 | I32: =I14 -> 1 | J32: =K32*G32/1000 -> 7.6673175 | K32: =K14 -> 33
A33: =LEFT(A15,LEN(A15)-1)&"M" -> Stairway_FloorM | B33: Stairwell | D33: Office | E33: =E15 -> Yes | F33: =G33/$G$57 -> 0.012332934 | G33: 661.39226 | H33: =H15 -> 5952.5303 | I33: =I15 -> 1 | K33: =K15 -> -
A34: =LEFT(A16,LEN(A16)-1)&"M" -> Corridor_W_FloorM | B34: Corridor Area | D34: Office | E34: =E16 -> Yes | F34: =G34/$G$57 -> 0.0055940783 | G34: 300 | H34: =H16 -> 2700 | I34: =I16 -> 1 | J34: =K34*G34/1000 -> 1.5 | K34: =K16 -> 5
A35: =LEFT(A17,LEN(A17)-1)&"M" -> Corridor_N_FloorM | B35: Corridor Area | D35: Office | E35: =E17 -> Yes | F35: =G35/$G$57 -> 0.00937889 | G35: 502.9724 | H35: =H17 -> 4526.7516 | I35: =I17 -> 1 | J35: =K35*G35/1000 -> 2.514862 | K35: =K17 -> 5
A36: =LEFT(A18,LEN(A18)-1)&"M" -> Corridor_E_FloorM | B36: Corridor Area | D36: Office | E36: =E18 -> Yes | F36: =G36/$G$57 -> 0.0055793025 | G36: 299.2076 | H36: =H18 -> 2692.8684 | I36: =I18 -> 1 | J36: =K36*G36/1000 -> 1.496038 | K36: =K18 -> 5 | N36: Layout of Zones
A37: =LEFT(A19,LEN(A19)-1)&"M" -> Corridor_S_FloorM | B37: Corridor Area | D37: Office | E37: =E19 -> Yes | F37: =G37/$G$57 -> 0.00937889 | G37: 502.9724 | H37: =H19 -> 4526.7516 | I37: =I19 -> 1 | J37: =K37*G37/1000 -> 2.514862 | K37: =K19 -> 5
A38: =LEFT(A20,LEN(A20)-1)&"M" -> Plenum_FloorM | B38: Plenum | D38: Office | E38: =E20 -> No | G38: 17875.932 | H38: =H20 -> 71503.73 | I38: =I20 -> 1 | K38: =K20 -> -
A39: =LEFT(A3,LEN(A3)-1)&"T" -> Open_Office_Core_FloorT | B39: Office Area (>250 square feet) | D39: Office | E39: =E3 -> Yes | F39: =G39/$G$57 -> 0.079864791 | G39: 4283 | H39: =H3 -> 38547 | I39: =I3 -> 1 | J39: =K39*G39/1000 -> 21.415 | K39: =K3 -> 5
A40: =LEFT(A4,LEN(A4)-1)&"T" -> Open_Office_N_FloorT | B40: Office Area (>250 square feet) | D40: Office | E40: =E4 -> Yes | F40: =G40/$G$57 -> 0.042850403 | G40: 2297.9873 | H40: =H4 -> 20681.886 | I40: =I4 -> 1 | J40: =K40*G40/1000 -> 11.489937 | K40: =K4 -> 5
...

Sheet Envelope
A1: Envelope - OfficeMedium
A2: Element | B2: Prototype | C2: Assembly Type | D2: Construction | E2: Thermal Properties | F2: Vintage | G2: Selected T24 | H2: Note | I2: CZ1 | J2: CZ2 | K2: CZ3 | L2: CZ4 | M2: CZ5 | N2: CZ6 | O2: CZ7 | P2: CZ8 | Q2: CZ9 | R2: CZ10 | S2: CZ11 | T2: CZ12 | U2: CZ13 | V2: CZ14 | W2: CZ15 | X2: CZ16
A3: External Wall | B3: OfficeMedium | C3: ExtWall_MetalFramed_NonRes | D3: Metal-frame walls + insulation + Gypsum board | E3: U-factor IP | F3: Pre 1978 | G3: N/A | H3: ASHRAE 90.1, 2022, Table A3.3.3.1, 3.5", R-0 | I3: 0.352 | J3: 0.352 | K3: 0.352 | L3: 0.352 | M3: 0.352 | N3: 0.352 | O3: 0.352 | P3: 0.352 | Q3: 0.352 | R3: 0.352 | S3: 0.352 | T3: 0.352 | U3: 0.352 | V3: 0.352 | W3: 0.352 | X3: 0.352
F4: 1978-1997 | G4: 1986 | H4: Low-rise office: Package A/ Heat Capacity was considered ~10 (BTU/F/ft2) | I4: =1/6.63 -> 0.15082956 | J4: =1/6.35 -> 0.15748031 | K4: =1/6.35 -> 0.15748031 | L4: =1/6.96 -> 0.14367816 | M4: =1/6.96 -> 0.14367816 | N4: =1/4.62 -> 0.21645022 | O4: =1/4.62 -> 0.21645022 | P4: =1/4.62 -> 0.21645022 | Q4: =1/4.62 -> 0.21645022 | R4: =1/4.62 -> 0.21645022 | S4: =1/5.37 -> 0.18621974 | T4: =1/5.37 -> 0.18621974 | U4: =1/5.37 -> 0.18621974 | V4: =1/6.3 -> 0.15873016 | W4: =1/6.3 -> 0.15873016 | X4: =1/6.63 -> 0.15082956
F5: 1998-2007 | G5: 2001 | I5: 0.182 | J5: 0.182 | K5: 0.189 | L5: 0.189 | M5: 0.189 | N5: 0.189 | O5: 0.189 | P5: 0.189 | Q5: 0.189 | R5: 0.182 | S5: 0.182 | T5: 0.182 | U5: 0.182 | V5: 0.182 | W5: 0.182 | X5: 0.182
F6: 2008-2018 | G6: 2013 | I6: 0.098 | J6: 0.062 | K6: 0.082 | L6: 0.062 | M6: 0.062 | N6: 0.098 | O6: 0.098 | P6: 0.062 | Q6: 0.062 | R6: 0.062 | S6: 0.062 | T6: 0.062 | U6: 0.062 | V6: 0.062 | W6: 0.062 | X6: 0.062
F7: 2019+ | G7: 2025 | I7: 0.06 | J7: 0.055 | K7: 0.071 | L7: 0.055 | M7: 0.055 | N7: 0.06 | O7: 0.06 | P7: 0.055 | Q7: 0.055 | R7: 0.055 | S7: 0.055 | T7: 0.055 | U7: 0.055 | V7: 0.055 | W7: 0.055 | X7: 0.055
A8: Roof | B8: OfficeMedium | C8: FlatRoof_WoodFramedAndOther_NonRes | D8: Metal-Deck roof + insulation + Roof membrane | E8: U-factor IP | F8: Pre 1978 | G8: N/A | H8: Considering 30 years for roof/ insultation replacement. | I8: 0.057 | J8: 0.057 | K8: 0.057 | L8: 0.057 | M8: 0.057 | N8: 0.078 | O8: 0.078 | P8: 0.078 | Q8: 0.078 | R8: 0.078 | S8: 0.057 | T8: 0.057 | U8: 0.057 | V8: 0.057 | W8: 0.057 | X8: 0.057
F9: 1978-1997 | G9: 1992 | H9: Considering 30 years for roof/ insultation replacement. | I9: 0.057 | J9: 0.057 | K9: 0.057 | L9: 0.057 | M9: 0.057 | N9: 0.078 | O9: 0.078 | P9: 0.078 | Q9: 0.078 | R9: 0.078 | S9: 0.057 | T9: 0.057 | U9: 0.057 | V9: 0.057 | W9: 0.057 | X9: 0.057
F10: 1998-2007 | G10: 2001 | I10: 0.057 | J10: 0.057 | K10: 0.057 | L10: 0.057 | M10: 0.057 | N10: 0.078 | O10: 0.078 | P10: 0.078 | Q10: 0.078 | R10: 0.057 | S10: 0.057 | T10: 0.057 | U10: 0.057 | V10: 0.057 | W10: 0.057 | X10: 0.057
F11: 2008-2018 | G11: 2013 | I11: 0.049 | J11: 0.039 | K11: 0.039 | L11: 0.039 | M11: 0.049 | N11: 0.075 | O11: 0.067 | P11: 0.067 | Q11: 0.039 | R11: 0.039 | S11: 0.039 | T11: 0.039 | U11: 0.039 | V11: 0.039 | W11: 0.039 | X11: 0.039
F12: 2019+ | G12: 2025 | I12: 0.028 | J12: 0.028 | K12: 0.028 | L12: 0.028 | M12: 0.028 | N12: 0.047 | O12: 0.047 | P12: 0.047 | Q12: 0.028 | R12: 0.028 | S12: 0.028 | T12: 0.028 | U12: 0.028 | V12: 0.028 | W12: 0.028 | X12: 0.028
A13: Windows | B13: OfficeMedium | C13: FixedWindow_NonRes | D13: CBECS 2018 shows that over 50 % of medium offices that were built before 2000 are single pane | E13: U-factor IP | F13: Pre 1978 | G13: N/A | H13: ASHRAE Handbook of Fundamentals for single pane & T24, 2013 for double pane(50%-50%)* | I13: =1.12*0.5+I$16*0.5 -> 0.74 | J13: =1.12*0.5+J$16*0.5 -> 0.74 | K13: =1.12*0.5+K$16*0.5 -> 0.74 | L13: =1.12*0.5+L$16*0.5 -> 0.74 | M13: =1.12*0.5+M$16*0.5 -> 0.74 | N13: =1.12*0.5+N$16*0.5 -> 0.74 | O13: =1.12*0.5+O$16*0.5 -> 0.74 | P13: =1.12*0.5+P$16*0.5 -> 0.74 | ... X13: =1.12*0.5+X$16*0.5 -> 0.74
F14: 1978-1997 | G14: N/A | I14: =1.12*0.5+I$16*0.5 -> 0.74 | J14: =1.12*0.5+J$16*0.5 -> 0.74 | K14: =1.12*0.5+K$16*0.5 -> 0.74 | L14: =1.12*0.5+L$16*0.5 -> 0.74 | M14: =1.12*0.5+M$16*0.5 -> 0.74 | N14: =1.12*0.5+N$16*0.5 -> 0.74 | O14: =1.12*0.5+O$16*0.5 -> 0.74 | P14: =1.12*0.5+P$16*0.5 -> 0.74 | ... X14: =1.12*0.5+X$16*0.5 -> 0.74
D15: Double pane | F15: 1998-2007 | G15: 2001 | I15: 0.49 | J15: 0.49 | K15: 0.81 | L15: 0.81 | M15: 0.81 | N15: 0.81 | O15: 0.81 | P15: 0.81 | Q15: 0.81 | R15: 0.49 | S15: 0.49 | T15: 0.49 | U15: 0.49 | V15: 0.49 | W15: 0.49 | X15: 0.49
F16: 2008-2018 | G16: 2013 | I16: 0.36 | J16: 0.36 | K16: 0.36 | L16: 0.36 | M16: 0.36 | N16: 0.36 | O16: 0.36 | P16: 0.36 | Q16: 0.36 | R16: 0.36 | S16: 0.36 | T16: 0.36 | U16: 0.36 | V16: 0.36 | W16: 0.36 | X16: 0.36
F17: 2019+ | G17: 2025 | I17: 0.36 | J17: 0.36 | K17: 0.36 | L17: 0.36 | M17: 0.36 | N17: 0.36 | O17: 0.36 | P17: 0.36 | Q17: 0.34 | R17: 0.36 | S17: 0.34 | T17: 0.34 | U17: 0.34 | V17: 0.34 | W17: 0.34 | X17: 0.36
B18: OfficeMedium | C18: FixedWindow_NonRes | D18: CBECS 2018 shows that over 50% of medium offices that were built before 2000 are single pane | E18: SHGC | F18: Pre 1978 | G18: N/A | H18: ASHRAE Handbook of Fundamentals for single pane & T24, 2013 for double pane(50%-50%)* | I18: =0.8*0.5+I$21*0.5 -> 0.615 | J18: =0.8*0.5+J$21*0.5 -> 0.58 | K18: =0.8*0.5+K$21*0.5 -> 0.605 | L18: =0.8*0.5+L$21*0.5 -> 0.605 | M18: =0.8*0.5+M$21*0.5 -> 0.605 | N18: =0.8*0.5+N$21*0.5 -> 0.595 | O18: =0.8*0.5+O$21*0.5 -> 0.595 | P18: =0.8*0.5+P$21*0.5 -> 0.595 | ... X18: =0.8*0.5+X$21*0.5 -> 0.615
F19: 1978-1997 | G19: N/A | I19: =0.8*0.5+I$21*0.5 -> 0.615 | J19: =0.8*0.5+J$21*0.5 -> 0.58 | K19: =0.8*0.5+K$21*0.5 -> 0.605 | L19: =0.8*0.5+L$21*0.5 -> 0.605 | M19: =0.8*0.5+M$21*0.5 -> 0.605 | N19: =0.8*0.5+N$21*0.5 -> 0.595 | O19: =0.8*0.5+O$21*0.5 -> 0.595 | P19: =0.8*0.5+P$21*0.5 -> 0.595 | ... X19: =0.8*0.5+X$21*0.5 -> 0.615
D20: Double pane | F20: 1998-2007 | G20: 2001 | H20: WWR:20-30 / SHGC north | I20: 0.47 | J20: 0.47 | K20: 0.61 | L20: 0.61 | M20: 0.61 | N20: 0.61 | O20: 0.61 | P20: 0.61 | Q20: 0.61 | R20: 0.47 | S20: 0.47 | T20: 0.47 | U20: 0.47 | V20: 0.47 | W20: 0.47 | X20: 0.47
H21: WWR:20-30 / SHGC non-north | I21: 0.43 | J21: 0.36 | K21: 0.41 | L21: 0.41 | M21: 0.41 | N21: 0.39 | O21: 0.39 | P21: 0.39 | Q21: 0.39 | R21: 0.36 | S21: 0.36 | T21: 0.36 | U21: 0.36 | V21: 0.36 | W21: 0.36 | X21: 0.43
F22: 2008-2018 | G22: 2013 | I22: 0.25 | J22: 0.25 | K22: 0.25 | L22: 0.25 | M22: 0.25 | N22: 0.25 | O22: 0.25 | P22: 0.25 | Q22: 0.25 | R22: 0.25 | S22: 0.25 | T22: 0.25 | U22: 0.25 | V22: 0.25 | W22: 0.25 | X22: 0.25
F23: 2019+ | G23: 2025 | I23: 0.25 | J23: 0.25 | K23: 0.25 | L23: 0.25 | M23: 0.25 | N23: 0.25 | O23: 0.25 | P23: 0.25 | Q23: 0.22 | R23: 0.25 | S23: 0.22 | T23: 0.22 | U23: 0.22 | V23: 0.22 | W23: 0.22 | X23: 0.25
E25: Infiltration
F26: Vintage | G26: I_75 (cfm/ft²) 6-sdied Infiltration rate @ 75 pa | H26: Source | I26: I-design (cfm/ft²) (4-sided Infiltration rate at normal pressure) (Design flow rate approach and Flow/Exterior Wall Area calculation method)
E27: Infiltration | F27: Pre 1978 | G27: 1.1 | H27: 2022 CASE report (Table 38) | I27: 0.3302
F28: 1978-1997 | G28: 1.1 | H28: 2022 CASE report (Table 38) | I28: 0.3302
F29: 1998-2007 | G29: 1.1 | H29: 2022 CASE report (Table 38) | I29: 0.3302
F30: 2008-2018 | G30: 1* | H30: 2022 CASE report (Table 38) & T24, 2008-2016 (Table 140.3-C) | I30: 0.3021
F31: 2019+ | G31: 0.6** | H31: 2022 CASE report (Table 38) & T24,140.3(a)9Cii & T24, 2025 (Table 140.3-C) | I31: 0.1801
E32: Infiltration_rate_report_14May2025-Short-Version.docx
E33: * An air barrier was not required for guest rooms under T24, until the 2019 edition. However, to reflect typical construction practices, we assumed that all exterior walls are equipped with an air barrier where it was required for nonresidential walls.
E34: *** T24 require 0.4 cfm/ft² for tested condition but it also in section 140.3(a)9Cii says that if the air leakage requirements are not met, a visual inspection and diagnostic evaluation shall be completed , all observed leaks shall be sealed where such sealing can be made without destruction of existing building components, and buildings where the tested leakage rate exceeded 0.6 cfm/ft² of building shell area at 75 Pa have been retested to confirm leakage is below 0.6 cfm/ft² of building shell at 75 Pa.
A36: *Note for windows properties in vintage 1 &2 :
A37: We’ve considered a 50% single-pane and 50% double-pane mix (based on the 2013 requirements) for the window properties in Vintage 1 & 2 (pre-1998 buildings).
A38: Since we don't have California-specific data, the decision is based on the CBECS 2018 data, which indicates:
A39: - 40% of medium offices built before 1978 have mixed windows, while only 6% of offices from the second vintage (1978-1997) have mixed glass.
A40: - Pre-1978: Among those with either single or double-pane windows, 80% have single-pane windows, and 20% have double-pane windows.
A41: - 1978-1997: Among those with either single or double-pane windows, 55% have single-pane windows, and 45% have double-pane windows.
A42: - Pre 1999: Among those with either single or double-pane windows, 61% has single pane windows.
...

Sheet HVAC System
A1: HVAC system - OfficeMedium
A2: Vintage | B2: Space/Thermal Zone | C2: Heating | D2: Cooling | E2: Air Distribution | F2: Source
A3: Existing | B3: All | C3: Furnace (Gas) | D3: Packaged (DX) | E3: CAV with Reheat for the first two vintages VAV with Reheat for vintage 3 and 4 | F3: CEUS 2022 + Engineering Judgement | G3: PTAC
A4: New Construction | B4: All | C4: VRF | D4: VRF | E4: VRF | F4: T24, 2025 | G4: VRF
A5: It Room hasa dedicated HVAC system
A9: Efficiency of HVAC system | G9: Detailed efficiency of cooling system
A10: Vintage | B10: Upgrade/Installed year | C10: Heating | D10: Cooling | E10: Source | G10: Vintage | H10: Cooling System (& air distribution ) | I10: HVAC Zones | J10: Serving floor | K10: Serving area (ft2) | L10: Estimated cooling capapcity (Btu/hr) | M10: Size category (Btu/hr) | N10: Cooling | O10: Upgrade/Installed year | P10: Source
A11: Pre 1978 | B11: 2008 | C11: Efficiency 80% | D11: EER=10.3, 9.7, 9.5 | E11: T24, 2008 (Table 112-A) | G11: Pre-1978 & 1978-1997 | H11: West_AC_CAV | I11: West_ZN | J11: No.1,2,3 | K11: =(Zones!G5+Zones!G16)*3 -> 5813.5835 | L11: =20*K11 -> 116271.67 | M11: 65,000-13,5000 | N11: EER=10.3 | O11: 2008 | P11: T24, Part 6, 2008 (Table 112-A): Ellectrically operated Unitary Air Conditioners and Condensing units- Minimun Efficicenc Requirements
A12: 1978-1997 | H12: East_AC_CAV | I12: East ZN | J12: No.1,2,3 | K12: =K11 -> 5813.5835 | L12: =20*K12 -> 116271.67 | M12: 65,000-13,5000 | N12: EER=10.3 | O12: 2008
A13: 1998-2007 | B13: 2008 | C13: Efficiency 80% | D13: EER=9.5 | E13: T24, 2008 (Table 112-A) | H13: North_AC_CAV | I13: North_ZN | J13: No.1,2,3 | K13: =(Zones!G4+Zones!G17)*3 -> 8402.8792 | L13: =20*K13 -> 168057.58 | M13: 135,000-240,000 | N13: EER=9.7 | O13: 2008
A14: 2008-2018 | B14: 2010 | C14: COP=3 / Efficiency 80% | D14: EER=10 | E14: T24,2010 (Table 112-A) | H14: South_AC_CAV | I14: South_ZoneN | J14: No.1,2,3 | K14: =K13 -> 8402.8792 | L14: =20*K14 -> 168057.58 | M14: 135,000-240,000 | N14: EER=9.7 | O14: 2008
A15: New Construction | B15: 2025 | C15: COP=3.3 / Efficiency 80% | D15: EER=10 | E15: T24, 2025 (Table 112-A) & CFR Energy 2024:Title 10- Table 19 - § 431.97 | H15: Core_Office_AC_CAV | I15: Core_Office_ZN | J15: No.1,2,3 | K15: =Zones!G3*3 -> 12849 | L15: =20*K15 -> 256980 | M15: 240,000-760,000 | N15: EER=9.5 | O15: 2008
H16: Core_Service_AC_CAV | I16: Core_Service_ZN | J16: No.1,2,3 | K16: =SUM(Zones!G9:G15)*3 -> 12347.797 | L16: =20*K16 -> 246955.94 | M16: 240,000-760,000 | N16: EER=9.5 | O16: 2008
G17: 1998-2007 | H17: Floor_1_AC_VAV | I17: All Zones in Floor 1 | J17: No. 1 | K17: =Zones!G20 -> 17875.932 | L17: =20*K17 -> 357518.65 | M17: 240,000-760,000 | N17: EER=9.5 | O17: 2008
H18: Floor_2_AC_VAV | I18: All Zones in Floor 2 | J18: No. 2 | K18: =K17 -> 17875.932 | L18: =20*K18 -> 357518.65 | M18: 240,000-760,000 | N18: EER=9.5 | O18: 2008
H19: Floor_3_AC_VAV | I19: All Zones in Floor 3 | J19: No. 3 | K19: =K18 -> 17875.932 | L19: =20*K19 -> 357518.65 | M19: 240,000-760,000 | N19: EER=9.5 | O19: 2008
G20: 2008-2018 | H20: Floor_1_AC_VAV | I20: All Zones in Floor 1 | J20: No. 1 | K20: =Zones!G20 -> 17875.932 | L20: =20*K20 -> 357518.65 | M20: 240,000-760,000 | N20: EER=10 | O20: 2010 | P20: T24, Part 6, 2010 (Table 112-A): Electrically operated Unitary Air Conditioners and Condensing units- Minimum Efficiency Requirements | Q20: 2010 California Energy Code, Part 6 - SUBCHAPTER 2
H21: Floor_2_AC_VAV | I21: All Zones in Floor 2 | J21: No. 2 | K21: =K20 -> 17875.932 | L21: =20*K21 -> 357518.65 | M21: 240,000-760,000 | N21: EER=10 | O21: 2010
H22: Floor_3_AC_VAV | I22: All Zones in Floor 3 | J22: No. 3 | K22: =K21 -> 17875.932 | L22: =20*K22 -> 357518.65 | M22: 240,000-760,000 | N22: EER=10 | O22: 2010
G23: New Construction | H23: Floor_1_AC_VRF | I23: All Zones in Floor 1 | J23: No. 1 | K23: =Zones!G20 -> 17875.932 | L23: =20*K23 -> 357518.65 | M23: >=240,000 | N23: EER=10 | O23: 2025 | P23: T24, Part 6, 2025 (Table 110.2-A) & CFR Energy 2024:Title 10- Table 1 - § 431.97 | Q23: eCFR :: 10 CFR 431.97 -- Energy efficiency standards and their compliance dates.
H24: Floor_2_AC_VRF | I24: All Zones in Floor 2 | J24: No. 2 | K24: =K23 -> 17875.932 | L24: =20*K24 -> 357518.65 | M24: >=240,000 | N24: EER=10 | O24: 2025 | Q24: https://www.govinfo.gov/content/pkg/CFR-2024-title10-vol3/pdf/CFR-2024-title10-vol3-part431-subpartF.pdf
H25: Floor_3_AC_VRF | I25: All Zones in Floor 3 | J25: No. 3 | K25: =K24 -> 17875.932 | L25: =20*K25 -> 357518.65 | M25: >=240,000 | N25: EER=10 | O25: 2025
G26: IT_Room is served by a dedicated system
A28: Fan power
A29: Vintage | B29: Approach | C29: System | D29: Total Static Pressure (TSP) (in w.c.) | E29: Fan Efficiency [ACM 2025] | F29: Fan Motor and Drive Efficiency [ACM 2025, Table 13] | G29: W/cfm [ACM 2025, Table 14 and 15] | H29: Data Source | I29: Note
A30: Existing | B30: PNNL TSP | C30: CAV System <7,437 cfm | D30: 2.5 | E30: 0.65 | F30: ~0.9 (The full-load efficiency of the motor serving the fan- will be determined based on ACM 2025, Table 13) | H30: Fan Motor and Efficiency: ACM 2025, 0.5 Engineering judgement TSP:[PNNL 20405, 2010, Table 5.11
C31: CAV System >7,437 cfm | D31: 4.09 | E31: 0.65
C32: VAV System > 4,648 cfm | D32: 5.58 | E32: 0.65
A33: Brake horse power (bhp)=(Supply cfm*TSP in w.c.)/(6356*Fan efficiency)
A34: Fan power (w/cfm) = bhp/motor and drive efficiency *746
A35: New Construction | B35: ACM 2025 | C35: Small indoor fan at zone (for VRF) | D35: =G35*$F$35*$E$35/746*6356 -> 1.744492 | E35: 0.65 | F35: 0.9 | G35: 0.35 | H35: Fan Motor and Efficiency and W/cfm: ACM 2025 | I35: 0.35 w/cfm for indoor unit fan (T24, 2025, Section 140.4(a)3 D)
F36: * 0.9 is an average fan efficiency according to ACM 2025, Table 13
A37: Fan total eff (E+ input) = 0.65 x Motor_eff
A38: TSP (E+ input) in w.c. = Motor_eff/746 x (6356 x Fan_eff) x W/cfm
A39: Fan_eff=0.65
A41: Microsoft Word - PNNL 90 1-2010_TSD_Final 5-23-2011_Final.docx
A51: Title 24, part6/2008 | E51: Title 24, Part 6/2010 | I51: Title 24, Part 6/2025 | N51: CFR/2024

Sheet Thermostat
A1: Thermostat Setpoints: OfficeMedium
A2: Setpoint | B2: CZ1 | C2: CZ2 | D2: CZ3 | E2: CZ4 | F2: CZ5 | G2: CZ6 | H2: CZ7 | I2: CZ8 | J2: CZ9 | K2: CZ10 | L2: CZ11 | M2: CZ12 | N2: CZ13 | O2: CZ14 | P2: CZ15 | Q2: CZ16 | R2: Source
A3: Heating Setpoint (F) | B3: 70 | C3: 70 | D3: 70 | E3: 70 | F3: 70 | G3: 70 | H3: 70 | I3: 70 | J3: 70 | K3: 70 | L3: 70 | M3: 70 | N3: 70 | O3: 70 | P3: 70 | Q3: 70 | R3: T24 2022 - Appendix 5.4B
A4: Heating Setback (F) | B4: 60 | C4: 60 | D4: 60 | E4: 60 | F4: 60 | G4: 60 | H4: 60 | I4: 60 | J4: 60 | K4: 60 | L4: 60 | M4: 60 | N4: 60 | O4: 60 | P4: 60 | Q4: 60
A5: Cooling Setpoint (F) | B5: 75 | C5: 75 | D5: 75 | E5: 75 | F5: 75 | G5: 75 | H5: 75 | I5: 75 | J5: 75 | K5: 75 | L5: 75 | M5: 75 | N5: 75 | O5: 75 | P5: 75 | Q5: 75
A6: Cooling Setback (F) | B6: 85 | C6: 85 | D6: 85 | E6: 85 | F6: 85 | G6: 85 | H6: 85 | I6: 85 | J6: 85 | K6: 85 | L6: 85 | M6: 85 | N6: 85 | O6: 85 | P6: 85 | Q6: 85
B7: *PNNL has considered 80 F for cooling setback of Medium Office prototype. However cooling setback is 85 F for Small Office prototype !!
A9: Note: The Medium Office prototype by PNNL also uses the same setpoints, except for one of the perimeter zones, which has a heating setpoint of 69 °F and a cooling setpoint of 76 °F during hours of 10:00-11:00, 12:00-13:00, and 14:00-15:00 .
A16: Background Data [To be deleted prior to publication]
A18: Heating/ CoolingSetpointsSchedules (existing prototypes extracted from the idf files (presented below)
B39: Heating | K39: Cooling
B40: CEC-2022 | F40: PNNL-2022 | K40: CEC-2022 | O40: PNNL-2022
B41: CEC-Weekday | C41: CEC-Saturday | D41: CEC-Sunday | F41: PNNL-Weekday | G41: PNNL-Saturday | H41: PNNL-Sunday | K41: CEC-Weekday | L41: CEC-Saturday | M41: CEC-Sunday | O41: PNNL-Weekday | P41: PNNL-Saturday | Q41: PNNL-Sunday
A42: 1 | B42: 60 | C42: 60 | D42: 60 | F42: 60.08 | G42: 60.08 | H42: 60.08 | K42: 85 | L42: 85 | M42: 85 | O42: 80.06 | P42: 80.06 | Q42: 80.06
A43: 2 | B43: 60 | C43: 60 | D43: 60 | F43: 60.08 | G43: 60.08 | H43: 60.08 | K43: 85 | L43: 85 | M43: 85 | O43: 80.06 | P43: 80.06 | Q43: 80.06
A44: 3 | B44: 60 | C44: 60 | D44: 60 | F44: 60.08 | G44: 60.08 | H44: 60.08 | K44: 85 | L44: 85 | M44: 85 | O44: 80.06 | P44: 80.06 | Q44: 80.06
A45: 4 | B45: 60 | C45: 60 | D45: 60 | F45: 60.08 | G45: 60.08 | H45: 60.08 | K45: 85 | L45: 85 | M45: 85 | O45: 80.06 | P45: 80.06 | Q45: 80.06
A46: 5 | B46: 60 | C46: 60 | D46: 60 | F46: 60.08 | G46: 60.08 | H46: 60.08 | K46: 85 | L46: 85 | M46: 85 | O46: 80.06 | P46: 80.06 | Q46: 80.06
A47: 6 | B47: 70 | C47: 70 | D47: 60 | F47: 64.04 | G47: 64.04 | H47: 60.08 | K47: 75 | L47: 75 | M47: 85 | O47: 78.08 | P47: 78.26 | Q47: 80.06
A48: 7 | B48: 70 | C48: 70 | D48: 60 | F48: 68 | G48: 68 | H48: 60.08 | K48: 75 | L48: 75 | M48: 85 | O48: 77 | P48: 77 | Q48: 80.06
A49: 8 | B49: 70 | C49: 70 | D49: 60 | F49: 69.8 | G49: 69.8 | H49: 60.08 | K49: 75 | L49: 75 | M49: 85 | O49: 75.2 | P49: 75.2 | Q49: 80.06
A50: 9 | B50: 70 | C50: 70 | D50: 60 | F50: 69.8 | G50: 69.8 | H50: 60.08 | K50: 75 | L50: 75 | M50: 85 | O50: 75.2 | P50: 75.2 | Q50: 80.06
A51: 10 | B51: 70 | C51: 70 | D51: 60 | F51: 69.8 | G51: 69.8 | H51: 60.08 | K51: 75 | L51: 75 | M51: 85 | O51: 75.2 | P51: 75.2 | Q51: 80.06
A52: 11 | B52: 70 | C52: 70 | D52: 60 | F52: 69.8 | G52: 69.8 | H52: 60.08 | K52: 75 | L52: 75 | M52: 85 | O52: 75.2 | P52: 75.2 | Q52: 80.06
A53: 12 | B53: 70 | C53: 70 | D53: 60 | F53: 69.8 | G53: 69.8 | H53: 60.08 | K53: 75 | L53: 75 | M53: 85 | O53: 75.2 | P53: 75.2 | Q53: 80.06
... A65: 24 | B65: 70 | C65: 60 | D65: 60 | F65: 60.08 | G65: 60.08 | H65: 60.08 | K65: 75 | L65: 85 | M65: 85 | O65: 80.06 | P65: 80.06 | Q65: 80.06

Sheet Ventilation
A1: Outdoor Airflow Rate - OfficeMedium
A2: Space | B2: Number of People | C2: Floor Area (ft²) | D2: cfm/person (T24, 2025, Equation 120.1-F and Table 120.1-A) | E2: cfm/ft² (T24, 2025, Equation 120.1-F and Table 120.1-A) | F2: Required Exhaust Rate (T24, 2025, Table 120.1-B – Minimum Exhaust Rates) | G2: Total cfm Driven by People | H2: Total cfm Driven by Area | I2: Total cfm Driven by Exhaust | J2: Total cfm | K2: Note
A3: =Zones!A3 -> Open_Office_Core_FloorG | B3: =Zones!J3 -> 21.415 | C3: =Zones!G3 -> 4283 | D3: 15 | E3: 0.15 | G3: =B3*D3 -> 321.225 | H3: =C3*E3 -> 642.45 | I3: =F3 -> 0 | J3: =MAX(G3,H3,I3) -> 642.45
A4: =Zones!A4 -> Open_Office_N_FloorG | B4: =Zones!J4 -> 11.489937 | C4: =Zones!G4 -> 2297.9873 | D4: 15 | E4: 0.15 | G4: =B4*D4 -> 172.34905 | H4: =C4*E4 -> 344.6981 | I4: =F4 -> 0 | J4: =MAX(G4,H4,I4) -> 344.6981
A5: =Zones!A5 -> Closed_Office_W_FloorG | B5: =Zones!J5 -> 8.1893058 | C5: =Zones!G5 -> 1637.8612 | D5: 15 | E5: 0.15 | G5: =B5*D5 -> 122.83959 | H5: =C5*E5 -> 245.67917 | I5: =F5 -> 0 | J5: =MAX(G5,H5,I5) -> 245.67917
A6: =Zones!A6 -> Closed_Office_E_FloorG | B6: =Zones!J6 -> 8.1893058 | C6: =Zones!G6 -> 1637.8612 | D6: 15 | E6: 0.15 | G6: =B6*D6 -> 122.83959 | H6: =C6*E6 -> 245.67917 | I6: =F6 -> 0 | J6: =MAX(G6,H6,I6) -> 245.67917
A7: =Zones!A7 -> Open_Office_S_FloorG | B7: =Zones!J7 -> 5.9310376 | C7: =Zones!G7 -> 1186.2075 | D7: 15 | E7: 0.15 | G7: =B7*D7 -> 88.965563 | H7: =C7*E7 -> 177.93113 | I7: =F7 -> 0 | J7: =MAX(G7,H7,I7) -> 177.93113
A8: =Zones!A8 -> Conference_FloorG | B8: =Zones!J8 -> 36.688734 | C8: =Zones!G8 -> 1111.7798 | D8: 15 | E8: 0.15 | G8: =B8*D8 -> 550.33101 | H8: =C8*E8 -> 166.76697 | I8: =F8 -> 0 | J8: =MAX(G8,H8,I8) -> 550.33101
A9: =Zones!A9 -> Lobby/Lounge_FloorG | B9: =Zones!J9 -> 10.591755 | C9: =Zones!G9 -> 1059.1755 | D9: 15 | E9: 0.15 | G9: =B9*D9 -> 158.87632 | H9: =C9*E9 -> 158.87632 | I9: =F9 -> 0 | J9: =MAX(G9,H9,I9) -> 158.87632
A10: =Zones!A10 -> Storage_FloorG | B10: =Zones!J10 -> 0 | C10: =Zones!G10 -> 983.15611 | D10: 15 | E10: 0.15 | H10: =C10*E10 -> 147.47342 | I10: =F10 -> 0 | J10: =MAX(G10,H10,I10) -> 147.47342
A11: =Zones!A11 -> Mechanical/Electrical_FloorG | B11: =Zones!J11 -> 0 | C11: =Zones!G11 -> 357.35034 | D11: 15 | E11: 0.15 | H11: =C11*E11 -> 53.602551 | I11: =F11 -> 0 | J11: =MAX(G11,H11,I11) -> 53.602551
A12: =Zones!A12 -> IT-Room_FloorG | B12: =Zones!J12 -> ? | C12: =Zones!G12 -> 178.9373 | D12: 15 | E12: 0.15 | H12: =C12*E12 -> 26.840595 | I12: =F12 -> 0 | J12: =MAX(G12,H12,I12) -> 26.840595
A13: =Zones!A13 -> Restroom_FloorG | B13: =Zones!J13 -> 0 | C13: =Zones!G13 -> 643.57783 | D13: 15 | E13: 0.15 | F13: 4*25/50 cfm per unit | H13: =C13*E13 -> 96.536674 | I13: 100 | J13: =MAX(G13,H13,I13) -> 100 | K13: Almost 1 unit per 30 occupant for exhaust fan
A14: =Zones!A14 -> Break_FloorG | B14: =Zones!J14 -> 7.6673175 | C14: =Zones!G14 -> 232.34295 | D14: 15 | E14: 0.15 | G14: =B14*D14 -> 115.00976 | H14: =C14*E14 -> 34.851443 | I14: =F14 -> 0 | J14: =MAX(G14,H14,I14) -> 115.00976
A15: =Zones!A15 -> Stairway_FloorG | B15: =Zones!J15 -> 0 | C15: =Zones!G15 -> 661.39226 | D15: 15 | E15: 0.15 | H15: =C15*E15 -> 99.208839 | I15: =F15 -> 0 | J15: =MAX(G15,H15,I15) -> 99.208839
A16: =Zones!A16 -> Corridor_W_FloorG | B16: =Zones!J16 -> 1.5 | C16: =Zones!G16 -> 300 | D16: 15 | E16: 0.15 | G16: =B16*D16 -> 22.5 | H16: =C16*E16 -> 45 | I16: =F16 -> 0 | J16: =MAX(G16,H16,I16) -> 45
A17: =Zones!A17 -> Corridor_N_FloorG | B17: =Zones!J17 -> 2.514862 | C17: =Zones!G17 -> 502.9724 | D17: 15 | E17: 0.15 | G17: =B17*D17 -> 37.72293 | H17: =C17*E17 -> 75.44586 | I17: =F17 -> 0 | J17: =MAX(G17,H17,I17) -> 75.44586
A18: =Zones!A18 -> Corridor_E_FloorG | B18: =Zones!J18 -> 1.496038 | C18: =Zones!G18 -> 299.2076 | D18: 15 | E18: 0.15 | G18: =B18*D18 -> 22.44057 | H18: =C18*E18 -> 44.88114 | I18: =F18 -> 0 | J18: =MAX(G18,H18,I18) -> 44.88114
A19: =Zones!A19 -> Corridor_S_FloorG | B19: =Zones!J19 -> 2.514862 | C19: =Zones!G19 -> 502.9724 | D19: 15 | E19: 0.15 | G19: =B19*D19 -> 37.72293 | H19: =C19*E19 -> 75.44586 | I19: =F19 -> 0 | J19: =MAX(G19,H19,I19) -> 75.44586
A20: =Zones!A20 -> Plenum_FloorG | B20: =Zones!J20 -> 0 | C20: =Zones!G20 -> 17875.932 | E20: - | I20: =F20 -> 0 | J20: =MAX(G20,H20,I20) -> 0
A21: =Zones!A21 -> Open_Office_Core_FloorM | B21: =Zones!J21 -> 21.415 | C21: =Zones!G21 -> 4283 | D21: =D3 -> 15 | E21: =E3 -> 0.15 | G21: =B21*D21 -> 321.225 | H21: =C21*E21 -> 642.45 | I21: =F21 -> 0 | J21: =MAX(G21,H21,I21) -> 642.45
A22: =Zones!A22 -> Open_Office_N_FloorM | B22: =Zones!J22 -> 11.489937 | C22: =Zones!G22 -> 2297.9873 | D22: =D4 -> 15 | E22: =E4 -> 0.15 | G22: =B22*D22 -> 172.34905 | H22: =C22*E22 -> 344.6981 | I22: =F22 -> 0 | J22: =MAX(G22,H22,I22) -> 344.6981
A23: =Zones!A23 -> Closed_Office_W_FloorM | B23: =Zones!J23 -> 8.1893058 | C23: =Zones!G23 -> 1637.8612 | D23: =D5 -> 15 | E23: =E5 -> 0.15 | G23: =B23*D23 -> 122.83959 | H23: =C23*E23 -> 245.67917 | I23: =F23 -> 0 | J23: =MAX(G23,H23,I23) -> 245.67917
A24: =Zones!A24 -> Closed_Office_E_FloorM | B24: =Zones!J24 -> 8.1893058 | C24: =Zones!G24 -> 1637.8612 | D24: =D6 -> 15 | E24: =E6 -> 0.15 | G24: =B24*D24 -> 122.83959 | H24: =C24*E24 -> 245.67917 | I24: =F24 -> 0 | J24: =MAX(G24,H24,I24) -> 245.67917
A25: =Zones!A25 -> Open_Office_S_FloorM | B25: =Zones!J25 -> 5.9310376 | C25: =Zones!G25 -> 1186.2075 | D25: =D7 -> 15 | E25: =E7 -> 0.15 | G25: =B25*D25 -> 88.965563 | H25: =C25*E25 -> 177.93113 | I25: =F25 -> 0 | J25: =MAX(G25,H25,I25) -> 177.93113
A26: =Zones!A26 -> Conference_FloorM | B26: =Zones!J26 -> 36.688734 | C26: =Zones!G26 -> 1111.7798 | D26: =D8 -> 15 | E26: =E8 -> 0.15 | G26: =B26*D26 -> 550.33101 | H26: =C26*E26 -> 166.76697 | I26: =F26 -> 0 | J26: =MAX(G26,H26,I26) -> 550.33101
A27: =Zones!A27 -> Lobby/Lounge_FloorM | B27: =Zones!J27 -> 10.591755 | C27: =Zones!G27 -> 1059.1755 | D27: =D9 -> 15 | E27: =E9 -> 0.15 | G27: =B27*D27 -> 158.87632 | H27: =C27*E27 -> 158.87632 | I27: =F27 -> 0 | J27: =MAX(G27,H27,I27) -> 158.87632
A28: =Zones!A28 -> Storage_FloorM | B28: =Zones!J28 -> 0 | C28: =Zones!G28 -> 983.15611 | D28: =D10 -> 15 | E28: =E10 -> 0.15 | H28: =C28*E28 -> 147.47342 | I28: =F28 -> 0 | J28: =MAX(G28,H28,I28) -> 147.47342
A29: =Zones!A29 -> Mechanical/Electrical_FloorM | B29: =Zones!J29 -> 0 | C29: =Zones!G29 -> 357.35034 | D29: =D11 -> 15 | E29: =E11 -> 0.15 | H29: =C29*E29 -> 53.602551 | I29: =F29 -> 0 | J29: =MAX(G29,H29,I29) -> 53.602551
A30: =Zones!A30 -> IT-Room_FloorM | B30: =Zones!J30 -> 0 | C30: =Zones!G30 -> 178.9373 | D30: =D12 -> 15 | E30: =E12 -> 0.15 | H30: =C30*E30 -> 26.840595 | I30: =F30 -> 0 | J30: =MAX(G30,H30,I30) -> 26.840595
A31: =Zones!A31 -> Restroom_FloorM | B31: =Zones!J31 -> 0 | C31: =Zones!G31 -> 643.57783 | D31: =D13 -> 15 | E31: =E13 -> 0.15 | F31: 4*25/50 cfm per unit | H31: =C31*E31 -> 96.536674 | I31: 100 | J31: =MAX(G31,H31,I31) -> 100
A32: =Zones!A32 -> Break_FloorM | B32: =Zones!J32 -> 7.6673175 | C32: =Zones!G32 -> 232.34295 | D32: =D14 -> 15 | E32: =E14 -> 0.15 | G32: =B32*D32 -> 115.00976 | H32: =C32*E32 -> 34.851443 | I32: =F32 -> 0 | J32: =MAX(G32,H32,I32) -> 115.00976
A33: =Zones!A33 -> Stairway_FloorM | B33: =Zones!J33 -> 0 | C33: =Zones!G33 -> 661.39226 | D33: =D15 -> 15 | E33: =E15 -> 0.15 | H33: =C33*E33 -> 99.208839 | I33: =F33 -> 0 | J33: =MAX(G33,H33,I33) -> 99.208839
A34: =Zones!A34 -> Corridor_W_FloorM | B34: =Zones!J34 -> 1.5 | C34: =Zones!G34 -> 300 | D34: =D16 -> 15 | E34: =E16 -> 0.15 | G34: =B34*D34 -> 22.5 | H34: =C34*E34 -> 45 | I34: =F34 -> 0 | J34: =MAX(G34,H34,I34) -> 45
A35: =Zones!A35 -> Corridor_N_FloorM | B35: =Zones!J35 -> 2.514862 | C35: =Zones!G35 -> 502.9724 | D35: =D17 -> 15 | E35: =E17 -> 0.15 | G35: =B35*D35 -> 37.72293 | H35: =C35*E35 -> 75.44586 | I35: =F35 -> 0 | J35: =MAX(G35,H35,I35) -> 75.44586
A36: =Zones!A36 -> Corridor_E_FloorM | B36: =Zones!J36 -> 1.496038 | C36: =Zones!G36 -> 299.2076 | D36: =D18 -> 15 | E36: =E18 -> 0.15 | G36: =B36*D36 -> 22.44057 | H36: =C36*E36 -> 44.88114 | I36: =F36 -> 0 | J36: =MAX(G36,H36,I36) -> 44.88114
A37: =Zones!A37 -> Corridor_S_FloorM | B37: =Zones!J37 -> 2.514862 | C37: =Zones!G37 -> 502.9724 | D37: =D19 -> 15 | E37: =E19 -> 0.15 | G37: =B37*D37 -> 37.72293 | H37: =C37*E37 -> 75.44586 | I37: =F37 -> 0 | J37: =MAX(G37,H37,I37) -> 75.44586
A38: =Zones!A38 -> Plenum_FloorM | B38: =Zones!J38 -> 0 | C38: =Zones!G38 -> 17875.932 | D38: =D20 -> 0 | E38: =E20 -> - | I38: =F38 -> 0 | J38: =MAX(G38,H38,I38) -> 0
A39: =Zones!A39 -> Open_Office_Core_FloorT | B39: =Zones!J39 -> 21.415 | C39: =Zones!G39 -> 4283 | D39: =D3 -> 15 | E39: =E3 -> 0.15 | G39: =B39*D39 -> 321.225 | H39: =C39*E39 -> 642.45 | I39: =F39 -> 0 | J39: =MAX(G39,H39,I39) -> 642.45
A40: =Zones!A40 -> Open_Office_N_FloorT | B40: =Zones!J40 -> 11.489937 | C40: =Zones!G40 -> 2297.9873 | D40: =D4 -> 15 | E40: =E4 -> 0.15 | G40: =B40*D40 -> 172.34905 | H40: =C40*E40 -> 344.6981 | I40: =F40 -> 0 | J40: =MAX(G40,H40,I40) -> 344.6981
...

Sheet Water Heater
A1: Water Heater - OfficeMedium
A2: Vintage | B2: WH Type | C2: Efficiency | D2: Tank Volume (gal) | E2: Tank Loss | F2: Unit | G2: Source
A3: Existing | B3: Gas | C3: 0.8 | D3: =F70 -> 50 | E3: =G70 -> 855.51465 | F3: =H70 -> Btu/hr
A4: New Construction | B4: Gas | C4: 0.8 | D4: =F70 -> 50 | E4: =G70 -> 855.51465 | F4: =H70 -> Btu/hr
A8: Peak Hot Water Consumption
A9: Space Name | B9: Baseline WH Type [T24, 2022, Appendix 5.4A , sheet: "2022 SpaceFuncData-Input"] | C9: Total Area (ft²) | D9: Number of People | E9: Hot Water Usage Specification (gal/hr per person) [T24, 2022, Appendix 5.4A , sheet: "2022 SpaceFuncData-Input"] | F9: Peak Hot Water Usage (gal/hr) | G9: Peak Hot Water Usage (gal/min)
A10: =Zones!A3 -> Open_Office_Core_FloorG | B10: Gas | C10: =Zones!G3*Zones!I3 -> 4283 | D10: =Zones!J3*Zones!I3 -> 21.415 | E10: 0.18 | F10: =D10*E10 -> 3.8547 | G10: =F10/60 -> 0.064245
A11: =Zones!A4 -> Open_Office_N_FloorG | B11: Gas | C11: =Zones!G4*Zones!I4 -> 2297.9873 | D11: =Zones!J4*Zones!I4 -> 11.489937 | E11: 0.18 | F11: =D11*E11 -> 2.0681886 | G11: =F11/60 -> 0.03446981
A12: =Zones!A5 -> Closed_Office_W_FloorG | B12: Gas | C12: =Zones!G5*Zones!I5 -> 1637.8612 | D12: =Zones!J5*Zones!I5 -> 8.1893058 | E12: 0.18 | F12: =D12*E12 -> 1.474075 | G12: =F12/60 -> 0.024567917
A13: =Zones!A6 -> Closed_Office_E_FloorG | B13: Gas | C13: =Zones!G6*Zones!I6 -> 1637.8612 | D13: =Zones!J6*Zones!I6 -> 8.1893058 | E13: 0.18 | F13: =D13*E13 -> 1.474075 | G13: =F13/60 -> 0.024567917
A14: =Zones!A7 -> Open_Office_S_FloorG | B14: Gas | C14: =Zones!G7*Zones!I7 -> 1186.2075 | D14: =Zones!J7*Zones!I7 -> 5.9310376 | E14: 0.18 | F14: =D14*E14 -> 1.0675868 | G14: =F14/60 -> 0.017793113
A15: =Zones!A8 -> Conference_FloorG | B15: Gas | C15: =Zones!G8*Zones!I8 -> 1111.7798 | D15: =Zones!J8*Zones!I8 -> 36.688734 | E15: 0.09 | F15: =D15*E15 -> 3.301986 | G15: =F15/60 -> 0.055033101
A16: =Zones!A9 -> Lobby/Lounge_FloorG | B16: Gas | C16: =Zones!G9*Zones!I9 -> 1059.1755 | D16: =Zones!J9*Zones!I9 -> 10.591755 | E16: 0.09 | F16: =D16*E16 -> 0.95325792 | G16: =F16/60 -> 0.015887632
A17: =Zones!A10 -> Storage_FloorG | C17: =Zones!G10*Zones!I10 -> 983.15611 | E17: 0 | F17: =D17*E17 -> 0 | G17: =F17/60 -> 0
A18: =Zones!A11 -> Mechanical/Electrical_FloorG | B18: Gas | C18: =Zones!G11*Zones!I11 -> 357.35034 | E18: 0.18 | F18: =D18*E18 -> 0 | G18: =F18/60 -> 0
A19: =Zones!A12 -> IT-Room_FloorG | B19: Gas | C19: =Zones!G12*Zones!I12 -> 178.9373 | E19: 0.18 | F19: =D19*E19 -> 0 | G19: =F19/60 -> 0
A20: =Zones!A13 -> Restroom_FloorG | B20: Gas | C20: =Zones!G13*Zones!I13 -> 643.57783 | F20: =D20*E20 -> 0 | G20: =F20/60 -> 0
A21: =Zones!A14 -> Break_FloorG | B21: Gas | C21: =Zones!G14*Zones!I14 -> 232.34295 | D21: =Zones!J14*Zones!I14 -> 7.6673175 | E21: 0.09 | F21: =D21*E21 -> 0.69005857 | G21: =F21/60 -> 0.011500976
A22: =Zones!A15 -> Stairway_FloorG | C22: =Zones!G15*Zones!I15 -> 661.39226 | E22: 0 | F22: =D22*E22 -> 0 | G22: =F22/60 -> 0
A23: =Zones!A16 -> Corridor_W_FloorG | C23: =Zones!G16*Zones!I16 -> 300 | D23: =Zones!J16*Zones!I16 -> 1.5 | E23: 0 | F23: =D23*E23 -> 0 | G23: =F23/60 -> 0
A24: =Zones!A17 -> Corridor_N_FloorG | C24: =Zones!G17*Zones!I17 -> 502.9724 | D24: =Zones!J17*Zones!I17 -> 2.514862 | E24: 0 | F24: =D24*E24 -> 0 | G24: =F24/60 -> 0
A25: =Zones!A18 -> Corridor_E_FloorG | C25: =Zones!G18*Zones!I18 -> 299.2076 | D25: =Zones!J18*Zones!I18 -> 1.496038 | E25: 0 | F25: =D25*E25 -> 0 | G25: =F25/60 -> 0
A26: =Zones!A19 -> Corridor_S_FloorG | C26: =Zones!G19*Zones!I19 -> 502.9724 | D26: =Zones!J19*Zones!I19 -> 2.514862 | E26: 0 | F26: =D26*E26 -> 0 | G26: =F26/60 -> 0
A27: =Zones!A20 -> Plenum_FloorG | C27: =Zones!G20*Zones!I20 -> 17875.932 | E27: 0 | F27: =D27*E27 -> 0 | G27: =F27/60 -> 0
A28: =Zones!A21 -> Open_Office_Core_FloorM | B28: Gas | C28: =Zones!G21*Zones!I21 -> 4283 | D28: =Zones!J21*Zones!I21 -> 21.415 | E28: 0.18 | F28: =D28*E28 -> 3.8547 | G28: =F28/60 -> 0.064245
A29: =Zones!A22 -> Open_Office_N_FloorM | B29: Gas | C29: =Zones!G22*Zones!I22 -> 2297.9873 | D29: =Zones!J22*Zones!I22 -> 11.489937 | E29: 0.18 | F29: =D29*E29 -> 2.0681886 | G29: =F29/60 -> 0.03446981
A30: =Zones!A23 -> Closed_Office_W_FloorM | B30: Gas | C30: =Zones!G23*Zones!I23 -> 1637.8612 | D30: =Zones!J23*Zones!I23 -> 8.1893058 | E30: 0.18 | F30: =D30*E30 -> 1.474075 | G30: =F30/60 -> 0.024567917
A31: =Zones!A24 -> Closed_Office_E_FloorM | B31: Gas | C31: =Zones!G24*Zones!I24 -> 1637.8612 | D31: =Zones!J24*Zones!I24 -> 8.1893058 | E31: 0.18 | F31: =D31*E31 -> 1.474075 | G31: =F31/60 -> 0.024567917
A32: =Zones!A25 -> Open_Office_S_FloorM | B32: Gas | C32: =Zones!G25*Zones!I25 -> 1186.2075 | D32: =Zones!J25*Zones!I25 -> 5.9310376 | E32: 0.18 | F32: =D32*E32 -> 1.0675868 | G32: =F32/60 -> 0.017793113
A33: =Zones!A26 -> Conference_FloorM | B33: Gas | C33: =Zones!G26*Zones!I26 -> 1111.7798 | D33: =Zones!J26*Zones!I26 -> 36.688734 | E33: 0.09 | F33: =D33*E33 -> 3.301986 | G33: =F33/60 -> 0.055033101
A34: =Zones!A27 -> Lobby/Lounge_FloorM | B34: Gas | C34: =Zones!G27*Zones!I27 -> 1059.1755 | D34: =Zones!J27*Zones!I27 -> 10.591755 | E34: 0.09 | F34: =D34*E34 -> 0.95325792 | G34: =F34/60 -> 0.015887632
A35: =Zones!A28 -> Storage_FloorM | C35: =Zones!G28*Zones!I28 -> 983.15611 | E35: 0 | F35: =D35*E35 -> 0 | G35: =F35/60 -> 0
A36: =Zones!A29 -> Mechanical/Electrical_FloorM | B36: Gas | C36: =Zones!G29*Zones!I29 -> 357.35034 | E36: 0.18 | F36: =D36*E36 -> 0 | G36: =F36/60 -> 0
A37: =Zones!A30 -> IT-Room_FloorM | B37: Gas | C37: =Zones!G30*Zones!I30 -> 178.9373 | E37: 0.18 | F37: =D37*E37 -> 0 | G37: =F37/60 -> 0
A38: =Zones!A31 -> Restroom_FloorM | C38: =Zones!G31*Zones!I31 -> 643.57783 | E38: 0 | F38: =D38*E38 -> 0 | G38: =F38/60 -> 0
A39: =Zones!A32 -> Break_FloorM | B39: Gas | C39: =Zones!G32*Zones!I32 -> 232.34295 | D39: =Zones!J32*Zones!I32 -> 7.6673175 | E39: 0.09 | F39: =D39*E39 -> 0.69005857 | G39: =F39/60 -> 0.011500976
A40: =Zones!A33 -> Stairway_FloorM | C40: =Zones!G33*Zones!I33 -> 661.39226 | E40: 0 | F40: =D40*E40 -> 0 | G40: =F40/60 -> 0
A41: =Zones!A34 -> Corridor_W_FloorM | C41: =Zones!G34*Zones!I34 -> 300 | D41: =Zones!J34*Zones!I34 -> 1.5 | E41: 0 | F41: =D41*E41 -> 0 | G41: =F41/60 -> 0
A42: =Zones!A35 -> Corridor_N_FloorM | C42: =Zones!G35*Zones!I35 -> 502.9724 | D42: =Zones!J35*Zones!I35 -> 2.514862 | E42: 0 | F42: =D42*E42 -> 0 | G42: =F42/60 -> 0
A43: =Zones!A36 -> Corridor_E_FloorM | C43: =Zones!G36*Zones!I36 -> 299.2076 | D43: =Zones!J36*Zones!I36 -> 1.496038 | E43: 0 | F43: =D43*E43 -> 0 | G43: =F43/60 -> 0
...

Sheet Interior Lights
A1: ="Interior Lighting - " & Prototype!A2 -> Interior Lighting - OfficeMedium
A2: Space Type | B2: New Construction | E2: Existing | H2: Note
B3: LPD (W/ft²) | C3: Additional LPD for Portable Lighting (W/ft²) | D3: Source | E3: LPD (W/ft²) | F3: Additional LPD for Portable Lighting (W/ft²) | G3: Source
A4: Office Area (>250 square feet) | B4: 0.6 | D4: T24, part 6, 2025, Table 140.6 C | E4: 0.75 | G4: T24, part 6, 2013, Table 140.6 C
A5: Convention, Conference, Multipurpose and Meeting Area | B5: 0.75 | E5: 1.4
A6: Lobby, Main Entry | B6: 0.7 | E6: 1.1
A7: Storage (General) | B7: 0.4 | E7: 0.6
A8: Electrical, Mechanical, Telephone Rooms | B8: 0.4 | E8: 0.7
A9: IT Room (EPD 12) | B9: 1.1 | E9: 1.2
A10: Restrooms | B10: 0.6 | E10: 0.6
A11: Lounge, Breakroom, or Waiting Area | B11: 0.55 | E11: 1.1 | H11: 2013 LPD is for "Lounge" area
A12: Stairwell | B12: 0.6 | E12: 0.6
A13: Corridor Area | B13: 0.4 | E13: 0.6
A14: Plenum | B14: -
B17: Whole Building method
B18: 2025 | C18: 2013
A19: LPD for Office Building ((W/ft²) | B19: 0.6 | C19: 0.8
A20: Ref: T24, Table 140.6 B
A25: Background Data [To be deleted prior to publication]
A27: Ref: Title 24, Part 6- Table 140.6-C (office area >250nSF)
A28: Title 24, part 6 Code cycle | B28: Lighting density for office Buildings: (complete building Method) | C28: Lighting density for office area >250 sf Floor area Method | D28: Table | E28: Note | G28: T24, part 6 2022 | H28: file://carcgl.com/amer/NOR/Groups/CodesStds/Standards/California/2022%20Building%20Energy%20Efficiency%20Standards%20for%20Residential%20and%20Nonresidential%20Buildings.pdf
A29: 2025 | B29: 0.6 | C29: 0.6, 0.2 (additional) | D29: Table 140.6 C | G29: T24, part 6 2019 | H29: file://carcgl.com/amer/NOR/Groups/CodesStds/Standards/California/2016-CEC-400-2015-037-CMF.pdf
A30: 2022 | B30: 0.6 | C30: 0.6, 0.2 (additional) | G30: T24, part 6 2016 | H30: file://carcgl.com/amer/NOR/Groups/CodesStds/Standards/California/2016-CEC-400-2015-037-CMF.pdf
A31: 2019 | B31: 0.65
A32: 2016 | B32: 0.8
A33: 2013 | B33: 0.8 | C33: 0.75
A34: 2010 | B34: 0.85
A35: 2008 | B35: 0.085 | C35: 0.9 | D35: Table 146-E
A36: 2005 | C36: 1.2
A37: TBD: Review the CASE report on 2016 for lighting
A41: Review of existing Medium Office prototype
A42: Prototype/Source | B42: Downloaded on | C42: Zone | D42: Light Intensity | E42: Unit | F42: Total intensity multipliers | G42: Total lighting intensity | H42: Core/Perims area ratio | K42: Working days | L42: =52*5-L45 -> 249
A43: PNNL | B43: 45323 | C43: All | D43: 0.53920766 | E43: W/ft2 | F43: =F91*L42+G91*L43+H91*(L44+L45) -> 1988.2232 | G43: =D43*F43 -> 1072.0652 | H43: =149.66/(511.16-149.66) -> 0.41399723 | K43: Saturday | L43: 52
A44: CEC (CBECC 2023) | B44: 45444 | C44: All | D44: 0.6 | E44: W/ft2 | F44: =B91*L42+C91*L43+D91*(L44+L45) -> 2238.1 | G44: =D44*F44 -> 1342.86 | H44: =149.66/(511.16-149.66) -> 0.41399723 | K44: Sunday | L44: 52
K45: Holiday | L45: 11
A49: Interior lighting Schedules (existing prototypes extracted from the idf files (presented below)
B65: CEC | F65: PNNL
A66: Hour | B66: CEC-Weekday | C66: CEC-Saturday | D66: CEC-Sunday | F66: PNNL-Weekday | G66: PNNL-Saturday | H66: PNNL-Otherday
A67: 1 | B67: 0.05 | C67: 0.05 | D67: 0.05 | F67: 0.03597147 | G67: 0.03597147 | H67: 0.03597147
A68: =1+A67 -> 2 | B68: 0.05 | C68: 0.05 | D68: 0.05 | F68: 0.03597147 | G68: 0.03597147 | H68: 0.03597147
...

Sheet Ext Lighting
A1: ="Exterior Lighting - "&Prototype!A2 -> Exterior Lighting - OfficeMedium
A2: Motion Controlled Luminaires (W) | B2: Non-motion Controlled Luminaires (W) | C2: Total (W) | D2: Source
A3: =G12 -> 1860.2954 | B3: =G13 -> 856.2397 | C3: =B3+A3 -> 2716.5351 | D3: Title 24, 2022
A5: Exterior Lighting
A6: Items (Assume LZ2) | B6: Assumptions [2019 Outdoor Lighting CASE Report & PNNL 90.1-2010 TSD] | D6: Unit | E6: Lighting Power Allowance [T24, 2025, Table 140.7-A & 140.7-B] | F6: Unit | G6: Exterior Lighting Power (W)
A7: IWA (Initial Wage Allowance) | E7: 200 | F7: (W) | G7: =$E7 -> 200
A8: Parking area | B8: 400 ft² for every parking space 1 parking space per 250 ft² of gross building area | C8: =B19/250*400 -> 85805.02 | D8: (ft²) | E8: 0.019 | F8: (W/ft²) | G8: =$E8*C8 -> 1630.2954
A9: Building Entrance | B9: 2 building entrance (1 per 10,000 ft² footprint) | C9: 2 | D9: (count) | E9: 15 | F9: (W/ea) | G9: =E9*2 -> 30
A10: Hardscape Ornamental Light | B10: 0.1 ft² per 1 ft² of gross building area for hardscape ornamental light | C10: =B19*0.1 -> 5362.8137 | D10: (ft²) | E10: 0.007 | F10: (W/ft²) | G10: =E10*C10 -> 37.539696
A11: Building façade | B11: 0.1 W per ft² of facade area Façade Area* = Perimeter × 0.5 × 30 ft (30 ft is the max height that is lit) The 0.5 factor assumes that only half of the perimeter walls are lit. -Formula ia developed based on the 2019 Outdoor Lighting CASE report | C11: =B18*0.5*30 -> 8187 | D11: (ft²) | E11: 0.1 | F11: (W/ft²) | G11: =E11*C11 -> 818.7
A12: Motion controlled Luminaires | G12: =G8+G7+G9 -> 1860.2954
A13: Non-motion-controlled Luminaires | G13: =G10+G11 -> 856.2397
A14: Total | G14: =G12+G13 -> 2716.5351
A16: *Developed based on 2019 Outdoor Lighting CASE Report
A18: Perimeter (ft) | B18: =(163.7+109.2)*2 -> 545.8
A19: Total floor area (ft²) | B19: =Zones!G57 -> 53628.137
A20: Floors (above ground) | B20: 3
A26: Background Data [To be deleted prior to publication]
A31: Exterior Lighting
A32: Ref: Title 24, Part 6- Table 140.6-C (office area >250 SF)
A33: Title 24, part 6 Code cycle | B33: Lighting for parking area | C33: Daylight Adaptation Zones**
A34: 2022 | B34: 0.1 | C34: 1
A35: 2019 | B35: 0.1 | C35: 0.5
A36: 2016 | B36: 0.14 | C36: 0.6
A37: **Daylight Adaptation Zones shall be no farther than 66 feet from the entrance to the parking garage
A40: Exterior Lighting - OfficeLarge (CEUS 2022 data)
A41: Building Type | B41: Planning Area & Forecast Zone | C41: End Use Saturation or Penetration
A42: OfficeLarge | B42: Statewide | C42: 0.96516939
B43: FCZ1 | C43: 0.97338373
B44: FCZ2 | C44: 1
B45: FCZ3 | C45: 0.85484318
B46: FCZ4 | C46: 0.85484318
B47: FCZ5 | C47: 1
B48: FCZ6 | C48: 1
B49: FCZ7 | C49: 0.97219774
B50: FCZ8 | C50: 1
B51: FCZ9 | C51: 1
B52: FCZ10 | C52: 0.89872443
B53: FCZ11 | C53: 1
B54: FCZ12c | C54: 0.915507
...

Sheet Equipment
A1: ="Equipment - "&Prototype!A2 -> Equipment - OfficeMedium
A2: Space Type | B2: Plug load Power Density (W/ft²) | C2: Gas Power Density (Btu/hr-ft²) | D2: Refrigeration Power Density (W/ft²) | E2: Source
A3: Office Area (>250 square feet) | B3: 0.7 | E3: Plug load and schedules project with CEC , 2025
A4: Convention, Conference, Multipurpose and Meeting Area | B4: 0.8 | E4: T24 2022 - Appendix 5.4A
A5: Lobby, Main Entry | B5: 0.5
A6: Storage (General) | B6: 0.2
A7: Electrical, Mechanical, Telephone Rooms | B7: 3
A8: IT Room (EPD 12) | B8: 12 | E8: Feedback from TAG team
A9: Restrooms | B9: 0 | E9: T24 2022 - Appendix 5.4A
A10: Lounge, Breakroom, or Waiting Area | B10: 0.5
A11: Stairwell | B11: 0
A12: Corridor Area | B12: 0
A13: Plenum | B13: 0
A16: Elevator
A17: Vintages | B17: No of Elevator | C17: Design Load (W) | D17: Source
A18: New Construction and Existing | B18: 2 | C18: 13930 | D18: CEC Medium Office prototype in CBEC 2022
A20: PNNL Medium Office prototype has lower load for elevator ( 61% of the CEC). We've considered two elevators for Medium Office prototype and therefore prefer CEC's assumptions.
A31: Background Data [To be deleted prior to publication]
D34: Equipment (Plug Load )- Prototypes comparison
E35: CEC | F35: PNNL | G35: Note
D36: Core Zones | E36: 1.5 W/ft2 | F36: 7937.16 W
D37: Perimeter 3,1 | F37: 1673.21 W
D38: Perimeter 2,4 | F38: 1059.22 W
D39: Elevator | E39: 10000 W | F39: 8517.82 W
D40: Elevatoir_lights_Fan | F40: 105.31 W | H40: =(8517.8+105.3)/(10000+3930) -> 0.61903087
D41: Escalator | E41: 3930 W
C42: Yearly Load multiplier
C45: Office Area | L45: Elevator | U45: Escalator (only CEC) | Y45: Lights_Fan (ONLY PNNL)
C60: CEC 2022 | G60: PNNL 2022 | L60: =C60 -> CEC 2022 | P60: PNNL 2022 | U60: =L60 -> CEC 2022 | Y60: PNNL 2022
