Workbook
Name Space_Function: Data!$A$2:$A$76

Sheet Notes
A1: Data Sources
A2: Dataset | B2: Dodge 2023
B3: CEUS 2022
B4: CBECS 2018
B5: ComStock 2023
A6: Prototype | B6: CEC prototype (CBECC 2022.3.1) | C6: https://bees.noresco.com/software2022.html
B7: PNNL prototype (90.1-2022) | C7: https://www.energycodes.gov/prototype-building-models#Commercial
B8: DEER prototype (June 2023) | C8: https://github.com/sound-data/DEER-Prototypes-EnergyPlus
B9: ORNL 2019 Large Office prototype zoning | C9: https://www.sciencedirect.com/science/article/abs/pii/S0306261920312186
C10: https://publications.ibpsa.org/proceedings/simbuild/2020/papers/simbuild2020_C064.pdf
B11: Massachusetts Large Office prototype | C11: https://www.mass.gov/doc/large-office-prototype-basis-of-design-report/download
A12: Codes | B12: Title 24, part 6, referred to as T24 (1984, 2001, 2008, 2010, 2013, 2022, 2025)
B13: ASHRAE 90.1 (2022)
B14: CFR Title 10 (2010, 2024)
A15: Others | B15: ACM (2022)
B16: Title 24, 2022 - Appendix 5.4A and Appendix 5.4B | C16: https://www.energy.ca.gov/publications/2022/2022-nonresidential-and-multifamily-alternative-calculation-method-reference
B17: 2022 Reduced infiltration CASE report | C17: https://title24stakeholders.com/wp-content/uploads/2020/10/2022-T24-Final-CASE-Report_Reduce-Infiltration.pdf
B18: 2019 Outdoor Lighting CASE Report | C18: https://title24stakeholders.com/wp-content/uploads/2016/10/T24-2019-CASE-Study-Results-Report-Outdoor-Sources_Final_with-Attachments.pdf
B19: PNNL 20405, 2010 | C19: https://www.pnnl.gov/main/publications/external/technical_reports/PNNL-20405.pdf
B20: Air leakage Memo, NORESCO, 2025 | C20: Infiltration_rate_report_14May2025-Short-Version.docx
B21: Proposed Updates to Equipment Power Densities and Building Schedules for the 2028 Energy Code, referred to as "Plug load and schedules project with CEC, 2025" (Docket Number =25-BSTD-03 & TN=265693) | C21: https://efiling.energy.ca.gov/GetDocument.aspx?tn=265693&DocumentContentId=102545
A23: Construction Rate
I25: Total Floor area (thousands of sf)
H26: Pre-1978 | I26: 1978-1997 | J26: 1998-2007 | K26: 2008-2018 | L26: 2019-2022
H27: New Construction (2019+) | I27: 248465.9 | J27: 93016.2 | K27: 62305.7 | L27: 27851.1
B35: Source: Dodge 2023 data ( NEW large office built after 1967)
A36: Notes
A37: Large office building is defined as any office building with a total area >150,000 sf, by analyzing Dodge 2023 data.
A38: Large office buildings cover approximately 52% of the floor area and 7% of the total number of the CA office buildings (according to the Dodge 2023 datasets).
A39: Only 2% of offices in CA have stories >6 and area <150,000. (according to the Dodge 2023 datasets)
A40: Analysis of the Dodge 2023 dataset (see table and chart below) shows that the median and average number of stories and total floor area (not footprint of each story) are considerably smaller than those represented in the existing prototypes developed by PNNL and CBECC. This suggests that a smaller prototype might better reflect the California building stock. However, we have chosen to continue using the existing prototype floor area and number of stories for the following reasons:
A41: - Developing a smaller prototype would make the CEC prototype different from national Large Office prototype.
A42: - Change would likely have little impact on energy consumption on a per sf basis (kBTU/sf), nor would it result in different HVAC system design .
B45: Statical Analysis of the CA Large Office Building Stock (STC:7,305,405 & floor area>150 ksf) | C45: No. of Stories | D45: Footprint (sf) | E45: Total Area (sf)
B46: Median | C46: 6 | D46: 40000 | E46: 250000
B47: Average | C47: 9 | D47: 35555 | E47: 320000
B48: Source: Dodge 2023 data ( NEW large office buildings built after 1967)
B50: Existing Large Office Prototype | C50: No. of Stories | D50: Footprint* (sf) | E50: Total Area (sf)
B51: CBECC (CEC) 2022 | C51: 13 | D51: 38400 | E51: 498000
B52: PNNL ASHRAE 90.1 2022 | C52: 13 | D52: 38400 | E52: 498000
...

Sheet Prototype
A1: NORESCO, Updated November 2025
A2: OfficeLarge
A3: Characteristic | B3: Value | C3: Data Sources
A4: Building Type | B4: Large Office
A5: Building Category | B5: Nonresidential
A6: Vintages | B6: 4 Vintages: Pre-1978 , 1978-1997 ,1998-2007 , 2008-2018 New Construction (2019+) | C6: Based on the vintage bin analysis | D6: NonRes-Vintage bins-Draft Report-30Nov2023-Final.docx
A7: Shape | C7: Number of floors: Based on the existing Large Office prototypes (PNNL, CEC) Footprint (floor area of each story): Supported by Dodge 2023 data and consistent with the existing Large Office prototypes Zone configuration and floor plan layout: Based on the ORNL 2019 project, with modifications informed by engineering and architectural judgment (see the "Zones" tab for more details) | D7: https://publications.ibpsa.org/proceedings/simbuild/2020/papers/simbuild2020_C064.pdf
A8: Total Floor Area (ft2) | B8: 498,589 (240 ft *160 ft) | C8: Same as CEC and PNNL
A9: Aspect Ratio | B9: 1.5 | C9: Same as CEC and PNNL
A10: Number of Floors | B10: 12 Floor + basement | C10: Number of floor: based on the existing Large Office prototypes (PNNL,CEC)
A11: Roof type | B11: Flat | C11: Supported by CBECS 2018 data (Same as CEC and PNNL)
A12: WWR | B12: 40% of the above grade wall
A13: Window dimensions | B13: Even distribution
A14: Shading Geometry | B14: None
A15: Floor to floor height (feet) | B15: 13 | C15: Same as CEC and PNNL
A16: Floor to ceiling height (feet) | B16: 9 | C16: Same as CEC and PNNL
A17: Glazing sill height (feet) | B17: 3 | C17: Same as CEC and PNNL

Sheet Envelope
A1: ="Envelope - "&Prototype!A2 -> Envelope - OfficeLarge
A2: Element | B2: Prototype | C2: Assembly Type | D2: Construction | E2: Thermal Properties | F2: Vintage | G2: Selected T24 | H2: Note | I2: CZ1 | J2: CZ2 | K2: CZ3 | L2: CZ4 | M2: CZ5 | N2: CZ6 | O2: CZ7 | P2: CZ8 | Q2: CZ9 | R2: CZ10 | S2: CZ11 | T2: CZ12 | U2: CZ13 | V2: CZ14 | W2: CZ15 | X2: CZ16
A3: External Wall | B3: OfficeLarge | C3: ExtWall_MetalFramed_NonRes | D3: Metal frame + insulation + Gypsum board | E3: U-factor IP | F3: Pre 1978 | G3: N/A | H3: ASHRAE 90.1 Table A3.3.3.1, 16" on center, R-0 | I3: 0.352 | J3: 0.352 | K3: 0.352 | L3: 0.352 | M3: 0.352 | N3: 0.352 | O3: 0.352 | P3: 0.352 | Q3: 0.352 | R3: 0.352 | S3: 0.352 | T3: 0.352 | U3: 0.352 | V3: 0.352 | W3: 0.352 | X3: 0.352
F4: 1978-1997 | G4: 1986 | H4: High-rise office: Package A with heat capacity 10.0-14.99 (BTU/F/ft2) | I4: =1/4.7 -> 0.21276596 | J4: =1/4.4 -> 0.22727273 | K4: =1/4.4 -> 0.22727273 | L4: =1/4.6 -> 0.2173913 | M4: =1/4.6 -> 0.2173913 | N4: =1/3.9 -> 0.25641026 | O4: =1/3.9 -> 0.25641026 | P4: =1/3.9 -> 0.25641026 | Q4: =1/3.9 -> 0.25641026 | R4: =1/3.9 -> 0.25641026 | S4: =1/4.2 -> 0.23809524 | T4: =1/4.2 -> 0.23809524 | U4: =1/4.2 -> 0.23809524 | V4: =1/4.8 -> 0.20833333 | W4: =1/4.8 -> 0.20833333 | X4: =1/4.7 -> 0.21276596
F5: 1998-2007 | G5: 2001 | I5: 0.182 | J5: 0.182 | K5: 0.189 | L5: 0.189 | M5: 0.189 | N5: 0.189 | O5: 0.189 | P5: 0.189 | Q5: 0.189 | R5: 0.182 | S5: 0.182 | T5: 0.182 | U5: 0.182 | V5: 0.182 | W5: 0.182 | X5: 0.182
F6: 2008-2018 | G6: 2013 | I6: 0.098 | J6: 0.062 | K6: 0.082 | L6: 0.062 | M6: 0.062 | N6: 0.098 | O6: 0.098 | P6: 0.062 | Q6: 0.062 | R6: 0.062 | S6: 0.062 | T6: 0.062 | U6: 0.062 | V6: 0.062 | W6: 0.062 | X6: 0.062
F7: 2019+ | G7: 2025 | I7: 0.06 | J7: 0.055 | K7: 0.071 | L7: 0.055 | M7: 0.055 | N7: 0.06 | O7: 0.06 | P7: 0.055 | Q7: 0.055 | R7: 0.055 | S7: 0.055 | T7: 0.055 | U7: 0.055 | V7: 0.055 | W7: 0.055 | X7: 0.055
A8: Roof | B8: OfficeLarge | C8: FlatRoof_WoodFramedAndOther_NonRes | D8: Metal deck + insulation + Roof membrane | E8: U-factor IP | F8: Pre 1978 | G8: N/A | H8: Considering 30 years for roof/ insulation replacement. | I8: =I9 -> 0.057 | J8: =J9 -> 0.057 | K8: =K9 -> 0.057 | L8: =L9 -> 0.057 | M8: =M9 -> 0.057 | N8: =N9 -> 0.078 | O8: =O9 -> 0.078 | P8: =P9 -> 0.078 | ... X8: =X9 -> 0.057
F9: 1978-1997 | G9: 1992 | I9: 0.057 | J9: 0.057 | K9: 0.057 | L9: 0.057 | M9: 0.057 | N9: 0.078 | O9: 0.078 | P9: 0.078 | Q9: 0.078 | R9: 0.078 | S9: 0.057 | T9: 0.057 | U9: 0.057 | V9: 0.057 | W9: 0.057 | X9: 0.057
F10: 1998-2007 | G10: 2001 | I10: 0.057 | J10: 0.057 | K10: 0.057 | L10: 0.057 | M10: 0.057 | N10: 0.078 | O10: 0.078 | P10: 0.078 | Q10: 0.078 | R10: 0.057 | S10: 0.057 | T10: 0.057 | U10: 0.057 | V10: 0.057 | W10: 0.057 | X10: 0.057
F11: 2008-2018 | G11: 2013 | I11: 0.049 | J11: 0.039 | K11: 0.039 | L11: 0.039 | M11: 0.049 | N11: 0.075 | O11: 0.067 | P11: 0.067 | Q11: 0.039 | R11: 0.039 | S11: 0.039 | T11: 0.039 | U11: 0.039 | V11: 0.039 | W11: 0.039 | X11: 0.039
F12: 2019+ | G12: 2025 | I12: 0.028 | J12: 0.028 | K12: 0.028 | L12: 0.028 | M12: 0.028 | N12: 0.047 | O12: 0.047 | P12: 0.047 | Q12: 0.028 | R12: 0.028 | S12: 0.028 | T12: 0.028 | U12: 0.028 | V12: 0.028 | W12: 0.028 | X12: 0.028
A13: Windows | B13: OfficeLarge | C13: FixedWindow_NonRes | D13: CBECS 2018 shows that ~50% of large offices that were built before 2000 are single pane | E13: U-factor IP | F13: Pre 1978 | G13: N/A | H13: ASHRAE Handbook of Fundamentals for single pane (Table 4-Ch15) & T24, 2013 for double pane(50%-50%)* | I13: =1.12*0.5+I$16*0.5 -> 0.74 | J13: =1.12*0.5+J$16*0.5 -> 0.74 | K13: =1.12*0.5+K$16*0.5 -> 0.74 | L13: =1.12*0.5+L$16*0.5 -> 0.74 | M13: =1.12*0.5+M$16*0.5 -> 0.74 | N13: =1.12*0.5+N$16*0.5 -> 0.74 | O13: =1.12*0.5+O$16*0.5 -> 0.74 | P13: =1.12*0.5+P$16*0.5 -> 0.74 | ... X13: =1.12*0.5+X$16*0.5 -> 0.74
F14: 1978-1997 | G14: N/A | I14: =1.12*0.5+I$16*0.5 -> 0.74 | J14: =1.12*0.5+J$16*0.5 -> 0.74 | K14: =1.12*0.5+K$16*0.5 -> 0.74 | L14: =1.12*0.5+L$16*0.5 -> 0.74 | M14: =1.12*0.5+M$16*0.5 -> 0.74 | N14: =1.12*0.5+N$16*0.5 -> 0.74 | O14: =1.12*0.5+O$16*0.5 -> 0.74 | P14: =1.12*0.5+P$16*0.5 -> 0.74 | ... X14: =1.12*0.5+X$16*0.5 -> 0.74
D15: Double pane | F15: 1998-2007 | G15: 2001 | I15: 0.49 | J15: 0.49 | K15: 0.81 | L15: 0.81 | M15: 0.81 | N15: 0.81 | O15: 0.81 | P15: 0.81 | Q15: 0.81 | R15: 0.49 | S15: 0.49 | T15: 0.49 | U15: 0.49 | V15: 0.49 | W15: 0.49 | X15: 0.49
F16: 2008-2018 | G16: 2013 | I16: 0.36 | J16: 0.36 | K16: 0.36 | L16: 0.36 | M16: 0.36 | N16: 0.36 | O16: 0.36 | P16: 0.36 | Q16: 0.36 | R16: 0.36 | S16: 0.36 | T16: 0.36 | U16: 0.36 | V16: 0.36 | W16: 0.36 | X16: 0.36
F17: 2019+ | G17: 2025 | I17: 0.36 | J17: 0.36 | K17: 0.36 | L17: 0.36 | M17: 0.36 | N17: 0.36 | O17: 0.36 | P17: 0.36 | Q17: 0.34 | R17: 0.36 | S17: 0.34 | T17: 0.34 | U17: 0.34 | V17: 0.34 | W17: 0.34 | X17: 0.36
C18: FixedWindow_NonRes | D18: CBECS 2018 shows that ~50% of large offices that were built before 2000 are single pane | E18: SHGC | F18: Pre 1978 | G18: N/A | H18: ASHRAE Handbook of Fundamentals for single pane (Table 10-Ch15) & T24, 2013 for double pane(50%-50%)* | I18: =0.79*0.5+I$21*0.5 -> 0.52 | J18: =0.79*0.5+J$21*0.5 -> 0.52 | K18: =0.79*0.5+K$21*0.5 -> 0.52 | L18: =0.79*0.5+L$21*0.5 -> 0.52 | M18: =0.79*0.5+M$21*0.5 -> 0.52 | N18: =0.79*0.5+N$21*0.5 -> 0.52 | O18: =0.79*0.5+O$21*0.5 -> 0.52 | P18: =0.79*0.5+P$21*0.5 -> 0.52 | ... X18: =0.79*0.5+X$21*0.5 -> 0.52
F19: 1978-1997 | G19: N/A | I19: =I18 -> 0.52 | J19: =J18 -> 0.52 | K19: =K18 -> 0.52 | L19: =L18 -> 0.52 | M19: =M18 -> 0.52 | N19: =N18 -> 0.52 | O19: =O18 -> 0.52 | P19: =P18 -> 0.52 | ... X19: =X18 -> 0.52
F20: 1998-2007 | G20: 2001 | H20: WWR:20-30 / SHGC non-north (Non-north SHGC is more stringent than north and is therefore considered for all sides) | I20: 0.43 | J20: 0.36 | K20: 0.41 | L20: 0.41 | M20: 0.41 | N20: 0.39 | O20: 0.39 | P20: 0.39 | Q20: 0.39 | R20: 0.36 | S20: 0.36 | T20: 0.36 | U20: 0.36 | V20: 0.36 | W20: 0.36 | X20: 0.43
F21: 2008-2018 | G21: 2013 | I21: 0.25 | J21: 0.25 | K21: 0.25 | L21: 0.25 | M21: 0.25 | N21: 0.25 | O21: 0.25 | P21: 0.25 | Q21: 0.25 | R21: 0.25 | S21: 0.25 | T21: 0.25 | U21: 0.25 | V21: 0.25 | W21: 0.25 | X21: 0.25
F22: 2019+ | G22: 2025 | I22: 0.25 | J22: 0.25 | K22: 0.25 | L22: 0.25 | M22: 0.25 | N22: 0.25 | O22: 0.25 | P22: 0.25 | Q22: 0.22 | R22: 0.25 | S22: 0.22 | T22: 0.22 | U22: 0.22 | V22: 0.22 | W22: 0.22 | X22: 0.25
E24: Infiltration rate at normal pressure (cfm/ft2) (Design flow rate approach and Flow/Exterior Wall Area calculation method)
F25: Vintage | G25: I_75 (cfm/sf) 6-sdied Infiltration rate @ 75 pa | H25: Note | I25: I-design (cfm/ft2) (4-sided Infiltration rate at normal pressure) (Design flow rate approach and Flow/Exterior Wall Area calculation method)
E26: Infiltration | F26: Pre 1978 | G26: 1.1 | H26: 2022 CASE report (Table 38) | I26: 0.2053
F27: 1978-1997 | G27: 1.1 | H27: 2022 CASE report (Table 38) | I27: 0.2053
F28: 1998-2007 | G28: 1.1 | H28: 2022 CASE report (Table 38) | I28: 0.2053
F29: 2008-2018 | G29: 1 | H29: 2022 CASE report (Table 38) & Title 24, part 6, 2008-2016 (Table 140.3-B) | I29: 0.1878
F30: 2019+ | G30: 0.6 | H30: 2022 CASE report (Table 38) & Title 24, part 6, 2025 (Table 140.3-B) | I30: 0.112
E31: Source: Title 24 air barrier requirements (all editions) and the standardized infiltration rate reported in the 2022 CASE report and Dodge 2023 data
E32: Air Leakage Memo: | G32: Infiltration_rate_report_14May2025-Short-Version.docx
A35: *Note for windows properties in vintage 1 &2 :
A36: We’ve considered a 50% single-pane and 50% double-pane mix (based on the 2013 requirements) for the window properties in Vintage 1 & 2 (pre-1998 buildings).
A37: We don't have California-specific data, and the decision was based on the CBECS 2018 data, which indicates:
A38: - 30% of large offices built before 1978 have mixed windows, while only 16% of large offices from the second vintage (1978-1997) have mixed glass.
A39: - Pre-1980: Among those with either single or double-pane windows, 70% have single-pane windows, and 30% have double-pane windows.
A40: - 1980-1999: Among those with either single or double-pane windows, 43% have single-pane windows, and 57% have double-pane windows.
A41: - Pre-2000: Among those with either single or double-pane windows, 49% has single pane windows.
A42: Considering the Pre-2000 percentage, we've decided to apply the 50%-50% mix to the window properties of the first two vintages.
C49: Fixed windows | D49: Double pane | E49: SHGC | F49: 1998-2007 | G49: 2001 | H49: WWR:20-30 / SHGC north | I49: 0.47 | J49: 0.47 | K49: 0.61 | L49: 0.61 | M49: 0.61 | N49: 0.61 | O49: 0.61 | P49: 0.61 | Q49: 0.61 | R49: 0.47 | S49: 0.47 | T49: 0.47 | U49: 0.47 | V49: 0.47 | W49: 0.47 | X49: 0.47
...

Sheet Zones
A1: ="Proposed Layout - "&Prototype!A2 -> Proposed Layout - OfficeLarge
A2: Space/ Thermal Zone | B2: Space Type | C2: HVAC System Name/AHU Name | D2: Schedule Category | E2: Conditioned (Y/N) | F2: Area Fraction | G2: Area (ft²) | H2: Volume (ft³) | I2: Multipliers | J2: Number of People | K2: People (Persons/1,000 ft²) [T24, 2025,Table 120.1-A]
A3: Perimeter_Open_ Office_N_Basement | B3: Office Area (>250 square feet) | C3: VAV With Reheat_Basement | D3: Office | E3: Y | F3: =G3/$G$82 -> 0.016883955 | G3: 8416.86 | H3: =G3*Prototype!$B$16 -> 75751.74 | I3: 1 | J3: =IFERROR(K3*G3/1000,"") -> 42.0843 | K3: 5
A4: Perimeter_Open_ Office_S_Basement | B4: Office Area (>250 square feet) | C4: VAV With Reheat_Basement | D4: Office | E4: Y | F4: =G4/$G$82 -> 0.0073462172 | G4: 3662.18 | H4: =G4*Prototype!$B$16 -> 32959.62 | I4: 1 | J4: =IFERROR(K4*G4/1000,"") -> 18.3109 | K4: =K3 -> 5
A5: Core_Enclosed_Office_Basement | B5: Office Area (>250 square feet) | C5: VAV With Reheat_Basement | D5: Office | E5: Y | F5: =G5/$G$82 -> 0.0074294649 | G5: 3703.68 | H5: =G5*Prototype!$B$16 -> 33333.12 | I5: 1 | J5: =IFERROR(K5*G5/1000,"") -> 18.5184 | K5: =K3 -> 5
A6: Server_Room_Basement | B6: Server Room (EPD 45) | C6: CRAH_ServerRoom_Basement | D6: Data | E6: Y | F6: =G6/$G$82 -> 0.016505108 | G6: 8228 | H6: =G6*Prototype!$B$16 -> 74052 | I6: 1 | J6: =IFERROR(K6*G6/1000,"") -> 0 | K6: 0
A7: Mech/Elec_Basement | B7: Electrical, Mechanical, Telephone Rooms | C7: VAV With Reheat_Basement | D7: Office | E7: Y | F7: =G7/$G$82 -> 0.015963496 | G7: 7958 | H7: =G7*Prototype!$B$16 -> 71622 | I7: 1 | J7: =IFERROR(K7*G7/1000,"") -> 0 | K7: 0
A8: Conference_Basement | B8: Convention, Conference, Multipurpose and Meeting Area | C8: VAV With Reheat_Basement | D8: Office | E8: Y | F8: =G8/$G$82 -> 0.0011628599 | G8: 579.7 | H8: =G8*Prototype!$B$16 -> 5217.3 | I8: 1 | J8: =IFERROR(K8*G8/1000,"") -> 19.1301 | K8: 33
A9: Break_Basement | B9: Lounge, Breakroom, or Waiting Area | C9: VAV With Reheat_Basement | D9: Office | E9: Y | F9: =G9/$G$82 -> 0.0019518072 | G9: 973 | H9: =G9*Prototype!$B$16 -> 8757 | I9: 1 | J9: =IFERROR(K9*G9/1000,"") -> 32.109 | K9: 33
A10: Storage_Basement | B10: Storage (General) | C10: VAV With Reheat_Basement | D10: Office | E10: Y | F10: =G10/$G$82 -> 0.002469347 | G10: 1231 | H10: =G10*Prototype!$B$16 -> 11079 | I10: 1 | J10: =IFERROR(K10*G10/1000,"") -> 0 | K10: 0
A11: Restroom_Basement | B11: Restrooms | C11: VAV With Reheat_Basement | D11: Office | E11: Y | F11: =G11/$G$82 -> 0.0019778848 | G11: 986 | H11: =G11*Prototype!$B$16 -> 8874 | I11: 1 | J11: =IFERROR(K11*G11/1000,"") -> 0 | K11: 0
A12: Lobby_Basement | B12: Lobby, Main Entry | C12: VAV With Reheat_Basement | D12: Office | E12: Y | F12: =G12/$G$82 -> 0.0014182196 | G12: 707 | H12: =G12*Prototype!$B$16 -> 6363 | I12: 1 | J12: =IFERROR(K12*G12/1000,"") -> 7.07 | K12: 10 | L12: Number of People: 10 according to ASHRAE 62.1 Table 6-1 for main entry lobbies T24: 33 for main Entry lobbies & 5 for reception area
A13: Stair/Elevator_Basement | B13: Stairwell | C13: VAV With Reheat_Basement | D13: Office | E13: Y | F13: =G13/$G$82 -> 0.0018876162 | G13: 941 | H13: =G13*Prototype!$B$16 -> 8469 | I13: 1 | J13: =IFERROR(K13*G13/1000,"") -> 0 | K13: 0
A14: Corridor_W_Basement | B14: Corridor Area | C14: VAV With Reheat_Basement | D14: Office | E14: Y | F14: =G14/$G$82 -> 0.00052736908 | G14: 262.9 | H14: =G14*Prototype!$B$16 -> 2366.1 | I14: 1 | J14: =IFERROR(K14*G14/1000,"") -> 1.3145 | K14: 5
A15: Corridor_E_Basement | B15: Corridor Area | C15: VAV With Reheat_Basement | D15: Office | E15: Y | F15: =G15/$G$82 -> 0.0014101958 | G15: 703 | H15: =G15*Prototype!$B$16 -> 6327 | I15: 1 | J15: =IFERROR(K15*G15/1000,"") -> 3.515 | K15: 5
A16: Perimeter_Open_ Office_N_FloorG | B16: Office Area (>250 square feet) | C16: VAV With Reheat_FloorG | D16: Office | E16: Y | F16: =G16/$G$82 -> 0.014103964 | G16: 7031 | H16: =G16*Prototype!$B$16 -> 63279 | I16: 1 | J16: =IFERROR(K16*G16/1000,"") -> 35.155 | K16: =$K$3 -> 5
A17: Perimeter_Open_ Office_W_FloorG | B17: Office Area (>250 square feet) | C17: VAV With Reheat_FloorG | D17: Office | E17: Y | F17: =G17/$G$82 -> 0.011626111 | G17: 5795.76 | H17: =G17*Prototype!$B$16 -> 52161.84 | I17: 1 | J17: =IFERROR(K17*G17/1000,"") -> 28.9788 | K17: =$K$3 -> 5
A18: Perimeter_Open_ Office_E_FloorG | B18: Office Area (>250 square feet) | C18: VAV With Reheat_FloorG | D18: Office | E18: Y | F18: =G18/$G$82 -> 0.011786027 | G18: 5875.48 | H18: =G18*Prototype!$B$16 -> 52879.32 | I18: 1 | J18: =IFERROR(K18*G18/1000,"") -> 29.3774 | K18: =$K$3 -> 5
A19: Perimeter_Enclosed_ Office_NE_FloorG | B19: Office Area (>250 square feet) | C19: VAV With Reheat_FloorG | D19: Office | E19: Y | F19: =G19/$G$82 -> 0.0018402353 | G19: 917.38 | H19: =G19*Prototype!$B$16 -> 8256.42 | I19: 1 | J19: =IFERROR(K19*G19/1000,"") -> 4.5869 | K19: =$K$3 -> 5
A20: Perimeter_Enclosed_ Office_NW_FloorG | B20: Office Area (>250 square feet) | C20: VAV With Reheat_FloorG | D20: Office | E20: Y | F20: =G20/$G$82 -> 0.0022679679 | G20: 1130.61 | H20: =G20*Prototype!$B$16 -> 10175.49 | I20: 1 | J20: =IFERROR(K20*G20/1000,"") -> 5.65305 | K20: =$K$3 -> 5 | N20: Basement | T20: First Floor | Y20: Middle/Top Floors
A21: Core_Enclosed_Office_FloorG | B21: Office Area (>250 square feet) | C21: VAV With Reheat_FloorG | D21: Office | E21: Y | F21: =G21/$G$82 -> 0.0066437672 | G21: 3312 | H21: =G21*Prototype!$B$16 -> 29808 | I21: 1 | J21: =IFERROR(K21*G21/1000,"") -> 16.56 | K21: =$K$3 -> 5
A22: Server_Room_FloorG | B22: Computer Room (EPD 20) | C22: CRAC DX Clg_FloorG | D22: Data | E22: Y | F22: =G22/$G$82 -> 0.00083837442 | G22: 417.94 | H22: =G22*Prototype!$B$16 -> 3761.46 | I22: 1 | J22: =IFERROR(K22*G22/1000,"") -> 0 | K22: 0 | O22: Spaces of Basement​ | P22: Area (ft2)​ | Q22: % of footprint | T22: Spaces of First Floor​ | U22: Area (ft2)​ | V22: % of footprint | Y22: Spaces of Middle/Top Floor​s | Z22: Area (ft2)​ | AA22: % of footprint
A23: Mech/Elec_FloorG | B23: Electrical, Mechanical, Telephone Rooms | C23: VAV With Reheat_FloorG | D23: Office | E23: Y | F23: =G23/$G$82 -> 0.0017030671 | G23: 849 | H23: =G23*Prototype!$B$16 -> 7641 | I23: 1 | J23: =IFERROR(K23*G23/1000,"") -> 0 | K23: 0 | O23: Open office​ | P23: =G3+G4 -> 12079.04 | Q23: =P23/$P$36 -> 0.31494381 | T23: Open office​ | U23: =G17+G18+G16 -> 18702.24 | V23: =U23/$P$36 -> 0.48763434 | Y23: Open office​ | Z23: =G36+G37+G38+G39 -> 21287.86 | AA23: =Z23/$P$36 -> 0.55505071
A24: Conference_FloorG | B24: Convention, Conference, Multipurpose and Meeting Area | C24: VAV With Reheat_FloorG | D24: Office | E24: Y | F24: =G24/$G$82 -> 0.001584715 | G24: 790 | H24: =G24*Prototype!$B$16 -> 7110 | I24: 1 | J24: =IFERROR(K24*G24/1000,"") -> 26.07 | K24: 33 | O24: Core Enclosed Office​ | P24: =G5 -> 3703.68 | Q24: =P24/$P$36 -> 0.096568195 | T24: Core Enclosed Office​ | U24: =G21 -> 3312 | V24: =U24/$P$36 -> 0.086355696 | Y24: Core Enclosed Office​ | Z24: =G44 -> 3233 | AA24: =Z24/$P$36 -> 0.084295883
A25: Break_FloorG | B25: Lounge, Breakroom, or Waiting Area | C25: VAV With Reheat_FloorG | D25: Office | E25: Y | F25: =G25/$G$82 -> 0.0012397887 | G25: 618.05 | H25: =G25*Prototype!$B$16 -> 5562.45 | I25: 1 | J25: =IFERROR(K25*G25/1000,"") -> 20.39565 | K25: 33 | O25: Perimeter Enclosed Office​ | P25: _ | Q25: _ | T25: Perimeter Enclosed Office​ | U25: =G20+G19 -> 2047.99 | V25: =U25/$P$36 -> 0.05339843 | Y25: Perimeter Enclosed Office​ | Z25: =G40+G41+G42+G43 -> 4092.56 | AA25: =Z25/$P$36 -> 0.10670769
A26: FoodPrep_FloorG | B26: Kitchen/Food Preparation Area | C26: VAV With Reheat_FloorG | D26: Office | E26: Y | F26: =G26/$G$82 -> 0.001879472 | G26: 936.94 | H26: =G26*Prototype!$B$16 -> 8432.46 | I26: 1 | J26: =IFERROR(K26*G26/1000,"") -> 2.81082 | K26: 3 | O26: Conference​ | P26: =G8 -> 579.7 | Q26: =P26/$P$36 -> 0.015114854 | T26: Conference​ | U26: =G24 -> 790 | V26: =U26/$P$36 -> 0.020598128 | Y26: Conference​ | Z26: =G47+G48+G49+G50 -> 2323.24 | AA26: =Z26/$P$36 -> 0.060575183
A27: Storage_FloorG | B27: Storage (General) | C27: VAV With Reheat_FloorG | D27: Office | E27: Y | F27: =G27/$G$82 -> 0.0019237638 | G27: 959.02 | H27: =G27*Prototype!$B$16 -> 8631.18 | I27: 1 | J27: =IFERROR(K27*G27/1000,"") -> 0 | K27: 0 | O27: Break + Food prep​ | P27: =G9 -> 973 | Q27: =P27/$P$36 -> 0.025369593 | T27: Break + Food prep​ | U27: =G26+G25 -> 1554.99 | V27: =U27/$P$36 -> 0.040544156 | Y27: Break + Food prep​ | Z27: =G51 -> 910 | AA27: =Z27/$P$36 -> 0.023726957
A28: Locker_FloorG | B28: Locker Room | C28: VAV With Reheat_FloorG | D28: Office | E28: Y | F28: =G28/$G$82 -> 0.0036407724 | G28: 1814.97 | H28: =G28*Prototype!$B$16 -> 16334.73 | I28: 1 | J28: =IFERROR(K28*G28/1000,"") -> 18.1497 | K28: 10 | L28: Based on 2022 CEC AP5 | O28: Storage​ | P28: =G10 -> 1231 | Q28: =P28/$P$36 -> 0.032096577 | T28: Storage​+locker | U28: =G28+G27 -> 2773.99 | V28: =U28/$P$36 -> 0.072327849 | Y28: Storage​ | Z28: =G52 -> 738 | AA28: =Z28/$P$36 -> 0.019242302
A29: Lobby_S_FloorG | B29: Lobby, Main Entry | C29: VAV With Reheat_FloorG | D29: Office | E29: Y | F29: =G29/$G$82 -> 0.0067413174 | G29: 3360.63 | H29: =G29*Prototype!$B$16 -> 30245.67 | I29: 1 | J29: =IFERROR(K29*G29/1000,"") -> 33.6063 | K29: =K12 -> 10 | O29: Mech/Elec​ | P29: =G7 -> 7958 | Q29: =P29/$P$36 -> 0.20749355 | T29: Mech/Elec​ | U29: =G23 -> 849 | V29: =U29/$P$36 -> 0.022136469 | Y29: Mech/Elec​ | Z29: =G46 -> 1070 | AA29: =Z29/$P$36 -> 0.02789873
A30: Lobby_FloorG | B30: Lobby, Main Entry | C30: VAV With Reheat_FloorG | D30: Office | E30: Y | F30: =G30/$G$82 -> 0.0013707985 | G30: 683.36 | H30: =G30*Prototype!$B$16 -> 6150.24 | I30: 1 | J30: =IFERROR(K30*G30/1000,"") -> 6.8336 | K30: =K12 -> 10 | O30: Server Room​ | P30: =G6 -> 8228 | Q30: =P30/$P$36 -> 0.21453341 | T30: Server Room​ | U30: =G22 -> 417.94 | V30: =U30/$P$36 -> 0.010897192 | Y30: Server Room​ | Z30: =G45 -> 418 | AA30: =Z30/$P$36 -> 0.010898756
A31: Restroom_FloorG | B31: Restrooms | C31: VAV With Reheat_FloorG | D31: Office | E31: Y | F31: =G31/$G$82 -> 0.0023188994 | G31: 1156 | H31: =G31*Prototype!$B$16 -> 10404 | I31: 1 | J31: =IFERROR(K31*G31/1000,"") -> 0 | K31: 0 | O31: Corridor​ | P31: =G14+G15 -> 965.9 | Q31: =P31/$P$36 -> 0.025184471 | T31: Corridor​ | U31: =G34+G33 -> 1803.99 | V31: =U31/$P$36 -> 0.047036477 | Y31: Corridor​ | Z31: =G56+G57 -> 1591.24 | AA31: =Z31/$P$36 -> 0.041489323
A32: Stair/Elevator_FloorG | B32: Stairwell | C32: VAV With Reheat_FloorG | D32: Office | E32: Y | F32: =G32/$G$82 -> 0.0017010612 | G32: 848 | H32: =G32*Prototype!$B$16 -> 7632 | I32: 1 | J32: =IFERROR(K32*G32/1000,"") -> 0 | K32: 0 | O32: Restroom​ | P32: =G11 -> 986 | Q32: =P32/$P$36 -> 0.02570855 | T32: Restroom​ | U32: =G31 -> 1156 | V32: =U32/$P$36 -> 0.030141058 | Y32: Restroom​ | Z32: =G54 -> 1155 | AA32: =Z32/$P$36 -> 0.030114984
A33: Corridor_W_FloorG | B33: Corridor Area | C33: VAV With Reheat_FloorG | D33: Office | E33: Y | F33: =G33/$G$82 -> 0.0020177635 | G33: 1005.88 | H33: =G33*Prototype!$B$16 -> 9052.92 | I33: 1 | J33: =IFERROR(K33*G33/1000,"") -> 5.0294 | K33: 5 | O33: Lobby​ | P33: =G12 -> 707 | Q33: =P33/$P$36 -> 0.018434021 | T33: Lobby​ | U33: =G30+G29 -> 4043.99 | V33: =U33/$P$36 -> 0.1054413 | Y33: Lobby​ | Z33: =G53 -> 684 | AA33: =Z33/$P$36 -> 0.017834328
A34: Corridor_E_FloorG | B34: Corridor Area | C34: VAV With Reheat_FloorG | D34: Office | E34: Y | F34: =G34/$G$82 -> 0.0016009834 | G34: 798.11 | H34: =G34*Prototype!$B$16 -> 7182.99 | I34: 1 | J34: =IFERROR(K34*G34/1000,"") -> 3.99055 | K34: 5 | O34: Stair/Elevator​ | P34: =G13 -> 941 | Q34: =P34/$P$36 -> 0.024535238 | T34: Stair/Elevator​ | U34: =G32 -> 848 | V34: =U34/$P$36 -> 0.022110396 | Y34: Stair/Elevator​ | Z34: =G55 -> 848 | AA34: =Z34/$P$36 -> 0.022110396
A35: Plenum_FloorG | B35: Plenum | C35: _ | E35: N | G35: =G58 -> 38352.015 | H35: =G35*(Prototype!$B$15-Prototype!$B$16) -> 153408.06 | I35: 1 | J35: =IFERROR(K35*G35/1000,"") -> 0 | K35: 0 | T35: Plenum​ | U35: =G35 -> 38352.015 | V35: =U35/$P$36 -> 0.99997432 | Y35: Plenum​ | Z35: 38,353 ​ | AA35: 1
A36: Perimeter_Open_ Office_N_FloorM | B36: Office Area (>250 square feet) | C36: VAV With Reheat_FloorM | D36: Office | E36: Y | F36: =G36/$G$82 -> 0.014305142 | G36: 7131.29 | H36: =G36*Prototype!$B$16 -> 64181.61 | I36: 10 | J36: =IFERROR(K36*G36/1000,"") -> 35.65645 | K36: 5 | P36: 38353 | Z36: =SUM(Z23:Z34) -> 38350.9
A37: Perimeter_Open_ Office_S_FloorM | B37: Office Area (>250 square feet) | C37: VAV With Reheat_FloorM | D37: Office | E37: Y | F37: =G37/$G$82 -> 0.010505998 | G37: 5237.37 | H37: =G37*Prototype!$B$16 -> 47136.33 | I37: 10 | J37: =IFERROR(K37*G37/1000,"") -> 26.18685 | K37: =K3 -> 5
A38: Perimeter_Open_ Office_E_FloorM | B38: Office Area (>250 square feet) | C38: VAV With Reheat_FloorM | D38: Office | E38: Y | F38: =G38/$G$82 -> 0.0089675612 | G38: 4470.44 | H38: =G38*Prototype!$B$16 -> 40233.96 | I38: =I37 -> 10 | J38: =IFERROR(K38*G38/1000,"") -> 22.3522 | K38: =K3 -> 5
A39: Perimeter_Open_ Office_W_FloorM | B39: Office Area (>250 square feet) | C39: VAV With Reheat_FloorM | D39: Office | E39: Y | F39: =G39/$G$82 -> 0.0089240718 | G39: 4448.76 | H39: =G39*Prototype!$B$16 -> 40038.84 | I39: =I38 -> 10 | J39: =IFERROR(K39*G39/1000,"") -> 22.2438 | K39: =K3 -> 5
A40: Perimeter_Enclosed_ Office_NE_FloorM | B40: Office Area (>250 square feet) | C40: VAV With Reheat_FloorM | D40: Office | E40: Y | F40: =G40/$G$82 -> 0.0018402353 | G40: 917.38 | H40: =G40*Prototype!$B$16 -> 8256.42 | I40: =I39 -> 10 | J40: =IFERROR(K40*G40/1000,"") -> 4.5869 | K40: =K3 -> 5
...

Sheet HVAC System
A1: ="HVAC system - "&Prototype!A2 -> HVAC system - OfficeLarge
A2: Vintage | B2: Zones | C2: Heating | D2: Cooling | E2: Air Distribution | F2: Source | G2: Note
A3: Existing | B3: Server Room_B | C3: - | D3: built up CRAH with chilled water coils (Computer Room Air Handling unit) | E3: CAV | F3: Engineering Judgement
B4: Server_Room_G Server_Room_M Server_Room_T | C4: - | D4: DX Computer Room Air Conditioner | E4: CAV | F4: Engineering Judgement | G4: DX Computer Room Air Conditioner units have been a standard solution in server rooms for many years.
B5: All other conditioned zones | C5: Gas Boiler | D5: Chiller (it also serves the Server_Room_B zone) | E5: built-up VAV with hydronic reheat | F5: CEUS 2022
A6: New Construction | B6: Server Room_B | C6: - | D6: built up CRAH with chilled water coils (Computer Room Air Handling unit) | E6: CAV | F6: T24 2025
B7: Server_Room_G Server_Room_M Server_Room_T | C7: - | D7: DX Computer Room Air Conditioner (CRAC) | E7: CAV | F7: T24 2025
B8: All other conditioned zones | C8: Gas Boiler | D8: Chiller (it also serves the Server_Room_B zone) | E8: VAV | F8: T24 2025
A13: Efficiency of HVAC system
B14: Upgrade/Installed year | C14: DX Computer Room Air Conditioner Server_Room_G/M/T (CRAC) | D14: Chiller | E14: Gas Boiler | F14: Sources | G14: Note
A15: Pre 1978 | B15: 2008 | C15: EER=9.0 | D15: 6.10 COP 6.40 IPLV | E15: Efficiency of 80% | F15: CFR Energy 2008 (for DX CRAC) | G15: Two centrifugal chillers (Total cooling plant load > 600 tons) Two atmospheric boilers (no combustion air fans) | H15: FR-2009-03-23.pdf
A16: 1978-1997
A17: 1998-2007
A18: 2008-2018 | B18: 2013 | C18: EER=9.0 | D18: ≤ 0.590 kW/ton ≤ 0.400 IPLV | E18: Thermal efficiency (Et) of 80% | F18: CFR Energy 2010:Title 10- Table 9 (for DX CRAC) Title 24, Part 6, 2013 ,Table 110.2-J (for Boiler thermal efficiency) | G18: water-cooled centrifugal chillers Two Boilers each with capacity between 300-2,500 KBTU/hr
A19: New Construction | B19: 2025 | C19: SEER=13.4 SCOP=2.09 | D19: ≤ 0.625 kW/ton ≤ 0.410 IPLV | E19: Thermal efficiency (Et) of 84% | F19: CFR Energy 2025, Table 12 (for DX CRAC) Title 24, Part 6, 2022 ,Table 110.2-J (for Boiler thermal efficiency) | G19: Two water-cooled screw chillers (Each between 300-600 ton), Path B, Positive displacement chiller with design leaving fluid temperature ≤ 32°F Two Boilers each with capacity between 300-2,500 KBTU/hr | H19: CFR-2024-title10-vol3-part431-subpartF.pdf
A21: Economizer is required for all the systems. CRAC units should have "integrated airside economizer"
A23: Only adiabatic humidification | C23: Title 24, Part 6_ 2025, Section 140.9 (a)1
A24: Demand Control ventilation
B27: Background Data [To be deleted prior to publication]
B29: Existing prototypes:
B31: Space | C31: System No. | D31: System Type | E31: Fan Control | F31: Cooling Type | G31: Heating Type
A32: CBECC 2025 | B32: All Space | E32: VAV | F32: Chilled water | G32: Hot-water fossil fuel boiler
A33: CPUC 2024 | B33: All Space | E33: VAV | F33: Chiller water | G33: Gas Boiler
A34: PNNL ASHRAE 90.1- 2022 San Diego | B34: data center room | C34: 14. WSHP (CRAC) | D34: Water source heat pump (Computer room air conditioning unit) | E34: Constant volume | F34: Fluid cooler | G34: Hot-water fossil fuel boiler
B35: Basement (Except data center) | C35: 12. SZ-CV-HW | D35: Single-zone system | E35: Constant volume | F35: Chilled water | G35: Hot-water fossil fuel boiler
B36: Other spaces | C36: 7. VAV with reheat | D36: VAV with reheat | E36: VAV | F36: Chilled water | G36: Hot-water fossil fuel boiler
A37: Basement system in PNNL model is :SZ-CV-HW (Single zone system: CV fan control & Chilled water cooling & Hot-water fossil fuel boiler heating)
A38: Other floors system in PNNL model is: VAV Reheat ( VAV with Reheat: VA fan control & Chilled water cooling & Hot-water fossil fuel boiler heating )
A39: Dat center zone has its won system in PNNL model: WSHP (CRAC): Water source heat pump (Computer room air conditioning unit) system: CV fan control & Fluid cooler & Hot-water fossil fuel boiler heating
B41: CEUS 2022 data:
A42: Heating System
A43: Calculation method | B43: Building Type | C43: Fan Coil / Unit Ventilator | D43: Dual Duct Constant Air Volume | E43: Dual Duct Variable Air Volume | G43: Single Duct Constant Air Volume | H43: Single Duct Variable Air Volume
A44: Floorspace-Based | B44: Office, Large | D44: 0.03 | E44: 0.15 | G44: 0.43 | H44: 0.21
A45: Sites-Based | B45: Office, Large | C45: 0.13 | D45: 0.02 | E45: 0.07 | G45: 0.66 | H45: 0.12
A48: Chiller System
A49: Calculation method | B49: Building Type | C49: Boiler/ Hydronic | D49: Package System / Heat Pump | E49: Split-System / Heat Pump | G49: Ductless Mini-Split Heat Pump | H49: Room Heating
A50: Floorspace-Based | B50: Office, Large | C50: 0.59 | D50: 0.35 | E50: 0.05 | G50: 0 | H50: 0
A51: Sites-Based | B51: Office, Large | C51: 0.34 | D51: 0.58 | E51: 0.07 | G51: 0 | H51: 0
A53: Heating Fuel Type
A54: Calculation method | B54: Building Type | C54: Gas Share | D54: Electric Share
...

Sheet Thermostat
A1: ="Thermostat Setpoints - "&Prototype!A2 -> Thermostat Setpoints - OfficeLarge
A2: Spaces/Zones | B2: Setpoint | C2: CZ1 | D2: CZ2 | E2: CZ3 | F2: CZ4 | G2: CZ5 | H2: CZ6 | I2: CZ7 | J2: CZ8 | K2: CZ9 | L2: CZ10 | M2: CZ11 | N2: CZ12 | O2: CZ13 | P2: CZ14 | Q2: CZ15 | R2: CZ16 | S2: Source
A3: All conditioned zones except server rooms | B3: Heating Setpoint (F) | C3: 70 | D3: 70 | E3: 70 | F3: 70 | G3: 70 | H3: 70 | I3: 70 | J3: 70 | K3: 70 | L3: 70 | M3: 70 | N3: 70 | O3: 70 | P3: 70 | Q3: 70 | R3: 70 | S3: T24 2022 - Appendix 5.4B
B4: Heating Setback (F) | C4: 60 | D4: 60 | E4: 60 | F4: 60 | G4: 60 | H4: 60 | I4: 60 | J4: 60 | K4: 60 | L4: 60 | M4: 60 | N4: 60 | O4: 60 | P4: 60 | Q4: 60 | R4: 60
B5: Cooling Setpoint (F) | C5: 75 | D5: 75 | E5: 75 | F5: 75 | G5: 75 | H5: 75 | I5: 75 | J5: 75 | K5: 75 | L5: 75 | M5: 75 | N5: 75 | O5: 75 | P5: 75 | Q5: 75 | R5: 75
B6: Cooling Setback (F) | C6: 85 | D6: 85* | E6: 85 | F6: 85 | G6: 85 | H6: 85 | I6: 85 | J6: 85 | K6: 85 | L6: 85 | M6: 85 | N6: 85 | O6: 85 | P6: 85 | Q6: 85 | R6: 85
A7: Server rooms | B7: Cooling Setpoint (F) | C7: 80 | D7: 80 | E7: 80 | F7: 80 | G7: 80 | H7: 80 | I7: 80 | J7: 80 | K7: 80 | L7: 80 | M7: 80 | N7: 80 | O7: 80 | P7: 80 | Q7: 80 | R7: 80 | S7: Title 24, Part 6, 2025, section 140.9 (a) and PNNL ASHRAE 90.1 2022 Large Office prototype
B8: Heating Setback (F) | C8: The Server room with 20 W/ft2 load would likely don't require heating system as the equipment constantly generate enough heat. **
B10: *PNNL has considered 80 F for cooling setback of Large Office prototype (same as Medium Office). However cooling setback is 85 F in Small Office prototype !
B11: **PNNL has set the heating system temperature to 65°F for all of their data center zones.
A18: Background Data [To be deleted prior to publication]
A38: Heating/ CoolingSetpointsSchedules (existing prototypes extracted from the idf files (presented below)
B59: Heating | K59: Cooling
B60: CEC-2022 | F60: PNNL-2022 | K60: CEC-2022 | O60: PNNL-2022
B61: CEC-Weekday | C61: CEC-Saturday | D61: CEC-Sunday | F61: PNNL-Weekday | G61: PNNL-Saturday | H61: PNNL-Sunday | K61: CEC-Weekday | L61: CEC-Saturday | M61: CEC-Sunday | O61: PNNL-Weekday | P61: PNNL-Saturday | Q61: PNNL-Sunday
A62: 1 | B62: 60 | C62: 60 | D62: 60 | F62: 60.08 | G62: 60.08 | H62: 60.08 | K62: 85 | L62: 85 | M62: 85 | O62: 80.06 | P62: 80.06 | Q62: 80.06
A63: 2 | B63: 60 | C63: 60 | D63: 60 | F63: 60.08 | G63: 60.08 | H63: 60.08 | K63: 85 | L63: 85 | M63: 85 | O63: 80.06 | P63: 80.06 | Q63: 80.06
A64: 3 | B64: 60 | C64: 60 | D64: 60 | F64: 60.08 | G64: 60.08 | H64: 60.08 | K64: 85 | L64: 85 | M64: 85 | O64: 80.06 | P64: 80.06 | Q64: 80.06
A65: 4 | B65: 60 | C65: 60 | D65: 60 | F65: 60.08 | G65: 60.08 | H65: 60.08 | K65: 85 | L65: 85 | M65: 85 | O65: 80.06 | P65: 80.06 | Q65: 80.06
A66: 5 | B66: 60 | C66: 60 | D66: 60 | F66: 60.08 | G66: 60.08 | H66: 60.08 | K66: 85 | L66: 85 | M66: 85 | O66: 80.06 | P66: 80.06 | Q66: 80.06
A67: 6 | B67: 70 | C67: 70 | D67: 60 | F67: 64.04 | G67: 64.04 | H67: 60.08 | K67: 75 | L67: 75 | M67: 85 | O67: 78.08 | P67: 78.26 | Q67: 80.06
A68: 7 | B68: 70 | C68: 70 | D68: 60 | F68: 68 | G68: 68 | H68: 60.08 | K68: 75 | L68: 75 | M68: 85 | O68: 77 | P68: 77 | Q68: 80.06
A69: 8 | B69: 70 | C69: 70 | D69: 60 | F69: 69.8 | G69: 69.8 | H69: 60.08 | K69: 75 | L69: 75 | M69: 85 | O69: 75.2 | P69: 75.2 | Q69: 80.06
A70: 9 | B70: 70 | C70: 70 | D70: 60 | F70: 69.8 | G70: 69.8 | H70: 60.08 | K70: 75 | L70: 75 | M70: 85 | O70: 75.2 | P70: 75.2 | Q70: 80.06
A71: 10 | B71: 70 | C71: 70 | D71: 60 | F71: 69.8 | G71: 69.8 | H71: 60.08 | K71: 75 | L71: 75 | M71: 85 | O71: 75.2 | P71: 75.2 | Q71: 80.06
A72: 11 | B72: 70 | C72: 70 | D72: 60 | F72: 69.8 | G72: 69.8 | H72: 60.08 | K72: 75 | L72: 75 | M72: 85 | O72: 75.2 | P72: 75.2 | Q72: 80.06
A73: 12 | B73: 70 | C73: 70 | D73: 60 | F73: 69.8 | G73: 69.8 | H73: 60.08 | K73: 75 | L73: 75 | M73: 85 | O73: 75.2 | P73: 75.2 | Q73: 80.06
... A85: 24 | B85: 70 | C85: 60 | D85: 60 | F85: 60.08 | G85: 60.08 | H85: 60.08 | K85: 75 | L85: 85 | M85: 85 | O85: 80.06 | P85: 80.06 | Q85: 80.06

Sheet Ventilation
A1: ="Outdoor Airflow Rate - "&Prototype!A2 -> Outdoor Airflow Rate - OfficeLarge
A2: Space Name | B2: Number of People | C2: Floor Area (ft²) | D2: cfm/person (T24, 2025, Equation 120.1-F and Table 120.1-A) | E2: cfm/ft² (T24, 2025, Equation 120.1-F and Table 120.1-A) | F2: Required Exhaust Rate (T24, 2025, Table 120.1-B – Minimum Exhaust Rates) | G2: Total cfm Driven by People | H2: Total cfm Driven by Area | I2: Total cfm Driven by Exhaust | J2: Total cfm | K2: Note
A3: =Zones!A3 -> Perimeter_Open_ Office_N_Basement | B3: =Zones!J3 -> 42.0843 | C3: =Zones!G3 -> 8416.86 | D3: 15 | E3: 0.15 | G3: =B3*D3 -> 631.2645 | H3: =C3*E3 -> 1262.529 | J3: =MAX(G3:I3) -> 1262.529
A4: =Zones!A4 -> Perimeter_Open_ Office_S_Basement | B4: =Zones!J4 -> 18.3109 | C4: =Zones!G4 -> 3662.18 | D4: 15 | E4: 0.15 | G4: =B4*D4 -> 274.6635 | H4: =C4*E4 -> 549.327 | J4: =MAX(G4:I4) -> 549.327
A5: =Zones!A5 -> Core_Enclosed_Office_Basement | B5: =Zones!J5 -> 18.5184 | C5: =Zones!G5 -> 3703.68 | D5: 15 | E5: 0.15 | G5: =B5*D5 -> 277.776 | H5: =C5*E5 -> 555.552 | J5: =MAX(G5:I5) -> 555.552
A6: =Zones!A6 -> Server_Room_Basement | B6: =Zones!J6 -> 0 | C6: =Zones!G6 -> 8228 | D6: 15 | E6: 0.15 | G6: =B6*D6 -> 0 | H6: =C6*E6 -> 1234.2 | J6: =MAX(G6:I6) -> 1234.2
A7: =Zones!A7 -> Mech/Elec_Basement | B7: =Zones!J7 -> 0 | C7: =Zones!G7 -> 7958 | D7: 15 | E7: 0.15 | G7: =B7*D7 -> 0 | H7: =C7*E7 -> 1193.7 | J7: =MAX(G7:I7) -> 1193.7
A8: =Zones!A8 -> Conference_Basement | B8: =Zones!J8 -> 19.1301 | C8: =Zones!G8 -> 579.7 | D8: 15 | E8: 0.15 | G8: =B8*D8 -> 286.9515 | H8: =C8*E8 -> 86.955 | J8: =MAX(G8:I8) -> 286.9515
A9: =Zones!A9 -> Break_Basement | B9: =Zones!J9 -> 32.109 | C9: =Zones!G9 -> 973 | D9: 15 | E9: 0.15 | G9: =B9*D9 -> 481.635 | H9: =C9*E9 -> 145.95 | J9: =MAX(G9:I9) -> 481.635
A10: =Zones!A10 -> Storage_Basement | B10: =Zones!J10 -> 0 | C10: =Zones!G10 -> 1231 | D10: 15 | E10: 0.15 | G10: =B10*D10 -> 0 | H10: =C10*E10 -> 184.65 | J10: =MAX(G10:I10) -> 184.65
A11: =Zones!A11 -> Restroom_Basement | B11: =Zones!J11 -> 0 | C11: =Zones!G11 -> 986 | D11: 15 | E11: 0.15 | F11: 5* 25/50 (cfm/unit) | G11: =B11*D11 -> 0 | H11: =C11*E11 -> 147.9 | I11: =5*25 -> 125 | J11: =MAX(G11:I11) -> 147.9 | K11: Almost 1 unit per 30 occupant for exhaust fan
A12: =Zones!A12 -> Lobby_Basement | B12: =Zones!J12 -> 7.07 | C12: =Zones!G12 -> 707 | D12: 15 | E12: 0.15 | G12: =B12*D12 -> 106.05 | H12: =C12*E12 -> 106.05 | J12: =MAX(G12:I12) -> 106.05
A13: =Zones!A13 -> Stair/Elevator_Basement | B13: =Zones!J13 -> 0 | C13: =Zones!G13 -> 941 | D13: 15 | E13: 0.15 | G13: =B13*D13 -> 0 | H13: =C13*E13 -> 141.15 | J13: =MAX(G13:I13) -> 141.15
A14: =Zones!A14 -> Corridor_W_Basement | B14: =Zones!J14 -> 1.3145 | C14: =Zones!G14 -> 262.9 | D14: 15 | E14: 0.15 | G14: =B14*D14 -> 19.7175 | H14: =C14*E14 -> 39.435 | J14: =MAX(G14:I14) -> 39.435
A15: =Zones!A15 -> Corridor_E_Basement | B15: =Zones!J15 -> 3.515 | C15: =Zones!G15 -> 703 | D15: 15 | E15: 0.15 | G15: =B15*D15 -> 52.725 | H15: =C15*E15 -> 105.45 | J15: =MAX(G15:I15) -> 105.45
A16: =Zones!A16 -> Perimeter_Open_ Office_N_FloorG | B16: =Zones!J16 -> 35.155 | C16: =Zones!G16 -> 7031 | D16: 15 | E16: 0.15 | G16: =B16*D16 -> 527.325 | H16: =C16*E16 -> 1054.65 | J16: =MAX(G16:I16) -> 1054.65
A17: =Zones!A17 -> Perimeter_Open_ Office_W_FloorG | B17: =Zones!J17 -> 28.9788 | C17: =Zones!G17 -> 5795.76 | D17: 15 | E17: 0.15 | G17: =B17*D17 -> 434.682 | H17: =C17*E17 -> 869.364 | J17: =MAX(G17:I17) -> 869.364
A18: =Zones!A18 -> Perimeter_Open_ Office_E_FloorG | B18: =Zones!J18 -> 29.3774 | C18: =Zones!G18 -> 5875.48 | D18: 15 | E18: 0.15 | G18: =B18*D18 -> 440.661 | H18: =C18*E18 -> 881.322 | J18: =MAX(G18:I18) -> 881.322
A19: =Zones!A19 -> Perimeter_Enclosed_ Office_NE_FloorG | B19: =Zones!J19 -> 4.5869 | C19: =Zones!G19 -> 917.38 | D19: 15 | E19: 0.15 | G19: =B19*D19 -> 68.8035 | H19: =C19*E19 -> 137.607 | J19: =MAX(G19:I19) -> 137.607
A20: =Zones!A20 -> Perimeter_Enclosed_ Office_NW_FloorG | B20: =Zones!J20 -> 5.65305 | C20: =Zones!G20 -> 1130.61 | D20: 15 | E20: 0.15 | G20: =B20*D20 -> 84.79575 | H20: =C20*E20 -> 169.5915 | J20: =MAX(G20:I20) -> 169.5915
A21: =Zones!A21 -> Core_Enclosed_Office_FloorG | B21: =Zones!J21 -> 16.56 | C21: =Zones!G21 -> 3312 | D21: 15 | E21: 0.15 | G21: =B21*D21 -> 248.4 | H21: =C21*E21 -> 496.8 | J21: =MAX(G21:I21) -> 496.8
A22: =Zones!A22 -> Server_Room_FloorG | B22: =Zones!J22 -> 0 | C22: =Zones!G22 -> 417.94 | D22: 15 | E22: 0.15 | G22: =B22*D22 -> 0 | H22: =C22*E22 -> 62.691 | J22: =MAX(G22:I22) -> 62.691
A23: =Zones!A23 -> Mech/Elec_FloorG | B23: =Zones!J23 -> 0 | C23: =Zones!G23 -> 849 | D23: 15 | E23: 0.15 | G23: =B23*D23 -> 0 | H23: =C23*E23 -> 127.35 | J23: =MAX(G23:I23) -> 127.35
... A27: =Zones!A27 -> Storage_FloorG | B27: =Zones!J27 -> 0 | C27: =Zones!G27 -> 959.02 | D27: 15 | E27: 0.15 | G27: =B27*D27 -> 0 | H27: =C27*E27 -> 143.853 | J27: =MAX(G27:I27) -> 143.853
A28: =Zones!A28 -> Locker_FloorG | B28: =Zones!J28 -> 18.1497 | C28: =Zones!G28 -> 1814.97 | D28: 15 | E28: 0.15 | F28: 0.25 (cfm/sf) | G28: =B28*D28 -> 272.2455 | H28: =C28*E28 -> 272.2455 | I28: =0.25*C28 -> 453.7425 | J28: =MAX(G28:I28) -> 453.7425
A29: =Zones!A29 -> Lobby_S_FloorG | B29: =Zones!J29 -> 33.6063 | C29: =Zones!G29 -> 3360.63 | D29: 15 | E29: 0.15 | G29: =B29*D29 -> 504.0945 | H29: =C29*E29 -> 504.0945 | J29: =MAX(G29:I29) -> 504.0945
A30: =Zones!A30 -> Lobby_FloorG | B30: =Zones!J30 -> 6.8336 | C30: =Zones!G30 -> 683.36 | D30: 15 | E30: 0.15 | G30: =B30*D30 -> 102.504 | H30: =C30*E30 -> 102.504 | J30: =MAX(G30:I30) -> 102.504
A31: =Zones!A31 -> Restroom_FloorG | B31: =Zones!J31 -> 0 | C31: =Zones!G31 -> 1156 | D31: 15 | E31: 0.15 | F31: 8* 25/50 (cfm/unit) | G31: =B31*D31 -> 0 | H31: =C31*E31 -> 173.4 | I31: =8*25 -> 200 | J31: =MAX(G31:I31) -> 200
A32: =Zones!A32 -> Stair/Elevator_FloorG | B32: =Zones!J32 -> 0 | C32: =Zones!G32 -> 848 | D32: 15 | E32: 0.15 | G32: =B32*D32 -> 0 | H32: =C32*E32 -> 127.2 | J32: =MAX(G32:I32) -> 127.2
A33: =Zones!A33 -> Corridor_W_FloorG | B33: =Zones!J33 -> 5.0294 | C33: =Zones!G33 -> 1005.88 | D33: 15 | E33: 0.15 | G33: =B33*D33 -> 75.441 | H33: =C33*E33 -> 150.882 | J33: =MAX(G33:I33) -> 150.882
A34: =Zones!A34 -> Corridor_E_FloorG | B34: =Zones!J34 -> 3.99055 | C34: =Zones!G34 -> 798.11 | D34: 15 | E34: 0.15 | G34: =B34*D34 -> 59.85825 | H34: =C34*E34 -> 119.7165 | J34: =MAX(G34:I34) -> 119.7165
A35: =Zones!A35 -> Plenum_FloorG | B35: =Zones!J35 -> 0 | C35: =Zones!G35 -> 38352.015 | G35: =B35*D35 -> 0 | H35: =C35*E35 -> 0 | J35: =MAX(G35:I35) -> 0
A36: =Zones!A36 -> Perimeter_Open_ Office_N_FloorM | B36: =Zones!J36 -> 35.65645 | C36: =Zones!G36 -> 7131.29 | D36: 15 | E36: 0.15 | G36: =B36*D36 -> 534.84675 | H36: =C36*E36 -> 1069.6935 | J36: =MAX(G36:I36) -> 1069.6935
A37: =Zones!A37 -> Perimeter_Open_ Office_S_FloorM | B37: =Zones!J37 -> 26.18685 | C37: =Zones!G37 -> 5237.37 | D37: 15 | E37: 0.15 | G37: =B37*D37 -> 392.80275 | H37: =C37*E37 -> 785.6055 | J37: =MAX(G37:I37) -> 785.6055
A38: =Zones!A38 -> Perimeter_Open_ Office_E_FloorM | B38: =Zones!J38 -> 22.3522 | C38: =Zones!G38 -> 4470.44 | D38: 15 | E38: 0.15 | G38: =B38*D38 -> 335.283 | H38: =C38*E38 -> 670.566 | J38: =MAX(G38:I38) -> 670.566
A39: =Zones!A39 -> Perimeter_Open_ Office_W_FloorM | B39: =Zones!J39 -> 22.2438 | C39: =Zones!G39 -> 4448.76 | D39: 15 | E39: 0.15 | G39: =B39*D39 -> 333.657 | H39: =C39*E39 -> 667.314 | J39: =MAX(G39:I39) -> 667.314
A40: =Zones!A40 -> Perimeter_Enclosed_ Office_NE_FloorM | B40: =Zones!J40 -> 4.5869 | C40: =Zones!G40 -> 917.38 | D40: 15 | E40: 0.15 | G40: =B40*D40 -> 68.8035 | H40: =C40*E40 -> 137.607 | J40: =MAX(G40:I40) -> 137.607
A41: =Zones!A41 -> Perimeter_Enclosed_ Office_NW_FloorM | B41: =Zones!J41 -> 5.65605 | C41: =Zones!G41 -> 1131.21 | D41: 15 | E41: 0.15 | G41: =B41*D41 -> 84.84075 | H41: =C41*E41 -> 169.6815 | J41: =MAX(G41:I41) -> 169.6815
A42: =Zones!A42 -> Perimeter_Enclosed_ Office_SW_FloorM | B42: =Zones!J42 -> 5.05245 | C42: =Zones!G42 -> 1010.49 | D42: 15 | E42: 0.15 | G42: =B42*D42 -> 75.78675 | H42: =C42*E42 -> 151.5735 | J42: =MAX(G42:I42) -> 151.5735
A43: =Zones!A43 -> Perimeter_Enclosed_ Office_SE_FloorM | B43: =Zones!J43 -> 5.1674 | C43: =Zones!G43 -> 1033.48 | D43: 15 | E43: 0.15 | G43: =B43*D43 -> 77.511 | H43: =C43*E43 -> 155.022 | J43: =MAX(G43:I43) -> 155.022
...

Sheet Water Heater
A1: Water Heater - OfficeLarge
A2: Vintage | B2: WH Type | C2: Efficiency | D2: Tank Volume (gal) | E2: Tank Loss | F2: Unit | G2: Source
A3: Existing | B3: Gas | C3: 0.8 | D3: =F95 -> 183 | E3: =G95 -> 1771.9389 | F3: =H95 -> Btu/hr | G3: Fuel Type based on CEUS
A4: New Construction | B4: Gas | C4: 0.8 | D4: =F95 -> 183 | E4: =G95 -> 1771.9389 | F4: =H95 -> Btu/hr
A8: Peak Hot Water Consumption
A9: Space Name | B9: Baseline WH Type [T24, 2022, Appendix 5.4A , sheet: "2022 SpaceFuncData-Input"] | C9: Total Area (ft²) | D9: Number of People | E9: Hot Water Usage Specification (gal/hr per person) [T24, 2022, Appendix 5.4A , sheet: "2022 SpaceFuncData-Input"] | F9: Peak Hot Water Usage (gal/hr) | G9: Peak Hot Water Usage (gal/min)
A10: =Zones!A3 -> Perimeter_Open_ Office_N_Basement | B10: Gas | C10: =Zones!G3*Zones!I3 -> 8416.86 | D10: =Zones!J3*Zones!I3 -> 42.0843 | E10: 0.18 | F10: =D10*E10 -> 7.575174 | G10: =F10/60 -> 0.1262529
A11: =Zones!A4 -> Perimeter_Open_ Office_S_Basement | B11: Gas | C11: =Zones!G4*Zones!I4 -> 3662.18 | D11: =Zones!J4*Zones!I4 -> 18.3109 | E11: 0.18 | F11: =D11*E11 -> 3.295962 | G11: =F11/60 -> 0.0549327
A12: =Zones!A5 -> Core_Enclosed_Office_Basement | B12: Gas | C12: =Zones!G5*Zones!I5 -> 3703.68 | D12: =Zones!J5*Zones!I5 -> 18.5184 | E12: 0.18 | F12: =D12*E12 -> 3.333312 | G12: =F12/60 -> 0.0555552
A13: =Zones!A6 -> Server_Room_Basement | B13: Gas | C13: =Zones!G6*Zones!I6 -> 8228 | D13: =Zones!J6*Zones!I6 -> 0 | E13: 0.18 | F13: =D13*E13 -> 0 | G13: =F13/60 -> 0
A14: =Zones!A7 -> Mech/Elec_Basement | B14: Gas | C14: =Zones!G7*Zones!I7 -> 7958 | D14: =Zones!J7*Zones!I7 -> 0 | E14: 0.18 | F14: =D14*E14 -> 0 | G14: =F14/60 -> 0
A15: =Zones!A8 -> Conference_Basement | B15: Gas | C15: =Zones!G8*Zones!I8 -> 579.7 | D15: =Zones!J8*Zones!I8 -> 19.1301 | E15: 0.09 | F15: =D15*E15 -> 1.721709 | G15: =F15/60 -> 0.02869515
A16: =Zones!A9 -> Break_Basement | B16: Gas | C16: =Zones!G9*Zones!I9 -> 973 | D16: =Zones!J9*Zones!I9 -> 32.109 | E16: 0.09 | F16: =D16*E16 -> 2.88981 | G16: =F16/60 -> 0.0481635
A17: =Zones!A10 -> Storage_Basement | C17: =Zones!G10*Zones!I10 -> 1231 | D17: =Zones!J10*Zones!I10 -> 0 | E17: 0 | F17: =D17*E17 -> 0 | G17: =F17/60 -> 0
A18: =Zones!A11 -> Restroom_Basement | C18: =Zones!G11*Zones!I11 -> 986 | D18: =Zones!J11*Zones!I11 -> 0 | E18: 0 | F18: =D18*E18 -> 0 | G18: =F18/60 -> 0
A19: =Zones!A12 -> Lobby_Basement | B19: Gas | C19: =Zones!G12*Zones!I12 -> 707 | D19: =Zones!J12*Zones!I12 -> 7.07 | E19: 0.09 | F19: =D19*E19 -> 0.6363 | G19: =F19/60 -> 0.010605
A20: =Zones!A13 -> Stair/Elevator_Basement | C20: =Zones!G13*Zones!I13 -> 941 | D20: =Zones!J13*Zones!I13 -> 0 | E20: 0 | F20: =D20*E20 -> 0 | G20: =F20/60 -> 0
A21: =Zones!A14 -> Corridor_W_Basement | C21: =Zones!G14*Zones!I14 -> 262.9 | D21: =Zones!J14*Zones!I14 -> 1.3145 | E21: 0 | F21: =D21*E21 -> 0 | G21: =F21/60 -> 0
A22: =Zones!A15 -> Corridor_E_Basement | C22: =Zones!G15*Zones!I15 -> 703 | D22: =Zones!J15*Zones!I15 -> 3.515 | E22: 0 | F22: =D22*E22 -> 0 | G22: =F22/60 -> 0
A23: =Zones!A16 -> Perimeter_Open_ Office_N_FloorG | B23: Gas | C23: =Zones!G16*Zones!I16 -> 7031 | D23: =Zones!J16*Zones!I16 -> 35.155 | E23: 0.18 | F23: =D23*E23 -> 6.3279 | G23: =F23/60 -> 0.105465
A24: =Zones!A17 -> Perimeter_Open_ Office_W_FloorG | B24: Gas | C24: =Zones!G17*Zones!I17 -> 5795.76 | D24: =Zones!J17*Zones!I17 -> 28.9788 | E24: 0.18 | F24: =D24*E24 -> 5.216184 | G24: =F24/60 -> 0.0869364
A25: =Zones!A18 -> Perimeter_Open_ Office_E_FloorG | B25: Gas | C25: =Zones!G18*Zones!I18 -> 5875.48 | D25: =Zones!J18*Zones!I18 -> 29.3774 | E25: 0.18 | F25: =D25*E25 -> 5.287932 | G25: =F25/60 -> 0.0881322
A26: =Zones!A19 -> Perimeter_Enclosed_ Office_NE_FloorG | B26: Gas | C26: =Zones!G19*Zones!I19 -> 917.38 | D26: =Zones!J19*Zones!I19 -> 4.5869 | E26: 0.18 | F26: =D26*E26 -> 0.825642 | G26: =F26/60 -> 0.0137607
A27: =Zones!A20 -> Perimeter_Enclosed_ Office_NW_FloorG | B27: Gas | C27: =Zones!G20*Zones!I20 -> 1130.61 | D27: =Zones!J20*Zones!I20 -> 5.65305 | E27: 0.18 | F27: =D27*E27 -> 1.017549 | G27: =F27/60 -> 0.01695915
A28: =Zones!A21 -> Core_Enclosed_Office_FloorG | B28: Gas | C28: =Zones!G21*Zones!I21 -> 3312 | D28: =Zones!J21*Zones!I21 -> 16.56 | E28: 0.18 | F28: =D28*E28 -> 2.9808 | G28: =F28/60 -> 0.04968
A29: =Zones!A22 -> Server_Room_FloorG | B29: Gas | C29: =Zones!G22*Zones!I22 -> 417.94 | D29: =Zones!J22*Zones!I22 -> 0 | E29: 0.18 | F29: =D29*E29 -> 0 | G29: =F29/60 -> 0
A30: =Zones!A23 -> Mech/Elec_FloorG | B30: Gas | C30: =Zones!G23*Zones!I23 -> 849 | D30: =Zones!J23*Zones!I23 -> 0 | E30: 0.18 | F30: =D30*E30 -> 0 | G30: =F30/60 -> 0
A31: =Zones!A24 -> Conference_FloorG | B31: Gas | C31: =Zones!G24*Zones!I24 -> 790 | D31: =Zones!J24*Zones!I24 -> 26.07 | E31: 0.09 | F31: =D31*E31 -> 2.3463 | G31: =F31/60 -> 0.039105
A32: =Zones!A25 -> Break_FloorG | B32: Gas | C32: =Zones!G25*Zones!I25 -> 618.05 | D32: =Zones!J25*Zones!I25 -> 20.39565 | E32: 0.09 | F32: =D32*E32 -> 1.8356085 | G32: =F32/60 -> 0.030593475
A33: =Zones!A26 -> FoodPrep_FloorG | B33: Gas | C33: =Zones!G26*Zones!I26 -> 936.94 | D33: =Zones!J26*Zones!I26 -> 2.81082 | E33: 0.578 | F33: =D33*E33 -> 1.624654 | G33: =F33/60 -> 0.027077566
A34: =Zones!A27 -> Storage_FloorG | B34: Gas | C34: =Zones!G27*Zones!I27 -> 959.02 | D34: =Zones!J27*Zones!I27 -> 0 | E34: 0 | F34: =D34*E34 -> 0 | G34: =F34/60 -> 0
... A37: =Zones!A30 -> Lobby_FloorG | B37: Gas | C37: =Zones!G30*Zones!I30 -> 683.36 | D37: =Zones!J30*Zones!I30 -> 6.8336 | E37: 0.09 | F37: =D37*E37 -> 0.615024 | G37: =F37/60 -> 0.0102504
A38: =Zones!A31 -> Restroom_FloorG | C38: =Zones!G31*Zones!I31 -> 1156 | D38: =Zones!J31*Zones!I31 -> 0 | E38: 0 | F38: =D38*E38 -> 0 | G38: =F38/60 -> 0
A39: =Zones!A32 -> Stair/Elevator_FloorG | C39: =Zones!G32*Zones!I32 -> 848 | D39: =Zones!J32*Zones!I32 -> 0 | E39: 0 | F39: =D39*E39 -> 0 | G39: =F39/60 -> 0
A40: =Zones!A33 -> Corridor_W_FloorG | C40: =Zones!G33*Zones!I33 -> 1005.88 | D40: =Zones!J33*Zones!I33 -> 5.0294 | E40: 0 | F40: =D40*E40 -> 0 | G40: =F40/60 -> 0
A41: =Zones!A34 -> Corridor_E_FloorG | C41: =Zones!G34*Zones!I34 -> 798.11 | D41: =Zones!J34*Zones!I34 -> 3.99055 | E41: 0 | F41: =D41*E41 -> 0 | G41: =F41/60 -> 0
A42: =Zones!A35 -> Plenum_FloorG | C42: =Zones!G35*Zones!I35 -> 38352.015 | D42: =Zones!J35*Zones!I35 -> 0 | E42: 0 | F42: =D42*E42 -> 0 | G42: =F42/60 -> 0
A43: =Zones!A36 -> Perimeter_Open_ Office_N_FloorM | B43: Gas | C43: =Zones!G36*Zones!I36 -> 71312.9 | D43: =Zones!J36*Zones!I36 -> 356.5645 | E43: 0.18 | F43: =D43*E43 -> 64.18161 | G43: =F43/60 -> 1.0696935
A44: =Zones!A37 -> Perimeter_Open_ Office_S_FloorM | B44: Gas | C44: =Zones!G37*Zones!I37 -> 52373.7 | D44: =Zones!J37*Zones!I37 -> 261.8685 | E44: 0.18 | F44: =D44*E44 -> 47.13633 | G44: =F44/60 -> 0.7856055
A45: =Zones!A38 -> Perimeter_Open_ Office_E_FloorM | B45: Gas | C45: =Zones!G38*Zones!I38 -> 44704.4 | D45: =Zones!J38*Zones!I38 -> 223.522 | E45: 0.18 | F45: =D45*E45 -> 40.23396 | G45: =F45/60 -> 0.670566
...

Sheet Interior Lights
A1: ="Interior Lighting - " & Prototype!A2 -> Interior Lighting - OfficeLarge
A2: Space Type | B2: New Construction | E2: Existing | H2: Note
B3: LPD (W/ft²) | C3: Additional LPD for Portable Lighting (W/ft²) | D3: Source | E3: LPD (W/ft²) | F3: Additional LPD for Portable Lighting (W/ft²) | G3: Source
A4: Office Area (>250 square feet) | B4: 0.6 | D4: T24, part 6, 2025, Table 140.6 C For Computer and Server room: Engineering Judgement | E4: 0.75 | G4: T24, part 6, 2013, Table 140.6 C For Computer and Server room: Engineering Judgement
A5: Convention, Conference, Multipurpose and Meeting Area | B5: 0.75 | E5: 1.4
A6: Lobby, Main Entry | B6: 0.7 | E6: 1.1
A7: Locker Room | B7: 0.45 | E7: 0.8
A8: Storage (General) | B8: 0.4 | E8: 0.6
A9: Electrical, Mechanical, Telephone Rooms | B9: 0.4 | E9: 0.7
A10: Server Room (EPD 45) | B10: 1.1 | E10: 1.1
A11: Computer Room (EPD 20) | B11: 1.1 | E11: 1.1
A12: Restrooms | B12: 0.6 | E12: 0.6
A13: Lounge, Breakroom, or Waiting Area | B13: 0.55 | E13: 1,1
A14: Kitchen/Food Preparation Area | B14: 0.95 | E14: 1.6
A15: Stairwell | B15: 0.6 | E15: 0.6
A16: Corridor Area | B16: 0.4 | E16: 0.6
A17: Plenum
B20: Whole Building method
B21: 2025 | C21: 2013
A22: LPD for Office Building ((W/ft²) | B22: 0.6 | C22: 0.8 | D22: Ref: T24, Table 140.6 B
A27: Background Data [To be deleted prior to publication]

Sheet Ext Lighting
A1: ="Exterior Lighting - "&Prototype!A2 -> Exterior Lighting - OfficeLarge
A2: Motion Controlled Luminaires (W) | B2: Non-motion Controlled Luminaires (W) | C2: Total (W) | D2: Source
A3: =G16 -> 15940.131 | B3: =G17 -> 1548.9586 | C3: =A3+B3 -> 17489.089 | D3: Title 24, 2022
A8: Exterior Lighting
A9: Items (Assume LZ2) | B9: Assumptions [2019 Outdoor Lighting CASE Report & PNNL 90.1-2010 TSD] | D9: Unit | E9: Lighting Power Allowance [T24, 2025, Table 140.7-A & 140.7-B] | F9: Unit | G9: Exterior Lighting Power (W)
A10: IWA (Initial Wage Allowance) | E10: 200 | F10: (W) | G10: =$E10 -> 200
A11: Parking area | B11: 400 ft² for every parking space 1 parking space per 250 ft² of gross building area | C11: =B23/250*400 -> 797619.76 | D11: (ft²) | E11: 0.019 | F11: (W/ft²) | G11: =$E11*C11 -> 15154.775
A12: Building Entrance | B12: 2 building entrance (1 per 10,000 ft² footprint) | C12: 4 | D12: (count) | E12: 15 | F12: (W/ea) | G12: =E12*C12 -> 60
A13: Hardscape Ornamental Light | B13: 0.1 ft² per 1 ft² of gross building area for hardscape ornamental light | C13: =B23*0.1 -> 49851.235 | D13: (ft²) | E13: 0.007 | F13: (W/ft²) | G13: =E13*C13 -> 348.95864
A14: Building façade | B14: 0.1 W per ft² of facade area Façade Area* = Perimeter × 0.5 × 30 ft (30 ft is the max height that is lit) The 0.5 factor assumes that only half of the perimeter walls are lit. -Formula ia developed based on the 2019 Outdoor Lighting CASE report | C14: =B22*0.5*30 -> 12000 | D14: (ft²) | E14: 0.1 | F14: (W/ft²) | G14: =E14*C14 -> 1200
A15: Non-sales canopy | C15: =(B23/B25)*0.1 -> 3834.7104 | D15: (ft²) | E15: 0.137 | F15: (W/ft²) | G15: =E15*C15 -> 525.35532
A16: Motion controlled Luminaires | G16: =G11+G10+G12+G15 -> 15940.131
A17: Non-motion-controlled Luminaires | G17: =G13+G14 -> 1548.9586
A18: Total | G18: =G16+G17 -> 17489.089
A20: *Developed based on 2019 Outdoor Lighting CASE Report
A22: Perimeter (ft) | B22: =(240+160)*2 -> 800
A23: Total floor area (ft²) | B23: =Zones!G82 -> 498512.35
A24: Floors (above ground) | B24: 12
A25: Floors (all) | B25: 13
A32: Background Data [To be deleted prior to publication]

Sheet Equipment
A1: ="Equipment - "&Prototype!A2 -> Equipment - OfficeLarge
A2: Space Type | B2: Plug load Power Density (W/ft²) | C2: Gas Power Density (Btu/hr-ft²) | D2: Refrigeration Power Density (W/ft²) | E2: Source
A3: Office Area (>250 square feet) | B3: 0.7 | E3: Plug load and schedule project with CEC, 2025
A4: Server Room (EPD 45) | B4: 45 | E4: PNNL ASHRAE 90.1 2022
A5: Computer Room (EPD 20) | B5: 20 | E5: Based on PNNL ASHRAE 90.1 2022 assumptions and minimum load for computer room
A6: Electrical, Mechanical, Telephone Rooms | B6: 0.5 | E6: T24 2022 - Appendix 5.4A
A7: Lounge, Breakroom, or Waiting Area | B7: 0.5
A8: Convention, Conference, Multipurpose and Meeting Area | B8: 0.8
A9: Storage (General) | B9: 0.2
A10: Locker Room | B10: 0.5
A11: Kitchen/Food Preparation Area | B11: 1.5
A12: Lobby, Main Entry | B12: 0.5
A13: Restrooms | B13: 0
A14: Stairwell | B14: 0
A15: Corridor Area | B15: 0
A16: Plenum | B16: 0
A17: OfficeLarge prototype is assumed to have a transformer, and its losses will be explicitly modeled.
A21: Elevator
A22: Vintages | B22: No of Elevator | C22: Design Load (W) | D22: Source
A23: New Construction and Existing | B23: 10 | C23: =140025.3+631.89 -> 140657.19 | D23: PNNL Large Office prorotype
A25: Assumptions for elevators:
A26: One elevator for approximately 50,000 ft² in use. | F26: https://buildingandinteriors.com/find-the-magic-number-elevators-per-building/
A27: For every two floors or two and a half floors, one more elevator was added.
A28: An in-use rate of 70% for the floor area was assumed, based on engineering judgment.
A29: Calculated number of Elevators: | C29: =ROUND((498000*0.7/50000)+ROUND(7/2.5,0),0) -> 10
A30: Calculate Elevator load (kw)based on ACM 2022: | C30: =10*C31 -> 100 | D30: 140.7 kW is PNNL ASHRE 90.1 2019 elevator load (Design level + Light/Fan) | F30: =(140025.3+631.89)/1000 -> 140.65719
A31: ACM 2022 suggestion for elevator load (kw): | C31: 10
A32: Elevator load will be defined as exterior load not equipment load (Same as PNNL ASHRAE 90.1 Large Hotel prototype).
A34: If we consider 10 elevators, the total load (10 × 10 kW) would be 100 kW, which is 40% lower than the PNNL assumption. However, CBECC considered both elevator and Escalator for medium office prototype (10,000 for elevator and 3930 per Escalator) for a 3 stoy, 50 k office buildings. Since elevator load is not typically climate-dependent, we will adopt the PNNL value for the Large Office prototype.
A46: Background Data [To be deleted prior to publication]

Sheet Schedules
A1: ="Schedules - "&Prototype!A2 -> Schedules - OfficeLarge
A2: Zone | B2: Schedule Category | C2: Schedule | D2: Source | E2: Type | F2: Hour
F3: 1 | G3: 2 | H3: 3 | I3: 4 | J3: 5 | K3: 6 | L3: 7 | M3: 8 | N3: 9 | O3: 10 | P3: 11 | Q3: 12 | R3: 13 | S3: 14 | T3: 15 | U3: 16 | V3: 17 | W3: 18 | X3: 19 | Y3: 20 | Z3: 21 | AA3: 22 | AB3: 23 | AC3: 24
A4: All zones | B4: Office | C4: Occupancy | D4: T24 2022 - Appendix 5.4B, [Office] Updated base on Plug load and schedules project with CEC, 2025 | E4: Weekday | F4: 0 | G4: 0 | H4: 0 | I4: 0 | J4: 0 | K4: 0 | L4: 0.1 | M4: 0.2 | N4: 0.95 | O4: 0.95 | P4: 0.95 | Q4: 0.95 | R4: 0.5 | S4: 0.95 | T4: 0.95 | U4: 0.95 | V4: 0.95 | W4: 0.3 | X4: 0.1 | Y4: 0.1 | Z4: 0.1 | AA4: 0.1 | AB4: 0.05 | AC4: 0.05
E5: Saturday | F5: 0 | G5: 0 | H5: 0 | I5: 0 | J5: 0 | K5: 0 | L5: 0.05 | M5: 0.05 | N5: 0.05 | O5: 0.05 | P5: 0.05 | Q5: 0.05 | R5: 0.05 | S5: 0.05 | T5: 0.05 | U5: 0.05 | V5: 0.05 | W5: 0.05 | X5: 0 | Y5: 0 | Z5: 0 | AA5: 0 | AB5: 0 | AC5: 0
E6: Sunday | F6: 0 | G6: 0 | H6: 0 | I6: 0 | J6: 0 | K6: 0 | L6: 0.05 | M6: 0.05 | N6: 0.05 | O6: 0.05 | P6: 0.05 | Q6: 0.05 | R6: 0.05 | S6: 0.05 | T6: 0.05 | U6: 0.05 | V6: 0.05 | W6: 0.05 | X6: 0 | Y6: 0 | Z6: 0 | AA6: 0 | AB6: 0 | AC6: 0
