Workbook
Name nonparticipating_forecastzone_scale_factor: '[1]Energy Usage'!#REF!
Name nonparticipating_forecastzone_scale_factor: 'Energy Usage'!#REF!
Name Space_Function: Data!$A$2:$A$76

Sheet Notes
A1: Data Sources
A2: Dataset | B2: Dodge 2023
B3: CEUS 2022
B4: ComStock 2023
A6: Prototype | B6: CEC Open parking garage prototype (CBECC 2022.3.1) | C6: https://bees.noresco.com/software2022.html
A9: Codes | B9: Title 24, part 6, referred to as T24 (1984, 2001, 2007, 2013, 2016, 2022, 2025)
B10: ASHRAE 90.1 (2022)
B11: CFR Title 10 (2008, 2010, 2025)
B12: ACM 2022
B13: T24 2022 - Appendix 5.4A and Appendix 5.4B | C13: https://www.energy.ca.gov/publications/2022/2022-nonresidential-and-multifamily-alternative-calculation-method-reference
A15: Other | B15: 2022 Reduced infiltration CASE report | C15: https://title24stakeholders.com/wp-content/uploads/2020/10/2022-T24-Final-CASE-Report_Reduce-Infiltration.pdf
B16: 2019 Outdoor Lighting CASE Report | C16: https://title24stakeholders.com/wp-content/uploads/2016/10/T24-2019-CASE-Study-Results-Report-Outdoor-Sources_Final_with-Attachments.pdf
B17: 2019 High Efficiency Fume Hoods in Laboratory Spaces CASE Report | C17: https://title24stakeholders.com/wp-content/uploads/2017/09/2019-T24-CASE-Report_Fume-Hoods_Final_September-2017.pdf?
B18: PNNL 20405, 2010 | C18: file:///N:/Prj_SUS/2023/S23668%20SCE%20CA%20Prototypes%20Development/Technical/NR/0_Input%20data/Lighting/PNNL-20405.pdf
B19: Air leakage Memo, NORESCO, 2025 | C19: Infiltration_rate_report_14May2025-Short-Version.docx
A20: Construction Rate
A33: Notes
A34: *Definitions are from T24 2025 | B34: Parking Garage Building is a building with building floor areas used for parking vehicles, and consists of at least a roof over the parking area enclosed with walls on all sides. The building includes areas for vehicle maneuvering to reach designated parking spaces. If the roof of a parking structure is also used for parking, the section without an overhead roof is considered an outdoor parking lot instead of a parking garage.
B35: Daylight Adaptation Zone in a Parking Garage is the interior path of travel for vehicles adjacent to the entrance or exit of a parking garage as needed for visual adaptation to transition from exterior daylight levels to interior light levels. Daylight Adaptation Zones only include the path of vehicular travel and do not include adjacent Parking Areas.
B36: Parking Zone and Ramps in a Parking Garage is used for the purpose of parking and maneuvering of vehicles. Parking areas include sloping floors of a parking garage. Ramps and driveways specifically for the purpose of moving vehicles between floors of a parking garage. Parking areas and ramps do not include Daylight Adaptation Zones or the roof of a Parking Garage, which may be present in a Parking Garage.

Sheet Prototype
A1: NORESCO, Updated August 2025
A2: ParkingOpen
A3: Characteristic | B3: Value | C3: Data Sources
A4: Building Type | B4: Open Parking
A5: Building Category | B5: Nonresidential
A6: Vintages | B6: 4 Vintages: Pre-1978 , 1978-1997 ,1998-2007 , 2008-2018 New Construction (2019+) | C6: Based on the vintage bin analysis | D6: NonRes-Vintage bins-Draft Report-30Nov2023-Final.docx
A7: Shape | C7: The analysis uses prototype geometry originally developed by CEC. This is an open parking garage, there are no actual windows—the space is fully open to ambient air and therefore unconditioned.
A8: Total Floor Area (ft²) | B8: =Zones!G10 -> 185627.8 | C8: Same as CEC
A9: Aspect Ratio | B9: 1 | C9: Same as CEC
A10: Number of Floors | B10: 3 | C10: Same as CEC
A11: Roof type | B11: Flat | C11: Same as CEC
A12: WWR | B12: n/a (50% openings all around the building) | C12: Same as CEC
A13: Shading Geometry | B13: No Shades | C13: Same as CEC
A14: Floor to floor height (feet) | B14: 13 | C14: Same as CEC
A15: Floor to ceiling height (feet) | B15: 13 | C15: Same as CEC
A16: Glazing sill height (feet) | B16: n/a | C16: Same as CEC
A20: Above grade wall area (ft²) | B20: 27302.66
A21: Gross wall area (ft²) | B21: 27302.66
A22: Roof area (ft²) | B22: 63116
A23: Underground Gross Wall Area (ft²) | B23: 0

Sheet Zones
A1: ="Proposed Layout - "&Prototype!A2 -> Proposed Layout - ParkingOpen
A2: Space Type | B2: Space/Thermal Zone | C2: HVAC System Name/AHU Name | D2: Schedule Category | E2: Conditioned (Y/N) | F2: Area Fraction | G2: Area (ft²) | H2: Volume (ft³) | I2: Multipliers | J2: Number of People | K2: People (Persons/1,000 ft²) [T24, 2025,Table 120.1-A]
A3: Parking Garage Area (Parking Zone and Ramps) | B3: Core | C3: n/a | D3: Parking | E3: Yes | F3: =G3/$G$10 -> 0.032595064 | G3: =6050.55 -> 6050.55 | H3: 13110.37 | I3: 3 | J3: =(K3*G3)/1000 -> 30.25275 | K3: 5
A4: Parking Garage Area (Daylight Adaptation Zones) | B4: Daylight adaption | C4: n/a | D4: Parking | E4: Yes | F4: =G4/$G$10 -> 0.0098053201 | G4: =1820.14 -> 1820.14 | H4: 23663.58 | I4: 1 | J4: =(K4*G4)/1000 -> 9.1007 | K4: 5
A5: Parking Garage Area (Parking Zone and Ramps) | B5: East perimeter | C5: n/a | D5: Parking | E5: Yes | F5: =G5/$G$10 -> 0.074349478 | G5: =13801.33 -> 13801.33 | H5: 29904.25 | I5: 3 | J5: =(K5*G5)/1000 -> 69.00665 | K5: 5
A6: Parking Garage Area (Parking Zone and Ramps) | B6: North perimeter | C6: n/a | D6: Parking | E6: Yes | F6: =G6/$G$10 -> 0.074349478 | G6: =13801.33 -> 13801.33 | H6: 29904.25 | I6: 3 | J6: =(K6*G6)/1000 -> 69.00665 | K6: 5
A7: Retail Sales Area (Retail Merchandise Sales) | B7: Parking attendant | C7: AHU-1 | D7: TicketAttendant | E7: Yes | F7: =G7/$G$10 -> 0.00021575432 | G7: =40.05*I7 -> 40.05 | H7: 320 | I7: 1 | J7: =(K7*G7)/1000 -> 0.68085 | K7: 17
A8: Parking Garage Area (Parking Zone and Ramps) | B8: South perimeter | C8: n/a | D8: Parking | E8: Yes | F8: =G8/$G$10 -> 0.074349478 | G8: =13801.33 -> 13801.33 | H8: 29904.25 | I8: 3 | J8: =(K8*G8)/1000 -> 69.00665 | K8: 5
A9: Parking Garage Area (Parking Zone and Ramps) | B9: West perimeter | C9: n/a | D9: Parking | E9: Yes | F9: =G9/$G$10 -> 0.074349478 | G9: =13801.33 -> 13801.33 | H9: 29904.25 | I9: 3 | J9: =(K9*G9)/1000 -> 69.00665 | K9: 5
A10: Total (3 Space types) | B10: Total ( 8 spaces) | C10: Total ( 1Thermal Zones) | E10: Total (1 Conditioned zones) | G10: =G3*I3+G4*I4+G5*I5+G6*I6+G7+G8*I8+G9*I9 -> 185627.8 | J10: =SUM(J3:J9) -> 316.0609
A22: Background Data [To be deleted prior to publication]

Sheet Envelope
A1: ="Envelope - "&Prototype!A2 -> Envelope - ParkingOpen
A2: Element | B2: Prototype | C2: Assembly Type | D2: Construction | E2: Thermal properties | F2: Vintage | G2: Selected T24 | H2: Note | I2: CZ1 | J2: CZ2 | K2: CZ3 | L2: CZ4 | M2: CZ5 | N2: CZ6 | O2: CZ7 | P2: CZ8 | Q2: CZ9 | R2: CZ10 | S2: CZ11 | T2: CZ12 | U2: CZ13 | V2: CZ14 | W2: CZ15 | X2: CZ16
A3: External Wall | B3: =Prototype!A2 -> ParkingOpen | C3: ExtWall_Concrete4in_Insulated | D3: 4 in. Concrete- Insulation (insulation only for ticket attendance ext wall) | E3: U-value IP | F3: Pre 1978 | G3: N/A | H3: ASHRAE 90.1, 2022 Table A3.1-2, 4", R-0, 135 lb/ft3 Density | I3: 0.87 | J3: 0.87 | K3: 0.87 | L3: 0.87 | M3: 0.87 | N3: 0.87 | O3: 0.87 | P3: 0.87 | Q3: 0.87 | R3: 0.87 | S3: 0.87 | T3: 0.87 | U3: 0.87 | V3: 0.87 | W3: 0.87 | X3: 0.87
F4: 1978-1997 | G4: 1986 | H4: Package A/ Heat Capacity was considered ~10 (BTU/F/ft²) | I4: =5/12.51 -> 0.39968026 | J4: =5/12.51 -> 0.39968026 | K4: =5/12.51 -> 0.39968026 | L4: =5/12.51 -> 0.39968026 | M4: =5/12.51 -> 0.39968026 | N4: =5/12.51 -> 0.39968026 | O4: =5/12.51 -> 0.39968026 | P4: =5/12.51 -> 0.39968026 | ... X4: =5/12.51 -> 0.39968026
F5: 1998-2007 | G5: 2001 | H5: Table 1-H | I5: 0.34 | J5: 0.43 | K5: 0.43 | L5: 0.43 | M5: 0.43 | N5: 0.43 | O5: 0.43 | P5: 0.43 | Q5: 0.43 | R5: 0.43 | S5: 0.43 | T5: 0.43 | U5: 0.43 | V5: 0.43 | W5: 0.43 | X5: 0.34
F6: 2008-2018 | G6: 2013 | H6: Table 140.3-B | I6: 0.196 | J6: 0.17 | K6: 0.278 | L6: 0.227 | M6: 0.44 | N6: 0.44 | O6: 0.44 | P6: 0.44 | Q6: 0.44 | R6: 0.17 | S6: 0.17 | T6: 0.17 | U6: 0.17 | V6: 0.17 | W6: 0.17 | X6: 0.17
F7: 2019+ | G7: 2025 | H7: Table 140.3-B | I7: 0.17 | J7: 0.138 | K7: 0.227 | L7: 0.196 | M7: 0.364 | N7: 0.364 | O7: 0.364 | P7: 0.364 | Q7: 0.364 | R7: 0.138 | S7: 0.138 | T7: 0.138 | U7: 0.138 | V7: 0.138 | W7: 0.138 | X7: 0.138
A8: Roof | B8: =$B$3 -> ParkingOpen | C8: FlatRoof_Concrete8in_Insulated | D8: Built-up Roof 8 in concrete deck + isulation ((insulation only for ticket attendant ceiling) | E8: U-value IP | F8: Pre 1978 | G8: N/A | H8: Considering 30 years for roof/ insulation replacement. | I8: 0.057 | J8: 0.057 | K8: 0.057 | L8: 0.057 | M8: 0.057 | N8: 0.078 | O8: 0.078 | P8: 0.078 | Q8: 0.078 | R8: 0.078 | S8: 0.057 | T8: 0.057 | U8: 0.057 | V8: 0.057 | W8: 0.057 | X8: 0.057
F9: 1978-1997 | G9: 1992 | I9: 0.057 | J9: 0.057 | K9: 0.057 | L9: 0.057 | M9: 0.057 | N9: 0.078 | O9: 0.078 | P9: 0.078 | Q9: 0.078 | R9: 0.078 | S9: 0.057 | T9: 0.057 | U9: 0.057 | V9: 0.057 | W9: 0.057 | X9: 0.057
F10: 1998-2007 | G10: 2001 | H10: Table 1-H | I10: 0.057 | J10: 0.057 | K10: 0.057 | L10: 0.057 | M10: 0.057 | N10: 0.078 | O10: 0.078 | P10: 0.078 | Q10: 0.078 | R10: 0.057 | S10: 0.057 | T10: 0.057 | U10: 0.057 | V10: 0.057 | W10: 0.057 | X10: 0.057
F11: 2008-2018 | G11: 2013 | H11: Table 140.3-B | I11: 0.049 | J11: 0.039 | K11: 0.039 | L11: 0.039 | M11: 0.049 | N11: 0.075 | O11: 0.067 | P11: 0.067 | Q11: 0.039 | R11: 0.039 | S11: 0.039 | T11: 0.039 | U11: 0.039 | V11: 0.039 | W11: 0.039 | X11: 0.039
F12: 2019+ | G12: 2025 | H12: Table 140.3-B | I12: 0.038 | J12: 0.038 | K12: 0.038 | L12: 0.038 | M12: 0.038 | N12: 0.038 | O12: 0.038 | P12: 0.038 | Q12: 0.038 | R12: 0.038 | S12: 0.038 | T12: 0.038 | U12: 0.038 | V12: 0.038 | W12: 0.038 | X12: 0.038
A13: **The unconditioned portion of the parking garage should only have concrete walls. However, there is also a small conditioned area served by an AHU system which should still use insulation in the assembly.

Sheet HVAC System
A1: ="HVAC system - "&Prototype!A2 -> HVAC system - ParkingOpen
A2: Vintage | B2: Zones | C2: Heating | D2: Cooling | E2: Air Distribution | F2: Source | G2: Note
A3: Exisiting | B3: Conditioned zones-Parking Attendant Zone | C3: Electric Unit heater | D3: n/a | E3: n/a | F3: Engineering judgement
A4: New Construction | B4: Conditioned zones-Parking Attendant Zone | C4: Electric Unit heater | D4: n/a | E4: n/a | F4: Engineering judgement
A9: Efficiency of HVAC system
A10: Vintage | B10: Upgrade/Installed year | C10: Electric Unit heater | D10: Heating DX | E10: Cooling DX | F10: Sources | G10: Note
A11: Pre 1978 | B11: 2008 | C11: Thermal Efficiency of 1 | D11: n/a | E11: n/a
A12: 1978-1997
A13: 1998-2007
A14: 2008-2018 | B14: 2013 | C14: Thermal Efficiency of 1 | D14: n/a | E14: n/a
A15: New Construction | B15: 2025 | C15: Thermal Efficiency of 1 | D15: n/a | E15: n/a
C17: * Et = Combustion efficiency | D17: * Et = Thermal efficiency
A19: Fan power
A20: Vintage | B20: Approach | C20: System | D20: Total Static Pressure (TSP) in w.c. [PNNL 20405, 2010, Table 5.11] | E20: Fan Efficiency [ACM, 2025] | F20: Fan Motor and Drive Efficiency [ACM 2025, Table 13] | G20: W/cfm [ACM 2025, Table 14 and 15] | H20: Data Source | I20: Note
A21: Existing | B21: PNNL TSP | C21: PTAC, PTHP, or FCUs | D21: 1.33 | E21: 0.65 | F21: 0.9 | H21: PNNL 2010 TSD
A22: Brake horse power (bhp)=(Supply cfm*TSP in w.c.)/(6356*Fan efficiency)
A23: Fan power (w/cfm) = bhp/motor and drive efficiency *746
A24: New Construction | B24: ACM 2025 | C24: PTAC, PTHP, or FCUs | D24: 1.33 | E24: 0.65 | F24: 0.9 | G24: 0.53 | H24: 2025 ACM
F25: * 0.9 is an average fan efficiency according to ACM 2025, Table 13
A26: Fan total eff (E+ input) = 0.65 x Motor_eff
A27: TSP (E+ input) in w.c. = Motor_eff/746 x (6356 x Fan_eff) x W/cfm
A28: Fan_eff=0.65
A32: Background Data [To be deleted prior to publication]

Sheet Ventilation
A1: ="Outdoor Airflow Rate - "&Prototype!A2 -> Outdoor Airflow Rate - ParkingOpen
A2: Space Type | B2: Space/Thermal Zone | C2: Number of People | D2: Floor Area (ft²) | E2: cfm/person [T24, 2025, Equation 120.1-F and Table 120.1-A] | F2: cfm/ft² [T24, 2025, Equation 120.1-F and Table 120.1-A] | G2: Required exhaust rate-CFM/ft²- [T24, 2025, Table 120.1-B – minimum exhaust rates] | H2: Total cfm driven by people | I2: Total cfm driven by area | J2: Total cfm driven by exhaust | K2: Total cfm | L2: Notes
A3: =Zones!A3 -> Parking Garage Area (Parking Zone and Ramps) | B3: =Zones!B3 -> Core | C3: =Zones!J3 -> 30.25275 | D3: =Zones!G3 -> 6050.55 | E3: 0 | F3: 0 | G3: 0 | H3: =C3*E3 -> 0 | I3: =D3*F3 -> 0 | J3: =G3*D3 -> 0 | K3: =MAX(H3,I3,J3) -> 0
A4: =Zones!A4 -> Parking Garage Area (Daylight Adaptation Zones) | B4: =Zones!B4 -> Daylight adaption | C4: =Zones!J4 -> 9.1007 | D4: =Zones!G4 -> 1820.14 | E4: 0 | F4: 0 | G4: 0 | H4: =C4*E4 -> 0 | I4: =D4*F4 -> 0 | J4: =G4*D4 -> 0 | K4: =MAX(H4,I4,J4) -> 0
A5: =Zones!A5 -> Parking Garage Area (Parking Zone and Ramps) | B5: =Zones!B5 -> East perimeter | C5: =Zones!J5 -> 69.00665 | D5: =Zones!G5 -> 13801.33 | E5: 0 | F5: 0 | G5: 0 | H5: =C5*E5 -> 0 | I5: =D5*F5 -> 0 | J5: =G5*D5 -> 0 | K5: =MAX(H5,I5,J5) -> 0
A6: =Zones!A6 -> Parking Garage Area (Parking Zone and Ramps) | B6: =Zones!B6 -> North perimeter | C6: =Zones!J6 -> 69.00665 | D6: =Zones!G6 -> 13801.33 | E6: 0 | F6: 0 | G6: 0 | H6: =C6*E6 -> 0 | I6: =D6*F6 -> 0 | J6: =G6*D6 -> 0 | K6: =MAX(H6,I6,J6) -> 0
A7: =Zones!A7 -> Retail Sales Area (Retail Merchandise Sales) | B7: =Zones!B7 -> Parking attendant | C7: =Zones!J7 -> 0.68085 | D7: =Zones!G7 -> 40.05 | E7: 15 | F7: 0.2 | G7: 0 | H7: =C7*E7 -> 10.21275 | I7: =D7*F7 -> 8.01 | J7: =G7*D7 -> 0 | K7: =MAX(H7,I7,J7) -> 10.21275 | L7: Exhaust shall not be required where two or more sides comprise walls that are at least 50% open to the outside.
A8: =Zones!A8 -> Parking Garage Area (Parking Zone and Ramps) | B8: =Zones!B8 -> South perimeter | C8: =Zones!J8 -> 69.00665 | D8: =Zones!G8 -> 13801.33 | E8: 0 | F8: 0 | G8: 0 | H8: =C8*E8 -> 0 | I8: =D8*F8 -> 0 | J8: =G8*D8 -> 0 | K8: =MAX(H8,I8,J8) -> 0
A9: =Zones!A9 -> Parking Garage Area (Parking Zone and Ramps) | B9: =Zones!B9 -> West perimeter | C9: =Zones!J9 -> 69.00665 | D9: =Zones!G9 -> 13801.33 | E9: 0 | F9: 0 | G9: 0 | H9: =C9*E9 -> 0 | I9: =D9*F9 -> 0 | J9: =G9*D9 -> 0 | K9: =MAX(H9,I9,J9) -> 0
A18: Background Data [To be deleted prior to publication]
A21: Requirement | B21: Description | C21: Criterion | D21: Value / Standard
A22: Airflow Modulation | B22: Reduce to minimum 10 ACH or pressurization limit | C22: Pressure relationship | D22: Negative relative to adjacent spaces
A23: Variable Exhaust/Makeup Air | B23: Coordinated VAV systems for pressurization | C23: Pressure differential target | D23: 0.01–0.05 in. w.c.
A24: Fan Power Limit | B24: ≤ 0.65 W/CFM (standard); ≤ 0.85 W/CFM (with filtration) | C24: Infiltration modeling | D24: Not the primary OA source; modeled as tightly controlled
A25: Sash Closure Controls | B25: Auto-close after 5 min inactivity with safety features | C25: Envelope air barrier | D25: Required per T24 standards
A26: Makeup Air Compliance | B26: Must meet Section 140.4(o) standards | C26: Standard reference | D26: ANSI Z9.5-2022, ASHRAE 62.1, ASHRAE 90.1
A28: ="Outdoor Airflow Rate - "&Prototype!B4 -> Outdoor Airflow Rate - Open Parking
A29: Space Type | B29: Total ft² | C29: Min. occupancy load (persons/1000 ft²) | D29: Total Number of Occupants | E29: cfm/ft² (Table 120.1-A – Minimum Ventilation Rates) | F29: Required Exhaust Rate-CFM/ft² (Table 120.1-B – Minimum Exhaust Rates) | G29: cfm | H29: Source
A30: =Zones!A3 -> Parking Garage Area (Parking Zone and Ramps) | B30: =SUMIF(Zones!A$3:A$9, "*Science laboratories*", Zones!G3:G9) -> 0 | C30: =Zones!K3 -> 5 | D30: =(B30/1000)*C30 -> 0 | E30: 0.15 | F30: 1 | G30: =MAX(E30*B30,D30*15,F30*B30) -> 0 | H30: T24, 2025, Equation 120.1-F and Table 120.1-A
A31: =Zones!#REF! -> #REF! | B31: =SUMIF(Zones!A$3:A$9, "*Office Area (>250 square feet)*", Zones!G$3:G$9) -> 0 | C31: =Zones!#REF! -> #REF! | D31: =(B31/1000)*C31 -> #REF! | E31: 0.15 | G31: =MAX(E31*B31,D31*15,F31*B31) -> #REF!
A32: Total | B32: =SUM(B30:B31) -> 0 | D32: =SUM(D30:D31) -> #REF! | G32: =SUM(G30:G31) -> #REF!

Sheet Thermostat
A1: ="Thermostat Setpoints - "&Prototype!A2 -> Thermostat Setpoints - ParkingOpen
A2: Setpoint | B2: CZ1 | C2: CZ2 | D2: CZ3 | E2: CZ4 | F2: CZ5 | G2: CZ6 | H2: CZ7 | I2: CZ8 | J2: CZ9 | K2: CZ10 | L2: CZ11 | M2: CZ12 | N2: CZ13 | O2: CZ14 | P2: CZ15 | Q2: CZ16 | R2: Source | S2: Note
A3: Parking Attendant Heating Setpoint (F) | B3: 70 | C3: 70 | D3: 70 | E3: 70 | F3: 70 | G3: 70 | H3: 70 | I3: 70 | J3: 70 | K3: 70 | L3: 70 | M3: 70 | N3: 70 | O3: 70 | P3: 70 | Q3: 70 | R3: T24 2022 - Appendix 5.4B | S3: The parking attendant area is fully conditioned in the CEC model, this is the setpoint requirement for that area.
A4: Parking AttendantSetback (F) | B4: 60 | C4: 60 | D4: 60 | E4: 60 | F4: 60 | G4: 60 | H4: 60 | I4: 60 | J4: 60 | K4: 60 | L4: 60 | M4: 60 | N4: 60 | O4: 60 | P4: 60 | Q4: 60
A5: Parking Attendant Setpoint (F) | B5: 75 | C5: 75 | D5: 75 | E5: 75 | F5: 75 | G5: 75 | H5: 75 | I5: 75 | J5: 75 | K5: 75 | L5: 75 | M5: 75 | N5: 75 | O5: 75 | P5: 75 | Q5: 75
A6: Parking Attendant Setback (F) | B6: 85 | C6: 85 | D6: 85 | E6: 85 | F6: 85 | G6: 85 | H6: 85 | I6: 85 | J6: 85 | K6: 85 | L6: 85 | M6: 85 | N6: 85 | O6: 85 | P6: 85 | Q6: 85
A9: Office Cooling Setback (F) | B9: 85 | C9: 85 | D9: 85 | E9: 85 | F9: 85 | G9: 85 | H9: 85 | I9: 85 | J9: 85 | K9: 85 | L9: 85 | M9: 85 | N9: 85 | O9: 85 | P9: 85 | Q9: 85
A11: Source: PNNL Healthcare-Outpaitiet prototype use this setpoints: Administration zones: 72°F Cooling/70°F Heating, Critical zones: 72°F Cooling/70°F Heating, Operating rooms: 65°F Cooling/65°F Heating
A12: PNNL Healthcare-Outpaitiet prototype use this setbacks: 77°F Cooling/65°F Heating, Critical zones: no setback, Operating rooms: 72°F Cooling/65°F Heating

Sheet Water Heater
A1: ="Water Heater - "&Prototype!A2 -> Water Heater - ParkingOpen
A2: Vintage | B2: WH Type | C2: Efficiency | D2: Tank Volume (gal) | E2: Tank Loss | F2: Unit | G2: Note
A3: Existing | B3: Electric | C3: 1 | D3: =F22 -> 30 | E3: =G25 -> 1.2 | F3: (%/hr) | G3: Engineering judgement
A4: New Construction | B4: Electric | C4: 1 | D4: =F22 -> 30 | E4: =G22 -> 1.2 | F4: (%/hr) | G4: According to 2025 ACM
A7: Peak Hot Water Consumption
A8: Space Name | B8: Baseline WH Type [CEUS 2022] | C8: Total Area (ft²) | D8: Number of People | E8: Hot Water Usage Specification (gal/hr per person) [T24, 2022, Appendix 5.4A , sheet: "2022 SpaceFuncData-Input"] | F8: Peak Hot Water Usage (gal/hr) | G8: Peak Hot Water Usage (gal/min)
A9: =Zones!B3 -> Core | B9: Electric | C9: =Zones!G3 -> 6050.55 | D9: =Zones!J3 -> 30.25275 | E9: 0 | F9: =E9*D9 -> 0 | G9: =F9/60 -> 0
A10: =Zones!B4 -> Daylight adaption | B10: Electric | C10: =Zones!G4 -> 1820.14 | D10: =Zones!J4 -> 9.1007 | E10: 0 | F10: =E10*D10 -> 0 | G10: =F10/60 -> 0
A11: =Zones!B5 -> East perimeter | B11: Electric | C11: =Zones!G5 -> 13801.33 | D11: =Zones!J5 -> 69.00665 | E11: 0 | F11: =E11*D11 -> 0 | G11: =F11/60 -> 0
A12: =Zones!B6 -> North perimeter | B12: Electric | C12: =Zones!G6 -> 13801.33 | D12: =Zones!J6 -> 69.00665 | E12: 0 | F12: =E12*D12 -> 0 | G12: =F12/60 -> 0
A13: =Zones!B7 -> Parking attendant | B13: Electric | C13: =Zones!G7 -> 40.05 | D13: =Zones!J7 -> 0.68085 | E13: 0.18 | F13: =E13*D13 -> 0.122553 | G13: =F13/60 -> 0.00204255
A14: =Zones!B8 -> South perimeter | B14: Electric | C14: =Zones!G8 -> 13801.33 | D14: =Zones!J8 -> 69.00665 | E14: 0 | F14: =E14*D14 -> 0 | G14: =F14/60 -> 0
A15: =Zones!B9 -> West perimeter | B15: Electric | C15: =Zones!G9 -> 13801.33 | D15: =Zones!J9 -> 69.00665 | E15: 0 | F15: =E15*D15 -> 0 | G15: =F15/60 -> 0
A16: Total | C16: =SUM(C9:C10) -> 7870.69 | D16: =SUM(D9:D10) -> 39.35345 | F16: =SUM(F9:F15) -> 0.122553 | G16: =F16/60 -> 0.00204255
A20: Water Heater Capacity, Tank Capacity, and Tank Loss
A21: WH Type | B21: Peak Hot Water Usage (gal/hr) | C21: Heat Output (Btu/hr) [ACM, 2025, 5.9.2: Rated capacity section] | D21: WH Capacity (Btu/hr) [ACM, 2025, 5.9.2: Rated capacity section] | E21: Required Energy Input (Btu/hr) | F21: Storage Volume (ga) | G21: Standby Loss | H21: Unit | I21: Off/On Cycle Loss Coefficient to Ambient Temp (Btu/h-F) | J21: Source
A22: Electric | B22: =MAX(SUMIF(B9:B11, "*Electric*", F9:F11),75) -> 75 | C22: =B22*(135-55)*8.2877*1 -> 49726.2 | D22: =C22*0.6 -> 29835.72 | E22: =D22/0.9498 -> 31412.634 | F22: =B22*1*0.4 -> 30 | G22: =0.3+(27/F22) -> 1.2 | H22: %/hr | I22: =0.0834*G22*F22 -> 3.0024 | J22: Standby loss equation: Title 20, §1605.1 Table F-4 WH capacity equation: ACM, 2025, 5.9.2: Rated capacity section)
A23: Total | B23: =B22 -> 75 | C23: =C22 -> 49726.2 | D23: =D22 -> 29835.72 | E23: =E22 -> 31412.634
A25: Design supply temperature (F) | B25: 135 | C25: Ref: T24 2022 - Appendix 5.4B | F25: Standby Loss for Existing | G25: =G22 -> 1.2 | H25: Btu/hr | I25: =0.0834*G22*F22 -> 3.0024
A26: Cold Water supply temperature (F) | B26: 55 | C26: Ref: ACM, 2025, 5.9.2: Rated capacity section
A27: WH system factor | B27: 0.6 | C27: Ref: ACM, 2025, 5.9.2: Rated capacity section
A28: Reheat multiplier | B28: 0.4
A29: * The 0.40 multiplier is a storage sizing factor used to account for the fact that the water heater doesn't need to store the full peak hour demand—it can reheat water during that time. This factor assumes that the heater will recover part of the hot water used during the peak hour, so only 40% of the peak hour demand needs to be stored at any given moment.
A30: **For Gas Water Heater: UA(Btu/h-°F)​=Q˙​SL​ (Btu/h)/ΔT (∘F)​
A31: Ambient temp | B31: 68
A32: Delta T | B32: =B25-B31 -> 67
A33: ** For Electric Water Heater: UA(Btu/h-°F)​= 0.0834 *SL​ (%/hr)*V gal
A35: Background Data [To be deleted prior to publication]

Sheet Interior Lights
A1: ="Interior Lighting - "&Prototype!A2 -> Interior Lighting - ParkingOpen
A2: Space Type | B2: New Construction | E2: Existing
B3: Lighting density (W/ft²) | C3: Additional lighting power for porTable lighting (W/ft²) | D3: Source | E3: LPD (W/ft²) | F3: Additional LPD for PorTable Lighting (W/ft²) | G3: Source
A4: =Zones!A3 -> Parking Garage Area (Parking Zone and Ramps) | B4: 0.1 | D4: T24, 2025, Table 140.6 C (Area category method) | E4: 0.14 | G4: T24, 2016, Table 140.6 C (Area category method)
A5: =Zones!A4 -> Parking Garage Area (Daylight Adaptation Zones) | B5: 1 | E5: 0.75
A6: =Zones!A7 -> Retail Sales Area (Retail Merchandise Sales) | B6: 0.95 | E6: 1.2 | H6: *Parking attendant zone

Sheet Ext Lighting
A1: ="Exterior Lighting - "&Prototype!A2 -> Exterior Lighting - ParkingOpen
A2: Motion Controlled Luminaires (W) | B2: Non-motion Controlled Luminaires (W) | C2: Total (W) | D2: Source
A3: =G16 -> 200 | B3: =G17 -> 782.541 | C3: =A3+B3 -> 982.541 | D3: T24, 2022 & 2025 2019 Outdoor Lighting CASE report PNNL 90.1-2010 TSD
A7: ="Exterior Lighting" -> Exterior Lighting
A8: Items (Assume LZ2) | B8: Assumptions [2019 Outdoor Lighting CASE Report & PNNL 90.1-2010 TSD] | D8: Unit | E8: Lighting Power Allowance [T24, 2025, Table 140.7-A & 140.7-B] | F8: Unit | G8: Exterior Lighting Power (W)
A9: IWA (Initial Wattage Allowance) | E9: 200 | F9: (W) | G9: =$E9 -> 200
A10: Parking area | B10: 400 ft² for every parking space 1 parking space per 830 ft² of gross building area | C10: 0 | D10: (ft²) | E10: 0.019 | F10: (W/ft²)
A11: Building Entrance | B11: 14 building entrance per PNNL Model | D11: (count) | E11: 15 | F11: (W/ea) | G11: =E11*C11 -> 0
A12: Hardscape Ornamental Light | B12: 0.1 ft² per 1 ft² of gross building area for hardscape ornamental light | C12: 18563 | D12: (ft²) | E12: 0.007 | F12: (W/ft²) | G12: =E12*C12 -> 129.941
A13: Building façade | B13: 0.1 W per 1 ft² of facade area Façade Area = Perimeter × 0.5 × 13 ft * The 0.5 factor assumes that only half of the perimeter walls are lit. -Formula ia developed based on the 2019 Outdoor Lighting CASE report | C13: =B23*0.5*13 -> 6526 | D13: (ft²) | E13: 0.1 | F13: (W/ft²) | G13: =E13*C13 -> 652.6
A14: Security lighting for retail parking | B14: 1 sf per 100 sf of gross building area | D14: (ft²) | E14: 0.005 | F14: (W/ft²) | G14: =E14*C14 -> 0
A15: Non-sales canopy | D15: (ft²) | E15: 0.137 | F15: (W/ft²) | G15: =E15*C15 -> 0
A16: Motion Controlled Luminaires (W) | G16: =G10+G9+G15+G11+G14 -> 200
A17: Non-motion-controlled Luminaires | G17: =G12+G13 -> 782.541
A18: Total | G18: =G16+G17 -> 982.541
A22: Total floor area | B22: =Prototype!B8 -> 185627.8
A23: Perimeter | B23: 1004
A24: Floors | B24: 3
A30: Background Data [To be deleted prior to publication]

Sheet Equipment
A1: ="Equipment - "&Prototype!A2 -> Equipment - ParkingOpen
A2: Spaces | B2: Plug load Power Density (W/ft²) | C2: Gas Power Density (Btu/hr-ft²) | D2: Refrigeration Power Density (W/ft²) | E2: Source | F2: Note
A3: =Zones!A3 -> Parking Garage Area (Parking Zone and Ramps) | B3: 0 | C3: 0 | D3: 0 | E3: T24 2022 - Appendix 5.4A
A4: =Zones!A4 -> Parking Garage Area (Daylight Adaptation Zones) | B4: 0 | C4: 0 | D4: 0
A5: =Zones!A7 -> Retail Sales Area (Retail Merchandise Sales) | B5: 0.4 | C5: 0 | D5: 0 | F5: Parking attendant zone - Plug load and schedules project with CEC, 2025
A10: Background Data [To be deleted prior to publication]

Sheet Schedules
A1: ="Schedules - "&Prototype!A2 -> Schedules - ParkingOpen
A2: Zone | B2: Schedule Category | C2: Schedule | D2: Source | E2: Type | F2: Hour
F3: 1 | G3: 2 | H3: 3 | I3: 4 | J3: 5 | K3: 6 | L3: 7 | M3: 8 | N3: 9 | O3: 10 | P3: 11 | Q3: 12 | R3: 13 | S3: 14 | T3: 15 | U3: 16 | V3: 17 | W3: 18 | X3: 19 | Y3: 20 | Z3: 21 | AA3: 22 | AB3: 23 | AC3: 24
A4: Parking Zones | B4: Parking | C4: Occupancy | D4: T24 2022 - Appendix 5.4B, [Parking] | E4: Weekday | F4: 0 | G4: 0 | H4: 0 | I4: 0 | J4: 0 | K4: 0 | L4: 0 | M4: 0 | N4: 0 | O4: 0 | P4: 0 | Q4: 0 | R4: 0 | S4: 0 | T4: 0 | U4: 0 | V4: 0 | W4: 0 | X4: 0 | Y4: 0 | Z4: 0 | AA4: 0 | AB4: 0 | AC4: 0
E5: Saturday | F5: 0 | G5: 0 | H5: 0 | I5: 0 | J5: 0 | K5: 0 | L5: 0 | M5: 0 | N5: 0 | O5: 0 | P5: 0 | Q5: 0 | R5: 0 | S5: 0 | T5: 0 | U5: 0 | V5: 0 | W5: 0 | X5: 0 | Y5: 0 | Z5: 0 | AA5: 0 | AB5: 0 | AC5: 0
E6: Sunday | F6: 0 | G6: 0 | H6: 0 | I6: 0 | J6: 0 | K6: 0 | L6: 0 | M6: 0 | N6: 0 | O6: 0 | P6: 0 | Q6: 0 | R6: 0 | S6: 0 | T6: 0 | U6: 0 | V6: 0 | W6: 0 | X6: 0 | Y6: 0 | Z6: 0 | AA6: 0 | AB6: 0 | AC6: 0
A7: Parking Zones | B7: Parking | C7: Lights | D7: T24 2022 - Appendix 5.4B, [Parking] | E7: Weekday | F7: 0.5 | G7: 0.5 | H7: 0.5 | I7: 0.5 | J7: 0.5 | K7: 0.5 | L7: 1 | M7: 1 | N7: 1 | O7: 1 | P7: 1 | Q7: 1 | R7: 1 | S7: 1 | T7: 1 | U7: 1 | V7: 1 | W7: 1 | X7: 1 | Y7: 1 | Z7: 1 | AA7: 1 | AB7: 0.5 | AC7: 0.5
E8: Saturday | F8: 0.5 | G8: 0.5 | H8: 0.5 | I8: 0.5 | J8: 0.5 | K8: 0.5 | L8: 1 | M8: 1 | N8: 1 | O8: 1 | P8: 1 | Q8: 1 | R8: 1 | S8: 1 | T8: 1 | U8: 1 | V8: 1 | W8: 0.5 | X8: 0.5 | Y8: 0.5 | Z8: 0.5 | AA8: 0.5 | AB8: 0.5 | AC8: 0.5
E9: Sunday | F9: 0.5 | G9: 0.5 | H9: 0.5 | I9: 0.5 | J9: 0.5 | K9: 0.5 | L9: 0.5 | M9: 0.5 | N9: 0.5 | O9: 0.5 | P9: 0.5 | Q9: 0.5 | R9: 0.5 | S9: 0.5 | T9: 0.5 | U9: 0.5 | V9: 0.5 | W9: 0.5 | X9: 0.5 | Y9: 0.5 | Z9: 0.5 | AA9: 0.5 | AB9: 0.5 | AC9: 0.5
A10: Parking Zones | B10: Parking | C10: ElecEquipment | D10: T24 2022 - Appendix 5.4B, [Parking] | E10: Weekday | F10: =F7 -> 0.5 | G10: =G7 -> 0.5 | H10: =H7 -> 0.5 | I10: =I7 -> 0.5 | J10: =J7 -> 0.5 | K10: =K7 -> 0.5 | L10: =L7 -> 1 | M10: =M7 -> 1 | ... AC10: =AC7 -> 0.5
E11: Saturday | F11: =F8 -> 0.5 | G11: =G8 -> 0.5 | H11: =H8 -> 0.5 | I11: =I8 -> 0.5 | J11: =J8 -> 0.5 | K11: =K8 -> 0.5 | L11: =L8 -> 1 | M11: =M8 -> 1 | ... AC11: =AC8 -> 0.5
E12: Sunday | F12: =F9 -> 0.5 | G12: =G9 -> 0.5 | H12: =H9 -> 0.5 | I12: =I9 -> 0.5 | J12: =J9 -> 0.5 | K12: =K9 -> 0.5 | L12: =L9 -> 0.5 | M12: =M9 -> 0.5 | ... AC12: =AC9 -> 0.5
A13: Parking Zones | B13: Parking | C13: GasEquipment | D13: T24 2022 - Appendix 5.4B, [Parking] | E13: Weekday | F13: 0 | G13: 0 | H13: 0 | I13: 0 | J13: 0 | K13: 0 | L13: 0 | M13: 0 | N13: 0 | O13: 0 | P13: 0 | Q13: 0 | R13: 0 | S13: 0 | T13: 0 | U13: 0 | V13: 0 | W13: 0 | X13: 0 | Y13: 0 | Z13: 0 | AA13: 0 | AB13: 0 | AC13: 0
E14: Saturday | F14: 0 | G14: 0 | H14: 0 | I14: 0 | J14: 0 | K14: 0 | L14: 0 | M14: 0 | N14: 0 | O14: 0 | P14: 0 | Q14: 0 | R14: 0 | S14: 0 | T14: 0 | U14: 0 | V14: 0 | W14: 0 | X14: 0 | Y14: 0 | Z14: 0 | AA14: 0 | AB14: 0 | AC14: 0
E15: Sunday | F15: 0 | G15: 0 | H15: 0 | I15: 0 | J15: 0 | K15: 0 | L15: 0 | M15: 0 | N15: 0 | O15: 0 | P15: 0 | Q15: 0 | R15: 0 | S15: 0 | T15: 0 | U15: 0 | V15: 0 | W15: 0 | X15: 0 | Y15: 0 | Z15: 0 | AA15: 0 | AB15: 0 | AC15: 0
A16: Parking Attendant
A17: Ticket Attendant Zone | B17: TicketAttendant | C17: Occupancy | D17: T24 2022 - Appendix 5.4B, [Parking] | E17: Weekday | F17: 0 | G17: 0 | H17: 0 | I17: 0 | J17: 0 | K17: 0 | L17: 1 | M17: 1 | N17: 1 | O17: 1 | P17: 1 | Q17: 1 | R17: 1 | S17: 1 | T17: 1 | U17: 1 | V17: 1 | W17: 0 | X17: 0 | Y17: 0 | Z17: 0 | AA17: 0 | AB17: 0 | AC17: 0
E18: Saturday | F18: 0 | G18: 0 | H18: 0 | I18: 0 | J18: 0 | K18: 0 | L18: 0 | M18: 1 | N18: 1 | O18: 1 | P18: 1 | Q18: 1 | R18: 1 | S18: 1 | T18: 1 | U18: 0 | V18: 0 | W18: 0 | X18: 0 | Y18: 0 | Z18: 0 | AA18: 0 | AB18: 0 | AC18: 0
E19: Sunday | F19: 0 | G19: 0 | H19: 0 | I19: 0 | J19: 0 | K19: 0 | L19: 0 | M19: 0 | N19: 0 | O19: 0 | P19: 0 | Q19: 0 | R19: 0 | S19: 0 | T19: 0 | U19: 0 | V19: 0 | W19: 0 | X19: 0 | Y19: 0 | Z19: 0 | AA19: 0 | AB19: 0 | AC19: 0
A20: Ticket Attendant Zone | B20: TicketAttendant | C20: Lights | D20: T24 2022 - Appendix 5.4B, [Parking] | E20: Weekday | F20: =F17 -> 0 | G20: =G17 -> 0 | H20: =H17 -> 0 | I20: =I17 -> 0 | J20: =J17 -> 0 | K20: =K17 -> 0 | L20: =L17 -> 1 | M20: =M17 -> 1 | ... AC20: =AC17 -> 0
E21: Saturday | F21: =F18 -> 0 | G21: =G18 -> 0 | H21: =H18 -> 0 | I21: =I18 -> 0 | J21: =J18 -> 0 | K21: =K18 -> 0 | L21: =L18 -> 0 | M21: =M18 -> 1 | ... AC21: =AC18 -> 0
E22: Sunday | F22: =F19 -> 0 | G22: =G19 -> 0 | H22: =H19 -> 0 | I22: =I19 -> 0 | J22: =J19 -> 0 | K22: =K19 -> 0 | L22: =L19 -> 0 | M22: =M19 -> 0 | ... AC22: =AC19 -> 0
A23: Ticket Attendant Zone | B23: TicketAttendant | C23: ElecEquipment | D23: T24 2022 - Appendix 5.4B, [Parking] | E23: Weekday | F23: =F17 -> 0 | G23: =G17 -> 0 | H23: =H17 -> 0 | I23: =I17 -> 0 | J23: =J17 -> 0 | K23: =K17 -> 0 | L23: =L17 -> 1 | M23: =M17 -> 1 | ... AC23: =AC17 -> 0
E24: Saturday | F24: =F18 -> 0 | G24: =G18 -> 0 | H24: =H18 -> 0 | I24: =I18 -> 0 | J24: =J18 -> 0 | K24: =K18 -> 0 | L24: =L18 -> 0 | M24: =M18 -> 1 | ... AC24: =AC18 -> 0
E25: Sunday | F25: =F19 -> 0 | G25: =G19 -> 0 | H25: =H19 -> 0 | I25: =I19 -> 0 | J25: =J19 -> 0 | K25: =K19 -> 0 | L25: =L19 -> 0 | M25: =M19 -> 0 | ... AC25: =AC19 -> 0
A26: Ticket Attendant Zone | B26: TicketAttendant | C26: ServiceHotWater | D26: T24 2022 - Appendix 5.4B, [Parking] | E26: Weekday | F26: 0 | G26: 0 | H26: 0 | I26: 0 | J26: 0 | K26: 0 | L26: 0 | M26: 0 | N26: 0 | O26: 0 | P26: 0 | Q26: 0 | R26: 0 | S26: 0 | T26: 0 | U26: 0 | V26: 0 | W26: 0 | X26: 0 | Y26: 0 | Z26: 0 | AA26: 0 | AB26: 0 | AC26: 0
E27: Saturday | F27: 0 | G27: 0 | H27: 0 | I27: 0 | J27: 0 | K27: 0 | L27: 0 | M27: 0 | N27: 0 | O27: 0 | P27: 0 | Q27: 0 | R27: 0 | S27: 0 | T27: 0 | U27: 0 | V27: 0 | W27: 0 | X27: 0 | Y27: 0 | Z27: 0 | AA27: 0 | AB27: 0 | AC27: 0
E28: Sunday | F28: 0 | G28: 0 | H28: 0 | I28: 0 | J28: 0 | K28: 0 | L28: 0 | M28: 0 | N28: 0 | O28: 0 | P28: 0 | Q28: 0 | R28: 0 | S28: 0 | T28: 0 | U28: 0 | V28: 0 | W28: 0 | X28: 0 | Y28: 0 | Z28: 0 | AA28: 0 | AB28: 0 | AC28: 0
A29: Ticket Attendant Zone | B29: TicketAttendant | C29: HVACAvail | D29: T24 2022 - Appendix 5.4B, [Parking] | E29: Weekday | F29: =IF(F17=1,1,0) -> 0 | G29: =IF(G17=1,1,0) -> 0 | H29: =IF(H17=1,1,0) -> 0 | I29: =IF(I17=1,1,0) -> 0 | J29: =IF(J17=1,1,0) -> 0 | K29: =IF(K17=1,1,0) -> 0 | L29: =IF(L17=1,1,0) -> 1 | M29: =IF(M17=1,1,0) -> 1 | ... AC29: =IF(AC17=1,1,0) -> 0
E30: Saturday | F30: =IF(F18=1,1,0) -> 0 | G30: =IF(G18=1,1,0) -> 0 | H30: =IF(H18=1,1,0) -> 0 | I30: =IF(I18=1,1,0) -> 0 | J30: =IF(J18=1,1,0) -> 0 | K30: =IF(K18=1,1,0) -> 0 | L30: =IF(L18=1,1,0) -> 0 | M30: =IF(M18=1,1,0) -> 1 | ... AC30: =IF(AC18=1,1,0) -> 0
E31: Sunday | F31: =IF(F19=1,1,0) -> 0 | G31: =IF(G19=1,1,0) -> 0 | H31: =IF(H19=1,1,0) -> 0 | I31: =IF(I19=1,1,0) -> 0 | J31: =IF(J19=1,1,0) -> 0 | K31: =IF(K19=1,1,0) -> 0 | L31: =IF(L19=1,1,0) -> 0 | M31: =IF(M19=1,1,0) -> 0 | ... AC31: =IF(AC19=1,1,0) -> 0
A32: Ticket Attendant Zone | B32: TicketAttendant | C32: Infiltration | D32: T24 2022 - Appendix 5.4B, [Parking] | E32: Weekday | F32: =IF(F17=0,1,0.25) -> 1 | G32: =IF(G17=0,1,0.25) -> 1 | H32: =IF(H17=0,1,0.25) -> 1 | I32: =IF(I17=0,1,0.25) -> 1 | J32: =IF(J17=0,1,0.25) -> 1 | K32: =IF(K17=0,1,0.25) -> 1 | L32: =IF(L17=0,1,0.25) -> 0.25 | M32: =IF(M17=0,1,0.25) -> 0.25 | ... AC32: =IF(AC17=0,1,0.25) -> 1
E33: Saturday | F33: =IF(F18=0,1,0.25) -> 1 | G33: =IF(G18=0,1,0.25) -> 1 | H33: =IF(H18=0,1,0.25) -> 1 | I33: =IF(I18=0,1,0.25) -> 1 | J33: =IF(J18=0,1,0.25) -> 1 | K33: =IF(K18=0,1,0.25) -> 1 | L33: =IF(L18=0,1,0.25) -> 1 | M33: =IF(M18=0,1,0.25) -> 0.25 | ... AC33: =IF(AC18=0,1,0.25) -> 1
E34: Sunday | F34: =IF(F19=0,1,0.25) -> 1 | G34: =IF(G19=0,1,0.25) -> 1 | H34: =IF(H19=0,1,0.25) -> 1 | I34: =IF(I19=0,1,0.25) -> 1 | J34: =IF(J19=0,1,0.25) -> 1 | K34: =IF(K19=0,1,0.25) -> 1 | L34: =IF(L19=0,1,0.25) -> 1 | M34: =IF(M19=0,1,0.25) -> 1 | ... AC34: =IF(AC19=0,1,0.25) -> 1
A35: Ticket Attendant Zone | B35: TicketAttendant | C35: HtgSetpt | D35: T24 2022 - Appendix 5.4B, [Parking] | E35: Weekday | F35: =IF(F29=1,Thermostat!$B$3,Thermostat!$B$4) -> 60 | G35: =IF(G29=1,Thermostat!$B$3,Thermostat!$B$4) -> 60 | H35: =IF(H29=1,Thermostat!$B$3,Thermostat!$B$4) -> 60 | I35: =IF(I29=1,Thermostat!$B$3,Thermostat!$B$4) -> 60 | J35: =IF(J29=1,Thermostat!$B$3,Thermostat!$B$4) -> 60 | K35: =IF(K29=1,Thermostat!$B$3,Thermostat!$B$4) -> 60 | L35: =IF(L29=1,Thermostat!$B$3,Thermostat!$B$4) -> 70 | M35: =IF(M29=1,Thermostat!$B$3,Thermostat!$B$4) -> 70 | ... AC35: =IF(AC29=1,Thermostat!$B$3,Thermostat!$B$4) -> 60
E36: Saturday | F36: =IF(F30=1,Thermostat!$B$3,Thermostat!$B$4) -> 60 | G36: =IF(G30=1,Thermostat!$B$3,Thermostat!$B$4) -> 60 | H36: =IF(H30=1,Thermostat!$B$3,Thermostat!$B$4) -> 60 | I36: =IF(I30=1,Thermostat!$B$3,Thermostat!$B$4) -> 60 | J36: =IF(J30=1,Thermostat!$B$3,Thermostat!$B$4) -> 60 | K36: =IF(K30=1,Thermostat!$B$3,Thermostat!$B$4) -> 60 | L36: =IF(L30=1,Thermostat!$B$3,Thermostat!$B$4) -> 60 | M36: =IF(M30=1,Thermostat!$B$3,Thermostat!$B$4) -> 70 | ... AC36: =IF(AC30=1,Thermostat!$B$3,Thermostat!$B$4) -> 60
E37: Sunday | F37: =IF(F31=1,Thermostat!$B$3,Thermostat!$B$4) -> 60 | G37: =IF(G31=1,Thermostat!$B$3,Thermostat!$B$4) -> 60 | H37: =IF(H31=1,Thermostat!$B$3,Thermostat!$B$4) -> 60 | I37: =IF(I31=1,Thermostat!$B$3,Thermostat!$B$4) -> 60 | J37: =IF(J31=1,Thermostat!$B$3,Thermostat!$B$4) -> 60 | K37: =IF(K31=1,Thermostat!$B$3,Thermostat!$B$4) -> 60 | L37: =IF(L31=1,Thermostat!$B$3,Thermostat!$B$4) -> 60 | M37: =IF(M31=1,Thermostat!$B$3,Thermostat!$B$4) -> 60 | ... AC37: =IF(AC31=1,Thermostat!$B$3,Thermostat!$B$4) -> 60
A38: Ticket Attendant Zone | B38: TicketAttendant | C38: ClgSetpt | D38: T24 2022 - Appendix 5.4B, [Parking] | E38: Weekday | F38: =IF(F29=1,Thermostat!$B$5,Thermostat!$B$6) -> 85 | G38: =IF(G29=1,Thermostat!$B$5,Thermostat!$B$6) -> 85 | H38: =IF(H29=1,Thermostat!$B$5,Thermostat!$B$6) -> 85 | I38: =IF(I29=1,Thermostat!$B$5,Thermostat!$B$6) -> 85 | J38: =IF(J29=1,Thermostat!$B$5,Thermostat!$B$6) -> 85 | K38: =IF(K29=1,Thermostat!$B$5,Thermostat!$B$6) -> 85 | L38: =IF(L29=1,Thermostat!$B$5,Thermostat!$B$6) -> 75 | M38: =IF(M29=1,Thermostat!$B$5,Thermostat!$B$6) -> 75 | ... AC38: =IF(AC29=1,Thermostat!$B$5,Thermostat!$B$6) -> 85
E39: Saturday | F39: =IF(F30=1,Thermostat!$B$5,Thermostat!$B$6) -> 85 | G39: =IF(G30=1,Thermostat!$B$5,Thermostat!$B$6) -> 85 | H39: =IF(H30=1,Thermostat!$B$5,Thermostat!$B$6) -> 85 | I39: =IF(I30=1,Thermostat!$B$5,Thermostat!$B$6) -> 85 | J39: =IF(J30=1,Thermostat!$B$5,Thermostat!$B$6) -> 85 | K39: =IF(K30=1,Thermostat!$B$5,Thermostat!$B$6) -> 85 | L39: =IF(L30=1,Thermostat!$B$5,Thermostat!$B$6) -> 85 | M39: =IF(M30=1,Thermostat!$B$5,Thermostat!$B$6) -> 75 | ... AC39: =IF(AC30=1,Thermostat!$B$5,Thermostat!$B$6) -> 85
E40: Sunday | F40: =IF(F31=1,Thermostat!$B$5,Thermostat!$B$6) -> 85 | G40: =IF(G31=1,Thermostat!$B$5,Thermostat!$B$6) -> 85 | H40: =IF(H31=1,Thermostat!$B$5,Thermostat!$B$6) -> 85 | I40: =IF(I31=1,Thermostat!$B$5,Thermostat!$B$6) -> 85 | J40: =IF(J31=1,Thermostat!$B$5,Thermostat!$B$6) -> 85 | K40: =IF(K31=1,Thermostat!$B$5,Thermostat!$B$6) -> 85 | L40: =IF(L31=1,Thermostat!$B$5,Thermostat!$B$6) -> 85 | M40: =IF(M31=1,Thermostat!$B$5,Thermostat!$B$6) -> 85 | ... AC40: =IF(AC31=1,Thermostat!$B$5,Thermostat!$B$6) -> 85
...

Sheet Energy Usage
A1: CalBEM Energy Consumption - ParkingOpen | N1: ="Energy Consumption - "&Prototype!A2 -> Energy Consumption - ParkingOpen
A2: Prototype | B2: CZ | C2: CalBEM Electricity EUI (KBTU/ft²) | D2: CalBEM Gas EUI (KBTU/ft²) | E2: CalBEM Total EUI (KBTU/ft²) | F2: New Construction Electricity EUI (KBTU/ft²) | G2: New Construction Gas EUI (KBTU/ft²) | H2: New Construction Total EUI (KBTU/ft²) | I2: National Average | J2: Acceptable Range (25% Higher) | K2: Acceptable Range (25% Lower) | L2: National Average Acceptable EUI Range | N2: Prototype | O2: CZ | P2: Total Floorspace (Thousand of ft²) | Q2: CEUS 2023 Electricity EUI (kBtu/ft²) | R2: CEUS 2023 Gas EUI (kBtu/ft²) | S2: CEUS 2023 Total EUI (kBtu/ft²) | T2: Acceptable Range (20% Higher) | U2: Acceptable Range (20% Lower) | V2: CEUS 2022 Acceptable EUI Range
A3: ParkingOpen | B3: 1 | C3: 3.9 | D3: 0 | E3: 3.9 | F3: 3.1 | G3: 0 | H3: 3.1 | I3: 4.2 | J3: =(I3*1.25) -> 5.25 | K3: =(I3*0.75) -> 3.15 | L3: =J3-K3 -> 2.1 | N3: ParkingOpen | O3: 1
B4: 2 | C4: 3.7 | D4: 0 | E4: 3.7 | F4: 2.9 | G4: 0 | H4: 2.9 | I4: 4.2 | J4: =(I4*1.25) -> 5.25 | K4: =(I4*0.75) -> 3.15 | L4: =J4-K4 -> 2.1 | O4: 2
B5: 3 | C5: 3.7 | D5: 0 | E5: 3.7 | F5: 2.9 | G5: 0 | H5: 2.9 | I5: 4.2 | J5: =(I5*1.25) -> 5.25 | K5: =(I5*0.75) -> 3.15 | L5: =J5-K5 -> 2.1 | O5: 3
B6: 4 | C6: 3.6 | D6: 0 | E6: 3.6 | F6: 2.8 | G6: 0 | H6: 2.8 | I6: 4.2 | J6: =(I6*1.25) -> 5.25 | K6: =(I6*0.75) -> 3.15 | L6: =J6-K6 -> 2.1 | O6: 4
B7: 5 | C7: 3.6 | D7: 0 | E7: 3.6 | F7: 2.8 | G7: 0 | H7: 2.8 | I7: 4.2 | J7: =(I7*1.25) -> 5.25 | K7: =(I7*0.75) -> 3.15 | L7: =J7-K7 -> 2.1 | O7: 5
B8: 6 | C8: 3.5 | D8: 0 | E8: 3.5 | F8: 2.7 | G8: 0 | H8: 2.7 | I8: 4.2 | J8: =(I8*1.25) -> 5.25 | K8: =(I8*0.75) -> 3.15 | L8: =J8-K8 -> 2.1 | O8: 6
B9: 7 | C9: 3.5 | D9: 0 | E9: 3.5 | F9: 2.7 | G9: 0 | H9: 2.7 | I9: 4.2 | J9: =(I9*1.25) -> 5.25 | K9: =(I9*0.75) -> 3.15 | L9: =J9-K9 -> 2.1 | O9: 7
B10: 8 | C10: 3.4 | D10: 0 | E10: 3.4 | F10: 2.6 | G10: 0 | H10: 2.6 | I10: 4.2 | J10: =(I10*1.25) -> 5.25 | K10: =(I10*0.75) -> 3.15 | L10: =J10-K10 -> 2.1 | O10: 8
B11: 9 | C11: 3.5 | D11: 0 | E11: 3.5 | F11: 2.7 | G11: 0 | H11: 2.7 | I11: 4.2 | J11: =(I11*1.25) -> 5.25 | K11: =(I11*0.75) -> 3.15 | L11: =J11-K11 -> 2.1 | O11: 9
B12: 10 | C12: 3.5 | D12: 0 | E12: 3.5 | F12: 2.7 | G12: 0 | H12: 2.7 | I12: 4.2 | J12: =(I12*1.25) -> 5.25 | K12: =(I12*0.75) -> 3.15 | L12: =J12-K12 -> 2.1 | O12: 10
B13: 11 | C13: 3.6 | D13: 0 | E13: 3.6 | F13: 2.8 | G13: 0 | H13: 2.8 | I13: 4.2 | J13: =(I13*1.25) -> 5.25 | K13: =(I13*0.75) -> 3.15 | L13: =J13-K13 -> 2.1 | O13: 11
B14: 12 | C14: 3.6 | D14: 0 | E14: 3.6 | F14: 2.8 | G14: 0 | H14: 2.8 | I14: 4.2 | J14: =(I14*1.25) -> 5.25 | K14: =(I14*0.75) -> 3.15 | L14: =J14-K14 -> 2.1 | O14: 12
B15: 13 | C15: 3.6 | D15: 0 | E15: 3.6 | F15: 2.8 | G15: 0 | H15: 2.8 | I15: 4.2 | J15: =(I15*1.25) -> 5.25 | K15: =(I15*0.75) -> 3.15 | L15: =J15-K15 -> 2.1 | O15: 13
... B18: 16 | C18: 3.8 | D18: 0 | E18: 3.8 | F18: 3 | G18: 0 | H18: 3 | I18: 4.2 | J18: =(I18*1.25) -> 5.25 | K18: =(I18*0.75) -> 3.15 | L18: =J18-K18 -> 2.1 | O18: 16
A20: chrome-extension://efaidnbmnnnibpcajpcglclefindmkaj/https://www.energystar.gov/sites/default/files/tools/Parking%20Adjustment%20Technical%20Reference_508.pdf | N20: Ref: CEUS 2022 Report
N21: And converted FZ level data to CZ level
N25: Background Data [To be deleted prior to publication]

Sheet Weights
A1: ="% of Floor Area per CZ and Vintage Bin - "&Prototype!A2 -> % of Floor Area per CZ and Vintage Bin - ParkingOpen | J1: ="% of Floor Area per CZ and Vintage Bin - "&Prototype!A2 -> % of Floor Area per CZ and Vintage Bin - ParkingOpen
A2: Prototype | B2: CZ | C2: Vintage Bin | J2: Prototype | K2: Vintage Bin | L2: CZ
C3: Pre-1978 | D3: 1978-1997 | E3: 1998-2007 | F3: 2008-2018 | G3: Not available | L3: 1 | M3: 2 | N3: 3 | O3: 4 | P3: 5 | Q3: 6 | R3: 7 | S3: 8 | T3: 9 | U3: 10 | V3: 11 | W3: 12 | X3: 13 | Y3: 14 | Z3: 15 | AA3: 16
A4: =Prototype!B4 -> Open Parking | B4: 1 | H4: =SUM(C4:G4) -> 0 | J4: =Prototype!B4 -> Open Parking | K4: Pre-1978 | AB4: =SUM(L4:AA4) -> 0
B5: 2 | H5: =SUM(C5:G5) -> 0 | K5: 1978-1997 | AB5: =SUM(L5:AA5) -> 0
B6: 3 | H6: =SUM(C6:G6) -> 0 | K6: 1998-2007 | AB6: =SUM(L6:AA6) -> 0
B7: 4 | H7: =SUM(C7:G7) -> 0 | K7: 2008-2018 | AB7: =SUM(L7:AA7) -> 0
B8: 5 | H8: =SUM(C8:G8) -> 0 | K8: Not available | AB8: =SUM(L8:AA8) -> 0
B9: 6 | H9: =SUM(C9:G9) -> 0 | K9: Total
B10: 7 | H10: =SUM(C10:G10) -> 0
B11: 8 | H11: =SUM(C11:G11) -> 0
B12: 9 | H12: =SUM(C12:G12) -> 0
B13: 10 | H13: =SUM(C13:G13) -> 0
B14: 11 | H14: =SUM(C14:G14) -> 0
B15: 12 | H15: =SUM(C15:G15) -> 0
B16: 13 | H16: =SUM(C16:G16) -> 0
B17: 14 | H17: =SUM(C17:G17) -> 0
B18: 15 | H18: =SUM(C18:G18) -> 0
B19: 16 | H19: =SUM(C19:G19) -> 0
B20: Statewide
A22: Ref: CEUS 2022 dataset
A29: Background Data [To be deleted prior to publication]

Sheet PV
A1: ="PV - "&Prototype!A2 -> PV - ParkingOpen
A2: TBD

Sheet EV Charger
A1: ="EV Charger - "&Prototype!A2 -> EV Charger - ParkingOpen
A2: TBD
A11: Background Data [To be deleted prior to publication]

Sheet Data
A1: Space Function | B1: Electric Equipment Load Intensity | C1: Electric Equipment Load Intensity | D1: LPD
A2: Aging Eye/Low-vision (Corridor Area) | D2: 2013 | E2: 2016 | F2: 2019 | G2: 2025
A3: Aging Eye/Low-vision (Dining)
A4: Aging Eye/Low-vision (Lobby, Main Entry)
A5: Aging Eye/Low-vision (Lounge/Waiting Area)
A6: Aging Eye/Low-vision (Multipurpose Room)
A7: Aging Eye/Low-vision (Religious Worship Area)
A8: Aging Eye/Low-vision (Restroom)
A9: Aging Eye/Low-vision (Stairwell)
A10: Audience Seating Area
A11: Auditorium Area
A12: Auto Repair / Maintenance Area
A13: Barber, Beauty Salon, Spa Area
A14: Civic Meeting Place Area
... A83: Server Room (EPD 45)
