Workbook
Name nonparticipating_forecastzone_scale_factor: #REF!
Name nonparticipating_forecastzone_scale_factor: #REF!
Name nonparticipating_forecastzone_scale_factor: 'Energy Usage'!#REF!
Name Space_Function: Data!$A$2:$A$76

Sheet Notes
A1: Data Sources
A2: Dataset | B2: Dodge 2023
B3: Commercial End-Use Survey (CEUS) 2022 | C3: https://www.energy.ca.gov/publications/2023/2022-california-commercial-end-use-survey-ceus-final-report
B4: Commercial Buildings Energy Consumption Survey (CBECS) 2018 | C4: https://www.eia.gov/consumption/commercial/data/2018/index.php?view=microdata
B5: Comstock 2023 | C5: https://data.openei.org/s3_viewer?bucket=oedi-data-lake&prefix=nrel-pds-building-stock%2Fend-use-load-profiles-for-us-building-stock%2F2023%2Fcomstock_amy2018_release_2%2Fmetadata_and_annual_results%2Fby_state%2Fstate%3DCA%2F
A6: Prototype | B6: California Energy Commission (CEC) Medium Retail prototype (CBECC 2022.3.1) | C6: https://bees.noresco.com/software2022.html
B7: Pacific Northwest National Laboratory (PNNL) Standalone Retail prototypes (90.1-2022) | C7: https://www.energycodes.gov/prototype-building-models#Commercial
B8: Database for Energy Efficient Resources (DEER) Retail prototypes (June 2023) | C8: https://github.com/sound-data/DEER-Prototypes-EnergyPlus
A10: Codes | B10: Title 24, part 6, referred to as T24 (1984, 1992,1998, 2001, 2005, 2008, 2013, 2016,2019, 2022, 2025) | C10: https://www.energy.ca.gov/publications/2025/2025-building-energy-efficiency-standards-residential-and-nonresidential | D10: 2025
C11: https://codes.iccsafe.org/codes/united-states/california | D11: 2010+
B12: American Society of Heating, Refrigerating and Air-Conditioning Engineers (ASHRAE) 90.1 (2022) | C12: https://www.ashrae.org/technical-resources/standards-and-guidelines/read-only-versions-of-ashrae-standards
B13: Code of Federal Regulations (CFR) Title 10 ( 2010) | C13: https://www.govinfo.gov/content/pkg/FR-2009-03-23/pdf/FR-2009-03-23.pdf
B14: CFR Title 10 ( 2024) | C14: https://www.govinfo.gov/content/pkg/CFR-2024-title10-vol3/pdf/CFR-2024-title10-vol3-part431-subpartF.pdf
A16: Others | B16: Alternative Calculation Method (ACM) (2022) | C16: https://www.energy.ca.gov/publications/2022/2022-nonresidential-and-multifamily-alternative-calculation-method-reference
B17: ACM (2025) | C17: https://www.energy.ca.gov/publications/2025/2025-nonresidential-and-multifamily-alternative-calculation-method-reference
B18: Nonres ACM 2022, Appendix 5.4A and Appendix 5.4B | C18: https://www.energy.ca.gov/publications/2022/2022-nonresidential-and-multifamily-alternative-calculation-method-reference
B19: 2022 Reduced infiltration Codes and Standards Enhancement (CASE) report | C19: https://title24stakeholders.com/wp-content/uploads/2020/10/2022-T24-Final-CASE-Report_Reduce-Infiltration.pdf
B20: 2019 Outdoor Lighting CASE Report | C20: https://title24stakeholders.com/wp-content/uploads/2016/10/T24-2019-CASE-Study-Results-Report-Outdoor-Sources_Final_with-Attachments.pdf
B21: PNNL 20405, 2011 | C21: https://www.pnnl.gov/main/publications/external/technical_reports/PNNL-20405.pdf
B22: Air leakage Memo, NORESCO, 2025 | C22: Infiltration_rate_report_14May2025-Short-Version.docx
B23: Yousefi, F., Athalye, R., (2025), "Determining Vintage Bins for Prototype Development: An Analysis of California Commercial Buildings," ASHRAE Annual Conference | C23: https://www.thefreelibrary.com/Determining+Vintage+Bins+for+Prototype+Development%3a+An+Analysis+of...-a0879271125
B24: Retail Building Guide for Entrance Energy Efficiency Measures (2012) | C24: https://www.osti.gov/servlets/purl/1037934
B25: Proposed Updates to Equipment Power Densities and Building Schedules for the 2028 Energy Code, referred to as "Plug load and schedules project with CEC, 2025" (Docket Number =25-BSTD-03 & TN=265693) | C25: https://efiling.energy.ca.gov/GetDocument.aspx?tn=265693&DocumentContentId=102545
B26: ENERGY STAR certified commercial water heaters | C26: https://www.energystar.gov/productfinder/product/certified-commercial-water-heaters/results?fuel_filter=Gas&markets_filter=United+States
B27: Grainger gas tank water heaters (sizes below commercial, e.g. 30–75 kBtu/h) | C27: https://www.grainger.com/category/plumbing/water-heaters/gas-tank-water-heaters
B28: Grainger electric tank water heaters | C28: https://www.grainger.com/category/plumbing/water-heaters/electric-tank-water-heaters
A33: Construction Rate
B46: Source:Dodge Construction Data, 2023 ( NEW Stores built after 1967) (STC refers to building types in Dodge terminology).
A47: Notes
A48: This prototype represents an open-format general merchandise "big box" typology for retail up to approximately 50,000 ft². It is intended to capture the overall building and energy-use characteristics of non-grocery general merchandise retailers, such as CVS, REI, Tj Max, Home Goods, Ross, Staples, Petco, Marshall, Mattress Firm, Old Navy, and other similar retail shops. This prototype is distinct from grocery stores, warehouse clubs, strip malls, and malls, as their refrigeration, plug/process load, lightings, occupancy, schedules, and other energy-use characteristics can differ substantially from general merchandise retail.

Sheet Prototype
A1: NORESCO, Updated September 2026
A2: RetailMedium
A3: Characteristic | B3: Value | C3: Data Sources
A4: Building Type | B4: General Merchandise Retail
A5: Building Category | B5: Nonresidential
A6: Version | B6: v2-0
A7: Vintages | B7: 4 Vintages: Pre-1978 , 1978-1997 ,1998-2007 , 2008-2018 New Construction (2019+) | C7: Based on the vintage bin analysis. A summary of the findings is presented in the following paper, with a link provided in the Notes tab: Yousefi, F., Athalye, R. (2025). “Determining Vintage Bins for Prototype Development: An Analysis of California Commercial Buildings.” ASHRAE Annual Conference.
A8: Shape | C8: Typical medium-sized box retail shop
A9: Total Floor Area (ft²) | B9: 24,692 (178 ft x 139 ft) | C9: Assumption: same as the CBECC RetailMedium prototypes. According to Dodge 2023 construction data, the average floor area of stores between 10,000 ft² and 50,000 ft² in California is approximately 20,414 ft²
A10: Aspect Ratio | B10: 1.28 | C10: Assumption; same as PNNL Retail_Standalone and CBECC RetailMedium prototypes
A11: Number of Floors | B11: 1 | C11: Typical medium-sized box retail shop
A12: Roof type | B12: Flat | C12: Typical medium-sized box retail shop
A13: WWR_Whole Building | B13: 0.071 | C13: Close to the General Merchandise 50% Energy Savings Technical Support Document (PNNL, 2009) which reports a 6.2% whole‑building WWR and 22% front‑façade WWR based on analysis of the 2003 CBECS retail dataset
A14: WWR_South Facade | B14: 0.254
A15: Shading Geometry | B15: None | C15: Assumption; same as PNNL Retail_Standalone and CBECC RetailMedium prototypes
A16: Floor to floor height (feet) | B16: N/A
A17: Floor to ceiling height (feet) | B17: 20 | C17: Assumption; same as PNNL Retail_Standalone and CBECC RetailMedium prototypes
A18: Glazing sill height (feet) | B18: 5 ft (top of the window is 8.73 ft high with 3.74 ft high glass) | C18: Assumption; same as PNNL Retail_Standalone and CBECC RetailMedium prototypes
A19: Skylight-to-Roof-Ratio (SRR) | B19: 0.0207 | C19: Assumption; same as PNNL Retail_Standalone and CBECC RetailMedium prototypes
A26: Background Data
A28: Existing Retail Prototypes
A30: Large size prototype | B30: CEC: Retail_Large | C30: CPUC: Retail_Multistory Large (Rt3) | D30: CPUC: Retail_Single-Story Large (RtL)
A31: Geometry
A32: Total floor area (ft²) | B32: 240000 | C32: =3*40000 -> 120000 | D32: 130502
A35: Medium size prototype | B35: CEC: Retail_Medium | C35: PNNL : Retail_Standalone | D35: PNNL: Retail_Stripmall | F35: CPUC: Retail_Grocery
A36: Geometry | B36: zoning same as PNNL Stand alone with more skylight
A37: Total floor area (ft²) | B37: 24692 | C37: 24692 | D37: 22500 | F37: 49997
A40: Small size prototype | B40: CEC: Retail_Stripmall (Mixed use) | C40: CPUC: Retail_Small (RtS)
A41: Geometry
A42: Total floor area (ft²) | B42: 9375 | C42: 8001

Sheet Zones
A1: ="Proposed Layout - "&Prototype!A2 -> Proposed Layout - RetailMedium | Q1: Spaces and Zoning layout
A2: Building | B2: Space/Thermal Zone | C2: Space Type [Primarily from: T24, 2022 Appendix 5.4A] - See Notes column | D2: HVAC System Name (NC) | E2: HVAC System Name (Existing) | F2: Schedule Category | G2: Conditioned (Y/N) | H2: Area Fraction* | I2: Area (ft²) | J2: Volume (ft³) | K2: Multipliers | L2: Number of People | M2: People (Persons/1,000 ft²) [T24, 2025,Table 120.1-A] | N2: Notes
A3: RetailMedium | B3: Core_Retail | C3: Retail Sales Area (Retail Merchandise Sales) | D3: PSZAC_Core1, PSZAC_Core2, PSZAC_Core3, PSZAC_Core4 | E3: SZVAVHP_Core1, SZVAVHP_Core2, SZVAVHP_Core3, SZVAVHP_Core4 | F3: Retail | G3: Y | H3: 0.698 | I3: =H3*$I$11 -> 17235.016 | J3: =I3*20 -> 344700.32 | K3: 1 | L3: =M3*I3/1000 -> 292.99527 | M3: 17
A4: RetailMedium | B4: Point_of_Sale | C4: Retail Sales Area (Retail Merchandise Sales) | D4: PSZAC_Point_Of_Sale | E4: PSZVAVHP_Point_Of_Sale | F4: Retail | G4: Y | H4: 0.066 | I4: =H4*$I$11 -> 1629.672 | J4: =I4*20 -> 32593.44 | K4: 1 | L4: =M4*I4/1000 -> 27.704424 | M4: 17
A5: RetailMedium | B5: Front_Retail | C5: Retail Sales Area (Retail Merchandise Sales) | D5: PSZAC_Front_Retail | E5: SZVAVHP_Front_Retail | F5: Retail | G5: Y | H5: 0.066 | I5: =H5*$I$11 -> 1629.672 | J5: =I5*20 -> 32593.44 | K5: 1 | L5: =M5*I5/1000 -> 27.704424 | M5: 17
A6: RetailMedium | B6: Front_Entry | C6: Corridor Area | F6: Retail | G6: N | H6: =0.005 -> 0.005 | I6: =H6*$I$11 -> 123.46 | J6: =I6*20 -> 2469.2 | K6: 1 | L6: =M6*I6/1000 -> 0.6173 | M6: 5
A7: RetailMedium | B7: Loading_Dock | C7: Storage, Commercial/Industrial (Shipping & Handling) | D7: PSZAC_Storage | E7: SZVAVHP_Storage | F7: Ancillary | G7: Y | H7: 0.024 | I7: =H7*$I$11 -> 592.608 | J7: =I7*20 -> 11852.16 | K7: 1 | L7: =M7*I7/1000 -> 1.185216 | M7: 2
A8: RetailMedium | B8: Bulk_Storage | C8: Storage (General) | D8: PSZAC_Storage | E8: SZVAVHP_Storage | F8: Ancillary | G8: Y | H8: 0.097 | I8: =H8*$I$11 -> 2395.124 | J8: =I8*20 -> 47902.48 | K8: 1 | L8: =M8*I8/1000 -> 0 | M8: 0
A9: RetailMedium | B9: Office/Stuff | C9: Office Area (>250 square feet) | D9: PSZAC_Office | E9: SZVAVHP_Office | F9: Retail | G9: Y | H9: 0.027 | I9: =H9*$I$11 -> 666.684 | J9: =I9*20 -> 13333.68 | K9: 1 | L9: =M9*I9/1000 -> 3.33342 | M9: 5
A10: RetailMedium | B10: Restroom | C10: Restrooms | F10: Retail | G10: Y | H10: 0.017 | I10: =H10*$I$11 -> 419.764 | J10: =I10*20 -> 8395.28 | K10: 1 | L10: =M10*I10/1000 -> 0 | M10: 0 | N10: Restroom: Indirectly conditioned: Transfer air + Exhaust room ( No dedicated HVAC)
A11: Total (1 Building) | B11: Total (8 Spaces) | C11: Total (6 Space types) | D11: Total (8 HVAC Systems) | E11: Total (8 HVAC Systems) | G11: Total (8 Conditioned zones) | H11: =SUM(H3:H10) -> 1 | I11: 24692 | J11: =SUM(J3:J10) -> 493840 | L11: =SUM(L3:L10) -> 353.54006 | U11: `
B13: *Note. The area fractions in this prototype align closely with the space distribution shown in the Advanced Energy Design Guide for Medium to Big Box Retail Buildings (ASHRAE),
B14: which indicates approximately 85% sales area and 15% non-sales area. The CalBEM RetailMedium prototype reflects a similar distribution, with 83% allocated to sales area and 17% to non-sales functions. | P14: Area Distribution By Space Type
P15: Space Type | S15: % Area
P16: =C3 -> Retail Sales Area (Retail Merchandise Sales) | S16: =SUM(H3:H5) -> 0.83
G17: {=_xlfn.UNIQUE(C3:C10)} -> Retail Sales Area (Retail Merchandise Sales) | P17: =C6 -> Corridor Area | S17: =H6 -> 0.005
G18: Corridor Area | P18: =C7 -> Storage, Commercial/Industrial (Shipping & Handling) | S18: =H7 -> 0.024
G19: Storage, Commercial/Industrial (Shipping & Handling) | P19: =C8 -> Storage (General) | S19: =H8 -> 0.097
G20: Storage (General) | P20: =C9 -> Office Area (>250 square feet) | S20: =H9 -> 0.027
G21: Office Area (>250 square feet) | P21: =C10 -> Restrooms | S21: =H10 -> 0.017
G22: Restrooms | P22: Total | S22: =SUM(S16:S21) -> 1
C26: Floorspace-Types-30Oct2024
C27: Retail (CEUS 2022, statewide %)
C28: Conditioned | E28: Ventilated
C29: 0.8262 | E29: 0.8344
C31: Advanced Energy Design Guide for Medium to Big Box Retail Buildings
C32: Space Type | D32: Medium Box Area (ft²) | E32: Percentage of Total Area
C33: Main sales | D33: 31500 | E33: 0.7778
C34: Perimeter sales | D34: 3076 | E34: 0.076
C35: Enclosed office | D35: 300 | E35: 0.0074
C36: Meeting room | D36: 500 | E36: 0.0123
C37: Break room | D37: 500 | E37: 0.0123
C38: Restroom | D38: 625 | E38: 0.0154
C39: Mechanical room | D39: 200 | E39: 0.0049
C40: Corridor | D40: 450 | E40: 0.0111
C41: Vestibule | D41: 300 | E41: 0.0074
C42: Active storage | D42: 3050 | E42: 0.0753
C43: Total | D43: 40500 | E43: 1
C45: Sales | E45: =SUM(E33:E34) -> 0.8538
C46: Non-Sell | E46: =SUM(E35:E42) -> 0.1461

Sheet Envelope
A1: ="Envelope - "&Prototype!A2 -> Envelope - RetailMedium
A2: Element | B2: Prototype | C2: Assembly Type | D2: Construction | E2: Thermal Properties | F2: Vintage | G2: Selected T24 | H2: Note | I2: CZ1 | J2: CZ2 | K2: CZ3 | L2: CZ4 | M2: CZ5 | N2: CZ6 | O2: CZ7 | P2: CZ8 | Q2: CZ9 | R2: CZ10 | S2: CZ11 | T2: CZ12 | U2: CZ13 | V2: CZ14 | W2: CZ15 | X2: CZ16
A3: External Wall | B3: RetailMedium | C3: ExtWall_MetalFramed_NonRes | D3: Metal framed wall: Metal frame + insulation + Gypsum board | E3: U-factor IP | F3: Pre 1978 | G3: N/A | H3: ASHRAE 90.1, 2022, Table A3.3.3.1, 3.5", R-0 | I3: 0.352 | J3: 0.352 | K3: 0.352 | L3: 0.352 | M3: 0.352 | N3: 0.352 | O3: 0.352 | P3: 0.352 | Q3: 0.352 | R3: 0.352 | S3: 0.352 | T3: 0.352 | U3: 0.352 | V3: 0.352 | W3: 0.352 | X3: 0.352
F4: 1978-1997 | G4: 1986 | H4: Package A with Heat Capacity 10.0-14.99 (Btu/F-ft²) - Still are lower than the next vintage! | I4: 0.15082956 | J4: 0.15748031 | K4: 0.15748031 | L4: 0.14367816 | M4: 0.14367816 | N4: 0.21645022 | O4: 0.21645022 | P4: 0.21645022 | Q4: 0.21645022 | R4: 0.21645022 | S4: 0.18621974 | T4: 0.18621974 | U4: 0.18621974 | V4: 0.15873016 | W4: 0.15873016 | X4: 0.15082956
F5: 1998-2007 | G5: 2001 | H5: Table 1-H | I5: 0.182 | J5: 0.182 | K5: 0.189 | L5: 0.189 | M5: 0.189 | N5: 0.189 | O5: 0.189 | P5: 0.189 | Q5: 0.189 | R5: 0.182 | S5: 0.182 | T5: 0.182 | U5: 0.182 | V5: 0.182 | W5: 0.182 | X5: 0.182
F6: 2008-2018 | G6: 2013 | H6: Table 140.3-B | I6: 0.098 | J6: 0.062 | K6: 0.082 | L6: 0.062 | M6: 0.062 | N6: 0.098 | O6: 0.098 | P6: 0.062 | Q6: 0.062 | R6: 0.062 | S6: 0.062 | T6: 0.062 | U6: 0.062 | V6: 0.062 | W6: 0.062 | X6: 0.062
F7: 2019+ | G7: 2025 | H7: Table 140.3-B | I7: 0.06 | J7: 0.055 | K7: 0.071 | L7: 0.055 | M7: 0.055 | N7: 0.06 | O7: 0.06 | P7: 0.055 | Q7: 0.055 | R7: 0.055 | S7: 0.055 | T7: 0.055 | U7: 0.055 | V7: 0.055 | W7: 0.055 | X7: 0.055
A8: Roof | B8: RetailMedium | C8: FlatRoof_WoodFramedAndOther_NonRes | D8: Metal deck roof: Roof membrane + insulation + metal decking | E8: U-factor IP | F8: Pre 1978 | G8: N/A | H8: Considering 30 years for roof/ insulation replacement. | I8: 0.057 | J8: 0.057 | K8: 0.057 | L8: 0.057 | M8: 0.057 | N8: 0.078 | O8: 0.078 | P8: 0.078 | Q8: 0.078 | R8: 0.078 | S8: 0.057 | T8: 0.057 | U8: 0.057 | V8: 0.057 | W8: 0.057 | X8: 0.057
F9: 1978-1997 | G9: 1992 | I9: 0.057 | J9: 0.057 | K9: 0.057 | L9: 0.057 | M9: 0.057 | N9: 0.078 | O9: 0.078 | P9: 0.078 | Q9: 0.078 | R9: 0.078 | S9: 0.057 | T9: 0.057 | U9: 0.057 | V9: 0.057 | W9: 0.057 | X9: 0.057
F10: 1998-2007 | G10: 2001 | H10: Table 1-H | I10: 0.057 | J10: 0.057 | K10: 0.057 | L10: 0.057 | M10: 0.057 | N10: 0.078 | O10: 0.078 | P10: 0.078 | Q10: 0.078 | R10: 0.057 | S10: 0.057 | T10: 0.057 | U10: 0.057 | V10: 0.057 | W10: 0.057 | X10: 0.057
F11: 2008-2018 | G11: 2013 | H11: Table 140.3-B | I11: 0.049 | J11: 0.039 | K11: 0.039 | L11: 0.039 | M11: 0.049 | N11: 0.075 | O11: 0.067 | P11: 0.067 | Q11: 0.039 | R11: 0.039 | S11: 0.039 | T11: 0.039 | U11: 0.039 | V11: 0.039 | W11: 0.039 | X11: 0.039
F12: 2019+ | G12: 2025 | H12: Table 140.3-B | I12: 0.028 | J12: 0.028 | K12: 0.028 | L12: 0.028 | M12: 0.028 | N12: 0.047 | O12: 0.047 | P12: 0.047 | Q12: 0.028 | R12: 0.028 | S12: 0.028 | T12: 0.028 | U12: 0.028 | V12: 0.028 | W12: 0.028 | X12: 0.028
A13: Window | B13: RetailMedium | C13: FixedWindow_NonRes | D13: CBECS 2018 shows that ~ 50 % of retail that were built before 2000 are single pane | E13: U-factor IP | F13: Pre 1978 | G13: N/A | H13: 2021 ASHRAE Handbook of Fundamentals - Section 15.9 Table 4 for single pane & T24, 2013 Table 140.3-B for double pane (50%-50%) | I13: =0.5*1.12+0.5*I16 -> 0.74 | J13: =0.5*1.12+0.5*J16 -> 0.74 | K13: =0.5*1.12+0.5*K16 -> 0.74 | L13: =0.5*1.12+0.5*L16 -> 0.74 | M13: =0.5*1.12+0.5*M16 -> 0.74 | N13: =0.5*1.12+0.5*N16 -> 0.74 | O13: =0.5*1.12+0.5*O16 -> 0.74 | P13: =0.5*1.12+0.5*P16 -> 0.74 | ... X13: =0.5*1.12+0.5*X16 -> 0.74
F14: 1978-1997 | G14: N/A | I14: =I13 -> 0.74 | J14: =J13 -> 0.74 | K14: =K13 -> 0.74 | L14: =L13 -> 0.74 | M14: =M13 -> 0.74 | N14: =N13 -> 0.74 | O14: =O13 -> 0.74 | P14: =P13 -> 0.74 | ... X14: =X13 -> 0.74
D15: Double pane | F15: 1998-2007 | G15: 2001 | H15: Table 1-H | I15: 0.49 | J15: 0.49 | K15: 0.81 | L15: 0.81 | M15: 0.81 | N15: 0.81 | O15: 0.81 | P15: 0.81 | Q15: 0.81 | R15: 0.49 | S15: 0.49 | T15: 0.49 | U15: 0.49 | V15: 0.49 | W15: 0.49 | X15: 0.49
F16: 2008-2018 | G16: 2013 | H16: Table 140.3-B | I16: 0.36 | J16: 0.36 | K16: 0.36 | L16: 0.36 | M16: 0.36 | N16: 0.36 | O16: 0.36 | P16: 0.36 | Q16: 0.36 | R16: 0.36 | S16: 0.36 | T16: 0.36 | U16: 0.36 | V16: 0.36 | W16: 0.36 | X16: 0.36
F17: 2019+ | G17: 2025 | H17: Table 140.3-B | I17: 0.36 | J17: 0.36 | K17: 0.36 | L17: 0.36 | M17: 0.36 | N17: 0.36 | O17: 0.36 | P17: 0.36 | Q17: 0.34 | R17: 0.36 | S17: 0.34 | T17: 0.34 | U17: 0.34 | V17: 0.34 | W17: 0.34 | X17: 0.36
B18: RetailMedium | C18: FixedWindow_NonRes | D18: CBECS 2018 shows that ~ 50 % of retail that were built before 2000 are single pane | E18: SHGC | F18: Pre 1978 | G18: N/A | H18: 2021 ASHRAE Handbook of Fundamentals - Section 15.22 Table 10 for single pane & T24, 2013 Table 140.3-B for double pane (50%-50%) | I18: =0.79*0.5+I21*0.5 -> 0.52 | J18: =0.79*0.5+J21*0.5 -> 0.52 | K18: =0.79*0.5+K21*0.5 -> 0.52 | L18: =0.79*0.5+L21*0.5 -> 0.52 | M18: =0.79*0.5+M21*0.5 -> 0.52 | N18: =0.79*0.5+N21*0.5 -> 0.52 | O18: =0.79*0.5+O21*0.5 -> 0.52 | P18: =0.79*0.5+P21*0.5 -> 0.52 | ... X18: =0.79*0.5+X21*0.5 -> 0.52
F19: 1978-1997 | G19: N/A | I19: =I18 -> 0.52 | J19: =J18 -> 0.52 | K19: =K18 -> 0.52 | L19: =L18 -> 0.52 | M19: =M18 -> 0.52 | N19: =N18 -> 0.52 | O19: =O18 -> 0.52 | P19: =P18 -> 0.52 | ... X19: =X18 -> 0.52
D20: Double pane | F20: 1998-2007 | G20: 2001 | H20: Table 1-H (Non north 0-10%) | I20: 0.49 | J20: 0.47 | K20: 0.61 | L20: 0.61 | M20: 0.61 | N20: 0.61 | O20: 0.61 | P20: 0.61 | Q20: 0.61 | R20: 0.47 | S20: 0.47 | T20: 0.47 | U20: 0.47 | V20: 0.46 | W20: 0.46 | X20: 0.49
F21: 2008-2018 | G21: 2013 | H21: Table 140.3-B | I21: 0.25 | J21: 0.25 | K21: 0.25 | L21: 0.25 | M21: 0.25 | N21: 0.25 | O21: 0.25 | P21: 0.25 | Q21: 0.25 | R21: 0.25 | S21: 0.25 | T21: 0.25 | U21: 0.25 | V21: 0.25 | W21: 0.25 | X21: 0.25
F22: 2019+ | G22: 2025 | H22: Table 140.3-B | I22: 0.25 | J22: 0.25 | K22: 0.25 | L22: 0.25 | M22: 0.25 | N22: 0.25 | O22: 0.25 | P22: 0.25 | Q22: 0.22 | R22: 0.25 | S22: 0.22 | T22: 0.22 | U22: 0.22 | V22: 0.22 | W22: 0.22 | X22: 0.25
A23: Skylight | B23: RetailMedium | C23: Skylight | D23: Translucent | E23: U-factor IP | F23: Pre 1978 | G23: N/A | H23: from 1992 code cycle | I23: 0.85 | J23: 1.31 | K23: 1.31 | L23: 1.31 | M23: 1.31 | N23: 1.31 | O23: 1.31 | P23: 1.31 | Q23: 1.31 | R23: 1.31 | S23: 0.85 | T23: 0.85 | U23: 0.85 | V23: 0.85 | W23: 0.85 | X23: 0.85
F24: 1978-1997 | G24: N/A | I24: 0.85 | J24: 1.31 | K24: 1.31 | L24: 1.31 | M24: 1.31 | N24: 1.31 | O24: 1.31 | P24: 1.31 | Q24: 1.31 | R24: 1.31 | S24: 0.85 | T24: 0.85 | U24: 0.85 | V24: 0.85 | W24: 0.85 | X24: 0.85
D25: Plastic curb mounted | F25: 1998-2007 | G25: 2001 | H25: Table 1-H | I25: 0.87 | J25: 1.1 | K25: 1.3 | L25: 1.3 | M25: 1.3 | N25: 1.3 | O25: 1.3 | P25: 1.3 | Q25: 1.3 | R25: 1.1 | S25: 1.1 | T25: 1.1 | U25: 1.1 | V25: 1.1 | W25: 1.1 | X25: 0.87
F26: 2008-2018 | G26: 2013 | H26: Table 140.3-B | I26: 0.88 | J26: 0.88 | K26: 0.88 | L26: 0.88 | M26: 0.88 | N26: 0.88 | O26: 0.88 | P26: 0.88 | Q26: 0.88 | R26: 0.88 | S26: 0.88 | T26: 0.88 | U26: 0.88 | V26: 0.88 | W26: 0.88 | X26: 0.88
F27: 2019+ | G27: 2025 | H27: Table 140.3-B | I27: 0.88 | J27: 0.88 | K27: 0.88 | L27: 0.88 | M27: 0.88 | N27: 0.88 | O27: 0.88 | P27: 0.88 | Q27: 0.88 | R27: 0.88 | S27: 0.88 | T27: 0.88 | U27: 0.88 | V27: 0.88 | W27: 0.88 | X27: 0.88
B28: RetailMedium | C28: Skylight | D28: Translucent | E28: SHGC | F28: Pre 1978 | G28: N/A | H28: From 1992 code cycle | I28: =0.81*0.87 -> 0.7047 | J28: =0.86*0.87 -> 0.7482 | K28: =0.86*0.87 -> 0.7482 | L28: =0.86*0.87 -> 0.7482 | M28: =0.86*0.87 -> 0.7482 | N28: =0.86*0.87 -> 0.7482 | O28: =0.86*0.87 -> 0.7482 | P28: =0.86*0.87 -> 0.7482 | Q28: =0.86*0.87 -> 0.7482 | R28: =0.86*0.87 -> 0.7482 | S28: =0.81*0.87 -> 0.7047 | T28: =0.81*0.87 -> 0.7047 | U28: =0.81*0.87 -> 0.7047 | V28: =0.81*0.87 -> 0.7047 | W28: =0.81*0.87 -> 0.7047 | X28: =0.81*0.87 -> 0.7047
F29: 1978-1997 | G29: N/A | I29: =0.81*0.87 -> 0.7047 | J29: =0.86*0.87 -> 0.7482 | K29: =0.86*0.87 -> 0.7482 | L29: =0.86*0.87 -> 0.7482 | M29: =0.86*0.87 -> 0.7482 | N29: =0.86*0.87 -> 0.7482 | O29: =0.86*0.87 -> 0.7482 | P29: =0.86*0.87 -> 0.7482 | Q29: =0.86*0.87 -> 0.7482 | R29: =0.86*0.87 -> 0.7482 | S29: =0.81*0.87 -> 0.7047 | T29: =0.81*0.87 -> 0.7047 | U29: =0.81*0.87 -> 0.7047 | V29: =0.81*0.87 -> 0.7047 | W29: =0.81*0.87 -> 0.7047 | X29: =0.81*0.87 -> 0.7047
D30: Plastic curb mounted | F30: 1998-2007 | G30: 2001 | H30: Table 1-H (For SRR 0-2%) | I30: 0.77 | J30: 0.77 | K30: 0.79 | L30: 0.79 | M30: 0.79 | N30: 0.77 | O30: 0.77 | P30: 0.77 | Q30: 0.77 | R30: 0.77 | S30: 0.77 | T30: 0.77 | U30: 0.77 | V30: 0.71 | W30: 0.71 | X30: 0.77
F31: 2008-2018 | G31: 2013 | H31: There is no requirement in the code (considered same as 2001) | I31: 0.77 | J31: 0.77 | K31: 0.79 | L31: 0.79 | M31: 0.79 | N31: 0.77 | O31: 0.77 | P31: 0.77 | Q31: 0.77 | R31: 0.77 | S31: 0.77 | T31: 0.77 | U31: 0.77 | V31: 0.71 | W31: 0.71 | X31: 0.77
F32: 2019+ | G32: 2025 | I32: 0.77 | J32: 0.77 | K32: 0.79 | L32: 0.79 | M32: 0.79 | N32: 0.77 | O32: 0.77 | P32: 0.77 | Q32: 0.77 | R32: 0.77 | S32: 0.77 | T32: 0.77 | U32: 0.77 | V32: 0.71 | W32: 0.71 | X32: 0.77
C35: Infiltration
D36: Building | E36: Zones | F36: Vintage | G36: I_75 (cfm/ft²) 6-sdied Infiltration rate @ 75 pa | H36: Note | I36: I-design (cfm/ft²) (4-sided Infiltration rate at normal pressure) (Design flow rate approach and Flow/Exterior Wall Area calculation method)
C37: Infiltration | D37: RetailMedium | F37: Pre 1978 | G37: 1.1 | H37: 2022 CASE report (Table 38) | I37: =(G37*0.112)*#REF! -> #REF! | Z37: Floor or roof area (ft2) | AA37: =Zones!I11 -> 24692
F38: 1978-1997 | G38: 1.1 | H38: 2022 CASE report (Table 38) | I38: =(G38*0.112)*#REF! -> #REF! | Z38: Walls area (ft2) | AA38: =(178+139 )*2*20 -> 12680
F39: 1998-2007 | G39: 1.1 | H39: 2022 CASE report (Table 38) | I39: =(G39*0.112)*#REF! -> #REF! | Z39: Building 4 sided area (ft2) | AA39: =AA38 -> 12680
F40: 2008-2018 | G40: 1 | H40: 2022 CASE report (Table 38) & T24, part 6, 2008-2016 (Table 140.3-B), Dodge 2023 data | I40: =(G40*0.112)*#REF! -> #REF! | Z40: Building 6 sided area (ft2) | AA40: =AA38+2*AA37 -> 62064
F41: 2019+ | G41: 0.6 (barrier in all CZ) | H41: 2022 CASE report (Table 38) & T24, part 6, 2025 (Table 140.3-B) | I41: =(0.6*0.112)*#REF! -> #REF!
E42: Infiltration_rate_report_14May2025-Short-Version.docx
...

Sheet HVAC System
A1: ="HVAC system - "&Prototype!A2 -> HVAC system - RetailMedium
A2: Vintage | B2: Heating | C2: Cooling | D2: Air Distribution | E2: Other systems | F2: Source | G2: Note
A3: Existing | B3: PSZAC (furnace) | C3: PSZAC (DX cooling) | D3: CAV | E3: OA mixing Economizer for Vintage 3 and 4 | F3: CEUS 2022 | G3: 4 RTUs for Core zone (each with a max of 20 ton)
A4: New Construction | B4: SZVAVHP | C4: SZVAVHP | D4: VAV | E4: OA mixing Economizer | F4: Title 24, 2025, Engineering judgement | G4: 4 systems for Core zone (each with a max of 20 ton)
A8: Efficiency of HVAC System (Efficiency is capacity-dependent. The following table provides a general estimate of system efficiency based on preliminary simulations in one climate zone, or assuming cooling load based on rule of thumb)
A9: Vintage | B9: Upgrade/Installed year | C9: Heating | D9: Cooling | E9: Source
A10: Pre 1978 | B10: 2008 | C10: Thermal Efficiency of 80% | D10: SEER=13.0 for <65 kBtu/h EER 10.1 for 65-135 kBtu/h EER 9.5 for 135-240 kBtu/h EER 9.3 for 240-760 kBtu/h | E10: T24, Table 112-A (2008) 10 CFR § 431.97, Table 1 (2008) California Title 20 Appliance Efficiency Regulations, Table E-4, Standards for Gas- and Oil-Fired Central Furnaces (2008)
A11: 1978-1997
A12: 1998-2007
A13: 2008-2018 | B13: 2013 | C13: Thermal Efficiency of 80%; | D13: SEER 13 for <65 kBtu/h EER 11.0 for 65-135 kBtu/h EER 10.8 for 135-240 kBtu/h EER 9.8 for 240-760 kBtu/h | E13: T24, 2013 Table 110.2-J & Table 110.2-A (2013) 10 CFR § 431.97(b) Table 1 (2013)
A14: New Construction | B14: 2025 | C14: HSPF 8.0 for <65 kBtu/h COP 3.4 for 65-135 kBtu/h COP 3.3 for 135-240 kBtu/h COP 3.2 for >240 kBtu/h | D14: SEER 14 for <65 kBtu/h EER 10.8, IEER 13.9 for 65-135 kBtu/h EER 10.4, IEER = 13.3 135-240 kBtu/h EER 9.3, IEER=12.3 for >240 kBtu/h | E14: 10 CFR § 431.97(b) Table 1 (2025) Title 20 Appliance Efficiency Regulations, Section 1605.1, Table C-5 (2025) T24, Table 110.2-B (2025)
B17: cfm | C17: 5000 12.5 tons _ 8000 cfm
A18: Fan Power
A19: Vintage | B19: Approach | C19: System | D19: Total Static Pressure (TSP) (in w.c.) | E19: Fan Efficiency [ACM 2025] | F19: Motor Efficiency | G19: Fan Power Index (W/cfm) | H19: Data Source | I19: Note
A20: Existing | B20: PNNL 90.1-2011, TSP | C20: CAV < 7,437 cfm | D20: 2.5 | E20: 0.65 | F20: ASHRAE 90.1, 2004, Table 10.8 * | H20: Fan power formula: PNNL 20405, 2010, section 5.2.2.5 TSP and fan efficiency: PNNL 20405, 2010, Table 5.11, 90.1-04ac values Motor and drive efficiency: ASHRAE 90.1, 2004, Table 10.8
C21: CAV >= 7,437 cfm | D21: 4.09
A22: Brake horsepower (bhp) = (Supply cfm × TSP in w.c.) / (6356 × fan efficiency)
A23: Fan power (w/cfm) = (bhp × 746) / ( supply cfm × motor efficiency )
A24: New Construction | B24: ACM 2025 | C24: SZVAVHP (System 7b), >5,000 and ≤10,000 cfm | D24: TSP = fan power × motor efficiency × fan efficiency × 6356 / 746 | E24: 0.65 | F24: 2025 ACM Table 12 ** | G24: 0.72 | H24: Fan power index: [ACM 2025, Table 13] Motor efficiency: [ACM 2025, Table 12]
C25: SZVAVHP (System 7b), >10,000 cfm | D25: TSP = fan power × motor efficiency × fan efficiency × 6356 / 746 | G25: 0.676
A27: * According to PNNL 20405 section 5.2.2.5, the full-load efficiency of the motor serving the fan is taken from ASHRAE 90.1, 2004, Table 10.8, based on motor nameplate and assuming enclosed motors operating at 1,800 rotations per minute (rpm) Motor nameplate size (bhp) = brake horsepower (bhp) × 1.1 ( using a 10% oversizing factor)
A28: ** The full‑load efficiency of the motor serving the fan is taken from ACM 2025 Table 12 based on the cfm of the fan. Brake horsepower (bhp) = (Supply cfm from sizing run × fan power in W/cfm) / 746. Note: HVAC: 4 core systems, each max 20 ton (about 8,000 cfm). ACM System 7b mid bin. Note: Only if a unit exceeds 10,000 cfm. Design note is max 20 ton, which is the row above.

Sheet Ventilation
A1: ="Outdoor Airflow Rate - "&Prototype!A2 -> Outdoor Airflow Rate - RetailMedium
A2: Space/Thermal Zone | B2: Number of People | C2: Floor Area (ft²) | D2: cfm/person [T24, 2025, Equation 120.1-F and Table 120.1-A] | E2: cfm/ft² [T24, 2025, Equation 120.1-F and Table 120.1-A] | F2: Required Exhaust Rate [T24, 2025, Table 120.1-B – minimum exhaust rates] | G2: Total cfm Driven by People | H2: Total cfm Driven by Area | I2: Total cfm Driven by Exhaust | J2: Total cfm | K2: Notes
A3: =Zones!B3 -> Core_Retail | B3: =Zones!L3 -> 292.99527 | C3: =Zones!I3 -> 17235.016 | D3: 15 | E3: 0.2 | G3: =D3*B3 -> 4394.9291 | H3: =E3*C3 -> 3447.0032 | I3: =F3*C3 -> 0 | J3: =MAX(G3:I3) -> 4394.9291
A4: =Zones!B4 -> Point_of_Sale | B4: =Zones!L4 -> 27.704424 | C4: =Zones!I4 -> 1629.672 | D4: 15 | E4: 0.2 | G4: =D4*B4 -> 415.56636 | H4: =E4*C4 -> 325.9344 | I4: =F4*C4 -> 0 | J4: =MAX(G4:I4) -> 415.56636
A5: =Zones!B5 -> Front_Retail | B5: =Zones!L5 -> 27.704424 | C5: =Zones!I5 -> 1629.672 | D5: 15 | E5: 0.2 | G5: =D5*B5 -> 415.56636 | H5: =E5*C5 -> 325.9344 | I5: =F5*C5 -> 0 | J5: =MAX(G5:I5) -> 415.56636
A6: =Zones!B6 -> Front_Entry | B6: =Zones!L6 -> 0.6173 | C6: =Zones!I6 -> 123.46 | D6: 15 | E6: 0.15 | G6: =D6*B6 -> 9.2595 | H6: =E6*C6 -> 18.519 | I6: =F6*C6 -> 0 | J6: =MAX(G6:I6) -> 18.519
A7: =Zones!B7 -> Loading_Dock | B7: =Zones!L7 -> 1.185216 | C7: =Zones!I7 -> 592.608 | D7: 15 | E7: 0.15 | G7: =D7*B7 -> 17.77824 | H7: =E7*C7 -> 88.8912 | I7: =F7*C7 -> 0 | J7: =MAX(G7:I7) -> 88.8912 | K7: Shipping/receiving
A8: =Zones!B8 -> Bulk_Storage | B8: =Zones!L8 -> 0 | C8: =Zones!I8 -> 2395.124 | D8: 15 | E8: 0.15 | G8: =D8*B8 -> 0 | H8: =E8*C8 -> 359.2686 | I8: =F8*C8 -> 0 | J8: =MAX(G8:I8) -> 359.2686 | K8: Warehouses
A9: =Zones!B9 -> Office/Stuff | B9: =Zones!L9 -> 3.33342 | C9: =Zones!I9 -> 666.684 | D9: 15 | E9: 0.15 | G9: =D9*B9 -> 50.0013 | H9: =E9*C9 -> 100.0026 | I9: =F9*C9 -> 0 | J9: =MAX(G9:I9) -> 100.0026
A10: =Zones!B10 -> Restroom | B10: =Zones!L10 -> 0 | C10: =Zones!I10 -> 419.764 | D10: 15 | E10: 0.15 | F10: 4*50/70 (cfm/unit) | G10: =D10*B10 -> 0 | H10: =E10*C10 -> 62.9646 | I10: =4*50 -> 200 | J10: =MAX(G10:I10) -> 200
A14: Currently assuming the entry is not actively ventilated due to doors (and connection to core) providing air.

Sheet Thermostat
A1: ="Thermostat Setpoints - "&Prototype!A2 -> Thermostat Setpoints - RetailMedium
A2: Spaces/Zones | B2: Setpoint | C2: CZ1 | D2: CZ2 | E2: CZ3 | F2: CZ4 | G2: CZ5 | H2: CZ6 | I2: CZ7 | J2: CZ8 | K2: CZ9 | L2: CZ10 | M2: CZ11 | N2: CZ12 | O2: CZ13 | P2: CZ14 | Q2: CZ15 | R2: CZ16 | S2: Source
A3: All spaces except Bulk_Storage and Loading_Dock | B3: Heating Setpoint (F) | C3: 70 | D3: 70 | E3: 70 | F3: 70 | G3: 70 | H3: 70 | I3: 70 | J3: 70 | K3: 70 | L3: 70 | M3: 70 | N3: 70 | O3: 70 | P3: 70 | Q3: 70 | R3: 70 | S3: T24 2022 - Appendix 5.4B
B4: Heating Setback (F) | C4: 60 | D4: 60 | E4: 60 | F4: 60 | G4: 60 | H4: 60 | I4: 60 | J4: 60 | K4: 60 | L4: 60 | M4: 60 | N4: 60 | O4: 60 | P4: 60 | Q4: 60 | R4: 60
B5: Cooling Setpoint (F) | C5: 75 | D5: 75 | E5: 75 | F5: 75 | G5: 75 | H5: 75 | I5: 75 | J5: 75 | K5: 75 | L5: 75 | M5: 75 | N5: 75 | O5: 75 | P5: 75 | Q5: 75 | R5: 75
B6: Cooling Setback (F) | C6: 85 | D6: 85 | E6: 85 | F6: 85 | G6: 85 | H6: 85 | I6: 85 | J6: 85 | K6: 85 | L6: 85 | M6: 85 | N6: 85 | O6: 85 | P6: 85 | Q6: 85 | R6: 85
A7: Bulk_Storage and Loading_Dock | B7: Heating Setpoint (F) | C7: 60 | D7: 60 | E7: 60 | F7: 60 | G7: 60 | H7: 60 | I7: 60 | J7: 60 | K7: 60 | L7: 60 | M7: 60 | N7: 60 | O7: 60 | P7: 60 | Q7: 60 | R7: 60 | S7: Engineering Judgment (Semi‑conditioned space)
B8: Heating Setback (F) | C8: 60 | D8: 60 | E8: 60 | F8: 60 | G8: 60 | H8: 60 | I8: 60 | J8: 60 | K8: 60 | L8: 60 | M8: 60 | N8: 60 | O8: 60 | P8: 60 | Q8: 60 | R8: 60
B9: Cooling Setpoint (F) | C9: 85 | D9: 85 | E9: 85 | F9: 85 | G9: 85 | H9: 85 | I9: 85 | J9: 85 | K9: 85 | L9: 85 | M9: 85 | N9: 85 | O9: 85 | P9: 85 | Q9: 85 | R9: 85
B10: Cooling Setback (F) | C10: 85 | D10: 85 | E10: 85 | F10: 85 | G10: 85 | H10: 85 | I10: 85 | J10: 85 | K10: 85 | L10: 85 | M10: 85 | N10: 85 | O10: 85 | P10: 85 | Q10: 85 | R10: 85

Sheet Water Heater
A1: ="Water Heater - "&Prototype!A2 -> Water Heater - RetailMedium
A2: Vintage | B2: WH Type | C2: Efficiency | D2: Number of WH | E2: Tank Volume (gal) | F2: Tank Loss | G2: Source
A3: Existing | B3: Electric | C3: 1 | D3: 1 | E3: 30 See table below for CZ-specific values: Climate Zone Water Heater Sizing and Loss Coefficients, Storage Volume column (col F) | F3: 1.2 %/hr See table below: Climate Zone Water Heater Sizing and Loss Coefficients, Standby Loss column (col G) | G3: See table below for sources: Climate Zone Water Heater Sizing and Loss Coefficients
A4: New Construction | B4: Electric | C4: 1 | D4: 1 | E4: 30 See table below for CZ-specific values: Climate Zone Water Heater Sizing and Loss Coefficients, Storage Volume column (col F) | F4: 1.2 %/hr See table below: Climate Zone Water Heater Sizing and Loss Coefficients, Standby Loss column (col G) | G4: See table below for sources: Climate Zone Water Heater Sizing and Loss Coefficients
A6: Peak Hot Water Consumption
A7: Space Name | B7: Baseline WH Type [CEUS 2022] | C7: Total Area (ft²) | D7: Number of People | E7: Hot Water Usage Specification (gal/hr per person) [T24, 2022, Appendix 5.4A , sheet: "2022 SpaceFuncData-Input"] | F7: Peak Hot Water Usage (gal/hr) | G7: Peak Hot Water Usage (gal/min) | H7: Note
A8: =Zones!B3 -> Core_Retail | B8: Electric | C8: =Zones!I3 -> 17235.016 | D8: =Zones!L3 -> 292.99527 | E8: 0.18 | F8: =E8*D8 -> 52.739149 | G8: =F8/60 -> 0.87898582 | H8: For space types marked with an asterisk (the ‘*’ symbol), the water‑heater type is listed as electric in Appendix 5.4A, sheet ‘2022 SpaceFuncData‑Input.’ However, we modified the value based on CEUS data, which indicates that gas is the primary fuel type.
A9: =Zones!B4 -> Point_of_Sale | B9: Electric | C9: =Zones!I4 -> 1629.672 | D9: =Zones!L4 -> 27.704424 | E9: 0.18 | F9: =E9*D9 -> 4.9867963 | G9: =F9/60 -> 0.083113272
A10: =Zones!B5 -> Front_Retail | B10: Electric | C10: =Zones!I5 -> 1629.672 | D10: =Zones!L5 -> 27.704424 | E10: 0.18 | F10: =E10*D10 -> 4.9867963 | G10: =F10/60 -> 0.083113272
A11: =Zones!B6 -> Front_Entry | B11: Electric | C11: =Zones!I6 -> 123.46 | D11: =Zones!L6 -> 0.6173 | E11: 0 | F11: =E11*D11 -> 0 | G11: =F11/60 -> 0
A12: =Zones!B7 -> Loading_Dock | B12: Electric | C12: =Zones!I7 -> 592.608 | D12: =Zones!L7 -> 1.185216 | E12: 0.18 | F12: =E12*D12 -> 0.21333888 | G12: =F12/60 -> 0.003555648
A13: =Zones!B8 -> Bulk_Storage | B13: Electric | C13: =Zones!I8 -> 2395.124 | D13: =Zones!L8 -> 0 | E13: 0 | F13: =E13*D13 -> 0 | G13: =F13/60 -> 0
A14: =Zones!B9 -> Office/Stuff | B14: Electric | C14: =Zones!I9 -> 666.684 | D14: =Zones!L9 -> 3.33342 | E14: 0.18 | F14: =E14*D14 -> 0.6000156 | G14: =F14/60 -> 0.01000026
A15: =Zones!B10 -> Restroom | B15: Electric | C15: =Zones!I10 -> 419.764 | D15: =Zones!L10 -> 0 | E15: 0 | F15: =E15*D15 -> 0 | G15: =F15/60 -> 0
A16: Total | B16: Gas storage | F16: =_xlfn.LET( _xlpm.g,SUMIF($B$8:$B$15,"Gas*",$F$8:$F$15), _xlpm.e,SUMIF($B$8:$B$15,"Electric*",$F$8:$F$15), IF(AND(_xlpm.g>0,_xlpm.e>0),_xlpm.g,IF(_xlpm.g>0,MAX(75,_xlpm.g),0))) -> 0 | H16: Minimum peak hot water usage is 75 gal according to ACM 2025
A17: Total | B17: Electric resistance | F17: =_xlfn.LET( _xlpm.g,SUMIF($B$8:$B$15,"Gas*",$F$8:$F$15), _xlpm.e,SUMIF($B$8:$B$15,"Electric*",$F$8:$F$15), IF(AND(_xlpm.g>0,_xlpm.e>0),_xlpm.e,IF(_xlpm.e>0,MAX(75,_xlpm.e),0))) -> 75
A21: Design supply temperature (°F) | B21: 135 | C21: CEC-400-2022-009-CMF-REV2-AP5.4B
A22: WH system factor | B22: 0.6 | C22: 2025 ACM §5.9.2 Rated Capacity
A23: Water mass conversion (lb/gal) | B23: 8.2877 | C23: 2025 ACM §5.9.2 Rated Capacity
A24: Reheat multiplier | B24: 0.4 | C24: 2025 ACM §5.9.2 Storage Volume
A25: Climate Zone Water Heater Sizing and Loss Coefficients (Individual WH)
A26: Water Heater Name | B26: Climate Zone | C26: Minimum Monthly Mains Temp (°F) [T24 2022 - Appendix 5.4B] | D26: Heat Output (Btu/hr) [ACM, 2025, 5.9.2: Rated capacity section] | E26: WH Capacity (Btu/hr) [ACM, 2025, 5.9.2: Rated capacity section] | F26: Required Energy Input (Btu/hr) | G26: Storage Volume (gal) | H26: Standby Loss [Title 20, §1605.1 Table F-4; Appendix B: Water Heating Calculation Method] | J26: Off/On Cycle Loss Coefficient to Ambient Temp | L26: Source/Note
A27: WH_RetailMedium | B27: CZ01 | C27: 47.9 | D27: =$F$17*($B$21-C27)*$B$23 -> 54139.4 | E27: =D27*$B$22 -> 32483.64 | F27: =_xlfn.LET(_xlpm.x,_xlfn.XLOOKUP(E27,$D$48:$D$62,$D$48:$D$62,"",1),IF(_xlpm.x="",ROUNDUP(E27,0),_xlpm.x)) -> 34121 | G27: =_xlfn.LET(_xlpm.v,MAX(30,$F$17*$B$24),_xlpm.x,_xlfn.XLOOKUP(_xlpm.v,$G$48:$G$62,$G$48:$G$62,"",1),IF(_xlpm.x="",ROUNDUP(_xlpm.v,0),_xlpm.x)) -> 30 | H27: =0.3+27/G27 -> 1.2 | I27: =IF($F$17>0,"%/hr","Btu/hr") -> %/hr | J27: =0.0834*H27*G27 -> 3.0024 | K27: Btu/h·°F | L27: Required Energy Input: vendor/available catalog size (Market data table). Storage Volume: standard/available catalog tank size (Market data table).
A28: WH_RetailMedium | B28: CZ02 | C28: 50.8 | D28: =$F$17*($B$21-C28)*$B$23 -> 52336.825 | E28: =D28*$B$22 -> 31402.095 | F28: =_xlfn.LET(_xlpm.x,_xlfn.XLOOKUP(E28,$D$48:$D$62,$D$48:$D$62,"",1),IF(_xlpm.x="",ROUNDUP(E28,0),_xlpm.x)) -> 34121 | G28: =_xlfn.LET(_xlpm.v,MAX(30,$F$17*$B$24),_xlpm.x,_xlfn.XLOOKUP(_xlpm.v,$G$48:$G$62,$G$48:$G$62,"",1),IF(_xlpm.x="",ROUNDUP(_xlpm.v,0),_xlpm.x)) -> 30 | H28: =0.3+27/G28 -> 1.2 | I28: =IF($F$17>0,"%/hr","Btu/hr") -> %/hr | J28: =0.0834*H28*G28 -> 3.0024 | K28: Btu/h·°F
A29: WH_RetailMedium | B29: CZ03 | C29: 52.2 | D29: =$F$17*($B$21-C29)*$B$23 -> 51466.617 | E29: =D29*$B$22 -> 30879.97 | F29: =_xlfn.LET(_xlpm.x,_xlfn.XLOOKUP(E29,$D$48:$D$62,$D$48:$D$62,"",1),IF(_xlpm.x="",ROUNDUP(E29,0),_xlpm.x)) -> 34121 | G29: =_xlfn.LET(_xlpm.v,MAX(30,$F$17*$B$24),_xlpm.x,_xlfn.XLOOKUP(_xlpm.v,$G$48:$G$62,$G$48:$G$62,"",1),IF(_xlpm.x="",ROUNDUP(_xlpm.v,0),_xlpm.x)) -> 30 | H29: =0.3+27/G29 -> 1.2 | I29: =IF($F$17>0,"%/hr","Btu/hr") -> %/hr | J29: =0.0834*H29*G29 -> 3.0024 | K29: Btu/h·°F
A30: WH_RetailMedium | B30: CZ04 | C30: 52.7 | D30: =$F$17*($B$21-C30)*$B$23 -> 51155.828 | E30: =D30*$B$22 -> 30693.497 | F30: =_xlfn.LET(_xlpm.x,_xlfn.XLOOKUP(E30,$D$48:$D$62,$D$48:$D$62,"",1),IF(_xlpm.x="",ROUNDUP(E30,0),_xlpm.x)) -> 30709 | G30: =_xlfn.LET(_xlpm.v,MAX(30,$F$17*$B$24),_xlpm.x,_xlfn.XLOOKUP(_xlpm.v,$G$48:$G$62,$G$48:$G$62,"",1),IF(_xlpm.x="",ROUNDUP(_xlpm.v,0),_xlpm.x)) -> 30 | H30: =0.3+27/G30 -> 1.2 | I30: =IF($F$17>0,"%/hr","Btu/hr") -> %/hr | J30: =0.0834*H30*G30 -> 3.0024 | K30: Btu/h·°F
A31: WH_RetailMedium | B31: CZ05 | C31: 51.6 | D31: =$F$17*($B$21-C31)*$B$23 -> 51839.563 | E31: =D31*$B$22 -> 31103.738 | F31: =_xlfn.LET(_xlpm.x,_xlfn.XLOOKUP(E31,$D$48:$D$62,$D$48:$D$62,"",1),IF(_xlpm.x="",ROUNDUP(E31,0),_xlpm.x)) -> 34121 | G31: =_xlfn.LET(_xlpm.v,MAX(30,$F$17*$B$24),_xlpm.x,_xlfn.XLOOKUP(_xlpm.v,$G$48:$G$62,$G$48:$G$62,"",1),IF(_xlpm.x="",ROUNDUP(_xlpm.v,0),_xlpm.x)) -> 30 | H31: =0.3+27/G31 -> 1.2 | I31: =IF($F$17>0,"%/hr","Btu/hr") -> %/hr | J31: =0.0834*H31*G31 -> 3.0024 | K31: Btu/h·°F
A32: WH_RetailMedium | B32: CZ06 | C32: 56.8 | D32: =$F$17*($B$21-C32)*$B$23 -> 48607.36 | E32: =D32*$B$22 -> 29164.416 | F32: =_xlfn.LET(_xlpm.x,_xlfn.XLOOKUP(E32,$D$48:$D$62,$D$48:$D$62,"",1),IF(_xlpm.x="",ROUNDUP(E32,0),_xlpm.x)) -> 30709 | G32: =_xlfn.LET(_xlpm.v,MAX(30,$F$17*$B$24),_xlpm.x,_xlfn.XLOOKUP(_xlpm.v,$G$48:$G$62,$G$48:$G$62,"",1),IF(_xlpm.x="",ROUNDUP(_xlpm.v,0),_xlpm.x)) -> 30 | H32: =0.3+27/G32 -> 1.2 | I32: =IF($F$17>0,"%/hr","Btu/hr") -> %/hr | J32: =0.0834*H32*G32 -> 3.0024 | K32: Btu/h·°F
A33: WH_RetailMedium | B33: CZ07 | C33: 58.4 | D33: =$F$17*($B$21-C33)*$B$23 -> 47612.836 | E33: =D33*$B$22 -> 28567.702 | F33: =_xlfn.LET(_xlpm.x,_xlfn.XLOOKUP(E33,$D$48:$D$62,$D$48:$D$62,"",1),IF(_xlpm.x="",ROUNDUP(E33,0),_xlpm.x)) -> 30709 | G33: =_xlfn.LET(_xlpm.v,MAX(30,$F$17*$B$24),_xlpm.x,_xlfn.XLOOKUP(_xlpm.v,$G$48:$G$62,$G$48:$G$62,"",1),IF(_xlpm.x="",ROUNDUP(_xlpm.v,0),_xlpm.x)) -> 30 | H33: =0.3+27/G33 -> 1.2 | I33: =IF($F$17>0,"%/hr","Btu/hr") -> %/hr | J33: =0.0834*H33*G33 -> 3.0024 | K33: Btu/h·°F
A34: WH_RetailMedium | B34: CZ08 | C34: 58.4 | D34: =$F$17*($B$21-C34)*$B$23 -> 47612.836 | E34: =D34*$B$22 -> 28567.702 | F34: =_xlfn.LET(_xlpm.x,_xlfn.XLOOKUP(E34,$D$48:$D$62,$D$48:$D$62,"",1),IF(_xlpm.x="",ROUNDUP(E34,0),_xlpm.x)) -> 30709 | G34: =_xlfn.LET(_xlpm.v,MAX(30,$F$17*$B$24),_xlpm.x,_xlfn.XLOOKUP(_xlpm.v,$G$48:$G$62,$G$48:$G$62,"",1),IF(_xlpm.x="",ROUNDUP(_xlpm.v,0),_xlpm.x)) -> 30 | H34: =0.3+27/G34 -> 1.2 | I34: =IF($F$17>0,"%/hr","Btu/hr") -> %/hr | J34: =0.0834*H34*G34 -> 3.0024 | K34: Btu/h·°F
A35: WH_RetailMedium | B35: CZ09 | C35: 57.6 | D35: =$F$17*($B$21-C35)*$B$23 -> 48110.098 | E35: =D35*$B$22 -> 28866.059 | F35: =_xlfn.LET(_xlpm.x,_xlfn.XLOOKUP(E35,$D$48:$D$62,$D$48:$D$62,"",1),IF(_xlpm.x="",ROUNDUP(E35,0),_xlpm.x)) -> 30709 | G35: =_xlfn.LET(_xlpm.v,MAX(30,$F$17*$B$24),_xlpm.x,_xlfn.XLOOKUP(_xlpm.v,$G$48:$G$62,$G$48:$G$62,"",1),IF(_xlpm.x="",ROUNDUP(_xlpm.v,0),_xlpm.x)) -> 30 | H35: =0.3+27/G35 -> 1.2 | I35: =IF($F$17>0,"%/hr","Btu/hr") -> %/hr | J35: =0.0834*H35*G35 -> 3.0024 | K35: Btu/h·°F
A36: WH_RetailMedium | B36: CZ10 | C36: 57.1 | D36: =$F$17*($B$21-C36)*$B$23 -> 48420.887 | E36: =D36*$B$22 -> 29052.532 | F36: =_xlfn.LET(_xlpm.x,_xlfn.XLOOKUP(E36,$D$48:$D$62,$D$48:$D$62,"",1),IF(_xlpm.x="",ROUNDUP(E36,0),_xlpm.x)) -> 30709 | G36: =_xlfn.LET(_xlpm.v,MAX(30,$F$17*$B$24),_xlpm.x,_xlfn.XLOOKUP(_xlpm.v,$G$48:$G$62,$G$48:$G$62,"",1),IF(_xlpm.x="",ROUNDUP(_xlpm.v,0),_xlpm.x)) -> 30 | H36: =0.3+27/G36 -> 1.2 | I36: =IF($F$17>0,"%/hr","Btu/hr") -> %/hr | J36: =0.0834*H36*G36 -> 3.0024 | K36: Btu/h·°F
A37: WH_RetailMedium | B37: CZ11 | C37: 50.5 | D37: =$F$17*($B$21-C37)*$B$23 -> 52523.299 | E37: =D37*$B$22 -> 31513.979 | F37: =_xlfn.LET(_xlpm.x,_xlfn.XLOOKUP(E37,$D$48:$D$62,$D$48:$D$62,"",1),IF(_xlpm.x="",ROUNDUP(E37,0),_xlpm.x)) -> 34121 | G37: =_xlfn.LET(_xlpm.v,MAX(30,$F$17*$B$24),_xlpm.x,_xlfn.XLOOKUP(_xlpm.v,$G$48:$G$62,$G$48:$G$62,"",1),IF(_xlpm.x="",ROUNDUP(_xlpm.v,0),_xlpm.x)) -> 30 | H37: =0.3+27/G37 -> 1.2 | I37: =IF($F$17>0,"%/hr","Btu/hr") -> %/hr | J37: =0.0834*H37*G37 -> 3.0024 | K37: Btu/h·°F
A38: WH_RetailMedium | B38: CZ12 | C38: 51.4 | D38: =$F$17*($B$21-C38)*$B$23 -> 51963.879 | E38: =D38*$B$22 -> 31178.327 | F38: =_xlfn.LET(_xlpm.x,_xlfn.XLOOKUP(E38,$D$48:$D$62,$D$48:$D$62,"",1),IF(_xlpm.x="",ROUNDUP(E38,0),_xlpm.x)) -> 34121 | G38: =_xlfn.LET(_xlpm.v,MAX(30,$F$17*$B$24),_xlpm.x,_xlfn.XLOOKUP(_xlpm.v,$G$48:$G$62,$G$48:$G$62,"",1),IF(_xlpm.x="",ROUNDUP(_xlpm.v,0),_xlpm.x)) -> 30 | H38: =0.3+27/G38 -> 1.2 | I38: =IF($F$17>0,"%/hr","Btu/hr") -> %/hr | J38: =0.0834*H38*G38 -> 3.0024 | K38: Btu/h·°F
A39: WH_RetailMedium | B39: CZ13 | C39: 51.7 | D39: =$F$17*($B$21-C39)*$B$23 -> 51777.406 | E39: =D39*$B$22 -> 31066.443 | F39: =_xlfn.LET(_xlpm.x,_xlfn.XLOOKUP(E39,$D$48:$D$62,$D$48:$D$62,"",1),IF(_xlpm.x="",ROUNDUP(E39,0),_xlpm.x)) -> 34121 | G39: =_xlfn.LET(_xlpm.v,MAX(30,$F$17*$B$24),_xlpm.x,_xlfn.XLOOKUP(_xlpm.v,$G$48:$G$62,$G$48:$G$62,"",1),IF(_xlpm.x="",ROUNDUP(_xlpm.v,0),_xlpm.x)) -> 30 | H39: =0.3+27/G39 -> 1.2 | I39: =IF($F$17>0,"%/hr","Btu/hr") -> %/hr | J39: =0.0834*H39*G39 -> 3.0024 | K39: Btu/h·°F
... A42: WH_RetailMedium | B42: CZ16 | C42: 41.4 | D42: =$F$17*($B$21-C42)*$B$23 -> 58179.654 | E42: =D42*$B$22 -> 34907.792 | F42: =_xlfn.LET(_xlpm.x,_xlfn.XLOOKUP(E42,$D$48:$D$62,$D$48:$D$62,"",1),IF(_xlpm.x="",ROUNDUP(E42,0),_xlpm.x)) -> 40946 | G42: =_xlfn.LET(_xlpm.v,MAX(30,$F$17*$B$24),_xlpm.x,_xlfn.XLOOKUP(_xlpm.v,$G$48:$G$62,$G$48:$G$62,"",1),IF(_xlpm.x="",ROUNDUP(_xlpm.v,0),_xlpm.x)) -> 30 | H42: =0.3+27/G42 -> 1.2 | I42: =IF($F$17>0,"%/hr","Btu/hr") -> %/hr | J42: =0.0834*H42*G42 -> 3.0024 | K42: Btu/h·°F
A46: Market data
A47: Catalog gas input (Btu/h) | B47: Input source | C47: Elec resistance tank (kW) | D47: Elec resistance (Btu/h) | E47: Catalog gas tank (gal) | F47: Tank source | G47: Elec tank (gal) | H47: Elec tank source | I47: =HYPERLINK("#'Note'!A1","Sources and links → Note tab") -> Sources and links → Note tab
A48: 60000 | B48: Grainger | C48: 1.5 | D48: 5118 | E48: 34 | F48: ENERGY STAR | G48: 6 | H48: Grainger
A49: 75100 | B49: Grainger | C49: 2 | D49: 6824 | E49: 35 | F49: Grainger | G49: 10 | H49: Grainger
...

Sheet Interior Lights
A1: ="Interior Lighting - "&Prototype!A2 -> Interior Lighting - RetailMedium
A2: Space Type | B2: New Construction | E2: Existing
B3: LPD (W/ft²) | C3: Additional LPD for Portable Lighting (W/ft²) | D3: Source | E3: LPD (W/ft²) | F3: Additional LPD for Portable Lighting (W/ft²) | G3: Source | H3: Note
A4: =Zones!C9 -> Office Area (>250 square feet) | B4: 0.6 | C4: 0.1 | D4: T24, part 6, 2025, Table 140.6-C (Area category method) | E4: 0.75 | F4: - | G4: T24, part 6, 2016, Table 140.6-C (Area category method) | H4: It is assumed that 50% of the additional allowance lighting is in use.
A5: =Zones!C7 -> Storage, Commercial/Industrial (Shipping & Handling) | B5: 0.6 | E5: 0.9 | H5: Used the value for General Commercial and Industrial Work Areas in 2016
A6: =Zones!C10 -> Restrooms | B6: 0.65 | E6: 0.6
A7: =Zones!C8 -> Storage (General) | B7: 0.4 | E7: 0.6 | H7: Space type used: Storage, Commercial/Industrial _ Warehouse in 2025 Commercial and Industrial Storage Area in 2016
A8: =Zones!C3 -> Retail Sales Area (Retail Merchandise Sales) | B8: 0.95 | C8: =0.52*0.2 -> 0.104 | E8: 1.2 | F8: =0.3*0.2 -> 0.06 | H8: The percentage of additional lighting depends heavily on the specific store type. As a general assumption, additional lighting is calculated for 20% of the Retail Sales Area.
A9: =Zones!C6 -> Corridor Area | B9: 0.7 | E9: 0.95 | H9: The values from Table 140.6-C have been slightly adjusted for this space to align with main entry space type

Sheet Ext Lighting
A1: ="Exterior Lighting - "&Prototype!A2 -> Exterior Lighting - RetailMedium
A2: Motion Controlled Luminaires (W) | B2: Non-motion Controlled Luminaires (W) | C2: Total (W) | D2: Source
A3: =G14 -> 796.27556 | B3: =G15 -> 651.2844 | C3: =SUM(A3:B3) -> 1447.56 | D3: T24, 2022
A6: Exterior Lighting
A7: Items (Assume LZ2) | B7: Assumptions [2019 Outdoor Lighting CASE Report & PNNL 90.1-2010 TSD] | D7: Unit | E7: Lighting Power Allowance [T24, 2025, Table 140.7-A & 140.7-B] | F7: Unit | G7: Exterior lighting power (w)
A8: IWA (Initial Wattage Allowance) | E8: 200 | F8: W | G8: =$E8 -> 200
A9: Parking area | B9: 400 ft² for every parking space [2019 Lighting CASE report, Appendix H] 1 parking space per 360 ft² of gross building area [2019 Lighting CASE report,Table 38] | C9: =B21/360*400 -> 27435.556 | D9: (ft²) | E9: 0.019 | F9: (W/ft²) | G9: =$E9*C9 -> 521.27556
A10: Building Entrance | B10: 1 per 5,000 sf footprint [2019 Lighting CASE report,Table 36] | C10: =ROUND(B21/5000,0) -> 5 | D10: (count) | E10: 15 | F10: (W/ea) | G10: =E10*C10 -> 75
A11: Hardscape Ornamental Light | B11: 0.1 ft² per 1 ft² of gross bldg area [2019 Lighting CASE report,Table 36] *The 0.5 multiplier has not been applied, as it is assumed it will be incorporated later during the measure analysis study. | C11: =B21*0.1 -> 2469.2 | D11: (ft²) | E11: 0.007 | F11: (W/ft²) | G11: =E11*C11 -> 17.2844
A12: Building façade | B12: 0.1 W per 1 ft² of facade area Façade Area = Perimeter × 0.5 × 20 ft The 0.5 factor assumes that only half of the perimeter walls are lit. -Formula ia developed based on the 2019 Outdoor Lighting CASE report | C12: =B20*0.5*Prototype!B17 -> 6340 | D12: (ft²) | E12: 0.1 | F12: (W/ft²) | G12: =E12*C12 -> 634
A13: Sales canopy | B13: 0.1 ft² per ft² of gross bldg area | C13: 0 | D13: (ft²) | E13: 0.47 | F13: (W/ft²) | G13: =E13*C13 -> 0
A14: Motion controlled Luminaires | G14: =SUM(G8:G13)-G15 -> 796.27556
A15: Non-motion-controlled Luminaires | G15: =G11+G12 -> 651.2844
A16: Total | G16: =G14+G15 -> 1447.56
A18: *Developed based on 2019 Outdoor Lighting CASE Report
A20: Perimeter | B20: =178*2+139*2 -> 634
A21: Total floor area | B21: =Zones!I11 -> 24692
A22: Floors | B22: 1
D31: The referenced report for many of the assumptions on this tab is the 2019 Outdoor Lighting CASE Report, which contains the following table. For retail, they applied the value to only 50% of the floor area. Perhaps the same factor should be applied to the prototype.

Sheet Equipment
A1: ="Equipment - "&Prototype!A2 -> Equipment - RetailMedium
A2: Space Type | B2: Plug load Power Density (W/ft²) | C2: Gas Power Density (Btu/hr-ft²) | D2: Refrigeration Power Density (W/ft²) | E2: Source | F2: Note
A3: ='Interior Lights'!A4 -> Office Area (>250 square feet) | B3: 0.7 | E3: Proposed Updates to Equipment Power Densities and Schedules in the 2028 Energy Code Nonresidential and Multifamily Alternative Calculation Method (NRMFACM) Reference Manual, August 7, 2025
A4: ='Interior Lights'!A5 -> Storage, Commercial/Industrial (Shipping & Handling) | B4: 0.5 | E4: T24 2022 - Appendix 5.4A: Space Use Data-T24N-2022
A5: ='Interior Lights'!A6 -> Restrooms | B5: 0 | E5: T24 2022 - Appendix 5.4A: Space Use Data-T24N-2022
A6: =Zones!C8 -> Storage (General) | B6: 0.2 | E6: T24 2022 - Appendix 5.4A: Space Use Data-T24N-2022 | F6: Matches Retail/All Other; PNNL prototype =~0.7; T24 Appendix 5.4A =0.2
A7: =Zones!C3 -> Retail Sales Area (Retail Merchandise Sales) | B7: 0.3 | E7: Mix of sources including "High-Efficiency Retrofit Lessons for Retail from a SuperTarget" (2013) & ASHRAE 90.1 Prototype
A8: =Zones!C6 -> Corridor Area | B8: 0 | E8: T24 2022 - Appendix 5.4A: Space Use Data-T24N-2022
A14: Background Data [To be deleted prior to publication]
G21: ~W PNNL | H21: ft² | I21: W/ft² PNNL | J21: W/ft² CEC
F22: BACK_SPACE | G22: 3000 | H22: 4089.1018 | I22: =G22/H22 -> 0.73365746 | J22: 0.2
F23: CORE_RETAIL | G23: 5000 | H23: 17227.423 | I23: =G23/H23 -> 0.29023494 | J23: 0.4
F24: POINT_OF_SALE | G24: 3000 | H24: 1623.3053 | I24: =G24/H24 -> 1.8480812 | J24: 0.4
F25: FRONT_RETAIL | G25: 500 | H25: 1623.3053 | I25: =G25/H25 -> 0.30801354 | J25: 0.4
A41: it is reasonable to leave the current 5.0 W/ft² assumption in the NMACM for refrigeration loads in Grocery Sales area

Sheet Schedules
A1: ="Schedules - "&Prototype!A2 -> Schedules - RetailMedium
A2: Zone | B2: Schedule Category | C2: Schedule | D2: Source | E2: Type | F2: Hour
F3: 1 | G3: 2 | H3: 3 | I3: 4 | J3: 5 | K3: 6 | L3: 7 | M3: 8 | N3: 9 | O3: 10 | P3: 11 | Q3: 12 | R3: 13 | S3: 14 | T3: 15 | U3: 16 | V3: 17 | W3: 18 | X3: 19 | Y3: 20 | Z3: 21 | AA3: 22 | AB3: 23 | AC3: 24
A4: All Zones | B4: Retail | C4: Occupancy | D4: NLR Study "Final Optimization Report: Empowering Energy Efficiency in Existing Big-Box Retail/Grocery Stores", (2020) & Adjusted based on Google Popular Time | E4: Weekday | F4: 0 | G4: 0 | H4: 0 | I4: 0 | J4: 0 | K4: 0 | L4: 0 | M4: 0 | N4: 0.2 | O4: 0.4 | P4: 0.5 | Q4: 0.6 | R4: 0.6 | S4: 0.6 | T4: 0.6 | U4: 0.6 | V4: 0.7 | W4: 0.8 | X4: 0.8 | Y4: 0.6 | Z4: 0.3 | AA4: 0 | AB4: 0 | AC4: 0
E5: Saturday | F5: 0 | G5: 0 | H5: 0 | I5: 0 | J5: 0 | K5: 0 | L5: 0 | M5: 0 | N5: 0.3 | O5: 0.6 | P5: 0.8 | Q5: 0.9 | R5: 0.9 | S5: 0.9 | T5: 0.9 | U5: 0.8 | V5: 0.8 | W5: 0.7 | X5: 0.6 | Y5: 0.5 | Z5: 0.3 | AA5: 0 | AB5: 0 | AC5: 0
E6: Sunday | F6: 0 | G6: 0 | H6: 0 | I6: 0 | J6: 0 | K6: 0 | L6: 0 | M6: 0 | N6: 0.2 | O6: 0.5 | P6: 0.7 | Q6: 0.8 | R6: 0.8 | S6: 0.8 | T6: 0.8 | U6: 0.7 | V6: 0.7 | W6: 0.6 | X6: 0.5 | Y6: 0.4 | Z6: 0.2 | AA6: 0 | AB6: 0 | AC6: 0
A7: =A4 -> All Zones | B7: =B4 -> Retail | C7: Lights | D7: T24 2022 - Appendix 5.4B, [Retail] | E7: Weekday | F7: 0.05 | G7: 0.05 | H7: 0.05 | I7: 0.05 | J7: 0.05 | K7: 0.05 | L7: 0.05 | M7: 0.7 | N7: 1 | O7: 1 | P7: 1 | Q7: 1 | R7: 1 | S7: 1 | T7: 1 | U7: 1 | V7: 1 | W7: 1 | X7: 1 | Y7: 1 | Z7: 1 | AA7: 0.7 | AB7: 0.05 | AC7: 0.05
E8: Saturday | F8: 0.05 | G8: 0.05 | H8: 0.05 | I8: 0.05 | J8: 0.05 | K8: 0.05 | L8: 0.05 | M8: 0.7 | N8: 1 | O8: 1 | P8: 1 | Q8: 1 | R8: 1 | S8: 1 | T8: 1 | U8: 1 | V8: 1 | W8: 1 | X8: 1 | Y8: 1 | Z8: 1 | AA8: 0.7 | AB8: 0.05 | AC8: 0.05
E9: Sunday | F9: 0.05 | G9: 0.05 | H9: 0.05 | I9: 0.05 | J9: 0.05 | K9: 0.05 | L9: 0.05 | M9: 0.7 | N9: 1 | O9: 1 | P9: 1 | Q9: 1 | R9: 1 | S9: 1 | T9: 1 | U9: 1 | V9: 1 | W9: 1 | X9: 1 | Y9: 1 | Z9: 1 | AA9: 0.7 | AB9: 0.05 | AC9: 0.05
A10: =A4 -> All Zones | B10: =B4 -> Retail | C10: ElecEquipment | D10: Plug load and schedules project with CEC, 2025 | E10: Weekday | F10: 0.4 | G10: 0.4 | H10: 0.4 | I10: 0.4 | J10: 0.4 | K10: 0.4 | L10: 0.4 | M10: 0.4 | N10: 0.9 | O10: 0.9 | P10: 0.9 | Q10: 0.9 | R10: 0.9 | S10: 0.9 | T10: 0.9 | U10: 0.9 | V10: 0.9 | W10: 0.9 | X10: 0.9 | Y10: 0.9 | Z10: 0.9 | AA10: 0.4 | AB10: 0.4 | AC10: 0.4
E11: Saturday | F11: 0.4 | G11: 0.4 | H11: 0.4 | I11: 0.4 | J11: 0.4 | K11: 0.4 | L11: 0.4 | M11: 0.4 | N11: 0.9 | O11: 0.9 | P11: 0.9 | Q11: 0.9 | R11: 0.9 | S11: 0.9 | T11: 0.9 | U11: 0.9 | V11: 0.9 | W11: 0.9 | X11: 0.9 | Y11: 0.9 | Z11: 0.9 | AA11: 0.4 | AB11: 0.4 | AC11: 0.4
E12: Sunday | F12: 0.4 | G12: 0.4 | H12: 0.4 | I12: 0.4 | J12: 0.4 | K12: 0.4 | L12: 0.4 | M12: 0.4 | N12: 0.9 | O12: 0.9 | P12: 0.9 | Q12: 0.9 | R12: 0.9 | S12: 0.9 | T12: 0.9 | U12: 0.9 | V12: 0.9 | W12: 0.9 | X12: 0.9 | Y12: 0.9 | Z12: 0.9 | AA12: 0.4 | AB12: 0.4 | AC12: 0.4
A13: =A7 -> All Zones | B13: =B7 -> Retail | C13: HVACAvail | D13: T24 2022 - Appendix 5.4B, [Retail] | E13: Weekday | F13: 0 | G13: 0 | H13: 0 | I13: 0 | J13: 0 | K13: 0 | L13: 1 | M13: 1 | N13: 1 | O13: 1 | P13: 1 | Q13: 1 | R13: 1 | S13: 1 | T13: 1 | U13: 1 | V13: 1 | W13: 1 | X13: 1 | Y13: 1 | Z13: 1 | AA13: 0 | AB13: 0 | AC13: 0
E14: Saturday | F14: 0 | G14: 0 | H14: 0 | I14: 0 | J14: 0 | K14: 0 | L14: 1 | M14: 1 | N14: 1 | O14: 1 | P14: 1 | Q14: 1 | R14: 1 | S14: 1 | T14: 1 | U14: 1 | V14: 1 | W14: 1 | X14: 1 | Y14: 1 | Z14: 1 | AA14: 1 | AB14: 0 | AC14: 0
E15: Sunday | F15: 0 | G15: 0 | H15: 0 | I15: 0 | J15: 0 | K15: 0 | L15: 0 | M15: 0 | N15: 1 | O15: 1 | P15: 1 | Q15: 1 | R15: 1 | S15: 1 | T15: 1 | U15: 1 | V15: 1 | W15: 1 | X15: 1 | Y15: 0 | Z15: 0 | AA15: 0 | AB15: 0 | AC15: 0
A16: =A10 -> All Zones | B16: =B10 -> Retail | C16: ServiceHotWater | D16: T24 2022 - Appendix 5.4B, [Retail] | E16: Weekday | F16: 0.04 | G16: 0.05 | H16: 0.05 | I16: 0.04 | J16: 0.04 | K16: 0.04 | L16: 0.04 | M16: 0.15 | N16: 0.23 | O16: 0.32 | P16: 0.41 | Q16: 0.57 | R16: 0.62 | S16: 0.61 | T16: 0.5 | U16: 0.45 | V16: 0.46 | W16: 0.47 | X16: 0.42 | Y16: 0.34 | Z16: 0.33 | AA16: 0.23 | AB16: 0.13 | AC16: 0.08
E17: Saturday | F17: 0.11 | G17: 0.1 | H17: 0.08 | I17: 0.06 | J17: 0.06 | K17: 0.06 | L17: 0.07 | M17: 0.2 | N17: 0.24 | O17: 0.27 | P17: 0.42 | Q17: 0.54 | R17: 0.59 | S17: 0.6 | T17: 0.49 | U17: 0.48 | V17: 0.47 | W17: 0.46 | X17: 0.44 | Y17: 0.36 | Z17: 0.29 | AA17: 0.22 | AB17: 0.16 | AC17: 0.13
E18: Sunday | F18: 0.07 | G18: 0.07 | H18: 0.07 | I18: 0.06 | J18: 0.06 | K18: 0.06 | L18: 0.07 | M18: 0.1 | N18: 0.12 | O18: 0.14 | P18: 0.29 | Q18: 0.31 | R18: 0.36 | S18: 0.36 | T18: 0.34 | U18: 0.35 | V18: 0.37 | W18: 0.34 | X18: 0.25 | Y18: 0.27 | Z18: 0.21 | AA18: 0.16 | AB18: 0.1 | AC18: 0.06
A19: =A13 -> All Zones | B19: =B13 -> Retail | C19: Infiltration | D19: T24 2022 - Appendix 5.4B, [Retail] | E19: Weekday | F19: 1 | G19: 1 | H19: 1 | I19: 1 | J19: 1 | K19: 1 | L19: 0.25 | M19: 0.25 | N19: 0.25 | O19: 0.25 | P19: 0.25 | Q19: 0.25 | R19: 0.25 | S19: 0.25 | T19: 0.25 | U19: 0.25 | V19: 0.25 | W19: 0.25 | X19: 0.25 | Y19: 0.25 | Z19: 0.25 | AA19: 1 | AB19: 1 | AC19: 1
E20: Saturday | F20: 1 | G20: 1 | H20: 1 | I20: 1 | J20: 1 | K20: 1 | L20: 0.25 | M20: 0.25 | N20: 0.25 | O20: 0.25 | P20: 0.25 | Q20: 0.25 | R20: 0.25 | S20: 0.25 | T20: 0.25 | U20: 0.25 | V20: 0.25 | W20: 0.25 | X20: 0.25 | Y20: 0.25 | Z20: 0.25 | AA20: 0.25 | AB20: 1 | AC20: 1
E21: Sunday | F21: 1 | G21: 1 | H21: 1 | I21: 1 | J21: 1 | K21: 1 | L21: 1 | M21: 1 | N21: 0.25 | O21: 0.25 | P21: 0.25 | Q21: 0.25 | R21: 0.25 | S21: 0.25 | T21: 0.25 | U21: 0.25 | V21: 0.25 | W21: 0.25 | X21: 0.25 | Y21: 1 | Z21: 1 | AA21: 1 | AB21: 1 | AC21: 1
A22: =A16 -> All Zones | B22: =B16 -> Retail | C22: HtgSetpt | D22: T24 2022 - Appendix 5.4B, [Retail] | E22: Weekday | F22: =IF(F13=1,Thermostat!$C$3,Thermostat!$C$4) -> 60 | G22: =IF(G13=1,Thermostat!$C$3,Thermostat!$C$4) -> 60 | H22: =IF(H13=1,Thermostat!$C$3,Thermostat!$C$4) -> 60 | I22: =IF(I13=1,Thermostat!$C$3,Thermostat!$C$4) -> 60 | J22: =IF(J13=1,Thermostat!$C$3,Thermostat!$C$4) -> 60 | K22: =IF(K13=1,Thermostat!$C$3,Thermostat!$C$4) -> 60 | L22: =IF(L13=1,Thermostat!$C$3,Thermostat!$C$4) -> 70 | M22: =IF(M13=1,Thermostat!$C$3,Thermostat!$C$4) -> 70 | ... AC22: =IF(AC13=1,Thermostat!$C$3,Thermostat!$C$4) -> 60
E23: Saturday | F23: =IF(F14=1,Thermostat!$C$3,Thermostat!$C$4) -> 60 | G23: =IF(G14=1,Thermostat!$C$3,Thermostat!$C$4) -> 60 | H23: =IF(H14=1,Thermostat!$C$3,Thermostat!$C$4) -> 60 | I23: =IF(I14=1,Thermostat!$C$3,Thermostat!$C$4) -> 60 | J23: =IF(J14=1,Thermostat!$C$3,Thermostat!$C$4) -> 60 | K23: =IF(K14=1,Thermostat!$C$3,Thermostat!$C$4) -> 60 | L23: =IF(L14=1,Thermostat!$C$3,Thermostat!$C$4) -> 70 | M23: =IF(M14=1,Thermostat!$C$3,Thermostat!$C$4) -> 70 | ... AC23: =IF(AC14=1,Thermostat!$C$3,Thermostat!$C$4) -> 60
E24: Sunday | F24: =IF(F15=1,Thermostat!$C$3,Thermostat!$C$4) -> 60 | G24: =IF(G15=1,Thermostat!$C$3,Thermostat!$C$4) -> 60 | H24: =IF(H15=1,Thermostat!$C$3,Thermostat!$C$4) -> 60 | I24: =IF(I15=1,Thermostat!$C$3,Thermostat!$C$4) -> 60 | J24: =IF(J15=1,Thermostat!$C$3,Thermostat!$C$4) -> 60 | K24: =IF(K15=1,Thermostat!$C$3,Thermostat!$C$4) -> 60 | L24: =IF(L15=1,Thermostat!$C$3,Thermostat!$C$4) -> 60 | M24: =IF(M15=1,Thermostat!$C$3,Thermostat!$C$4) -> 60 | ... AC24: =IF(AC15=1,Thermostat!$C$3,Thermostat!$C$4) -> 60
A25: =A19 -> All Zones | B25: =B19 -> Retail | C25: ClgSetpt | D25: T24 2022 - Appendix 5.4B, [Retail] | E25: Weekday | F25: =IF(F13=1,Thermostat!$C$5,Thermostat!$C$6) -> 85 | G25: =IF(G13=1,Thermostat!$C$5,Thermostat!$C$6) -> 85 | H25: =IF(H13=1,Thermostat!$C$5,Thermostat!$C$6) -> 85 | I25: =IF(I13=1,Thermostat!$C$5,Thermostat!$C$6) -> 85 | J25: =IF(J13=1,Thermostat!$C$5,Thermostat!$C$6) -> 85 | K25: =IF(K13=1,Thermostat!$C$5,Thermostat!$C$6) -> 85 | L25: =IF(L13=1,Thermostat!$C$5,Thermostat!$C$6) -> 75 | M25: =IF(M13=1,Thermostat!$C$5,Thermostat!$C$6) -> 75 | ... AC25: =IF(AC13=1,Thermostat!$C$5,Thermostat!$C$6) -> 85
E26: Saturday | F26: =IF(F14=1,Thermostat!$C$5,Thermostat!$C$6) -> 85 | G26: =IF(G14=1,Thermostat!$C$5,Thermostat!$C$6) -> 85 | H26: =IF(H14=1,Thermostat!$C$5,Thermostat!$C$6) -> 85 | I26: =IF(I14=1,Thermostat!$C$5,Thermostat!$C$6) -> 85 | J26: =IF(J14=1,Thermostat!$C$5,Thermostat!$C$6) -> 85 | K26: =IF(K14=1,Thermostat!$C$5,Thermostat!$C$6) -> 85 | L26: =IF(L14=1,Thermostat!$C$5,Thermostat!$C$6) -> 75 | M26: =IF(M14=1,Thermostat!$C$5,Thermostat!$C$6) -> 75 | ... AC26: =IF(AC14=1,Thermostat!$C$5,Thermostat!$C$6) -> 85
E27: Sunday | F27: =IF(F15=1,Thermostat!$C$5,Thermostat!$C$6) -> 85 | G27: =IF(G15=1,Thermostat!$C$5,Thermostat!$C$6) -> 85 | H27: =IF(H15=1,Thermostat!$C$5,Thermostat!$C$6) -> 85 | I27: =IF(I15=1,Thermostat!$C$5,Thermostat!$C$6) -> 85 | J27: =IF(J15=1,Thermostat!$C$5,Thermostat!$C$6) -> 85 | K27: =IF(K15=1,Thermostat!$C$5,Thermostat!$C$6) -> 85 | L27: =IF(L15=1,Thermostat!$C$5,Thermostat!$C$6) -> 85 | M27: =IF(M15=1,Thermostat!$C$5,Thermostat!$C$6) -> 85 | ... AC27: =IF(AC15=1,Thermostat!$C$5,Thermostat!$C$6) -> 85
A28: Storage & Loading Dock
A29: Storage & Loading Dock | B29: Ancillary | C29: Occupancy | D29: T24 2022 - Appendix 5.4B | E29: Weekday | F29: 0 | G29: 0 | H29: 0 | I29: 0 | J29: 0 | K29: 0 | L29: 0 | M29: 0 | N29: 0.2 | O29: 0.4 | P29: 0.5 | Q29: 0.6 | R29: 0.6 | S29: 0.6 | T29: 0.6 | U29: 0.6 | V29: 0.7 | W29: 0.8 | X29: 0.8 | Y29: 0.6 | Z29: 0.3 | AA29: 0 | AB29: 0 | AC29: 0
E30: Saturday | F30: 0 | G30: 0 | H30: 0 | I30: 0 | J30: 0 | K30: 0 | L30: 0 | M30: 0 | N30: 0.3 | O30: 0.6 | P30: 0.8 | Q30: 0.9 | R30: 0.9 | S30: 0.9 | T30: 0.9 | U30: 0.8 | V30: 0.8 | W30: 0.7 | X30: 0.6 | Y30: 0.5 | Z30: 0.3 | AA30: 0 | AB30: 0 | AC30: 0
E31: Sunday | F31: 0 | G31: 0 | H31: 0 | I31: 0 | J31: 0 | K31: 0 | L31: 0 | M31: 0 | N31: 0.2 | O31: 0.5 | P31: 0.7 | Q31: 0.8 | R31: 0.8 | S31: 0.8 | T31: 0.8 | U31: 0.7 | V31: 0.7 | W31: 0.6 | X31: 0.5 | Y31: 0.4 | Z31: 0.2 | AA31: 0 | AB31: 0 | AC31: 0
