Workbook
Name nonparticipating_forecastzone_scale_factor: #REF!
Name nonparticipating_forecastzone_scale_factor: 'Energy Usage'!#REF!
Name Space_Function: Data!$A$2:$A$76

Sheet Notes
A1: Data Sources
A2: Dataset | B2: Dodge 2023
B3: CEUS 2022 | C3: https://www.energy.ca.gov/publications/2023/2022-california-commercial-end-use-survey-ceus-final-report
B4: CBECS 2018 | C4: https://www.eia.gov/consumption/commercial/data/2018/index.php?view=microdata
B5: ComStock 2023 | C5: https://data.openei.org/s3_viewer?bucket=oedi-data-lake&prefix=nrel-pds-building-stock%2Fend-use-load-profiles-for-us-building-stock%2F2023%2Fcomstock_amy2018_release_2%2Fmetadata_and_annual_results%2Fby_state%2Fstate%3DCA%2F
A6: Prototype | C6: https://bees.noresco.com/software2022.html
C7: https://www.energycodes.gov/prototype-building-models#Commercial
B8: DEER prototypes (June 2023) | C8: https://github.com/sound-data/DEER-Prototypes-EnergyPlus
A10: Codes | B10: Title 24, part 6, referred to as T24 (1984, 1992, 2001, 2007, 2013, 2022, 2025)
B11: ASHRAE 90.1 (2022)
B12: CFR Title 10 (2010) | C12: https://www.govinfo.gov/content/pkg/FR-2009-03-23/pdf/FR-2009-03-23.pdf
B13: CFR Title 10 ( 2024) | C13: https://www.govinfo.gov/content/pkg/CFR-2024-title10-vol3/pdf/CFR-2024-title10-vol3-part431-subpartF.pdf
B14: Title 20
A15: Others | B15: ACM (2022)
B16: T24 2022 - Appendix 5.4A and Appendix 5.4B | C16: https://www.energy.ca.gov/publications/2022/2022-nonresidential-and-multifamily-alternative-calculation-method-reference
B17: 2022 Reduced infiltration CASE report | C17: https://title24stakeholders.com/wp-content/uploads/2020/10/2022-T24-Final-CASE-Report_Reduce-Infiltration.pdf
B18: 2019 Outdoor Lighting CASE Report | C18: https://title24stakeholders.com/wp-content/uploads/2016/10/T24-2019-CASE-Study-Results-Report-Outdoor-Sources_Final_with-Attachments.pdf
B19: PNNL 20405, 2010 | C19: https://www.pnnl.gov/main/publications/external/technical_reports/PNNL-20405.pdf
B20: Air leakage Memo, NORESCO, 2025 | C20: https://2050partners.sharepoint.com/:w:/r/sites/CalBEMCollaborativeEfforts/_layouts/15/Doc.aspx?sourcedoc=%7B3BEF8F74-7FAC-44F2-A70C-D76617660066%7D&file=Infiltration_rate_report_14May2025-Short-Version.docx&action=default&mobileredirect=true
B21: Proposed Updates to Equipment Power Densities and Building Schedules for the 2028 Energy Code, referred to as "Plug load and schedules project with CEC, 2025" (Docket Number =25-BSTD-03 & TN=265693) | C21: https://efiling.energy.ca.gov/GetDocument.aspx?tn=265693&DocumentContentId=102545
A42: Background Data [To be deleted prior to publication]
A57: Dodge categories 1, 4, and 101
A62: Store only

Sheet Prototype
A1: NORESCO, Updated October 2025
A2: RetailGrocery
A3: Characteristic | B3: Value | C3: Data Sources
A4: Building Type | B4: Grocery
A5: Building Category | B5: Nonresidential
A6: Vintages | B6: 4 Vintages: Pre-1978 , 1978-1997 ,1998-2007 , 2008-2018 New Construction (2019+) | C6: Based on the vintage bin analysis _ Link | D6: NonRes-Vintage bins-Draft Report-30Nov2023-Final.docx
A7: Shape | C7: PNNL Retail_Standalone
A8: Total Floor Area (ft²) | B8: 50,000 (250 ft x 200 ft) | C8: PNNL Retail_Standalone
A9: Aspect Ratio | B9: 1.25 | C9: Proposed Plan Based on Typical Grocery Store
A10: Number of Floors | B10: 1 | C10: Proposed Plan Based on Typical Grocery Store
A11: Roof type | B11: Flat | C11: Proposed Plan Based on Typical Grocery Store
A12: WWR | B12: 0.0775 | C12: Proposed Plan Based on Typical Grocery Store
A13: Shading Geometry | B13: N/A | C13: Proposed Plan Based on Typical Grocery Store
A14: Floor to floor height (feet) | B14: N/A | C14: Proposed Plan Based on Typical Grocery Store
A15: Floor to ceiling height (feet) | B15: 25 | C15: CPUC (DEER 2023) Grocery prototype
A16: Glazing sill height (feet) | B16: 3 ft (top of the window is 10 ft high with 7 ft high glass) | C16: CPUC (DEER 2023) Grocery prototype
A25: Background Data [To be deleted prior to publication]
A27: Existing Grocery Prototypes
B28: CPUC: Retail_Grocery
A29: Geometry/ Floor plan | D29: Zones of DEER prototype | E29: Floor area | F29: Share
A30: Total floor area (ft²) | B30: 49997 | D30: IndLoadDock | E30: 2850.9 | F30: =E30/$E$36 -> 0.057021467
D31: RefWalkInCool | E31: 1559.65 | F31: =E31/$E$36 -> 0.031194897
D32: RefWalkInFreeze | E32: 812.23 | F32: =E32/$E$36 -> 0.016245588
D33: RefFoodPrep | E33: 1267.01 | F33: =E33/$E$36 -> 0.025341741
D34: Grocery Sale | E34: 40007.28 | F34: =E34/$E$36 -> 0.80019425
D35: Office | E35: 3499.89 | F35: =E35/$E$36 -> 0.070002056
E36: =SUM(E30:E35) -> 49996.96
A39: Other Existing Retail Prototypes
A41: Large size prototype
B42: CEC: Retail_Large | C42: CPUC: Retail_Multistory Large (Rt3) | D42: CPUC: Retail_Single-Story Large (RtL)
A43: Geometry
A44: Total floor area (ft²) | B44: 240000 | C44: =3*40000 -> 120000 | D44: 130502
A46: Medium size prototype
B47: CEC: Retail_Medium | E47: PNNL : Retail_Standalone | F47: PNNL: Retail_Stripmall
A48: Geometry | B48: zoning same as PNNL Stand alone with more skylight
A49: Total floor area (ft²) | B49: 24692 | E49: 24692 | F49: 22500
A51: Small size prototype
B52: CEC: Retail_Stripmall (Mixed use) | C52: CPUC: Retail_Small (RtS)
A53: Geometry
A54: Total floor area (ft²) | B54: 9375 | C54: 8001

Sheet Zones
A1: ="Proposed Layout - "&Prototype!A2 -> Proposed Layout - RetailGrocery | O1: Spaces and Zoning layout - "Rn" indicates which refrigerated cases are in each zone.
A2: Space/Thermal Zone | B2: Space Type | C2: HVAC System Name/AHU Name | D2: Schedule Category | E2: Conditioned (Y/N) | F2: Area Fraction | G2: Area (ft²) | H2: Volume (ft³) | I2: Multipliers | J2: Number of People | K2: People (Persons/1,000 ft²) [T24, 2025,Table 120.1-A] | M2: --- 40 ft --- | N2: --- 70ft --- | O2: N --- 34 ft --- | P2: 250' North Façade | Q2: --- 106 ft ---
A3: Checkout Area | B3: Retail Sales Area (Grocery Sales) | C3: SZVAV HP_Checkout Area_NC PSZAC_Checkout Area_Existing | D3: Retail | E3: Y | F3: =10000/50000 -> 0.2 | G3: 10000 | H3: =G3*Prototype!$B$15 -> 250000 | I3: 1 | J3: =K3*G3/1000 -> 170 | K3: 17 | M3: Back Office | N3: Refr Food Prep | O3: Walk-in Freezers | P3: Loading Dock - Semi-Conditioned | R3: 30 ft
A4: Produce | B4: Retail Sales Area (Grocery Sales) | C4: SZVAV HP_Produce_NC PSZAC_Produce_Existing | D4: Retail | E4: Y | F4: =4400/50000 -> 0.088 | G4: =F4*50000 -> 4400 | H4: =G4*Prototype!$B$15 -> 110000 | I4: 1 | J4: =K4*G4/1000 -> 74.8 | K4: 17 | M4: (1200 sf) | N4: 2100 sf) | O4: Walk-in Coolers | P4: (stock area) | Q4: 3200 sf
A5: General Merch | B5: Retail Sales Area (Grocery Sales) | C5: SZVAV HP_General Merch_NC PSZAC_General Merch_Existing | D5: Retail | E5: Y | F5: =7700/50000 -> 0.154 | G5: =F5*50000 -> 7700 | H5: =G5*Prototype!$B$15 -> 192500 | I5: 1 | J5: =K5*G5/1000 -> 130.9 | K5: 17 | N5: 5000 sf (250'x20') | O5: Meat and Dairy | Q5: R1, R2 | R5: 20'
A6: Frozen | B6: Retail Sales Area (Grocery Sales) | C6: SZVAV HP_Frozen_NC SPSZAC_Frozen_Existing | D6: Retail | E6: Y | F6: =6600/50000 -> 0.132 | G6: =F6*50000 -> 6600 | H6: =G6*Prototype!$B$15 -> 165000 | I6: 1 | J6: =K6*G6/1000 -> 112.2 | K6: 17
A7: Beverage | B7: Retail Sales Area (Grocery Sales) | C7: SZVAV HP_Beverage_NC PSZAC_Beverage_Existing | D7: Retail | E7: Y | F7: =4400/50000 -> 0.088 | G7: =F7*50000 -> 4400 | H7: =G7*Prototype!$B$15 -> 110000 | I7: 1 | J7: =K7*G7/1000 -> 74.8 | K7: 17 | M7: Produce | N7: Grocery - General | O7: Grocery - Frozen | P7: Beverage | Q7: Bakery and Deli
A8: Bakery and Deli | B8: Retail Sales Area (Grocery Sales) | C8: SZVAV HP_Bakery and Deli PSZAC_Bakery and Deli_Existing | D8: Retail | E8: Y | F8: =4400/50000 -> 0.088 | G8: =F8*50000 -> 4400 | H8: =G8*Prototype!$B$15 -> 110000 | I8: 1 | J8: =K8*G8/1000 -> 74.8 | K8: 17
A9: Meat and Dairy | B9: Retail Sales Area (Grocery Sales) | C9: SZVAV HP_Meat and Dairy PSZAC_Meat and Dairy_Existing | D9: Retail | E9: Y | F9: =5000/50000 -> 0.1 | G9: =F9*50000 -> 5000 | H9: =G9*Prototype!$B$15 -> 125000 | I9: 1 | J9: =K9*G9/1000 -> 85 | K9: 17 | R9: 200' totalEastFacade
A10: Back Office | B10: Lounge, Breakroom, or Waiting Area | C10: SZVAV HP_Back Office PSZAC_Back Office_Existing | D10: Retail | E10: Y | F10: =1200/50000 -> 0.024 | G10: =F10*50000 -> 1200 | H10: =G10*Prototype!$B$15 -> 30000 | I10: 1 | J10: =K10*G10/1000 -> 6 | K10: 5 | M10: R4, R7 | O10: R5 | P10: R6, R9 | Q10: R3,R10
A11: Loading Dock EL1 | B11: Storage, Commercial/Industrial (Warehouse) | C11: SZVAV HP_Loading Dock EL1 PSZAC_Loading Dock EL1_Existing | D11: Retail | E11: Y | F11: =3200/50000 -> 0.064 | G11: =F11*50000 -> 3200 | H11: =G11*Prototype!$B$15 -> 80000 | I11: 1 | J11: =K11*G11/1000 -> 0 | K11: 0 | M11: 4400 sf | N11: 7700 sf | O11: 6600 sf | P11: 4400 sf | Q11: 4400 sf | R11: 110'
A12: RefFoodPRep Core | B12: Storage, Commercial/Industrial (Refrigerated) | C12: SZVAV HP_RefFoodPRep Core PSZAC_RefFoodPRep Core_Existing | D12: Retail | E12: Y | F12: =2100/50000 -> 0.042 | G12: 2100 | H12: =G12*Prototype!$B$15 -> 52500 | I12: 1 | J12: =K12*G12/1000 -> 0 | K12: 0 | M12: (40'x110') | N12: (70'x110') | O12: (60'x110') | P12: (40'x110') | Q12: (40'x110')
A13: RefWalkInCool Core | B13: Storage, Commercial/Industrial (Refrigerated) | C13: - | D13: Always On | E13: Y | F13: =500/50000 -> 0.01 | G13: =F13*50000 -> 500 | H13: =G13*Prototype!$B$15 -> 12500 | I13: 1 | J13: =K13*G13/1000 -> 0 | K13: 0
A14: Ref WalkInFreezer Core | B14: Storage, Commercial/Industrial (Refrigerated) | C14: - | D14: Always On | E14: Y | F14: =500/50000 -> 0.01 | G14: =F14*50000 -> 500 | H14: =G14*Prototype!$B$15 -> 12500 | I14: 1 | J14: =K14*G14/1000 -> 0 | K14: 0
A15: Total (12 Thermal zones) | B15: Total (4 Space Types) | E15: Total (12 Conditioned zones) | F15: =SUM(F3:F14) -> 1 | G15: =SUM(G3:G14) -> 50000 | H15: =SUM(H3:H14) -> 1250000 | J15: =SUM(J3:J14) -> 728.5
O21: Cashier area and front of the store | R21: 40'
O22: 10,000 sf (250'*40')
O24: 250' south façade
A25: Background Data [To be deleted prior to publication]
A27: Floorspace-Types-30Oct2024
A28: Retail (CEUS 2022, statewide %)
A29: Conditioned | B29: Unconditioned | E29: Ventilated | M29: Zoning based on ~50,000 sf prototype total floor area assumption. If different area desired, scale zone size accordingly.
A30: 0.8262 | B30: 0.1737 | E30: 0.8344
B31: Assumed semi-heated storage
A38: Fan Power: References
A40: 1. Equipment plan schedules for multiple retail / grocery stores. (Target)
A42: 2. Cross-Reference Summary (AI) Below:
A44: For a rooftop heat pump (RTU) system serving a grocery store, the typical external static pressure (ESP) value depends on the ductwork design and the size of the unit. However, here are the standard industry ranges and a good rule of thumb for modeling or specification purposes:
A48: 🧰 Typical External Static Pressure Ranges
A50: System Size | B50: External Static Pressure (ESP)
A51: 5–10 tons | B51: 0.5 to 1.0 inches w.g. (125–250 Pa)
A52: 10–20 tons | B52: 1.0 to 2.0 inches w.g. (250–500 Pa)
A53: 20–50+ tons | B53: 2.0 to 3.0 inches w.g. (500–750 Pa)
A56: ✅ Typical for Grocery Store RTUs:
A58: A typical value used in grocery store design (especially when using EnergyPlus, Trane Trace, or Carrier HAP) is:
A60: 🔹 ESP = 2.0 inches w.g. (500 Pa)
A62: This accommodates:
A64: Long duct runs
A66: Multiple branches/zones (e.g., deli, produce, checkout)
A68: Filtration (e.g., MERV 8–13)
...

Sheet Envelope
A1: ="Envelope - "&Prototype!A2 -> Envelope - RetailGrocery
A2: Element | B2: Prototype | C2: Assembly Type | D2: Construction | E2: Thermal Properties | F2: Vintage | G2: Selected T24 | H2: Note | I2: CZ1 | J2: CZ2 | K2: CZ3 | L2: CZ4 | M2: CZ5 | N2: CZ6 | O2: CZ7 | P2: CZ8 | Q2: CZ9 | R2: CZ10 | S2: CZ11 | T2: CZ12 | U2: CZ13 | V2: CZ14 | W2: CZ15 | X2: CZ16
A3: External Wall | B3: RetailGrocery | C3: Metal frame Wall | D3: Metal frame + insulation + Gypsum board | E3: U-factor IP | F3: Pre 1978 | G3: N/A | H3: ASHRAE 90.1, 2022, Table A3.3.3.1, 3.5", R-0 | I3: 0.352 | J3: 0.352 | K3: 0.352 | L3: 0.352 | M3: 0.352 | N3: 0.352 | O3: 0.352 | P3: 0.352 | Q3: 0.352 | R3: 0.352 | S3: 0.352 | T3: 0.352 | U3: 0.352 | V3: 0.352 | W3: 0.352 | X3: 0.352
F4: 1978-1997 | G4: 1986 | H4: Package A with Heat Capacity 10.0-14.99 (Btu/F-ft²) - Still are lower than the next vintage! | I4: 0.15082956 | J4: 0.15748031 | K4: 0.15748031 | L4: 0.14367816 | M4: 0.14367816 | N4: 0.21645022 | O4: 0.21645022 | P4: 0.21645022 | Q4: 0.21645022 | R4: 0.21645022 | S4: 0.18621974 | T4: 0.18621974 | U4: 0.18621974 | V4: 0.15873016 | W4: 0.15873016 | X4: 0.15082956
F5: 1998-2007 | G5: 2001 | H5: Table 1-H | I5: 0.182 | J5: 0.182 | K5: 0.189 | L5: 0.189 | M5: 0.189 | N5: 0.189 | O5: 0.189 | P5: 0.189 | Q5: 0.189 | R5: 0.182 | S5: 0.182 | T5: 0.182 | U5: 0.182 | V5: 0.182 | W5: 0.182 | X5: 0.182
F6: 2008-2018 | G6: 2013 | H6: Table 140.3-B | I6: 0.098 | J6: 0.062 | K6: 0.082 | L6: 0.062 | M6: 0.062 | N6: 0.098 | O6: 0.098 | P6: 0.062 | Q6: 0.062 | R6: 0.062 | S6: 0.062 | T6: 0.062 | U6: 0.062 | V6: 0.062 | W6: 0.062 | X6: 0.062
F7: 2019+ | G7: 2025 | H7: Table 140.3-B | I7: 0.06 | J7: 0.055 | K7: 0.071 | L7: 0.055 | M7: 0.055 | N7: 0.06 | O7: 0.06 | P7: 0.055 | Q7: 0.055 | R7: 0.055 | S7: 0.055 | T7: 0.055 | U7: 0.055 | V7: 0.055 | W7: 0.055 | X7: 0.055
A8: Roof | B8: RetailGrocery | C8: Metal decking | D8: Built-up roof: Roof membrane+ insulation+metal decking | E8: U-factor IP | F8: Pre 1978 | G8: N/A | H8: Considering 30 years for roof/ insulation replacement. | I8: 0.057 | J8: 0.057 | K8: 0.057 | L8: 0.057 | M8: 0.057 | N8: 0.078 | O8: 0.078 | P8: 0.078 | Q8: 0.078 | R8: 0.078 | S8: 0.057 | T8: 0.057 | U8: 0.057 | V8: 0.057 | W8: 0.057 | X8: 0.057
F9: 1978-1997 | G9: 1992 | I9: 0.057 | J9: 0.057 | K9: 0.057 | L9: 0.057 | M9: 0.057 | N9: 0.078 | O9: 0.078 | P9: 0.078 | Q9: 0.078 | R9: 0.078 | S9: 0.057 | T9: 0.057 | U9: 0.057 | V9: 0.057 | W9: 0.057 | X9: 0.057
F10: 1998-2007 | G10: 2001 | H10: Table 1-H | I10: 0.057 | J10: 0.057 | K10: 0.057 | L10: 0.057 | M10: 0.057 | N10: 0.078 | O10: 0.078 | P10: 0.078 | Q10: 0.078 | R10: 0.057 | S10: 0.057 | T10: 0.057 | U10: 0.057 | V10: 0.057 | W10: 0.057 | X10: 0.057
F11: 2008-2018 | G11: 2013 | H11: Table 140.3-B | I11: 0.049 | J11: 0.039 | K11: 0.039 | L11: 0.039 | M11: 0.049 | N11: 0.075 | O11: 0.067 | P11: 0.067 | Q11: 0.039 | R11: 0.039 | S11: 0.039 | T11: 0.039 | U11: 0.039 | V11: 0.039 | W11: 0.039 | X11: 0.039
F12: 2019+ | G12: 2025 | H12: Table 140.3-B | I12: 0.028 | J12: 0.028 | K12: 0.028 | L12: 0.028 | M12: 0.028 | N12: 0.047 | O12: 0.047 | P12: 0.047 | Q12: 0.028 | R12: 0.028 | S12: 0.028 | T12: 0.028 | U12: 0.028 | V12: 0.028 | W12: 0.028 | X12: 0.028
A13: Window | B13: RetailGrocery | C13: Fixed windows | D13: CBECS 2018 shows that ~ 50 % of retail that were built before 2000 are single pane | E13: U-factor IP | F13: Pre 1978 | G13: N/A | H13: ASHRAE Handbook of Fundamentals for single pane & T24, 2013 for double pane (50%-50%) | I13: =0.5*1.12+0.5*I16 -> 0.74 | J13: =0.5*1.12+0.5*J16 -> 0.74 | K13: =0.5*1.12+0.5*K16 -> 0.74 | L13: =0.5*1.12+0.5*L16 -> 0.74 | M13: =0.5*1.12+0.5*M16 -> 0.74 | N13: =0.5*1.12+0.5*N16 -> 0.74 | O13: =0.5*1.12+0.5*O16 -> 0.74 | P13: =0.5*1.12+0.5*P16 -> 0.74 | ... X13: =0.5*1.12+0.5*X16 -> 0.74
F14: 1978-1997 | G14: N/A | I14: =I13 -> 0.74 | J14: =J13 -> 0.74 | K14: =K13 -> 0.74 | L14: =L13 -> 0.74 | M14: =M13 -> 0.74 | N14: =N13 -> 0.74 | O14: =O13 -> 0.74 | P14: =P13 -> 0.74 | ... X14: =X13 -> 0.74
D15: Double pane | F15: 1998-2007 | G15: 2001 | H15: Table 1-H | I15: 0.49 | J15: 0.49 | K15: 0.81 | L15: 0.81 | M15: 0.81 | N15: 0.81 | O15: 0.81 | P15: 0.81 | Q15: 0.81 | R15: 0.49 | S15: 0.49 | T15: 0.49 | U15: 0.49 | V15: 0.49 | W15: 0.49 | X15: 0.49
F16: 2008-2018 | G16: 2013 | H16: Table 140.3-B | I16: 0.36 | J16: 0.36 | K16: 0.36 | L16: 0.36 | M16: 0.36 | N16: 0.36 | O16: 0.36 | P16: 0.36 | Q16: 0.36 | R16: 0.36 | S16: 0.36 | T16: 0.36 | U16: 0.36 | V16: 0.36 | W16: 0.36 | X16: 0.36
F17: 2019+ | G17: 2025 | H17: Table 140.3-B | I17: 0.36 | J17: 0.36 | K17: 0.36 | L17: 0.36 | M17: 0.36 | N17: 0.36 | O17: 0.36 | P17: 0.36 | Q17: 0.34 | R17: 0.36 | S17: 0.34 | T17: 0.34 | U17: 0.34 | V17: 0.34 | W17: 0.34 | X17: 0.36
C18: Fixed windows | D18: CBECS 2018 shows that ~ 50 % of retail that were built before 2000 are single pane | E18: SHGC | F18: Pre 1978 | G18: N/A | H18: ASHRAE Handbook of Fundamentals for single pane & T24, 2013 , for double pane (50%-50%) | I18: =0.8*0.5+I21*0.5 -> 0.525 | J18: =0.8*0.5+J21*0.5 -> 0.525 | K18: =0.8*0.5+K21*0.5 -> 0.525 | L18: =0.8*0.5+L21*0.5 -> 0.525 | M18: =0.8*0.5+M21*0.5 -> 0.525 | N18: =0.8*0.5+N21*0.5 -> 0.525 | O18: =0.8*0.5+O21*0.5 -> 0.525 | P18: =0.8*0.5+P21*0.5 -> 0.525 | ... X18: =0.8*0.5+X21*0.5 -> 0.525
F19: 1978-1997 | G19: N/A | I19: =0.8*0.5+I22*0.5 -> 0.525 | J19: =0.8*0.5+J22*0.5 -> 0.525 | K19: =0.8*0.5+K22*0.5 -> 0.525 | L19: =0.8*0.5+L22*0.5 -> 0.525 | M19: =0.8*0.5+M22*0.5 -> 0.525 | N19: =0.8*0.5+N22*0.5 -> 0.525 | O19: =0.8*0.5+O22*0.5 -> 0.525 | P19: =0.8*0.5+P22*0.5 -> 0.525 | ... X19: =0.8*0.5+X22*0.5 -> 0.525
D20: Double pane | F20: 1998-2007 | G20: 2001 | H20: Table 1-H (Non north 0-10%) | I20: 0.49 | J20: 0.47 | K20: 0.61 | L20: 0.61 | M20: 0.61 | N20: 0.61 | O20: 0.61 | P20: 0.61 | Q20: 0.61 | R20: 0.47 | S20: 0.47 | T20: 0.47 | U20: 0.47 | V20: 0.46 | W20: 0.46 | X20: 0.49
F21: 2008-2018 | G21: 2013 | H21: Table 140.3-B | I21: 0.25 | J21: 0.25 | K21: 0.25 | L21: 0.25 | M21: 0.25 | N21: 0.25 | O21: 0.25 | P21: 0.25 | Q21: 0.25 | R21: 0.25 | S21: 0.25 | T21: 0.25 | U21: 0.25 | V21: 0.25 | W21: 0.25 | X21: 0.25
F22: 2019+ | G22: 2025 | H22: Table 140.3-B | I22: 0.25 | J22: 0.25 | K22: 0.25 | L22: 0.25 | M22: 0.25 | N22: 0.25 | O22: 0.25 | P22: 0.25 | Q22: 0.22 | R22: 0.25 | S22: 0.22 | T22: 0.22 | U22: 0.22 | V22: 0.22 | W22: 0.22 | X22: 0.25
E24: Infiltration
F25: Vintage | G25: I_75 (cfm/ft²) 6-sdied Infiltration rate @ 75 pa | H25: Note | I25: I-design (cfm/ft²) (4-sided Infiltration rate at normal pressure) (Design flow rate approach and Flow/Exterior Wall Area calculation method)
E26: Infiltration | F26: Pre 1978 | G26: 1.1 | H26: 2022 CASE report (Table 38) | I26: =(G26*0.112)*$F$47 -> 0.67075556
F27: 1978-1997 | G27: 1.1 | H27: 2022 CASE report (Table 38) | I27: =(G27*0.112)*$F$47 -> 0.67075556
F28: 1998-2007 | G28: 1.1 | H28: 2022 CASE report (Table 38) | I28: =(G28*0.112)*$F$47 -> 0.67075556
F29: 2008-2018 | G29: 1 | H29: 2022 CASE report (Table 38) & T24, part 6, 2008-2016 (Table 140.3-B), Dodge 2023 data | I29: =(G29*0.112)*$F$47 -> 0.60977778
F30: 2019+ | G30: 0.6 (barrier in all CZ) | H30: 2022 CASE report (Table 38) & T24, part 6, 2025 (Table 140.3-B) | I30: =(0.6*0.112)*$F$47 -> 0.36586667
E31: Source: T24 air barrier requirements (all editions) , the standardized infiltration rate reported in the 2022 CASE report, and Dodge 2023 data
E32: Infiltration_rate_report_14May2025-Short-Version.docx
A35: Background Data [To be deleted prior to publication]
A38: Retail Standalone
A39: in.comstock_building_type | B39: Sum of calc.weighted.sqft | C39: %
A40: Mass | B40: 1.5009312e+08 | C40: 0.30478552
A41: SteelFramed | B41: 2.0052046e+08 | C41: 0.40718543
A42: WoodFramed | B42: 1.4184131e+08 | C42: 0.28802905
A43: Grand Total | B43: 4.9245489e+08 | C43: 1
E44: 6 sided area | F44: =(250+200)*2*25+2*250*200 -> 122500
E45: 4 sided area | F45: =(250+200)*25*2 -> 22500
...

Sheet HVAC System
A1: ="HVAC system - "&Prototype!A2 -> HVAC system - RetailGrocery
A2: Vintage | B2: Heating | C2: Cooling | D2: Air Distribution | E2: Source
A3: Existing | B3: PSZAC (furnace) | C3: PSZAC (DX cooling) | D3: PSZAC | E3: CEUS 2022 | F3: PTAC
A4: New Construction | B4: SZVAVHP | C4: SZVAVHP | D4: PSZVAVHP | E4: Title 24, 2025, Engineering judgement
A8: Efficiency of HVAC system (Efficiency is capacity-dependent. The following table provides a general estimate of system efficiency based on what we saw in the existing prototype runs, or assuming cooling load base on rule of thumbs)
A9: Vintage | B9: Upgrade/Installed year | C9: Heating | D9: Cooling | E9: Source
A10: Pre 1978 | B10: 2008 | C10: Thermal Efficiency of 80%; | D10: EER 9 for <65 kBtu/h EER 10.3 for 65-135 kBtu/h EER 9.7 for 135-240 kBtu/h EER 9.5 for 240-760 kBtu/h | E10: 2005 Title 20 Appliance Efficiency Regulations, 2005 T24 Standards, Tables 112-A, 112-B
A11: 1978-1997
A12: 1998-2007
A13: 2008-2018 | B13: 2013 | C13: Thermal Efficiency of 80%; | D13: SEER 13, EER 11.2 for <65 kBtu/h EER 11.2 for 65-135 kBtu/h EER 11 for 135-240 kBtu/h EER 10 for 240-760 kBtu/h | E13: 2013 Title 20 Appliance Efficiency Regulations, 2013 T24 Tables 112-A, 112-B
A14: New Construction | B14: 2025 | C14: SEER 14 for <65 kBtu/h EER 11, COP fed min for 65-135 kBtu/h EER 10.6, COP fed min 135-240 kBtu/h EER 9.5 for >240 kBtu/h | D14: EER 11 for <65 kBtu/h EER 11, COP fed min for 65-135 kBtu/h EER 10.6, COP fed min 135-240 kBtu/h EER 9.5 for >240 kBtu/h | E14: Title 20 Appliance Efficiency Regulations (Tsble 18) , T24, 2025, Tables 110.2-A, 110.2-B
A18: Fan Power
A19: Vintage | B19: Approach | C19: System | D19: Total Static Pressure (TSP) (in w.c.) | E19: Fan Efficiency [ACM 2025] | F19: Fan Motor and Drive Efficiency [ACM 2025, Table 13] | G19: W/cfm [ACM 2025, Table 14 and 15] | H19: Data Source
A20: Existing | B20: PNNL TSP | C20: Zones should be sized so that design airflow is 10,000 cfm or less | D20: 4.00 if VAV< 4,648 cfm 5.58 if VAV ≥ 4,648 cfm | E20: 0.65 | F20: ~0.9 (The full-load efficiency of the motor serving the fan- will be determined based on ACM 2025, Table 13) | H20: ACM 2025, PNNL 2010 TSD
A21: Brake horse power (bhp)=(Supply cfm*TSP in w.c.)/(6356*Fan efficiency)
A22: Fan power (w/cfm) = bhp/motor and drive efficiency *746
A23: New Construction | B23: ACM 2025 | C23: SZVAVHP System <= 10,000 cfm | D23: =G23*E23*F23/746*6356 -> 3.5886692 | E23: 0.65 | F23: 0.9 | G23: 0.72 | H23: ACM 2025
F24: * 0.9 is an average fan efficiency according to ACM 2025, Table 13
A25: Fan total eff (E+ input) = 0.65 x Motor_eff
A26: TSP (E+ input) in w.c. = Motor_eff/746 x (6356 x Fan_eff) x W/cfm
A27: Fan_eff=0.65
A34: Background Data [To be deleted prior to publication]
A38: CEUS 2022 | B38: Heating | E38: Cooling | G38: Air Distribution | H38: Water Heater
B39: Floorspace Heated | C39: Primary Heating | D39: Fuel Type | E39: Floorspace Cooled | F39: Primary Cooling | G39: Primary Air Dis | H39: Fuel Type
C40: The default is the floorspace method unless otherwise specified | F40: The default is the floorspace method unless otherwise specified | G40: The default is the floorspace method unless otherwise specified
A41: Retail | B41: 0.79 | C41: Package System / Heat Pump (80.2%) | D41: Gas (58%) Elec ( 41%) | E41: 0.8 | F41: Package System / Heat Pump (80.2%) | G41: Single Duct CAV (92.1%) | H41: Elec (51%), Gas (34%)
A44: ACM 2025

Sheet Ventilation
A1: ="Outdoor Airflow Rate - "&Prototype!A2 -> Outdoor Airflow Rate - RetailGrocery
A2: Space/Thermal Zone | B2: Number of People | C2: Floor Area (ft²) | D2: cfm/person [T24, 2025, Equation 120.1-F and Table 120.1-A] | E2: cfm/ft² [T24, 2025, Equation 120.1-F and Table 120.1-A] | F2: Required Exhaust Rate [T24, 2025, Table 120.1-B – minimum exhaust rates] | G2: Total cfm Driven by People | H2: Total cfm Driven by Area | I2: Total cfm Driven by Exhaust | J2: Total cfm | K2: Notes
A3: =Zones!A3 -> Checkout Area | B3: =Zones!J3 -> 170 | C3: =Zones!G3 -> 10000 | D3: 15 | E3: 0.2 | F3: 25/50 cfm/unit | G3: =D3*B3 -> 2550 | H3: =E3*C3 -> 2000 | I3: 75 | J3: =MAX(G3:I3) -> 2550
A4: =Zones!A4 -> Produce | B4: =Zones!J4 -> 74.8 | C4: =Zones!G4 -> 4400 | D4: 15 | E4: 0.2 | F4: _ | G4: =D4*B4 -> 1122 | H4: =E4*C4 -> 880 | I4: _ | J4: =MAX(G4:I4) -> 1122
A5: =Zones!A5 -> General Merch | B5: =Zones!J5 -> 130.9 | C5: =Zones!G5 -> 7700 | D5: 15 | E5: 0.2 | F5: _ | G5: =D5*B5 -> 1963.5 | H5: =E5*C5 -> 1540 | I5: _ | J5: =MAX(G5:I5) -> 1963.5
A6: =Zones!A6 -> Frozen | B6: =Zones!J6 -> 112.2 | C6: =Zones!G6 -> 6600 | D6: 15 | E6: 0.2 | F6: _ | G6: =D6*B6 -> 1683 | H6: =E6*C6 -> 1320 | I6: _ | J6: =MAX(G6:I6) -> 1683
A7: =Zones!A7 -> Beverage | B7: =Zones!J7 -> 74.8 | C7: =Zones!G7 -> 4400 | D7: 15 | E7: 0.2 | F7: _ | G7: =D7*B7 -> 1122 | H7: =E7*C7 -> 880 | I7: _ | J7: =MAX(G7:I7) -> 1122
A8: =Zones!A8 -> Bakery and Deli | B8: =Zones!J8 -> 74.8 | C8: =Zones!G8 -> 4400 | D8: 15 | E8: 0.2 | F8: _ | G8: =D8*B8 -> 1122 | H8: =E8*C8 -> 880 | I8: _ | J8: =MAX(G8:I8) -> 1122
A9: =Zones!A9 -> Meat and Dairy | B9: =Zones!J9 -> 85 | C9: =Zones!G9 -> 5000 | D9: 15 | E9: 0.2 | F9: _ | G9: =D9*B9 -> 1275 | H9: =E9*C9 -> 1000 | I9: _ | J9: =MAX(G9:I9) -> 1275
A10: =Zones!A10 -> Back Office | B10: =Zones!J10 -> 6 | C10: =Zones!G10 -> 1200 | D10: 15 | E10: 0.15 | F10: _ | G10: =D10*B10 -> 90 | H10: =E10*C10 -> 180 | I10: _ | J10: =MAX(G10:I10) -> 180
A11: =Zones!A11 -> Loading Dock EL1 | B11: =Zones!J11 -> 0 | C11: =Zones!G11 -> 3200 | D11: 15 | E11: 0.15 | F11: _ | G11: =D11*B11 -> 0 | H11: =E11*C11 -> 480 | I11: _ | J11: =MAX(G11:I11) -> 480
A12: =Zones!A12 -> RefFoodPRep Core | B12: =Zones!J12 -> 0 | C12: =Zones!G12 -> 2100 | G12: =D12*B12 -> 0 | H12: =E12*C12 -> 0 | J12: =MAX(G12:I12) -> 0
A13: =Zones!A13 -> RefWalkInCool Core | B13: =Zones!J13 -> 0 | C13: =Zones!G13 -> 500 | G13: =D13*B13 -> 0 | H13: =E13*C13 -> 0 | J13: =MAX(G13:I13) -> 0
A14: =Zones!A14 -> Ref WalkInFreezer Core | B14: =Zones!J14 -> 0 | C14: =Zones!G14 -> 500 | E14: 0 | F14: _ | G14: =D14*B14 -> 0 | H14: =E14*C14 -> 0 | I14: _ | J14: =MAX(G14:I14) -> 0
A20: Background Data [To be deleted prior to publication]
A22: Currently assuming the entry is not actively ventilated due to doors (and connection to core) providing air.

Sheet Thermostat
A1: ="Thermostat Setpoints - "&Prototype!A2 -> Thermostat Setpoints - RetailGrocery
A2: Setpoint | B2: CZ1 | C2: CZ2 | D2: CZ3 | E2: CZ4 | F2: CZ5 | G2: CZ6 | H2: CZ7 | I2: CZ8 | J2: CZ9 | K2: CZ10 | L2: CZ11 | M2: CZ12 | N2: CZ13 | O2: CZ14 | P2: CZ15 | Q2: CZ16 | R2: Source
A3: Produce Heating Setpoint (F) | B3: 70 | C3: 70 | D3: 70 | E3: 70 | F3: 70 | G3: 70 | H3: 70 | I3: 70 | J3: 70 | K3: 70 | L3: 70 | M3: 70 | N3: 70 | O3: 70 | P3: 70 | Q3: 70 | R3: T24 2022 - Appendix 5.4B, [Retail]
A4: Produce Heating Setback (F) | B4: 60 | C4: 60 | D4: 60 | E4: 60 | F4: 60 | G4: 60 | H4: 60 | I4: 60 | J4: 60 | K4: 60 | L4: 60 | M4: 60 | N4: 60 | O4: 60 | P4: 60 | Q4: 60
A5: Produce Cooling Setpoint (F) | B5: 75 | C5: 75 | D5: 75 | E5: 75 | F5: 75 | G5: 75 | H5: 75 | I5: 75 | J5: 75 | K5: 75 | L5: 75 | M5: 75 | N5: 75 | O5: 75 | P5: 75 | Q5: 75
A6: Produce Cooling Setback (F) | B6: 85 | C6: 85 | D6: 85 | E6: 85 | F6: 85 | G6: 85 | H6: 85 | I6: 85 | J6: 85 | K6: 85 | L6: 85 | M6: 85 | N6: 85 | O6: 85 | P6: 85 | Q6: 85
A7: Grocery - Frozen Heating Setpoint (F) | B7: 65 | C7: 65 | D7: 65 | E7: 65 | F7: 65 | G7: 65 | H7: 65 | I7: 65 | J7: 65 | K7: 65 | L7: 65 | M7: 65 | N7: 65 | O7: 65 | P7: 65 | Q7: 65 | R7: T24 2022 - Appendix 5.4B, [Retail]
A8: Grocery - Frozen Heating Setback (F) | B8: 55 | C8: 55 | D8: 55 | E8: 55 | F8: 55 | G8: 55 | H8: 55 | I8: 55 | J8: 55 | K8: 55 | L8: 55 | M8: 55 | N8: 55 | O8: 55 | P8: 55 | Q8: 55
A9: Grocery - Frozen Cooling Setpoint (F) | B9: 78 | C9: 78 | D9: 78 | E9: 78 | F9: 78 | G9: 78 | H9: 78 | I9: 78 | J9: 78 | K9: 78 | L9: 78 | M9: 78 | N9: 78 | O9: 78 | P9: 78 | Q9: 78
A10: Grocery - Frozen Cooling Setback (F) | B10: 85 | C10: 85 | D10: 85 | E10: 85 | F10: 85 | G10: 85 | H10: 85 | I10: 85 | J10: 85 | K10: 85 | L10: 85 | M10: 85 | N10: 85 | O10: 85 | P10: 85 | Q10: 85
A11: Storage Heating Setpoint (F) | B11: 60 | C11: 60 | D11: 60 | E11: 60 | F11: 60 | G11: 60 | H11: 60 | I11: 60 | J11: 60 | K11: 60 | L11: 60 | M11: 60 | N11: 60 | O11: 60 | P11: 60 | Q11: 60 | R11: T24 2022 - Appendix 5.4B, [Retail]
A12: Storage Heating Setback (F) | B12: 50 | C12: 50 | D12: 50 | E12: 50 | F12: 50 | G12: 50 | H12: 50 | I12: 50 | J12: 50 | K12: 50 | L12: 50 | M12: 50 | N12: 50 | O12: 50 | P12: 50 | Q12: 50
A13: Storage Cooling Setpoint (F) | B13: 80 | C13: 80 | D13: 80 | E13: 80 | F13: 80 | G13: 80 | H13: 80 | I13: 80 | J13: 80 | K13: 80 | L13: 80 | M13: 80 | N13: 80 | O13: 80 | P13: 80 | Q13: 80
A14: Storage Cooling Setback (F) | B14: 90 | C14: 90 | D14: 90 | E14: 90 | F14: 90 | G14: 90 | H14: 90 | I14: 90 | J14: 90 | K14: 90 | L14: 90 | M14: 90 | N14: 90 | O14: 90 | P14: 90 | Q14: 90

Sheet Water Heater
A1: ="Water Heater Summary - "&Prototype!A2 -> Water Heater Summary - RetailGrocery
A2: Vintage | B2: WH Type | C2: Efficiency | D2: Tank Volume (gal) | E2: Tank Loss | F2: Unit | G2: Source
A3: Existing | B3: Electric | C3: 1 | D3: =D4 -> 52.236 | E3: =E4 -> 0.81688491 | F3: % hr | G3: Loss per hour, 10 CFR 431.110(a) Table F-4
A4: New Construction | B4: Electric | C4: 1 | D4: =MAX(50,F29) -> 52.236 | E4: =G29 -> 0.81688491 | F4: % hr
A7: Peak Hot Water Consumption
A8: Space Name | B8: Baseline WH Type [CEUS 2022] | C8: Total Area (ft²) | D8: Number of People | E8: Hot Water Usage Specification (gal/hr per person) [T24, 2022, Appendix 5.4A , sheet: "2022 SpaceFuncData-Input"] | F8: Peak Hot Water Usage (gal/hr) | G8: Peak Hot Water Usage (gal/min)
A9: =Zones!A3 -> Checkout Area | B9: Electric resistance WH | C9: =Zones!G3 -> 10000 | D9: =Zones!J3 -> 170 | E9: 0.18 | F9: =E9*D9 -> 30.6 | G9: =F9/60 -> 0.51
A10: =Zones!A4 -> Produce | B10: Electric resistance WH | C10: =Zones!G4 -> 4400 | D10: =Zones!J4 -> 74.8 | E10: 0.18 | F10: =E10*D10 -> 13.464 | G10: =F10/60 -> 0.2244
A11: =Zones!A5 -> General Merch | B11: Electric resistance WH | C11: =Zones!G5 -> 7700 | D11: =Zones!J5 -> 130.9 | E11: 0.18 | F11: =E11*D11 -> 23.562 | G11: =F11/60 -> 0.3927
A12: =Zones!A6 -> Frozen | B12: Electric resistance WH | C12: =Zones!G6 -> 6600 | D12: =Zones!J6 -> 112.2 | E12: 0.18 | F12: =E12*D12 -> 20.196 | G12: =F12/60 -> 0.3366
A13: =Zones!A7 -> Beverage | B13: Electric resistance WH | C13: =Zones!G7 -> 4400 | D13: =Zones!J7 -> 74.8 | E13: 0.18 | F13: =E13*D13 -> 13.464 | G13: =F13/60 -> 0.2244
A14: =Zones!A8 -> Bakery and Deli | B14: Electric resistance WH | C14: =Zones!G8 -> 4400 | D14: =Zones!J8 -> 74.8 | E14: 0.18 | F14: =E14*D14 -> 13.464 | G14: =F14/60 -> 0.2244
A15: =Zones!A9 -> Meat and Dairy | B15: Electric resistance WH | C15: =Zones!G9 -> 5000 | D15: =Zones!J9 -> 85 | E15: 0.18 | F15: =E15*D15 -> 15.3 | G15: =F15/60 -> 0.255
A16: =Zones!A10 -> Back Office | B16: Electric resistance WH | C16: =Zones!G10 -> 1200 | D16: =Zones!J10 -> 6 | E16: 0.09 | F16: =E16*D16 -> 0.54 | G16: =F16/60 -> 0.009
A17: =Zones!A11 -> Loading Dock EL1 | B17: Electric resistance WH | C17: =Zones!G11 -> 3200 | D17: =Zones!J11 -> 0 | E17: 0.18 | F17: =E17*D17 -> 0 | G17: =F17/60 -> 0
A18: =Zones!A12 -> RefFoodPRep Core | B18: Electric resistance WH | C18: =Zones!G12 -> 2100 | D18: =Zones!J12 -> 0 | E18: 0.18 | F18: =E18*D18 -> 0 | G18: =F18/60 -> 0
A19: =Zones!A13 -> RefWalkInCool Core | B19: Electric resistance WH | C19: =Zones!G13 -> 500 | D19: =Zones!J13 -> 0 | E19: 0.18 | F19: =E19*D19 -> 0 | G19: =F19/60 -> 0
A20: =Zones!A14 -> Ref WalkInFreezer Core | B20: Electric resistance WH | C20: =Zones!G14 -> 500 | D20: =Zones!J14 -> 0 | E20: 0.18 | F20: =E20*D20 -> 0 | G20: =F20/60 -> 0
A21: =Zones!A15 -> Total (12 Thermal zones) | B21: Electric resistance WH | C21: =Zones!G15 -> 50000 | D21: =Zones!J15 -> 728.5 | E21: 0 | F21: =SUM(F9:F20) -> 130.59 | G21: =SUM(G8:G20) -> 2.1765
A27: Water Heater Capacity, Tank Capacity, and Tank Loss
A28: WH Type | B28: Peak Hot Water Usage (gal/hr) | C28: Heat Output (Btu/hr) [ACM, 2025, 5.9.2: Rated capacity section] | D28: WH Capacity (Btu/hr) [ACM, 2025, 5.9.2: Rated capacity section] | E28: Required Energy Input (Btu/hr) | F28: Storage Volume (gal) | G28: Standby Loss | H28: Unit | I28: Off/On Cycle Loss Coefficient to Ambient Temp (Btu/h-F) | J28: Source
A29: Electric resistance WH | B29: =MAX(125,SUM(F9:F20)) -> 130.59 | C29: =B29*(B32-B33)*8.2877*1 -> 86583.259 | D29: =C29*B34 -> 51949.956 | E29: =D29/C3 -> 51949.956 | F29: =B29*0.4*1 -> 52.236 | G29: =0.3+(27/F30) -> 0.81688491 | H29: %hr | I29: =0.0834*G29*F29 -> 3.5587447
A30: Total | B30: =B29 -> 130.59 | C30: =C29 -> 86583.259 | D30: =D29 -> 51949.956 | E30: =E29 -> 51949.956 | F30: =F29 -> 52.236 | G30: =G29 -> 0.81688491
A32: Design supply temperature (F) | B32: 135 | C32: Ref: T24 2022 - Appendix 5.4B
A33: Cold Water supply temperature (F) | B33: 55 | C33: Ref: ACM, 2025, 5.9.2: Rated capacity section
A34: WH system factor | B34: 0.6 | C34: Ref: ACM, 2025, 5.9.2: Rated capacity section
A35: Reheat multiplier | B35: 0.4
A36: * The 0.40 multiplier is a storage sizing factor used to account for the fact that the water heater doesn't need to store the full peak hour demand—it can reheat water during that time. This factor assumes that the heater will recover part of the hot water used during the peak hour, so only 40% of the peak hour demand needs to be stored at any given moment.
A37: **For Gas Water Heater: UA(Btu/h-°F)​=Q˙​SL​ (Btu/h)/ΔT (∘F)​
A38: Ambient temp | B38: 68
A39: Delta T | B39: 67
A40: ** For Electric Water Heater: UA(Btu/h-°F)​= 0.0834 *SL​ (%/hr)*V gal
A51: Background Data [To be deleted prior to publication]
A53: Fuel should match HVAC decision for new construction.

Sheet Interior Lights
A1: ="Interior Lighting - "&Prototype!A2 -> Interior Lighting - RetailGrocery
A2: Space Type | B2: New Construction | E2: Existing
B3: LPD (W/ft²) | C3: Additional LPD for Portable Lighting (W/ft²) | D3: Source | E3: LPD (W/ft²) | F3: Additional LPD for Portable Lighting (W/ft²) | G3: Source
A4: Retail Sales Area (Grocery Sales) | B4: 1 | D4: T24, part 6, 2025, Table 140.6-C (Area category method) | E4: 1.2 | G4: T24, part 6, 2016, Table 140.6-C (Area category method) LPD of "All other spaces" is considered for Back_Space
A5: Lounge, Breakroom, or Waiting Area | B5: 0.55 | E5: 0.9
A6: Storage, Commercial/Industrial (Warehouse) | B6: 0.4 | E6: 0.6
A7: Storage, Commercial/Industrial (Refrigerated) | B7: 0.4 | E7: 0.7
A8: Storage (General) | B8: 0.4 | E8: 0.6
A13: Background Data [To be deleted prior to publication]
A16: 2016
A17: All other area=0.5
A18: Commercial and Industrial Storage Areas (conditioned and unconditioned)=0.6

Sheet Equipment
A1: ="Equipment - "&Prototype!A2 -> Equipment - RetailGrocery
A2: Space Type | B2: Plug Load Power Density (W/ft²) | C2: Source | D2: Note
A3: Retail Sales Area (Grocery Sales) | B3: 0.4 | C3: Plug load and schedules project with CEC, 2025 T24 2022 - Appendix 5.4A: Space Use Data-T24N-2022 | D3: Matches Retail/All Other; PNNL prototype =~0.7; T24 Appendix 5.4A =0.2
A4: Lounge, Breakroom, or Waiting Area | B4: 1
A5: Storage, Commercial/Industrial (Warehouse) | B5: 0.2
A6: Storage, Commercial/Industrial (Refrigerated) | B6: 0.2
A7: Storage (General) | B7: 0.2
A9: Refrigeration Equipment
A11: Tag | B11: Equipment Type | C11: Location | D11: Duty / Type | E11: Dimensions (LxDxH) | F11: Temp Range (°F) | G11: Refrigerant | H11: Compressor Type | I11: Lighting | J11: Defrost Type | K11: Rated Power | L11: Defrost Power | M11: Notes
A12: R1 | B12: Open Multideck Dairy Case | C12: Dairy Aisle | D12: Medium Temp | E12: 12' x 42" x 84" | F12: 34–38 | G12: R-448A | H12: Remote | I12: LED canopy/shelves | J12: Off-cycle | K12: 3500 | M12: Glass end panels, night curtain
A13: R2 | B13: Service Deli Case | C13: Deli Counter | D13: Medium Temp | E13: 8' x 36" x 50" | F13: 36–40 | G13: R-448A | H13: Remote | I13: LED top light | J13: Off-cycle | K13: 2000 | M13: Dual temp option for meats/cheeses
A14: R3 | B14: Meat Self-Service Case | C14: Meat Department | D14: Medium Temp | E14: 12' x 42" x 84" | F14: 28–32 | G14: R-448A | H14: Remote | I14: LED lighting | J14: Off-cycle | K14: 3800 | M14: Gravity coil, low temp
A15: R4 | B15: Produce Case (Refrigerated) | C15: Produce Aisle | D15: Medium Temp | E15: 8' x 42" x 84" | F15: 36–40 | G15: R-448A | H15: Remote | I15: LED canopy light | J15: Off-cycle | K15: 2500 | M15: Mist system optional
A16: R5 | B16: Frozen Food Upright Case | C16: Frozen Foods Aisle | D16: Low Temp | E16: 12' x 36" x 84" | F16: -5 to 0 | G16: R-448A | H16: Remote | I16: LED door lighting | J16: Electric | K16: 4200 | L16: 400 | M16: Glass doors, anti-sweat heaters
A17: R6 | B17: Ice Cream Low-Temp Case | C17: Frozen Foods Aisle | D17: Low Temp | E17: 6' x 36" x 84" | F17: -10 to -20 | G17: R-448A or CO₂ | H17: Remote | I17: LED lighting | J17: Electric | K17: 4500 | L17: 450 | M17: Critical temp holding, tight door seals
A18: R7 | B18: Walk-In Cooler (Produce) | C18: Back of House | D18: Low Temp | E18: 10' x 12' x 8' | F18: 34–38 | G18: R-448A | H18: Remote condensing unit | I18: LED ceiling | J18: Off-cycle | K18: 2800 | M18: Floorless, strip curtain at door
A19: R8 | B19: Walk-In Freezer | C19: Back of House | D19: Low Temp | E19: 10' x 10' x 8' | F19: -10 to -20 | G19: R-448A | H19: Remote condensing unit | I19: LED ceiling | J19: Electric | K19: 4800 | M19: Insulated floor, heated door frame
A20: R9 | B20: Beverage Case | C20: Front of Store | D20: Medium Temp | E20: 8' x 36" x 84" | F20: 34–38 | G20: R-448A | H20: Remote | I20: LED shelves | J20: Off-cycle | K20: 2200 | M20: Reach-in with glass doors
A21: R10 | B21: Grab-n-Go Sandwich Cooler | C21: Front Grab-n-Go Area | D21: Medium Temp | E21: 6' x 30" x 60" | F21: 36–40 | G21: R-448A | H21: Self-contained | I21: LED canopy | J21: Off-cycle | K21: 1500 | M21: Plug-in, casters for mobility
A23: Condenser and Compressor Rack
A24: Tag | B24: Service | C24: Rated Power | D24: Condensing Temp (deg C) | E24: Subcooling Delta (deg C) | F24: Fan Power (W/W) | G24: Notes
A25: C1 | B25: Medium Temp | C25: 35000 | D25: 35 | E25: 25 | F25: 0.1 | G25: Condenser and Compressor Rack
A26: C2 | B26: Low Temp | C26: 28000 | D26: 30 | E26: 25 | F26: 0.1 | G26: Condenser and Compressor Rack
A33: Background Data [To be deleted prior to publication]
F40: ~W PNNL | G40: ft² | H40: W/ft² PNNL | I40: W/ft² CEC
E41: BACK_SPACE | F41: 3000 | G41: 4089.1018 | H41: =F41/G41 -> 0.73365746 | I41: 0.2
E42: CORE_RETAIL | F42: 5000 | G42: 17227.423 | H42: =F42/G42 -> 0.29023494 | I42: 0.4
E43: POINT_OF_SALE | F43: 3000 | G43: 1623.3053 | H43: =F43/G43 -> 1.8480812 | I43: 0.4
E44: FRONT_RETAIL | F44: 500 | G44: 1623.3053 | H44: =F44/G44 -> 0.30801354 | I44: 0.4
A60: it is reasonable to leave the current 5.0 W/ft² assumption in the NMACM for refrigeration loads in Grocery Sales area

Sheet Schedules
A1: ="Schedules - "&Prototype!A2 -> Schedules - RetailGrocery
A2: Zone | B2: Schedule Category | C2: Schedule | D2: Source | E2: Type | F2: Hour
F3: 1 | G3: 2 | H3: 3 | I3: 4 | J3: 5 | K3: 6 | L3: 7 | M3: 8 | N3: 9 | O3: 10 | P3: 11 | Q3: 12 | R3: 13 | S3: 14 | T3: 15 | U3: 16 | V3: 17 | W3: 18 | X3: 19 | Y3: 20 | Z3: 21 | AA3: 22 | AB3: 23 | AC3: 24
A4: All the zones | B4: Retail | C4: Occupancy | D4: T24 2022 - Appendix 5.4B | E4: Weekday | F4: 0 | G4: 0 | H4: 0 | I4: 0 | J4: 0 | K4: 0 | L4: 0 | M4: 0.1 | N4: 0.2 | O4: 0.5 | P4: 0.5 | Q4: 0.7 | R4: 0.7 | S4: 0.7 | T4: 0.7 | U4: 0.8 | V4: 0.7 | W4: 0.5 | X4: 0.5 | Y4: 0.3 | Z4: 0.3 | AA4: 0 | AB4: 0 | AC4: 0
E5: Saturday | F5: 0 | G5: 0 | H5: 0 | I5: 0 | J5: 0 | K5: 0 | L5: 0 | M5: 0.1 | N5: 0.2 | O5: 0.5 | P5: 0.6 | Q5: 0.8 | R5: 0.8 | S5: 0.8 | T5: 0.8 | U5: 0.8 | V5: 0.8 | W5: 0.6 | X5: 0.2 | Y5: 0.2 | Z5: 0.2 | AA5: 0.1 | AB5: 0 | AC5: 0
E6: Sunday | F6: 0 | G6: 0 | H6: 0 | I6: 0 | J6: 0 | K6: 0 | L6: 0 | M6: 0 | N6: 0 | O6: 0.1 | P6: 0.2 | Q6: 0.2 | R6: 0.4 | S6: 0.4 | T6: 0.4 | U6: 0.4 | V6: 0.4 | W6: 0.2 | X6: 0.1 | Y6: 0 | Z6: 0 | AA6: 0 | AB6: 0 | AC6: 0
A7: All the zones | B7: Retail | C7: Lights | D7: T24 2022 - Appendix 5.4B | E7: Weekday | F7: 0.05 | G7: 0.05 | H7: 0.05 | I7: 0.05 | J7: 0.05 | K7: 0.05 | L7: 0.05 | M7: 0.2 | N7: 0.5 | O7: 0.85 | P7: 0.85 | Q7: 0.85 | R7: 0.85 | S7: 0.85 | T7: 0.85 | U7: 0.85 | V7: 0.85 | W7: 0.85 | X7: 0.55 | Y7: 0.55 | Z7: 0.5 | AA7: 0.2 | AB7: 0.05 | AC7: 0.05
E8: Saturday | F8: 0.05 | G8: 0.05 | H8: 0.05 | I8: 0.05 | J8: 0.05 | K8: 0.05 | L8: 0.05 | M8: 0.1 | N8: 0.3 | O8: 0.55 | P8: 0.85 | Q8: 0.85 | R8: 0.85 | S8: 0.85 | T8: 0.85 | U8: 0.85 | V8: 0.85 | W8: 0.85 | X8: 0.5 | Y8: 0.3 | Z8: 0.3 | AA8: 0.1 | AB8: 0.05 | AC8: 0.05
E9: Sunday | F9: 0.05 | G9: 0.05 | H9: 0.05 | I9: 0.05 | J9: 0.05 | K9: 0.05 | L9: 0.05 | M9: 0.05 | N9: 0.1 | O9: 0.1 | P9: 0.4 | Q9: 0.4 | R9: 0.55 | S9: 0.55 | T9: 0.55 | U9: 0.55 | V9: 0.55 | W9: 0.4 | X9: 0.2 | Y9: 0.05 | Z9: 0.05 | AA9: 0.05 | AB9: 0.05 | AC9: 0.05
A10: All the zones | B10: Retail | C10: ElecEquipment | D10: Plug load and schedules project with CEC, 2025 | E10: Weekday | F10: 0.4 | G10: 0.4 | H10: 0.4 | I10: 0.4 | J10: 0.4 | K10: 0.4 | L10: 0.6 | M10: 0.6 | N10: 0.9 | O10: 0.9 | P10: 0.9 | Q10: 0.9 | R10: 0.9 | S10: 0.9 | T10: 0.9 | U10: 0.9 | V10: 0.9 | W10: 0.9 | X10: 0.9 | Y10: 0.6 | Z10: 0.6 | AA10: 0.4 | AB10: 0.4 | AC10: 0.4
E11: Saturday | F11: 0.4 | G11: 0.4 | H11: 0.4 | I11: 0.4 | J11: 0.4 | K11: 0.4 | L11: 0.6 | M11: 0.6 | N11: 0.9 | O11: 0.9 | P11: 0.9 | Q11: 0.9 | R11: 0.9 | S11: 0.9 | T11: 0.9 | U11: 0.9 | V11: 0.9 | W11: 0.9 | X11: 0.9 | Y11: 0.9 | Z11: 0.6 | AA11: 0.6 | AB11: 0.4 | AC11: 0.4
E12: Sunday | F12: 0.4 | G12: 0.4 | H12: 0.4 | I12: 0.4 | J12: 0.4 | K12: 0.4 | L12: 0.4 | M12: 0.4 | N12: 0.6 | O12: 0.6 | P12: 0.6 | Q12: 0.9 | R12: 0.9 | S12: 0.9 | T12: 0.9 | U12: 0.9 | V12: 0.9 | W12: 0.6 | X12: 0.6 | Y12: 0.4 | Z12: 0.4 | AA12: 0.4 | AB12: 0.4 | AC12: 0.4
A13: =A7 -> All the zones | B13: Retail | C13: HVACAvail | D13: T24 2022 - Appendix 5.4B, [Retail] | E13: Weekday | F13: 0 | G13: 0 | H13: 0 | I13: 0 | J13: 0 | K13: 0 | L13: 1 | M13: 1 | N13: 1 | O13: 1 | P13: 1 | Q13: 1 | R13: 1 | S13: 1 | T13: 1 | U13: 1 | V13: 1 | W13: 1 | X13: 1 | Y13: 1 | Z13: 1 | AA13: 0 | AB13: 0 | AC13: 0
E14: Saturday | F14: 0 | G14: 0 | H14: 0 | I14: 0 | J14: 0 | K14: 0 | L14: 1 | M14: 1 | N14: 1 | O14: 1 | P14: 1 | Q14: 1 | R14: 1 | S14: 1 | T14: 1 | U14: 1 | V14: 1 | W14: 1 | X14: 1 | Y14: 1 | Z14: 1 | AA14: 1 | AB14: 0 | AC14: 0
E15: Sunday | F15: 0 | G15: 0 | H15: 0 | I15: 0 | J15: 0 | K15: 0 | L15: 0 | M15: 0 | N15: 1 | O15: 1 | P15: 1 | Q15: 1 | R15: 1 | S15: 1 | T15: 1 | U15: 1 | V15: 1 | W15: 1 | X15: 1 | Y15: 0 | Z15: 0 | AA15: 0 | AB15: 0 | AC15: 0
A16: =A10 -> All the zones | B16: Retail | C16: ServiceHotWater | D16: T24 2022 - Appendix 5.4B, [Retail] | E16: Weekday | F16: 0.04 | G16: 0.05 | H16: 0.05 | I16: 0.04 | J16: 0.04 | K16: 0.04 | L16: 0.04 | M16: 0.15 | N16: 0.23 | O16: 0.32 | P16: 0.41 | Q16: 0.57 | R16: 0.62 | S16: 0.61 | T16: 0.5 | U16: 0.45 | V16: 0.46 | W16: 0.47 | X16: 0.42 | Y16: 0.34 | Z16: 0.33 | AA16: 0.23 | AB16: 0.13 | AC16: 0.08
E17: Saturday | F17: 0.11 | G17: 0.1 | H17: 0.08 | I17: 0.06 | J17: 0.06 | K17: 0.06 | L17: 0.07 | M17: 0.2 | N17: 0.24 | O17: 0.27 | P17: 0.42 | Q17: 0.54 | R17: 0.59 | S17: 0.6 | T17: 0.49 | U17: 0.48 | V17: 0.47 | W17: 0.46 | X17: 0.44 | Y17: 0.36 | Z17: 0.29 | AA17: 0.22 | AB17: 0.16 | AC17: 0.13
E18: Sunday | F18: 0.07 | G18: 0.07 | H18: 0.07 | I18: 0.06 | J18: 0.06 | K18: 0.06 | L18: 0.07 | M18: 0.1 | N18: 0.12 | O18: 0.14 | P18: 0.29 | Q18: 0.31 | R18: 0.36 | S18: 0.36 | T18: 0.34 | U18: 0.35 | V18: 0.37 | W18: 0.34 | X18: 0.25 | Y18: 0.27 | Z18: 0.21 | AA18: 0.16 | AB18: 0.1 | AC18: 0.06
A19: =A13 -> All the zones | B19: Retail | C19: Infiltration | D19: T24 2022 - Appendix 5.4B, [Retail] | E19: Weekday | F19: 1 | G19: 1 | H19: 1 | I19: 1 | J19: 1 | K19: 1 | L19: 0.25 | M19: 0.25 | N19: 0.25 | O19: 0.25 | P19: 0.25 | Q19: 0.25 | R19: 0.25 | S19: 0.25 | T19: 0.25 | U19: 0.25 | V19: 0.25 | W19: 0.25 | X19: 0.25 | Y19: 0.25 | Z19: 0.25 | AA19: 1 | AB19: 1 | AC19: 1
E20: Saturday | F20: 1 | G20: 1 | H20: 1 | I20: 1 | J20: 1 | K20: 1 | L20: 0.25 | M20: 0.25 | N20: 0.25 | O20: 0.25 | P20: 0.25 | Q20: 0.25 | R20: 0.25 | S20: 0.25 | T20: 0.25 | U20: 0.25 | V20: 0.25 | W20: 0.25 | X20: 0.25 | Y20: 0.25 | Z20: 0.25 | AA20: 0.25 | AB20: 1 | AC20: 1
E21: Sunday | F21: 1 | G21: 1 | H21: 1 | I21: 1 | J21: 1 | K21: 1 | L21: 1 | M21: 1 | N21: 0.25 | O21: 0.25 | P21: 0.25 | Q21: 0.25 | R21: 0.25 | S21: 0.25 | T21: 0.25 | U21: 0.25 | V21: 0.25 | W21: 0.25 | X21: 0.25 | Y21: 1 | Z21: 1 | AA21: 1 | AB21: 1 | AC21: 1
A22: =A16 -> All the zones | B22: Retail | C22: Refrigeration | D22: T24 2022 - Appendix 5.4B, [Retail] | E22: Weekday | F22: 0.9 | G22: 0.9 | H22: 0.9 | I22: 0.9 | J22: 0.9 | K22: 0.9 | L22: 0.9 | M22: 0.9 | N22: 0.9 | O22: 0.9 | P22: 0.9 | Q22: 0.9 | R22: 0.9 | S22: 0.9 | T22: 0.9 | U22: 0.9 | V22: 0.9 | W22: 0.9 | X22: 0.9 | Y22: 0.9 | Z22: 0.9 | AA22: 0.9 | AB22: 0.9 | AC22: 0.9
E23: Saturday | F23: 0.9 | G23: 0.9 | H23: 0.9 | I23: 0.9 | J23: 0.9 | K23: 0.9 | L23: 0.9 | M23: 0.9 | N23: 0.9 | O23: 0.9 | P23: 0.9 | Q23: 0.9 | R23: 0.9 | S23: 0.9 | T23: 0.9 | U23: 0.9 | V23: 0.9 | W23: 0.9 | X23: 0.9 | Y23: 0.9 | Z23: 0.9 | AA23: 0.9 | AB23: 0.9 | AC23: 0.9
E24: Sunday | F24: 0.9 | G24: 0.9 | H24: 0.9 | I24: 0.9 | J24: 0.9 | K24: 0.9 | L24: 0.9 | M24: 0.9 | N24: 0.9 | O24: 0.9 | P24: 0.9 | Q24: 0.9 | R24: 0.9 | S24: 0.9 | T24: 0.9 | U24: 0.9 | V24: 0.9 | W24: 0.9 | X24: 0.9 | Y24: 0.9 | Z24: 0.9 | AA24: 0.9 | AB24: 0.9 | AC24: 0.9
A25: =A16 -> All the zones | B25: Retail | C25: HtgSetpt | D25: T24 2022 - Appendix 5.4B, [Retail] | E25: Weekday | F25: 60 | G25: 60 | H25: 60 | I25: 60 | J25: 60 | K25: 60 | L25: 70 | M25: 70 | N25: 70 | O25: 70 | P25: 70 | Q25: 70 | R25: 70 | S25: 70 | T25: 70 | U25: 70 | V25: 70 | W25: 70 | X25: 70 | Y25: 70 | Z25: 70 | AA25: 60 | AB25: 60 | AC25: 60
E26: Saturday | F26: 60 | G26: 60 | H26: 60 | I26: 60 | J26: 60 | K26: 60 | L26: 70 | M26: 70 | N26: 70 | O26: 70 | P26: 70 | Q26: 70 | R26: 70 | S26: 70 | T26: 70 | U26: 70 | V26: 70 | W26: 70 | X26: 70 | Y26: 70 | Z26: 70 | AA26: 70 | AB26: 60 | AC26: 60
E27: Sunday | F27: 60 | G27: 60 | H27: 60 | I27: 60 | J27: 60 | K27: 60 | L27: 60 | M27: 60 | N27: 70 | O27: 70 | P27: 70 | Q27: 70 | R27: 70 | S27: 70 | T27: 70 | U27: 70 | V27: 70 | W27: 70 | X27: 70 | Y27: 60 | Z27: 60 | AA27: 60 | AB27: 60 | AC27: 60
A28: =A19 -> All the zones | B28: Retail | C28: ClgSetpt | D28: T24 2022 - Appendix 5.4B, [Retail] | E28: Weekday | F28: 85 | G28: 85 | H28: 85 | I28: 85 | J28: 85 | K28: 85 | L28: 75 | M28: 75 | N28: 75 | O28: 75 | P28: 75 | Q28: 75 | R28: 75 | S28: 75 | T28: 75 | U28: 75 | V28: 75 | W28: 75 | X28: 75 | Y28: 75 | Z28: 75 | AA28: 85 | AB28: 85 | AC28: 85
E29: Saturday | F29: 85 | G29: 85 | H29: 85 | I29: 85 | J29: 85 | K29: 85 | L29: 75 | M29: 75 | N29: 75 | O29: 75 | P29: 75 | Q29: 75 | R29: 75 | S29: 75 | T29: 75 | U29: 75 | V29: 75 | W29: 75 | X29: 75 | Y29: 75 | Z29: 75 | AA29: 75 | AB29: 85 | AC29: 85
E30: Sunday | F30: 85 | G30: 85 | H30: 85 | I30: 85 | J30: 85 | K30: 85 | L30: 85 | M30: 85 | N30: 75 | O30: 75 | P30: 75 | Q30: 75 | R30: 75 | S30: 75 | T30: 75 | U30: 75 | V30: 75 | W30: 75 | X30: 75 | Y30: 85 | Z30: 85 | AA30: 85 | AB30: 85 | AC30: 85
A31: Zones with Refrigeration systems | B31: Retail | C31: Defrost | E31: Weekday | F31: 0 | G31: 0 | H31: 0 | I31: 0 | J31: 0 | K31: 0 | L31: 0 | M31: 0 | N31: 0 | O31: 0 | P31: 0 | Q31: 1 | R31: 0 | S31: 0 | T31: 0 | U31: 0 | V31: 0 | W31: 0 | X31: 0 | Y31: 0 | Z31: 0 | AA31: 0 | AB31: 0 | AC31: 1 | AE31: Note: The defrost cycle runs for 20 minutes, followed by a roughly 10-minute drip-down period during which the system remains off to allow residual meltwater to drain from the coils into the pan.
E32: Saturday | F32: 0 | G32: 0 | H32: 0 | I32: 0 | J32: 0 | K32: 0 | L32: 0 | M32: 0 | N32: 0 | O32: 0 | P32: 0 | Q32: 1 | R32: 0 | S32: 0 | T32: 0 | U32: 0 | V32: 0 | W32: 0 | X32: 0 | Y32: 0 | Z32: 0 | AA32: 0 | AB32: 0 | AC32: 1
E33: Sunday | F33: 0 | G33: 0 | H33: 0 | I33: 0 | J33: 0 | K33: 0 | L33: 0 | M33: 0 | N33: 0 | O33: 0 | P33: 0 | Q33: 1 | R33: 0 | S33: 0 | T33: 0 | U33: 0 | V33: 0 | W33: 0 | X33: 0 | Y33: 0 | Z33: 0 | AA33: 0 | AB33: 0 | AC33: 1
A34: Zones with Refrigeration systems | B34: Retail | C34: DefrostDripDown | D34: ` | E34: Weekday | F34: 0 | G34: 0 | H34: 0 | I34: 0 | J34: 0 | K34: 0 | L34: 0 | M34: 0 | N34: 0 | O34: 0 | P34: 0 | Q34: 1 | R34: 0 | S34: 0 | T34: 0 | U34: 0 | V34: 0 | W34: 0 | X34: 0 | Y34: 0 | Z34: 0 | AA34: 0 | AB34: 0 | AC34: 1
E35: Saturday | F35: 0 | G35: 0 | H35: 0 | I35: 0 | J35: 0 | K35: 0 | L35: 0 | M35: 0 | N35: 0 | O35: 0 | P35: 0 | Q35: 1 | R35: 0 | S35: 0 | T35: 0 | U35: 0 | V35: 0 | W35: 0 | X35: 0 | Y35: 0 | Z35: 0 | AA35: 0 | AB35: 0 | AC35: 1
E36: Sunday | F36: 0 | G36: 0 | H36: 0 | I36: 0 | J36: 0 | K36: 0 | L36: 0 | M36: 0 | N36: 0 | O36: 0 | P36: 0 | Q36: 1 | R36: 0 | S36: 0 | T36: 0 | U36: 0 | V36: 0 | W36: 0 | X36: 0 | Y36: 0 | Z36: 0 | AA36: 0 | AB36: 0 | AC36: 1
A37: Zones with Refrigeration systems | B37: Retail | C37: CaseRestock | E37: Weekday | F37: 0 | G37: 0 | H37: 0 | I37: 0 | J37: 0 | K37: 0 | L37: 0 | M37: 0 | N37: 0 | O37: 0 | P37: 0 | Q37: 0 | R37: 0 | S37: 0.5 | T37: 0.35 | U37: 0 | V37: 0 | W37: 0 | X37: 0 | Y37: 0 | Z37: 0 | AA37: 0 | AB37: 0 | AC37: 0
E38: Saturday | F38: 0 | G38: 0 | H38: 0 | I38: 0 | J38: 0 | K38: 0 | L38: 0 | M38: 0 | N38: 0 | O38: 0 | P38: 0 | Q38: 0 | R38: 0 | S38: 0.5 | T38: 0.35 | U38: 0 | V38: 0 | W38: 0 | X38: 0 | Y38: 0 | Z38: 0 | AA38: 0 | AB38: 0 | AC38: 0
E39: Sunday | F39: 0 | G39: 0 | H39: 0 | I39: 0 | J39: 0 | K39: 0 | L39: 0 | M39: 0 | N39: 0 | O39: 0 | P39: 0 | Q39: 0 | R39: 0 | S39: 0.5 | T39: 0.35 | U39: 0 | V39: 0 | W39: 0 | X39: 0 | Y39: 0 | Z39: 0 | AA39: 0 | AB39: 0 | AC39: 0
A40: Zones with Refrigeration systems | B40: Retail | C40: CaseCredit | E40: Weekday | F40: 0.2 | G40: 0.2 | H40: 0.2 | I40: 0.2 | J40: 0.2 | K40: 0.2 | L40: 0.2 | M40: 0.6 | N40: 0.6 | O40: 0.6 | P40: 0.6 | Q40: 0.6 | R40: 0.6 | S40: 0.6 | T40: 0.6 | U40: 0.6 | V40: 0.6 | W40: 0.6 | X40: 0.6 | Y40: 0.6 | Z40: 0.6 | AA40: 0.2 | AB40: 0.2 | AC40: 0.2
...

Sheet Ext Lighting
A1: ="Exterior Lighting - "&Prototype!A2 -> Exterior Lighting - RetailGrocery
A2: Motion Controlled Luminaires (W) | B2: Non-motion Controlled Luminaires (W) | C2: Total (W) | D2: Source
A3: =G14 -> 3680.5556 | B3: =G15 -> 1160 | C3: =SUM(A3:B3) -> 4840.5556 | D3: T24, 2022
A6: Exterior Lighting
A7: Items (Assume LZ2) | B7: Assumptions [2019 Outdoor Lighting CASE Report & PNNL 90.1-2010 TSD] | D7: Unit | E7: Lighting Power Allowance [T24, 2025, Table 140.7-A & 140.7-B] | F7: Unit | G7: Exterior lighting power (w)
A8: IWA (Initial Wattage Allowance) | E8: 200 | F8: W | G8: =$E8 -> 200
A9: Parking area | B9: 400 ft² for every parking space 1 parking space per 360 ft² of gross building area | C9: =B21/360*400 -> 55555.556 | D9: (ft²) | E9: 0.019 | F9: (W/ft²) | G9: =$E9*C9 -> 1055.5556
A10: Building Entrance | B10: 1 per 10,000sf footprint | C10: 5 | D10: (count) | E10: 15 | F10: (W/ea) | G10: =E10*C10 -> 75
A11: Hardscape Ornamental Light | B11: 0.1 ft² per 1 ft² of gross bldg area for hardscape ornamental light | C11: =B21*0.1 -> 5000 | D11: (ft²) | E11: 0.007 | F11: (W/ft²) | G11: =E11*C11 -> 35
A12: Building façade | B12: 0.1 W per 1 ft² of facade area Façade Area = Perimeter × 0.5 × 25 ft The 0.5 factor assumes that only half of the perimeter walls are lit. -Formula ia developed based on the 2019 Outdoor Lighting CASE report | C12: =B20*0.5*Prototype!B15 -> 11250 | D12: (ft²) | E12: 0.1 | F12: (W/ft²) | G12: =E12*C12 -> 1125
A13: Sales canopy | B13: 0.1 ft² per ft² of gross bldg area | C13: =(B21/B22)*0.1 -> 5000 | D13: (ft²) | E13: 0.47 | F13: (W/ft²) | G13: =E13*C13 -> 2350
A14: Motion controlled Luminaires | G14: =SUM(G8:G13)-G15 -> 3680.5556
A15: Non-motion-controlled Luminaires | G15: =G11+G12 -> 1160
A16: Total | G16: =G14+G15 -> 4840.5556
A18: *Developed based on 2019 Outdoor Lighting CASE Report
A20: Perimeter | B20: =200*2+250*2 -> 900
A21: Total floor area | B21: 50000
A22: Floors | B22: 1
A26: Background Data [To be deleted prior to publication]

Sheet Energy Usage
A1: CalBEM Energy Consumption - RetailGrocery | I1: National Average (EnergyStar Portfolio Manager) | N1: ="CEUS Energy Consumption - "&"Retail" -> CEUS Energy Consumption - Retail
A2: Prototype | B2: CZ | C2: CalBEM Electricity EUI (KBTU/ft²) | D2: CalBEM Gas EUI (KBTU/ft²) | E2: CalBEM Total EUI (KBTU/ft²) | F2: New Construction Electricity EUI (KBTU/ft²) | G2: New Construction Gas EUI (KBTU/ft²) | H2: New Construction Total EUI (KBTU/ft²) | I2: National Average | J2: Acceptable eRange (25% Higher) | K2: Acceptable Range (25% Lower) | L2: National Average Acceptable Range | M2: Zip code | N2: Prototype | O2: CZ | P2: Total Floorspace (Thousand of ft²) | Q2: CEUS 2022 Electric Energy Intensity (kWh/ft²) | R2: CEUS 2022 Annual Gas Intensity (kWh/ft²) | S2: CEUS 2022 Total EUI (kBtu/ft²) | T2: Acceptable Range (25% Higher) | U2: Acceptable Range (25% Lower) | V2: CEUS 2022 Acceptable Range
A3: HotelSmall | B3: 1 | C3: 36.3 | D3: 46.3 | E3: 82.5 | F3: 50.2 | G3: 0 | H3: 50.2 | I3: 58.5 | J3: =I3*1.25 -> 73.125 | K3: =I3*0.75 -> 43.875 | L3: =J3-K3 -> 29.25 | M3: 95519 | N3: Retail | O3: 1 | P3: 13814 | Q3: 11.1 | R3: 3.06 | S3: =(Q3+R3)*3.412 -> 48.31392 | T3: =S3*1.25 -> 60.3924 | U3: =S3*0.75 -> 36.23544 | V3: =T3-U3 -> 24.15696
B4: 2 | C4: 40.5 | D4: 31.7 | E4: 72.2 | F4: 47.8 | G4: 0 | H4: 47.8 | I4: 68.9 | J4: =I4*1.25 -> 86.125 | K4: =I4*0.75 -> 51.675 | L4: =J4-K4 -> 34.45 | M4: 95403 | O4: 2 | P4: 25239 | Q4: 7.8 | R4: 4.35 | S4: =(Q4+R4)*3.412 -> 41.4558 | T4: =S4*1.25 -> 51.81975 | U4: =S4*0.75 -> 31.09185 | V4: =T4-U4 -> 20.7279
B5: 3 | C5: 36.2 | D5: 25.5 | E5: 61.7 | F5: 43.1 | G5: 0 | H5: 43.1 | I5: 63.5 | J5: =I5*1.25 -> 79.375 | K5: =I5*0.75 -> 47.625 | L5: =J5-K5 -> 31.75 | M5: 94621 | O5: 3 | P5: 88648 | Q5: 10.2 | R5: 3.48 | S5: =(Q5+R5)*3.412 -> 46.67616 | T5: =S5*1.25 -> 58.3452 | U5: =S5*0.75 -> 35.00712 | V5: =T5-U5 -> 23.33808
B6: 4 | C6: 45.6 | D6: 22.5 | E6: 68.1 | F6: 49.8 | G6: 0 | H6: 49.8 | I6: 71.2 | J6: =I6*1.25 -> 89 | K6: =I6*0.75 -> 53.4 | L6: =J6-K6 -> 35.6 | M6: 93446 | O6: 4 | P6: 44551 | Q6: 10.4 | R6: 3.38 | S6: =(Q6+R6)*3.412 -> 47.01736 | T6: =S6*1.25 -> 58.7717 | U6: =S6*0.75 -> 35.26302 | V6: =T6-U6 -> 23.50868
B7: 5 | C7: 33.8 | D7: 14.5 | E7: 48.3 | F7: 42.4 | G7: 0 | H7: 42.4 | I7: 61.8 | J7: =I7*1.25 -> 77.25 | K7: =I7*0.75 -> 46.35 | L7: =J7-K7 -> 30.9 | M7: 93455 | O7: 5 | P7: 9847 | Q7: 9.3 | R7: 4.28 | S7: =(Q7+R7)*3.412 -> 46.33496 | T7: =S7*1.25 -> 57.9187 | U7: =S7*0.75 -> 34.75122 | V7: =T7-U7 -> 23.16748
B8: 6 | C8: 36.1 | D8: 7.8 | E8: 43.9 | F8: 39.2 | G8: 0 | H8: 39.2 | I8: 68.4 | J8: =I8*1.25 -> 85.5 | K8: =I8*0.75 -> 51.3 | L8: =J8-K8 -> 34.2 | M8: 90045 | O8: 6 | P8: 92562 | Q8: 8.6 | R8: 1.35 | S8: =(Q8+R8)*3.412 -> 33.9494 | T8: =S8*1.25 -> 42.43675 | U8: =S8*0.75 -> 25.46205 | V8: =T8-U8 -> 16.9747
B9: 7 | C9: 35.2 | D9: 6 | E9: 41.2 | F9: 38.1 | G9: 0 | H9: 38.1 | I9: 68.4 | J9: =I9*1.25 -> 85.5 | K9: =I9*0.75 -> 51.3 | L9: =J9-K9 -> 34.2 | M9: 92101 | O9: 7 | P9: 63471 | Q9: 10.3 | R9: 0.93 | S9: =(Q9+R9)*3.412 -> 38.31676 | T9: =S9*1.25 -> 47.89595 | U9: =S9*0.75 -> 28.73757 | V9: =T9-U9 -> 19.15838
B10: 8 | C10: 43.4 | D10: 8.2 | E10: 51.6 | F10: 45.8 | G10: 0 | H10: 45.8 | I10: 69.4 | J10: =I10*1.25 -> 86.75 | K10: =I10*0.75 -> 52.05 | L10: =J10-K10 -> 34.7 | M10: 92832 | O10: 8 | P10: 147354 | Q10: 8.5 | R10: 1.31 | S10: =(Q10+R10)*3.412 -> 33.47172 | T10: =S10*1.25 -> 41.83965 | U10: =S10*0.75 -> 25.10379 | V10: =T10-U10 -> 16.73586
B11: 9 | C11: 44.9 | D11: 11.1 | E11: 56 | F11: 46.3 | G11: 0 | H11: 46.3 | I11: 70.1 | J11: =I11*1.25 -> 87.625 | K11: =I11*0.75 -> 52.575 | L11: =J11-K11 -> 35.05 | M11: 91505 | O11: 9 | P11: 212697 | Q11: 9.4 | R11: 1.4 | S11: =(Q11+R11)*3.412 -> 36.8496 | T11: =S11*1.25 -> 46.062 | U11: =S11*0.75 -> 27.6372 | V11: =T11-U11 -> 18.4248
B12: 10 | C12: 46.2 | D12: 10.3 | E12: 56.5 | F12: 48.6 | G12: 0 | H12: 48.6 | I12: 70.6 | J12: =I12*1.25 -> 88.25 | K12: =I12*0.75 -> 52.95 | L12: =J12-K12 -> 35.3 | M12: 92501 | O12: 10 | P12: 149832 | Q12: 9.3 | R12: 1.54 | S12: =(Q12+R12)*3.412 -> 36.98608 | T12: =S12*1.25 -> 46.2326 | U12: =S12*0.75 -> 27.73956 | V12: =T12-U12 -> 18.49304
B13: 11 | C13: 45.9 | D13: 33.9 | E13: 79.7 | F13: 57.5 | G13: 0 | H13: 57.5 | I13: 72.5 | J13: =I13*1.25 -> 90.625 | K13: =I13*0.75 -> 54.375 | L13: =J13-K13 -> 36.25 | M13: 96080 | O13: 11 | P13: 45934 | Q13: 10.6 | R13: 2.72 | S13: =(Q13+R13)*3.412 -> 45.44784 | T13: =S13*1.25 -> 56.8098 | U13: =S13*0.75 -> 34.08588 | V13: =T13-U13 -> 22.72392
B14: 12 | C14: 42.1 | D14: 28.9 | E14: 71 | F14: 51 | G14: 0 | H14: 51 | I14: 71.6 | J14: =I14*1.25 -> 89.5 | K14: =I14*0.75 -> 53.7 | L14: =J14-K14 -> 35.8 | M14: 95822 | O14: 12 | P14: 195816 | Q14: 11 | R14: 2.87 | S14: =(Q14+R14)*3.412 -> 47.32444 | T14: =S14*1.25 -> 59.15555 | U14: =S14*0.75 -> 35.49333 | V14: =T14-U14 -> 23.66222
B15: 13 | C15: 47.3 | D15: 22.3 | E15: 69.6 | F15: 56.8 | G15: 0 | H15: 56.8 | I15: 72.5 | J15: =I15*1.25 -> 90.625 | K15: =I15*0.75 -> 54.375 | L15: =J15-K15 -> 36.25 | M15: 93727 | O15: 13 | P15: 67122 | Q15: 12.4 | R15: 2.61 | S15: =(Q15+R15)*3.412 -> 51.21412 | T15: =S15*1.25 -> 64.01765 | U15: =S15*0.75 -> 38.41059 | V15: =T15-U15 -> 25.60706
... B18: 16 | C18: 49.3 | D18: 58.4 | E18: 107.7 | F18: 69.4 | G18: 0 | H18: 69.4 | I18: 71.5 | J18: =I18*1.25 -> 89.375 | K18: =I18*0.75 -> 53.625 | L18: =J18-K18 -> 35.75 | M18: 95726 | O18: 16 | P18: 149464 | Q18: 9.6 | R18: 1.56 | S18: =(Q18+R18)*3.412 -> 38.07792 | T18: =S18*1.25 -> 47.5974 | U18: =S18*0.75 -> 28.55844 | V18: =T18-U18 -> 19.03896
N20: Ref: CEUS 2022 Report
N21: And converted FZ level data to CZ level
N22: CEUS has only one category for all the retails
A64: Background Data [To be deleted prior to publication]
I66: Using Supermarket/Grocery Store use type
H67: Alternative One | I67: 130 | J67: Alternative Two | K67: 68.7
I68: 139 | K68: 80.3
I69: 135 | K69: 74.2
I70: 141.5 | K70: 82.8
I71: 133.6 | K71: 72.3
I72: 139.1 | K72: 79.7 | P72: CEUS 2022 Electric Energy Intensity (kWh/ft²) | Q72: CEUS 2022 Annual Gas Intensity (kWh/ft²)
I73: 139.1 | K73: 79.7 | P73: Food Store
I74: 139.9 | K74: 80.8 | P74: Electricity Usage (kWh/SqF) | Q74: Gas Usage (kWh/SqF)
I75: 140.4 | K75: 81.5 | P75: 40.9 | Q75: 16.31 | S75: =(P75+Q75)*3.412 -> 195.20052
I76: 140.9 | K76: 82.1 | P76: 39.8 | Q76: 13.63
I77: 142.5 | K77: 84.2 | P77: 38 | Q77: 13.46
I78: 141.7 | K78: 83.2 | P78: 37.6 | Q78: 13.59
I79: 142.4 | K79: 84.2 | P79: 41.2 | Q79: 12.4
I80: 142.7 | K80: 84.5 | P80: 33.4 | Q80: 15.7
I81: 140.8 | K81: 82 | P81: 39.4 | Q81: 17.66
I82: 141.6 | K82: 83.1 | P82: 34.7 | Q82: 16.15
P83: 33.2 | Q83: 12.45
P84: 38.8 | Q84: 27.69
I85: CA Climate Zone | J85: Climate Character (short) | K85: HDD vs CDD Balance | L85: HVAC Dominance | P85: 39.1 | Q85: 15.49
...

Sheet Weights
A1: ="% of Floor Area per CZ and Vintage Bin - "&"Retail" -> % of Floor Area per CZ and Vintage Bin - Retail | J1: ="% of Floor Area per CZ and Vintage Bin - "&"Retail" -> % of Floor Area per CZ and Vintage Bin - Retail
A2: Prototype | B2: CZ | C2: Vintage Bin | J2: Prototype | K2: Vintage Bin | L2: CZ
C3: Pre-1978 | D3: 1978-1997 | E3: 1998-2007 | F3: 2008-2018 | G3: Not available | L3: 1 | M3: 2 | N3: 3 | O3: 4 | P3: 5 | Q3: 6 | R3: 7 | S3: 8 | T3: 9 | U3: 10 | V3: 11 | W3: 12 | X3: 13 | Y3: 14 | Z3: 15 | AA3: 16
A4: Retail | B4: 1 | C4: 0.312 | D4: 0.283 | E4: 0.162 | F4: 0.086 | G4: 0.157 | H4: =SUM(C4:G4) -> 1 | J4: Retail | K4: Pre-1978 | L4: 0.010318539 | M4: 0.029366621 | N4: 0.084695091 | O4: 0.044778878 | P4: 0.00512302 | Q4: 0.092452429 | R4: 0.039592212 | S4: 0.15153346 | T4: 0.22773636 | U4: 0.043801296 | V4: 0.029412305 | W4: 0.12324788 | X4: 0.034112319 | Y4: 0.017624405 | Z4: 0.022383301 | AA4: 0.043821883 | AB4: =SUM(L4:AA4) -> 1
B5: 2 | C5: 0.486 | D5: 0.292 | E5: 0.068 | F5: 0.026 | G5: 0.128 | H5: =SUM(C5:G5) -> 1 | K5: 1978-1997 | L5: 0.009654311 | M5: 0.018200183 | N5: 0.048977778 | O5: 0.023912375 | P5: 0.006523299 | Q5: 0.061209764 | R5: 0.0671703 | S5: 0.088770272 | T5: 0.13600272 | U5: 0.12822097 | V5: 0.028728247 | W5: 0.13558819 | X5: 0.044256912 | Y5: 0.02919616 | Z5: 0.055827032 | AA5: 0.11776148 | AB5: =SUM(L5:AA5) -> 1
