Workbook
Name nonparticipating_forecastzone_scale_factor: '[1]Energy Usage'!#REF!
Name nonparticipating_forecastzone_scale_factor: #REF!
Name nonparticipating_forecastzone_scale_factor: 'Energy Usage'!#REF!
Name Space_Function: Data!$A$2:$A$76

Sheet Notes
A1: Data Sources
A2: Dataset | B2: Dodge 2023
B3: Commercial End-Use Survey (CEUS) 2022 | C3: https://www.energy.ca.gov/publications/2023/2022-california-commercial-end-use-survey-ceus-final-report
B4: Lawrence Berkeley National Laboratory (LBNL) / U.S. Department of Energy (DOE), 2019
A6: Prototype | B6: California Energy Commission (CEC) Laboratory prototype (CBECC 2022.3.1) | C6: https://bees.noresco.com/software2022.html
B7: Database for Energy Efficient Resources (DEER) Manufacturing-BioTech prototype (June 2024) | C7: https://github.com/sound-data/DEER-Prototypes-EnergyPlus
A9: Codes | B9: Title 24, part 6, referred to as T24 (1984, 1992,1998, 2001, 2005, 2008, 2013, 2016,2019, 2022, 2025) | C9: https://www.energy.ca.gov/publications/2025/2025-building-energy-efficiency-standards-residential-and-nonresidential | D9: 2025
C10: https://codes.iccsafe.org/codes/united-states/california | D10: 2010+
B11: American Society of Heating, Refrigerating and Air-Conditioning Engineers (ASHRAE) 90.1 (2022) | C11: https://www.ashrae.org/technical-resources/standards-and-guidelines/read-only-versions-of-ashrae-standards
B12: Code of Federal Regulations (CFR) Title 10 (2008, 2010) | C12: https://www.govinfo.gov/content/pkg/FR-2009-03-23/pdf/FR-2009-03-23.pdf
B13: CFR Title 10 (2025) | C13: https://www.ecfr.gov/current/title-10
A15: Other | B15: Alternative Calculation Method (ACM) (2022) | C15: https://www.energy.ca.gov/publications/2022/2022-nonresidential-and-multifamily-alternative-calculation-method-reference
B16: Nonres ACM 2022, Appendix 5.4A and Appendix 5.4B | C16: https://www.energy.ca.gov/publications/2022/2022-nonresidential-and-multifamily-alternative-calculation-method-reference
B17: 2022 Reduced infiltration Codes and Standards Enhancement (CASE) report | C17: https://title24stakeholders.com/wp-content/uploads/2020/10/2022-T24-Final-CASE-Report_Reduce-Infiltration.pdf
B18: 2019 Outdoor Lighting CASE Report | C18: https://title24stakeholders.com/wp-content/uploads/2016/10/T24-2019-CASE-Study-Results-Report-Outdoor-Sources_Final_with-Attachments.pdf
B19: 2019 High Efficiency Fume Hoods in Laboratory Spaces CASE Report | C19: https://title24stakeholders.com/wp-content/uploads/2017/09/2019-T24-CASE-Report_Fume-Hoods_Final_September-2017.pdf?
B20: PNNL 20405, 2011 | C20: https://www.pnnl.gov/main/publications/external/technical_reports/PNNL-20405.pdf
B21: Air leakage Memo, NORESCO, 2025 | C21: Infiltration_rate_report_14May2025-Short-Version.docx
B22: Proposed Updates to Equipment Power Densities and Building Schedules for the 2028 Energy Code, referred to as "Plug load and schedules project with CEC, 2025" (Docket Number =25-BSTD-03 & TN=265693) | C22: https://efiling.energy.ca.gov/GetDocument.aspx?tn=265693&DocumentContentId=102545
B23: ASHRAE/AIHA/ACS, Classification of Laboratory Ventilation Design Levels | C23: https://www.ashrae.org/File%20Library/Technical%20Resources/Free%20Resources/Publications/ClassificationOfLabVentDesLevels.pdf
B24: ANSI/ASSP Z9.5-2022, Laboratory Ventilation | C24: https://webstore.ansi.org/standards/asse/ansiasspz92022
B25: U.S. DOE Federal Energy Management Program, Right-Sizing Laboratory Equipment Loads. | C25: https://www.osti.gov/servlets/purl/922847
B26: I2SL Laboratory Benchmarking Tool (successor to the Labs21 Energy Benchmarking Tool) | C26: https://lbt.i2sl.org/
B27: Commercial Building Prototypes Based on ANSI/ASHRAE/IES Standard 90.1-2019 Appendix G PRM: Technical Support Document | C27: https://www.pnnl.gov/main/publications/external/technical_reports/PNNL-32815.pdf
... B36: Grainger electric tank water heaters | C36: https://www.grainger.com/category/plumbing/water-heaters/electric-tank-water-heaters
A41: Construction Rate
A53: Four vintage bins (Pre-1978, 1978-1997, 1998-2007, 2008-2018) plus New Construction (2019+) are derived from the California nonresidential construction-rate analysis shown in the Construction Rate block above, binned at the Title 24 code-cycle boundaries that changed the governing envelope and equipment requirements.
A54: Notes
A55: 2025 T24 | B55: Laboratory is a space or room where hazardous materials are used for activities such as testing, analysis, instruction, research, or developmental activities. Laboratory Suite is a Group L occupancy space within a building or structure, which may include multiple laboratories, offices, storage, equipment rooms or similar support functions. Laboratory, Scientific Area is a room or area where research, experiments, and measurement in medical and physical sciences are performed requiring examination of fine details. The area may include workbenches, countertops, scientific instruments, and associated floor spaces. Scientific laboratory does not refer to film, computer, and other laboratories where scientific experiments are not performed.
A56: Laboratory type and ventilation design level | B56: The prototype represents a WET RESEARCH LABORATORY BUILDING (medical / biological research), operating at Laboratory Ventilation Design Level LVDL-2 per ASHRAE/AIHA/ACS, Classification of Laboratory Ventilation Design Levels (2018). Lab space is classified as "Laboratory, Scientific" under the T24 2025 definition quoted above. Declaring the LVDL - not only the lab type - is what fixes the downstream assumptions: minimum air change rates, occupied/unoccupied setback, fume hood face velocity and sash control, and exhaust discharge. Pharmaceutical / biopharma GMP production facilities are EXCLUDED from this prototype: they fall outside the OSHA 29 CFR 1910.1450(b) definition of "laboratory scale", which expressly excludes production-scale work, and cleanroom classification, process loads and 24/7 operation would reopen ventilation, internal loads, schedules and humidity control. PENDING CONFIRMATION - this decision governs the Ventilation tab.
A57: Wet laboratory Definition | B57: A WET LABORATORY is a space where chemicals, drugs, or other material or biological matter are tested and analyzed, requiring water, direct ventilation and specialized piped utilities (WBDG, Space Types: Laboratory - Wet). The NIH Design Requirements Manual makes the same distinction operationally: wet laboratories handle liquid solutions, biological materials and chemicals and are fitted with bench space, hand-wash and work sinks, chemical fume hoods and/or biological safety cabinets, and piped services such as DI or RO water and laboratory gases; DRY laboratories are computational, bioinformatics, electronics and instrumentation spaces and require no wet services. MIT Design Standards T10 characterises wet laboratories as spaces that use and store chemical and biological materials, equipped with sinks or fume hoods, specialized local exhaust ventilation (SLEV) and containment equipment such as biological safety cabinets. All three are consistent with the OSHA definition of laboratory scale at 29 CFR 1910.1450(b) - work with hazardous chemicals on a NON-PRODUCTION basis, in containers that can be handled safely by one person.
A58: Laboratory types the prototype does NOT represent (LAB4) | B58: Laboratory is not a single building type. MIT Design Standards T10 lists SEVENTEEN laboratory types (Baseline; Life Science/Bio; Optical; Engineering/Physical Sciences; Maker Space/Machine Shop; Chemistry; BL1; BL2; BL2+; BL3; Radioactive Material; Radiation Producing; Clinical Lab; Animal/Survival Surgery; ABSL-1; ABSL-2; ABSL-2+). The prototype is proposed to represent a general WET RESEARCH laboratory (medical/biological, broadly MIT types Baseline and Life Science/Bio) at LVDL-2. It does NOT represent: DRY/COMPUTATIONAL laboratories (no hoods or piped services; office-like ventilation, load-driven); TEACHING laboratories (very high hood density per unit area but low occupied hours); CLINICAL and DIAGNOSTIC laboratories (biological safety cabinets rather than chemical fume hoods; ventilation governed by ASHRAE 170 and the CMC rather than by hood demand); VIVARIA and animal holding (high fixed air change rates with tight temperature and humidity control, 24/7); HIGH-CONTAINMENT laboratories at BSL-3 and above (single-pass air, sealed envelope, HEPA filtration, deeper interstitial space); and PHARMACEUTICAL/BIOPHARMA GMP PRODUCTION (cleanroom classification, process loads, 24/7 operation), which is excluded because it falls outside the OSHA 29 CFR 1910.1450(b) laboratory-scale definition. Each of these carries a materially different ventilation rate, exhaust configuration, internal load and schedule, so a prototype cannot represent them all.

Sheet Prototype
A1: NORESCO, Updated September 2026
A2: Laboratory
A3: Characteristic | B3: Value | C3: Data Sources
A4: Building Type | B4: Laboratory
A5: Building Category | B5: Nonresidential
A6: Version | B6: v2-0
A7: Vintages | B7: 4 Vintages: Pre-1978 , 1978-1997 ,1998-2007 , 2008-2018 New Construction (2019+) | C7: Based on the vintage bin analysis. A summary of the findings is presented in the following paper, with a link provided in the Notes tab: Yousefi, F., Athalye, R. (2025). “Determining Vintage Bins for Prototype Development: An Analysis of California Commercial Buildings.” ASHRAE Annual Conference.
A8: Shape | C8: Assume rectangular shape; supported by CBECS, CEC, and LBNL/DOE. The windows have been updated from ribbon style to punched openings.
A9: Total Floor Area (ft²) | B9: 53627 | C9: Based on CEC Lab prototype, which is based on the Medium Office prototype. External features, such as number of floors, conditioned floor area, WWR, etc., are identical to Medium Office prototype. Lab buildings are similar to office buildings in their characteristics. They are outfitted for lab purposes, such as with exhaust hoods, etc., though they are designed to be repurposed as office space. This prototype is based on the Medium Office prototype geometry. The program/spaces, people, ventilation, and other loads are those for a lab building.
A10: Aspect Ratio | B10: 1.5
A11: Number of Floors | B11: 3
A12: Roof type | B12: Flat
A13: WWR | B13: 0.33
A14: Shading Geometry | B14: No Shades
A15: Floor to floor height (feet) | B15: 15 | C15: LBNL/DOE prototype
A16: Floor to ceiling height (feet) | B16: 9 (6 ft above-ceiling plenum)
A17: Glazing sill height (feet) | B17: 3.35 ft (top of the window is 7.64 ft high with 4.29 ft high glass) | C17: Based on CEC Lab prototype
A19: Laboratory Program Metrics
A20: Laboratory, Scientific area (ft2) | B20: 28800 | C20: 53.9% of conditioned area. Eleven laboratory spaces: the core on all three floors, plus the north, west, east, south and conference spaces on FloorM and the north, south and conference spaces on FloorT.
A21: Office area (ft2) | B21: 11537 | C21: 21.7% of conditioned area - office area (10,036 ft2), conference (1,112), lobby (1,059) and lounge/breakroom (2,814).
A22: Lab support area (ft2) | B22: =B23-B21-B20 -> 13290 | C22: 24.4% of conditioned area - corridor (4,816 ft2), storage (2,949), stairwell (1,983), restrooms (1,932), mechanical/electrical (1,071) and IT room (537). The previous layout had NO support space at all.
A23: Total floor area (ft2) | B23: 53627 | C23: Conditioned total. Excludes the three plenums at 17,876 ft2 each. The IDF geometry gives 53,633 ft2
A24: Fume hood count | B24: 90 | C24: At 18.6 ft of hood per 1,000 ft2 of laboratory area (CEC TN 222188 Table 29) applied to 28,800 ft2 of laboratory space: 536 ft of hood, about 90 six-foot hoods. T
A28: Above grade wall area (ft²) | B28: 21287.463
A29: Gross wall area (ft²) | B29: 21287.463
A30: Roof area (ft²) | B30: 17875.949
A31: Underground Gross Wall Area (ft²) | B31: 0

Sheet Zones
A1: ="Proposed Layout - "&Prototype!B4 -> Proposed Layout - Laboratory
A2: Building | B2: Space/Thermal Zone | C2: Space Type Primarily from [T24, 2022 Appendix 5.4A] - See Notes column | D2: HVAC System Name (New Construction) | E2: Schedule Category | F2: Conditioned (Y/N) | G2: Area Fraction | H2: Area (ft²) | I2: Volume (ft³) | J2: Multipliers | K2: Number of People | L2: People (Persons/1,000 ft²) [T24, 2025,Table 120.1-A] | M2: Notes
A3: Laboratory | B3: Lab_Core_FloorG | C3: Laboratory, Scientific | D3: BaseAirSys14 | E3: Lab | F3: Yes | G3: =H3/$H$57 -> 0.079866485 | H3: 4283 | I3: 38547 | J3: 1 | K3: =ROUND(H3*L3/1000,0) -> 21 | L3: 5 | M3: Laboratory Space Occupancy level Derived from the LBNL/DOE Prototype
A4: Laboratory | B4: Lab_N_FloorG | C4: Laboratory, Scientific | D4: BaseAirSys14-2 | E4: Lab | F4: Yes | G4: =H4/$H$57 -> 0.042851549 | H4: 2298 | I4: 20682 | J4: 1 | K4: =ROUND(H4*L4/1000,0) -> 11 | L4: 5
A5: Laboratory | B5: Enclosed_Office_W_FloorG | C5: Office Area (>250 square feet) | D5: BaseAirSys5-1 | E5: Office | F5: Yes | G5: =H5/$H$57 -> 0.030544315 | H5: 1638 | I5: 14741 | J5: 1 | K5: =ROUND(H5*L5/1000,0) -> 8 | L5: 5
A6: Laboratory | B6: Enclosed_Office_E_FloorG | C6: Office Area (>250 square feet) | D6: BaseAirSys5-1 | E6: Office | F6: Yes | G6: =H6/$H$57 -> 0.030544315 | H6: 1638 | I6: 14741 | J6: 1 | K6: =ROUND(H6*L6/1000,0) -> 8 | L6: 5
A7: Laboratory | B7: Lab_S_FloorG | C7: Laboratory, Scientific | D7: BaseAirSys14-3 | E7: Lab | F7: Yes | G7: =H7/$H$57 -> 0.022115725 | H7: 1186 | I7: 10676 | J7: 1 | K7: =ROUND(H7*L7/1000,0) -> 6 | L7: 5
A8: Laboratory | B8: Conference_FloorG | C8: Convention, Conference, Multipurpose and Meeting Area | D8: BaseAirSys5-1 | E8: Office | F8: Yes | G8: =H8/$H$57 -> 0.020735823 | H8: 1112 | I8: 10006 | J8: 1 | K8: =ROUND(H8*L8/1000,0) -> 37 | L8: 33
A9: Laboratory | B9: Lobby_FloorG | C9: Lobby, Main Entry | D9: BaseAirSys5-1 | E9: Office | F9: Yes | G9: =H9/$H$57 -> 0.019747515 | H9: 1059 | I9: 9533 | J9: 1 | K9: =ROUND(H9*L9/1000,0) -> 11 | L9: 10
A10: Laboratory | B10: Storage_FloorG | C10: Storage (General) | D10: BaseAirSys5-1 | E10: Ancillary | F10: Yes | G10: =H10/$H$57 -> 0.018330319 | H10: 983 | I10: 8848 | J10: 1 | K10: =ROUND(H10*L10/1000,0) -> 0 | L10: 0
A11: Laboratory | B11: Mechanical/Electrical_FloorG | C11: Electrical, Mechanical, Telephone Rooms | D11: BaseAirSys5-1 | E11: Ancillary | F11: Yes | G11: =H11/$H$57 -> 0.0066570944 | H11: 357 | I11: 3216 | J11: 1 | K11: =ROUND(H11*L11/1000,0) -> 0 | L11: 0
A12: Laboratory | B12: IT-Room_FloorG | C12: IT Room (EPD 12) | D12: BaseAirSys5-1 | E12: Data | F12: Yes | G12: =H12/$H$57 -> 0.0033378708 | H12: 179 | I12: 1610 | J12: 1 | K12: =ROUND(H12*L12/1000,0) -> 0 | L12: 1.5
A13: Laboratory | B13: Restroom_FloorG | C13: Restrooms | D13: BaseAirSys5-1 | E13: Office | F13: Yes | G13: =H13/$H$57 -> 0.012008876 | H13: 644 | I13: 5792 | J13: 1 | K13: =ROUND(H13*L13/1000,0) -> 0 | L13: 0
A14: Laboratory | B14: BreakRoom/Kitchenette_FloorG | C14: Lounge, Breakroom, or Waiting Area | D14: BaseAirSys5-1 | E14: Office | F14: Yes | G14: =H14/$H$57 -> 0.004326179 | H14: 232 | I14: 2091 | J14: 1 | K14: =ROUND(H14*L14/1000,0) -> 8 | L14: 33
A15: Laboratory | B15: Stairway_FloorG | C15: Stairwell | D15: BaseAirSys5-1 | E15: Ancillary | F15: Yes | G15: =H15/$H$57 -> 0.012325881 | H15: 661 | I15: 5953 | J15: 1 | K15: =ROUND(H15*L15/1000,0) -> 0 | L15: 0
... A19: Laboratory | B19: Corridor_S_FloorG | C19: Corridor Area | D19: BaseAirSys5-1 | E19: Office | F19: Yes | G19: =H19/$H$57 -> 0.0093796036 | H19: 503 | I19: 4527 | J19: 1 | K19: =ROUND(H19*L19/1000,0) -> 3 | L19: 5
A20: Laboratory | B20: Plenum_FloorG | C20: Plenum | D20: n/a | E20: Office | F20: No | H20: 17876 | I20: 71504 | J20: 1 | K20: =ROUND(H20*L20/1000,0) -> 0 | L20: 0
A21: Laboratory | B21: Lab_Core_FloorM | C21: Laboratory, Scientific | D21: BaseAirSys14-4 | E21: Lab | F21: Yes | G21: =H21/$H$57 -> 0.079866485 | H21: 4283 | I21: 38547 | J21: 1 | K21: =ROUND(H21*L21/1000,0) -> 21 | L21: 5 | P21: Ground floor (FloorG) | T21: Middle and top floors (FloorM and FloorT)
A22: Laboratory | B22: Lab_N_FloorM | C22: Laboratory, Scientific | D22: BaseAirSys14-5 | E22: Lab | F22: Yes | G22: =H22/$H$57 -> 0.042851549 | H22: 2298 | I22: 20682 | J22: 1 | K22: =ROUND(H22*L22/1000,0) -> 11 | L22: 5
A23: Laboratory | B23: Lab_W_FloorM | C23: Laboratory, Scientific | D23: BaseAirSys14-6 | E23: Lab | F23: Yes | G23: =H23/$H$57 -> 0.030544315 | H23: 1638 | I23: 14741 | J23: 1 | K23: =ROUND(H23*L23/1000,0) -> 8 | L23: 5
A24: Laboratory | B24: Lab_E_FloorM | C24: Laboratory, Scientific | D24: BaseAirSys14-7 | E24: Lab | F24: Yes | G24: =H24/$H$57 -> 0.030544315 | H24: 1638 | I24: 14741 | J24: 1 | K24: =ROUND(H24*L24/1000,0) -> 8 | L24: 5
A25: Laboratory | B25: Lab_S_FloorM | C25: Laboratory, Scientific | D25: BaseAirSys14-8 | E25: Lab | F25: Yes | G25: =H25/$H$57 -> 0.022115725 | H25: 1186 | I25: 10676 | J25: 1 | K25: =ROUND(H25*L25/1000,0) -> 6 | L25: 5 | P25: Area Distribution By Space Type
A26: Laboratory | B26: Lab_FloorM | C26: Laboratory, Scientific | D26: BaseAirSys14-9 | E26: Lab | F26: Yes | G26: =H26/$H$57 -> 0.020735823 | H26: 1112 | I26: 10006 | J26: 1 | K26: =ROUND(H26*L26/1000,0) -> 6 | L26: 5 | P26: Space Type | Q26: % Area | R26: Number of People | S26: % People
A27: Laboratory | B27: Lounge_FloorM | C27: Lounge, Breakroom, or Waiting Area | D27: BaseAirSys5-2 | E27: Office | F27: Yes | G27: =H27/$H$57 -> 0.019747515 | H27: 1059 | I27: 9533 | J27: 1 | K27: =ROUND(H27*L27/1000,0) -> 16 | L27: 15 | P27: Laboratory, Scientific | Q27: =SUMIF($C$3:$C$56,P27,$G$3:$G$56) -> 0.53706155 | R27: =SUMIF($C$3:$C$56,P27,$K$3:$K$56) -> 142 | S27: =R27/$R$38 -> 0.46254072
A28: Laboratory | B28: Storage_FloorM | C28: Storage (General) | D28: BaseAirSys5-2 | E28: Ancillary | F28: Yes | G28: =H28/$H$57 -> 0.018330319 | H28: 983 | I28: 8848 | J28: 1 | K28: =ROUND(H28*L28/1000,0) -> 0 | L28: 0 | P28: Office Area (>250 square feet) | Q28: =SUMIF($C$3:$C$56,P28,$G$3:$G$56) -> 0.12217726 | R28: =SUMIF($C$3:$C$56,P28,$K$3:$K$56) -> 32 | S28: =R28/$R$38 -> 0.10423453
A29: Laboratory | B29: Mechanical/Electrical_FloorM | C29: Electrical, Mechanical, Telephone Rooms | D29: BaseAirSys5-2 | E29: Ancillary | F29: Yes | G29: =H29/$H$57 -> 0.0066570944 | H29: 357 | I29: 3216 | J29: 1 | K29: =ROUND(H29*L29/1000,0) -> 0 | L29: 0 | P29: Convention, Conference, Multipurpose and Meeting Area | Q29: =SUMIF($C$3:$C$56,P29,$G$3:$G$56) -> 0.020735823 | R29: =SUMIF($C$3:$C$56,P29,$K$3:$K$56) -> 37 | S29: =R29/$R$38 -> 0.12052117
A30: Laboratory | B30: IT-Room_FloorM | C30: IT Room (EPD 12) | D30: BaseAirSys5-2 | E30: Data | F30: Yes | G30: =H30/$H$57 -> 0.0033378708 | H30: 179 | I30: 1610 | J30: 1 | K30: =ROUND(H30*L30/1000,0) -> 0 | L30: 1.5 | P30: Lobby, Main Entry | Q30: =SUMIF($C$3:$C$56,P30,$G$3:$G$56) -> 0.019747515 | R30: =SUMIF($C$3:$C$56,P30,$K$3:$K$56) -> 11 | S30: =R30/$R$38 -> 0.035830619
A31: Laboratory | B31: Restroom_FloorM | C31: Restrooms | D31: BaseAirSys5-2 | E31: Office | F31: Yes | G31: =H31/$H$57 -> 0.012008876 | H31: 644 | I31: 5792 | J31: 1 | K31: =ROUND(H31*L31/1000,0) -> 0 | L31: 0 | P31: Storage (General) | Q31: =SUMIF($C$3:$C$56,P31,$G$3:$G$56) -> 0.054990956 | R31: =SUMIF($C$3:$C$56,P31,$K$3:$K$56) -> 0 | S31: =R31/$R$38 -> 0
A32: Laboratory | B32: BreakRoom/Kitchenette_FloorM | C32: Lounge, Breakroom, or Waiting Area | D32: BaseAirSys5-2 | E32: Office | F32: Yes | G32: =H32/$H$57 -> 0.004326179 | H32: 232 | I32: 2091 | J32: 1 | K32: =ROUND(H32*L32/1000,0) -> 8 | L32: 33 | P32: Electrical, Mechanical, Telephone Rooms | Q32: =SUMIF($C$3:$C$56,P32,$G$3:$G$56) -> 0.019971283 | R32: =SUMIF($C$3:$C$56,P32,$K$3:$K$56) -> 0 | S32: =R32/$R$38 -> 0
A33: Laboratory | B33: Stairway_FloorM | C33: Stairwell | D33: BaseAirSys5-2 | E33: Ancillary | F33: Yes | G33: =H33/$H$57 -> 0.012325881 | H33: 661 | I33: 5953 | J33: 1 | K33: =ROUND(H33*L33/1000,0) -> 0 | L33: 0 | P33: IT Room (EPD 12) | Q33: =SUMIF($C$3:$C$56,P33,$G$3:$G$56) -> 0.010013613 | R33: =SUMIF($C$3:$C$56,P33,$K$3:$K$56) -> 0 | S33: =R33/$R$38 -> 0
A34: Laboratory | B34: Corridor_W_FloorM | C34: Corridor Area | D34: BaseAirSys5-2 | E34: Office | F34: Yes | G34: =H34/$H$57 -> 0.005594197 | H34: 300 | I34: 2700 | J34: 1 | K34: =ROUND(H34*L34/1000,0) -> 2 | L34: 5 | P34: Restrooms | Q34: =SUMIF($C$3:$C$56,P34,$G$3:$G$56) -> 0.036026628 | R34: =SUMIF($C$3:$C$56,P34,$K$3:$K$56) -> 0 | S34: =R34/$R$38 -> 0
A35: Laboratory | B35: Corridor_N_FloorM | C35: Corridor Area | D35: BaseAirSys5-2 | E35: Office | F35: Yes | G35: =H35/$H$57 -> 0.0093796036 | H35: 503 | I35: 4527 | J35: 1 | K35: =ROUND(H35*L35/1000,0) -> 3 | L35: 5 | P35: Lounge, Breakroom, or Waiting Area | Q35: =SUMIF($C$3:$C$56,P35,$G$3:$G$56) -> 0.052473567 | R35: =SUMIF($C$3:$C$56,P35,$K$3:$K$56) -> 56 | S35: =R35/$R$38 -> 0.18241042
A36: Laboratory | B36: Corridor_E_FloorM | C36: Corridor Area | D36: BaseAirSys5-2 | E36: Office | F36: Yes | G36: =H36/$H$57 -> 0.005594197 | H36: 300 | I36: 2693 | J36: 1 | K36: =ROUND(H36*L36/1000,0) -> 2 | L36: 5 | P36: Stairwell | Q36: =SUMIF($C$3:$C$56,P36,$G$3:$G$56) -> 0.036977642 | R36: =SUMIF($C$3:$C$56,P36,$K$3:$K$56) -> 0 | S36: =R36/$R$38 -> 0
A37: Laboratory | B37: Corridor_S_FloorM | C37: Corridor Area | D37: BaseAirSys5-2 | E37: Office | F37: Yes | G37: =H37/$H$57 -> 0.0093796036 | H37: 503 | I37: 4527 | J37: 1 | K37: =ROUND(H37*L37/1000,0) -> 3 | L37: 5 | P37: Corridor Area | Q37: =SUMIF($C$3:$C$56,P37,$G$3:$G$56) -> 0.089824156 | R37: =SUMIF($C$3:$C$56,P37,$K$3:$K$56) -> 29 | S37: =R37/$R$38 -> 0.094462541
A38: Laboratory | B38: Plenum_FloorM | C38: Plenum | D38: n/a | E38: Office | F38: No | H38: 17876 | I38: 71504 | J38: 1 | K38: =ROUND(H38*L38/1000,0) -> 0 | L38: 0 | P38: Total | Q38: =SUM(Q27:Q37) -> 1 | R38: =SUM(R27:R37) -> 307 | S38: =SUM(S27:S37) -> 1
A39: Laboratory | B39: Lab_Core_FloorT | C39: Laboratory, Scientific | D39: BaseAirSys14-10 | E39: Lab | F39: Yes | G39: =H39/$H$57 -> 0.079866485 | H39: 4283 | I39: 38547 | J39: 1 | K39: =ROUND(H39*L39/1000,0) -> 21 | L39: 5
A40: Laboratory | B40: Lab_N_FloorT | C40: Laboratory, Scientific | D40: BaseAirSys14-11 | E40: Lab | F40: Yes | G40: =H40/$H$57 -> 0.042851549 | H40: 2298 | I40: 20682 | J40: 1 | K40: =ROUND(H40*L40/1000,0) -> 11 | L40: 5
A41: Laboratory | B41: Enclosed_Office_W_FloorT | C41: Office Area (>250 square feet) | D41: BaseAirSys5-3 | E41: Office | F41: Yes | G41: =H41/$H$57 -> 0.030544315 | H41: 1638 | I41: 14741 | J41: 1 | K41: =ROUND(H41*L41/1000,0) -> 8 | L41: 5
A42: Laboratory | B42: Enclosed_Office_E_FloorT | C42: Office Area (>250 square feet) | D42: BaseAirSys5-3 | E42: Office | F42: Yes | G42: =H42/$H$57 -> 0.030544315 | H42: 1638 | I42: 14741 | J42: 1 | K42: =ROUND(H42*L42/1000,0) -> 8 | L42: 5
A43: Laboratory | B43: Lab_S_FloorT | C43: Laboratory, Scientific | D43: BaseAirSys14-12 | E43: Lab | F43: Yes | G43: =H43/$H$57 -> 0.022115725 | H43: 1186 | I43: 10676 | J43: 1 | K43: =ROUND(H43*L43/1000,0) -> 6 | L43: 5
...

Sheet Envelope
A1: ="Envelope - "&Prototype!B4 -> Envelope - Laboratory
A2: Element | B2: Prototype | C2: Assembly Type | D2: Construction | E2: Thermal properties | F2: Vintage | G2: Selected T24 | H2: Notes | I2: CZ1 | J2: CZ2 | K2: CZ3 | L2: CZ4 | M2: CZ5 | N2: CZ6 | O2: CZ7 | P2: CZ8 | Q2: CZ9 | R2: CZ10 | S2: CZ11 | T2: CZ12 | U2: CZ13 | V2: CZ14 | W2: CZ15 | X2: CZ16
A3: External Wall | B3: =Prototype!A2 -> Laboratory | C3: ExtWall_MetalFramed_NonRes | D3: Metal framed wall: Metal frame + insulation + Gypsum board | E3: U-value IP | F3: Pre 1978 | G3: N/A | H3: ASHRAE 90.1, 2022 Table A3.3.3.1, 3.5", R-0 | I3: 0.352 | J3: 0.352 | K3: 0.352 | L3: 0.352 | M3: 0.352 | N3: 0.352 | O3: 0.352 | P3: 0.352 | Q3: 0.352 | R3: 0.352 | S3: 0.352 | T3: 0.352 | U3: 0.352 | V3: 0.352 | W3: 0.352 | X3: 0.352
F4: 1978-1997 | G4: 1986 | H4: Similar to Low-rise office: Package A/ Heat Capacity was considered ~10 (BTU/F/ft²) | I4: 0.21276596 | J4: 0.22727273 | K4: 0.22727273 | L4: 0.2173913 | M4: 0.25641026 | N4: 0.25641026 | O4: 0.25641026 | P4: 0.25641026 | Q4: 0.25641026 | R4: 0.25641026 | S4: 0.23809524 | T4: 0.23809524 | U4: 0.23809524 | V4: 0.20833333 | W4: 0.20833333 | X4: 0.21276596 | Y4: *U = 1 / R_assembly, with the per-CZ R-values (4.7 / 4.4 / 4.4 / 4.6 / 3.9 CZ5-10 / 4.2 CZ11-13 / 4.8 CZ14-15 / 4.7 CZ16)
F5: 1998-2007 | G5: 2001 | H5: Table 1-H | I5: 0.182 | J5: 0.182 | K5: 0.189 | L5: 0.189 | M5: 0.189 | N5: 0.189 | O5: 0.189 | P5: 0.189 | Q5: 0.189 | R5: 0.182 | S5: 0.182 | T5: 0.182 | U5: 0.182 | V5: 0.182 | W5: 0.182 | X5: 0.182
F6: 2008-2018 | G6: 2013 | H6: Table 140.3-B | I6: 0.098 | J6: 0.062 | K6: 0.082 | L6: 0.062 | M6: 0.062 | N6: 0.098 | O6: 0.098 | P6: 0.062 | Q6: 0.062 | R6: 0.062 | S6: 0.062 | T6: 0.062 | U6: 0.062 | V6: 0.062 | W6: 0.062 | X6: 0.062
F7: 2019+ | G7: 2025 | H7: Table 140.3-B | I7: 0.06 | J7: 0.055 | K7: 0.071 | L7: 0.055 | M7: 0.055 | N7: 0.06 | O7: 0.06 | P7: 0.055 | Q7: 0.055 | R7: 0.055 | S7: 0.055 | T7: 0.055 | U7: 0.055 | V7: 0.055 | W7: 0.055 | X7: 0.055
A8: Roof | B8: =$B$3 -> Laboratory | C8: FlatRoof_WoodFramedAndOther_NonRes | D8: Metal deck roof: roof membrane+roof insulation+metal decking | E8: U-value IP | F8: Pre 1978 | G8: N/A | H8: Considering 30 years for roof/ insulation replacement. | I8: 0.057 | J8: 0.057 | K8: 0.057 | L8: 0.057 | M8: 0.057 | N8: 0.078 | O8: 0.078 | P8: 0.078 | Q8: 0.078 | R8: 0.078 | S8: 0.057 | T8: 0.057 | U8: 0.057 | V8: 0.057 | W8: 0.057 | X8: 0.057
F9: 1978-1997 | G9: 1992 | I9: 0.057 | J9: 0.057 | K9: 0.057 | L9: 0.057 | M9: 0.057 | N9: 0.078 | O9: 0.078 | P9: 0.078 | Q9: 0.078 | R9: 0.078 | S9: 0.057 | T9: 0.057 | U9: 0.057 | V9: 0.057 | W9: 0.057 | X9: 0.057
F10: 1998-2007 | G10: 2001 | H10: Table 1-H | I10: 0.057 | J10: 0.057 | K10: 0.057 | L10: 0.057 | M10: 0.057 | N10: 0.078 | O10: 0.078 | P10: 0.078 | Q10: 0.078 | R10: 0.057 | S10: 0.057 | T10: 0.057 | U10: 0.057 | V10: 0.057 | W10: 0.057 | X10: 0.057
F11: 2008-2018 | G11: 2013 | H11: Table 140.3-B | I11: 0.049 | J11: 0.039 | K11: 0.039 | L11: 0.039 | M11: 0.049 | N11: 0.075 | O11: 0.067 | P11: 0.067 | Q11: 0.039 | R11: 0.039 | S11: 0.039 | T11: 0.039 | U11: 0.039 | V11: 0.039 | W11: 0.039 | X11: 0.039
F12: 2019+ | G12: 2025 | H12: Table 140.3-B | I12: 0.038 | J12: 0.038 | K12: 0.038 | L12: 0.038 | M12: 0.038 | N12: 0.038 | O12: 0.038 | P12: 0.038 | Q12: 0.038 | R12: 0.038 | S12: 0.038 | T12: 0.038 | U12: 0.038 | V12: 0.038 | W12: 0.038 | X12: 0.038
A13: Windows | B13: =$B$3 -> Laboratory | C13: FixedWindow_NonRes | D13: Single pane | E13: U-value IP | F13: Pre 1978 | G13: N/A | H13: ASHRAE Handbook of Fundamentals (Table 4-Ch15) for single pane & T24, 2013 for double pane (33%-67%)* | I13: =0.33*1.12+0.67*0.36 -> 0.6108 | J13: =0.33*1.12+0.67*0.36 -> 0.6108 | K13: =0.33*1.12+0.67*0.36 -> 0.6108 | L13: =0.33*1.12+0.67*0.36 -> 0.6108 | M13: =0.33*1.12+0.67*0.36 -> 0.6108 | N13: =0.33*1.12+0.67*0.36 -> 0.6108 | O13: =0.33*1.12+0.67*0.36 -> 0.6108 | P13: =0.33*1.12+0.67*0.36 -> 0.6108 | ... X13: =0.33*1.12+0.67*0.36 -> 0.6108
F14: 1978-1997 | G14: N/A | I14: =0.33*1.12+0.67*0.36 -> 0.6108 | J14: =0.33*1.12+0.67*0.36 -> 0.6108 | K14: =0.33*1.12+0.67*0.36 -> 0.6108 | L14: =0.33*1.12+0.67*0.36 -> 0.6108 | M14: =0.33*1.12+0.67*0.36 -> 0.6108 | N14: =0.33*1.12+0.67*0.36 -> 0.6108 | O14: =0.33*1.12+0.67*0.36 -> 0.6108 | P14: =0.33*1.12+0.67*0.36 -> 0.6108 | ... X14: =0.33*1.12+0.67*0.36 -> 0.6108
D15: Double pane | F15: 1998-2007 | G15: 2001 | H15: Table 1-H | I15: 0.49 | J15: 0.49 | K15: 0.81 | L15: 0.81 | M15: 0.81 | N15: 0.81 | O15: 0.81 | P15: 0.81 | Q15: 0.81 | R15: 0.49 | S15: 0.49 | T15: 0.49 | U15: 0.49 | V15: 0.49 | W15: 0.49 | X15: 0.49
F16: 2008-2018 | G16: 2013 | H16: Table 140.3-B | I16: 0.36 | J16: 0.36 | K16: 0.36 | L16: 0.36 | M16: 0.36 | N16: 0.36 | O16: 0.36 | P16: 0.36 | Q16: 0.36 | R16: 0.36 | S16: 0.36 | T16: 0.36 | U16: 0.36 | V16: 0.36 | W16: 0.36 | X16: 0.36
F17: 2019+ | G17: 2025 | H17: Table 140.3-B | I17: 0.36 | J17: 0.36 | K17: 0.36 | L17: 0.36 | M17: 0.36 | N17: 0.36 | O17: 0.36 | P17: 0.36 | Q17: 0.34 | R17: 0.36 | S17: 0.34 | T17: 0.34 | U17: 0.34 | V17: 0.34 | W17: 0.34 | X17: 0.36
B18: =$B$3 -> Laboratory | C18: FixedWindow_NonRes | D18: Single pane | E18: SHGC | F18: Pre 1978 | G18: N/A | H18: ASHRAE Handbook of Fundamentals (Table 10-Ch15) for single pane & T24, 2013 for double pane (33%-67%)* | I18: =0.79*0.33+0.67*I21 -> 0.4282 | J18: =0.79*0.33+0.67*J21 -> 0.4282 | K18: =0.79*0.33+0.67*K21 -> 0.4282 | L18: =0.79*0.33+0.67*L21 -> 0.4282 | M18: =0.79*0.33+0.67*M21 -> 0.4282 | N18: =0.79*0.33+0.67*N21 -> 0.4282 | O18: =0.79*0.33+0.67*O21 -> 0.4282 | P18: =0.79*0.33+0.67*P21 -> 0.4282 | ... X18: =0.79*0.33+0.67*X21 -> 0.4282
F19: 1978-1997 | G19: N/A | I19: =0.79*0.33+0.67*I21 -> 0.4282 | J19: =0.79*0.33+0.67*J21 -> 0.4282 | K19: =0.79*0.33+0.67*K21 -> 0.4282 | L19: =0.79*0.33+0.67*L21 -> 0.4282 | M19: =0.79*0.33+0.67*M21 -> 0.4282 | N19: =0.79*0.33+0.67*N21 -> 0.4282 | O19: =0.79*0.33+0.67*O21 -> 0.4282 | P19: =0.79*0.33+0.67*P21 -> 0.4282 | ... X19: =0.79*0.33+0.67*X21 -> 0.4282
D20: Double pane | F20: 1998-2007 | G20: 2001 | H20: Table 1-H - WWR:31-40% / SHGC non-north | I20: 0.43 | J20: 0.31 | K20: 0.41 | L20: 0.41 | M20: 0.41 | N20: 0.34 | O20: 0.34 | P20: 0.34 | Q20: 0.34 | R20: 0.31 | S20: 0.31 | T20: 0.31 | U20: 0.31 | V20: 0.31 | W20: 0.31 | X20: 0.43
F21: 2008-2018 | G21: 2013 | H21: Table 140.3-B | I21: 0.25 | J21: 0.25 | K21: 0.25 | L21: 0.25 | M21: 0.25 | N21: 0.25 | O21: 0.25 | P21: 0.25 | Q21: 0.25 | R21: 0.25 | S21: 0.25 | T21: 0.25 | U21: 0.25 | V21: 0.25 | W21: 0.25 | X21: 0.25
F22: 2019+ | G22: 2025 | H22: Table 140.3-B | I22: 0.25 | J22: 0.25 | K22: 0.25 | L22: 0.25 | M22: 0.25 | N22: 0.25 | O22: 0.25 | P22: 0.25 | Q22: 0.22 | R22: 0.25 | S22: 0.22 | T22: 0.22 | U22: 0.22 | V22: 0.22 | W22: 0.22 | X22: 0.25
C25: Infiltration
D26: Building | E26: Zones | F26: Vintage | G26: I_75 6-sdied Infiltration rate @ 75 pa | H26: Note | I26: I-design (cfm/ft²) (4-sided Infiltration rate at normal pressure) (Design flow rate approach and Flow/Exterior Wall Area calculation method)
C27: Infiltration | D27: Laboratory | F27: Pre 1978 | G27: 1.1 | H27: 2022 CASE report (Table 38) | I27: 0.3301
F28: 1978-1997 | G28: 1.1 | H28: 2022 CASE report (Table 38) | I28: 0.3301
F29: 1998-2007 | G29: 1.1 | H29: 2022 CASE report (Table 38) | I29: 0.3301
F30: 2008-2018 | G30: 1 | H30: 2022 CASE report (Table 38) & T24, 2008-2016 (Table 140.3-B)--Air barrier is required in CZ 10-16 | I30: 0.3021
F31: 2019+ | G31: 0.6 | H31: 2022 CASE report (Table 38) & T24, 2025 (Table 140.3-B)--Air barrier is required in all CZs | I31: 0.1801
F32: Air Leakage Memo: | G32: Infiltration_rate_report_14May2025-Short-Version.docx
F33: -

Sheet HVAC System
A1: ="HVAC system - "&Prototype!B4 -> HVAC system - Laboratory
A2: Vintage | B2: Zones | C2: Heating | D2: Cooling | E2: Air Distribution | F2: Source | G2: Note
A3: Exisiting | B3: Offices and support area | C3: Gas Boiler | D3: Packaged (DX) | E3: Multi zone VAV with hydronic reheat | F3: Engineering Judgement | G3: System 5 PVAV for offices and support area
B4: Other Conditioned zones (Labs) | C4: Gas Boiler | D4: Packaged (DX) | E4: Multi zone VAV with hydronic reheat | G4: System 5 PVAV- 100% outdoor air for labs, but no required energy recovery For V1 and V2. V3 has Heat recovery.
A5: New Construction | B5: Offices and support area | C5: Gas Boiler | D5: Packaged (DX) | E5: Multi zone VAV with hydronic reheat | F5: T24 2025 ACM 2025, Table 1 and 2 | G5: System 5 PVAV for offices and support area
B6: Other Conditioned zones (Labs) | C6: Central air-to-water HP | D6: Central air-cooled Chiller | E6: Single zone VAV ( Each zone has a chilled water or hot water changeover coil with a 6-way valve for cooling or heating) | G6: System 14a for Labs– Aircooled 4pipe VAV with Exhaust heat recovery-
A7: *The New Construction HVAC system is assigned by the 2025 ACM Reference Manual, Table 1 (Nonresidential HVAC System Map), which selects the standard design system by space function rather than building type. For a covered process laboratory, Table 1 assigns System 14a – ACSZVAV (air-cooled single zone VAV) where the design maximum exhaust exceeds 20,000 cfm, no exception applies, and total conditioned floor area is below 150,000 ft²; above that area it becomes System 14b (water-cooled), and where the exhaust test is not met or an exception applies it drops to System 5 – PVAV. The laboratory prototype meets all three conditions: laboratory exhaust is a covered process under the ACM, design exhaust is 25,317 cfm, and conditioned floor area is 53,626 ft², which is why 14a rather than 14b was selected. The ACM is used as the basis because no observed stock dataset reports laboratory HVAC system type: CEUS 2022 has twelve building types with no laboratory or R&D category. Existing vintages use System 5 – PVAV on the same ACM basis, applied as a documented proxy.
A8: ** DEDICATED FANS: each of the laboratory zones carries its own exhaust fan, in every vintage and in New Construction. The exhaust is modelled as a per-zone dedicated fan, i.e. non-manifolded; no common exhaust plenum or manifold is represented. HEAT RECOVERY: present in New Construction and V3 only, as part of System 14a and systen 5, and absent from the other vintages. PLUME AND EXIT VELOCITY: not modelled and not modellable with the current objects, since EnergyPlus zone exhaust fans carry no stack or discharge model.
A10: Efficiency of HVAC System (Efficiency is capacity-dependent. The following table provides a general estimate of system efficiency based on preliminary simulations in one climate zone, or assuming cooling load based on rule of thumb)
A11: Vintage | B11: Upgrade/Installed year | C11: Air-Cooled Chiller | D11: DX | E11: Gas Boiler | F11: Air-to-Water HP | G11: Sources | H11: Note
A12: Pre 1978 | B12: 2008 | C12: n/a | D12: ≥ 65,000 Btu/h and < 135,000 Btu/h , 11.0 EER | E12: 80% Ec | F12: n/a | G12: T24, 2008 , Table 112-A (for DX Coil) -Title 24-2008 §111 / Title 20 Table E-3 (and 10 CFR 431.87 as in effect through March 1, 2012) for Boiler Efficiency
A13: 1978-1997
A14: 1998-2007
A15: 2008-2018 | B15: 2013 | C15: n/a | D15: ≥ 65,000 Btu/h and < 135,000 Btu/h , 11.0 EER | E15: Gas-Fired Boiler > 300,000 Btu/h and ≤2,500,000 Btu/h-- 80% Et Gas-Fired Boiler > 2,500,000 Btu/h -- 82% Ec | F15: n/a | G15: T24, 2013 , Table 110.2-A (for DX Coil) -Table 110.2-k (for Gas Fired Boiler)
A16: New Construction | B16: 2025 | C16: Air-cooled Chiller >150 Tons--≥ 10.100 EER, ≥ 14.000 IPLV | D16: ≥ 65,000 Btu/h and < 135,000 Btu/h , 11.0 EER | E16: Gas-Fired Boiler > 300,000 Btu/h and ≤2,500,000 Btu/h-- 80% Et Gas-Fired Boiler > 2,500,000 Btu/h -- 82% Ec | F16: Air Cooled (Heating Mode) Split system and single package≥ 135,000 Btu/h and < 240,000 Btu/h 3.3 COP | G16: T24, 2025 , Table 110.2-A (for DX Coil), Table 110.2-D (for chiller COP) - 10 CFR 431.86 , section § 431.87 Table 1 (for Boiler thermal efficiency).
C18: * Et = Combustion efficiency | D18: * Et = Thermal efficiency
A20: Fan power
A21: Vintage | B21: Approach | C21: System | D21: Total Static Pressure (TSP) (in w.c.) | E21: Fan Efficiency [ACM 2025] | F21: Motor Efficiency | G21: Fan Power Index (W/cfm) | H21: Data Source | I21: Note
A22: Existing | B22: PNNL 90.1-2011, TSP | C22: System 6 VAV >5,000 cfm | D22: 5.58 | E22: 0.65 | F22: ASHRAE 90.1, 2004, Table 10.8 * | H22: Fan power formula: PNNL 20405, 2010, section 5.2.2.5 TSP and fan efficiency: PNNL 20405, 2010, Table 5.11, 90.1-04ac values Motor efficiency: ASHRAE 90.1, 2004, Table 10.8
A23: Brake horsepower (bhp) = (Supply cfm × TSP in w.c.) / (6356 × fan efficiency)
A24: Fan power (w/cfm) = (bhp × 746) / ( supply cfm × motor efficiency )
A25: New Construction | B25: ACM 2025 | C25: Multi Zone VAV System >5,000 cfm; < 10,000 cfm | D25: TSP = fan power × motor efficiency × fan efficiency × 6356 / 747 | E25: 0.65 | F25: 2025 ACM Table 12 ** | G25: 1.013 | H25: Fan power index: [ACM 2025, Table 13] Motot efficiency: [ ACM 2025, Table 12]
F26: * 0.9 is an average fan efficiency according to ACM 2025, Table 13
A27: * According to PNNL 20405 section 5.2.2.5, the full-load efficiency of the motor serving the fan is taken from ASHRAE 90.1, 2004, Table 10.8, based on motor nameplate and assuming enclosed motors operating at 1,800 rotations per minute (rpm) Motor nameplate size (bhp) = brake horsepower (bhp) × 1.1 ( using a 10% oversizing factor)
A28: ** The full‑load efficiency of the motor serving the fan is taken from ACM 2025 Table 12 based on the cfm of the fan. Brake horsepower (bhp) = (Supply cfm from sizing run × fan power in W/cfm) / 746.
A33: Background Data [To be deleted prior to publication]

Sheet Thermostat
A1: ="Thermostat Setpoints - "&Prototype!A2 -> Thermostat Setpoints - Laboratory
A2: Spaces/Zones | B2: Setpoint | C2: CZ1 | D2: CZ2 | E2: CZ3 | F2: CZ4 | G2: CZ5 | H2: CZ6 | I2: CZ7 | J2: CZ8 | K2: CZ9 | L2: CZ10 | M2: CZ11 | N2: CZ12 | O2: CZ13 | P2: CZ14 | Q2: CZ15 | R2: CZ16 | S2: Source
A3: Laboratory | B3: Heating Setpoint (F) | C3: 70 | D3: 70 | E3: 70 | F3: 70 | G3: 70 | H3: 70 | I3: 70 | J3: 70 | K3: 70 | L3: 70 | M3: 70 | N3: 70 | O3: 70 | P3: 70 | Q3: 70 | R3: 70 | S3: LBNL/DOE Prototype for Labs
B4: Heating Setback (F) | C4: 68 | D4: 68 | E4: 68 | F4: 68 | G4: 68 | H4: 68 | I4: 68 | J4: 68 | K4: 68 | L4: 68 | M4: 68 | N4: 68 | O4: 68 | P4: 68 | Q4: 68 | R4: 68
B5: Cooling Setpoint (F) | C5: 75 | D5: 75 | E5: 75 | F5: 75 | G5: 75 | H5: 75 | I5: 75 | J5: 75 | K5: 75 | L5: 75 | M5: 75 | N5: 75 | O5: 75 | P5: 75 | Q5: 75 | R5: 75
B6: Cooling Setback (F) | C6: 78 | D6: 78 | E6: 78 | F6: 78 | G6: 78 | H6: 78 | I6: 78 | J6: 78 | K6: 78 | L6: 78 | M6: 78 | N6: 78 | O6: 78 | P6: 78 | Q6: 78 | R6: 78
A7: All conditioned zones except server rooms, Storage, Stairway & Mechanical_Electrical | B7: Heating Setpoint (F) | C7: 70 | D7: 70 | E7: 70 | F7: 70 | G7: 70 | H7: 70 | I7: 70 | J7: 70 | K7: 70 | L7: 70 | M7: 70 | N7: 70 | O7: 70 | P7: 70 | Q7: 70 | R7: 70 | S7: T24 2025 - Appendix 5.4B
B8: Heating Setback (F) | C8: 60 | D8: 60 | E8: 60 | F8: 60 | G8: 60 | H8: 60 | I8: 60 | J8: 60 | K8: 60 | L8: 60 | M8: 60 | N8: 60 | O8: 60 | P8: 60 | Q8: 60 | R8: 60
B9: Cooling Setpoint (F) | C9: 75 | D9: 75 | E9: 75 | F9: 75 | G9: 75 | H9: 75 | I9: 75 | J9: 75 | K9: 75 | L9: 75 | M9: 75 | N9: 75 | O9: 75 | P9: 75 | Q9: 75 | R9: 75
B10: Cooling Setback (F) | C10: 85 | D10: 85 | E10: 85 | F10: 85 | G10: 85 | H10: 85 | I10: 85 | J10: 85 | K10: 85 | L10: 85 | M10: 85 | N10: 85 | O10: 85 | P10: 85 | Q10: 85 | R10: 85
A11: Storage, Stairway, and Mechanical_Electrical | B11: Heating Setpoint (F) | C11: 60 | D11: 60 | E11: 60 | F11: 60 | G11: 60 | H11: 60 | I11: 60 | J11: 60 | K11: 60 | L11: 60 | M11: 60 | N11: 60 | O11: 60 | P11: 60 | Q11: 60 | R11: 60 | S11: Enginnering Judgment
B12: Heating Setback (F) | C12: 60 | D12: 60 | E12: 60 | F12: 60 | G12: 60 | H12: 60 | I12: 60 | J12: 60 | K12: 60 | L12: 60 | M12: 60 | N12: 60 | O12: 60 | P12: 60 | Q12: 60 | R12: 60 | S12: (Semi‑conditioned space)
B13: Cooling Setpoint (F) | C13: 85 | D13: 85 | E13: 85 | F13: 85 | G13: 85 | H13: 85 | I13: 85 | J13: 85 | K13: 85 | L13: 85 | M13: 85 | N13: 85 | O13: 85 | P13: 85 | Q13: 85 | R13: 85
B14: Cooling Setback (F) | C14: 85 | D14: 85 | E14: 85 | F14: 85 | G14: 85 | H14: 85 | I14: 85 | J14: 85 | K14: 85 | L14: 85 | M14: 85 | N14: 85 | O14: 85 | P14: 85 | Q14: 85 | R14: 85
A15: IT rooms | B15: Cooling Setpoint (F)* | C15: 80 | D15: 80 | E15: 80 | F15: 80 | G15: 80 | H15: 80 | I15: 80 | J15: 80 | K15: 80 | L15: 80 | M15: 80 | N15: 80 | O15: 80 | P15: 80 | Q15: 80 | R15: 80 | S15: Title 24, Part 6, 2025, section 140.9 (a) and PNNL ASHRAE 90.1 2022 Large Office prototype
B16: Heating Setpoint (F)* | C16: *The IT room with over 12 W/ft2 load doesn't require heating system as the equipment constantly generate enough heat.
A18: *Relative Humidity Ratio: 40%-60%
A34: Office Cooling Setback (F) | B34: 85 | C34: 85 | D34: 85 | E34: 85 | F34: 85 | G34: 85 | H34: 85 | I34: 85 | J34: 85 | K34: 85 | L34: 85 | M34: 85 | N34: 85 | O34: 85 | P34: 85 | Q34: 85
A36: Source: PNNL Healthcare-Outpaitiet prototype use this setpoints: Administration zones: 72°F Cooling/70°F Heating, Critical zones: 72°F Cooling/70°F Heating, Operating rooms: 65°F Cooling/65°F Heating
A37: PNNL Healthcare-Outpaitiet prototype use this setbacks: 77°F Cooling/65°F Heating, Critical zones: no setback, Operating rooms: 72°F Cooling/65°F Heating

Sheet Ventilation
A1: ="Outdoor Airflow Rate - "&Prototype!A2 -> Outdoor Airflow Rate - Laboratory
A2: Space Type | B2: Space/Thermal Zone | C2: Number of People | D2: Floor Area (ft²) | E2: cfm/person (T24, 2025, Equation 120.1-F and Table 120.1-A) | F2: cfm/ft² (T24, 2025, Equation 120.1-F and Table 120.1-A) | G2: Required exhaust rate-CFM/ft²- (T24, part 6 2025, Table 120.1-B – minimum exhaust rates) | H2: Hood Exhaust Rate (cfm) @133 cfm/ft - At sash stop | I2: Total cfm driven by people | J2: Total cfm driven by area | K2: Total cfm driven by exhaust | L2: Total cfm | M2: Notes
A3: =Zones!C3 -> Laboratory, Scientific | B3: =Zones!B3 -> Lab_Core_FloorG | C3: =(D3*25/1000) -> 107.075 | D3: =Zones!H3 -> 4283 | E3: 15 | F3: 0.15 | G3: 1 | H3: =G68 -> 10612.375 | I3: =C3*E3 -> 1606.125 | J3: =D3*F3 -> 642.45 | K3: =G3*D3 -> 4283 | L3: =MAX(I3,J3,K3,H3) -> 10612.375
A4: =Zones!C4 -> Laboratory, Scientific | B4: =Zones!B4 -> Lab_N_FloorG | C4: =(D4*25/1000) -> 57.45 | D4: =Zones!H4 -> 2298 | E4: 15 | F4: 0.15 | G4: 1 | H4: =G69 -> 5693.9614 | I4: =C4*E4 -> 861.75 | J4: =D4*F4 -> 344.7 | K4: =G4*D4 -> 2298 | L4: =MAX(I4,J4,K4,H4) -> 5693.9614
A5: =Zones!C5 -> Office Area (>250 square feet) | B5: =Zones!B5 -> Enclosed_Office_W_FloorG | C5: =Zones!K5 -> 8 | D5: =Zones!H5 -> 1638 | E5: 15 | F5: 0.15 | I5: =C5*E5 -> 120 | J5: =D5*F5 -> 245.7 | K5: =G5*D5 -> 0 | L5: =MAX(I5,J5,K5) -> 245.7
A6: =Zones!C6 -> Office Area (>250 square feet) | B6: =Zones!B6 -> Enclosed_Office_E_FloorG | C6: =Zones!K6 -> 8 | D6: =Zones!H6 -> 1638 | E6: 15 | F6: 0.15 | I6: =C6*E6 -> 120 | J6: =D6*F6 -> 245.7 | K6: =G6*D6 -> 0 | L6: =MAX(I6,J6,K6) -> 245.7
A7: =Zones!C7 -> Laboratory, Scientific | B7: =Zones!B7 -> Lab_S_FloorG | C7: =(D7*25/1000) -> 29.65 | D7: =Zones!H7 -> 1186 | E7: 15 | F7: 0.15 | G7: 1 | H7: =G70 -> 2938.6589 | I7: =C7*E7 -> 444.75 | J7: =D7*F7 -> 177.9 | K7: =G7*D7 -> 1186 | L7: =MAX(I7,J7,K7,H7) -> 2938.6589
A8: =Zones!C8 -> Convention, Conference, Multipurpose and Meeting Area | B8: =Zones!B8 -> Conference_FloorG | C8: =Zones!K8 -> 37 | D8: =Zones!H8 -> 1112 | E8: 15 | F8: 0.15 | I8: =C8*E8 -> 555 | J8: =D8*F8 -> 166.8 | K8: =G8*D8 -> 0 | L8: =MAX(I8,J8,K8) -> 555
A9: =Zones!C9 -> Lobby, Main Entry | B9: =Zones!B9 -> Lobby_FloorG | C9: =Zones!K9 -> 11 | D9: =Zones!H9 -> 1059 | E9: 15 | F9: 0.15 | I9: =C9*E9 -> 165 | J9: =D9*F9 -> 158.85 | K9: =G9*D9 -> 0 | L9: =MAX(I9,J9,K9) -> 165
A10: =Zones!C10 -> Storage (General) | B10: =Zones!B10 -> Storage_FloorG | C10: =Zones!K10 -> 0 | D10: =Zones!H10 -> 983 | E10: 15 | F10: 0.15 | I10: =C10*E10 -> 0 | J10: =D10*F10 -> 147.45 | K10: =G10*D10 -> 0 | L10: =MAX(I10,J10,K10) -> 147.45
A11: =Zones!C11 -> Electrical, Mechanical, Telephone Rooms | B11: =Zones!B11 -> Mechanical/Electrical_FloorG | C11: =Zones!K11 -> 0 | D11: =Zones!H11 -> 357 | E11: 15 | F11: 0.15 | I11: =C11*E11 -> 0 | J11: =D11*F11 -> 53.55 | K11: =G11*D11 -> 0 | L11: =MAX(I11,J11,K11) -> 53.55
A12: =Zones!C12 -> IT Room (EPD 12) | B12: =Zones!B12 -> IT-Room_FloorG | C12: =Zones!K12 -> 0 | D12: =Zones!H12 -> 179 | E12: 15 | F12: 0.15 | I12: =C12*E12 -> 0 | J12: =D12*F12 -> 26.85 | K12: =G12*D12 -> 0 | L12: =MAX(I12,J12,K12) -> 26.85
A13: =Zones!C13 -> Restrooms | B13: =Zones!B13 -> Restroom_FloorG | C13: =Zones!K13 -> 0 | D13: =Zones!H13 -> 644 | E13: 15 | F13: 0.15 | G13: 4*50/70 cfm per unit | I13: =C13*E13 -> 0 | J13: =D13*F13 -> 96.6 | K13: =4*50 -> 200 | L13: =MAX(I13,J13,K13) -> 200
A14: =Zones!C14 -> Lounge, Breakroom, or Waiting Area | B14: =Zones!B14 -> BreakRoom/Kitchenette_FloorG | C14: =Zones!K14 -> 8 | D14: =Zones!H14 -> 232 | E14: 15 | F14: 0.15 | I14: =C14*E14 -> 120 | J14: =D14*F14 -> 34.8 | K14: =G14*D14 -> 0 | L14: =MAX(I14,J14,K14) -> 120
A15: =Zones!C15 -> Stairwell | B15: =Zones!B15 -> Stairway_FloorG | C15: =Zones!K15 -> 0 | D15: =Zones!H15 -> 661 | E15: 15 | F15: 0.15 | I15: =C15*E15 -> 0 | J15: =D15*F15 -> 99.15 | K15: =G15*D15 -> 0 | L15: =MAX(I15,J15,K15) -> 99.15
A16: =Zones!C16 -> Corridor Area | B16: =Zones!B16 -> Corridor_W_FloorG | C16: =Zones!K16 -> 2 | D16: =Zones!H16 -> 300 | E16: 15 | F16: 0.15 | I16: =C16*E16 -> 30 | J16: =D16*F16 -> 45 | K16: =G16*D16 -> 0 | L16: =MAX(I16,J16,K16) -> 45
A17: =Zones!C17 -> Corridor Area | B17: =Zones!B17 -> Corridor_N_FloorG | C17: =Zones!K17 -> 3 | D17: =Zones!H17 -> 503 | E17: 15 | F17: 0.15 | I17: =C17*E17 -> 45 | J17: =D17*F17 -> 75.45 | K17: =G17*D17 -> 0 | L17: =MAX(I17,J17,K17) -> 75.45
A18: =Zones!C18 -> Corridor Area | B18: =Zones!B18 -> Corridor_E_FloorG | C18: =Zones!K18 -> 1 | D18: =Zones!H18 -> 299 | E18: 15 | F18: 0.15 | I18: =C18*E18 -> 15 | J18: =D18*F18 -> 44.85 | K18: =G18*D18 -> 0 | L18: =MAX(I18,J18,K18) -> 44.85
A19: =Zones!C19 -> Corridor Area | B19: =Zones!B19 -> Corridor_S_FloorG | C19: =Zones!K19 -> 3 | D19: =Zones!H19 -> 503 | E19: 15 | F19: 0.15 | I19: =C19*E19 -> 45 | J19: =D19*F19 -> 75.45 | K19: =G19*D19 -> 0 | L19: =MAX(I19,J19,K19) -> 75.45
A20: =Zones!C20 -> Plenum | B20: =Zones!B20 -> Plenum_FloorG | C20: =Zones!K20 -> 0 | D20: =Zones!H20 -> 17876 | F20: - | I20: =C20*E20 -> 0 | J20: 0 | K20: =G20*D20 -> 0 | L20: =MAX(I20,J20,K20) -> 0
A21: =Zones!C21 -> Laboratory, Scientific | B21: =Zones!B21 -> Lab_Core_FloorM | C21: =(D21*25/1000) -> 107.075 | D21: =Zones!H21 -> 4283 | E21: 15 | F21: 0.15 | G21: 1 | H21: =G71 -> 10612.375 | I21: =C21*E21 -> 1606.125 | J21: =D21*F21 -> 642.45 | K21: =G21*D21 -> 4283 | L21: =MAX(I21,J21,K21,H21) -> 10612.375
A22: =Zones!C22 -> Laboratory, Scientific | B22: =Zones!B22 -> Lab_N_FloorM | C22: =(D22*25/1000) -> 57.45 | D22: =Zones!H22 -> 2298 | E22: 15 | F22: 0.15 | G22: 1 | H22: =G72 -> 5693.9614 | I22: =C22*E22 -> 861.75 | J22: =D22*F22 -> 344.7 | K22: =G22*D22 -> 2298 | L22: =MAX(I22,J22,K22,H22) -> 5693.9614
A23: =Zones!C23 -> Laboratory, Scientific | B23: =Zones!B23 -> Lab_W_FloorM | C23: =(D23*25/1000) -> 40.95 | D23: =Zones!H23 -> 1638 | E23: 15 | F23: 0.15 | G23: 1 | H23: =G73 -> 4058.62 | I23: =C23*E23 -> 614.25 | J23: =D23*F23 -> 245.7 | K23: =G23*D23 -> 1638 | L23: =MAX(I23,J23,K23,H23) -> 4058.62
A24: =Zones!C24 -> Laboratory, Scientific | B24: =Zones!B24 -> Lab_E_FloorM | C24: =(D24*25/1000) -> 40.95 | D24: =Zones!H24 -> 1638 | E24: 15 | F24: 0.15 | G24: 1 | H24: =G74 -> 4058.62 | I24: =C24*E24 -> 614.25 | J24: =D24*F24 -> 245.7 | K24: =G24*D24 -> 1638 | L24: =MAX(I24,J24,K24,H24) -> 4058.62
A25: =Zones!C25 -> Laboratory, Scientific | B25: =Zones!B25 -> Lab_S_FloorM | C25: =(D25*25/1000) -> 29.65 | D25: =Zones!H25 -> 1186 | E25: 15 | F25: 0.15 | G25: 1 | H25: =G75 -> 2938.6589 | I25: =C25*E25 -> 444.75 | J25: =D25*F25 -> 177.9 | K25: =G25*D25 -> 1186 | L25: =MAX(I25,J25,K25,H25) -> 2938.6589
A26: =Zones!C26 -> Laboratory, Scientific | B26: =Zones!B26 -> Lab_FloorM | C26: =(D26*25/1000) -> 27.8 | D26: =Zones!H26 -> 1112 | E26: 15 | F26: 0.15 | G26: 1 | H26: =G76 -> 2755.3025 | I26: =C26*E26 -> 417 | J26: =D26*F26 -> 166.8 | K26: =G26*D26 -> 1112 | L26: =MAX(I26,J26,K26,H26) -> 2755.3025
A27: =Zones!C27 -> Lounge, Breakroom, or Waiting Area | B27: =Zones!B27 -> Lounge_FloorM | C27: =Zones!K27 -> 16 | D27: =Zones!H27 -> 1059 | E27: 15 | F27: 0.15 | I27: =C27*E27 -> 240 | J27: =D27*F27 -> 158.85 | K27: =G27*D27 -> 0 | L27: =MAX(I27,J27,K27) -> 240
A28: =Zones!C28 -> Storage (General) | B28: =Zones!B28 -> Storage_FloorM | C28: =Zones!K28 -> 0 | D28: =Zones!H28 -> 983 | E28: 15 | F28: 0.15 | I28: =C28*E28 -> 0 | J28: =D28*F28 -> 147.45 | K28: =G28*D28 -> 0 | L28: =MAX(I28,J28,K28) -> 147.45
A29: =Zones!C29 -> Electrical, Mechanical, Telephone Rooms | B29: =Zones!B29 -> Mechanical/Electrical_FloorM | C29: =Zones!K29 -> 0 | D29: =Zones!H29 -> 357 | E29: 15 | F29: 0.15 | I29: =C29*E29 -> 0 | J29: =D29*F29 -> 53.55 | K29: =G29*D29 -> 0 | L29: =MAX(I29,J29,K29) -> 53.55
A30: =Zones!C30 -> IT Room (EPD 12) | B30: =Zones!B30 -> IT-Room_FloorM | C30: =Zones!K30 -> 0 | D30: =Zones!H30 -> 179 | E30: 15 | F30: 0.15 | I30: =C30*E30 -> 0 | J30: =D30*F30 -> 26.85 | K30: =G30*D30 -> 0 | L30: =MAX(I30,J30,K30) -> 26.85
A31: =Zones!C31 -> Restrooms | B31: =Zones!B31 -> Restroom_FloorM | C31: =Zones!K31 -> 0 | D31: =Zones!H31 -> 644 | E31: 15 | F31: 0.15 | G31: 4*50/70 cfm per unit | I31: =C31*E31 -> 0 | J31: =D31*F31 -> 96.6 | K31: =4*50 -> 200 | L31: =MAX(I31,J31,K31) -> 200
A32: =Zones!C32 -> Lounge, Breakroom, or Waiting Area | B32: =Zones!B32 -> BreakRoom/Kitchenette_FloorM | C32: =Zones!K32 -> 8 | D32: =Zones!H32 -> 232 | E32: 15 | F32: 0.15 | I32: =C32*E32 -> 120 | J32: =D32*F32 -> 34.8 | K32: =G32*D32 -> 0 | L32: =MAX(I32,J32,K32) -> 120
A33: =Zones!C33 -> Stairwell | B33: =Zones!B33 -> Stairway_FloorM | C33: =Zones!K33 -> 0 | D33: =Zones!H33 -> 661 | E33: 15 | F33: 0.15 | I33: =C33*E33 -> 0 | J33: =D33*F33 -> 99.15 | K33: =G33*D33 -> 0 | L33: =MAX(I33,J33,K33) -> 99.15
A34: =Zones!C34 -> Corridor Area | B34: =Zones!B34 -> Corridor_W_FloorM | C34: =Zones!K34 -> 2 | D34: =Zones!H34 -> 300 | E34: 15 | F34: 0.15 | I34: =C34*E34 -> 30 | J34: =D34*F34 -> 45 | K34: =G34*D34 -> 0 | L34: =MAX(I34,J34,K34) -> 45
A35: =Zones!C35 -> Corridor Area | B35: =Zones!B35 -> Corridor_N_FloorM | C35: =Zones!K35 -> 3 | D35: =Zones!H35 -> 503 | E35: 15 | F35: 0.15 | I35: =C35*E35 -> 45 | J35: =D35*F35 -> 75.45 | K35: =G35*D35 -> 0 | L35: =MAX(I35,J35,K35) -> 75.45
A36: =Zones!C36 -> Corridor Area | B36: =Zones!B36 -> Corridor_E_FloorM | C36: =Zones!K36 -> 2 | D36: =Zones!H36 -> 300 | E36: 15 | F36: 0.15 | I36: =C36*E36 -> 30 | J36: =D36*F36 -> 45 | K36: =G36*D36 -> 0 | L36: =MAX(I36,J36,K36) -> 45
A37: =Zones!C37 -> Corridor Area | B37: =Zones!B37 -> Corridor_S_FloorM | C37: =Zones!K37 -> 3 | D37: =Zones!H37 -> 503 | E37: 15 | F37: 0.15 | I37: =C37*E37 -> 45 | J37: =D37*F37 -> 75.45 | K37: =G37*D37 -> 0 | L37: =MAX(I37,J37,K37) -> 75.45
A38: =Zones!C38 -> Plenum | B38: =Zones!B38 -> Plenum_FloorM | C38: =Zones!K38 -> 0 | D38: =Zones!H38 -> 17876 | E38: 0 | F38: - | I38: =C38*E38 -> 0 | K38: =G38*D38 -> 0 | L38: =MAX(I38,J38,K38) -> 0
A39: =Zones!C39 -> Laboratory, Scientific | B39: =Zones!B39 -> Lab_Core_FloorT | C39: =(D39*25/1000) -> 107.075 | D39: =Zones!H39 -> 4283 | E39: 15 | F39: 0.15 | G39: 1 | H39: =G77 -> 10612.375 | I39: =C39*E39 -> 1606.125 | J39: =D39*F39 -> 642.45 | K39: =G39*D39 -> 4283 | L39: =MAX(I39,J39,K39,H39) -> 10612.375
A40: =Zones!C40 -> Laboratory, Scientific | B40: =Zones!B40 -> Lab_N_FloorT | C40: =(D40*25/1000) -> 57.45 | D40: =Zones!H40 -> 2298 | E40: 15 | F40: 0.15 | G40: 1 | H40: =G78 -> 5693.9614 | I40: =C40*E40 -> 861.75 | J40: =D40*F40 -> 344.7 | K40: =G40*D40 -> 2298 | L40: =MAX(I40,J40,K40,H40) -> 5693.9614
...

Sheet Water Heater
A1: Water Heater - Laboratory
A2: Vintage | B2: WH Type | C2: Efficiency | D2: Number of WH | E2: Tank Volume (gal) | F2: Tank Loss | G2: Source
A3: Existing | B3: Gas | C3: 0.8 | D3: 1 | E3: See table below for CZ-specific values: Climate Zone Water Heater Sizing and Loss Coefficients, Storage Volume column (col F) | F3: See table below: Climate Zone Water Heater Sizing and Loss Coefficients, Standby Loss column (col G) | G3: See table below for sources: Climate Zone Water Heater Sizing and Loss Coefficients
A4: New Construction | B4: Gas | C4: 0.8 | D4: 1 | E4: See table below for CZ-specific values: Climate Zone Water Heater Sizing and Loss Coefficients, Storage Volume column (col F) | F4: See table below: Climate Zone Water Heater Sizing and Loss Coefficients, Standby Loss column (col G) | G4: See table below for sources: Climate Zone Water Heater Sizing and Loss Coefficients
A7: Peak Hot Water Consumption
A8: Space Name | B8: Baseline WH Type [CEUS 2022] | C8: Total Area (ft²) | D8: Number of People | E8: Hot Water Usage Specification (gal/hr per person) [T24, 2022, Appendix 5.4A , sheet: "2022 SpaceFuncData-Input"] | F8: Peak Hot Water Usage (gal/hr) | G8: Peak Hot Water Usage (gal/min) | H8: Note
A9: =Zones!B3 -> Lab_Core_FloorG | B9: Gas* | C9: =Zones!H3 -> 4283 | D9: =Ventilation!C3 -> 107.075 | E9: 0.18 | F9: =E9*D9 -> 19.2735 | G9: =F9/60 -> 0.321225 | H9: For space types marked with an asterisk (the ‘*’ symbol), the water‑heater type is listed as electric in Appendix 5.4A, sheet ‘2022 SpaceFuncData‑Input.’ However, we modified the value based on CEUS data, which indicates that gas is the primary fuel type.
A10: =Zones!B4 -> Lab_N_FloorG | B10: Gas* | C10: =Zones!H4 -> 2298 | D10: =Ventilation!C4 -> 57.45 | E10: 0.18 | F10: =E10*D10 -> 10.341 | G10: =F10/60 -> 0.17235
A11: =Zones!B5 -> Enclosed_Office_W_FloorG | B11: Gas* | C11: =Zones!H5 -> 1638 | D11: =Ventilation!C5 -> 8 | E11: 0.18 | F11: =E11*D11 -> 1.44 | G11: =F11/60 -> 0.024
A12: =Zones!B6 -> Enclosed_Office_E_FloorG | B12: Gas* | C12: =Zones!H6 -> 1638 | D12: =Ventilation!C6 -> 8 | E12: 0.18 | F12: =E12*D12 -> 1.44 | G12: =F12/60 -> 0.024
A13: =Zones!B7 -> Lab_S_FloorG | B13: Gas* | C13: =Zones!H7 -> 1186 | D13: =Ventilation!C7 -> 29.65 | E13: 0.18 | F13: =E13*D13 -> 5.337 | G13: =F13/60 -> 0.08895
A14: =Zones!B8 -> Conference_FloorG | B14: Gas* | C14: =Zones!H8 -> 1112 | D14: =Ventilation!C8 -> 37 | E14: 0.09 | F14: =E14*D14 -> 3.33 | G14: =F14/60 -> 0.0555
A15: =Zones!B9 -> Lobby_FloorG | B15: Gas | C15: =Zones!H9 -> 1059 | D15: =Ventilation!C9 -> 11 | E15: 0.09 | F15: =E15*D15 -> 0.99 | G15: =F15/60 -> 0.0165
A16: =Zones!B10 -> Storage_FloorG | B16: Gas* | C16: =Zones!H10 -> 983 | D16: =Ventilation!C10 -> 0 | E16: 0 | F16: =E16*D16 -> 0 | G16: =F16/60 -> 0
A17: =Zones!B11 -> Mechanical/Electrical_FloorG | B17: Gas* | C17: =Zones!H11 -> 357 | D17: =Ventilation!C11 -> 0 | E17: 0.18 | F17: =E17*D17 -> 0 | G17: =F17/60 -> 0
A18: =Zones!B12 -> IT-Room_FloorG | B18: Gas* | C18: =Zones!H12 -> 179 | D18: =Ventilation!C12 -> 0 | E18: 0.18 | F18: =E18*D18 -> 0 | G18: =F18/60 -> 0
A19: =Zones!B13 -> Restroom_FloorG | B19: Gas | C19: =Zones!H13 -> 644 | D19: =Ventilation!C13 -> 0 | E19: 0 | F19: =E19*D19 -> 0 | G19: =F19/60 -> 0
A20: =Zones!B14 -> BreakRoom/Kitchenette_FloorG | B20: Gas | C20: =Zones!H14 -> 232 | D20: =Ventilation!C14 -> 8 | E20: 0.58 | F20: =E20*D20 -> 4.64 | G20: =F20/60 -> 0.077333333
A21: =Zones!B15 -> Stairway_FloorG | B21: Gas* | C21: =Zones!H15 -> 661 | D21: =Ventilation!C15 -> 0 | E21: 0 | F21: =E21*D21 -> 0 | G21: =F21/60 -> 0
... A25: =Zones!B19 -> Corridor_S_FloorG | B25: Gas* | C25: =Zones!H19 -> 503 | D25: =Ventilation!C19 -> 3 | E25: 0 | F25: =E25*D25 -> 0 | G25: =F25/60 -> 0
A26: =Zones!B20 -> Plenum_FloorG | C26: =Zones!H20 -> 17876 | D26: =Ventilation!C20 -> 0 | E26: 0 | F26: =E26*D26 -> 0 | G26: =F26/60 -> 0
A27: =Zones!B21 -> Lab_Core_FloorM | B27: Gas* | C27: =Zones!H21 -> 4283 | D27: =Ventilation!C21 -> 107.075 | E27: 0.18 | F27: =E27*D27 -> 19.2735 | G27: =F27/60 -> 0.321225
A28: =Zones!B22 -> Lab_N_FloorM | B28: Gas* | C28: =Zones!H22 -> 2298 | D28: =Ventilation!C22 -> 57.45 | E28: 0.18 | F28: =E28*D28 -> 10.341 | G28: =F28/60 -> 0.17235
A29: =Zones!B23 -> Lab_W_FloorM | B29: Gas* | C29: =Zones!H23 -> 1638 | D29: =Ventilation!C23 -> 40.95 | E29: 0.18 | F29: =E29*D29 -> 7.371 | G29: =F29/60 -> 0.12285
A30: =Zones!B24 -> Lab_E_FloorM | B30: Gas* | C30: =Zones!H24 -> 1638 | D30: =Ventilation!C24 -> 40.95 | E30: 0.18 | F30: =E30*D30 -> 7.371 | G30: =F30/60 -> 0.12285
A31: =Zones!B25 -> Lab_S_FloorM | B31: Gas* | C31: =Zones!H25 -> 1186 | D31: =Ventilation!C25 -> 29.65 | E31: 0.18 | F31: =E31*D31 -> 5.337 | G31: =F31/60 -> 0.08895
A32: =Zones!B26 -> Lab_FloorM | B32: Gas* | C32: =Zones!H26 -> 1112 | D32: =Ventilation!C26 -> 27.8 | E32: 0.09 | F32: =E32*D32 -> 2.502 | G32: =F32/60 -> 0.0417
A33: =Zones!B27 -> Lounge_FloorM | B33: Gas | C33: =Zones!H27 -> 1059 | D33: =Ventilation!C27 -> 16 | E33: 0.09 | F33: =E33*D33 -> 1.44 | G33: =F33/60 -> 0.024
A34: =Zones!B28 -> Storage_FloorM | B34: - | C34: =Zones!H28 -> 983 | D34: =Ventilation!C28 -> 0 | E34: 0 | F34: =E34*D34 -> 0 | G34: =F34/60 -> 0
A35: =Zones!B29 -> Mechanical/Electrical_FloorM | B35: Gas* | C35: =Zones!H29 -> 357 | D35: =Ventilation!C29 -> 0 | E35: 0.18 | F35: =E35*D35 -> 0 | G35: =F35/60 -> 0
A36: =Zones!B30 -> IT-Room_FloorM | B36: Gas* | C36: =Zones!H30 -> 179 | D36: =Ventilation!C30 -> 0 | E36: 0.18 | F36: =E36*D36 -> 0 | G36: =F36/60 -> 0
A37: =Zones!B31 -> Restroom_FloorM | B37: Gas | C37: =Zones!H31 -> 644 | D37: =Ventilation!C31 -> 0 | E37: 0 | F37: =E37*D37 -> 0 | G37: =F37/60 -> 0
A38: =Zones!B32 -> BreakRoom/Kitchenette_FloorM | B38: Gas | C38: =Zones!H32 -> 232 | D38: =Ventilation!C32 -> 8 | E38: 0.58 | F38: =E38*D38 -> 4.64 | G38: =F38/60 -> 0.077333333
... A43: =Zones!B37 -> Corridor_S_FloorM | B43: Gas* | C43: =Zones!H37 -> 503 | D43: =Ventilation!C37 -> 3 | E43: 0 | F43: =E43*D43 -> 0 | G43: =F43/60 -> 0
A44: =Zones!B38 -> Plenum_FloorM | C44: =Zones!H38 -> 17876 | D44: =Ventilation!C38 -> 0 | E44: 0 | F44: =E44*D44 -> 0 | G44: =F44/60 -> 0
A45: =Zones!B39 -> Lab_Core_FloorT | B45: Gas* | C45: =Zones!H39 -> 4283 | D45: =Ventilation!C39 -> 107.075 | E45: 0.18 | F45: =E45*D45 -> 19.2735 | G45: =F45/60 -> 0.321225
A46: =Zones!B40 -> Lab_N_FloorT | B46: Gas* | C46: =Zones!H40 -> 2298 | D46: =Ventilation!C40 -> 57.45 | E46: 0.18 | F46: =E46*D46 -> 10.341 | G46: =F46/60 -> 0.17235
A47: =Zones!B41 -> Enclosed_Office_W_FloorT | B47: Gas* | C47: =Zones!H41 -> 1638 | D47: =Ventilation!C41 -> 8 | E47: 0.18 | F47: =E47*D47 -> 1.44 | G47: =F47/60 -> 0.024
A48: =Zones!B42 -> Enclosed_Office_E_FloorT | B48: Gas* | C48: =Zones!H42 -> 1638 | D48: =Ventilation!C42 -> 8 | E48: 0.18 | F48: =E48*D48 -> 1.44 | G48: =F48/60 -> 0.024
A49: =Zones!B43 -> Lab_S_FloorT | B49: Gas* | C49: =Zones!H43 -> 1186 | D49: =Ventilation!C43 -> 29.65 | E49: 0.18 | F49: =E49*D49 -> 5.337 | G49: =F49/60 -> 0.08895
...

Sheet Interior Lights
A1: ="Interior Lighting - "&Prototype!B4 -> Interior Lighting - Laboratory
A2: Space Type | B2: New Construction | E2: Existing | H2: Notes
B3: Lighting density (W/ft²) | C3: Additional LPD for Portable Lighting (W/ft²) | D3: Source | E3: LPD (W/ft²) | F3: Additional LPD for Portable Lighting (W/ft²) | G3: Source
A4: =Zones!P27 -> Laboratory, Scientific | B4: 0.9 | C4: 0.35 | D4: T24, part 6, 2025, Table 140.6 C (Area category method) | E4: 1.4 | F4: 0.2 | G4: T24, part 6, 2016, Table 140.6 C (Area category method) | H4: Additional lighting for: Detailed Task Work
A5: =Zones!P28 -> Office Area (>250 square feet) | B5: 0.6 | C5: =0.2*0.5 -> 0.1 | E5: 0.75 | H5: Additional lighting for: decorative/display It is assumed that 50% of the additional allowance lighting is in use.
A6: =Zones!P29 -> Convention, Conference, Multipurpose and Meeting Area | B6: 0.75 | C6: =0.25*0.5 -> 0.125 | E6: 1.2 | F6: =0.5*0.5 -> 0.25 | H6: Additional lighting for: decorative/display
A7: =Zones!P30 -> Lobby, Main Entry | B7: 0.7 | C7: 0.25 | E7: 0.95 | F7: 0.5 | H7: Additional lighting for: decorative/display
A8: =Zones!P31 -> Storage (General) | B8: 0.4 | E8: 0.6
A9: =Zones!P32 -> Electrical, Mechanical, Telephone Rooms | B9: 0.4 | E9: 0.55
A10: =Zones!P33 -> IT Room (EPD 12) | B10: 0.75 | E10: 1.2
A11: =Zones!P34 -> Restrooms | B11: 0.65 | E11: 0.6
A12: =Zones!P35 -> Lounge, Breakroom, or Waiting Area | B12: 0.55 | C12: 0.25 | E12: 0.9 | F12: 0.5 | H12: Additional lighting for: decorative/display
A13: =Zones!P36 -> Stairwell | B13: 0.6 | E13: 0.6
A14: =Zones!P37 -> Corridor Area | B14: 0.4 | E14: 0.6

Sheet Ext Lighting
A1: ="Exterior Lighting - "&Prototype!B4 -> Exterior Lighting - Laboratory
A2: Motion Controlled Luminaires (W) | B2: Non-motion Controlled Luminaires (W) | C2: Total (W) | D2: Source
A3: =G15 -> 2533.08 | B3: =G16 -> 1392.3 | C3: =A3+B3 -> 3925.38 | D3: T24, 2022 & 2025 2019 Outdoor Lighting CASE report PNNL 90.1-2010 TSD
A7: ="Exterior Lighting" -> Exterior Lighting
