Workbook
Name nonparticipating_forecastzone_scale_factor: #REF!
Name nonparticipating_forecastzone_scale_factor: #REF!
Name nonparticipating_forecastzone_scale_factor: 'Energy Usage'!#REF!
Name Space_Function: Data!$A$2:$A$76

Sheet Notes
A1: Data Sources
A2: Dataset | B2: Dodge 2023
B3: CEUS 2022
B4: CBECS 2018
B5: ComStock 2023
A6: Prototype | B6: CEC prototype (CBECC 2022.3.1) | C6: https://bees.noresco.com/software2022.html
B7: PNNL prototype (90.1-2022) | C7: https://www.energycodes.gov/prototype-building-models#Commercial
B8: DEER prototype (June 2023) | C8: https://github.com/sound-data/DEER-Prototypes-EnergyPlus
A10: Codes | B10: Title 24, part 6, referred to as T24 (1986, 1992, 2001, 2007, 2013, 2016, 2019, 2022, 2025)
B11: ASHRAE 90.1 (2022)
A13: Others | B13: ACM (2013, 2019, 2022, 2025)
B14: Title 24, 2022 - Appendix 5.4A and Appendix 5.4B | C14: https://www.energy.ca.gov/publications/2022/2022-nonresidential-and-multifamily-alternative-calculation-method-reference
B15: 2022 Reduced infiltration CASE report | C15: https://title24stakeholders.com/wp-content/uploads/2020/10/2022-T24-Final-CASE-Report_Reduce-Infiltration.pdf
B16: 2019 Outdoor Lighting CASE Report | C16: https://title24stakeholders.com/wp-content/uploads/2016/10/T24-2019-CASE-Study-Results-Report-Outdoor-Sources_Final_with-Attachments.pdf
B17: PNNL 20405, 2011 | C17: https://www.pnnl.gov/main/publications/external/technical_reports/PNNL-20405.pdf
B18: Air leakage Memo, NORESCO, 2025 | C18: https://2050partners.sharepoint.com/:w:/r/sites/CalBEMCollaborativeEfforts/_layouts/15/Doc.aspx?sourcedoc=%7B3BEF8F74-7FAC-44F2-A70C-D76617660066%7D&file=Infiltration_rate_report_14May2025-Short-Version.docx&action=default&mobileredirect=true
B19: Design Guide: Advanced Water Heating for Foodservice (2022) (by GTI and Frontier funded by SoCalGas and Pacific Gas and Electric Company | C19: https://caenergywise.com/design-guides/hot-water/Technical_Design_Guide.pdf
B20: Design Guide 1: Improving Commercial Kitchen Ventilation System Performance : Selecting & Sizing Exhaust Hoods referred as CKV (2004) (by SCE) | C20: https://www.streivor.com/wp-content/uploads/2020/11/CKV-Design-Guide-1-Selecting-and-Sizing-Exhaust-Hoods.pdf
B21: Proposed Updates to Equipment Power Densities and Building Schedules for the 2028 Energy Code, referred to as "Plug load and schedules project with CEC, 2025" (Docket Number =25-BSTD-03 & TN=265693) | C21: https://efiling.energy.ca.gov/GetDocument.aspx?tn=265693&DocumentContentId=102545
A22: Water Heater | B22: ENERGY STAR certified commercial water heaters (gas storage input ≥76 kBtu/h; ES tank sizes) | C22: =HYPERLINK("https://www.energystar.gov/productfinder/product/certified-commercial-water-heaters/results?fuel_filter=Gas&markets_filter=United+States","ENERGY STAR product finder — gas") -> ENERGY STAR product finder — gas
B23: ENERGY STAR commercial WH dataset (download) | C23: =HYPERLINK("https://data.energystar.gov/Active-Specifications/ENERGY-STAR-Certified-Commercial-Water-Heaters/xmq6-bm79","ENERGY STAR dataset xmq6-bm79") -> ENERGY STAR dataset xmq6-bm79
B24: ENERGY STAR commercial WH eligibility (gas storage >75 kBtu/h) | C24: =HYPERLINK("https://www.energystar.gov/products/water_heaters/commercial_water_heaters/key_product_criteria","ENERGY STAR key product criteria") -> ENERGY STAR key product criteria
B25: Grainger gas tank water heaters (sizes below ES commercial, e.g. 30–75 kBtu/h) | C25: =HYPERLINK("https://www.grainger.com/category/plumbing/water-heaters/gas-tank-water-heaters","Grainger — gas tank WH") -> Grainger — gas tank WH
B26: Grainger electric tank water heaters (kW ladder, tank gallons) | C26: =HYPERLINK("https://www.grainger.com/category/plumbing/water-heaters/electric-tank-water-heaters","Grainger — electric tank WH") -> Grainger — electric tank WH
B27: ES commercial electric = heat pumps only; not used for resistance tank list | C27: =HYPERLINK("https://www.energystar.gov/productfinder/product/certified-commercial-water-heaters/results?fuel_filter=Electric&markets_filter=United+States","ENERGY STAR — electric (HPWH)") -> ENERGY STAR — electric (HPWH)
A36: Notes
A40: EIS, 2018: | B40: U.S. Energy Information Administration - EIA - Independent Statistics and Analysis
A71: Dodge Construction data , 2023

Sheet Prototype
A1: NORESCO, Updated September 2026
A2: RestaurantSitDown
A3: Characteristic | B3: Value | C3: Data Sources
A4: Building Type | B4: Sit Down Restaurant
A5: Building Category | B5: Nonresidential
A6: Vintages | B6: 4 Vintages: Pre-1978 , 1978-1997 ,1998-2007 , 2008-2018 New Construction (2019+) | C6: Based on the vintage bin analysis. A summary of the findings is presented in the following paper, with a link provided in the Notes tab: Yousefi, F., Athalye, R. (2025). “Determining Vintage Bins for Prototype Development: An Analysis of California Commercial Buildings.” ASHRAE Annual Conference.
A7: Shape | C7: PNNL prototype, 2022
A8: Total Floor Area (ft²) | B8: 5,502.1 (74.18 ft * 74.18 ft) | C8: PNNL prototype, 2022
A9: Aspect Ratio | B9: 1 | C9: PNNL prototype, 2022
A10: Number of Floors | B10: 1 | C10: PNNL prototype, 2022
A11: Roof type | B11: Attic (17°) | C11: PNNL prototype, 2022, suppoerted by CBECS 2018
A12: WWR | B12: Average 17.11% (South: 28% , East: 20.22% ,North: 0% ,West: 20.22% | C12: PNNL prototype, 2022
A13: Shading Geometry | B13: No shades | C13: PNNL prototype, 2021
A14: Floor to floor height (ft) | B14: N/A | C14: PNNL prototype, 2022
A15: Floor to ceiling height (ft) | B15: 10 | C15: PNNL prototype, 2022
A16: Glazing sill height (ft) | B16: 3.5 (top of the window is 6.5 ft high with 3 ft high glass) | C16: PNNL prototype, 2022
A26: Existing public prototypes
A28: Kitchen height: 10 ft
A29: https://www.naksinc.com/ceiling-height-and-cooking-equipment-specifications-for-hoods-an-in-depth-look/
C36: PNNL (Sit down) | D36: CPUC (Sit down) | F36: CEC (Small Restaurant)
A37: Geometry | B37: Whole building
A38: Floor area (ft²) | B38: Total | C38: 5502 | D38: 5602 | F38: 2500
A39: Height (ft) | B39: All | C39: 10 | D39: 10 | F39: 10
A40: Zones | C40: Dining 73% (4001.46 ft2), Kitchen 27% (1500.54 ft2), Attic (NOT conditioned) | D40: Dining 54% , Kitchen 29% , Waiting Area 14% , Restroom 4% (200 sf) | F40: Dining 50% , Kitchen 50%, Attic (NOT conditioned)
A41: Internal Load
A42: People (person/ft²) | B42: Dining | C42: 0.07 | D42: 0.033 | F42: 0.033
B43: Kitchen | C43: 0.005 (7.5 People) | D43: 0.0025 | F43: 0.0025
B44: Other zones (if any) | D44: 0.0033 Lobby & 0.005 Restroom | F44: -
A45: Lights (W/ft²) | B45: Dining | C45: 0.48 | D45: 0.4 | F45: 0.45
B46: Kitchen | C46: 0.78 | D46: 0.95 | F46: 0.95
B47: Other zones (if any) | D47: 0.7 Lobby & 0.65 Restroom
A48: Ext lights (W) | C48: 1509 (204 and 1305) | F48: -
A49: Gas Equipment (Btu/h-ft2) | B49: Kitchen | C49: 194.7 (292,164 Btu/h) | D49: 17.5 | F49: 32.4
A50: Electric Equipment (W/ft²) | B50: Dining | C50: 5.7 (22833 W) | D50: 0.5 | F50: 0.75 (0.5 receptacle & 0.25 refrigerator )
B51: Kitchen | C51: 35.91 (53,277 W Receptacle & 313 W ReachIn Refrigerator & 277 W ReachInFreezer) | D51: 2.62 (1.5 receptacle & 1.12 refrigerator) | F51: 2.62 (1.5 receptacle & 1.12 refrigerator)
B52: Other zones (if any) | D52: 0.5 Lobby
A54: Refrigerator | B54: Kitchen | C54: In addition to the Reachin freezer and refrigerator load defined as electric load, it has : 2 Case refrigerator : 716 and 763 Btu/hr-ft for 8 and 10 ft cases 2.5 COP for design compressor rack 1126 Btu/h for fan power of design compressor | D54: Refrigerator loads is defined as electric equipment load for kitchen | F54: Two Refrigerator loads is defined as electric equipment load for dining and kitchen
A56: Heating Sizing Factor | C56: H&C: 1.2 | D56: H: 2.5 , C: 2.3 | F56: H&C:1
A57: HVAC | B57: Dining | C57: PSZ AC: CAV no reheat, DX cooling coil: multi speed, Gas heating coil | D57: Single Zone VAV Reheat (Sys7)+ 1 DX cooling coil:multi speed + 1 water heating coil (+ 1 water heating coil for Reheat) Boiler (2 objects) | F57: (BAseAirSys 13): VAV no Reheat +DX cooling coil:two speed, Gas Heating coil
B58: Kitchen | C58: PSZ AC : CAV no reheat, DX cooling coil: multi speed, Gas heating coil | D58: Single Zone VAV no Reheat + 1 DX cooling coil:single speed + Gas heating coil | F58: (sys7or3a): CAV no Reheat+DX cooling coil: single speed+ Gas Heating coil
...

Sheet Zones
A1: ="Proposed Layout - "&Prototype!A2 -> Proposed Layout - RestaurantSitDown
A2: Building | B2: Space/Thermal Zone | C2: Space Type [Primarily from: T24, 2022 Appendix 5.4A] - See Notes column | D2: HVAC Zone | E2: Schedule Category | F2: Conditioned (Y/N) | G2: Area Fraction | H2: Area (ft²) | I2: Volume (ft³) | J2: Multipliers | K2: Number of People | L2: People (Persons/1,000 ft²) [T24, 2025,Table 120.1-A] | M2: Notes | O2: Kitchen (North) , Dining (south)
A3: RestaurantSitDown | B3: Dining | C3: Dining Area (Bar/Lounge and Fine Dining) | D3: AHU_1 | E3: Restaurant | F3: Y | G3: =H3/$H$6 -> 0.7272724 | H3: 4001.46 | I3: =H3*Prototype!$B$15 -> 40014.6 | J3: 1 | K3: =L3*H3/1000 -> 132.04818 | L3: 33
A4: RestaurantSitDown | B4: Kitchen | C4: Kitchen/Food Preparation Area | D4: AHU_2 | E4: Kitchen | F4: Y | G4: =H4/$H$6 -> 0.2727276 | H4: 1500.55 | I4: =H4*Prototype!$B$15 -> 15005.5 | J4: 1 | K4: =L4*H4/1000 -> 4.50165 | L4: 3
A5: RestaurantSitDown | B5: Attic | C5: Attic | D5: n/a | F5: N | H5: =H6 -> 5502.01 | I5: =H5*Prototype!$B$15 -> 55020.1 | J5: 1 | K5: =L5*H5/1000 -> 0
A6: Total (1 Building) | B6: Total (3 Space) | C6: Total (3 space type) | D6: Total ( 2 HVAC Zones) | E6: Total (2 category) | F6: Total (2 Conditioned zones) | G6: =SUM(G3:G4) -> 1 | H6: =SUM(H3:H4) -> 5502.01 | I6: =SUM(I3:I4) -> 55020.1

Sheet Envelope
A1: ="Envelope - "&Prototype!A2 -> Envelope - RestaurantSitDown
A2: Element | B2: Prototype | C2: Assembly Type | D2: Construction | E2: Thermal properties | F2: Vintage | G2: Selected T24 | H2: Notes | I2: CZ1 | J2: CZ2 | K2: CZ3 | L2: CZ4 | M2: CZ5 | N2: CZ6 | O2: CZ7 | P2: CZ8 | Q2: CZ9 | R2: CZ10 | S2: CZ11 | T2: CZ12 | U2: CZ13 | V2: CZ14 | W2: CZ15 | X2: CZ16
A3: External Wall | B3: =Prototype!A2 -> RestaurantSitDown | C3: ExtWall_MetalFramed_NonRes | D3: stucco + insulation +gypsum board | E3: U-factor IP | F3: Pre 1978 | G3: N/A | H3: ASHRAE 90.1, 2022 Table A3.3.3.1, 3.5", R-0 | I3: 0.352 | J3: 0.352 | K3: 0.352 | L3: 0.352 | M3: 0.352 | N3: 0.352 | O3: 0.352 | P3: 0.352 | Q3: 0.352 | R3: 0.352 | S3: 0.352 | T3: 0.352 | U3: 0.352 | V3: 0.352 | W3: 0.352 | X3: 0.352
F4: 1978-1997 | G4: 1986 | H4: Copied from low-rise office alternative table: Package A with heat capacity of 0.0-3.99 (Btu/F-ft²) | I4: =1/7.52 -> 0.13297872 | J4: =1/7.52 -> 0.13297872 | K4: =1/7.52 -> 0.13297872 | L4: =1/7.52 -> 0.13297872 | M4: =1/7.52 -> 0.13297872 | N4: =1/7.52 -> 0.13297872 | O4: =1/7.52 -> 0.13297872 | P4: =1/7.52 -> 0.13297872 | ... X4: =1/7.52 -> 0.13297872 | Y4: These values have better performance than the next vintage
F5: 1998-2007 | G5: 2001 | H5: Table 1-H | I5: 0.182 | J5: 0.182 | K5: 0.189 | L5: 0.189 | M5: 0.189 | N5: 0.189 | O5: 0.189 | P5: 0.189 | Q5: 0.189 | R5: 0.182 | S5: 0.182 | T5: 0.182 | U5: 0.182 | V5: 0.182 | W5: 0.182 | X5: 0.182
F6: 2008-2018 | G6: 2013 | H6: Table 140.3-B | I6: 0.098 | J6: 0.062 | K6: 0.082 | L6: 0.062 | M6: 0.062 | N6: 0.098 | O6: 0.098 | P6: 0.062 | Q6: 0.062 | R6: 0.062 | S6: 0.062 | T6: 0.062 | U6: 0.062 | V6: 0.062 | W6: 0.062 | X6: 0.062
F7: 2019+ | G7: 2025 | H7: Table 140.3-B | I7: 0.06 | J7: 0.055 | K7: 0.071 | L7: 0.055 | M7: 0.055 | N7: 0.06 | O7: 0.06 | P7: 0.055 | Q7: 0.055 | R7: 0.055 | S7: 0.055 | T7: 0.055 | U7: 0.055 | V7: 0.055 | W7: 0.055 | X7: 0.055
A8: Ceiling/Roof | B8: =B3 -> RestaurantSitDown | C8: AtticFloor Reversed | D8: Attic roof (no insulation): asphalt shingles + gypsum board Ceiling (wood-joist): insulation + gypsum board | E8: U-factor IP | F8: Pre 1978 | G8: N/A | H8: Considering 30 years for roof/ insulation replacement. | I8: =I9 -> 0.057 | J8: =J9 -> 0.057 | K8: =K9 -> 0.057 | L8: =L9 -> 0.057 | M8: =M9 -> 0.057 | N8: =N9 -> 0.078 | O8: =O9 -> 0.078 | P8: =P9 -> 0.078 | ... X8: =X9 -> 0.057
F9: 1978-1997 | G9: 1992 | I9: 0.057 | J9: 0.057 | K9: 0.057 | L9: 0.057 | M9: 0.057 | N9: 0.078 | O9: 0.078 | P9: 0.078 | Q9: 0.078 | R9: 0.078 | S9: 0.057 | T9: 0.057 | U9: 0.057 | V9: 0.057 | W9: 0.057 | X9: 0.057
F10: 1998-2007 | G10: 2001 | H10: Table 1-H | I10: 0.057 | J10: 0.057 | K10: 0.057 | L10: 0.057 | M10: 0.057 | N10: 0.078 | O10: 0.078 | P10: 0.078 | Q10: 0.078 | R10: 0.057 | S10: 0.057 | T10: 0.057 | U10: 0.057 | V10: 0.057 | W10: 0.057 | X10: 0.057
F11: 2008-2018 | G11: 2013 | H11: Table 140.3-B (Wood Framed and Other) | I11: 0.049 | J11: 0.039 | K11: 0.039 | L11: 0.039 | M11: 0.049 | N11: 0.075 | O11: 0.067 | P11: 0.067 | Q11: 0.039 | R11: 0.039 | S11: 0.039 | T11: 0.039 | U11: 0.039 | V11: 0.039 | W11: 0.039 | X11: 0.039
F12: 2019+ | G12: 2025 | H12: Table 140.3-B (Wood Framed and Other) | I12: 0.028 | J12: 0.028 | K12: 0.028 | L12: 0.028 | M12: 0.028 | N12: 0.047 | O12: 0.047 | P12: 0.047 | Q12: 0.028 | R12: 0.028 | S12: 0.028 | T12: 0.028 | U12: 0.028 | V12: 0.028 | W12: 0.028 | X12: 0.028
A13: Windows | B13: =B3 -> RestaurantSitDown | C13: FixedWindow_NonRes | D13: Single Pane (CBECS 2018, ~ 30 % of windows of Restaurant built before 2000 are single pane) | E13: U-factor IP | F13: Pre 1978 | G13: N/A | H13: 2021 ASHRAE Handbook of Fundamentals for single pane (Table 4- Ch15, Section 15.9) & T24, 2013 Table 140.3-B for double pane (30%-70%) | I13: =0.3*1.12+0.7*I16 -> 0.588 | J13: =0.3*1.12+0.7*J16 -> 0.588 | K13: =0.3*1.12+0.7*K16 -> 0.588 | L13: =0.3*1.12+0.7*L16 -> 0.588 | M13: =0.3*1.12+0.7*M16 -> 0.588 | N13: =0.3*1.12+0.7*N16 -> 0.588 | O13: =0.3*1.12+0.7*O16 -> 0.588 | P13: =0.3*1.12+0.7*P16 -> 0.588 | ... X13: =0.3*1.12+0.7*X16 -> 0.588
F14: 1978-1997 | G14: N/A | I14: =I13 -> 0.588 | J14: =J13 -> 0.588 | K14: =K13 -> 0.588 | L14: =L13 -> 0.588 | M14: =M13 -> 0.588 | N14: =N13 -> 0.588 | O14: =O13 -> 0.588 | P14: =P13 -> 0.588 | ... X14: =X13 -> 0.588 | Y14: These vintages have better performance because of partial retrofit
D15: Double pane | F15: 1998-2007 | G15: 2001 | H15: Table 1-H | I15: 0.49 | J15: 0.49 | K15: 0.81 | L15: 0.81 | M15: 0.81 | N15: 0.81 | O15: 0.81 | P15: 0.81 | Q15: 0.81 | R15: 0.49 | S15: 0.49 | T15: 0.49 | U15: 0.49 | V15: 0.49 | W15: 0.49 | X15: 0.49
F16: 2008-2018 | G16: 2013 | H16: Table 140.3-B | I16: 0.36 | J16: 0.36 | K16: 0.36 | L16: 0.36 | M16: 0.36 | N16: 0.36 | O16: 0.36 | P16: 0.36 | Q16: 0.36 | R16: 0.36 | S16: 0.36 | T16: 0.36 | U16: 0.36 | V16: 0.36 | W16: 0.36 | X16: 0.36
F17: 2019+ | G17: 2025 | H17: Table 140.3-B | I17: 0.36 | J17: 0.36 | K17: 0.36 | L17: 0.36 | M17: 0.36 | N17: 0.36 | O17: 0.36 | P17: 0.36 | Q17: 0.34 | R17: 0.36 | S17: 0.34 | T17: 0.34 | U17: 0.34 | V17: 0.34 | W17: 0.34 | X17: 0.36
D18: Single Pane (CBECS 2018, ~ 30 % of windows of Restaurant built before 2000 are single pane) | E18: SHGC | F18: Pre 1978 | G18: N/A | H18: 2021 ASHRAE Handbook of Fundamentals for single pane (Table 10- Ch15, Section 15.22) & T24, 2013 Table 140.3-B for double pane (30%-70%) | I18: =0.79*0.3+I21*0.7 -> 0.412 | J18: =0.79*0.3+J21*0.7 -> 0.412 | K18: =0.79*0.3+K21*0.7 -> 0.412 | L18: =0.79*0.3+L21*0.7 -> 0.412 | M18: =0.79*0.3+M21*0.7 -> 0.412 | N18: =0.79*0.3+N21*0.7 -> 0.412 | O18: =0.79*0.3+O21*0.7 -> 0.412 | P18: =0.79*0.3+P21*0.7 -> 0.412 | ... X18: =0.79*0.3+X21*0.7 -> 0.412
F19: 1978-1997 | G19: N/A | I19: =I18 -> 0.412 | J19: =J18 -> 0.412 | K19: =K18 -> 0.412 | L19: =L18 -> 0.412 | M19: =M18 -> 0.412 | N19: =N18 -> 0.412 | O19: =O18 -> 0.412 | P19: =P18 -> 0.412 | ... X19: =X18 -> 0.412 | Y19: These vintages have better performance because of partial retrofit
D20: Double pane | F20: 1998-2007 | G20: 2001 | H20: Table 1-H (Non North, 10-20% total WWR) | I20: 0.43 | J20: 0.36 | K20: 0.55 | L20: 0.55 | M20: 0.55 | N20: 0.61 | O20: 0.61 | P20: 0.61 | Q20: 0.61 | R20: 0.36 | S20: 0.36 | T20: 0.36 | U20: 0.36 | V20: 0.36 | W20: 0.36 | X20: 0.43
F21: 2008-2018 | G21: 2013 | H21: Table 140.3-B | I21: 0.25 | J21: 0.25 | K21: 0.25 | L21: 0.25 | M21: 0.25 | N21: 0.25 | O21: 0.25 | P21: 0.25 | Q21: 0.25 | R21: 0.25 | S21: 0.25 | T21: 0.25 | U21: 0.25 | V21: 0.25 | W21: 0.25 | X21: 0.25
F22: 2019+ | G22: 2025 | H22: Table 140.3-B | I22: 0.25 | J22: 0.25 | K22: 0.25 | L22: 0.25 | M22: 0.25 | N22: 0.25 | O22: 0.25 | P22: 0.25 | Q22: 0.22 | R22: 0.25 | S22: 0.22 | T22: 0.22 | U22: 0.22 | V22: 0.22 | W22: 0.22 | X22: 0.25
C24: Infiltration
D25: Building | E25: Zones | F25: Vintage | G25: I_75 (cfm/ft2) 6-sdied Infiltration rate @ 75 pa | H25: Source | I25: I-design (cfm/ft²) (4-sided Infiltration rate at normal pressure) (Design flow rate approach and Flow/Exterior Wall Area calculation method)
C26: Infiltration | D26: RestaurantSitDown | F26: Pre 1978 | G26: 1.1 | H26: 2022 CASE report (Table 38) | I26: =0.112*G26*$F$36 -> 0.580272
F27: 1978-1997 | G27: 1.1 | H27: 2022 CASE report (Table 38) | I27: =0.112*G27*$F$36 -> 0.580272
F28: 1998-2007 | G28: 1.1 | H28: 2022 CASE report (Table 38) | I28: =0.112*G28*$F$36 -> 0.580272
F29: 2008-2018 | G29: 1 | H29: 2022 CASE report (Table 38) & T24, 2008-2016 (Table 140.3-B) | I29: =0.112*G29*$F$36 -> 0.52752
F30: 2019+ | G30: 0.6 | H30: 2022 CASE report (Table 38) & T24, 2025 (Table 140.3-B) | I30: =0.112*G30*$F$36 -> 0.316512
E31: Source: T24 air barrier requirements (all editions) , the standardized infiltration rate reported in the 2022 CASE report, and Dodge 2023 data
E32: Infiltration_rate_report_14May2025-Short-Version.docx
E34: 6 sided area | F34: =(74.2*4)*10+(74.2^2)*2 -> 13979.28
E35: 4 sided area | F35: =(74.2*4)*10 -> 2968
E36: 6 sided/4sided fraction | F36: =F34/F35 -> 4.71

Sheet HVAC System
A1: ="HVAC system - "&Prototype!A2 -> HVAC system - RestaurantSitDown
A2: Vintage | B2: Space/Thermal Zone | C2: Heating | D2: Cooling | E2: Air Distribution | F2: Other Systems | G2: Source
A3: Existing | B3: Dining | C3: Gas Furnace (PSZAC) | D3: DX Coil (PSZAC) | E3: CAV (PSZAC) | F3: Economizer for after 2008 | G3: CEUS 2022 + Engineering Judgement
B4: Kitchen | C4: Gas Furnace (PSZAC) | D4: DX Coil (PSZAC) | E4: CAV (PSZAC) | F4: Makeup Air Unit (Combo with RTU) to supply make-up air exceeding transfer air from dining space (can be included in system13b)
A5: New Construction | B5: Dining | C5: Gas Furnace (PSZAC) | D5: DX Coil (PSZAC) | E5: CAV (PSZAC) | F5: Economizer | G5: T24, 2025
B6: Kitchen | C6: Gas Furnace (PSZAC) | D6: DX Coil (PSZAC) | E6: CAV (PSZAC) | F6: HR-Makeup Air Unit (systems that integrate make-up air and heat recovery functions) (can be included in system13b)
A7: *CPUC considres Boiler in the Dining space for heating
A11: Efficiency of HVAC System (Efficiency is capacity-dependent. The following table provides a general estimate of system efficiency based on preliminary simulations in one climate zone, or assuming cooling load based on rule of thumb)
A12: Vintage | B12: Upgrade/Installed year | C12: Gas Furnace | D12: Dining DX cooling (>=65,000 and < 135,000 Btu/h ) | E12: Kitchen DX cooling (>=65,000 and < 135,000 Btu/h ) | F12: Source | G12: Note
A13: Pre 1978 | B13: 2008 | C13: Efficiency 80% | D13: EER 10.3 | E13: EER 10.3 | F13: T24, 2008, Table 112-A | G13: Econ Max Position=0.9. *Econ Max Position is set to below 1 to approximate effects of not having fault detection and diagnostics (FDD) requirements, which began in 2013. it can be modeled in E+ either by: - Reducing Maximum Outdoor Air Flow Rate in Controller:OutdoorAir. - Or using FaultModel objects to simulate pre-2013 “no FDD” conditions
A14: 1978-1997
A15: 1998-2007
A16: 2008-2018 | B16: 2013 | C16: Efficiency 80% | D16: EER 11.2 | E16: EER 11.2 | F16: T24, 2013, Table 110.2-A | G16: Econ Max Position=0.9
A17: New Construction | B17: 2025 | C17: Efficiency 80% | D17: EER 11.2 | E17: EER 11.2 | F17: T24, 2025, Table 110.2-A | G17: - Econ Max Position=1 - Deduct 0.2 from the required EERs and IEERs for units with a heating section other than electric resistance heat.
A21: Fan Power
A22: Vintage | B22: Approach | C22: System | D22: Total Static Pressure (TSP) (in w.c.) | E22: Fan Efficiency [ACM 2025] | F22: Motor Efficiency | G22: Fan Power Index (W/cfm) | H22: Data Source
A23: Existing | B23: PNNL TSP | C23: CAV Kitchen (system <7,437 cfm) | D23: 2.5 | E23: 0.65 | F23: ~0.9 (The full-load efficiency of the motor serving the fan- will be determined based on ACM 2025, Table 13) | H23: TSP: [PNNL 20405, 2010, Table 5.11, Fan, motor and drive efficiency: ACM 2025
C24: CAV Dining (system <7,437 cfm) CAV Dining (system >7,437 cfm) | D24: 2.5 (system <7,437 cfm) 4.46 (system >7,437 cfm) | E24: 0.65
A25: Brake horsepower (bhp) = (Supply cfm × TSP in w.c.) / (6356 × fan efficiency)
A26: Fan power (w/cfm) = (bhp × 746) / ( supply cfm × motor efficiency )
A27: New Construction | B27: ACM 2025 | C27: CAV Kitchen (system <5,000 cfm) | D27: =G27*$F$27*$E$27/746*6356 -> 3.9973787 | E27: 0.65 | F27: 0.9 | G27: 0.802 | H27: ACM 2025
C28: CAV Dining (system >5,000 cfm and <10,000 cfm) | D28: =G28*$F$27*$E$27/746*6356 -> 3.8877249 | G28: 0.78
F29: * 0.9 is an average fan efficiency according to ACM 2025, Table 13
A30: Fan total eff (E+ input) = 0.65 x Motor_eff
A31: TSP (E+ input) in w.c. = Motor_eff/746 x (6356 x Fan_eff) x W/cfm
A32: Fan_eff=0.65

Sheet Heating-No area used to convert
A1: Small Office Heating System | B1: Only Conversion factors | F1: Multiplied by Floor area at FZ level | J1: No. of zones with | Z1: Converting the FZ data to the CZ level by applying total small office floor area in each FZ
B2: =AA28 -> Saturation (Electric) | C2: =AA2 -> Saturation (Gas) | D2: =AA55 -> Saturation (Other Fuels) | F2: ='HVAC System'!#REF! -> #REF! | G2: ='HVAC System'!#REF! -> #REF! | H2: ='HVAC System'!#REF! -> #REF! | J2: Elec | K2: Gas | O2: Forecast Zone | P2: Building-type | Q2: End Use | R2: End Use Saturation | S2: Electric Fuel Share | T2: Gas Fuel Share | U2: Other Fuel Share | V2: Saturation (Electric) | W2: Saturation (Gas) | X2: Saturation (Other Fuels) | AA2: Saturation (Gas) | AB2: 1 | AC2: 2 | AD2: 3 | AE2: 4 | AF2: 5 | AG2: 6 | AH2: 7 | AI2: 8 | AJ2: 9 | AK2: 10 | AL2: 11 | AM2: 12 | AN2: 13 | AO2: 14 | AP2: 15 | AQ2: 16
A3: 1 | B3: =AB51 -> #REF! | C3: =AB25 -> #REF! | D3: =AB78 -> #REF! | F3: ='HVAC System'!#REF! -> #REF! | G3: ='HVAC System'!#REF! -> #REF! | H3: ='HVAC System'!#REF! -> #REF! | J3: 1 | K3: 4 | M3: =B3-F3 -> #REF! | O3: Statewide | P3: Office, Small | Q3: Heating | R3: 0.91160159 | S3: 0.43376662 | T3: 0.55528365 | U3: 0.010949729 | V3: 0.39542234 | W3: 0.50619745 | X3: 0.0099817906 | Z3: FZ0 | AA3: =AA18 -> 0.72768161 | AB3: =$AA3*#REF! -> #REF! | AC3: =$AA3*#REF! -> #REF! | AD3: =$AA3*#REF! -> #REF! | AE3: =$AA3*#REF! -> #REF! | AF3: =$AA3*#REF! -> #REF! | AG3: =$AA3*#REF! -> #REF! | AH3: =$AA3*#REF! -> #REF! | AI3: =$AA3*#REF! -> #REF! | ... AQ3: =$AA3*#REF! -> #REF!
A4: 2 | B4: =AC51 -> #REF! | C4: =AC25 -> #REF! | D4: =AC78 -> #REF! | F4: ='HVAC System'!#REF! -> #REF! | G4: ='HVAC System'!#REF! -> #REF! | H4: ='HVAC System'!#REF! -> #REF! | J4: 0 | K4: 5 | M4: =B4-F4 -> #REF! | O4: FCZ1 | P4: Office, Small | Q4: Heating | R4: 0.91301514 | S4: 0.30732839 | T4: 0.68379277 | U4: 0.0088788345 | V4: 0.28059547 | W4: 0.62431315 | X4: 0.0081065103 | Z4: FCZ1 | AA4: =W4 -> 0.62431315 | AB4: =$AA4*#REF! -> #REF! | AC4: =$AA4*#REF! -> #REF! | AD4: =$AA4*#REF! -> #REF! | AE4: =$AA4*#REF! -> #REF! | AF4: =$AA4*#REF! -> #REF! | AG4: =$AA4*#REF! -> #REF! | AH4: =$AA4*#REF! -> #REF! | AI4: =$AA4*#REF! -> #REF! | ... AQ4: =$AA4*#REF! -> #REF!
A5: 3 | B5: =AD51 -> #REF! | C5: =AD25 -> #REF! | D5: =AD78 -> #REF! | F5: ='HVAC System'!#REF! -> #REF! | G5: ='HVAC System'!#REF! -> #REF! | H5: ='HVAC System'!#REF! -> #REF! | J5: 1 | K5: 4 | M5: =B5-F5 -> #REF! | O5: FCZ2 | P5: Office, Small | Q5: Heating | R5: 0.86214134 | S5: 0.11930353 | T5: 0.81413327 | U5: 0.066563197 | V5: 0.10285651 | W5: 0.70189795 | X5: 0.057386884 | Z5: FCZ2 | AA5: =W5 -> 0.70189795 | AB5: =$AA5*#REF! -> #REF! | AC5: =$AA5*#REF! -> #REF! | AD5: =$AA5*#REF! -> #REF! | AE5: =$AA5*#REF! -> #REF! | AF5: =$AA5*#REF! -> #REF! | AG5: =$AA5*#REF! -> #REF! | AH5: =$AA5*#REF! -> #REF! | AI5: =$AA5*#REF! -> #REF! | ... AQ5: =$AA5*#REF! -> #REF!
A6: 4 | B6: =AE51 -> #REF! | C6: =AE25 -> #REF! | D6: =AE78 -> #REF! | F6: ='HVAC System'!#REF! -> #REF! | G6: ='HVAC System'!#REF! -> #REF! | H6: ='HVAC System'!#REF! -> #REF! | J6: 1 | K6: 4 | M6: =B6-F6 -> #REF! | O6: FCZ3 | P6: Office, Small | Q6: Heating | R6: 0.89761067 | S6: 0.25361458 | T6: 0.66491077 | U6: 0.081474649 | V6: 0.22764715 | W6: 0.596831 | X6: 0.073132514 | Z6: FCZ3 | AA6: =W6 -> 0.596831 | AB6: =$AA6*#REF! -> #REF! | AC6: =$AA6*#REF! -> #REF! | AD6: =$AA6*#REF! -> #REF! | AE6: =$AA6*#REF! -> #REF! | AF6: =$AA6*#REF! -> #REF! | AG6: =$AA6*#REF! -> #REF! | AH6: =$AA6*#REF! -> #REF! | AI6: =$AA6*#REF! -> #REF! | ... AQ6: =$AA6*#REF! -> #REF!
A7: 5 | B7: =AF51 -> #REF! | C7: =AF25 -> #REF! | D7: =AF78 -> #REF! | F7: ='HVAC System'!#REF! -> #REF! | G7: ='HVAC System'!#REF! -> #REF! | H7: ='HVAC System'!#REF! -> #REF! | J7: 1 | K7: 4 | M7: =B7-F7 -> #REF! | O7: FCZ4 | P7: Office, Small | Q7: Heating | R7: 0.89761067 | S7: 0.25361458 | T7: 0.66491077 | U7: 0.081474649 | V7: 0.22764715 | W7: 0.596831 | X7: 0.073132514 | Z7: FCZ4 | AA7: =W7 -> 0.596831 | AB7: =$AA7*#REF! -> #REF! | AC7: =$AA7*#REF! -> #REF! | AD7: =$AA7*#REF! -> #REF! | AE7: =$AA7*#REF! -> #REF! | AF7: =$AA7*#REF! -> #REF! | AG7: =$AA7*#REF! -> #REF! | AH7: =$AA7*#REF! -> #REF! | AI7: =$AA7*#REF! -> #REF! | ... AQ7: =$AA7*#REF! -> #REF!
A8: 6 | B8: =AG51 -> #REF! | C8: =AG25 -> #REF! | D8: =AG78 -> #REF! | F8: ='HVAC System'!#REF! -> #REF! | G8: ='HVAC System'!#REF! -> #REF! | H8: ='HVAC System'!#REF! -> #REF! | J8: 3 | K8: 2 | M8: =B8-F8 -> #REF! | O8: FCZ5 | P8: Office, Small | Q8: Heating | R8: 0.92215011 | S8: 0.20498209 | T8: 0.78911405 | U8: 0.005903857 | V8: 0.18902426 | W8: 0.72768161 | X8: 0.0054442424 | Z8: FCZ5 | AA8: =W8 -> 0.72768161 | AB8: =$AA8*#REF! -> #REF! | AC8: =$AA8*#REF! -> #REF! | AD8: =$AA8*#REF! -> #REF! | AE8: =$AA8*#REF! -> #REF! | AF8: =$AA8*#REF! -> #REF! | AG8: =$AA8*#REF! -> #REF! | AH8: =$AA8*#REF! -> #REF! | AI8: =$AA8*#REF! -> #REF! | ... AQ8: =$AA8*#REF! -> #REF!
A9: 7 | B9: =AH51 -> #REF! | C9: =AH25 -> #REF! | D9: =AH78 -> #REF! | F9: ='HVAC System'!#REF! -> #REF! | G9: ='HVAC System'!#REF! -> #REF! | H9: ='HVAC System'!#REF! -> #REF! | J9: 2 | K9: 3 | M9: =B9-F9 -> #REF! | O9: FCZ6 | P9: Office, Small | Q9: Heating | R9: 0.92647551 | S9: 0.25462062 | T9: 0.74336959 | U9: 0.0020097902 | V9: 0.23589977 | W9: 0.68871372 | X9: 0.0018620214 | Z9: FCZ6 | AA9: =W9 -> 0.68871372 | AB9: =$AA9*#REF! -> #REF! | AC9: =$AA9*#REF! -> #REF! | AD9: =$AA9*#REF! -> #REF! | AE9: =$AA9*#REF! -> #REF! | AF9: =$AA9*#REF! -> #REF! | AG9: =$AA9*#REF! -> #REF! | AH9: =$AA9*#REF! -> #REF! | AI9: =$AA9*#REF! -> #REF! | ... AQ9: =$AA9*#REF! -> #REF!
A10: 8 | B10: =AI51 -> #REF! | C10: =AI25 -> #REF! | D10: =AI78 -> #REF! | F10: ='HVAC System'!#REF! -> #REF! | G10: ='HVAC System'!#REF! -> #REF! | H10: ='HVAC System'!#REF! -> #REF! | J10: 3 | K10: 2 | M10: =B10-F10 -> #REF! | O10: FCZ7 | P10: Office, Small | Q10: Heating | R10: 0.95232641 | S10: 0.66151275 | T10: 0.33848725 | U10: 0 | V10: 0.62997607 | W10: 0.32235034 | X10: 0 | Z10: FCZ7 | AA10: =W10 -> 0.32235034 | AB10: =$AA10*#REF! -> #REF! | AC10: =$AA10*#REF! -> #REF! | AD10: =$AA10*#REF! -> #REF! | AE10: =$AA10*#REF! -> #REF! | AF10: =$AA10*#REF! -> #REF! | AG10: =$AA10*#REF! -> #REF! | AH10: =$AA10*#REF! -> #REF! | AI10: =$AA10*#REF! -> #REF! | ... AQ10: =$AA10*#REF! -> #REF!
A11: 9 | B11: =AJ51 -> #REF! | C11: =AJ25 -> #REF! | D11: =AJ78 -> #REF! | F11: ='HVAC System'!#REF! -> #REF! | G11: ='HVAC System'!#REF! -> #REF! | H11: ='HVAC System'!#REF! -> #REF! | J11: 3 | K11: 2 | M11: =B11-F11 -> #REF! | O11: FCZ8 | P11: Office, Small | Q11: Heating | R11: 0.93208847 | S11: 0.5412083 | T11: 0.4587917 | U11: 0 | V11: 0.50445402 | W11: 0.42763446 | X11: 0 | Z11: FCZ8 | AA11: =W11 -> 0.42763446 | AB11: =$AA11*#REF! -> #REF! | AC11: =$AA11*#REF! -> #REF! | AD11: =$AA11*#REF! -> #REF! | AE11: =$AA11*#REF! -> #REF! | AF11: =$AA11*#REF! -> #REF! | AG11: =$AA11*#REF! -> #REF! | AH11: =$AA11*#REF! -> #REF! | AI11: =$AA11*#REF! -> #REF! | ... AQ11: =$AA11*#REF! -> #REF!
A12: 10 | B12: =AK51 -> #REF! | C12: =AK25 -> #REF! | D12: =AK78 -> #REF! | F12: ='HVAC System'!#REF! -> #REF! | G12: ='HVAC System'!#REF! -> #REF! | H12: ='HVAC System'!#REF! -> #REF! | J12: 2 | K12: 3 | M12: =B12-F12 -> #REF! | O12: FCZ9 | P12: Office, Small | Q12: Heating | R12: 0.94526481 | S12: 0.059542838 | T12: 0.91122329 | U12: 0.029233869 | V12: 0.056283749 | W12: 0.86134731 | X12: 0.027633748 | Z12: FCZ9 | AA12: =W12 -> 0.86134731 | AB12: =$AA12*#REF! -> #REF! | AC12: =$AA12*#REF! -> #REF! | AD12: =$AA12*#REF! -> #REF! | AE12: =$AA12*#REF! -> #REF! | AF12: =$AA12*#REF! -> #REF! | AG12: =$AA12*#REF! -> #REF! | AH12: =$AA12*#REF! -> #REF! | AI12: =$AA12*#REF! -> #REF! | ... AQ12: =$AA12*#REF! -> #REF!
A13: 11 | B13: =AL51 -> #REF! | C13: =AL25 -> #REF! | D13: =AL78 -> #REF! | F13: ='HVAC System'!#REF! -> #REF! | G13: ='HVAC System'!#REF! -> #REF! | H13: ='HVAC System'!#REF! -> #REF! | J13: 1 | K13: 4 | M13: =B13-F13 -> #REF! | O13: FCZ10 | P13: Office, Small | Q13: Heating | R13: 0.91238163 | S13: 0.45969281 | T13: 0.54030719 | U13: 0 | V13: 0.41941528 | W13: 0.49296635 | X13: 0 | Z13: FCZ10 | AA13: =W13 -> 0.49296635 | AB13: =$AA13*#REF! -> #REF! | AC13: =$AA13*#REF! -> #REF! | AD13: =$AA13*#REF! -> #REF! | AE13: =$AA13*#REF! -> #REF! | AF13: =$AA13*#REF! -> #REF! | AG13: =$AA13*#REF! -> #REF! | AH13: =$AA13*#REF! -> #REF! | AI13: =$AA13*#REF! -> #REF! | ... AQ13: =$AA13*#REF! -> #REF!
A14: 12 | B14: =AM51 -> #REF! | C14: =AM25 -> #REF! | D14: =AM78 -> #REF! | F14: ='HVAC System'!#REF! -> #REF! | G14: ='HVAC System'!#REF! -> #REF! | H14: ='HVAC System'!#REF! -> #REF! | J14: 1 | K14: 4 | M14: =B14-F14 -> #REF! | O14: FCZ11 | P14: Office, Small | Q14: Heating | R14: 0.98089904 | S14: 0.53514277 | T14: 0.45769447 | U14: 0.0071627591 | V14: 0.52492103 | W14: 0.44895207 | X14: 0.0070259435 | Z14: FCZ11 | AA14: =W14 -> 0.44895207 | AB14: =$AA14*#REF! -> #REF! | AC14: =$AA14*#REF! -> #REF! | AD14: =$AA14*#REF! -> #REF! | AE14: =$AA14*#REF! -> #REF! | AF14: =$AA14*#REF! -> #REF! | AG14: =$AA14*#REF! -> #REF! | AH14: =$AA14*#REF! -> #REF! | AI14: =$AA14*#REF! -> #REF! | ... AQ14: =$AA14*#REF! -> #REF!
A15: 13 | B15: =AN51 -> #REF! | C15: =AN25 -> #REF! | D15: =AN78 -> #REF! | F15: ='HVAC System'!#REF! -> #REF! | G15: ='HVAC System'!#REF! -> #REF! | H15: ='HVAC System'!#REF! -> #REF! | J15: 1 | K15: 4 | M15: =B15-F15 -> #REF! | O15: FCZ12c | P15: Office, Small | Q15: Heating | R15: 0.90055976 | S15: 0.57985696 | T15: 0.41763915 | U15: 0.0025038818 | V15: 0.52219585 | W15: 0.37610902 | X15: 0.0022548952 | Z15: FCZ12 | AA15: =(W15+W16)/2 -> 0.44192117 | AB15: =$AA15*#REF! -> #REF! | AC15: =$AA15*#REF! -> #REF! | AD15: =$AA15*#REF! -> #REF! | AE15: =$AA15*#REF! -> #REF! | AF15: =$AA15*#REF! -> #REF! | AG15: =$AA15*#REF! -> #REF! | AH15: =$AA15*#REF! -> #REF! | AI15: =$AA15*#REF! -> #REF! | ... AQ15: =$AA15*#REF! -> #REF!
A16: 14 | B16: =AO51 -> #REF! | C16: =AO25 -> #REF! | D16: =AO78 -> #REF! | F16: ='HVAC System'!#REF! -> #REF! | G16: ='HVAC System'!#REF! -> #REF! | H16: ='HVAC System'!#REF! -> #REF! | J16: 3 | K16: 2 | M16: =B16-F16 -> #REF! | O16: FCZ12i | P16: Office, Small | Q16: Heating | R16: 0.87840233 | S16: 0.4205928 | T16: 0.57801911 | U16: 0.0013880902 | V16: 0.3694497 | W16: 0.50773333 | X16: 0.0012193017 | Z16: FCZ13 | AA16: =W17 -> 0.53370716 | AB16: =$AA16*#REF! -> #REF! | AC16: =$AA16*#REF! -> #REF! | AD16: =$AA16*#REF! -> #REF! | AE16: =$AA16*#REF! -> #REF! | AF16: =$AA16*#REF! -> #REF! | AG16: =$AA16*#REF! -> #REF! | AH16: =$AA16*#REF! -> #REF! | AI16: =$AA16*#REF! -> #REF! | ... AQ16: =$AA16*#REF! -> #REF!
A17: 15 | B17: =AP51 -> #REF! | C17: =AP25 -> #REF! | D17: =AP78 -> #REF! | F17: ='HVAC System'!#REF! -> #REF! | G17: ='HVAC System'!#REF! -> #REF! | H17: ='HVAC System'!#REF! -> #REF! | J17: 3 | K17: 2 | M17: =B17-F17 -> #REF! | O17: FCZ13 | P17: Office, Small | Q17: Heating | R17: 0.86848685 | S17: 0.38547468 | T17: 0.61452532 | U17: 0 | V17: 0.33477969 | W17: 0.53370716 | X17: 0 | Z17: FCZ14 | AA17: =W8 -> 0.72768161 | AB17: =$AA17*#REF! -> #REF! | AC17: =$AA17*#REF! -> #REF! | AD17: =$AA17*#REF! -> #REF! | AE17: =$AA17*#REF! -> #REF! | AF17: =$AA17*#REF! -> #REF! | AG17: =$AA17*#REF! -> #REF! | AH17: =$AA17*#REF! -> #REF! | AI17: =$AA17*#REF! -> #REF! | ... AQ17: =$AA17*#REF! -> #REF!
A18: 16 | B18: =AQ51 -> #REF! | C18: =AQ25 -> #REF! | D18: =AQ78 -> #REF! | F18: ='HVAC System'!#REF! -> #REF! | G18: ='HVAC System'!#REF! -> #REF! | H18: ='HVAC System'!#REF! -> #REF! | J18: 1 | K18: 4 | M18: =B18-F18 -> #REF! | O18: FCZ16 | P18: Office, Small | Q18: Heating | R18: 0.73640495 | S18: 0.48204749 | T18: 0.51795251 | U18: 0 | V18: 0.35498216 | W18: 0.38142279 | X18: 0 | Z18: FCZ15 | AA18: =W8 -> 0.72768161 | AB18: =$AA18*#REF! -> #REF! | AC18: =$AA18*#REF! -> #REF! | AD18: =$AA18*#REF! -> #REF! | AE18: =$AA18*#REF! -> #REF! | AF18: =$AA18*#REF! -> #REF! | AG18: =$AA18*#REF! -> #REF! | AH18: =$AA18*#REF! -> #REF! | AI18: =$AA18*#REF! -> #REF! | ... AQ18: =$AA18*#REF! -> #REF!
O19: FCZ17 | P19: Office, Small | Q19: Heating | R19: 0.90563926 | S19: 0.35215233 | T19: 0.64784767 | U19: 0 | V19: 0.31892297 | W19: 0.58671629 | X19: 0 | Z19: FCZ16 | AA19: =W18 -> 0.38142279 | AB19: =$AA19*#REF! -> #REF! | AC19: =$AA19*#REF! -> #REF! | AD19: =$AA19*#REF! -> #REF! | AE19: =$AA19*#REF! -> #REF! | AF19: =$AA19*#REF! -> #REF! | AG19: =$AA19*#REF! -> #REF! | AH19: =$AA19*#REF! -> #REF! | AI19: =$AA19*#REF! -> #REF! | ... AQ19: =$AA19*#REF! -> #REF!
Z20: FCZ17 | AA20: =W19 -> 0.58671629 | AB20: =$AA20*#REF! -> #REF! | AC20: =$AA20*#REF! -> #REF! | AD20: =$AA20*#REF! -> #REF! | AE20: =$AA20*#REF! -> #REF! | AF20: =$AA20*#REF! -> #REF! | AG20: =$AA20*#REF! -> #REF! | AH20: =$AA20*#REF! -> #REF! | AI20: =$AA20*#REF! -> #REF! | ... AQ20: =$AA20*#REF! -> #REF!
Z21: FCZ18 | AA21: =W19 -> 0.58671629 | AB21: =$AA21*#REF! -> #REF! | AC21: =$AA21*#REF! -> #REF! | AD21: =$AA21*#REF! -> #REF! | AE21: =$AA21*#REF! -> #REF! | AF21: =$AA21*#REF! -> #REF! | AG21: =$AA21*#REF! -> #REF! | AH21: =$AA21*#REF! -> #REF! | AI21: =$AA21*#REF! -> #REF! | ... AQ21: =$AA21*#REF! -> #REF!
Z22: FCZ19 | AA22: =W14 -> 0.44895207 | AB22: =$AA22*#REF! -> #REF! | AC22: =$AA22*#REF! -> #REF! | AD22: =$AA22*#REF! -> #REF! | AE22: =$AA22*#REF! -> #REF! | AF22: =$AA22*#REF! -> #REF! | AG22: =$AA22*#REF! -> #REF! | AH22: =$AA22*#REF! -> #REF! | AI22: =$AA22*#REF! -> #REF! | ... AQ22: =$AA22*#REF! -> #REF!
Z23: FCZ20 | AA23: =W13 -> 0.49296635 | AB23: =$AA23*#REF! -> #REF! | AC23: =$AA23*#REF! -> #REF! | AD23: =$AA23*#REF! -> #REF! | AE23: =$AA23*#REF! -> #REF! | AF23: =$AA23*#REF! -> #REF! | AG23: =$AA23*#REF! -> #REF! | AH23: =$AA23*#REF! -> #REF! | AI23: =$AA23*#REF! -> #REF! | ... AQ23: =$AA23*#REF! -> #REF!
Z24: Sum | AB24: =SUM(AB3:AB23) -> #REF! | AC24: =SUM(AC3:AC23) -> #REF! | AD24: =SUM(AD3:AD23) -> #REF! | AE24: =SUM(AE3:AE23) -> #REF! | AF24: =SUM(AF3:AF23) -> #REF! | AG24: =SUM(AG3:AG23) -> #REF! | AH24: =SUM(AH3:AH23) -> #REF! | AI24: =SUM(AI3:AI23) -> #REF! | ... AQ24: =SUM(AQ3:AQ23) -> #REF!
AB25: =AB24/(AB50+AB24+AB77) -> #REF! | AC25: =AC24/(AC50+AC24+AC77) -> #REF! | AD25: =AD24/(AD50+AD24+AD77) -> #REF! | AE25: =AE24/(AE50+AE24+AE77) -> #REF! | AF25: =AF24/(AF50+AF24+AF77) -> #REF! | AG25: =AG24/(AG50+AG24+AG77) -> #REF! | AH25: =AH24/(AH50+AH24+AH77) -> #REF! | AI25: =AI24/(AI50+AI24+AI77) -> #REF! | ... AQ25: =AQ24/(AQ50+AQ24+AQ77) -> #REF!
AA28: Saturation (Electric) | AB28: 1 | AC28: 2 | AD28: 3 | AE28: 4 | AF28: 5 | AG28: 6 | AH28: 7 | AI28: 8 | AJ28: 9 | AK28: 10 | AL28: 11 | AM28: 12 | AN28: 13 | AO28: 14 | AP28: 15 | AQ28: 16
Z29: FZ0 | AA29: =AA44 -> 0.18902426 | AB29: =$AA29*#REF! -> #REF! | AC29: =$AA29*#REF! -> #REF! | AD29: =$AA29*#REF! -> #REF! | AE29: =$AA29*#REF! -> #REF! | AF29: =$AA29*#REF! -> #REF! | AG29: =$AA29*#REF! -> #REF! | AH29: =$AA29*#REF! -> #REF! | AI29: =$AA29*#REF! -> #REF! | ... AQ29: =$AA29*#REF! -> #REF!
Z30: FCZ1 | AA30: =V4 -> 0.28059547 | AB30: =$AA30*#REF! -> #REF! | AC30: =$AA30*#REF! -> #REF! | AD30: =$AA30*#REF! -> #REF! | AE30: =$AA30*#REF! -> #REF! | AF30: =$AA30*#REF! -> #REF! | AG30: =$AA30*#REF! -> #REF! | AH30: =$AA30*#REF! -> #REF! | AI30: =$AA30*#REF! -> #REF! | ... AQ30: =$AA30*#REF! -> #REF!
Z31: FCZ2 | AA31: =V5 -> 0.10285651 | AB31: =$AA31*#REF! -> #REF! | AC31: =$AA31*#REF! -> #REF! | AD31: =$AA31*#REF! -> #REF! | AE31: =$AA31*#REF! -> #REF! | AF31: =$AA31*#REF! -> #REF! | AG31: =$AA31*#REF! -> #REF! | AH31: =$AA31*#REF! -> #REF! | AI31: =$AA31*#REF! -> #REF! | ... AQ31: =$AA31*#REF! -> #REF!
Z32: FCZ3 | AA32: =V6 -> 0.22764715 | AB32: =$AA32*#REF! -> #REF! | AC32: =$AA32*#REF! -> #REF! | AD32: =$AA32*#REF! -> #REF! | AE32: =$AA32*#REF! -> #REF! | AF32: =$AA32*#REF! -> #REF! | AG32: =$AA32*#REF! -> #REF! | AH32: =$AA32*#REF! -> #REF! | AI32: =$AA32*#REF! -> #REF! | ... AQ32: =$AA32*#REF! -> #REF!
Z33: FCZ4 | AA33: =V7 -> 0.22764715 | AB33: =$AA33*#REF! -> #REF! | AC33: =$AA33*#REF! -> #REF! | AD33: =$AA33*#REF! -> #REF! | AE33: =$AA33*#REF! -> #REF! | AF33: =$AA33*#REF! -> #REF! | AG33: =$AA33*#REF! -> #REF! | AH33: =$AA33*#REF! -> #REF! | AI33: =$AA33*#REF! -> #REF! | ... AQ33: =$AA33*#REF! -> #REF!
Z34: FCZ5 | AA34: =V8 -> 0.18902426 | AB34: =$AA34*#REF! -> #REF! | AC34: =$AA34*#REF! -> #REF! | AD34: =$AA34*#REF! -> #REF! | AE34: =$AA34*#REF! -> #REF! | AF34: =$AA34*#REF! -> #REF! | AG34: =$AA34*#REF! -> #REF! | AH34: =$AA34*#REF! -> #REF! | AI34: =$AA34*#REF! -> #REF! | ... AQ34: =$AA34*#REF! -> #REF!
Z35: FCZ6 | AA35: =V9 -> 0.23589977 | AB35: =$AA35*#REF! -> #REF! | AC35: =$AA35*#REF! -> #REF! | AD35: =$AA35*#REF! -> #REF! | AE35: =$AA35*#REF! -> #REF! | AF35: =$AA35*#REF! -> #REF! | AG35: =$AA35*#REF! -> #REF! | AH35: =$AA35*#REF! -> #REF! | AI35: =$AA35*#REF! -> #REF! | ... AQ35: =$AA35*#REF! -> #REF!
Z36: FCZ7 | AA36: =V10 -> 0.62997607 | AB36: =$AA36*#REF! -> #REF! | AC36: =$AA36*#REF! -> #REF! | AD36: =$AA36*#REF! -> #REF! | AE36: =$AA36*#REF! -> #REF! | AF36: =$AA36*#REF! -> #REF! | AG36: =$AA36*#REF! -> #REF! | AH36: =$AA36*#REF! -> #REF! | AI36: =$AA36*#REF! -> #REF! | ... AQ36: =$AA36*#REF! -> #REF!
Z37: FCZ8 | AA37: =V11 -> 0.50445402 | AB37: =$AA37*#REF! -> #REF! | AC37: =$AA37*#REF! -> #REF! | AD37: =$AA37*#REF! -> #REF! | AE37: =$AA37*#REF! -> #REF! | AF37: =$AA37*#REF! -> #REF! | AG37: =$AA37*#REF! -> #REF! | AH37: =$AA37*#REF! -> #REF! | AI37: =$AA37*#REF! -> #REF! | ... AQ37: =$AA37*#REF! -> #REF!
Z38: FCZ9 | AA38: =V12 -> 0.056283749 | AB38: =$AA38*#REF! -> #REF! | AC38: =$AA38*#REF! -> #REF! | AD38: =$AA38*#REF! -> #REF! | AE38: =$AA38*#REF! -> #REF! | AF38: =$AA38*#REF! -> #REF! | AG38: =$AA38*#REF! -> #REF! | AH38: =$AA38*#REF! -> #REF! | AI38: =$AA38*#REF! -> #REF! | ... AQ38: =$AA38*#REF! -> #REF!
Z39: FCZ10 | AA39: =V13 -> 0.41941528 | AB39: =$AA39*#REF! -> #REF! | AC39: =$AA39*#REF! -> #REF! | AD39: =$AA39*#REF! -> #REF! | AE39: =$AA39*#REF! -> #REF! | AF39: =$AA39*#REF! -> #REF! | AG39: =$AA39*#REF! -> #REF! | AH39: =$AA39*#REF! -> #REF! | AI39: =$AA39*#REF! -> #REF! | ... AQ39: =$AA39*#REF! -> #REF!
Z40: FCZ11 | AA40: =V14 -> 0.52492103 | AB40: =$AA40*#REF! -> #REF! | AC40: =$AA40*#REF! -> #REF! | AD40: =$AA40*#REF! -> #REF! | AE40: =$AA40*#REF! -> #REF! | AF40: =$AA40*#REF! -> #REF! | AG40: =$AA40*#REF! -> #REF! | AH40: =$AA40*#REF! -> #REF! | AI40: =$AA40*#REF! -> #REF! | ... AQ40: =$AA40*#REF! -> #REF!
Z41: FCZ12 | AA41: =(V15+V16)/2 -> 0.44582277 | AB41: =$AA41*#REF! -> #REF! | AC41: =$AA41*#REF! -> #REF! | AD41: =$AA41*#REF! -> #REF! | AE41: =$AA41*#REF! -> #REF! | AF41: =$AA41*#REF! -> #REF! | AG41: =$AA41*#REF! -> #REF! | AH41: =$AA41*#REF! -> #REF! | AI41: =$AA41*#REF! -> #REF! | ... AQ41: =$AA41*#REF! -> #REF!
Z42: FCZ13 | AA42: =V17 -> 0.33477969 | AB42: =$AA42*#REF! -> #REF! | AC42: =$AA42*#REF! -> #REF! | AD42: =$AA42*#REF! -> #REF! | AE42: =$AA42*#REF! -> #REF! | AF42: =$AA42*#REF! -> #REF! | AG42: =$AA42*#REF! -> #REF! | AH42: =$AA42*#REF! -> #REF! | AI42: =$AA42*#REF! -> #REF! | ... AQ42: =$AA42*#REF! -> #REF!
...

Sheet Thermostat
A1: ="Thermostat Setpoints - "&Prototype!A2 -> Thermostat Setpoints - RestaurantSitDown
A2: Space/Thermal Zone | B2: Setpoint | C2: CZ1 | D2: CZ2 | E2: CZ3 | F2: CZ4 | G2: CZ5 | H2: CZ6 | I2: CZ7 | J2: CZ8 | K2: CZ9 | L2: CZ10 | M2: CZ11 | N2: CZ12 | O2: CZ13 | P2: CZ14 | Q2: CZ15 | R2: CZ16 | S2: Source
A3: Dining | B3: Heating Setpoint (F) | C3: 70 | D3: 70 | E3: 70 | F3: 70 | G3: 70 | H3: 70 | I3: 70 | J3: 70 | K3: 70 | L3: 70 | M3: 70 | N3: 70 | O3: 70 | P3: 70 | Q3: 70 | R3: 70 | S3: T24 2022 - Appendix 5.4B
B4: Heating Setback (F) | C4: 60 | D4: 60 | E4: 60 | F4: 60 | G4: 60 | H4: 60 | I4: 60 | J4: 60 | K4: 60 | L4: 60 | M4: 60 | N4: 60 | O4: 60 | P4: 60 | Q4: 60 | R4: 60
B5: Cooling Setpoint (F) | C5: 75 | D5: 75 | E5: 75 | F5: 75 | G5: 75 | H5: 75 | I5: 75 | J5: 75 | K5: 75 | L5: 75 | M5: 75 | N5: 75 | O5: 75 | P5: 75 | Q5: 75 | R5: 75
B6: Cooling Setback (F) | C6: 85 | D6: 85 | E6: 85 | F6: 85 | G6: 85 | H6: 85 | I6: 85 | J6: 85 | K6: 85 | L6: 85 | M6: 85 | N6: 85 | O6: 85 | P6: 85 | Q6: 85 | R6: 85
A7: Kitchen | B7: Heating Setpoint (F) | C7: 66 | D7: 66 | E7: 66 | F7: 66 | G7: 66 | H7: 66 | I7: 66 | J7: 66 | K7: 66 | L7: 66 | M7: 66 | N7: 66 | O7: 66 | P7: 66 | Q7: 66 | R7: 66 | S7: PNNL 09.1, 2022 Restaurant prototype
B8: Heating Setback (F) | C8: 60 | D8: 60 | E8: 60 | F8: 60 | G8: 60 | H8: 60 | I8: 60 | J8: 60 | K8: 60 | L8: 60 | M8: 60 | N8: 60 | O8: 60 | P8: 60 | Q8: 60 | R8: 60
B9: Cooling Setpoint (F) | C9: 79 | D9: 79 | E9: 79 | F9: 79 | G9: 79 | H9: 79 | I9: 79 | J9: 79 | K9: 79 | L9: 79 | M9: 79 | N9: 79 | O9: 79 | P9: 79 | Q9: 79 | R9: 79
B10: Cooling Setback (F) | C10: 86 | D10: 86 | E10: 86 | F10: 86 | G10: 86 | H10: 86 | I10: 86 | J10: 86 | K10: 86 | L10: 86 | M10: 86 | N10: 86 | O10: 86 | P10: 86 | Q10: 86 | R10: 86
A12: PNNL's comfort range in kitchen is 4 F wider : 66 -79 F (with Heating setback of 60 F and Cooling setback of 86 F)
A13: PNNL comfort range in Dining is 70 -75 F (with Heating setback of 60 F and Cooling setback of 86 F)
A15: CPUC comfort range is 70 -75 F (with Heating setback of 60 F and Cooling setback of 85 F)

Sheet Ventilation
A1: ="Outdoor Airflow Rate - "&Prototype!A2 -> Outdoor Airflow Rate - RestaurantSitDown
A2: Space/Thermal Zone | B2: Number of People | C2: Floor Area (ft²) | D2: cfm/person [T24, 2025, Equation 120.1-F and Table 120.1-A] | E2: cfm/ft² [T24, 2025, Equation 120.1-F and Table 120.1-A] | F2: Required Exhaust Rate [T24, 2025, Table 120.1-B – minimum exhaust rates] | G2: Total cfm Driven by People | H2: Total cfm Driven by Area | I2: Total cfm Driven by Exhaust | J2: Total cfm | K2: Notes
A3: =Zones!B3 -> Dining | B3: =Zones!K3 -> 132.04818 | C3: =Zones!H3 -> 4001.46 | D3: 15 | E3: 0.15 | F3: 4 restroom, each 25/50 cfm pr unit | G3: =B3*D3 -> 1980.7227 | H3: =C3*E3 -> 600.219 | I3: =4*50 -> 200 | J3: =MAX(G3:I3) -> 1980.7227
A4: =Zones!B4 -> Kitchen | B4: =Zones!K4 -> 4.50165 | C4: =Zones!H4 -> 1500.55 | D4: 15 | E4: 0.15 | F4: 0.7 cfm/ft2 | G4: =B4*D4 -> 67.52475 | H4: =C4*E4 -> 225.0825 | I4: =0.7*C4 -> 1050.385 | J4: =MAX(G4:I4) -> 1050.385
A5: =Zones!B5 -> Attic
A7: Fine storage is defined for normal inventory that doesn't require an extra exhaust rate based on the space functions in T24, Part6, 2025, Table 120.1 B.
A10: Exhaust hood
A11: Type of Hood | C11: Max Exhaust Flow Rate (cfm/ft) [T24, 2025, Table 140.9-C] | D11: Hood Length (ft) * [CKV, 2004] & | E11: Hood Exhaust Rate (cfm) | F11: Note
A12: Type I , wall-mounted canopy, medium duty hood | C12: 210 | D12: =B26 -> 21.5 | E12: =D12*C12 -> 4515
A14: Efficiency of exhaust fan is 50% (according to ACM, 2025,section 5.7.3)
A16: Quick Service Restaurant Hood Appliance
A17: Appliance | C17: Length (ft) | D17: Source
A18: Fryers side | B18: 3 | C18: 3.75 | D18: CKV Design Guide, 2004 (with equipment of a casual dining restaurant) *Charbroiler length is extended from 3 to 4
A19: Fryer drip station (doesn't generate heat or grease but still need to be covered) | B19: 1 | C19: 1.25
A20: Griddle | B20: 1 | C20: 6
A21: Prep surface | B21: 1 | C21: 1
A22: Open range burners (top) | B22: 4 | C22: 2
A23: Charbroiler | B23: 1 | C23: 4
A24: Convection oven | B24: 1 | C24: 2.5 | D24: added from the list of fast food restaurant
A25: Total cooking line length (ft) | B25: =SUM(C18:C24) -> 20.5
A26: Hood length (ft) (+1 ft buffer) | B26: =B25+1 -> 21.5

Sheet Interior Lights
A1: ="Interior Lighting - "&Prototype!A2 -> Interior Lighting - RestaurantSitDown
A2: Space Type | B2: New Construction | E2: Existing
B3: LPD (W/ft²) | C3: Additional LPD for Portable Lighting (W/ft²) | D3: Source | E3: LPD (W/ft²) | F3: Additional LPD for Portable Lighting (W/ft²) | G3: Source
A4: =Zones!C3 -> Dining Area (Bar/Lounge and Fine Dining) | B4: 0.45 | C4: 0.25 | D4: T24, 2025, Table 140.6-C (Area category method) | E4: 1 | G4: T24, 2016, Table 140.6-C (Area category method) LPD of "All other spaces" is considered for storage space
A5: =Zones!C4 -> Kitchen/Food Preparation Area | B5: 0.95 | E5: 1.2
A6: =Zones!C5 -> Attic

Sheet Cooking Euipment
A1: Forecast Zone | B1: Building-type | C1: End Use | E1: End Use Saturation | F1: Electric Fuel Share | G1: Gas Fuel Share | H1: Other Fuel Share | I1: Saturation (Electric) | J1: Saturation (Gas) | K1: Saturation (Other Fuels)
A2: Statewide | B2: Office, Small | C2: Commercial-Grade Cooking Equipment | E2: 0.020119267 | F2: 0.36728899 | G2: 0.62894178 | H2: 0.0037692297 | I2: 0.0073895852 | J2: 0.012653847 | K2: 7.5834137e-05
A3: FCZ1 | B3: Office, Small | C3: Commercial-Grade Cooking Equipment | E3: 0.016135745 | F3: 0.47987336 | G3: 0.50250088 | H3: 0.01762576 | I3: 0.0077431142 | J3: 0.0081082261 | K3: 0.00028440477
A4: FCZ2 | B4: Office, Small | C4: Commercial-Grade Cooking Equipment | D4: Gas | E4: 0.014700452 | F4: 0.17579513 | G4: 0.82420487 | H4: 0 | I4: 0.0025842678 | J4: 0.012116184 | K4: 0
A5: FCZ3 | B5: Office, Small | C5: Commercial-Grade Cooking Equipment | E5: 0.024755045 | F5: 0.76947624 | G5: 0.23052376 | H5: 0 | I5: 0.019048419 | J5: 0.005706626 | K5: 0
A6: FCZ4 | B6: Office, Small | C6: Commercial-Grade Cooking Equipment | E6: 0.024755045 | F6: 0.76947624 | G6: 0.23052376 | H6: 0 | I6: 0.019048419 | J6: 0.005706626 | K6: 0
A7: FCZ5 | B7: Office, Small | C7: Commercial-Grade Cooking Equipment | E7: 0.050073018 | F7: 0.5814357 | G7: 0.4185643 | H7: 0 | I7: 0.02911424 | J7: 0.020958778 | K7: 0
A8: FCZ6 | B8: Office, Small | C8: Commercial-Grade Cooking Equipment | D8: Gas | E8: 0.016879395 | F8: 0.017126659 | G8: 0.98287334 | H8: 0 | I8: 0.00028908764 | J8: 0.016590307 | K8: 0
A9: FCZ7 | B9: Office, Small | C9: Commercial-Grade Cooking Equipment | D9: Gas | E9: 0.023652968 | F9: 0.17483516 | G9: 0.82516484 | H9: 0 | I9: 0.0041353706 | J9: 0.019517598 | K9: 0
A10: FCZ8 | B10: Office, Small | C10: Commercial-Grade Cooking Equipment | E10: 0.01616372 | F10: 0.23253461 | G10: 0.76746539 | H10: 0 | I10: 0.0037586242 | J10: 0.012405095 | K10: 0
A11: FCZ9 | B11: Office, Small | C11: Commercial-Grade Cooking Equipment | E11: 0.021460625 | F11: 0.24364847 | G11: 0.75635153 | H11: 0 | I11: 0.0052288485 | J11: 0.016231777 | K11: 0
A12: FCZ10 | B12: Office, Small | C12: Commercial-Grade Cooking Equipment | E12: 0.016965581 | F12: 0.25575825 | G12: 0.74424175 | H12: 0 | I12: 0.0043390872 | J12: 0.012626493 | K12: 0
A13: FCZ11 | B13: Office, Small | C13: Commercial-Grade Cooking Equipment | E13: 0.020916604 | F13: 0.56741363 | G13: 0.43258637 | H13: 0 | I13: 0.011868366 | J13: 0.0090482379 | K13: 0
A14: FCZ12c | B14: Office, Small | C14: Commercial-Grade Cooking Equipment | E14: 0.02002232 | F14: 0.37811695 | G14: 0.62188305 | H14: 0 | I14: 0.0075707786 | J14: 0.012451541 | K14: 0
A15: FCZ12i | B15: Office, Small | C15: Commercial-Grade Cooking Equipment | E15: 0.0055388004 | F15: 0.75222324 | G15: 0.24777676 | H15: 0 | I15: 0.0041664144 | J15: 0.001372386 | K15: 0
A16: FCZ13 | B16: Office, Small | C16: Commercial-Grade Cooking Equipment | E16: 0.016186866 | F16: 0.48031793 | G16: 0.51383015 | H16: 0.0058519235 | I16: 0.0077748422 | J16: 0.0083173 | K16: 9.4724304e-05
A17: FCZ16 | B17: Office, Small | C17: Commercial-Grade Cooking Equipment | D17: Gas | E17: 0.0060803936 | F17: 0.21087233 | G17: 0.78912767 | H17: 0 | I17: 0.0012821867 | J17: 0.0047982069 | K17: 0
A18: FCZ17 | B18: Office, Small | C18: Commercial-Grade Cooking Equipment | D18: Gas | E18: 0.010327399 | F18: 0.017611914 | G18: 0.98238809 | H18: 0 | I18: 0.00018188527 | J18: 0.010145514 | K18: 0
A23: Planning Area & Forecast Zone | B23: Building-type | C23: End Use | E23: End Use Saturation or Penetration | F23: Electric Fuel Share | G23: Gas Fuel Share | H23: Other Fuel Share | I23: Saturation (Electric) | J23: Saturation (Gas) | K23: Saturation (Other Fuels)
A24: Statewide | B24: Office, Small | C24: Commercial Cooking Space | E24: 0.0042513248 | F24: 0.36728899 | G24: 0.62894178 | H24: 0.0037692297 | I24: 0.0015614648 | J24: 0.0026738358 | K24: 1.602422e-05
A25: FCZ1 | B25: Office, Small | C25: Commercial Cooking Space | E25: 0.0055971614 | F25: 0.47987336 | G25: 0.50250088 | H25: 0.01762576 | I25: 0.0026859287 | J25: 0.0028125785 | K25: 9.8654224e-05
A26: FCZ2 | B26: Office, Small | C26: Commercial Cooking Space | E26: 0.0042162427 | F26: 0.17579513 | G26: 0.82420487 | H26: 0 | I26: 0.00074119492 | J26: 0.0034750478 | K26: 0
A27: FCZ3 | B27: Office, Small | C27: Commercial Cooking Space | E27: 0.0029787351 | F27: 0.76947624 | G27: 0.23052376 | H27: 0 | I27: 0.0022920659 | J27: 0.00068666922 | K27: 0
A28: FCZ4 | B28: Office, Small | C28: Commercial Cooking Space | E28: 0.0029787351 | F28: 0.76947624 | G28: 0.23052376 | H28: 0 | I28: 0.0022920659 | J28: 0.00068666922 | K28: 0
A29: FCZ5 | B29: Office, Small | C29: Commercial Cooking Space | E29: 0.0058178622 | F29: 0.5814357 | G29: 0.4185643 | H29: 0 | I29: 0.0033827128 | J29: 0.0024351494 | K29: 0
A30: FCZ6 | B30: Office, Small | C30: Commercial Cooking Space | E30: 0.003711553 | F30: 0.017126659 | G30: 0.98287334 | H30: 0 | I30: 6.3566502e-05 | J30: 0.0036479865 | K30: 0
A31: FCZ7 | B31: Office, Small | C31: Commercial Cooking Space | E31: 0.0042121502 | F31: 0.17483516 | G31: 0.82516484 | H31: 0 | I31: 0.00073643198 | J31: 0.0034757183 | K31: 0
A32: FCZ8 | B32: Office, Small | C32: Commercial Cooking Space | E32: 0.001957273 | F32: 0.23253461 | G32: 0.76746539 | H32: 0 | I32: 0.00045513371 | J32: 0.0015021393 | K32: 0
A33: FCZ9 | B33: Office, Small | C33: Commercial Cooking Space | E33: 0.0020418399 | F33: 0.24364847 | G33: 0.75635153 | H33: 0 | I33: 0.00049749117 | J33: 0.0015443487 | K33: 0
A34: FCZ10 | B34: Office, Small | C34: Commercial Cooking Space | E34: 0.0037379161 | F34: 0.25575825 | G34: 0.74424175 | H34: 0 | I34: 0.0009560029 | J34: 0.0027819132 | K34: 0
A35: FCZ11 | B35: Office, Small | C35: Commercial Cooking Space | E35: 0.0048031981 | F35: 0.56741363 | G35: 0.43258637 | H35: 0 | I35: 0.0027254001 | J35: 0.002077798 | K35: 0
... A40: FCZ17 | B40: Office, Small | C40: Commercial Cooking Space | E40: 0.00076819869 | F40: 0.017611914 | G40: 0.98238809 | H40: 0 | I40: 1.352945e-05 | J40: 0.00075466924 | K40: 0

Sheet Air compressor
A1: Forecast Zone | B1: Building-type | C1: End Use | D1: End Use Saturation | E1: Electric Fuel Share | F1: Gas Fuel Share | G1: Other Fuel Share | H1: Saturation (Electric) | I1: Saturation (Gas) | J1: Saturation (Other Fuels)
A2: Statewide | B2: Office, Small | C2: Air Compressors | D2: 0.15531554 | E2: NA | F2: NA | G2: NA | H2: 0.15531554 | I2: 0 | J2: 0
A3: FCZ1 | B3: Office, Small | C3: Air Compressors | D3: 0.16127386 | E3: NA | F3: NA | G3: NA | H3: 0.16127386 | I3: 0 | J3: 0
A4: FCZ2 | B4: Office, Small | C4: Air Compressors | D4: 0.16046383 | E4: NA | F4: NA | G4: NA | H4: 0.16046383 | I4: 0 | J4: 0
A5: FCZ3 | B5: Office, Small | C5: Air Compressors | D5: 0.17700838 | E5: NA | F5: NA | G5: NA | H5: 0.17700838 | I5: 0 | J5: 0
A6: FCZ4 | B6: Office, Small | C6: Air Compressors | D6: 0.17700838 | E6: NA | F6: NA | G6: NA | H6: 0.17700838 | I6: 0 | J6: 0
A7: FCZ5 | B7: Office, Small | C7: Air Compressors | D7: 0.11292694 | E7: NA | F7: NA | G7: NA | H7: 0.11292694 | I7: 0 | J7: 0
A8: FCZ6 | B8: Office, Small | C8: Air Compressors | D8: 0.19948704 | E8: NA | F8: NA | G8: NA | H8: 0.19948704 | I8: 0 | J8: 0
A9: FCZ7 | B9: Office, Small | C9: Air Compressors | D9: 0.11620337 | E9: NA | F9: NA | G9: NA | H9: 0.11620337 | I9: 0 | J9: 0
A10: FCZ8 | B10: Office, Small | C10: Air Compressors | D10: 0.18247124 | E10: NA | F10: NA | G10: NA | H10: 0.18247124 | I10: 0 | J10: 0
A11: FCZ9 | B11: Office, Small | C11: Air Compressors | D11: 0.26849572 | E11: NA | F11: NA | G11: NA | H11: 0.26849572 | I11: 0 | J11: 0
A12: FCZ10 | B12: Office, Small | C12: Air Compressors | D12: 0.085403948 | E12: NA | F12: NA | G12: NA | H12: 0.085403948 | I12: 0 | J12: 0
A13: FCZ11 | B13: Office, Small | C13: Air Compressors | D13: 0.17534707 | E13: NA | F13: NA | G13: NA | H13: 0.17534707 | I13: 0 | J13: 0
... A18: FCZ17 | B18: Office, Small | C18: Air Compressors | D18: 0.24877341 | E18: NA | F18: NA | G18: NA | H18: 0.24877341 | I18: 0 | J18: 0

Sheet Refrigerated
A1: Forecast Zone | B1: Building-type | C1: End Use | D1: End Use Saturation | E1: Electric Fuel Share | F1: Gas Fuel Share | G1: Other Fuel Share | H1: Saturation (Electric) | I1: Saturation (Gas) | J1: Saturation (Other Fuels)
A2: Statewide | B2: Office, Small | C2: Commercial-Grade Refrigerators | D2: 0.84563059 | E2: NA | F2: NA | G2: NA | H2: 0.84563059 | I2: 0 | J2: 0
A3: FCZ1 | B3: Office, Small | C3: Commercial-Grade Refrigerators | D3: 0.79853341 | E3: NA | F3: NA | G3: NA | H3: 0.79853341 | I3: 0 | J3: 0
A4: FCZ2 | B4: Office, Small | C4: Commercial-Grade Refrigerators | D4: 0.86552927 | E4: NA | F4: NA | G4: NA | H4: 0.86552927 | I4: 0 | J4: 0
A5: FCZ3 | B5: Office, Small | C5: Commercial-Grade Refrigerators | D5: 0.82761773 | E5: NA | F5: NA | G5: NA | H5: 0.82761773 | I5: 0 | J5: 0
A6: FCZ4 | B6: Office, Small | C6: Commercial-Grade Refrigerators | D6: 0.82761773 | E6: NA | F6: NA | G6: NA | H6: 0.82761773 | I6: 0 | J6: 0
A7: FCZ5 | B7: Office, Small | C7: Commercial-Grade Refrigerators | D7: 0.85238511 | E7: NA | F7: NA | G7: NA | H7: 0.85238511 | I7: 0 | J7: 0
A8: FCZ6 | B8: Office, Small | C8: Commercial-Grade Refrigerators | D8: 0.837724 | E8: NA | F8: NA | G8: NA | H8: 0.837724 | I8: 0 | J8: 0
A9: FCZ7 | B9: Office, Small | C9: Commercial-Grade Refrigerators | D9: 0.82299363 | E9: NA | F9: NA | G9: NA | H9: 0.82299363 | I9: 0 | J9: 0
A10: FCZ8 | B10: Office, Small | C10: Commercial-Grade Refrigerators | D10: 0.88393635 | E10: NA | F10: NA | G10: NA | H10: 0.88393635 | I10: 0 | J10: 0
A11: FCZ9 | B11: Office, Small | C11: Commercial-Grade Refrigerators | D11: 1 | E11: NA | F11: NA | G11: NA | H11: 1 | I11: 0 | J11: 0
A12: FCZ10 | B12: Office, Small | C12: Commercial-Grade Refrigerators | D12: 0.8177684 | E12: NA | F12: NA | G12: NA | H12: 0.8177684 | I12: 0 | J12: 0
A13: FCZ11 | B13: Office, Small | C13: Commercial-Grade Refrigerators | D13: 0.86099786 | E13: NA | F13: NA | G13: NA | H13: 0.86099786 | I13: 0 | J13: 0
... A18: FCZ17 | B18: Office, Small | C18: Commercial-Grade Refrigerators | D18: 0.94722377 | E18: NA | F18: NA | G18: NA | H18: 0.94722377 | I18: 0 | J18: 0
A22: Forecast Zone | B22: Building-type | C22: End Use | D22: End Use Saturation | E22: Electric Fuel Share | F22: Gas Fuel Share | G22: Other Fuel Share | H22: Saturation (Electric) | I22: Saturation (Gas) | J22: Saturation (Other Fuels)
A23: Statewide | B23: Office, Small | C23: Commercial-Grade Freezers | D23: 0.059735148 | E23: NA | F23: NA | G23: NA | H23: 0.059735148 | I23: 0 | J23: 0
A24: FCZ1 | B24: Office, Small | C24: Commercial-Grade Freezers | D24: 0.026408903 | E24: NA | F24: NA | G24: NA | H24: 0.026408903 | I24: 0 | J24: 0
A25: FCZ2 | B25: Office, Small | C25: Commercial-Grade Freezers | D25: 0.03266756 | E25: NA | F25: NA | G25: NA | H25: 0.03266756 | I25: 0 | J25: 0
A26: FCZ3 | B26: Office, Small | C26: Commercial-Grade Freezers | D26: 0.092718675 | E26: NA | F26: NA | G26: NA | H26: 0.092718675 | I26: 0 | J26: 0
A27: FCZ4 | B27: Office, Small | C27: Commercial-Grade Freezers | D27: 0.092718675 | E27: NA | F27: NA | G27: NA | H27: 0.092718675 | I27: 0 | J27: 0
A28: FCZ5 | B28: Office, Small | C28: Commercial-Grade Freezers | D28: 0.12772306 | E28: NA | F28: NA | G28: NA | H28: 0.12772306 | I28: 0 | J28: 0
A29: FCZ6 | B29: Office, Small | C29: Commercial-Grade Freezers | D29: 0.048742044 | E29: NA | F29: NA | G29: NA | H29: 0.048742044 | I29: 0 | J29: 0
A30: FCZ7 | B30: Office, Small | C30: Commercial-Grade Freezers | D30: 0.068151284 | E30: NA | F30: NA | G30: NA | H30: 0.068151284 | I30: 0 | J30: 0
A31: FCZ8 | B31: Office, Small | C31: Commercial-Grade Freezers | D31: 0.0755228 | E31: NA | F31: NA | G31: NA | H31: 0.0755228 | I31: 0 | J31: 0
A32: FCZ9 | B32: Office, Small | C32: Commercial-Grade Freezers | D32: 0.11154655 | E32: NA | F32: NA | G32: NA | H32: 0.11154655 | I32: 0 | J32: 0
A33: FCZ10 | B33: Office, Small | C33: Commercial-Grade Freezers | D33: 0.048634661 | E33: NA | F33: NA | G33: NA | H33: 0.048634661 | I33: 0 | J33: 0
A34: FCZ11 | B34: Office, Small | C34: Commercial-Grade Freezers | D34: 0.041049526 | E34: NA | F34: NA | G34: NA | H34: 0.041049526 | I34: 0 | J34: 0
... A39: FCZ17 | B39: Office, Small | C39: Commercial-Grade Freezers | D39: 0.025770435 | E39: NA | F39: NA | G39: NA | H39: 0.025770435 | I39: 0 | J39: 0
A41: Forecast Zone | B41: Building-type | C41: End Use | D41: End Use Saturation | E41: Electric Fuel Share | F41: Gas Fuel Share | G41: Other Fuel Share | H41: Saturation (Electric) | I41: Saturation (Gas) | J41: Saturation (Other Fuels)
A42: Statewide | B42: Office, Small | C42: Frozen Floor Space | D42: 0.00032878385 | E42: NA | F42: NA | G42: NA | H42: 0.00032878385 | I42: 0 | J42: 0
A43: FCZ1 | B43: Office, Small | C43: Frozen Floor Space | D43: 0 | E43: NA | F43: NA | G43: NA | H43: 0 | I43: 0 | J43: 0
A44: FCZ2 | B44: Office, Small | C44: Frozen Floor Space | D44: 0 | E44: NA | F44: NA | G44: NA | H44: 0 | I44: 0 | J44: 0
A45: FCZ3 | B45: Office, Small | C45: Frozen Floor Space | D45: 0 | E45: NA | F45: NA | G45: NA | H45: 0 | I45: 0 | J45: 0
A46: FCZ4 | B46: Office, Small | C46: Frozen Floor Space | D46: 0 | E46: NA | F46: NA | G46: NA | H46: 0 | I46: 0 | J46: 0
A47: FCZ5 | B47: Office, Small | C47: Frozen Floor Space | D47: 0 | E47: NA | F47: NA | G47: NA | H47: 0 | I47: 0 | J47: 0
A48: FCZ6 | B48: Office, Small | C48: Frozen Floor Space | D48: 0.0049760278 | E48: NA | F48: NA | G48: NA | H48: 0.0049760278 | I48: 0 | J48: 0
A49: FCZ7 | B49: Office, Small | C49: Frozen Floor Space | D49: 0.00014179139 | E49: NA | F49: NA | G49: NA | H49: 0.00014179139 | I49: 0 | J49: 0
A50: FCZ8 | B50: Office, Small | C50: Frozen Floor Space | D50: 0.0011345583 | E50: NA | F50: NA | G50: NA | H50: 0.0011345583 | I50: 0 | J50: 0
A51: FCZ9 | B51: Office, Small | C51: Frozen Floor Space | D51: 0 | E51: NA | F51: NA | G51: NA | H51: 0 | I51: 0 | J51: 0
A52: FCZ10 | B52: Office, Small | C52: Frozen Floor Space | D52: 0 | E52: NA | F52: NA | G52: NA | H52: 0 | I52: 0 | J52: 0
...

Sheet Water Heater
A1: ="Water Heater Summary - "&Prototype!A2 -> Water Heater Summary - RestaurantSitDown
A2: Vintage | B2: WH Type | C2: Efficiency | D2: Number of WH | E2: Tank Volume (gal) | F2: Tank Loss | G2: Source
A3: Existing | B3: Gas | C3: 0.8 | D3: 1 | E3: See table below for CZ-specific values: Climate Zone Water Heater Sizing and Loss Coefficients, Storage Volume column (col F) | F3: See table below: Climate Zone Water Heater Sizing and Loss Coefficients, Standby Loss column (col G) | G3: See table below for sources: Climate Zone Water Heater Sizing and Loss Coefficients
