Workbook
Name nonparticipating_forecastzone_scale_factor: #REF!
Name nonparticipating_forecastzone_scale_factor: #REF!
Name nonparticipating_forecastzone_scale_factor: 'Energy Usage'!#REF!
Name Space_Function: Data!$A$2:$A$76

Sheet Notes
A1: Data Sources
A2: Dataset | B2: Dodge 2023
B3: Commercial End-Use Survey (CEUS) 2022 | C3: https://www.energy.ca.gov/publications/2023/2022-california-commercial-end-use-survey-ceus-final-report
B4: Commercial Buildings Energy Consumption Survey (CBECS) 2018 | C4: https://www.eia.gov/consumption/commercial/data/2018/
B5: ComStock 2023 | C5: https://comstock.nlr.gov/page/datasets
B6: Database for Energy Efficient Resources (DEER) Grocery Store prototype (June 2023) | C6: https://github.com/sound-data/DEER-Prototypes-EnergyPlus
B7: Oak Ridge National Laboratory (ORNL) (2019) Supermarket Building Energy Model | C7: https://www.osti.gov/servlets/purl/3019970
A8: Codes | B8: Titile 24, part 6, referred to as T24 (1984, 1992,1998, 2001, 2005, 2008, 2013, 2016,2019, 2022, 2025) | C8: https://www.energy.ca.gov/publications/2025/2025-building-energy-efficiency-standards-residential-and-nonresidential | D8: 2025
C9: https://codes.iccsafe.org/codes/united-states/california | D9: 2010+
B10: American Society of Heating, Refrigerating and Air-Conditioning Engineers (ASHRAE) 90.1 (2022) | C10: https://www.ashrae.org/technical-resources/standards-and-guidelines/read-only-versions-of-ashrae-standards
B11: Code of Federal Regulations (CFR) Title 10 (2010) | C11: https://www.govinfo.gov/content/pkg/FR-2009-03-23/pdf/FR-2009-03-23.pdf
B12: CFR Title 10 (2024) | C12: https://www.govinfo.gov/content/pkg/CFR-2024-title10-vol3/pdf/CFR-2024-title10-vol3-part431-subpartF.pdf
B13: Title 20 | C13: https://govt.westlaw.com/calregs/Document/I270DCA634B4011EFA8F7F119BAF97AD6?viewType=FullText&originationContext=documenttoc&transitionType=CategoryPageItem&contextData=(sc.Default)
A14: Others | B14: Alternative Calculation Method (ACM) (2022) | C14: https://www.energy.ca.gov/publications/2022/2022-nonresidential-and-multifamily-alternative-calculation-method-reference
B15: ACM (2025) | C15: https://www.energy.ca.gov/publications/2025/2025-nonresidential-and-multifamily-alternative-calculation-method-reference
B16: Title 24, 2025, Appendix B: Water Heating Calculation Method | C16: https://www.energy.ca.gov/sites/default/files/2025-11/CEC-400-2025-006-AP-B.pdf
B17: Nonres ACM 2022, Appendix 5.4A and Appendix 5.4B | C17: https://www.energy.ca.gov/publications/2022/2022-nonresidential-and-multifamily-alternative-calculation-method-reference
B18: 2022 Reduced infiltration Codes and Standards Enhancement (CASE) report | C18: https://title24stakeholders.com/wp-content/uploads/2020/10/2022-T24-Final-CASE-Report_Reduce-Infiltration.pdf
B19: 2019 Outdoor Lighting CASE Report | C19: https://title24stakeholders.com/wp-content/uploads/2016/10/T24-2019-CASE-Study-Results-Report-Outdoor-Sources_Final_with-Attachments.pdf
B20: PNNL 20405, 2011 | C20: https://www.pnnl.gov/main/publications/external/technical_reports/PNNL-20405.pdf
B21: Air leakage Memo, NORESCO, 2025 | C21: Infiltration_rate_report_14May2025-Short-Version.docx
B22: Retail Building Guide for Entrance Energy Efficiency Measures (2012) | C22: https://www.osti.gov/servlets/purl/1037934
B23: Yousefi, F., Athalye, R., (2025), "Determining Vintage Bins for Prototype Development: An Analysis of California Commercial Buildings," ASHRAE Annual Conference | C23: https://www.thefreelibrary.com/Determining+Vintage+Bins+for+Prototype+Development%3a+An+Analysis+of...-a0879271125
B24: Proposed Updates to Equipment Power Densities and Building Schedules for the 2028 Energy Code, referred to as "Plug load and schedules project with CEC, 2025" (Docket Number =25-BSTD-03 & TN=265693) | C24: https://efiling.energy.ca.gov/GetDocument.aspx?tn=265693&DocumentContentId=102545
B25: ENERGY STAR certified commercial water heaters | C25: https://www.energystar.gov/productfinder/product/certified-commercial-water-heaters/results?fuel_filter=Gas&markets_filter=United+States
B26: Grainger gas tank water heaters (sizes below commercial, e.g. 30–75 kBtu/h) | C26: https://www.grainger.com/category/plumbing/water-heaters/gas-tank-water-heaters
B27: Grainger electric tank water heaters | C27: https://www.grainger.com/category/plumbing/water-heaters/electric-tank-water-heaters
A30: Construction Rate
A43: Notes
A44: The grocery prototype represents the "big-box" stand-alone retail model typical of Ralph's, Safeway, Albertsons. Where needed, the Grocery and Medium Retail could be weighted to represent a Super Walmart type of space.

Sheet Prototype
A1: NORESCO, Updated September 2026
A2: RetailGrocery
A3: Characteristic | B3: Value | C3: Data Sources
A4: Building Type | B4: Grocery
A5: Building Category | B5: Nonresidential
A6: Version | B6: v2-0
A7: Vintages | B7: 4 Vintages: Pre-1978 , 1978-1997 ,1998-2007 , 2008-2018 New Construction (2019+) | C7: Based on the vintage bin analysis. A summary of the findings is presented in the following paper, with a link provided in the Notes tab: Yousefi, F., Athalye, R. (2025). “Determining Vintage Bins for Prototype Development: An Analysis of California Commercial Buildings.” ASHRAE Annual Conference.
A8: Shape | C8: Proposed Plan Based on Typical Grocery Store
A9: Total Floor Area (ft²) | B9: 50,000 (250 ft x 200 ft) | C9: Proposed Plan Based on Typical Grocery Store
A10: Aspect Ratio | B10: 1.25 | C10: Proposed Plan Based on Typical Grocery Store
A11: Number of Floors | B11: 1 | C11: Proposed Plan Based on Typical Grocery Store
A12: Roof type | B12: Flat | C12: Proposed Plan Based on Typical Grocery Store
A13: WWR | B13: 0.0775 | C13: Proposed Plan Based on Typical Grocery Store
A14: Shading Geometry | B14: N/A | C14: Proposed Plan Based on Typical Grocery Store
A15: Floor to floor height (feet) | B15: N/A | C15: Proposed Plan Based on Typical Grocery Store
A16: Floor to ceiling height (feet) | B16: 25 | C16: Proposed Plan Based on Typical Grocery Store
A17: Glazing sill height (feet) | B17: 3 ft (top of the window is 10 ft high with 7 ft high glass) | C17: CPUC (DEER 2023) Grocery prototype
A18: Skylight-to-Roof-Ratio (SRR) | B18: 0.023 | C18: Title 24 Skylight Requirement
A29: Existing Grocery Prototypes
B32: CPUC: Retail_Grocery
A33: Geometry/ Floor plan | D33: Zones of DEER prototype | E33: Floor area | F33: Share
A34: Total floor area (ft²) | B34: 49997 | D34: IndLoadDock | E34: 2850.9 | F34: =E34/$E$40 -> 0.057021467
D35: RefWalkInCool | E35: 1559.65 | F35: =E35/$E$40 -> 0.031194897
D36: RefWalkInFreeze | E36: 812.23 | F36: =E36/$E$40 -> 0.016245588
D37: RefFoodPrep | E37: 1267.01 | F37: =E37/$E$40 -> 0.025341741
D38: Grocery Sale | E38: 40007.28 | F38: =E38/$E$40 -> 0.80019425
D39: Office | E39: 3499.89 | F39: =E39/$E$40 -> 0.070002056
E40: =SUM(E34:E39) -> 49996.96
A43: Other Existing Retail Prototypes
A45: Large size prototype
B46: CEC: Retail_Large | C46: CPUC: Retail_Multistory Large (Rt3) | D46: CPUC: Retail_Single-Story Large (RtL)
A47: Geometry
A48: Total floor area (ft²) | B48: 240000 | C48: =3*40000 -> 120000 | D48: 130502
A50: Medium size prototype
B51: CEC: Retail_Medium | E51: PNNL : Retail_Standalone | F51: PNNL: Retail_Stripmall
A52: Geometry | B52: zoning same as PNNL Stand alone with more skylight
A53: Total floor area (ft²) | B53: 24692 | E53: 24692 | F53: 22500
A55: Small size prototype
B56: CEC: Retail_Stripmall (Mixed use) | C56: CPUC: Retail_Small (RtS)
A57: Geometry
...

Sheet Zones
A1: ="Proposed Layout - "&Prototype!A2 -> Proposed Layout - RetailGrocery | R1: Spaces and Zoning layout - "Rn" indicates which refrigerated cases are in each zone.
A2: Building | B2: Space/Thermal Zone | C2: Space Type [Primarily from: T24, 2022 Appendix 5.4A] - See Notes column | D2: HVAC System Name (NC) | E2: HVAC System Name (Existing) | F2: Schedule Category | G2: Conditioned (Y/N) | H2: Area Fraction | I2: Area (ft²) | J2: Volume (ft³) | K2: Multipliers | L2: Number of People | M2: People (Persons/1,000 ft²) [T24, 2025,Table 120.1-A] | N2: Notes | P2: --- 40 ft --- | Q2: --- 70ft --- | R2: N --- 34 ft --- | S2: 250' North Façade | T2: --- 106 ft ---
A3: RetailGrocery | B3: Checkout Area | C3: Retail Sales Area (Grocery Sales) | D3: SZVAVHP_Checkout Area_NC | E3: PSZAC_Checkout Area_Existing | F3: Grocery Sales & Office | G3: Y | H3: =10000/50000 -> 0.2 | I3: =H3*50000 -> 10000 | J3: =I3*Prototype!$B$16 -> 250000 | K3: 1 | L3: =M3*I3/1000 -> 170 | M3: 17 | P3: Back Office | Q3: Refr Food Prep | R3: Walk-in Freezers | S3: Loading Dock - Semi-Conditioned | U3: 30 ft
A4: RetailGrocery | B4: Produce | C4: Retail Sales Area (Grocery Sales) | D4: SZVAVHP_Produce_NC | E4: PSZAC_Produce_Existing | F4: Grocery Sales & Office | G4: Y | H4: =4400/50000 -> 0.088 | I4: =H4*50000 -> 4400 | J4: =I4*Prototype!$B$16 -> 110000 | K4: 1 | L4: =M4*I4/1000 -> 74.8 | M4: 17 | P4: (1200 sf) | Q4: 2100 sf) | R4: Walk-in Coolers | S4: (stock area) | T4: 3200 sf
A5: RetailGrocery | B5: General Merch | C5: Retail Sales Area (Grocery Sales) | D5: SZVAVHP_General Merch_NC | E5: PSZAC_General Merch_Existing | F5: Grocery Sales & Office | G5: Y | H5: =7700/50000 -> 0.154 | I5: =H5*50000 -> 7700 | J5: =I5*Prototype!$B$16 -> 192500 | K5: 1 | L5: =M5*I5/1000 -> 130.9 | M5: 17 | Q5: 5000 sf (250'x20') | R5: Meat and Dairy | T5: R1, R2 | U5: 20'
A6: RetailGrocery | B6: Frozen | C6: Retail Sales Area (Grocery Sales) | D6: SZVAVHP_Frozen_NC | E6: SPSZAC_Frozen_Existing | F6: Grocery Sales & Office | G6: Y | H6: =6600/50000 -> 0.132 | I6: =H6*50000 -> 6600 | J6: =I6*Prototype!$B$16 -> 165000 | K6: 1 | L6: =M6*I6/1000 -> 112.2 | M6: 17
A7: RetailGrocery | B7: Beverage | C7: Retail Sales Area (Grocery Sales) | D7: SZVAVHP_Beverage_NC | E7: PSZAC_Beverage_Existing | F7: Grocery Sales & Office | G7: Y | H7: =4400/50000 -> 0.088 | I7: =H7*50000 -> 4400 | J7: =I7*Prototype!$B$16 -> 110000 | K7: 1 | L7: =M7*I7/1000 -> 74.8 | M7: 17 | P7: Produce | Q7: Grocery - General | R7: Grocery - Frozen | S7: Beverage | T7: Bakery and Deli
A8: RetailGrocery | B8: Bakery and Deli | C8: Retail Sales Area (Grocery Sales) | D8: SZVAVHP_Bakery and Deli | E8: PSZAC_Bakery and Deli_Existing | F8: Grocery Sales & Office | G8: Y | H8: =4400/50000 -> 0.088 | I8: =H8*50000 -> 4400 | J8: =I8*Prototype!$B$16 -> 110000 | K8: 1 | L8: =M8*I8/1000 -> 74.8 | M8: 17
A9: RetailGrocery | B9: Meat and Dairy | C9: Retail Sales Area (Grocery Sales) | D9: SZVAVHP_Meat and Dairy | E9: PSZAC_Meat and Dairy_Existing | F9: Grocery Sales & Office | G9: Y | H9: =5000/50000 -> 0.1 | I9: =H9*50000 -> 5000 | J9: =I9*Prototype!$B$16 -> 125000 | K9: 1 | L9: =M9*I9/1000 -> 85 | M9: 17 | U9: 200' totalEastFacade
A10: RetailGrocery | B10: Back Office | C10: Lounge, Breakroom, or Waiting Area | D10: SZVAVHP_Back Office | E10: PSZAC_Back Office_Existing | F10: Grocery Sales & Office | G10: Y | H10: =1200/50000 -> 0.024 | I10: =H10*50000 -> 1200 | J10: =I10*Prototype!$B$16 -> 30000 | K10: 1 | L10: =M10*I10/1000 -> 6 | M10: 5 | P10: R4, R7 | R10: R5 | S10: R6, R9 | T10: R3,R10
A11: RetailGrocery | B11: Loading Dock EL1 | C11: Storage, Commercial/Industrial (Shipping & Handling) | D11: SZVAVHP_Loading Dock EL1 | E11: PSZAC_Loading Dock EL1_Existing | F11: Ancillary | G11: Y | H11: =3200/50000 -> 0.064 | I11: =H11*50000 -> 3200 | J11: =I11*Prototype!$B$16 -> 80000 | K11: 1 | L11: =M11*I11/1000 -> 6.4 | M11: 2 | P11: 4400 sf | Q11: 7700 sf | R11: 6600 sf | S11: 4400 sf | T11: 4400 sf | U11: 110'
A12: RetailGrocery | B12: Food Prep | C12: Storage, Commercial/Industrial (Refrigerated) | D12: SZVAVHP_RefFoodPRep Core | E12: PSZAC_RefFoodPRep Core_Existing | F12: Refrigeration | G12: Y | H12: =2100/50000 -> 0.042 | I12: 2100 | J12: =I12*Prototype!$B$16 -> 52500 | K12: 1 | L12: =M12*I12/1000 -> 0 | M12: 0 | P12: (40'x110') | Q12: (70'x110') | R12: (60'x110') | S12: (40'x110') | T12: (40'x110')
A13: RetailGrocery | B13: RefWalkInCool Core | C13: Storage, Commercial/Industrial (Refrigerated) | D13: - | E13: - | F13: Refrigeration | G13: Y | H13: =500/50000 -> 0.01 | I13: =H13*50000 -> 500 | J13: =I13*Prototype!$B$16 -> 12500 | K13: 1 | L13: =M13*I13/1000 -> 0 | M13: 0
A14: RetailGrocery | B14: Ref WalkInFreezer Core | C14: Storage, Commercial/Industrial (Refrigerated) | D14: - | E14: - | F14: Refrigeration | G14: Y | H14: =500/50000 -> 0.01 | I14: =H14*50000 -> 500 | J14: =I14*Prototype!$B$16 -> 12500 | K14: 1 | L14: =M14*I14/1000 -> 0 | M14: 0
A15: Total (1 Building) | B15: Total (12 Thermal zones) | C15: Total (4 Space Types) | G15: Total (12 Conditioned zones) | H15: =SUM(H3:H14) -> 1 | I15: =SUM(I3:I14) -> 50000 | J15: =SUM(J3:J14) -> 1250000 | L15: =SUM(L3:L14) -> 734.9
D17: {=_xlfn.UNIQUE(C3:C14)} -> Retail Sales Area (Grocery Sales)
D18: Lounge, Breakroom, or Waiting Area
D19: Storage, Commercial/Industrial (Shipping & Handling)
D20: Storage, Commercial/Industrial (Refrigerated)
R21: Cashier area and front of the store | U21: 40'
R22: 10,000 sf (250'*40')

Sheet Envelope
A1: ="Envelope - "&Prototype!A2 -> Envelope - RetailGrocery
A2: Element | B2: Prototype | C2: Assembly Type | D2: Construction | E2: Thermal Properties | F2: Vintage | G2: Selected T24 | H2: Notes | I2: CZ1 | J2: CZ2 | K2: CZ3 | L2: CZ4 | M2: CZ5 | N2: CZ6 | O2: CZ7 | P2: CZ8 | Q2: CZ9 | R2: CZ10 | S2: CZ11 | T2: CZ12 | U2: CZ13 | V2: CZ14 | W2: CZ15 | X2: CZ16
A3: External Wall | B3: RetailGrocery | C3: ExtWall_MetalFramed_NonRes | D3: Metal frame + insulation + Gypsum board | E3: U-factor IP | F3: Pre 1978 | G3: N/A | H3: ASHRAE 90.1, 2022, Table A3.3.3.1, 3.5", R-0 | I3: 0.352 | J3: 0.352 | K3: 0.352 | L3: 0.352 | M3: 0.352 | N3: 0.352 | O3: 0.352 | P3: 0.352 | Q3: 0.352 | R3: 0.352 | S3: 0.352 | T3: 0.352 | U3: 0.352 | V3: 0.352 | W3: 0.352 | X3: 0.352
F4: 1978-1997 | G4: 1986 | H4: Package A with Heat Capacity 10.0-14.99 (Btu/F-ft²) - Still are lower than the next vintage! | I4: 0.15082956 | J4: 0.15748031 | K4: 0.15748031 | L4: 0.14367816 | M4: 0.14367816 | N4: 0.21645022 | O4: 0.21645022 | P4: 0.21645022 | Q4: 0.21645022 | R4: 0.21645022 | S4: 0.18621974 | T4: 0.18621974 | U4: 0.18621974 | V4: 0.15873016 | W4: 0.15873016 | X4: 0.15082956
F5: 1998-2007 | G5: 2001 | H5: Table 1-H | I5: 0.182 | J5: 0.182 | K5: 0.189 | L5: 0.189 | M5: 0.189 | N5: 0.189 | O5: 0.189 | P5: 0.189 | Q5: 0.189 | R5: 0.182 | S5: 0.182 | T5: 0.182 | U5: 0.182 | V5: 0.182 | W5: 0.182 | X5: 0.182
F6: 2008-2018 | G6: 2013 | H6: Table 140.3-B | I6: 0.098 | J6: 0.062 | K6: 0.082 | L6: 0.062 | M6: 0.062 | N6: 0.098 | O6: 0.098 | P6: 0.062 | Q6: 0.062 | R6: 0.062 | S6: 0.062 | T6: 0.062 | U6: 0.062 | V6: 0.062 | W6: 0.062 | X6: 0.062
F7: 2019+ | G7: 2025 | H7: Table 140.3-B | I7: 0.06 | J7: 0.055 | K7: 0.071 | L7: 0.055 | M7: 0.055 | N7: 0.06 | O7: 0.06 | P7: 0.055 | Q7: 0.055 | R7: 0.055 | S7: 0.055 | T7: 0.055 | U7: 0.055 | V7: 0.055 | W7: 0.055 | X7: 0.055
A8: Roof | B8: RetailGrocery | C8: FlatRoof_WoodFramedAndOther_NonRes | D8: Built-up roof: Roof membrane+ insulation+metal decking | E8: U-factor IP | F8: Pre 1978 | G8: N/A | H8: Considering 30 years for roof/ insulation replacement. | I8: 0.057 | J8: 0.057 | K8: 0.057 | L8: 0.057 | M8: 0.057 | N8: 0.078 | O8: 0.078 | P8: 0.078 | Q8: 0.078 | R8: 0.078 | S8: 0.057 | T8: 0.057 | U8: 0.057 | V8: 0.057 | W8: 0.057 | X8: 0.057
F9: 1978-1997 | G9: 1992 | I9: 0.057 | J9: 0.057 | K9: 0.057 | L9: 0.057 | M9: 0.057 | N9: 0.078 | O9: 0.078 | P9: 0.078 | Q9: 0.078 | R9: 0.078 | S9: 0.057 | T9: 0.057 | U9: 0.057 | V9: 0.057 | W9: 0.057 | X9: 0.057
F10: 1998-2007 | G10: 2001 | H10: Table 1-H | I10: 0.057 | J10: 0.057 | K10: 0.057 | L10: 0.057 | M10: 0.057 | N10: 0.078 | O10: 0.078 | P10: 0.078 | Q10: 0.078 | R10: 0.057 | S10: 0.057 | T10: 0.057 | U10: 0.057 | V10: 0.057 | W10: 0.057 | X10: 0.057
F11: 2008-2018 | G11: 2013 | H11: Table 140.3-B | I11: 0.049 | J11: 0.039 | K11: 0.039 | L11: 0.039 | M11: 0.049 | N11: 0.075 | O11: 0.067 | P11: 0.067 | Q11: 0.039 | R11: 0.039 | S11: 0.039 | T11: 0.039 | U11: 0.039 | V11: 0.039 | W11: 0.039 | X11: 0.039
F12: 2019+ | G12: 2025 | H12: Table 140.3-B | I12: 0.028 | J12: 0.028 | K12: 0.028 | L12: 0.028 | M12: 0.028 | N12: 0.047 | O12: 0.047 | P12: 0.047 | Q12: 0.028 | R12: 0.028 | S12: 0.028 | T12: 0.028 | U12: 0.028 | V12: 0.028 | W12: 0.028 | X12: 0.028
A13: Window | B13: RetailGrocery | C13: FixedWindow_NonRes | D13: CBECS 2018 shows that ~ 50 % of retail that were built before 2000 are single pane | E13: U-factor IP | F13: Pre 1978 | G13: N/A | H13: 2021 ASHRAE Handbook of Fundamentals - Section 15.9 Table 4 for single pane & T24, 2013 Table 140.3-B for double pane (50%-50%) | I13: =0.5*1.12+0.5*I16 -> 0.74 | J13: =0.5*1.12+0.5*J16 -> 0.74 | K13: =0.5*1.12+0.5*K16 -> 0.74 | L13: =0.5*1.12+0.5*L16 -> 0.74 | M13: =0.5*1.12+0.5*M16 -> 0.74 | N13: =0.5*1.12+0.5*N16 -> 0.74 | O13: =0.5*1.12+0.5*O16 -> 0.74 | P13: =0.5*1.12+0.5*P16 -> 0.74 | ... X13: =0.5*1.12+0.5*X16 -> 0.74
F14: 1978-1997 | G14: N/A | I14: =I13 -> 0.74 | J14: =J13 -> 0.74 | K14: =K13 -> 0.74 | L14: =L13 -> 0.74 | M14: =M13 -> 0.74 | N14: =N13 -> 0.74 | O14: =O13 -> 0.74 | P14: =P13 -> 0.74 | ... X14: =X13 -> 0.74
D15: Double pane | F15: 1998-2007 | G15: 2001 | H15: Table 1-H | I15: 0.49 | J15: 0.49 | K15: 0.81 | L15: 0.81 | M15: 0.81 | N15: 0.81 | O15: 0.81 | P15: 0.81 | Q15: 0.81 | R15: 0.49 | S15: 0.49 | T15: 0.49 | U15: 0.49 | V15: 0.49 | W15: 0.49 | X15: 0.49
F16: 2008-2018 | G16: 2013 | H16: Table 140.3-B | I16: 0.36 | J16: 0.36 | K16: 0.36 | L16: 0.36 | M16: 0.36 | N16: 0.36 | O16: 0.36 | P16: 0.36 | Q16: 0.36 | R16: 0.36 | S16: 0.36 | T16: 0.36 | U16: 0.36 | V16: 0.36 | W16: 0.36 | X16: 0.36
F17: 2019+ | G17: 2025 | H17: Table 140.3-B | I17: 0.36 | J17: 0.36 | K17: 0.36 | L17: 0.36 | M17: 0.36 | N17: 0.36 | O17: 0.36 | P17: 0.36 | Q17: 0.34 | R17: 0.36 | S17: 0.34 | T17: 0.34 | U17: 0.34 | V17: 0.34 | W17: 0.34 | X17: 0.36
C18: FixedWindow_NonRes | D18: CBECS 2018 shows that ~ 50 % of retail that were built before 2000 are single pane | E18: SHGC | F18: Pre 1978 | G18: N/A | H18: 2021 ASHRAE Handbook of Fundamentals - Section 15.22 Table 10 for single pane & T24, 2013 Table 140.3-B for double pane (50%-50%) | I18: =0.79*0.5+I21*0.5 -> 0.52 | J18: =0.79*0.5+J21*0.5 -> 0.52 | K18: =0.79*0.5+K21*0.5 -> 0.52 | L18: =0.79*0.5+L21*0.5 -> 0.52 | M18: =0.79*0.5+M21*0.5 -> 0.52 | N18: =0.79*0.5+N21*0.5 -> 0.52 | O18: =0.79*0.5+O21*0.5 -> 0.52 | P18: =0.79*0.5+P21*0.5 -> 0.52 | ... X18: =0.79*0.5+X21*0.5 -> 0.52
F19: 1978-1997 | G19: N/A | I19: =I18 -> 0.52 | J19: =J18 -> 0.52 | K19: =K18 -> 0.52 | L19: =L18 -> 0.52 | M19: =M18 -> 0.52 | N19: =N18 -> 0.52 | O19: =O18 -> 0.52 | P19: =P18 -> 0.52 | ... X19: =X18 -> 0.52
D20: Double pane | F20: 1998-2007 | G20: 2001 | H20: Table 1-H (Non north 0-10%) | I20: 0.49 | J20: 0.47 | K20: 0.61 | L20: 0.61 | M20: 0.61 | N20: 0.61 | O20: 0.61 | P20: 0.61 | Q20: 0.61 | R20: 0.47 | S20: 0.47 | T20: 0.47 | U20: 0.47 | V20: 0.46 | W20: 0.46 | X20: 0.49
F21: 2008-2018 | G21: 2013 | H21: Table 140.3-B | I21: 0.25 | J21: 0.25 | K21: 0.25 | L21: 0.25 | M21: 0.25 | N21: 0.25 | O21: 0.25 | P21: 0.25 | Q21: 0.25 | R21: 0.25 | S21: 0.25 | T21: 0.25 | U21: 0.25 | V21: 0.25 | W21: 0.25 | X21: 0.25
F22: 2019+ | G22: 2025 | H22: Table 140.3-B | I22: 0.25 | J22: 0.25 | K22: 0.25 | L22: 0.25 | M22: 0.25 | N22: 0.25 | O22: 0.25 | P22: 0.25 | Q22: 0.22 | R22: 0.25 | S22: 0.22 | T22: 0.22 | U22: 0.22 | V22: 0.22 | W22: 0.22 | X22: 0.25
A23: Skylight | B23: RetailMedium | C23: Skylight | D23: Translucent | E23: U-factor IP | F23: Pre 1978 | G23: N/A | H23: from 1992 code cycle | I23: 0.85 | J23: 1.31 | K23: 1.31 | L23: 1.31 | M23: 1.31 | N23: 1.31 | O23: 1.31 | P23: 1.31 | Q23: 1.31 | R23: 1.31 | S23: 0.85 | T23: 0.85 | U23: 0.85 | V23: 0.85 | W23: 0.85 | X23: 0.85
F24: 1978-1997 | G24: N/A | I24: 0.85 | J24: 1.31 | K24: 1.31 | L24: 1.31 | M24: 1.31 | N24: 1.31 | O24: 1.31 | P24: 1.31 | Q24: 1.31 | R24: 1.31 | S24: 0.85 | T24: 0.85 | U24: 0.85 | V24: 0.85 | W24: 0.85 | X24: 0.85
D25: Plastic curb mounted | F25: 1998-2007 | G25: 2001 | H25: Table 1-H | I25: 0.87 | J25: 1.1 | K25: 1.3 | L25: 1.3 | M25: 1.3 | N25: 1.3 | O25: 1.3 | P25: 1.3 | Q25: 1.3 | R25: 1.1 | S25: 1.1 | T25: 1.1 | U25: 1.1 | V25: 1.1 | W25: 1.1 | X25: 0.87
F26: 2008-2018 | G26: 2013 | H26: Table 140.3-B | I26: 0.88 | J26: 0.88 | K26: 0.88 | L26: 0.88 | M26: 0.88 | N26: 0.88 | O26: 0.88 | P26: 0.88 | Q26: 0.88 | R26: 0.88 | S26: 0.88 | T26: 0.88 | U26: 0.88 | V26: 0.88 | W26: 0.88 | X26: 0.88
F27: 2019+ | G27: 2025 | H27: Table 140.3-B | I27: 0.88 | J27: 0.88 | K27: 0.88 | L27: 0.88 | M27: 0.88 | N27: 0.88 | O27: 0.88 | P27: 0.88 | Q27: 0.88 | R27: 0.88 | S27: 0.88 | T27: 0.88 | U27: 0.88 | V27: 0.88 | W27: 0.88 | X27: 0.88
B28: RetailMedium | C28: Skylight | D28: Translucent | E28: SHGC | F28: Pre 1978 | G28: N/A | H28: From 1992 code cycle | I28: =0.81*0.87 -> 0.7047 | J28: =0.86*0.87 -> 0.7482 | K28: =0.86*0.87 -> 0.7482 | L28: =0.86*0.87 -> 0.7482 | M28: =0.86*0.87 -> 0.7482 | N28: =0.86*0.87 -> 0.7482 | O28: =0.86*0.87 -> 0.7482 | P28: =0.86*0.87 -> 0.7482 | Q28: =0.86*0.87 -> 0.7482 | R28: =0.86*0.87 -> 0.7482 | S28: =0.81*0.87 -> 0.7047 | T28: =0.81*0.87 -> 0.7047 | U28: =0.81*0.87 -> 0.7047 | V28: =0.81*0.87 -> 0.7047 | W28: =0.81*0.87 -> 0.7047 | X28: =0.81*0.87 -> 0.7047
F29: 1978-1997 | G29: N/A | I29: =0.81*0.87 -> 0.7047 | J29: =0.86*0.87 -> 0.7482 | K29: =0.86*0.87 -> 0.7482 | L29: =0.86*0.87 -> 0.7482 | M29: =0.86*0.87 -> 0.7482 | N29: =0.86*0.87 -> 0.7482 | O29: =0.86*0.87 -> 0.7482 | P29: =0.86*0.87 -> 0.7482 | Q29: =0.86*0.87 -> 0.7482 | R29: =0.86*0.87 -> 0.7482 | S29: =0.81*0.87 -> 0.7047 | T29: =0.81*0.87 -> 0.7047 | U29: =0.81*0.87 -> 0.7047 | V29: =0.81*0.87 -> 0.7047 | W29: =0.81*0.87 -> 0.7047 | X29: =0.81*0.87 -> 0.7047
D30: Plastic curb mounted | F30: 1998-2007 | G30: 2001 | H30: Table 1-H (For SRR 2.1-5%) | I30: 0.58 | J30: 0.62 | K30: 0.65 | L30: 0.65 | M30: 0.65 | N30: 0.62 | O30: 0.62 | P30: 0.62 | Q30: 0.62 | R30: 0.62 | S30: 0.62 | T30: 0.62 | U30: 0.62 | V30: 0.58 | W30: 0.58 | X30: 0.58
F31: 2008-2018 | G31: 2013 | H31: There is no requirement in the code (considered same as 2001) | I31: 0.58 | J31: 0.62 | K31: 0.65 | L31: 0.65 | M31: 0.65 | N31: 0.62 | O31: 0.62 | P31: 0.62 | Q31: 0.62 | R31: 0.62 | S31: 0.62 | T31: 0.62 | U31: 0.62 | V31: 0.58 | W31: 0.58 | X31: 0.58
F32: 2019+ | G32: 2025 | H32: There is no requirement in the code (considered same as 2001) | I32: 0.58 | J32: 0.62 | K32: 0.65 | L32: 0.65 | M32: 0.65 | N32: 0.62 | O32: 0.62 | P32: 0.62 | Q32: 0.62 | R32: 0.62 | S32: 0.62 | T32: 0.62 | U32: 0.62 | V32: 0.58 | W32: 0.58 | X32: 0.58
C35: Infiltration
D36: Building | E36: Zones | F36: Vintage | G36: I_75 (cfm/ft²) 6-sdied Infiltration rate @ 75 pa | H36: Note | I36: I-design (cfm/ft²) (4-sided Infiltration rate at normal pressure) (Design flow rate approach and Flow/Exterior Wall Area calculation method)
C37: Infiltration | D37: RetailGrocery | F37: Pre 1978 | G37: 1.1 | H37: 2022 CASE report (Table 38) | I37: =(G37*0.112)*$AA$41 -> 0.67075556 | Z37: Floor or roof area (ft2) | AA37: =Zones!I15 -> 50000
F38: 1978-1997 | G38: 1.1 | H38: 2022 CASE report (Table 38) | I38: =(G38*0.112)*$AA$41 -> 0.67075556 | Z38: Walls area (ft2) | AA38: =(250+200)*2*25 -> 22500
F39: 1998-2007 | G39: 1.1 | H39: 2022 CASE report (Table 38) | I39: =(G39*0.112)*$AA$41 -> 0.67075556 | Z39: Building 4 sided area (ft2) | AA39: =AA38 -> 22500
F40: 2008-2018 | G40: 1 | H40: 2022 CASE report (Table 38) & T24, part 6, 2008-2016 (Table 140.3-B), Dodge 2023 data | I40: =(G40*0.112)*$AA$41 -> 0.60977778 | Z40: Building 6 sided area (ft2) | AA40: =AA38+(2*AA37) -> 122500
F41: 2019+ | G41: 0.6 (barrier in all CZ) | H41: 2022 CASE report (Table 38) & T24, part 6, 2025 (Table 140.3-B) | I41: =(0.6*0.112)*$AA$41 -> 0.36586667 | Z41: 6 sided /4 sided factor | AA41: =AA40/AA39 -> 5.4444444
E42: Source: T24 air barrier requirements (all editions) , the standardized infiltration rate reported in the 2022 CASE report, and Dodge 2023 data
...

Sheet HVAC System
A1: ="HVAC system - "&Prototype!A2 -> HVAC system - RetailGrocery
A2: Vintage | B2: Heating | C2: Cooling | D2: Air Distribution | E2: Other systems | F2: Source
A3: Existing | B3: PSZAC (furnace) | C3: PSZAC (DX cooling) | D3: PSZAC | E3: OA mixing Economizer for Vintage 3 and 4 | F3: CEUS 2022
A4: New Construction | B4: SZVAVHP | C4: SZVAVHP | D4: PSZVAVHP | E4: OA mixing Economizer | F4: Title 24, 2025, Engineering judgement
A8: Efficiency of HVAC System (Efficiency is capacity-dependent. The following table provides a general estimate of system efficiency based on preliminary simulations in one climate zone, or assuming cooling load based on rule of thumb)
A9: Vintage | B9: Upgrade/Installed year | C9: Heating | D9: Cooling | E9: Source
A10: Pre 1978 | B10: 2008 | C10: Thermal Efficiency of 80% | D10: SEER=13.0 for <65 kBtu/h EER 10.1 for 65-135 kBtu/h EER 9.5 for 135-240 kBtu/h EER 9.3 for 240-760 kBtu/h | E10: T24, Table 112-A (2008) 10 CFR § 431.97, Table 1 (2008) California Title 20 Appliance Efficiency Regulations, Table E-4, Standards for Gas- and Oil-Fired Central Furnaces (2008)
A11: 1978-1997
A12: 1998-2007
A13: 2008-2018 | B13: 2013 | C13: Thermal Efficiency of 80%; | D13: SEER 13 for <65 kBtu/h EER 11.0 for 65-135 kBtu/h EER 10.8 for 135-240 kBtu/h EER 9.8 for 240-760 kBtu/h | E13: T24, 2013 Table 110.2-J & Table 110.2-A (2013) 10 CFR § 431.97(b) Table 1 (2013)
A14: New Construction | B14: 2025 | C14: HSPF 8.0 for <65 kBtu/h COP 3.4 for 65-135 kBtu/h COP 3.3 for 135-240 kBtu/h COP 3.2 for >240 kBtu/h | D14: SEER 14 for <65 kBtu/h EER 10.8, IEER 13.9 for 65-135 kBtu/h EER 10.4, IEER = 13.3 135-240 kBtu/h EER 9.3, IEER=12.3 for >240 kBtu/h | E14: 10 CFR § 431.97(b) Table 1 (2025) Title 20 Appliance Efficiency Regulations, Section 1605.1, Table C-5 (2025) T24, Table 110.2-B (2025)
A18: Fan Power
A19: Vintage | B19: Approach | C19: System | D19: Total Static Pressure (TSP) (in w.c.) | E19: Fan Efficiency [ACM 2025] | F19: Motor Efficiency | G19: Fan Power Index (W/cfm) | H19: Data Source
A20: Existing | B20: PNNL 90.1-2011, TSP | C20: CAV < 7,437 cfm | D20: 2.5 | E20: 0.65 | F20: ASHRAE 90.1, 2004, Table 10.8 * | H20: Fan power formula: PNNL 20405, 2010, section 5.2.2.5 TSP and fan efficiecncy: PNNL 20405, 2010, Table 5.11, 90.1-04ac values Motor and drive efficiency: ASHRAE 90.1, 2004, Table 10.8
C21: CAV >= 7,437 cfm | D21: 4.09
A22: Brake horsepower (bhp) = (Supply cfm × TSP in w.c.) / (6356 × fan efficiency)
A23: Fan power (w/cfm) = (bhp × 746) / ( supply cfm × motor efficiency )
A24: New Construction | B24: ACM 2025 | C24: SZVAVHP (System 7b), ≤5,000 cfm | D24: TSP = fan power × motor efficiency × fan efficiency × 6356 / 746 | E24: 0.65 | F24: 2025 ACM Table 12 ** | G24: 0.744 | H24: Fan power index: [ACM 2025, Table 13] Motor efficiency: [ACM 2025, Table 12]
C25: SZVAVHP (System 7b), >5,000 and ≤10,000 cfm | D25: TSP = fan power × motor efficiency × fan efficiency × 6356 / 746 | G25: 0.72
A27: * According to PNNL 20405 section 5.2.2.5, the full-load efficiency of the motor serving the fan is taken from ASHRAE 90.1, 2004, Table 10.8, based on motor nameplate and assuming enclosed motors operating at 1,800 rotations per minute (rpm) Motor nameplate size (bhp) = brake horsepower (bhp) × 1.1 ( using a 10% oversizing factor)
A28: ** The full‑load efficiency of the motor serving the fan is taken from ACM 2025 Table 12 based on the cfm of the fan. Brake horsepower (bhp) = (Supply cfm from sizing run × fan power in W/cfm) / 746. Note: HVAC New Construction is SZVAVHP, not multi-zone VAV. ACM System 7b ≤5,000 cfm. Note: ACM System 7b mid bin. Existing PSZAC CAV rows above stay on PNNL.

Sheet Ventilation
A1: ="Outdoor Airflow Rate - "&Prototype!A2 -> Outdoor Airflow Rate - RetailGrocery
A2: Space/Thermal Zone | B2: Number of People | C2: Floor Area (ft²) | D2: cfm/person [T24, 2025, Equation 120.1-F and Table 120.1-A] | E2: cfm/ft² [T24, 2025, Equation 120.1-F and Table 120.1-A] | F2: Required Exhaust Rate [T24, 2025, Table 120.1-B – minimum exhaust rates] | G2: Total cfm Driven by People | H2: Total cfm Driven by Area | I2: Total cfm Driven by Exhaust | J2: Total cfm | K2: Notes
A3: =Zones!B3 -> Checkout Area | B3: =Zones!L3 -> 170 | C3: =Zones!I3 -> 10000 | D3: 15 | E3: 0.2 | F3: _ | G3: =D3*B3 -> 2550 | H3: =E3*C3 -> 2000 | I3: _ | J3: =MAX(G3:I3) -> 2550
A4: =Zones!B4 -> Produce | B4: =Zones!L4 -> 74.8 | C4: =Zones!I4 -> 4400 | D4: 15 | E4: 0.2 | F4: _ | G4: =D4*B4 -> 1122 | H4: =E4*C4 -> 880 | I4: _ | J4: =MAX(G4:I4) -> 1122
A5: =Zones!B5 -> General Merch | B5: =Zones!L5 -> 130.9 | C5: =Zones!I5 -> 7700 | D5: 15 | E5: 0.2 | F5: _ | G5: =D5*B5 -> 1963.5 | H5: =E5*C5 -> 1540 | I5: _ | J5: =MAX(G5:I5) -> 1963.5
A6: =Zones!B6 -> Frozen | B6: =Zones!L6 -> 112.2 | C6: =Zones!I6 -> 6600 | D6: 15 | E6: 0.2 | F6: _ | G6: =D6*B6 -> 1683 | H6: =E6*C6 -> 1320 | I6: _ | J6: =MAX(G6:I6) -> 1683
A7: =Zones!B7 -> Beverage | B7: =Zones!L7 -> 74.8 | C7: =Zones!I7 -> 4400 | D7: 15 | E7: 0.2 | F7: _ | G7: =D7*B7 -> 1122 | H7: =E7*C7 -> 880 | I7: _ | J7: =MAX(G7:I7) -> 1122
A8: =Zones!B8 -> Bakery and Deli | B8: =Zones!L8 -> 74.8 | C8: =Zones!I8 -> 4400 | D8: 15 | E8: 0.2 | F8: _ | G8: =D8*B8 -> 1122 | H8: =E8*C8 -> 880 | I8: _ | J8: =MAX(G8:I8) -> 1122
A9: =Zones!B9 -> Meat and Dairy | B9: =Zones!L9 -> 85 | C9: =Zones!I9 -> 5000 | D9: 15 | E9: 0.2 | F9: _ | G9: =D9*B9 -> 1275 | H9: =E9*C9 -> 1000 | I9: _ | J9: =MAX(G9:I9) -> 1275
A10: =Zones!B10 -> Back Office | B10: =Zones!L10 -> 6 | C10: =Zones!I10 -> 1200 | D10: 15 | E10: 0.15 | F10: 8*50/70 cfm/unit | G10: =D10*B10 -> 90 | H10: =E10*C10 -> 180 | I10: =8*50 -> 400 | J10: =MAX(G10:I10) -> 400
A11: =Zones!B11 -> Loading Dock EL1 | B11: =Zones!L11 -> 6.4 | C11: =Zones!I11 -> 3200 | D11: 15 | E11: 0.15 | G11: =D11*B11 -> 96 | H11: =E11*C11 -> 480 | I11: _ | J11: =MAX(G11:I11) -> 480
A12: =Zones!B12 -> Food Prep | B12: =Zones!L12 -> 0 | C12: =Zones!I12 -> 2100 | F12: 0.7 | G12: =D12*B12 -> 0 | H12: =E12*C12 -> 0 | I12: =F12*C12 -> 1470 | J12: =MAX(G12:I12) -> 1470
A13: =Zones!B13 -> RefWalkInCool Core | B13: =Zones!L13 -> 0 | C13: =Zones!I13 -> 500 | G13: =D13*B13 -> 0 | H13: =E13*C13 -> 0 | J13: =MAX(G13:I13) -> 0
A14: =Zones!B14 -> Ref WalkInFreezer Core | B14: =Zones!L14 -> 0 | C14: =Zones!I14 -> 500 | E14: 0 | F14: _ | G14: =D14*B14 -> 0 | H14: =E14*C14 -> 0 | I14: _ | J14: =MAX(G14:I14) -> 0

Sheet Thermostat
A1: ="Thermostat Setpoints - "&Prototype!A2 -> Thermostat Setpoints - RetailGrocery
A2: Setpoint | B2: CZ1 | C2: CZ2 | D2: CZ3 | E2: CZ4 | F2: CZ5 | G2: CZ6 | H2: CZ7 | I2: CZ8 | J2: CZ9 | K2: CZ10 | L2: CZ11 | M2: CZ12 | N2: CZ13 | O2: CZ14 | P2: CZ15 | Q2: CZ16 | R2: Source
A3: Grocery Sales & Office Heating Setpoint (F) | B3: 70 | C3: 70 | D3: 70 | E3: 70 | F3: 70 | G3: 70 | H3: 70 | I3: 70 | J3: 70 | K3: 70 | L3: 70 | M3: 70 | N3: 70 | O3: 70 | P3: 70 | Q3: 70 | R3: T24 2022 - Appendix 5.4B, [Retail]
A4: Grocery Sales & Office Heating Setback (F) | B4: 60 | C4: 60 | D4: 60 | E4: 60 | F4: 60 | G4: 60 | H4: 60 | I4: 60 | J4: 60 | K4: 60 | L4: 60 | M4: 60 | N4: 60 | O4: 60 | P4: 60 | Q4: 60
A5: Grocery Sales & Office Cooling Setpoint (F) | B5: 75 | C5: 75 | D5: 75 | E5: 75 | F5: 75 | G5: 75 | H5: 75 | I5: 75 | J5: 75 | K5: 75 | L5: 75 | M5: 75 | N5: 75 | O5: 75 | P5: 75 | Q5: 75
A6: Grocery Sales & Office Cooling Setback (F) | B6: 85 | C6: 85 | D6: 85 | E6: 85 | F6: 85 | G6: 85 | H6: 85 | I6: 85 | J6: 85 | K6: 85 | L6: 85 | M6: 85 | N6: 85 | O6: 85 | P6: 85 | Q6: 85
A7: Dock/Storage Heating Setpoint (F) | B7: 60 | C7: 60 | D7: 60 | E7: 60 | F7: 60 | G7: 60 | H7: 60 | I7: 60 | J7: 60 | K7: 60 | L7: 60 | M7: 60 | N7: 60 | O7: 60 | P7: 60 | Q7: 60 | R7: Engineering Judement
A8: Dock/Storage Heating Setback (F) | B8: 60 | C8: 60 | D8: 60 | E8: 60 | F8: 60 | G8: 60 | H8: 60 | I8: 60 | J8: 60 | K8: 60 | L8: 60 | M8: 60 | N8: 60 | O8: 60 | P8: 60 | Q8: 60
A9: Dock/StorageCooling Setpoint (F) | B9: 85 | C9: 85 | D9: 85 | E9: 85 | F9: 85 | G9: 85 | H9: 85 | I9: 85 | J9: 85 | K9: 85 | L9: 85 | M9: 85 | N9: 85 | O9: 85 | P9: 85 | Q9: 85
A10: Dock/Storage Cooling Setback (F) | B10: 85 | C10: 85 | D10: 85 | E10: 85 | F10: 85 | G10: 85 | H10: 85 | I10: 85 | J10: 85 | K10: 85 | L10: 85 | M10: 85 | N10: 85 | O10: 85 | P10: 85 | Q10: 85

Sheet Water Heater
A1: ="Water Heater Summary - "&Prototype!A2 -> Water Heater Summary - RetailGrocery
A2: Vintage | B2: WH Type | C2: Efficiency | D2: Number of WH | E2: Tank Volume (gal) | F2: Tank Loss | G2: Source
A3: Existing | B3: Electric | C3: 1 | D3: 1 | E3: See table below for CZ-specific values: Climate Zone Water Heater Sizing and Loss Coefficients, Storage Volume column (col F) | F3: See table below: Climate Zone Water Heater Sizing and Loss Coefficients, Standby Loss column (col G) | G3: See table below for sources: Climate Zone Water Heater Sizing and Loss Coefficients
A4: New Construction | B4: Electric | C4: 1 | D4: 1 | E4: See table below for CZ-specific values: Climate Zone Water Heater Sizing and Loss Coefficients, Storage Volume column (col F) | F4: See table below: Climate Zone Water Heater Sizing and Loss Coefficients, Standby Loss column (col G) | G4: See table below for sources: Climate Zone Water Heater Sizing and Loss Coefficients
A7: Peak Hot Water Consumption
A8: Space Name | B8: Baseline WH Type [CEUS 2022] | C8: Total Area (ft²) | D8: Number of People | E8: Hot Water Usage Specification (gal/hr per person) [T24, 2022, Appendix 5.4A , sheet: "2022 SpaceFuncData-Input"] | F8: Peak Hot Water Usage (gal/hr) | G8: Peak Hot Water Usage (gal/min) | H8: Note
A9: =Zones!B3 -> Checkout Area | B9: Electric resistance WH | C9: =Zones!I3 -> 10000 | D9: =Zones!L3 -> 170 | E9: 0.18 | F9: =E9*D9 -> 30.6 | G9: =F9/60 -> 0.51 | H9: For space types marked with an asterisk (the ‘*’ symbol), the water‑heater type is listed as electric in Appendix 5.4A, sheet ‘2022 SpaceFuncData‑Input.’ However, we modified the value based on CEUS data, which indicates that gas is the primary fuel type.
A10: =Zones!B4 -> Produce | B10: Electric resistance WH | C10: =Zones!I4 -> 4400 | D10: =Zones!L4 -> 74.8 | E10: 0.18 | F10: =E10*D10 -> 13.464 | G10: =F10/60 -> 0.2244
A11: =Zones!B5 -> General Merch | B11: Electric resistance WH | C11: =Zones!I5 -> 7700 | D11: =Zones!L5 -> 130.9 | E11: 0.18 | F11: =E11*D11 -> 23.562 | G11: =F11/60 -> 0.3927
A12: =Zones!B6 -> Frozen | B12: Electric resistance WH | C12: =Zones!I6 -> 6600 | D12: =Zones!L6 -> 112.2 | E12: 0.18 | F12: =E12*D12 -> 20.196 | G12: =F12/60 -> 0.3366
A13: =Zones!B7 -> Beverage | B13: Electric resistance WH | C13: =Zones!I7 -> 4400 | D13: =Zones!L7 -> 74.8 | E13: 0.18 | F13: =E13*D13 -> 13.464 | G13: =F13/60 -> 0.2244
A14: =Zones!B8 -> Bakery and Deli | B14: Electric resistance WH | C14: =Zones!I8 -> 4400 | D14: =Zones!L8 -> 74.8 | E14: 0.18 | F14: =E14*D14 -> 13.464 | G14: =F14/60 -> 0.2244
A15: =Zones!B9 -> Meat and Dairy | B15: Electric resistance WH | C15: =Zones!I9 -> 5000 | D15: =Zones!L9 -> 85 | E15: 0.18 | F15: =E15*D15 -> 15.3 | G15: =F15/60 -> 0.255
A16: =Zones!B10 -> Back Office | B16: Electric resistance WH | C16: =Zones!I10 -> 1200 | D16: =Zones!L10 -> 6 | E16: 0.09 | F16: =E16*D16 -> 0.54 | G16: =F16/60 -> 0.009
A17: =Zones!B11 -> Loading Dock EL1 | B17: Electric resistance WH | C17: =Zones!I11 -> 3200 | D17: =Zones!L11 -> 6.4 | E17: 0.18 | F17: =E17*D17 -> 1.152 | G17: =F17/60 -> 0.0192
A18: =Zones!B12 -> Food Prep | B18: Electric resistance WH | C18: =Zones!I12 -> 2100 | D18: =Zones!L12 -> 0 | E18: 0.18 | F18: =E18*D18 -> 0 | G18: =F18/60 -> 0
A19: =Zones!B13 -> RefWalkInCool Core | B19: Electric resistance WH | C19: =Zones!I13 -> 500 | D19: =Zones!L13 -> 0 | E19: 0.18 | F19: =E19*D19 -> 0 | G19: =F19/60 -> 0
A20: =Zones!B14 -> Ref WalkInFreezer Core | B20: Electric resistance WH | C20: =Zones!I14 -> 500 | D20: =Zones!L14 -> 0 | E20: 0.18 | F20: =E20*D20 -> 0 | G20: =F20/60 -> 0
A21: Total | B21: Gas storage | F21: =_xlfn.LET( _xlpm.g,SUMIF($B$9:$B$20,"Gas*",$F$9:$F$20), _xlpm.e,SUMIF($B$9:$B$20,"Electric*",$F$9:$F$20), IF(AND(_xlpm.g>0,_xlpm.e>0),_xlpm.g,IF(_xlpm.g>0,MAX(75,_xlpm.g),0))) -> 0 | H21: Minimum peak hot water usage is 75 gal according to ACM 2025
A22: Total | B22: Electric resistance | F22: =_xlfn.LET( _xlpm.g,SUMIF($B$9:$B$20,"Gas*",$F$9:$F$20), _xlpm.e,SUMIF($B$9:$B$20,"Electric*",$F$9:$F$20), IF(AND(_xlpm.g>0,_xlpm.e>0),_xlpm.e,IF(_xlpm.e>0,MAX(75,_xlpm.e),0))) -> 131.742
A26: Design supply temperature (°F) | B26: 135 | C26: CEC-400-2022-009-CMF-REV2-AP5.4B
A27: WH system factor | B27: 0.6 | C27: 2025 ACM §5.9.2 Rated Capacity
A28: Water mass conversion (lb/gal) | B28: 8.2877 | C28: 2025 ACM §5.9.2 Rated Capacity
A29: Reheat multiplier | B29: 0.4 | C29: 2025 ACM §5.9.2 Storage Volume
A30: Climate Zone Water Heater Sizing and Loss Coefficients (Individual WH)
A31: Climate Zone | B31: Minimum Monthly Mains Temp (°F) [T24 2022 - Appendix 5.4B] | C31: Heat Output (Btu/hr) [ACM, 2025, 5.9.2: Rated capacity section] | D31: WH Capacity (Btu/hr) [ACM, 2025, 5.9.2: Rated capacity section] | E31: Required Energy Input (Btu/hr) | F31: Storage Volume (gal) | G31: Standby Loss [Title 20, §1605.1 Table F-4; Appendix B: Water Heating Calculation Method] | I31: Off/On Cycle Loss Coefficient to Ambient Temp | K31: Source/Note
A32: CZ01 | B32: 47.9 | C32: =$F$22*($B$26-B32)*$B$28 -> 95099.105 | D32: =C32*$B$27 -> 57059.463 | E32: =_xlfn.LET(_xlpm.x,_xlfn.XLOOKUP(D32,$D$53:$D$67,$D$53:$D$67,"",1),IF(_xlpm.x="",ROUNDUP(D32,0),_xlpm.x)) -> 61419 | F32: =_xlfn.LET(_xlpm.v,MAX(30,$F$22*$B$29),_xlpm.x,_xlfn.XLOOKUP(_xlpm.v,$G$53:$G$67,$G$53:$G$67,"",1),IF(_xlpm.x="",ROUNDUP(_xlpm.v,0),_xlpm.x)) -> 65 | G32: =0.3+27/F32 -> 0.71538462 | H32: =IF($F$22>0,"%/hr","Btu/hr") -> %/hr | I32: =0.0834*G32*F32 -> 3.8781 | J32: Btu/h·°F | K32: Required Energy Input: vendor/available catalog size (Market data table). Storage Volume: standard/available catalog tank size (Market data table).
A33: CZ02 | B33: 50.8 | C33: =$F$22*($B$26-B33)*$B$28 -> 91932.774 | D33: =C33*$B$27 -> 55159.665 | E33: =_xlfn.LET(_xlpm.x,_xlfn.XLOOKUP(D33,$D$53:$D$67,$D$53:$D$67,"",1),IF(_xlpm.x="",ROUNDUP(D33,0),_xlpm.x)) -> 61419 | F33: =_xlfn.LET(_xlpm.v,MAX(30,$F$22*$B$29),_xlpm.x,_xlfn.XLOOKUP(_xlpm.v,$G$53:$G$67,$G$53:$G$67,"",1),IF(_xlpm.x="",ROUNDUP(_xlpm.v,0),_xlpm.x)) -> 65 | G33: =0.3+27/F33 -> 0.71538462 | H33: =IF($F$22>0,"%/hr","Btu/hr") -> %/hr | I33: =0.0834*G33*F33 -> 3.8781 | J33: Btu/h·°F
A34: CZ03 | B34: 52.2 | C34: =$F$22*($B$26-B34)*$B$28 -> 90404.201 | D34: =C34*$B$27 -> 54242.52 | E34: =_xlfn.LET(_xlpm.x,_xlfn.XLOOKUP(D34,$D$53:$D$67,$D$53:$D$67,"",1),IF(_xlpm.x="",ROUNDUP(D34,0),_xlpm.x)) -> 61419 | F34: =_xlfn.LET(_xlpm.v,MAX(30,$F$22*$B$29),_xlpm.x,_xlfn.XLOOKUP(_xlpm.v,$G$53:$G$67,$G$53:$G$67,"",1),IF(_xlpm.x="",ROUNDUP(_xlpm.v,0),_xlpm.x)) -> 65 | G34: =0.3+27/F34 -> 0.71538462 | H34: =IF($F$22>0,"%/hr","Btu/hr") -> %/hr | I34: =0.0834*G34*F34 -> 3.8781 | J34: Btu/h·°F
A35: CZ04 | B35: 52.7 | C35: =$F$22*($B$26-B35)*$B$28 -> 89858.282 | D35: =C35*$B$27 -> 53914.969 | E35: =_xlfn.LET(_xlpm.x,_xlfn.XLOOKUP(D35,$D$53:$D$67,$D$53:$D$67,"",1),IF(_xlpm.x="",ROUNDUP(D35,0),_xlpm.x)) -> 61419 | F35: =_xlfn.LET(_xlpm.v,MAX(30,$F$22*$B$29),_xlpm.x,_xlfn.XLOOKUP(_xlpm.v,$G$53:$G$67,$G$53:$G$67,"",1),IF(_xlpm.x="",ROUNDUP(_xlpm.v,0),_xlpm.x)) -> 65 | G35: =0.3+27/F35 -> 0.71538462 | H35: =IF($F$22>0,"%/hr","Btu/hr") -> %/hr | I35: =0.0834*G35*F35 -> 3.8781 | J35: Btu/h·°F
A36: CZ05 | B36: 51.6 | C36: =$F$22*($B$26-B36)*$B$28 -> 91059.304 | D36: =C36*$B$27 -> 54635.582 | E36: =_xlfn.LET(_xlpm.x,_xlfn.XLOOKUP(D36,$D$53:$D$67,$D$53:$D$67,"",1),IF(_xlpm.x="",ROUNDUP(D36,0),_xlpm.x)) -> 61419 | F36: =_xlfn.LET(_xlpm.v,MAX(30,$F$22*$B$29),_xlpm.x,_xlfn.XLOOKUP(_xlpm.v,$G$53:$G$67,$G$53:$G$67,"",1),IF(_xlpm.x="",ROUNDUP(_xlpm.v,0),_xlpm.x)) -> 65 | G36: =0.3+27/F36 -> 0.71538462 | H36: =IF($F$22>0,"%/hr","Btu/hr") -> %/hr | I36: =0.0834*G36*F36 -> 3.8781 | J36: Btu/h·°F
A37: CZ06 | B37: 56.8 | C37: =$F$22*($B$26-B37)*$B$28 -> 85381.745 | D37: =C37*$B$27 -> 51229.047 | E37: =_xlfn.LET(_xlpm.x,_xlfn.XLOOKUP(D37,$D$53:$D$67,$D$53:$D$67,"",1),IF(_xlpm.x="",ROUNDUP(D37,0),_xlpm.x)) -> 61419 | F37: =_xlfn.LET(_xlpm.v,MAX(30,$F$22*$B$29),_xlpm.x,_xlfn.XLOOKUP(_xlpm.v,$G$53:$G$67,$G$53:$G$67,"",1),IF(_xlpm.x="",ROUNDUP(_xlpm.v,0),_xlpm.x)) -> 65 | G37: =0.3+27/F37 -> 0.71538462 | H37: =IF($F$22>0,"%/hr","Btu/hr") -> %/hr | I37: =0.0834*G37*F37 -> 3.8781 | J37: Btu/h·°F
A38: CZ07 | B38: 58.4 | C38: =$F$22*($B$26-B38)*$B$28 -> 83634.804 | D38: =C38*$B$27 -> 50180.882 | E38: =_xlfn.LET(_xlpm.x,_xlfn.XLOOKUP(D38,$D$53:$D$67,$D$53:$D$67,"",1),IF(_xlpm.x="",ROUNDUP(D38,0),_xlpm.x)) -> 61419 | F38: =_xlfn.LET(_xlpm.v,MAX(30,$F$22*$B$29),_xlpm.x,_xlfn.XLOOKUP(_xlpm.v,$G$53:$G$67,$G$53:$G$67,"",1),IF(_xlpm.x="",ROUNDUP(_xlpm.v,0),_xlpm.x)) -> 65 | G38: =0.3+27/F38 -> 0.71538462 | H38: =IF($F$22>0,"%/hr","Btu/hr") -> %/hr | I38: =0.0834*G38*F38 -> 3.8781 | J38: Btu/h·°F
A39: CZ08 | B39: 58.4 | C39: =$F$22*($B$26-B39)*$B$28 -> 83634.804 | D39: =C39*$B$27 -> 50180.882 | E39: =_xlfn.LET(_xlpm.x,_xlfn.XLOOKUP(D39,$D$53:$D$67,$D$53:$D$67,"",1),IF(_xlpm.x="",ROUNDUP(D39,0),_xlpm.x)) -> 61419 | F39: =_xlfn.LET(_xlpm.v,MAX(30,$F$22*$B$29),_xlpm.x,_xlfn.XLOOKUP(_xlpm.v,$G$53:$G$67,$G$53:$G$67,"",1),IF(_xlpm.x="",ROUNDUP(_xlpm.v,0),_xlpm.x)) -> 65 | G39: =0.3+27/F39 -> 0.71538462 | H39: =IF($F$22>0,"%/hr","Btu/hr") -> %/hr | I39: =0.0834*G39*F39 -> 3.8781 | J39: Btu/h·°F
A40: CZ09 | B40: 57.6 | C40: =$F$22*($B$26-B40)*$B$28 -> 84508.275 | D40: =C40*$B$27 -> 50704.965 | E40: =_xlfn.LET(_xlpm.x,_xlfn.XLOOKUP(D40,$D$53:$D$67,$D$53:$D$67,"",1),IF(_xlpm.x="",ROUNDUP(D40,0),_xlpm.x)) -> 61419 | F40: =_xlfn.LET(_xlpm.v,MAX(30,$F$22*$B$29),_xlpm.x,_xlfn.XLOOKUP(_xlpm.v,$G$53:$G$67,$G$53:$G$67,"",1),IF(_xlpm.x="",ROUNDUP(_xlpm.v,0),_xlpm.x)) -> 65 | G40: =0.3+27/F40 -> 0.71538462 | H40: =IF($F$22>0,"%/hr","Btu/hr") -> %/hr | I40: =0.0834*G40*F40 -> 3.8781 | J40: Btu/h·°F
A41: CZ10 | B41: 57.1 | C41: =$F$22*($B$26-B41)*$B$28 -> 85054.194 | D41: =C41*$B$27 -> 51032.516 | E41: =_xlfn.LET(_xlpm.x,_xlfn.XLOOKUP(D41,$D$53:$D$67,$D$53:$D$67,"",1),IF(_xlpm.x="",ROUNDUP(D41,0),_xlpm.x)) -> 61419 | F41: =_xlfn.LET(_xlpm.v,MAX(30,$F$22*$B$29),_xlpm.x,_xlfn.XLOOKUP(_xlpm.v,$G$53:$G$67,$G$53:$G$67,"",1),IF(_xlpm.x="",ROUNDUP(_xlpm.v,0),_xlpm.x)) -> 65 | G41: =0.3+27/F41 -> 0.71538462 | H41: =IF($F$22>0,"%/hr","Btu/hr") -> %/hr | I41: =0.0834*G41*F41 -> 3.8781 | J41: Btu/h·°F
A42: CZ11 | B42: 50.5 | C42: =$F$22*($B$26-B42)*$B$28 -> 92260.326 | D42: =C42*$B$27 -> 55356.195 | E42: =_xlfn.LET(_xlpm.x,_xlfn.XLOOKUP(D42,$D$53:$D$67,$D$53:$D$67,"",1),IF(_xlpm.x="",ROUNDUP(D42,0),_xlpm.x)) -> 61419 | F42: =_xlfn.LET(_xlpm.v,MAX(30,$F$22*$B$29),_xlpm.x,_xlfn.XLOOKUP(_xlpm.v,$G$53:$G$67,$G$53:$G$67,"",1),IF(_xlpm.x="",ROUNDUP(_xlpm.v,0),_xlpm.x)) -> 65 | G42: =0.3+27/F42 -> 0.71538462 | H42: =IF($F$22>0,"%/hr","Btu/hr") -> %/hr | I42: =0.0834*G42*F42 -> 3.8781 | J42: Btu/h·°F
A43: CZ12 | B43: 51.4 | C43: =$F$22*($B$26-B43)*$B$28 -> 91277.671 | D43: =C43*$B$27 -> 54766.603 | E43: =_xlfn.LET(_xlpm.x,_xlfn.XLOOKUP(D43,$D$53:$D$67,$D$53:$D$67,"",1),IF(_xlpm.x="",ROUNDUP(D43,0),_xlpm.x)) -> 61419 | F43: =_xlfn.LET(_xlpm.v,MAX(30,$F$22*$B$29),_xlpm.x,_xlfn.XLOOKUP(_xlpm.v,$G$53:$G$67,$G$53:$G$67,"",1),IF(_xlpm.x="",ROUNDUP(_xlpm.v,0),_xlpm.x)) -> 65 | G43: =0.3+27/F43 -> 0.71538462 | H43: =IF($F$22>0,"%/hr","Btu/hr") -> %/hr | I43: =0.0834*G43*F43 -> 3.8781 | J43: Btu/h·°F
A44: CZ13 | B44: 51.7 | C44: =$F$22*($B$26-B44)*$B$28 -> 90950.12 | D44: =C44*$B$27 -> 54570.072 | E44: =_xlfn.LET(_xlpm.x,_xlfn.XLOOKUP(D44,$D$53:$D$67,$D$53:$D$67,"",1),IF(_xlpm.x="",ROUNDUP(D44,0),_xlpm.x)) -> 61419 | F44: =_xlfn.LET(_xlpm.v,MAX(30,$F$22*$B$29),_xlpm.x,_xlfn.XLOOKUP(_xlpm.v,$G$53:$G$67,$G$53:$G$67,"",1),IF(_xlpm.x="",ROUNDUP(_xlpm.v,0),_xlpm.x)) -> 65 | G44: =0.3+27/F44 -> 0.71538462 | H44: =IF($F$22>0,"%/hr","Btu/hr") -> %/hr | I44: =0.0834*G44*F44 -> 3.8781 | J44: Btu/h·°F
... A47: CZ16 | B47: 41.4 | C47: =$F$22*($B$26-B47)*$B$28 -> 102196.05 | D47: =C47*$B$27 -> 61317.632 | E47: =_xlfn.LET(_xlpm.x,_xlfn.XLOOKUP(D47,$D$53:$D$67,$D$53:$D$67,"",1),IF(_xlpm.x="",ROUNDUP(D47,0),_xlpm.x)) -> 61419 | F47: =_xlfn.LET(_xlpm.v,MAX(30,$F$22*$B$29),_xlpm.x,_xlfn.XLOOKUP(_xlpm.v,$G$53:$G$67,$G$53:$G$67,"",1),IF(_xlpm.x="",ROUNDUP(_xlpm.v,0),_xlpm.x)) -> 65 | G47: =0.3+27/F47 -> 0.71538462 | H47: =IF($F$22>0,"%/hr","Btu/hr") -> %/hr | I47: =0.0834*G47*F47 -> 3.8781 | J47: Btu/h·°F
...

Sheet Interior Lights
A1: ="Interior Lighting - "&Prototype!A2 -> Interior Lighting - RetailGrocery
A2: Space Type | B2: New Construction | E2: Existing | H2: Note
B3: LPD (W/ft²) | C3: Additional LPD for Portable Lighting (W/ft²) | D3: Source | E3: LPD (W/ft²) | F3: Additional LPD for Portable Lighting (W/ft²) | G3: Source
A4: Retail Sales Area (Grocery Sales) | B4: 1 | C4: =0.7*0.27 -> 0.189 | D4: T24, part 6, 2025, Table 140.6-C (Area category method) | E4: 1.2 | F4: =0.3*0.27 -> 0.081 | G4: T24, part 6, 2016, Table 140.6-C (Area category method) | H4: Additional lighting was allocated for the Bakery & Deli and Produce areas, which together represent about 27% of the store’s retail sales area; accordingly, the code allowance for extra lighting was multiplied by 27%.
A5: Lounge, Breakroom, or Waiting Area | B5: 0.55 | E5: 0.9
A6: Storage, Commercial/Industrial (Shipping & Handling) | B6: 0.6 | E6: 0.6
A7: Storage, Commercial/Industrial (Refrigerated) | B7: 0.4 | E7: 0.7

Sheet Ext Lighting
A1: ="Exterior Lighting - "&Prototype!A2 -> Exterior Lighting - RetailGrocery
A2: Motion Controlled Luminaires (W) | B2: Non-motion Controlled Luminaires (W) | C2: Total (W) | D2: Source
A3: =G14 -> 1405.5556 | B3: =G15 -> 1160 | C3: =SUM(A3:B3) -> 2565.5556 | D3: T24, 2022
A6: Exterior Lighting
A7: Items (Assume LZ2) | B7: Assumptions [2019 Outdoor Lighting CASE Report & PNNL 90.1-2010 TSD] | D7: Unit | E7: Lighting Power Allowance [T24, 2025, Table 140.7-A & 140.7-B] | F7: Unit | G7: Exterior lighting power (w)
A8: IWA (Initial Wattage Allowance) | E8: 200 | F8: W | G8: =$E8 -> 200
A9: Parking area | B9: 400 ft² for every parking space 1 parking space per 360 ft² of gross building area | C9: =B21/360*400 -> 55555.556 | D9: (ft²) | E9: 0.019 | F9: (W/ft²) | G9: =$E9*C9 -> 1055.5556
A10: Building Entrance | B10: 1 per 5,000 sf footprint | C10: =ROUNDUP(B21/5000,0) -> 10 | D10: (count) | E10: 15 | F10: (W/ea) | G10: =E10*C10 -> 150
A11: Hardscape Ornamental Light | B11: 0.1 ft² per 1 ft² of gross bldg area [2019 Lighting CASE report,Table 36] *The 0.5 multiplier has not been applied, as it is assumed it will be incorporated later during the measure analysis study. | C11: =B21*0.1 -> 5000 | D11: (ft²) | E11: 0.007 | F11: (W/ft²) | G11: =E11*C11 -> 35
A12: Building façade | B12: 0.1 W per 1 ft² of facade area Façade Area = Perimeter × 0.5 × 25 ft The 0.5 factor assumes that only half of the perimeter walls are lit. -Formula ia developed based on the 2019 Outdoor Lighting CASE report | C12: =B20*0.5*Prototype!B16 -> 11250 | D12: (ft²) | E12: 0.1 | F12: (W/ft²) | G12: =E12*C12 -> 1125
A13: Sales canopy | B13: 0.1 ft² per ft² of gross bldg area | C13: =(B21/B22)*0.1*0 -> 0 | D13: (ft²) | E13: 0.47 | F13: (W/ft²) | G13: =E13*C13 -> 0
A14: Motion controlled Luminaires | G14: =SUM(G8:G13)-G15 -> 1405.5556
A15: Non-motion-controlled Luminaires | G15: =G11+G12 -> 1160
A16: Total | G16: =G14+G15 -> 2565.5556
A18: *Developed based on 2019 Outdoor Lighting CASE Report
A20: Perimeter | B20: =200*2+250*2 -> 900
A21: Total floor area | B21: 50000
A22: Floors | B22: 1
A26: Background Data [To be deleted prior to publication]

Sheet Equipment
A1: ="Equipment - "&Prototype!A2 -> Equipment - RetailGrocery
A2: Space Type | B2: Plug Load Power Density (W/ft²) | C2: Source | D2: Note
A3: Retail Sales Area (Grocery Sales) | B3: 0.4 | C3: Proposed Updates to Equipment Power Densities and Schedules in the 2028 Energy Code Nonresidential and Multifamily Alternative Calculation Method (NRMFACM) Reference Manual, August 7, 2025 | D3: Matches Retail/All Other; PNNL prototype =~0.7; T24 Appendix 5.4A =0.2
A4: Lounge, Breakroom, or Waiting Area | B4: 1 | C4: T24 2022 - Appendix 5.4A: Space Use Data-T24N-2022
A5: Storage, Commercial/Industrial (Shipping & Handling) | B5: 0.5
A6: Storage, Commercial/Industrial (Refrigerated) | B6: 0.2
A8: Refrigeration Equipment
A10: Tag | B10: Equipment Type | C10: Location | D10: Duty / Type | E10: Number of Units | F10: Case Length (ft) | G10: Dimensions (LxDxH) | H10: Temp Range (°F) | I10: Refrigerant | J10: Vintage | K10: Rated Power (W/m) | L10: Defrost Power (W/m) | M10: Fan Power (W/m) | N10: Lights Power (W/m) | O10: Anti Sweat (W) | P10: Compressor Type | Q10: Lighting | R10: Defrost Type | S10: Notes | T10: Source
A11: R1 | B11: Open Multideck Dairy Case | C11: Dairy Aisle | D11: Medium Temp | E11: 12 | F11: 12 | G11: 12' x 42" x 84" | H11: 34–38 | I11: R-448A | J11: New Construction | K11: 1143 | L11: 0 | M11: 16 | N11: 16 | O11: 0 | P11: Remote | Q11: LED canopy/shelves | R11: Off-cycle | S11: Glass end panels, night curtain | T11: Grocery Store 50% Energy Savings Technical Support Document NREl (2009) ORNL Prototype Supermarket Building Energy Model (2019) Performance Comparison of Three High Efficiency Medium-Temperature Display Cases (2009)
I12: R22 | J12: Vintage | K12: 1438 | L12: 0 | M12: 43 | N12: 73 | O12: 0
A13: R2 | B13: Service Deli Case | C13: Deli Counter | D13: Medium Temp | E13: 2 | F13: 8 | G13: 8' x 36" x 50" | H13: 36–40 | I13: R-448A | J13: New Construction | K13: 599 | L13: 0 | M13: 20 | N13: 18 | O13: 64 | P13: Remote | Q13: LED top light | R13: Off-cycle | S13: Dual temp option for meats/cheeses
I14: R22 | J14: Vintage | K14: 808 | L14: 0 | M14: 32 | N14: 72 | O14: 0
A15: R3 | B15: Meat Self-Service Case | C15: Meat Department | D15: Medium Temp | E15: 14 | F15: 12 | G15: 12' x 42" x 84" | H15: 28–32 | I15: R-448A | J15: New Construction | K15: 1143 | L15: 0 | M15: 16 | N15: 16 | O15: 0 | P15: Remote | Q15: LED lighting | R15: Off-cycle | S15: Gravity coil, low temp
I16: R22 | J16: Vintage | K16: 1438 | L16: 0 | M16: 43 | N16: 73 | O16: 0
A17: R4 | B17: Produce Case (Refrigerated) | C17: Produce Aisle | D17: Medium Temp | E17: 10 | F17: 8 | G17: 8' x 42" x 84" | H17: 36–40 | I17: R-448A | J17: New Construction | K17: 1143 | L17: 0 | M17: 16 | N17: 16 | O17: 0 | P17: Remote | Q17: LED canopy light | R17: Off-cycle | S17: Mist system optional
I18: R22 | J18: Vintage | K18: 1438 | L18: 0 | M18: 43 | N18: 73 | O18: 0
A19: R5 | B19: Frozen Food Upright Case | C19: Frozen Foods Aisle | D19: Low Temp | E19: 20 | F19: 12 | G19: 12' x 36" x 84" | H19: -5 to 0 | I19: R-448A | J19: New Construction | K19: 426 | L19: 971 | M19: 30 | N19: 26 | O19: 139 | P19: Remote | Q19: LED door lighting | R19: Electric | S19: Glass doors, anti-sweat heaters
I20: R22 | J20: Vintage | K20: 584 | L20: 1222 | M20: 70 | N20: 99 | O20: 78
A21: R6 | B21: Ice Cream Low-Temp Case | C21: Frozen Foods Aisle | D21: Low Temp | E21: 6 | F21: 6 | G21: 6' x 36" x 84" | H21: -10 to -20 | I21: R-448A or CO₂ | J21: New Construction | K21: 521 | L21: 971 | M21: 30 | N21: 26 | O21: 139 | P21: Remote | Q21: LED lighting | R21: Electric | S21: Critical temp holding, tight door seals
I22: R22 | J22: Vintage | K22: 618 | L22: 1222 | M22: 70 | N22: 99 | O22: 78
A23: R7 | B23: Walk-In Cooler (Produce) | C23: Back of House | D23: Medium Temp | E23: 1 | F23: N/A | G23: 10' x 12' x 8' | H23: 34–38 | I23: R-448A | J23: New Construction | K23: 2917 (W) | L23: 0 | M23: 152 (W) | N23: 60 (W) | O23: 0 | P23: Remote condensing unit | Q23: LED ceiling | R23: Off-cycle | S23: Floorless, strip curtain at door
I24: R22 | J24: Vintage | K24: 2917 (W) | L24: 0 | M24: 169 (W) | N24: 120 (W) | O24: 0
A25: R8 | B25: Walk-In Freezer | C25: Back of House | D25: Low Temp | E25: 1 | F25: N/A | G25: 10' x 10' x 8' | H25: -10 to -20 | I25: R-448A | J25: New Construction | K25: 2454 (W) | L25: 1939 (W) | M25: 128 (W) | N25: 50 (W) | O25: 0 | P25: Remote condensing unit | Q25: LED ceiling | R25: Electric | S25: Insulated floor, heated door frame
I26: R22 | J26: Vintage | K26: 2454 (W) | L26: 1939 (W) | M26: 196 (W) | N26: 100 (W) | O26: 0
A27: R9 | B27: Beverage Case | C27: Front of Store | D27: Medium Temp | E27: 4 | F27: 8 | G27: 8' x 36" x 84" | H27: 34–38 | I27: R-448A | J27: New Construction | K27: 1143 | L27: 0 | M27: 16 | N27: 16 | O27: 64 | P27: Remote | Q27: LED shelves | R27: Off-cycle | S27: Reach-in with glass doors
I28: R22 | J28: Vintage | K28: 1438 | L28: 0 | M28: 43 | N28: 73 | O28: 0
A29: R10 | B29: Grab-n-Go Sandwich Cooler | C29: Front Grab-n-Go Area | D29: Medium Temp | E29: 2 | F29: 6 | G29: 6' x 30" x 60" | H29: 36–40 | I29: R-448A | J29: New Construction | K29: 599 | L29: 0 | M29: 20 | N29: 18 | O29: 64 | P29: Self-contained | Q29: LED canopy | R29: Off-cycle | S29: Plug-in, casters for mobility
I30: R22 | J30: Vintage | K30: 808 | L30: 0 | M30: 32 | N30: 72 | O30: 0
A31: Total | E31: =SUM(E11:E29) -> 72 | F31: =SUMPRODUCT(E11:E29,F11:F29) -> 728
A33: Refrigeration Systems
A34: Vintage | B34: Name | C34: Service | D34: # of compressors | E34: # of condensors | F34: Connected Load (KW) | G34: Heat Rejection | H34: Min SCT (°F) | I34: Condensor Design Capacity (kW) | J34: Condensor Fan Power (W) | K34: Fan Control | L34: Source
A35: New Construction | B35: LT_Refrigeration System | C35: Low Temp (R5, R6, R8) | D35: 4 | E35: 1 | F35: 39.3 | G35: Outdoors | H35: 70 | I35: 83.5 | J35: 4378 | K35: Two Speed | L35: ORNL Prototype Supermarket Building Energy (2019)
B36: MT_Refrigeration System | C36: Medium Temp (R1–R4, R9, R7) | D36: 5 | E36: 1 | F36: 153.6 | G36: Outdoors | H36: 70 | I36: 276.4 | J36: 12884 | K36: Two Speed
B37: R10_SelfContained System | C37: Medium Temp _ Self Contained | D37: 1 | E37: 1 | F37: 2.19 | G37: Checkout_Area | H37: 70 | I37: 3.94 | J37: 869 | K37: Fixed
A38: Vintage | B38: LT_Refrigeration System | C38: Low Temp (R5, R6, R8) | D38: 4 | E38: 1 | F38: 52 | G38: Outdoors | H38: 70 | I38: 110.3 | J38: 5560 | K38: Two Speed | L38: ORNL Prototype Supermarket Building Energy (2019)
B39: MT_Refrigeration System | C39: Medium Temp (R1–R4, R9, R7) | D39: 5 | E39: 1 | F39: 192.7 | G39: Outdoors | H39: 70 | I39: 346.9 | J39: 15991 | K39: Two Speed
B40: R10_SelfContained System | C40: Medium Temp _ Self Contained | D40: 1 | E40: 1 | F40: 2.96 | G40: Checkout_Area | H40: 70 | I40: 5.32 | J40: 930 | K40: Fixed

Sheet Schedules
A1: ="Schedules - "&Prototype!A2 -> Schedules - RetailGrocery
A2: Zone | B2: Schedule Category | C2: Schedule | D2: Source | E2: Type | F2: Hour
F3: 1 | G3: 2 | H3: 3 | I3: 4 | J3: 5 | K3: 6 | L3: 7 | M3: 8 | N3: 9 | O3: 10 | P3: 11 | Q3: 12 | R3: 13 | S3: 14 | T3: 15 | U3: 16 | V3: 17 | W3: 18 | X3: 19 | Y3: 20 | Z3: 21 | AA3: 22 | AB3: 23 | AC3: 24
A4: All | B4: Grocery Sales & Office | C4: Occupancy | D4: NLR Study "Final Optimization Report: Empowering Energy Efficiency in Existing Big-Box Retail/Grocery Stores", (2020) & Adjusted based on Google Popular Time | E4: Weekday | F4: 0 | G4: 0 | H4: 0 | I4: 0 | J4: 0 | K4: 0.05 | L4: 0.1 | M4: 0.15 | N4: 0.2 | O4: 0.3 | P4: 0.4 | Q4: 0.5 | R4: 0.6 | S4: 0.6 | T4: 0.6 | U4: 0.6 | V4: 0.7 | W4: 0.8 | X4: 0.8 | Y4: 0.8 | Z4: 0.6 | AA4: 0.3 | AB4: 0.1 | AC4: 0.05
E5: Saturday | F5: 0 | G5: 0 | H5: 0 | I5: 0 | J5: 0 | K5: 0.05 | L5: 0.1 | M5: 0.2 | N5: 0.3 | O5: 0.5 | P5: 0.7 | Q5: 0.8 | R5: 0.9 | S5: 0.9 | T5: 0.9 | U5: 0.9 | V5: 0.9 | W5: 0.9 | X5: 0.8 | Y5: 0.7 | Z5: 0.6 | AA5: 0.5 | AB5: 0.3 | AC5: 0.1
E6: Sunday | F6: 0 | G6: 0 | H6: 0 | I6: 0 | J6: 0 | K6: 0.05 | L6: 0.1 | M6: 0.2 | N6: 0.3 | O6: 0.5 | P6: 0.7 | Q6: 0.8 | R6: 0.9 | S6: 0.9 | T6: 0.9 | U6: 0.9 | V6: 0.9 | W6: 0.9 | X6: 0.8 | Y6: 0.7 | Z6: 0.6 | AA6: 0.5 | AB6: 0.3 | AC6: 0.1
A7: All | B7: Grocery Sales & Office | C7: Lights | D7: T24 2022 - Appendix 5.4B | E7: Weekday | F7: 0.05 | G7: 0.05 | H7: 0.05 | I7: 0.05 | J7: 0.7 | K7: 1 | L7: 1 | M7: 1 | N7: 1 | O7: 1 | P7: 1 | Q7: 1 | R7: 1 | S7: 1 | T7: 1 | U7: 1 | V7: 1 | W7: 1 | X7: 1 | Y7: 1 | Z7: 1 | AA7: 1 | AB7: 1 | AC7: 1
E8: Saturday | F8: 0.05 | G8: 0.05 | H8: 0.05 | I8: 0.05 | J8: 0.7 | K8: 1 | L8: 1 | M8: 1 | N8: 1 | O8: 1 | P8: 1 | Q8: 1 | R8: 1 | S8: 1 | T8: 1 | U8: 1 | V8: 1 | W8: 1 | X8: 1 | Y8: 1 | Z8: 1 | AA8: 1 | AB8: 1 | AC8: 1
E9: Sunday | F9: 0.05 | G9: 0.05 | H9: 0.05 | I9: 0.05 | J9: 0.7 | K9: 1 | L9: 1 | M9: 1 | N9: 1 | O9: 1 | P9: 1 | Q9: 1 | R9: 1 | S9: 1 | T9: 1 | U9: 1 | V9: 1 | W9: 1 | X9: 1 | Y9: 1 | Z9: 1 | AA9: 1 | AB9: 1 | AC9: 1
A10: All | B10: Grocery Sales & Office | C10: ElecEquipment | D10: Plug load and schedules project with CEC, 2025 | E10: Weekday | F10: 0.4 | G10: 0.4 | H10: 0.4 | I10: 0.4 | J10: 0.4 | K10: 0.9 | L10: 0.9 | M10: 0.9 | N10: 0.9 | O10: 0.9 | P10: 0.9 | Q10: 0.9 | R10: 0.9 | S10: 0.9 | T10: 0.9 | U10: 0.9 | V10: 0.9 | W10: 0.9 | X10: 0.9 | Y10: 0.9 | Z10: 0.9 | AA10: 0.9 | AB10: 0.9 | AC10: 0.9
E11: Saturday | F11: 0.4 | G11: 0.4 | H11: 0.4 | I11: 0.4 | J11: 0.4 | K11: 0.9 | L11: 0.9 | M11: 0.9 | N11: 0.9 | O11: 0.9 | P11: 0.9 | Q11: 0.9 | R11: 0.9 | S11: 0.9 | T11: 0.9 | U11: 0.9 | V11: 0.9 | W11: 0.9 | X11: 0.9 | Y11: 0.9 | Z11: 0.9 | AA11: 0.9 | AB11: 0.9 | AC11: 0.9
E12: Sunday | F12: 0.4 | G12: 0.4 | H12: 0.4 | I12: 0.4 | J12: 0.4 | K12: 0.9 | L12: 0.9 | M12: 0.9 | N12: 0.9 | O12: 0.9 | P12: 0.9 | Q12: 0.9 | R12: 0.9 | S12: 0.9 | T12: 0.9 | U12: 0.9 | V12: 0.9 | W12: 0.9 | X12: 0.9 | Y12: 0.9 | Z12: 0.9 | AA12: 0.9 | AB12: 0.9 | AC12: 0.9
A13: All | B13: Grocery Sales & Office | C13: HVACAvail | D13: T24 2022 - Appendix 5.4B, [Retail] | E13: Weekday | F13: 0 | G13: 0 | H13: 0 | I13: 0 | J13: 1 | K13: 1 | L13: 1 | M13: 1 | N13: 1 | O13: 1 | P13: 1 | Q13: 1 | R13: 1 | S13: 1 | T13: 1 | U13: 1 | V13: 1 | W13: 1 | X13: 1 | Y13: 1 | Z13: 1 | AA13: 1 | AB13: 1 | AC13: 1
E14: Saturday | F14: 0 | G14: 0 | H14: 0 | I14: 0 | J14: 1 | K14: 1 | L14: 1 | M14: 1 | N14: 1 | O14: 1 | P14: 1 | Q14: 1 | R14: 1 | S14: 1 | T14: 1 | U14: 1 | V14: 1 | W14: 1 | X14: 1 | Y14: 1 | Z14: 1 | AA14: 1 | AB14: 1 | AC14: 1
E15: Sunday | F15: 0 | G15: 0 | H15: 0 | I15: 0 | J15: 1 | K15: 1 | L15: 1 | M15: 1 | N15: 1 | O15: 1 | P15: 1 | Q15: 1 | R15: 1 | S15: 1 | T15: 1 | U15: 1 | V15: 1 | W15: 1 | X15: 1 | Y15: 1 | Z15: 1 | AA15: 1 | AB15: 1 | AC15: 1
A16: All | B16: Grocery Sales & Office | C16: ServiceHotWater | D16: T24 2022 - Appendix 5.4B, [Retail] | E16: Weekday | F16: 0.04 | G16: 0.05 | H16: 0.05 | I16: 0.04 | J16: 0.04 | K16: 0.04 | L16: 0.04 | M16: 0.15 | N16: 0.23 | O16: 0.32 | P16: 0.41 | Q16: 0.57 | R16: 0.62 | S16: 0.61 | T16: 0.5 | U16: 0.45 | V16: 0.46 | W16: 0.47 | X16: 0.42 | Y16: 0.34 | Z16: 0.33 | AA16: 0.23 | AB16: 0.13 | AC16: 0.08
E17: Saturday | F17: 0.11 | G17: 0.1 | H17: 0.08 | I17: 0.06 | J17: 0.06 | K17: 0.06 | L17: 0.07 | M17: 0.2 | N17: 0.24 | O17: 0.27 | P17: 0.42 | Q17: 0.54 | R17: 0.59 | S17: 0.6 | T17: 0.49 | U17: 0.48 | V17: 0.47 | W17: 0.46 | X17: 0.44 | Y17: 0.36 | Z17: 0.29 | AA17: 0.22 | AB17: 0.16 | AC17: 0.13
E18: Sunday | F18: 0.07 | G18: 0.07 | H18: 0.07 | I18: 0.06 | J18: 0.06 | K18: 0.06 | L18: 0.07 | M18: 0.1 | N18: 0.12 | O18: 0.14 | P18: 0.29 | Q18: 0.31 | R18: 0.36 | S18: 0.36 | T18: 0.34 | U18: 0.35 | V18: 0.37 | W18: 0.34 | X18: 0.25 | Y18: 0.27 | Z18: 0.21 | AA18: 0.16 | AB18: 0.1 | AC18: 0.06
A19: All | B19: Grocery Sales & Office | C19: Infiltration | D19: T24 2022 - Appendix 5.4B, [Retail] | E19: Weekday | F19: 1 | G19: 1 | H19: 1 | I19: 1 | J19: 0.25 | K19: 0.25 | L19: 0.25 | M19: 0.25 | N19: 0.25 | O19: 0.25 | P19: 0.25 | Q19: 0.25 | R19: 0.25 | S19: 0.25 | T19: 0.25 | U19: 0.25 | V19: 0.25 | W19: 0.25 | X19: 0.25 | Y19: 0.25 | Z19: 0.25 | AA19: 0.25 | AB19: 0.25 | AC19: 0.25
E20: Saturday | F20: 1 | G20: 1 | H20: 1 | I20: 1 | J20: 0.25 | K20: 0.25 | L20: 0.25 | M20: 0.25 | N20: 0.25 | O20: 0.25 | P20: 0.25 | Q20: 0.25 | R20: 0.25 | S20: 0.25 | T20: 0.25 | U20: 0.25 | V20: 0.25 | W20: 0.25 | X20: 0.25 | Y20: 0.25 | Z20: 0.25 | AA20: 0.25 | AB20: 0.25 | AC20: 0.25
