Workbook
Name nonparticipating_forecastzone_scale_factor: #REF!
Name nonparticipating_forecastzone_scale_factor: #REF!
Name nonparticipating_forecastzone_scale_factor: #REF!
Name nonparticipating_forecastzone_scale_factor: 'Energy Usage'!#REF!
Name Space_Function: Data!$A$2:$A$76

Sheet Notes
A1: Data Sources
A2: Dataset | B2: Dodge 2023
B3: Commercial End-Use Survey (CEUS) 2022 | C3: https://www.energy.ca.gov/publications/2023/2022-california-commercial-end-use-survey-ceus-final-report
B4: Comstock 2023 | C4: https://data.openei.org/s3_viewer?bucket=oedi-data-lake&prefix=nrel-pds-building-stock%2Fend-use-load-profiles-for-us-building-stock%2F2023%2Fcomstock_amy2018_release_2%2Fmetadata_and_annual_results%2Fby_state%2Fstate%3DCA%2F
A6: Prototype | B6: CEC 2028 School prototype | C6: https://efiling.energy.ca.gov/GetDocument.aspx?tn=265691&DocumentContentId=102542
A9: Codes | B9: Title 24, part 6, referred to as T24 (1984, 1992,1998, 2001, 2005, 2008, 2013, 2016,2019, 2022, 2025) | C9: https://www.energy.ca.gov/publications/2025/2025-building-energy-efficiency-standards-residential-and-nonresidential
C10: https://codes.iccsafe.org/codes/united-states/california
B11: American Society of Heating, Refrigerating and Air-Conditioning Engineers (ASHRAE) 90.1 (2022) | C11: https://www.ashrae.org/technical-resources/standards-and-guidelines/read-only-versions-of-ashrae-standards
B12: Code of Federal Regulations (CFR) Title 10 (2010) | C12: https://www.govinfo.gov/content/pkg/FR-2009-03-23/pdf/FR-2009-03-23.pdf
B13: CFR Title 10 ( 2024) | C13: https://www.govinfo.gov/content/pkg/CFR-2024-title10-vol3/pdf/CFR-2024-title10-vol3-part431-subpartF.pdf
B15: Alternative Calculation Method (ACM) (2022) | C15: https://www.energy.ca.gov/publications/2022/2022-nonresidential-and-multifamily-alternative-calculation-method-reference
B16: ACM (2025) | C16: https://www.energy.ca.gov/publications/2025/2025-nonresidential-and-multifamily-alternative-calculation-method-reference
B17: Nonres ACM 2022, Appendix 5.4A and Appendix 5.4B | C17: https://www.energy.ca.gov/publications/2022/2022-nonresidential-and-multifamily-alternative-calculation-method-reference
A18: Other | B18: 2022 Reduced infiltration Codes and Standards Enhancement (CASE) report | C18: https://title24stakeholders.com/wp-content/uploads/2020/10/2022-T24-Final-CASE-Report_Reduce-Infiltration.pdf
B19: 2019 Outdoor Lighting CASE Report | C19: https://title24stakeholders.com/wp-content/uploads/2016/10/T24-2019-CASE-Study-Results-Report-Outdoor-Sources_Final_with-Attachments.pdf
B20: 2019 High Efficiency Fume Hoods in Laboratory Spaces CASE Report | C20: https://title24stakeholders.com/wp-content/uploads/2017/09/2019-T24-CASE-Report_Fume-Hoods_Final_September-2017.pdf?
B21: PNNL 20405, 2011 | C21: https://www.pnnl.gov/main/publications/external/technical_reports/PNNL-20405.pdf
B22: Air leakage Memo, NORESCO, 2025 | C22: Infiltration_rate_report_14May2025-Short-Version.docx — internal NORESCO project memo (not a public URL). See Prototype basis / Source access below.
B23: Yousefi, F., Athalye, R., (2025), "Determining Vintage Bins for Prototype Development: An Analysis of California Commercial Buildings," ASHRAE Annual Conference | C23: https://www.thefreelibrary.com/Determining+Vintage+Bins+for+Prototype+Development%3a+An+Analysis+of...-a0879271125
B24: Proposed Updates to Equipment Power Densities and Building Schedules for the 2028 Energy Code, referred to as "Plug load and schedules project with CEC, 2025" (Docket Number =25-BSTD-03 & TN=265693) | C24: https://efiling.energy.ca.gov/GetDocument.aspx?tn=265693&DocumentContentId=102545
B25: ENERGY STAR certified commercial water heaters | C25: https://www.energystar.gov/productfinder/product/certified-commercial-water-heaters/results?fuel_filter=Gas&markets_filter=United+States
B26: Grainger gas tank water heaters (sizes below commercial, e.g. 30–75 kBtu/h) | C26: https://www.grainger.com/category/plumbing/water-heaters/gas-tank-water-heaters
B27: Grainger electric tank water heaters | C27: https://www.grainger.com/category/plumbing/water-heaters/electric-tank-water-heaters
A31: Construction Rate
B43: Dodge 2023 construction rates used in the SCE vintage-bin analysis. Legend labels STC 41 and STC 49 are Dodge structure-type series identifiers from that analysis (Prototype D6, NonRes-Vintage bins-Draft Report-30Nov2023). They are not Title 24 climate zones.
A44: Notes
A45: 2025 T24 | B45: School Building includes four individual buildings, including north classroom, westclassroom, kindergarten, and MPR/Admin.
A46: Prototype basis
A47: Geometry | B47: Geometry is CEC SchoolKto8 as implemented in CBECC 2028 (Prototype C7:C16; four buildings in B40: north classroom, west classroom, kindergarten, MPR/Admin). Floor area 49,979 ft². Prototype comparison columns (DEER Education-Primary, PNNL SchoolPrimary) are reference only; they are not the geometry basis.
A48: Vintage bins | B48: Existing vintages Pre-1978, 1978-1997, 1998-2007, 2008-2018 plus New Construction 2019+ follow the SCE Enhanced Prototypes vintage-bin analysis (Prototype D6). Dodge 2023 construction rates (figure above) inform stock weighting for existing California schools; they are not a Title 24 prescriptive requirement.
A49: Curriculum and stock | B49: Conventional K-8 curriculum (classrooms, MPR, kitchen, library, administration). Specialized spaces such as science labs, locker rooms, and computer classrooms are not in the CEC space list. The prototype represents average California K-8 stock. Funding and facility-condition variation is not a separate building; it is carried in vintage envelope/HVAC/lighting assumptions (including the 30-year roof replacement on Envelope H8).
A50: WWR, heights, energy | B50: WWR 7.08%, no exterior shades (CEC). Floor-to-floor 14 ft except MPR/Admin 14–25 ft. Existing HVAC: PSZAC + gas furnace (MPR SZVAV). New construction: SZHP. Service water: existing electric resistance; NC heat-pump water heater (Water Heater B3:B4).
A51: Abbreviations | B51: T24 = California Title 24, Part 6. ACM = Nonresidential/Multifamily Alternative Calculation Method Reference Manual. CEC = California Energy Commission. CBECC = California Building Energy Code Compliance software. CEUS = California Commercial End-Use Survey. STC (construction-rate figure) = Dodge structure-type series 41 and 49. PSZAC = packaged single-zone air conditioner. SZHP = single-zone heat pump. HPWH = heat-pump water heater. SRR = skylight-to-roof ratio. WWR = window-to-wall ratio. IWA = initial wattage allowance.
A52: Source access | B52: Column C lists public links where they exist. Dodge 2023 is a licensed dataset with no public URL. The NORESCO air-leakage memo is an internal file (C19), not a webpage. ENERGY STAR water-heater rows use the commercial electric (heat pump) Product Finder and dataset xmq6-bm79. Schedule fractions that cite the Plug Loads and Schedules project with CEC (2025) do not have an external link yet; an ASHRAE paper has been submitted and the citation will be updated when that paper is published or when ACM 2028 is released.
A53: Sources used | B53: Used on this scorecard: CEC SchoolKto8 (efiling tn=265691); T24 2022 App. 5.4A/5.4B; ACM 2025 §5.9.2 and fan tables; T24 Tables 140.3-B, 110.2-A/B, 140.6-C, 140.7-A/B, 120.1-A; 2022 Reduced Infiltration CASE; 2019 Outdoor Lighting CASE; PNNL 20405; ASHRAE 90.1-2022 Appendix A; ASHRAE Handbook of Fundamentals Ch. 4 and 10 (early-vintage windows); ENERGY STAR commercial HPWH list. The 2019 fume-hood CASE remains on the school-family source list; K-8 has no lab exhaust. Reviewer-suggested references that do not support a retained assumption are not added.

Sheet Prototype
A1: NORESCO, Updated September 2026
A2: SchoolK-8
A3: Characteristic | B3: Value | C3: Data Sources
A4: Building Type | B4: K-8 School
A5: Building Category | B5: Nonresidential
A6: Version | B6: v2-0
A7: Vintages | B7: 4 Vintages: Pre-1978, 1978-1997,1998-2007, 2008-2018 New Construction (2019+) | C7: Based on the vintage bin analysis. A summary of the findings is presented in the following paper, with a link provided in the Notes tab: Yousefi, F., Athalye, R. (2025). “Determining Vintage Bins for Prototype Development: An Analysis of California Commercial Buildings.” ASHRAE Annual Conference.
A8: Shape | C8: The analysis uses prototype geometry originally developed by CEC approved 2028 SchoolK-8 prototype.
A9: Total Floor Area (ft²) | B9: 49979.36 | C9: CEC SchoolKto8 (same as Prototype comparison column C).
A10: Aspect Ratio | B10: It varies for different buildings. | C10: Same as the CEC approved 2028 SchoolK-8 prototype
A11: Number of Floors | B11: It varies for different buildings. | C11: Same as the CEC approved 2028 SchoolK-8 prototype
A12: Roof type | B12: Flat | C12: Same as the CEC approved 2028 SchoolK-8 prototype
A13: WWR | B13: 0.0708 | C13: Same as the CEC approved 2028 SchoolK-8 prototype
A14: Shading Geometry | B14: No Shades | C14: Same as the CEC approved 2028 SchoolK-8 prototype
A15: Floor to floor height (feet) | B15: It varies for different buildings: MPR/Admin: 14-25 Other buildings: 14 ft | C15: Same as the CEC approved 2028 SchoolK-8 prototype
A16: Floor to ceiling height (feet) | B16: It varies for different buildings: MPR/Admin: 14-25 Other buildings: 14 ft | C16: Same as the CEC approved 2028 SchoolK-8 prototype
A17: Glazing sill height (feet) | B17: It varies for different buildings. | C17: Same as the CEC approved 2028 SchoolK-8 prototype
A21: Above grade wall area (ft²) | B21: 42450.09
A22: Gross wall area (ft²) | B22: 42450.09
A23: Roof area (ft²) | B23: 37687.78
A24: Underground Gross Wall Area (ft²) | B24: 0
A35: Prototype Geomerty and HVAC Comparison
A36: Program | B36: CalBEM (SchoolK8) | C36: CEC (SchoolKto8) | D36: DEER (Education-Primary School) | E36: PNNL (SchoolPrimary)
A37: Geometry
A38: HVAC and Water Heater
A39: HVAC System Type | B39: System: central air loops Distribution: 38 air loops; constant-volume no-reheat terminal; DX cooling; electric heating | C39: System: central VAV air loops Distribution: 38 air loops; VAV no-reheat and constant-volume no-reheat terminals; DX cooling; electric heating and natural-gas heating | D39: System: unitary/package systems + central VAV air loops Distribution: 7 air loops; VAV no-reheat terminal; DX cooling; natural-gas heating | E39: System: unitary/package systems + central VAV air loops Distribution: 7 air loops; VAV reheat and constant-volume no-reheat terminals; DX cooling; hot-water heating and natural-gas heating Plant: 1 natural-gas hot-water boiler
A40: Water Heater | B40: 4 water heaters: 4 electric 4 service water loops | C40: 1 water heater: 1 electric 1 service water loop | D40: 1 water heater: 1 natural-gas 1 service water loop | E40: 2 water heaters: 1 electric, 1 natural-gas 1 service water loop

Sheet Zones
A1: ="Proposed Layout - "&Prototype!B4 -> Proposed Layout - K-8 School
A2: Building | B2: Space/Thermal Zone | C2: Space Type [Primarily from: T24, 2022 Appendix 5.4A] - See Notes column | D2: HVAC System Name/AHU Name | E2: Schedule Category | F2: Conditioned (Y/N) | G2: Area Fraction | H2: Area (ft²) | I2: Volume (ft³) | J2: Multipliers | K2: Number of People | L2: People (Persons/1,000 ft²) [T24, 2025,Table 120.1-A] | M2: Notes
A3: SkoolK-8 Admin/MPR | B3: Admin/MPR_Breakroom_Zn | C3: Lounge, Breakroom, or Waiting Area | D3: AHU-1 | E3: MPR | F3: Y | G3: =H3/$H$41 -> 0.011508749 | H3: 575.2 | I3: =H3*14 -> 8052.8 | J3: 1 | K3: =L3*H3/1000 -> 18.9816 | L3: 33
A4: SkoolK-8 Admin/MPR | B4: Admin/MPR_Conference Room Zns 3_Zn | C4: Convention, Conference, Multipurpose and Meeting Area | D4: AHU-2 | E4: MPR | F4: Y | G4: =H4/$H$41 -> 0.033508626 | H4: 1674.74 | I4: =H4*14 -> 23446.36 | J4: 1 | K4: =L4*H4/1000 -> 55.26642 | L4: 33
A5: SkoolK-8 Admin/MPR | B5: Admin/MPR_Corridor_Zn | C5: Corridor Area | D5: AHU-3 | E5: MPR | F5: Y | G5: =H5/$H$41 -> 0.023239989 | H5: 1161.52 | I5: =H5*14 -> 16261.28 | J5: 1 | K5: =L5*H5/1000 -> 5.8076 | L5: 5
A6: SkoolK-8 Admin/MPR | B6: Admin/MPR_EMT_Zn | C6: Electrical, Mechanical, Telephone Rooms | D6: AHU-4 | E6: MPR | F6: Y | G6: =H6/$H$41 -> 0.0055664967 | H6: 278.21 | I6: =H6*14 -> 3894.94 | J6: 1 | K6: =L6*H6/1000 -> 1.39105 | L6: 5
A7: SkoolK-8 Admin/MPR | B7: Admin/MPR_IDF Room_Zn | C7: Electrical, Mechanical, Telephone Rooms | D7: AHU-5 | E7: MPR | F7: Y | G7: =H7/$H$41 -> 0.0068074087 | H7: 340.23 | I7: =H7*14 -> 4763.22 | J7: 1 | K7: =L7*H7/1000 -> 1.70115 | L7: 5
A8: SkoolK-8 Admin/MPR | B8: Admin/MPR_Kitchen_Zn | C8: Kitchen/Food Preparation Area | D8: AHU-6 | E8: Kitchen | F8: Y | G8: =H8/$H$41 -> 0.02915703 | H8: 1457.25 | I8: =H8*14 -> 20401.5 | J8: 1 | K8: =L8*H8/1000 -> 4.37175 | L8: 3
A9: SkoolK-8 Admin/MPR | B9: Admin/MPR_Lobby_Zn | C9: Lobby, Main Entry | D9: AHU-7 | E9: MPR | F9: Y | G9: =H9/$H$41 -> 0.024839649 | H9: 1241.47 | I9: =H9*14 -> 17380.58 | J9: 1 | K9: =L9*H9/1000 -> 40.96851 | L9: 33
A10: SkoolK-8 Admin/MPR | B10: Admin/MPR_Multipurpose Room Zns 3_Zn | C10: Convention, Conference, Multipurpose and Meeting Area | D10: AHU-8 | E10: MPR | F10: Y | G10: =H10/$H$41 -> 0.11028931 | H10: 5512.19 | I10: =H10*25 -> 137804.75 | J10: 1 | K10: =L10*H10/1000 -> 181.90227 | L10: 33
A11: SkoolK-8 Admin/MPR | B11: Admin/MPR_Office - LT 250 sf Zns 6_Zn | C11: Office Area (<250 square feet) | D11: AHU-9 | E11: MPR | F11: Y | G11: =H11/$H$41 -> 0.020975655 | H11: 1048.35 | I11: =H11*14 -> 14676.9 | J11: 1 | K11: =L11*H11/1000 -> 5.24175 | L11: 5
A12: SkoolK-8 Admin/MPR | B12: Admin/MPR_Restroom Zns 3_Zn | C12: Restrooms | D12: AHU-10 | E12: MPR | F12: Y | G12: =H12/$H$41 -> 0.01803084 | H12: 901.17 | I12: =H12*14 -> 12616.38 | J12: 1 | K12: =L12*H12/1000 -> 4.50585 | L12: 5
A13: SkoolK-8 Admin/MPR | B13: Admin/MPR_Storage - General_Zn | C13: Storage (General) | D13: AHU-11 | E13: MPR | F13: Y | G13: =H13/$H$41 -> 0.024964901 | H13: 1247.73 | I13: =H13*14 -> 17468.22 | J13: 1 | K13: =L13*H13/1000 -> 6.23865 | L13: 5
A14: SkoolK-8 Admin/MPR | B14: Admin/MPR_Storage - Refrigerated_Zn | C14: Storage, Commercial/Industrial (Refrigerated) | D14: AHU-12 | E14: MPR | F14: Y | G14: =H14/$H$41 -> 0.0050364781 | H14: 251.72 | I14: =H14*14 -> 3524.08 | J14: 1 | K14: =L14*H14/1000 -> 0 | L14: 0
A15: SkoolK-8 Admin/MPR | B15: Admin/MPR_Theater - Performance_Zn | C15: Theater Area (Performance) | D15: AHU-13 | E15: MPR | F15: Y | G15: =H15/$H$41 -> 0.021319997 | H15: 1065.56 | I15: =H15*25 -> 26639 | J15: 1 | K15: =L15*H15/1000 -> 35.16348 | L15: 33
A16: SkoolK-8 North Classrooms | B16: Classrm N_Flr 1_Classroom-01_Zn | C16: Classroom, Lecture, Training, Vocational Areas | D16: AHU-14 | E16: Classroom | F16: Y | G16: =H16/$H$41 -> 0.02004327 | H16: 1001.75 | I16: =H16*14 -> 14024.5 | J16: 1 | K16: =L16*H16/1000 -> 25.04375 | L16: 25
A17: SkoolK-8 North Classrooms | B17: Classrm N_Flr 1_Classroom-02 Zns 6_Zn | C17: Classroom, Lecture, Training, Vocational Areas | D17: AHU-15 | E17: Classroom | F17: Y | G17: =H17/$H$41 -> 0.12113058 | H17: 6054.03 | I17: =H17*14 -> 84756.42 | J17: 1 | K17: =L17*H17/1000 -> 151.35075 | L17: 25
A18: SkoolK-8 North Classrooms | B18: Classrm N_Flr 1_Office - LT 250 sf_Zn | C18: Office Area (<250 square feet) | D18: AHU-16 | E18: Classroom | F18: Y | G18: =H18/$H$41 -> 0.0057649786 | H18: 288.13 | I18: =H18*14 -> 4033.82 | J18: 1 | K18: =L18*H18/1000 -> 1.44065 | L18: 5
A19: SkoolK-8 North Classrooms | B19: Classrm N_Flr 1_Restroom_Zn | C19: Restrooms | D19: AHU-17 | E19: Classroom | F19: Y | G19: =H19/$H$41 -> 0.010658398 | H19: 532.7 | I19: =H19*14 -> 7457.8 | J19: 1 | K19: =L19*H19/1000 -> 2.6635 | L19: 5
A20: SkoolK-8 North Classrooms | B20: Classrm N_Flr 2_Classroom-01 Zns 6_Zn | C20: Classroom, Lecture, Training, Vocational Areas | D20: AHU-18 | E20: Classroom | F20: Y | G20: =H20/$H$41 -> 0.12113058 | H20: 6054.03 | I20: =H20*14 -> 84756.42 | J20: 1 | K20: =L20*H20/1000 -> 151.35075 | L20: 25
A21: SkoolK-8 North Classrooms | B21: Classrm N_Flr 2_Classroom-02_Zn | C21: Classroom, Lecture, Training, Vocational Areas | D21: AHU-19 | E21: Classroom | F21: Y | G21: =H21/$H$41 -> 0.02004327 | H21: 1001.75 | I21: =H21*14 -> 14024.5 | J21: 1 | K21: =L21*H21/1000 -> 25.04375 | L21: 25
A22: SkoolK-8 North Classrooms | B22: Classrm N_Flr 2_Office - LT 250 sf_Zn | C22: Office Area (<250 square feet) | D22: AHU-20 | E22: Classroom | F22: Y | G22: =H22/$H$41 -> 0.0057649786 | H22: 288.13 | I22: =H22*14 -> 4033.82 | J22: 1 | K22: =L22*H22/1000 -> 1.44065 | L22: 5
A23: SkoolK-8 North Classrooms | B23: Classrm N_Flr 2_Restroom_Zn | C23: Restrooms | D23: AHU-21 | E23: Classroom | F23: Y | G23: =H23/$H$41 -> 0.010658398 | H23: 532.7 | I23: =H23*14 -> 7457.8 | J23: 1 | K23: =L23*H23/1000 -> 2.6635 | L23: 5
A24: SkoolK-8 West Classrooms | B24: Classrm W_Flr 1_Classroom Zns 2_Zn | C24: Classroom, Lecture, Training, Vocational Areas | D24: AHU-22 | E24: Classroom | F24: Y | G24: =H24/$H$41 -> 0.041115764 | H24: 2054.94 | I24: =H24*14 -> 28769.16 | J24: 1 | K24: =L24*H24/1000 -> 51.3735 | L24: 25
A25: SkoolK-8 West Classrooms | B25: Classrm W_Flr 1_EMT-01_Zn | C25: Electrical, Mechanical, Telephone Rooms | D25: AHU-23 | E25: Classroom | F25: Y | G25: =H25/$H$41 -> 0.002421199 | H25: 121.01 | I25: =H25*14 -> 1694.14 | J25: 1 | K25: =L25*H25/1000 -> 0.60505 | L25: 5
A26: SkoolK-8 West Classrooms | B26: Classrm W_Flr 1_EMT-02_Zn | C26: Electrical, Mechanical, Telephone Rooms | D26: AHU-24 | E26: Classroom | F26: Y | G26: =H26/$H$41 -> 0.0019610091 | H26: 98.01 | I26: =H26*14 -> 1372.14 | J26: 1 | K26: =L26*H26/1000 -> 0.49005 | L26: 5
A27: SkoolK-8 West Classrooms | B27: Classrm W_Flr 1_Library - Reading Area_Zn | C27: Library (Reading Area) | D27: AHU-25 | E27: Classroom | F27: Y | G27: =H27/$H$41 -> 0.023952483 | H27: 1197.13 | I27: =H27*14 -> 16759.82 | J27: 1 | K27: =L27*H27/1000 -> 11.9713 | L27: 10
... A40: SkoolK-8 Kindergarten | B40: Kindergarten_Storage - General_Zn | C40: Storage (General) | D40: AHU-38 | E40: Classroom | F40: Y | G40: =H40/$H$41 -> 0.023685773 | H40: 1183.8 | I40: =H40*14 -> 16573.2 | J40: 1 | K40: =L40*H40/1000 -> 5.919 | L40: 5
A41: Total (4 Buildings) | B41: Total (38 spaces) | C41: Total (13 Space types) | D41: Total (38 HVAC Systems) | E41: Total (3 Schedule categories)) | F41: Total (38 Conditioned zones) | G41: =H41/$H$41 -> 1 | H41: =SUM(H3:H40) -> 49979.37 | I41: =SUM(I3:I40) -> 772066.43 | K41: =SUM(K3:K40) -> 1068.3275
O43: Area Distribution By Space Type
O44: Space Type | R44: % Area
O45: Lounge, Breakroom, or Waiting Area | R45: =SUMIF($C$3:$C$40,O45,$G$3:$G$40) -> 0.011508749
O46: Convention, Conference, Multipurpose and Meeting Area | R46: =SUMIF($C$3:$C$40,O46,$G$3:$G$40) -> 0.14379793
O47: Corridor Area | R47: =SUMIF($C$3:$C$40,O47,$G$3:$G$40) -> 0.023239989
O48: Electrical, Mechanical, Telephone Rooms | R48: =SUMIF($C$3:$C$40,O48,$G$3:$G$40) -> 0.024306429
O49: Kitchen/Food Preparation Area | R49: =SUMIF($C$3:$C$40,O49,$G$3:$G$40) -> 0.02915703
O50: Lobby, Main Entry | R50: =SUMIF($C$3:$C$40,O50,$G$3:$G$40) -> 0.024839649
O51: Office Area (<250 square feet) | R51: =SUMIF($C$3:$C$40,O51,$G$3:$G$40) -> 0.032505612
O52: Restrooms | R52: =SUMIF($C$3:$C$40,O52,$G$3:$G$40) -> 0.067201727
O53: Storage (General) | R53: =SUMIF($C$3:$C$40,O53,$G$3:$G$40) -> 0.058231626
...

Sheet Envelope
A1: ="Envelope - "&Prototype!A2 -> Envelope - SchoolK-8
A2: Element | B2: Prototype | C2: Assembly Type | D2: Construction | E2: Thermal properties | F2: Vintage | G2: Selected T24 | H2: Notes | I2: CZ1 | J2: CZ2 | K2: CZ3 | L2: CZ4 | M2: CZ5 | N2: CZ6 | O2: CZ7 | P2: CZ8 | Q2: CZ9 | R2: CZ10 | S2: CZ11 | T2: CZ12 | U2: CZ13 | V2: CZ14 | W2: CZ15 | X2: CZ16
A3: External Wall | B3: =Prototype!A2 -> SchoolK-8 | C3: ExtWall_MetalFramed_NonRes | D3: Metal framed wall: Metal frame + insulation + Gypsum board | E3: U-factor IP | F3: Pre 1978 | G3: N/A | H3: ASHRAE 90.1, 2022, Table A3.3.3.1, 3.5", R-0 | I3: 0.352 | J3: 0.352 | K3: 0.352 | L3: 0.352 | M3: 0.352 | N3: 0.352 | O3: 0.352 | P3: 0.352 | Q3: 0.352 | R3: 0.352 | S3: 0.352 | T3: 0.352 | U3: 0.352 | V3: 0.352 | W3: 0.352 | X3: 0.352
F4: 1978-1997 | G4: 1992 | H4: TABLE NO. 1-I | I4: 0.182 | J4: 0.189 | K4: 0.189 | L4: 0.189 | M4: 0.189 | N4: 0.189 | O4: 0.189 | P4: 0.189 | Q4: 0.189 | R4: 0.189 | S4: 0.182 | T4: 0.182 | U4: 0.182 | V4: 0.182 | W4: 0.182 | X4: 0.182
F5: 1998-2007 | G5: 2001 | H5: Table 1-H | I5: 0.182 | J5: 0.182 | K5: 0.189 | L5: 0.189 | M5: 0.189 | N5: 0.189 | O5: 0.189 | P5: 0.189 | Q5: 0.189 | R5: 0.182 | S5: 0.182 | T5: 0.182 | U5: 0.182 | V5: 0.182 | W5: 0.182 | X5: 0.182
F6: 2008-2018 | G6: 2013 | H6: Table 140.3-B | I6: 0.098 | J6: 0.062 | K6: 0.082 | L6: 0.062 | M6: 0.062 | N6: 0.098 | O6: 0.098 | P6: 0.062 | Q6: 0.062 | R6: 0.062 | S6: 0.062 | T6: 0.062 | U6: 0.062 | V6: 0.062 | W6: 0.062 | X6: 0.062
F7: 2019+ | G7: 2025 | H7: Table 140.3-B (2025) Metal-framed walls | I7: 0.06 | J7: 0.055 | K7: 0.071 | L7: 0.055 | M7: 0.055 | N7: 0.06 | O7: 0.06 | P7: 0.055 | Q7: 0.055 | R7: 0.055 | S7: 0.055 | T7: 0.055 | U7: 0.055 | V7: 0.055 | W7: 0.055 | X7: 0.055
A8: Roof | B8: =$B$3 -> SchoolK-8 | C8: FlatRoof_WoodFramedAndOther_NonRes | D8: Metal deck roof: roof membrane+roof insulation+metal decking | E8: U-factor IP | F8: Pre 1978 | G8: N/A | H8: Considering 30 years for roof/ insultation replacement | I8: 0.057 | J8: 0.057 | K8: 0.057 | L8: 0.057 | M8: 0.057 | N8: 0.078 | O8: 0.078 | P8: 0.078 | Q8: 0.078 | R8: 0.078 | S8: 0.057 | T8: 0.057 | U8: 0.057 | V8: 0.057 | W8: 0.057 | X8: 0.057
F9: 1978-1997 | G9: N/A | I9: 0.057 | J9: 0.057 | K9: 0.057 | L9: 0.057 | M9: 0.057 | N9: 0.078 | O9: 0.078 | P9: 0.078 | Q9: 0.078 | R9: 0.078 | S9: 0.057 | T9: 0.057 | U9: 0.057 | V9: 0.057 | W9: 0.057 | X9: 0.057
F10: 1998-2007 | G10: 2001 | H10: Table 1-H | I10: 0.057 | J10: 0.057 | K10: 0.057 | L10: 0.057 | M10: 0.057 | N10: 0.078 | O10: 0.078 | P10: 0.078 | Q10: 0.078 | R10: 0.057 | S10: 0.057 | T10: 0.057 | U10: 0.057 | V10: 0.057 | W10: 0.057 | X10: 0.057
F11: 2008-2018 | G11: 2013 | H11: Table 140.3-B | I11: 0.049 | J11: 0.039 | K11: 0.039 | L11: 0.039 | M11: 0.049 | N11: 0.075 | O11: 0.067 | P11: 0.067 | Q11: 0.039 | R11: 0.039 | S11: 0.039 | T11: 0.039 | U11: 0.039 | V11: 0.039 | W11: 0.039 | X11: 0.039
F12: 2019+ | G12: 2025 | H12: Table 140.3-B | I12: 0.028 | J12: 0.028 | K12: 0.028 | L12: 0.028 | M12: 0.028 | N12: 0.047 | O12: 0.047 | P12: 0.047 | Q12: 0.028 | R12: 0.028 | S12: 0.028 | T12: 0.028 | U12: 0.028 | V12: 0.028 | W12: 0.028 | X12: 0.028
A13: Windows | B13: SchoolK-8 | C13: FixedWindow_NonRes | D13: Single pane | E13: U-factor IP | F13: Pre 1978 | G13: N/A | H13: ASHRAE Handbook of Fundamentals (Table 4-Ch15) for single pane & T24, 2013 for double pane (33%-67%)* | I13: =0.33*1.12+0.67*I16 -> 0.6108 | J13: =0.33*1.12+0.67*J16 -> 0.6108 | K13: =0.33*1.12+0.67*K16 -> 0.6108 | L13: =0.33*1.12+0.67*L16 -> 0.6108 | M13: =0.33*1.12+0.67*M16 -> 0.6108 | N13: =0.33*1.12+0.67*N16 -> 0.6108 | O13: =0.33*1.12+0.67*O16 -> 0.6108 | P13: =0.33*1.12+0.67*P16 -> 0.6108 | ... X13: =0.33*1.12+0.67*X16 -> 0.6108
F14: 1978-1997 | G14: N/A | I14: =0.33*1.12+0.67*I16 -> 0.6108 | J14: =0.33*1.12+0.67*J16 -> 0.6108 | K14: =0.33*1.12+0.67*K16 -> 0.6108 | L14: =0.33*1.12+0.67*L16 -> 0.6108 | M14: =0.33*1.12+0.67*M16 -> 0.6108 | N14: =0.33*1.12+0.67*N16 -> 0.6108 | O14: =0.33*1.12+0.67*O16 -> 0.6108 | P14: =0.33*1.12+0.67*P16 -> 0.6108 | ... X14: =0.33*1.12+0.67*X16 -> 0.6108
D15: Double pane | F15: 1998-2007 | G15: 2001 | H15: Table 1-H | I15: 0.49 | J15: 0.49 | K15: 0.81 | L15: 0.81 | M15: 0.81 | N15: 0.81 | O15: 0.81 | P15: 0.81 | Q15: 0.81 | R15: 0.49 | S15: 0.49 | T15: 0.49 | U15: 0.49 | V15: 0.49 | W15: 0.49 | X15: 0.49
F16: 2008-2018 | G16: 2013 | H16: Table 140.3-B | I16: 0.36 | J16: 0.36 | K16: 0.36 | L16: 0.36 | M16: 0.36 | N16: 0.36 | O16: 0.36 | P16: 0.36 | Q16: 0.36 | R16: 0.36 | S16: 0.36 | T16: 0.36 | U16: 0.36 | V16: 0.36 | W16: 0.36 | X16: 0.36
F17: 2019+ | G17: 2025 | H17: Table 140.3-B | I17: 0.36 | J17: 0.36 | K17: 0.36 | L17: 0.36 | M17: 0.36 | N17: 0.36 | O17: 0.36 | P17: 0.36 | Q17: 0.34 | R17: 0.36 | S17: 0.34 | T17: 0.34 | U17: 0.34 | V17: 0.34 | W17: 0.34 | X17: 0.36
C18: FixedWindow_NonRes | D18: Single pane | E18: SHGC | F18: Pre 1978 | G18: N/A | H18: ASHRAE Handbook of Fundamentals (Table 10-Ch15) for single pane & T24, 2013 for double pane (33%-67%)* | I18: =0.79*0.33+0.67*I21 -> 0.4282 | J18: =0.79*0.33+0.67*J21 -> 0.4282 | K18: =0.79*0.33+0.67*K21 -> 0.4282 | L18: =0.79*0.33+0.67*L21 -> 0.4282 | M18: =0.79*0.33+0.67*M21 -> 0.4282 | N18: =0.79*0.33+0.67*N21 -> 0.4282 | O18: =0.79*0.33+0.67*O21 -> 0.4282 | P18: =0.79*0.33+0.67*P21 -> 0.4282 | ... X18: =0.79*0.33+0.67*X21 -> 0.4282
F19: 1978-1997 | G19: N/A | I19: =0.79*0.33+0.67*I21 -> 0.4282 | J19: =0.79*0.33+0.67*J21 -> 0.4282 | K19: =0.79*0.33+0.67*K21 -> 0.4282 | L19: =0.79*0.33+0.67*L21 -> 0.4282 | M19: =0.79*0.33+0.67*M21 -> 0.4282 | N19: =0.79*0.33+0.67*N21 -> 0.4282 | O19: =0.79*0.33+0.67*O21 -> 0.4282 | P19: =0.79*0.33+0.67*P21 -> 0.4282 | ... X19: =0.79*0.33+0.67*X21 -> 0.4282
D20: Double pane | F20: 1998-2007 | G20: 2001 | H20: Table 1-H — WWR ≤10% (prototype 7.08%), SHGC non-north. | I20: 0.43 | J20: 0.31 | K20: 0.41 | L20: 0.41 | M20: 0.41 | N20: 0.34 | O20: 0.34 | P20: 0.34 | Q20: 0.34 | R20: 0.31 | S20: 0.31 | T20: 0.31 | U20: 0.31 | V20: 0.31 | W20: 0.31 | X20: 0.43
F21: 2008-2018 | G21: 2013 | H21: Table 140.3-B | I21: 0.25 | J21: 0.25 | K21: 0.25 | L21: 0.25 | M21: 0.25 | N21: 0.25 | O21: 0.25 | P21: 0.25 | Q21: 0.25 | R21: 0.25 | S21: 0.25 | T21: 0.25 | U21: 0.25 | V21: 0.25 | W21: 0.25 | X21: 0.25
F22: 2019+ | G22: 2025 | H22: Table 140.3-B | I22: 0.25 | J22: 0.25 | K22: 0.25 | L22: 0.25 | M22: 0.25 | N22: 0.25 | O22: 0.25 | P22: 0.25 | Q22: 0.22 | R22: 0.25 | S22: 0.22 | T22: 0.22 | U22: 0.22 | V22: 0.22 | W22: 0.22 | X22: 0.25
A23: Skylight | B23: SchoolK-8 | C23: Skylight | D23: Plastic curb-mounted | E23: U-factor IP | F23: Pre 1978 | G23: 1992 | H23: Table 1-I Translucent (1992 term for this plastic curb product). 4 MPR skylights; CalBEM 63.97 ft² vs CEC 130.57 ft²; SRR ~0.17%/0.35% (0–2% bin). | I23: 0.85 | J23: 1.31 | K23: 1.31 | L23: 1.31 | M23: 1.31 | N23: 1.31 | O23: 1.31 | P23: 1.31 | Q23: 1.31 | R23: 1.31 | S23: 0.85 | T23: 0.85 | U23: 0.85 | V23: 0.85 | W23: 0.85 | X23: 0.85
F24: 1978-1997 | G24: 1992 | I24: =I23 -> 0.85 | J24: =J23 -> 1.31 | K24: =K23 -> 1.31 | L24: =L23 -> 1.31 | M24: =M23 -> 1.31 | N24: =N23 -> 1.31 | O24: =O23 -> 1.31 | P24: =P23 -> 1.31 | ... X24: =X23 -> 0.85
F25: 1998-2007 | G25: 2001 | H25: Table 1-H plastic w/curb U-factor (U does not vary by SRR). | I25: 0.87 | J25: 1.1 | K25: 1.3 | L25: 1.3 | M25: 1.3 | N25: 1.3 | O25: 1.3 | P25: 1.3 | Q25: 1.3 | R25: 1.1 | S25: 1.1 | T25: 1.1 | U25: 1.1 | V25: 1.1 | W25: 1.1 | X25: 0.87
F26: 2008-2018 | G26: 2013 | H26: Table 140.3-B | I26: 0.88 | J26: 0.88 | K26: 0.88 | L26: 0.88 | M26: 0.88 | N26: 0.88 | O26: 0.88 | P26: 0.88 | Q26: 0.88 | R26: 0.88 | S26: 0.88 | T26: 0.88 | U26: 0.88 | V26: 0.88 | W26: 0.88 | X26: 0.88
F27: 2019+ | G27: 2025 | H27: Table 140.3-B | I27: 0.88 | J27: 0.88 | K27: 0.88 | L27: 0.88 | M27: 0.88 | N27: 0.88 | O27: 0.88 | P27: 0.88 | Q27: 0.88 | R27: 0.88 | S27: 0.88 | T27: 0.88 | U27: 0.88 | V27: 0.88 | W27: 0.88 | X27: 0.88
E28: SHGC | F28: Pre 1978 | G28: 1992 | H28: Table 1-I Translucent SHGC (1992 term; same plastic curb product). | I28: 0.81 | J28: 0.86 | K28: 0.86 | L28: 0.86 | M28: 0.86 | N28: 0.86 | O28: 0.86 | P28: 0.86 | Q28: 0.86 | R28: 0.86 | S28: 0.81 | T28: 0.81 | U28: 0.81 | V28: 0.81 | W28: 0.81 | X28: 0.81
F29: 1978-1997 | G29: 1992 | I29: =I28 -> 0.81 | J29: =J28 -> 0.86 | K29: =K28 -> 0.86 | L29: =L28 -> 0.86 | M29: =M28 -> 0.86 | N29: =N28 -> 0.86 | O29: =O28 -> 0.86 | P29: =P28 -> 0.86 | ... X29: =X28 -> 0.81
F30: 1998-2007 | G30: 2001 | H30: Table 1-H plastic w/curb, SRR 0–2% (K8 ~0.17% CalBEM / 0.35% CBECC). Not 2.1–5%. | I30: 0.77 | J30: 0.77 | K30: 0.79 | L30: 0.79 | M30: 0.79 | N30: 0.77 | O30: 0.77 | P30: 0.77 | Q30: 0.77 | R30: 0.77 | S30: 0.77 | T30: 0.77 | U30: 0.77 | V30: 0.71 | W30: 0.71 | X30: 0.77
F31: 2008-2018 | G31: 2013 | H31: Table 140.3-B plastic curb SHGC = NR; used 2001 Table 1-H 0–2% SRR. | I31: 0.77 | J31: 0.77 | K31: 0.79 | L31: 0.79 | M31: 0.79 | N31: 0.77 | O31: 0.77 | P31: 0.77 | Q31: 0.77 | R31: 0.77 | S31: 0.77 | T31: 0.77 | U31: 0.77 | V31: 0.71 | W31: 0.71 | X31: 0.77
F32: 2019+ | G32: 2025 | H32: Table 140.3-B (2025) plastic curb SHGC = NR; same 2001 0–2% SRR values. | I32: 0.77 | J32: 0.77 | K32: 0.79 | L32: 0.79 | M32: 0.79 | N32: 0.77 | O32: 0.77 | P32: 0.77 | Q32: 0.77 | R32: 0.77 | S32: 0.77 | T32: 0.77 | U32: 0.77 | V32: 0.71 | W32: 0.71 | X32: 0.77
A34: Floor: SlabOnGrade_Unheated_NonRes is a 4 in. concrete slab-on-grade with no insulation. It is the same for every vintage (F-factor 0.73), so it is documented here instead of as a table row.
C36: Infiltration
D37: Building | E37: Zones | F37: Vintage | G37: I_75 6-Sided Inifltration rate @ 75 pa | H37: Note | I37: I-design (cfm/ft²) (4-sided Infiltration rate at normal presure) (Design flow rate approach and Flow/Exterior Wall Area calulation method)
C38: Infiltration | D38: SkoolK-8 Admin/MPR | F38: Pre 1978 | G38: 1.1 | H38: 2022 CASE report (Table 38) | I38: =0.112*G38*#REF! -> #REF! | Z38: Floor or roof area (ft2) | AA38: 16755.34
F39: 1978-1997 | G39: 1.1 | H39: 2022 CASE report (Table 38) | I39: =0.112*G39*#REF! -> #REF! | Z39: Walls area (ft2) | AA39: 14068
F40: 1998-2007 | G40: 1.1 | H40: 2022 CASE report (Table 38) | I40: =0.112*G40*#REF! -> #REF! | Z40: Building 4 sided area (ft2)= | AA40: =AA39 -> 14068
F41: 2008-2018 | G41: 1 | H41: 2022 CASE report (Table 38) & T24, 2008-2016 (Table 140.3-B)--Air barrier is required in CZ 10-16 | I41: =0.112*G41*#REF! -> #REF! | Z41: Building 6 sided area (ft2)= | AA41: =AA39+(2*AA38) -> 47578.68
F42: 2019+ | G42: 0.6 | H42: 2022 CASE report (Table 38) & T24, 2025 (Table 140.3-B)--Air barrier is required in all CZs | I42: =0.112*G42*#REF! -> #REF!
...

Sheet HVAC System
A1: ="HVAC system - "&Prototype!A2 -> HVAC system - SchoolK-8
A2: Vintage | B2: Zones | C2: Heating | D2: Cooling | E2: Air Distribution | F2: Other Systems | G2: Source | H2: Note
A3: Exisiting | B3: All Space Types except MPR/refrigerated storage | C3: Gas Furnace | D3: PSZAC (DX cooling) | E3: CAV | F3: OA mixing. Air-side economizer: not modeled (see Economizer / ERV). | G3: Engineering Judgement | H3: System 3a
B4: Admin/MPR Multipurpose Room | C4: SZHP (DX heating) | D4: SZHP (DX cooling) | E4: SZVAV (single-zone VAV) | F4: OA mixing. Air-side economizer: not modeled (see Economizer / ERV). | G4: Engineering Judgement | H4: VAV:NoReheat terminal, Fan:VariableVolume. Theater and other Admin zones remain CAV. Kitchen makeup loop BaseAirSys13 is also VAV (exhaust makeup).
B5: Admin/MPR_Storage - Refrigerated | C5: n/a (walk-in refrigeration) | D5: Walk-in cooler (not PSZ DX) | E5: n/a | F5: n/a — walk-in refrigeration, not an air-side HVAC OA system. | G5: Engineering Judgement | H5: Refrigeration system; 35°F product; equipment W/ft² on Equipment tab.
A6: New Construction | B6: All Space Types except MPR and refrigerated storage | C6: SZHP | D6: SZHP | E6: CAV | F6: OA mixing. Air-side economizer: not modeled (see Economizer / ERV). | G6: ACM 2025 | H6: System 3b
B7: Admin/MPR Multipurpose Room | C7: SZHP (DX heating) | D7: SZHP (DX cooling) | E7: SZVAV (single-zone VAV) | F7: OA mixing. Air-side economizer: not modeled (see Economizer / ERV). | G7: Engineering Judgement | H7: VAV:NoReheat terminal, Fan:VariableVolume. Theater and other Admin zones remain CAV. Kitchen makeup loop BaseAirSys13 is also VAV (exhaust makeup).
B8: Admin/MPR_Storage - Refrigerated | C8: n/a (walk-in refrigeration) | D8: Walk-in cooler (not PSZ DX) | E8: n/a | F8: n/a — walk-in refrigeration, not an air-side HVAC OA system. | G8: Engineering Judgement | H8: Refrigeration system; 35°F product; equipment W/ft² on Equipment tab.
A11: Efficiency of HVAC System (Efficiency is capacity-dependent. The following table provides a general estimate of system efficiency based on preliminary simulations in one climate zone, or assuming cooling load based on rule of thumb)
A12: Vintage | B12: Upgrade/Installed year | C12: Gas Furnace | D12: Heating DX | E12: Cooling DX | F12: Sources | G12: Note
A13: Pre 1978 | B13: 2008 | C13: Thermal Efficiency of 80% | D13: n/a | E13: EER 11.2 for <65 kBtu/h EER 10.3 for 65-135 kBtu/h | F13: 2005 Title 20 Appliance Efficiency Regulations, 2005 T24 Standards, Tables 112-A, 112-B
A14: 1978-1997
A15: 1998-2007
A16: 2008-2018 | B16: 2013 | C16: Thermal Efficiency of 80% | D16: n/a | E16: EER 11.2 for <65 kBtu/h EER 11.2 for 65–135 kBtu/h | F16: 2013 Title 20 Appliance Efficiency Regulations, 2013 T24 Tables 110.2 | G16: 2013 T24 Table 110.2-A (air-cooled packaged AC). Existing vintage is PSZAC + gas furnace, not HP.
A17: New Construction | B17: 2025 | C17: n/a | D17: Heating @ 47°F: <65 kBtu/h (AHRI 210/240): federal minimum HSPF2 / 10 CFR 430 65–135 kBtu/h: COP 3.40 (10 CFR 431 / T24 Table 110.2-B) Heating @ 17°F: COP 2.25 (Table 110.2-B) | E17: <65 kBtu/h packaged HP (10 CFR 430.32): SEER2 13.4 (pair to HSPF2 6.7) 65–135 kBtu/h: EER 11.0 + federal min IEER (Table 110.2-B) 135–240 kBtu/h: EER 10.6 + federal min IEER (MPR bin) ≥240 kBtu/h: EER 9.5 + federal min IEER | F17: T24 2025 Table 110.2-B; 10 CFR 431.97 (COP @ 47°F); 10 CFR 430.32 (HSPF2/SEER2 <65 kBtu/h); AHRI 340/360 (≥65) / AHRI 210/240 (<65)
C19: * Et = Combustion efficiency | D19: * Et = Thermal efficiency
A21: Fan power
A22: Vintage | B22: Approach | C22: System | D22: Total Static Pressure (TSP) (in w.c.) | E22: Fan Efficiency [ACM 2025] | F22: Motor Efficiency | G22: Fan Power Index (W/cfm) | H22: Data Source
A23: Existing | B23: PNNL 90.1-2011, TSP | C23: CAV, PSZ classrooms/admin (except MPR), design airflow < 7,437 cfm | D23: 2.5 | E23: 0.65 | F23: ASHRAE 90.1, 2004, Table 10.8 * | H23: Fan power formula: PNNL 20405, 2010, section 5.2.2.5 TSP and fan efficiency: PNNL 20405, 2010, Table 5.11, 90.1-04ac values Motor and drive efficiency: ASHRAE 90.1, 2004, Table 10.8 | I23: PNNL 20405, 2010, Table 5.11
C24: SZVAV, Admin/MPR Multipurpose Room, VAV > 4,648 cfm | D24: 5.58
A25: Brake horsepower (bhp) = (Supply cfm × TSP in w.c.) / (6356 × fan efficiency)
A26: Fan power (w/cfm) = (bhp × 746) / ( supply cfm × motor efficiency )
A27: New Construction | B27: ACM 2025 | C27: SZHP (System 3b), CAV classrooms/admin, ≤5,000 cfm | D27: TSP = fan power × motor efficiency × fan efficiency × 6356 / 746 | E27: 0.65 | F27: 2025 ACM Table 12 ** | G27: 0.744 | H27: Fan power index: [ACM 2025, Table 13] Motor efficiency: [ACM 2025, Table 12]
C28: SZVAVHP (System 7b), MPR/cafeteria, >10,000 cfm | D28: TSP = fan power × motor efficiency × fan efficiency × 6356 / 746 | G28: 0.676
A30: * According to PNNL 20405 section 5.2.2.5, the full-load efficiency of the motor serving the fan is taken from ASHRAE 90.1, 2004, Table 10.8, based on motor nameplate and assuming enclosed motors operating at 1,800 rotations per minute (rpm) Motor nameplate size (bhp) = brake horsepower (bhp) × 1.1 ( using a 10% oversizing factor)
A31: ** The full‑load efficiency of the motor serving the fan is taken from ACM 2025 Table 12 based on the cfm of the fan. Brake horsepower (bhp) = (Supply cfm from sizing run × fan power in W/cfm) / 746. Note: Packaged SZHP. Same index as Hotel Small System 3b ≤5,000 cfm. Note: Single-zone VAV heat pump, not System 6. ACM System 7b >10,000 cfm = 0.676; >5,000–10,000 cfm = 0.720. PNNL row was VAV >4,648 cfm.
A32: Economizer / ERV | B32: Air-side economizer: not modeled. EnergyPlus Controller:OutdoorAir Economizer Control Type = NoEconomizer on existing PSZAC and NC SZHP units. ERV: not modeled. T24 §140.4(e) would require an air economizer when cooling capacity ≥ 54,000 Btu/h (with listed exceptions); CBECC Standard Design uses FixedDryBulb on units that meet that threshold. This prototype does not include economizers.
A34: Background Data [To be deleted prior to publication]

Sheet Thermostat
A1: ="Thermostat Setpoints - "&Prototype!A2 -> Thermostat Setpoints - SchoolK-8
A2: Setpoint | B2: CZ1 | C2: CZ2 | D2: CZ3 | E2: CZ4 | F2: CZ5 | G2: CZ6 | H2: CZ7 | I2: CZ8 | J2: CZ9 | K2: CZ10 | L2: CZ11 | M2: CZ12 | N2: CZ13 | O2: CZ14 | P2: CZ15 | Q2: CZ16 | R2: Source
A3: School Heating Setpoint (F) | B3: 70 | C3: 70 | D3: 70 | E3: 70 | F3: 70 | G3: 70 | H3: 70 | I3: 70 | J3: 70 | K3: 70 | L3: 70 | M3: 70 | N3: 70 | O3: 70 | P3: 70 | Q3: 70 | R3: T24 2022 - Appendix 5.4B
A4: School Heating Setback (F) | B4: 60 | C4: 60 | D4: 60 | E4: 60 | F4: 60 | G4: 60 | H4: 60 | I4: 60 | J4: 60 | K4: 60 | L4: 60 | M4: 60 | N4: 60 | O4: 60 | P4: 60 | Q4: 60
A5: School Cooling Setpoint (F) | B5: 75 | C5: 75 | D5: 75 | E5: 75 | F5: 75 | G5: 75 | H5: 75 | I5: 75 | J5: 75 | K5: 75 | L5: 75 | M5: 75 | N5: 75 | O5: 75 | P5: 75 | Q5: 75 | R5: T24 2022 - Appendix 5.4B
A6: School Cooling Setback (F) | B6: 85 | C6: 85 | D6: 85 | E6: 85 | F6: 85 | G6: 85 | H6: 85 | I6: 85 | J6: 85 | K6: 85 | L6: 85 | M6: 85 | N6: 85 | O6: 85 | P6: 85 | Q6: 85
A7: Kitchen Heating Setpoint (F) | B7: 70 | C7: 70 | D7: 70 | E7: 70 | F7: 70 | G7: 70 | H7: 70 | I7: 70 | J7: 70 | K7: 70 | L7: 70 | M7: 70 | N7: 70 | O7: 70 | P7: 70 | Q7: 70 | R7: T24 2022 - Appendix 5.4B (school kitchen occupied 70/75; not commercial restaurant 66–79)
A8: Kitchen Heating Setback (F) | B8: 60 | C8: 60 | D8: 60 | E8: 60 | F8: 60 | G8: 60 | H8: 60 | I8: 60 | J8: 60 | K8: 60 | L8: 60 | M8: 60 | N8: 60 | O8: 60 | P8: 60 | Q8: 60
A9: Kitchen Cooling Setpoint (F) | B9: 75 | C9: 75 | D9: 75 | E9: 75 | F9: 75 | G9: 75 | H9: 75 | I9: 75 | J9: 75 | K9: 75 | L9: 75 | M9: 75 | N9: 75 | O9: 75 | P9: 75 | Q9: 75
A10: Kitchen Cooling Setback (F) | B10: 85 | C10: 85 | D10: 85 | E10: 85 | F10: 85 | G10: 85 | H10: 85 | I10: 85 | J10: 85 | K10: 85 | L10: 85 | M10: 85 | N10: 85 | O10: 85 | P10: 85 | Q10: 85
A11: Restrooms Heating Setpoint (F) | B11: 60 | C11: 60 | D11: 60 | E11: 60 | F11: 60 | G11: 60 | H11: 60 | I11: 60 | J11: 60 | K11: 60 | L11: 60 | M11: 60 | N11: 60 | O11: 60 | P11: 60 | Q11: 60 | R11: PNNL 90.1 Primary School bathroom (HTGSETP_SCH_Setback / CLGSETP_SCH_Setup)
A12: Restrooms Heating Setback (F) | B12: 60 | C12: 60 | D12: 60 | E12: 60 | F12: 60 | G12: 60 | H12: 60 | I12: 60 | J12: 60 | K12: 60 | L12: 60 | M12: 60 | N12: 60 | O12: 60 | P12: 60 | Q12: 60
A13: Restrooms Cooling Setpoint (F) | B13: 80 | C13: 80 | D13: 80 | E13: 80 | F13: 80 | G13: 80 | H13: 80 | I13: 80 | J13: 80 | K13: 80 | L13: 80 | M13: 80 | N13: 80 | O13: 80 | P13: 80 | Q13: 80
A14: Restrooms Cooling Setback (F) | B14: 80 | C14: 80 | D14: 80 | E14: 80 | F14: 80 | G14: 80 | H14: 80 | I14: 80 | J14: 80 | K14: 80 | L14: 80 | M14: 80 | N14: 80 | O14: 80 | P14: 80 | Q14: 80
A15: Storage and Electrical/Mechanical (non-refrigerated) Heating Setpoint (F) | B15: 60 | C15: 60 | D15: 60 | E15: 60 | F15: 60 | G15: 60 | H15: 60 | I15: 60 | J15: 60 | K15: 60 | L15: 60 | M15: 60 | N15: 60 | O15: 60 | P15: 60 | Q15: 60 | R15: Engineering Judgment (semi-conditioned storage / electrical-mechanical)
A16: Storage and Electrical/Mechanical (non-refrigerated) Heating Setback (F) | B16: 60 | C16: 60 | D16: 60 | E16: 60 | F16: 60 | G16: 60 | H16: 60 | I16: 60 | J16: 60 | K16: 60 | L16: 60 | M16: 60 | N16: 60 | O16: 60 | P16: 60 | Q16: 60
A17: Storage and Electrical/Mechanical (non-refrigerated) Cooling Setpoint (F) | B17: 85 | C17: 85 | D17: 85 | E17: 85 | F17: 85 | G17: 85 | H17: 85 | I17: 85 | J17: 85 | K17: 85 | L17: 85 | M17: 85 | N17: 85 | O17: 85 | P17: 85 | Q17: 85
A18: Storage and Electrical/Mechanical (non-refrigerated) Cooling Setback (F) | B18: 85 | C18: 85 | D18: 85 | E18: 85 | F18: 85 | G18: 85 | H18: 85 | I18: 85 | J18: 85 | K18: 85 | L18: 85 | M18: 85 | N18: 85 | O18: 85 | P18: 85 | Q18: 85
A19: Refrigerated storage setpoint (F) | B19: 35 | C19: 35 | D19: 35 | E19: 35 | F19: 35 | G19: 35 | H19: 35 | I19: 35 | J19: 35 | K19: 35 | L19: 35 | M19: 35 | N19: 35 | O19: 35 | P19: 35 | Q19: 35 | R19: Engineering judgment, medium-temp cooler within T24 28–55°F
A20: Refrigerated storage setback (F) | B20: 35 | C20: 35 | D20: 35 | E20: 35 | F20: 35 | G20: 35 | H20: 35 | I20: 35 | J20: 35 | K20: 35 | L20: 35 | M20: 35 | N20: 35 | O20: 35 | P20: 35 | Q20: 35

Sheet Ventilation
A1: ="Outdoor Airflow Rate - "&Prototype!A2 -> Outdoor Airflow Rate - SchoolK-8
A2: Space Type | B2: Space/Thermal Zone | C2: Number of People | D2: Floor Area (ft²) | E2: cfm/person [T24, 2025, Equation 120.1-F and Table 120.1-A] | F2: cfm/ft² [T24, 2025, Equation 120.1-F and Table 120.1-A] | G2: Required exhaust rate-CFM/ft²- [T24, 2025, Table 120.1-B – minimum exhaust rates] | H2: Total cfm driven by people | I2: Total cfm driven by area | J2: Total cfm driven by exhaust | K2: Total cfm | L2: Notes
A3: =Zones!C3 -> Lounge, Breakroom, or Waiting Area | B3: =Zones!B3 -> Admin/MPR_Breakroom_Zn | C3: =Zones!K3 -> 18.9816 | D3: =Zones!H3 -> 575.2 | E3: 15 | F3: 0.15 | H3: =C3*E3 -> 284.724 | I3: =D3*F3 -> 86.28 | J3: =G3*D3 -> 0 | K3: =MAX(H3,I3,J3) -> 284.724
A4: =Zones!C4 -> Convention, Conference, Multipurpose and Meeting Area | B4: =Zones!B4 -> Admin/MPR_Conference Room Zns 3_Zn | C4: =Zones!K4 -> 55.26642 | D4: =Zones!H4 -> 1674.74 | E4: 15 | F4: 0.15 | H4: =C4*E4 -> 828.9963 | I4: =D4*F4 -> 251.211 | J4: =G4*D4 -> 0 | K4: =MAX(H4,I4,J4) -> 828.9963
A5: =Zones!C5 -> Corridor Area | B5: =Zones!B5 -> Admin/MPR_Corridor_Zn | C5: =Zones!K5 -> 5.8076 | D5: =Zones!H5 -> 1161.52 | E5: 15 | F5: 0.15 | H5: =C5*E5 -> 87.114 | I5: =D5*F5 -> 174.228 | J5: =G5*D5 -> 0 | K5: =MAX(H5,I5,J5) -> 174.228
A6: =Zones!C6 -> Electrical, Mechanical, Telephone Rooms | B6: =Zones!B6 -> Admin/MPR_EMT_Zn | C6: =Zones!K6 -> 1.39105 | D6: =Zones!H6 -> 278.21 | E6: 15 | F6: 0.15 | H6: =C6*E6 -> 20.86575 | I6: =D6*F6 -> 41.7315 | J6: =G6*D6 -> 0 | K6: =MAX(H6,I6,J6) -> 41.7315
A7: =Zones!C7 -> Electrical, Mechanical, Telephone Rooms | B7: =Zones!B7 -> Admin/MPR_IDF Room_Zn | C7: =Zones!K7 -> 1.70115 | D7: =Zones!H7 -> 340.23 | E7: 15 | F7: 0.15 | H7: =C7*E7 -> 25.51725 | I7: =D7*F7 -> 51.0345 | J7: =G7*D7 -> 0 | K7: =MAX(H7,I7,J7) -> 51.0345
A8: =Zones!C8 -> Kitchen/Food Preparation Area | B8: =Zones!B8 -> Admin/MPR_Kitchen_Zn | C8: =Zones!K8 -> 4.37175 | D8: =Zones!H8 -> 1457.25 | E8: 15 | F8: 0.15 | G8: 0.7 | H8: =C8*E8 -> 65.57625 | I8: =D8*F8 -> 218.5875 | J8: =G8*D8 -> 1020.075 | K8: =MAX(H8,I8,J8) -> 1020.075
A9: =Zones!C9 -> Lobby, Main Entry | B9: =Zones!B9 -> Admin/MPR_Lobby_Zn | C9: =Zones!K9 -> 40.96851 | D9: =Zones!H9 -> 1241.47 | E9: 15 | F9: 0.15 | H9: =C9*E9 -> 614.52765 | I9: =D9*F9 -> 186.2205 | J9: =G9*D9 -> 0 | K9: =MAX(H9,I9,J9) -> 614.52765
A10: =Zones!C10 -> Convention, Conference, Multipurpose and Meeting Area | B10: =Zones!B10 -> Admin/MPR_Multipurpose Room Zns 3_Zn | C10: =Zones!K10 -> 181.90227 | D10: =Zones!H10 -> 5512.19 | E10: 15 | F10: 0.15 | H10: =C10*E10 -> 2728.534 | I10: =D10*F10 -> 826.8285 | J10: =G10*D10 -> 0 | K10: =MAX(H10,I10,J10) -> 2728.534
A11: =Zones!C11 -> Office Area (<250 square feet) | B11: =Zones!B11 -> Admin/MPR_Office - LT 250 sf Zns 6_Zn | C11: =Zones!K11 -> 5.24175 | D11: =Zones!H11 -> 1048.35 | E11: 15 | F11: 0.15 | H11: =C11*E11 -> 78.62625 | I11: =D11*F11 -> 157.2525 | J11: =G11*D11 -> 0 | K11: =MAX(H11,I11,J11) -> 157.2525
A12: =Zones!C12 -> Restrooms | B12: =Zones!B12 -> Admin/MPR_Restroom Zns 3_Zn | C12: =Zones!K12 -> 4.50585 | D12: =Zones!H12 -> 901.17 | E12: 0 | F12: 0 | G12: 0.5 | H12: =C12*E12 -> 0 | I12: =D12*F12 -> 0 | J12: =G12*D12 -> 450.585 | K12: =MAX(H12,I12,J12) -> 450.585
A13: =Zones!C13 -> Storage (General) | B13: =Zones!B13 -> Admin/MPR_Storage - General_Zn | C13: =Zones!K13 -> 6.23865 | D13: =Zones!H13 -> 1247.73 | E13: 15 | F13: 0.15 | H13: =C13*E13 -> 93.57975 | I13: =D13*F13 -> 187.1595 | J13: =G13*D13 -> 0 | K13: =MAX(H13,I13,J13) -> 187.1595
A14: =Zones!C14 -> Storage, Commercial/Industrial (Refrigerated) | B14: =Zones!B14 -> Admin/MPR_Storage - Refrigerated_Zn | C14: =Zones!K14 -> 0 | D14: =Zones!H14 -> 251.72 | E14: 0 | F14: 0 | H14: =C14*E14 -> 0 | I14: =D14*F14 -> 0 | J14: =G14*D14 -> 0 | K14: =MAX(H14,I14,J14) -> 0
A15: =Zones!C15 -> Theater Area (Performance) | B15: =Zones!B15 -> Admin/MPR_Theater - Performance_Zn | C15: =Zones!K15 -> 35.16348 | D15: =Zones!H15 -> 1065.56 | E15: 15 | F15: 0.15 | H15: =C15*E15 -> 527.4522 | I15: =D15*F15 -> 159.834 | J15: =G15*D15 -> 0 | K15: =MAX(H15,I15,J15) -> 527.4522
A16: =Zones!C16 -> Classroom, Lecture, Training, Vocational Areas | B16: =Zones!B16 -> Classrm N_Flr 1_Classroom-01_Zn | C16: =Zones!K16 -> 25.04375 | D16: =Zones!H16 -> 1001.75 | E16: 15 | F16: 0.15 | H16: =C16*E16 -> 375.65625 | I16: =D16*F16 -> 150.2625 | J16: =G16*D16 -> 0 | K16: =MAX(H16,I16,J16) -> 375.65625
A17: =Zones!C17 -> Classroom, Lecture, Training, Vocational Areas | B17: =Zones!B17 -> Classrm N_Flr 1_Classroom-02 Zns 6_Zn | C17: =Zones!K17 -> 151.35075 | D17: =Zones!H17 -> 6054.03 | E17: 15 | F17: 0.15 | H17: =C17*E17 -> 2270.2613 | I17: =D17*F17 -> 908.1045 | J17: =G17*D17 -> 0 | K17: =MAX(H17,I17,J17) -> 2270.2613
A18: =Zones!C18 -> Office Area (<250 square feet) | B18: =Zones!B18 -> Classrm N_Flr 1_Office - LT 250 sf_Zn | C18: =Zones!K18 -> 1.44065 | D18: =Zones!H18 -> 288.13 | E18: 15 | F18: 0.15 | H18: =C18*E18 -> 21.60975 | I18: =D18*F18 -> 43.2195 | J18: =G18*D18 -> 0 | K18: =MAX(H18,I18,J18) -> 43.2195
A19: =Zones!C19 -> Restrooms | B19: =Zones!B19 -> Classrm N_Flr 1_Restroom_Zn | C19: =Zones!K19 -> 2.6635 | D19: =Zones!H19 -> 532.7 | E19: 0 | F19: 0 | G19: 0.5 | H19: =C19*E19 -> 0 | I19: =D19*F19 -> 0 | J19: =G19*D19 -> 266.35 | K19: =MAX(H19,I19,J19) -> 266.35
A20: =Zones!C20 -> Classroom, Lecture, Training, Vocational Areas | B20: =Zones!B20 -> Classrm N_Flr 2_Classroom-01 Zns 6_Zn | C20: =Zones!K20 -> 151.35075 | D20: =Zones!H20 -> 6054.03 | E20: 15 | F20: 0.15 | H20: =C20*E20 -> 2270.2613 | I20: =D20*F20 -> 908.1045 | J20: =G20*D20 -> 0 | K20: =MAX(H20,I20,J20) -> 2270.2613
A21: =Zones!C21 -> Classroom, Lecture, Training, Vocational Areas | B21: =Zones!B21 -> Classrm N_Flr 2_Classroom-02_Zn | C21: =Zones!K21 -> 25.04375 | D21: =Zones!H21 -> 1001.75 | E21: 15 | F21: 0.15 | H21: =C21*E21 -> 375.65625 | I21: =D21*F21 -> 150.2625 | J21: =G21*D21 -> 0 | K21: =MAX(H21,I21,J21) -> 375.65625
A22: =Zones!C22 -> Office Area (<250 square feet) | B22: =Zones!B22 -> Classrm N_Flr 2_Office - LT 250 sf_Zn | C22: =Zones!K22 -> 1.44065 | D22: =Zones!H22 -> 288.13 | E22: 15 | F22: 0.15 | H22: =C22*E22 -> 21.60975 | I22: =D22*F22 -> 43.2195 | J22: =G22*D22 -> 0 | K22: =MAX(H22,I22,J22) -> 43.2195
A23: =Zones!C23 -> Restrooms | B23: =Zones!B23 -> Classrm N_Flr 2_Restroom_Zn | C23: =Zones!K23 -> 2.6635 | D23: =Zones!H23 -> 532.7 | E23: 0 | F23: 0 | G23: 0.5 | H23: =C23*E23 -> 0 | I23: =D23*F23 -> 0 | J23: =G23*D23 -> 266.35 | K23: =MAX(H23,I23,J23) -> 266.35
A24: =Zones!C24 -> Classroom, Lecture, Training, Vocational Areas | B24: =Zones!B24 -> Classrm W_Flr 1_Classroom Zns 2_Zn | C24: =Zones!K24 -> 51.3735 | D24: =Zones!H24 -> 2054.94 | E24: 15 | F24: 0.15 | H24: =C24*E24 -> 770.6025 | I24: =D24*F24 -> 308.241 | J24: =G24*D24 -> 0 | K24: =MAX(H24,I24,J24) -> 770.6025
A25: =Zones!C25 -> Electrical, Mechanical, Telephone Rooms | B25: =Zones!B25 -> Classrm W_Flr 1_EMT-01_Zn | C25: =Zones!K25 -> 0.60505 | D25: =Zones!H25 -> 121.01 | E25: 15 | F25: 0.15 | H25: =C25*E25 -> 9.07575 | I25: =D25*F25 -> 18.1515 | J25: =G25*D25 -> 0 | K25: =MAX(H25,I25,J25) -> 18.1515
A26: =Zones!C26 -> Electrical, Mechanical, Telephone Rooms | B26: =Zones!B26 -> Classrm W_Flr 1_EMT-02_Zn | C26: =Zones!K26 -> 0.49005 | D26: =Zones!H26 -> 98.01 | E26: 15 | F26: 0.15 | H26: =C26*E26 -> 7.35075 | I26: =D26*F26 -> 14.7015 | J26: =G26*D26 -> 0 | K26: =MAX(H26,I26,J26) -> 14.7015
A27: =Zones!C27 -> Library (Reading Area) | B27: =Zones!B27 -> Classrm W_Flr 1_Library - Reading Area_Zn | C27: =Zones!K27 -> 11.9713 | D27: =Zones!H27 -> 1197.13 | E27: 15 | F27: 0.15 | H27: =C27*E27 -> 179.5695 | I27: =D27*F27 -> 179.5695 | J27: =G27*D27 -> 0 | K27: =MAX(H27,I27,J27) -> 179.5695
A28: =Zones!C28 -> Restrooms | B28: =Zones!B28 -> Classrm W_Flr 1_Restroom_Zn | C28: =Zones!K28 -> 2.81525 | D28: =Zones!H28 -> 563.05 | E28: 0 | F28: 0 | G28: 0.5 | H28: =C28*E28 -> 0 | I28: =D28*F28 -> 0 | J28: =G28*D28 -> 281.525 | K28: =MAX(H28,I28,J28) -> 281.525
A29: =Zones!C29 -> Storage (General) | B29: =Zones!B29 -> Classrm W_Flr 1_Storage - General_Zn | C29: =Zones!K29 -> 1.9042 | D29: =Zones!H29 -> 380.84 | E29: 15 | F29: 0.15 | H29: =C29*E29 -> 28.563 | I29: =D29*F29 -> 57.126 | J29: =G29*D29 -> 0 | K29: =MAX(H29,I29,J29) -> 57.126
A30: =Zones!C30 -> Classroom, Lecture, Training, Vocational Areas | B30: =Zones!B30 -> Classrm W_Flr 2_Classroom-01 Zns 3_Zn | C30: =Zones!K30 -> 81.3015 | D30: =Zones!H30 -> 3252.06 | E30: 15 | F30: 0.15 | H30: =C30*E30 -> 1219.5225 | I30: =D30*F30 -> 487.809 | J30: =G30*D30 -> 0 | K30: =MAX(H30,I30,J30) -> 1219.5225
A31: =Zones!C31 -> Classroom, Lecture, Training, Vocational Areas | B31: =Zones!B31 -> Classrm W_Flr 2_Classroom-02_Zn | C31: =Zones!K31 -> 9.521 | D31: =Zones!H31 -> 380.84 | E31: 15 | F31: 0.15 | H31: =C31*E31 -> 142.815 | I31: =D31*F31 -> 57.126 | J31: =G31*D31 -> 0 | K31: =MAX(H31,I31,J31) -> 142.815
A32: =Zones!C32 -> Electrical, Mechanical, Telephone Rooms | B32: =Zones!B32 -> Classrm W_Flr 2_IDF Room_Zn | C32: =Zones!K32 -> 0.60505 | D32: =Zones!H32 -> 121.01 | E32: 15 | F32: 0.15 | H32: =C32*E32 -> 9.07575 | I32: =D32*F32 -> 18.1515 | J32: =G32*D32 -> 0 | K32: =MAX(H32,I32,J32) -> 18.1515
A33: =Zones!C33 -> Restrooms | B33: =Zones!B33 -> Classrm W_Flr 2_Restroom_Zn | C33: =Zones!K33 -> 2.81525 | D33: =Zones!H33 -> 563.05 | E33: 0 | F33: 0 | G33: 0.5 | H33: =C33*E33 -> 0 | I33: =D33*F33 -> 0 | J33: =G33*D33 -> 281.525 | K33: =MAX(H33,I33,J33) -> 281.525
A34: =Zones!C34 -> Storage (General) | B34: =Zones!B34 -> Classrm W_Flr 2_Storage - General_Zn | C34: =Zones!K34 -> 0.49005 | D34: =Zones!H34 -> 98.01 | E34: 15 | F34: 0.15 | H34: =C34*E34 -> 7.35075 | I34: =D34*F34 -> 14.7015 | J34: =G34*D34 -> 0 | K34: =MAX(H34,I34,J34) -> 14.7015
A35: =Zones!C35 -> Classroom, Lecture, Training, Vocational Areas | B35: =Zones!B35 -> Kindergarten_Classroom-01_Zn | C35: =Zones!K35 -> 137.3635 | D35: =Zones!H35 -> 5494.54 | E35: 15 | F35: 0.15 | H35: =C35*E35 -> 2060.4525 | I35: =D35*F35 -> 824.181 | J35: =G35*D35 -> 0 | K35: =MAX(H35,I35,J35) -> 2060.4525
A36: =Zones!C36 -> Classroom, Lecture, Training, Vocational Areas | B36: =Zones!B36 -> Kindergarten_Classroom-02_Zn | C36: =Zones!K36 -> 36.0035 | D36: =Zones!H36 -> 1440.14 | E36: 15 | F36: 0.15 | H36: =C36*E36 -> 540.0525 | I36: =D36*F36 -> 216.021 | J36: =G36*D36 -> 0 | K36: =MAX(H36,I36,J36) -> 540.0525
A37: =Zones!C37 -> Electrical, Mechanical, Telephone Rooms | B37: =Zones!B37 -> Kindergarten_EMT_Zn | C37: =Zones!K37 -> 0.85435 | D37: =Zones!H37 -> 170.87 | E37: 15 | F37: 0.15 | H37: =C37*E37 -> 12.81525 | I37: =D37*F37 -> 25.6305 | J37: =G37*D37 -> 0 | K37: =MAX(H37,I37,J37) -> 25.6305
A38: =Zones!C38 -> Electrical, Mechanical, Telephone Rooms | B38: =Zones!B38 -> Kindergarten_IDF Room_Zn | C38: =Zones!K38 -> 0.4274 | D38: =Zones!H38 -> 85.48 | E38: 15 | F38: 0.15 | H38: =C38*E38 -> 6.411 | I38: =D38*F38 -> 12.822 | J38: =G38*D38 -> 0 | K38: =MAX(H38,I38,J38) -> 12.822
A39: =Zones!C39 -> Restrooms | B39: =Zones!B39 -> Kindergarten_Restroom_Zn | C39: =Zones!K39 -> 1.33015 | D39: =Zones!H39 -> 266.03 | E39: 0 | F39: 0 | G39: 0.5 | H39: =C39*E39 -> 0 | I39: =D39*F39 -> 0 | J39: =G39*D39 -> 133.015 | K39: =MAX(H39,I39,J39) -> 133.015
A40: =Zones!C40 -> Storage (General) | B40: =Zones!B40 -> Kindergarten_Storage - General_Zn | C40: =Zones!K40 -> 5.919 | D40: =Zones!H40 -> 1183.8 | E40: 15 | F40: 0.15 | H40: =C40*E40 -> 88.785 | I40: =D40*F40 -> 177.57 | J40: =G40*D40 -> 0 | K40: =MAX(H40,I40,J40) -> 177.57
...

Sheet Water Heater
A1: ="Water Heater - "&Prototype!A2 -> Water Heater - SchoolK-8
A2: Vintage | B2: WH Type | C2: Efficiency | D2: Number of WH | E2: Tank Volume (gal) | F2: Tank Loss | G2: Source
A3: Existing | B3: Electric | C3: 0.98 | D3: 4 | E3: See table below for CZ-specific values: Climate Zone Water Heater Sizing and Loss Coefficients, Storage Volume column (col F) | F3: See table below: Climate Zone Water Heater Sizing and Loss Coefficients, Standby Loss column (col G) | G3: See table below for sources: Climate Zone Water Heater Sizing and Loss Coefficients
A4: New Construction | B4: HPWH | C4: =B64 -> 4.3 | D4: 4 | E4: =E3 -> See table below for CZ-specific values: Climate Zone Water Heater Sizing and Loss Coefficients, Storage Volume column (col F) | F4: =F3 -> See table below: Climate Zone Water Heater Sizing and Loss Coefficients, Standby Loss column (col G) | G4: =G3 -> See table below for sources: Climate Zone Water Heater Sizing and Loss Coefficients
A6: Peak Hot Water Consumption
A7: Space Name | B7: Baseline WH Type [T24, 2022, Appendix 5.4A , sheet: "2022 SpaceFuncData-Input"] | C7: Total Area (ft²) | D7: Number of People | E7: Hot Water Usage Specification (gal/hr per person) [T24, 2022, Appendix 5.4A , sheet: "2022 SpaceFuncData-Input"] | F7: Peak Hot Water Usage (gal/hr) | G7: Peak Hot Water Usage (gal/min)
A8: =Zones!B3 -> Admin/MPR_Breakroom_Zn | B8: HPWH | C8: =Zones!H3 -> 575.2 | D8: =Zones!K3 -> 18.9816 | E8: 0.09 | F8: =E8*D8 -> 1.708344 | G8: =F8/60 -> 0.0284724
A9: =Zones!B4 -> Admin/MPR_Conference Room Zns 3_Zn | B9: HPWH | C9: =Zones!H4 -> 1674.74 | D9: =Zones!K4 -> 55.26642 | E9: 0.09 | F9: =E9*D9 -> 4.9739778 | G9: =F9/60 -> 0.08289963
A10: =Zones!B5 -> Admin/MPR_Corridor_Zn | B10: HPWH | C10: =Zones!H5 -> 1161.52 | D10: =Zones!K5 -> 5.8076 | E10: 0 | F10: =E10*D10 -> 0 | G10: =F10/60 -> 0
A11: =Zones!B6 -> Admin/MPR_EMT_Zn | B11: HPWH | C11: =Zones!H6 -> 278.21 | D11: =Zones!K6 -> 1.39105 | E11: 0.18 | F11: =E11*D11 -> 0.250389 | G11: =F11/60 -> 0.00417315
A12: =Zones!B7 -> Admin/MPR_IDF Room_Zn | B12: HPWH | C12: =Zones!H7 -> 340.23 | D12: =Zones!K7 -> 1.70115 | E12: 0.18 | F12: =E12*D12 -> 0.306207 | G12: =F12/60 -> 0.00510345
A13: =Zones!B8 -> Admin/MPR_Kitchen_Zn | B13: HPWH | C13: =Zones!H8 -> 1457.25 | D13: =Zones!K8 -> 4.37175 | E13: 0.578 | F13: =E13*D13 -> 2.5268715 | G13: =F13/60 -> 0.042114525
A14: =Zones!B9 -> Admin/MPR_Lobby_Zn | B14: HPWH | C14: =Zones!H9 -> 1241.47 | D14: =Zones!K9 -> 40.96851 | E14: 0.09 | F14: =E14*D14 -> 3.6871659 | G14: =F14/60 -> 0.061452765
A15: =Zones!B10 -> Admin/MPR_Multipurpose Room Zns 3_Zn | B15: HPWH | C15: =Zones!H10 -> 5512.19 | D15: =Zones!K10 -> 181.90227 | E15: 0.09 | F15: =E15*D15 -> 16.371204 | G15: =F15/60 -> 0.2728534
A16: =Zones!B11 -> Admin/MPR_Office - LT 250 sf Zns 6_Zn | B16: HPWH | C16: =Zones!H11 -> 1048.35 | D16: =Zones!K11 -> 5.24175 | E16: 0.18 | F16: =E16*D16 -> 0.943515 | G16: =F16/60 -> 0.01572525
A17: =Zones!B12 -> Admin/MPR_Restroom Zns 3_Zn | B17: HPWH | C17: =Zones!H12 -> 901.17 | D17: =Zones!K12 -> 4.50585 | E17: 0 | F17: =E17*D17 -> 0 | G17: =F17/60 -> 0
A18: =Zones!B13 -> Admin/MPR_Storage - General_Zn | B18: HPWH | C18: =Zones!H13 -> 1247.73 | D18: =Zones!K13 -> 6.23865 | E18: 0 | F18: =E18*D18 -> 0 | G18: =F18/60 -> 0
A19: =Zones!B14 -> Admin/MPR_Storage - Refrigerated_Zn | B19: HPWH | C19: =Zones!H14 -> 251.72 | D19: =Zones!K14 -> 0 | E19: 0.18 | F19: =E19*D19 -> 0 | G19: =F19/60 -> 0
... A45: =Zones!B40 -> Kindergarten_Storage - General_Zn | B45: HPWH | C45: =Zones!H40 -> 1183.8 | D45: =Zones!K40 -> 5.919 | E45: 0 | F45: =E45*D45 -> 0 | G45: =F45/60 -> 0
A50: Plant peak hot water (gal/hr)
A51: Water Heater Name | B51: WH type | C51: Peak Hot Water Usage (gal/hr) | D51: Notes
A52: HPWH - Admin | B52: HPWH | C52: =MAX(SUMIF($B$8:$B$20,"*HPWH*",$F$8:$F$20),75) -> 75 | D52: Minimum peak hot water usage is 75 gal/hr according to ACM 2025, §5.9.2
A53: HPWH - North Classroom | B53: HPWH | C53: =MAX(SUMIF($B$21:$B$28,"*HPWH*",$F$21:$F$28),75) -> 75
A54: HPWH - West Classroom | B54: HPWH | C54: =MAX(SUMIF($B$29:$B$39,"*HPWH*",$F$29:$F$39),75) -> 75
A55: HPWH - Kindergarten | B55: HPWH | C55: =MAX(SUMIF($B$40:$B$45,"*HPWH*",$F$40:$F$45),75) -> 75
A57: Design supply temperature (°F) | B57: 135 | C57: CEC-400-2022-009-CMF-REV2-AP5.4B
A58: WH system factor | B58: 0.6 | C58: 2025 ACM §5.9.2 Rated Capacity
A59: Water mass conversion (lb/gal) | B59: 8.2877 | C59: 2025 ACM §5.9.2 Rated Capacity
A60: Reheat multiplier | B60: 0.4 | C60: 2025 ACM §5.9.2 Storage Volume
A61: Commercial HPWH configuration | B61: Unitary storage HPWH (integrated) | C61: Distributed unitary storage HPWH; retain the K-8 prototype's 4 water heaters and 4 service-water loops.
A62: Selected commercial COPh | B62: 4.3 | C62: ENERGY STAR Certified Commercial Water Heaters export, filtered Electric Heat Pump (2026-09-03): integrated 119-gal CHP family COPh = 4.3.
A63: ENERGY STAR minimum commercial COPh | B63: 3 | C63: ENERGY STAR commercial electric heat pump water-heater criterion; shown as the floor, not the selected enhanced value.
A64: Design COPh | B64: =B62 -> 4.3 | C64: Use commercial COPh directly.
A67: Climate Zone Water Heater Sizing and Loss Coefficients (Individual WH)
A68: Water Heater name | B68: Climate Zone | C68: Minimum Monthly Mains Temp (°F) [T24 2022 - Appendix 5.4B] | D68: Heat Output (Btu/hr) [ACM, 2025, 5.9.2: Rated capacity section] | E68: WH Capacity (Btu/hr) [ACM, 2025, 5.9.2: Rated capacity section] | F68: Required Energy Input (Btu/hr) | G68: Storage Volume (gal) | H68: Standby Loss (%/hr) [DEER Commercial HPWH Calculator V1.0.3.2; NREL 64904. Not Title 20 Table F-4] | J68: Off/On Cycle Loss Coefficient to Ambient Temp | L68: Source/Note
A69: HPWH_SkoolK-8_Admin | B69: CZ01 | C69: 47.9 | D69: =$C$52*($B$57-C69)*$B$59 -> 54139.4 | E69: =D69*$B$58 -> 32483.64 | F69: =_xlfn.LET(_xlpm.x,_xlfn.XLOOKUP(E69,$C$137:$C$141,$C$137:$C$141,"",1),IF(_xlpm.x="",E69/$B$64,_xlpm.x/$B$64)) -> 7554.3349 | G69: =_xlfn.LET(_xlpm.v,MAX(30,$C$52*$B$60),_xlpm.x,_xlfn.XLOOKUP(_xlpm.v,$A$137:$A$141,$A$137:$A$141,"",1),IF(_xlpm.x="",ROUNDUP(_xlpm.v,0),_xlpm.x)) -> 40 | H69: =IF(AND(ISNUMBER(J69),G69>0),J69/(0.0834*G69),NA()) -> 1.309952 | I69: %/hr | J69: 4.37 | K69: Btu/h·°F | L69: Approach: distributed unitary storage HPWH. The K-8 Prototype has 4 water heaters and 4 service-water loops; retain one plant for Admin, North Classroom, West Classroom, and Kindergarten. Efficiency: commercial COPh = 4.3 from the ENERGY STAR Certified Commercial Water Heaters export (Electric Heat Pump filter). The only integrated commercial family in that export is 119 gal: AO Smith CAHP-120 100, Lochinvar CHPA120PD 100, and State CSHP-120-DHPT 100. Required electric input (col E) = required WH capacity (col D) / COPh. Tank loss: DEER Commercial HPWH Calculator §1.7.2 states HPWH standby losses are not published and uses UA = 4.37 Btu/h·°F for HPWHs (from NREL 64904). Therefore I = 4.37 constant for one unitary tank per plant; G (%/hr) = I / (0.0834 × F). Do not scale UA by assumed cylinder area. Title 20 Table F-4 electric-storage standby (0.30 + 27/V %/hr) is not used because 10 CFR 431.102 excludes commercial heat pump water heaters. The 40/50/66/80/120-gal rows are retained as prototype storage-sizing bins; they are not represented as ENERGY STAR commercial market rows. Sources: https://www.energystar.gov/productfinder/product/certified-commercial-water-heaters/results https://cedars.cpuc.ca.gov/deer-resources/tools/water-heaters/ https://www.ecfr.gov/current/title-10/chapter-II/subchapter-D/part-431/subpart-G/section-431.102 https://www.nlr.gov/docs/fy16osti/64904.pdf
A70: HPWH_SkoolK-8_Admin | B70: CZ02 | C70: 50.8 | D70: =$C$52*($B$57-C70)*$B$59 -> 52336.825 | E70: =D70*$B$58 -> 31402.095 | F70: =_xlfn.LET(_xlpm.x,_xlfn.XLOOKUP(E70,$C$137:$C$141,$C$137:$C$141,"",1),IF(_xlpm.x="",E70/$B$64,_xlpm.x/$B$64)) -> 7302.8129 | G70: =_xlfn.LET(_xlpm.v,MAX(30,$C$52*$B$60),_xlpm.x,_xlfn.XLOOKUP(_xlpm.v,$A$137:$A$141,$A$137:$A$141,"",1),IF(_xlpm.x="",ROUNDUP(_xlpm.v,0),_xlpm.x)) -> 40 | H70: =IF(AND(ISNUMBER(J70),G70>0),J70/(0.0834*G70),NA()) -> 1.309952 | I70: %/hr | J70: 4.37 | K70: Btu/h·°F
