Workbook
Name nonparticipating_forecastzone_scale_factor: #REF!
Name nonparticipating_forecastzone_scale_factor: #REF!
Name nonparticipating_forecastzone_scale_factor: 'Energy Usage'!#REF!
Name Space_Function: Data!$A$2:$A$76

Sheet Notes
A1: Data Sources
A2: Dataset | B2: Dodge 2023
B3: CEUS 2022
B4: ComStock 2023
A6: Prototype | B6: CEC 2028 School prototype | C6: https://efiling.energy.ca.gov/GetDocument.aspx?tn=265691&DocumentContentId=102542
A9: Codes | B9: Title 24, part 6, referred to as T24 (1984, 2001, 2007, 2013, 2016, 2022, 2025)
B10: ASHRAE 90.1 (2022)
B11: CFR Title 10 (2008, 2010, 2025)
B12: ACM 2022
B13: T24 2022 - Appendix 5.4A and Appendix 5.4B | C13: https://www.energy.ca.gov/publications/2022/2022-nonresidential-and-multifamily-alternative-calculation-method-reference
A15: Other | B15: 2022 Reduced infiltration CASE report | C15: https://title24stakeholders.com/wp-content/uploads/2020/10/2022-T24-Final-CASE-Report_Reduce-Infiltration.pdf
B16: 2019 Outdoor Lighting CASE Report | C16: https://title24stakeholders.com/wp-content/uploads/2016/10/T24-2019-CASE-Study-Results-Report-Outdoor-Sources_Final_with-Attachments.pdf
B17: 2019 High Efficiency Fume Hoods in Laboratory Spaces CASE Report | C17: https://title24stakeholders.com/wp-content/uploads/2017/09/2019-T24-CASE-Report_Fume-Hoods_Final_September-2017.pdf?
B18: PNNL 20405, 2011 | C18: https://www.pnnl.gov/main/publications/external/technical_reports/PNNL-20405.pdf
B19: Air leakage Memo, NORESCO, 2025 | C19: Infiltration_rate_report_14May2025-Short-Version.docx — internal NORESCO project memo (not a public URL). See Prototype basis / Source access below.
B20: ENERGY STAR certified commercial water heaters (electric heat pump; integrated commercial HPWH) | C20: =HYPERLINK("https://www.energystar.gov/productfinder/product/certified-commercial-water-heaters/results?fuel_filter=Electric&markets_filter=United+States","ENERGY STAR — electric (HPWH)") -> ENERGY STAR — electric (HPWH)
B21: ENERGY STAR commercial WH dataset (download) | C21: =HYPERLINK("https://data.energystar.gov/Active-Specifications/ENERGY-STAR-Certified-Commercial-Water-Heaters/xmq6-bm79","ENERGY STAR dataset xmq6-bm79") -> ENERGY STAR dataset xmq6-bm79
B22: ENERGY STAR commercial WH eligibility (electric heat pump, min COPh 3) | C22: =HYPERLINK("https://www.energystar.gov/products/water_heaters/commercial_water_heaters/key_product_criteria","ENERGY STAR key product criteria") -> ENERGY STAR key product criteria
A24: Construction Rate
B36: Dodge 2023 construction rates used in the SCE vintage-bin analysis. Legend labels STC 41 and STC 49 are Dodge structure-type series identifiers from that analysis (Prototype D6, NonRes-Vintage bins-Draft Report-30Nov2023). They are not Title 24 climate zones.
A37: Notes
A38: 2025 T24 | B38: School includes five buildings: north classroom, lab classroom, shop classroom, MPR/Admin, and gym/courts/locker.
A40: Prototype basis
A41: Geometry | B41: Geometry is CEC SchoolHigh as implemented in CBECC (Prototype C7:C16; five buildings in B34: north classroom, lab classroom, shop classroom, MPR/Admin, gym/courts/locker). Floor area 174,819 ft². Prototype comparison columns (CalBEM SchoolLarge, DEER Education-Secondary, PNNL SchoolSecondary) are reference only.
A42: Vintage bins | B42: Existing vintages Pre-1978, 1978-1997, 1998-2007, 2008-2018 plus New Construction 2019+ follow the SCE Enhanced Prototypes vintage-bin analysis (Prototype D6). Dodge 2023 construction rates inform stock weighting; they are not a Title 24 prescriptive requirement.
A43: Curriculum and stock | B43: Comprehensive high school program (classrooms, labs, shops, gym/lockers, MPR, kitchen, library, administration). The prototype represents average California high-school stock. Funding/condition variation is carried in vintage envelope/HVAC/lighting assumptions (including Envelope H8 30-year roof replacement).
A44: WWR, heights, energy | B44: WWR 6.86%, no exterior shades (CEC). Floor-to-floor 14 ft except MPR/Admin 14–25 ft and Court 22–34 ft. Existing HVAC: PSZAC + gas furnace (MPR SZVAV). New construction: SZHP. Service water: existing electric resistance; NC heat-pump water heater (Water Heater B3:B4).
A45: Abbreviations | B45: T24 = California Title 24, Part 6. ACM = Nonresidential/Multifamily Alternative Calculation Method Reference Manual. CEC = California Energy Commission. CBECC = California Building Energy Code Compliance software. CEUS = California Commercial End-Use Survey. PSZAC = packaged single-zone air conditioner. SZHP = single-zone heat pump. SZVAV = single-zone VAV. HPWH = heat-pump water heater. SRR = skylight-to-roof ratio. WWR = window-to-wall ratio. IWA = initial wattage allowance.
A46: Source access | B46: Column C lists public links where they exist. Dodge 2023 is a licensed dataset with no public URL. The NORESCO air-leakage memo is an internal file (C19), not a webpage. ENERGY STAR water-heater rows use the commercial electric (heat pump) Product Finder and dataset xmq6-bm79. Schedule fractions that cite the Plug Loads and Schedules project with CEC (2025) do not have an external link yet; an ASHRAE paper has been submitted and the citation will be updated when that paper is published or when ACM 2028 is released.
A47: Sources used | B47: Used on this scorecard: CEC SchoolHigh (efiling tn=265691); T24 2022 App. 5.4A/5.4B; ACM 2025 §5.9.2 and fan tables; T24 Tables 140.3-B, 110.2-A/B, 140.6-C, 140.7-A/B, 120.1-A/B; 2022 Reduced Infiltration CASE; 2019 Outdoor Lighting CASE; 2019 Fume-hood CASE (labs present); PNNL 20405; ASHRAE 90.1-2022 Appendix A; ASHRAE Handbook of Fundamentals; ENERGY STAR commercial HPWH list. Reviewer-suggested references that do not support a retained assumption are not added.

Sheet Prototype
A1: NORESCO, Updated September 2026
A2: SchoolHigh
A3: Characteristic | B3: Value | C3: Data Sources
A4: Building Type | B4: High School
A5: Building Category | B5: Nonresidential
A6: Version | B6: v2-0
A7: Vintages | B7: 4 Vintages: Pre-1978, 1978-1997,1998-2007, 2008-2018 New Construction (2019+) | C7: Based on the vintage bin analysis. A summary of the findings is presented in the following paper, with a link provided in the Notes tab: Yousefi, F., Athalye, R. (2025). “Determining Vintage Bins for Prototype Development: An Analysis of California Commercial Buildings.” ASHRAE Annual Conference.
A8: Shape | C8: The analysis uses prototype geometry originally developed by CEC approved 2028 SchoolK-8 prototype.
A9: Total Floor Area (ft²) | B9: 174818.98 | C9: CEC SchoolKto8 / CBECC (same as Prototype comparison column C).
A10: Aspect Ratio | B10: It varies for different buildings. | C10: Same as the CEC approved 2028 SchoolK-8 prototype
A11: Number of Floors | B11: It varies for different buildings. | C11: Same as the CEC approved 2028 SchoolK-8 prototype
A12: Roof type | B12: Flat | C12: Same as the CEC approved 2028 SchoolK-8 prototype
A13: WWR | B13: 0.0686 | C13: Same as the CEC approved 2028 SchoolK-8 prototype
A14: Shading Geometry | B14: No Shades | C14: Same as the CEC approved 2028 SchoolK-8 prototype
A15: Floor to floor height (feet) | B15: It varies for different buildings: MPR/Admin: 14-25 Court: 22-34 Other buildings: 14 ft | C15: Same as the CEC approved 2028 SchoolK-8 prototype
A16: Floor to ceiling height (feet) | B16: It varies for different buildings: MPR/Admin: 14-25 Court: 22-34 Other buildings: 14 ft | C16: Same as the CEC approved 2028 SchoolK-8 prototype
A17: Glazing sill height (feet) | B17: It varies for different buildings. | C17: Same as the CEC approved 2028 SchoolK-8 prototype
A21: Above grade wall area (ft²) | B21: 140514
A22: Gross wall area (ft²) | B22: 140514
A23: Roof area (ft²) | B23: 134334.45
A24: Underground Gross Wall Area (ft²) | B24: 0

Sheet Zones
A1: ="Proposed Layout - "&Prototype!B4 -> Proposed Layout - High School
A2: Building | B2: Space/Thermal Zone | C2: Space Type [Primarily from: T24, 2022 Appendix 5.4A] - See Notes column | D2: HVAC System Name/AHU Name | E2: Schedule Category | F2: Conditioned (Y/N) | G2: Area Fraction | H2: Area (ft²) | I2: Volume (ft³) | J2: Multipliers | K2: Number of People | L2: People (Persons/1,000 ft²) [T24, 2025,Table 120.1-A] | M2: Notes | N2: Total Floor area (multiper applied)
A3: SchoolHigh Admin/MPR | B3: ADMIN/MPR_BREAKROOM_ZN | C3: Lounge, Breakroom, or Waiting Area | D3: AHU-1 | E3: MPR | F3: Y | G3: =(H3*J3)/SUMPRODUCT($H$3:$H$44,$J$3:$J$44) -> 0.0032902596 | H3: 575.2 | I3: 8053.16 | J3: 1 | K3: =L3*H3/1000 -> 18.9816 | L3: 33 | N3: =J3*H3 -> 575.2
A4: SchoolHigh Admin/MPR | B4: ADMIN/MPR_CAFETERIA ZNS 3_ZN | C4: Dining Area (Cafeteria/Fast Food) | D4: AHU-2 | E4: MPR | F4: Y | G4: =(H4*J4)/SUMPRODUCT($H$3:$H$44,$J$3:$J$44) -> 0.031530835 | H4: 5512.19 | I4: 137811.47 | J4: 1 | K4: =L4*H4/1000 -> 181.90227 | L4: 33 | N4: =J4*H4 -> 5512.19
A5: SchoolHigh Admin/MPR | B5: ADMIN/MPR_CONFERENCE ROOM ZNS 3_ZN | C5: Convention, Conference, Multipurpose and Meeting Area | D5: AHU-3 | E5: MPR | F5: Y | G5: =(H5*J5)/SUMPRODUCT($H$3:$H$44,$J$3:$J$44) -> 0.0095798495 | H5: 1674.74 | I5: 23447.5 | J5: 1 | K5: =L5*H5/1000 -> 55.26642 | L5: 33 | N5: =J5*H5 -> 1674.74
A6: SchoolHigh Admin/MPR | B6: ADMIN/MPR_CORRIDOR_ZN | C6: Corridor Area | D6: AHU-4 | E6: MPR | F6: Y | G6: =(H6*J6)/SUMPRODUCT($H$3:$H$44,$J$3:$J$44) -> 0.11295017 | H6: 1161.52 | I6: 16262.09 | J6: 17 | K6: =L6*H6/1000 -> 5.8076 | L6: 5 | N6: =J6*H6 -> 19745.84
A7: SchoolHigh Admin/MPR | B7: ADMIN/MPR_EMT_ZN | C7: Electrical, Mechanical, Telephone Rooms | D7: AHU-5 | E7: MPR | F7: Y | G7: =(H7*J7)/SUMPRODUCT($H$3:$H$44,$J$3:$J$44) -> 0.0079570857 | H7: 278.21 | I7: 3895.07 | J7: 5 | K7: =L7*H7/1000 -> 1.39105 | L7: 5 | N7: =J7*H7 -> 1391.05
A8: SchoolHigh Admin/MPR | B8: ADMIN/MPR_IDF ROOM_ZN | C8: Electrical, Mechanical, Telephone Rooms | D8: AHU-6 | E8: MPR | F8: Y | G8: =(H8*J8)/SUMPRODUCT($H$3:$H$44,$J$3:$J$44) -> 0.00973092 | H8: 340.23 | I8: 4763.43 | J8: 5 | K8: =L8*H8/1000 -> 1.70115 | L8: 5 | N8: =J8*H8 -> 1701.15
A9: SchoolHigh Admin/MPR | B9: ADMIN/MPR_KITCHEN_ZN | C9: Kitchen/Food Preparation Area | D9: AHU-7 | E9: Kitchen | F9: Y | G9: =(H9*J9)/SUMPRODUCT($H$3:$H$44,$J$3:$J$44) -> 0.008335763 | H9: 1457.25 | I9: 20402.54 | J9: 1 | K9: =L9*H9/1000 -> 4.37175 | L9: 3 | N9: =J9*H9 -> 1457.25
A10: SchoolHigh Admin/MPR | B10: ADMIN/MPR_LOBBY_ZN | C10: Lobby, Main Entry | D10: AHU-8 | E10: MPR | F10: Y | G10: =(H10*J10)/SUMPRODUCT($H$3:$H$44,$J$3:$J$44) -> 0.028405832 | H10: 1241.47 | I10: 17381.45 | J10: 4 | K10: =L10*H10/1000 -> 40.96851 | L10: 33 | N10: =J10*H10 -> 4965.88
A11: SchoolHigh Admin/MPR | B11: ADMIN/MPR_OFFICE - LT 250 SF ZNS 6_ZN | C11: Office Area (<250 square feet) | D11: AHU-9 | E11: MPR | F11: Y | G11: =(H11*J11)/SUMPRODUCT($H$3:$H$44,$J$3:$J$44) -> 0.035980637 | H11: 1048.35 | I11: 14677.59 | J11: 6 | K11: =L11*H11/1000 -> 5.24175 | L11: 5 | N11: =J11*H11 -> 6290.1
A12: SchoolHigh Admin/MPR | B12: ADMIN/MPR_RESTROOM ZNS 3_ZN | C12: Restrooms | D12: AHU-10 | E12: MPR | F12: Y | G12: =(H12*J12)/SUMPRODUCT($H$3:$H$44,$J$3:$J$44) -> 0.010309747 | H12: 901.17 | I12: 12620.46 | J12: 2 | K12: =L12*H12/1000 -> 4.50585 | L12: 5 | N12: =J12*H12 -> 1802.34
A13: SchoolHigh Admin/MPR | B13: ADMIN/MPR_STORAGE - GENERAL_ZN | C13: Storage (General) | D13: AHU-11 | E13: MPR | F13: Y | G13: =(H13*J13)/SUMPRODUCT($H$3:$H$44,$J$3:$J$44) -> 0.028549066 | H13: 1247.73 | I13: 17469.08 | J13: 4 | K13: =L13*H13/1000 -> 6.23865 | L13: 5 | N13: =J13*H13 -> 4990.92
A14: SchoolHigh Admin/MPR | B14: ADMIN/MPR_STORAGE - REFRIGERATED_ZN | C14: Storage, Commercial/Industrial (Refrigerated) | D14: AHU-12 | E14: MPR | F14: Y | G14: =(H14*J14)/SUMPRODUCT($H$3:$H$44,$J$3:$J$44) -> 0.001439889 | H14: 251.72 | I14: 3524.26 | J14: 1 | K14: =L14*H14/1000 -> 0 | L14: 0 | N14: =J14*H14 -> 251.72
... A44: SchoolHigh Sports | B44: ROOMS & STUDIOS ZN | C44: Exercise/Fitness Center and Gymnasium Areas | D44: AHU-42 | E44: Gym | F44: Y | G44: =(H44*J44)/SUMPRODUCT($H$3:$H$44,$J$3:$J$44) -> 0.026361261 | H44: 4608.45 | I44: 101390.84 | J44: 1 | K44: =L44*H44/1000 -> 46.0845 | L44: 10 | N44: =J44*H44 -> 4608.45
A45: Total (5 Buildings) | B45: Total (42 spaces) | C45: Total (18 Space types) | D45: Total (42 HVAC Systems) | E45: Total (4 Schedule categories) | F45: Total (42 Conditioned zones) | G45: =SUM(G3:G44) -> 1 | H45: =SUM(H3:H44) -> 79502.25 | I45: =SUM(I3:I44) -> 1629030.6 | K45: =SUM(K3:K44) -> 1221.3724
Q48: Area Distribution By Space Type
Q49: Space Type | R49: Area (ft²) | S49: % Area
Q50: Lounge, Breakroom, or Waiting Area | R50: =SUMIF($C$3:$C$44,"Lounge, Breakroom, or Waiting Area",$H$3:$H$44) -> 575.2 | S50: =SUMIF($C$3:$C$44,"Lounge, Breakroom, or Waiting Area",$G$3:$G$44) -> 0.0032902596
Q51: Dining Area (Cafeteria/Fast Food) | R51: =SUMIF($C$3:$C$44,"Dining Area (Cafeteria/Fast Food)",$H$3:$H$44) -> 5512.19 | S51: =SUMIF($C$3:$C$44,"Dining Area (Cafeteria/Fast Food)",$G$3:$G$44) -> 0.031530835
Q52: Convention, Conference, Multipurpose and Meeting Area | R52: =SUMIF($C$3:$C$44,"Convention, Conference, Multipurpose and Meeting Area",$H$3:$H$44) -> 1674.74 | S52: =SUMIF($C$3:$C$44,"Convention, Conference, Multipurpose and Meeting Area",$G$3:$G$44) -> 0.0095798495
Q53: Corridor Area | R53: =SUMIF($C$3:$C$44,"Corridor Area",$H$3:$H$44) -> 1161.52 | S53: =SUMIF($C$3:$C$44,"Corridor Area",$G$3:$G$44) -> 0.11295017
Q54: Electrical, Mechanical, Telephone Rooms | R54: =SUMIF($C$3:$C$44,"Electrical, Mechanical, Telephone Rooms",$H$3:$H$44) -> 1214.82 | S54: =SUMIF($C$3:$C$44,"Electrical, Mechanical, Telephone Rooms",$G$3:$G$44) -> 0.021099419
Q55: Kitchen/Food Preparation Area | R55: =SUMIF($C$3:$C$44,"Kitchen/Food Preparation Area",$H$3:$H$44) -> 1457.25 | S55: =SUMIF($C$3:$C$44,"Kitchen/Food Preparation Area",$G$3:$G$44) -> 0.008335763
Q56: Lobby, Main Entry | R56: =SUMIF($C$3:$C$44,"Lobby, Main Entry",$H$3:$H$44) -> 1241.47 | S56: =SUMIF($C$3:$C$44,"Lobby, Main Entry",$G$3:$G$44) -> 0.028405832
Q57: Office Area (<250 square feet) | R57: =SUMIF($C$3:$C$44,"Office Area (<250 square feet)",$H$3:$H$44) -> 1624.61 | S57: =SUMIF($C$3:$C$44,"Office Area (<250 square feet)",$G$3:$G$44) -> 0.055758575
Q58: Restrooms | R58: =SUMIF($C$3:$C$44,"Restrooms",$H$3:$H$44) -> 3358.7 | S58: =SUMIF($C$3:$C$44,"Restrooms",$G$3:$G$44) -> 0.030461615
Q59: Storage (General) | R59: =SUMIF($C$3:$C$44,"Storage (General)",$H$3:$H$44) -> 2910.38 | S59: =SUMIF($C$3:$C$44,"Storage (General)",$G$3:$G$44) -> 0.038059758
Q60: Storage, Commercial/Industrial (Refrigerated) | R60: =SUMIF($C$3:$C$44,"Storage, Commercial/Industrial (Refrigerated)",$H$3:$H$44) -> 251.72 | S60: =SUMIF($C$3:$C$44,"Storage, Commercial/Industrial (Refrigerated)",$G$3:$G$44) -> 0.001439889
Q61: Theater Area (Performance) | R61: =SUMIF($C$3:$C$44,"Theater Area (Performance)",$H$3:$H$44) -> 1065.56 | S61: =SUMIF($C$3:$C$44,"Theater Area (Performance)",$G$3:$G$44) -> 0.030476087
Q62: Laboratory, Scientific | R62: =SUMIF($C$3:$C$44,"Laboratory, Scientific",$H$3:$H$44) -> 5307 | S62: =SUMIF($C$3:$C$44,"Laboratory, Scientific",$G$3:$G$44) -> 0.030357107
Q63: Library (Reading Area) | R63: =SUMIF($C$3:$C$44,"Library (Reading Area)",$H$3:$H$44) -> 1197.13 | S63: =SUMIF($C$3:$C$44,"Library (Reading Area)",$G$3:$G$44) -> 0.0068478243
Q64: Classroom, Lecture, Training, Vocational Areas | R64: =SUMIF($C$3:$C$44,"Classroom, Lecture, Training, Vocational Areas",$H$3:$H$44) -> 14492.4 | S64: =SUMIF($C$3:$C$44,"Classroom, Lecture, Training, Vocational Areas",$G$3:$G$44) -> 0.38286244
Q65: Wood/Metal Shop Classroom | R65: =SUMIF($C$3:$C$44,"Wood/Metal Shop Classroom",$H$3:$H$44) -> 6934.68 | S65: =SUMIF($C$3:$C$44,"Wood/Metal Shop Classroom",$G$3:$G$44) -> 0.039667764
Q66: Exercise/Fitness Center and Gymnasium Areas | R66: =SUMIF($C$3:$C$44,"Exercise/Fitness Center and Gymnasium Areas",$H$3:$H$44) -> 21890.14 | S66: =SUMIF($C$3:$C$44,"Exercise/Fitness Center and Gymnasium Areas",$G$3:$G$44) -> 0.125216
Q67: Locker Room | R67: =SUMIF($C$3:$C$44,"Locker Room",$H$3:$H$44) -> 7632.74 | S67: =SUMIF($C$3:$C$44,"Locker Room",$G$3:$G$44) -> 0.043660807
Q68: Total | R68: =SUM(R50:R67) -> 79502.25 | S68: =SUM(S50:S67) -> 1

Sheet Envelope
A1: ="Envelope - "&Prototype!A2 -> Envelope - SchoolHigh
A2: Element | B2: Prototype | C2: Assembly Type | D2: Construction | E2: Thermal properties | F2: Vintage | G2: Selected T24 | H2: Notes | I2: CZ1 | J2: CZ2 | K2: CZ3 | L2: CZ4 | M2: CZ5 | N2: CZ6 | O2: CZ7 | P2: CZ8 | Q2: CZ9 | R2: CZ10 | S2: CZ11 | T2: CZ12 | U2: CZ13 | V2: CZ14 | W2: CZ15 | X2: CZ16
A3: External Wall | B3: =Prototype!A2 -> SchoolHigh | C3: ExtWall_MetalFramed_NonRes | D3: Metal frame + insulation + Gypsum board | E3: U-value IP | F3: Pre 1978 | G3: N/A | H3: ASHRAE 90.1-2022 Table A3.3.3.1 (metal-framed), 3.5 in., R-0, U-0.352 all CZ | I3: 0.352 | J3: 0.352 | K3: 0.352 | L3: 0.352 | M3: 0.352 | N3: 0.352 | O3: 0.352 | P3: 0.352 | Q3: 0.352 | R3: 0.352 | S3: 0.352 | T3: 0.352 | U3: 0.352 | V3: 0.352 | W3: 0.352 | X3: 0.352
F4: 1978-1997 | G4: 1992 | H4: TABLE NO. 1-I | I4: 0.182 | J4: 0.189 | K4: 0.189 | L4: 0.189 | M4: 0.189 | N4: 0.189 | O4: 0.189 | P4: 0.189 | Q4: 0.189 | R4: 0.189 | S4: 0.182 | T4: 0.182 | U4: 0.182 | V4: 0.182 | W4: 0.182 | X4: 0.182
F5: 1998-2007 | G5: 2001 | H5: Table 1-H metal frame | I5: 0.182 | J5: 0.182 | K5: 0.189 | L5: 0.189 | M5: 0.189 | N5: 0.189 | O5: 0.189 | P5: 0.189 | Q5: 0.189 | R5: 0.182 | S5: 0.182 | T5: 0.182 | U5: 0.182 | V5: 0.182 | W5: 0.182 | X5: 0.182
F6: 2008-2018 | G6: 2013 | H6: Table 140.3-B metal-framed | I6: 0.098 | J6: 0.062 | K6: 0.082 | L6: 0.062 | M6: 0.062 | N6: 0.098 | O6: 0.098 | P6: 0.062 | Q6: 0.062 | R6: 0.062 | S6: 0.062 | T6: 0.062 | U6: 0.062 | V6: 0.062 | W6: 0.062 | X6: 0.062
F7: 2019+ | G7: 2025 | H7: Table 140.3-B (2025) Metal-framed walls | I7: 0.06 | J7: 0.055 | K7: 0.071 | L7: 0.055 | M7: 0.055 | N7: 0.06 | O7: 0.06 | P7: 0.055 | Q7: 0.055 | R7: 0.055 | S7: 0.055 | T7: 0.055 | U7: 0.055 | V7: 0.055 | W7: 0.055 | X7: 0.055
A8: Roof | B8: =$B$3 -> SchoolHigh | C8: FlatRoof_WoodFramedAndOther_NonRes | D8: Built-up Roof roof membrane+roof insulation+metal decking | E8: U-value IP | F8: Pre 1978 | G8: N/A | H8: Considering 30 years for roof/insulation replacement | I8: 0.057 | J8: 0.057 | K8: 0.057 | L8: 0.057 | M8: 0.057 | N8: 0.078 | O8: 0.078 | P8: 0.078 | Q8: 0.078 | R8: 0.078 | S8: 0.057 | T8: 0.057 | U8: 0.057 | V8: 0.057 | W8: 0.057 | X8: 0.057
F9: 1978-1997 | G9: N/A | I9: 0.057 | J9: 0.057 | K9: 0.057 | L9: 0.057 | M9: 0.057 | N9: 0.078 | O9: 0.078 | P9: 0.078 | Q9: 0.078 | R9: 0.078 | S9: 0.057 | T9: 0.057 | U9: 0.057 | V9: 0.057 | W9: 0.057 | X9: 0.057
F10: 1998-2007 | G10: 2001 | H10: Table 1-H | I10: 0.057 | J10: 0.057 | K10: 0.057 | L10: 0.057 | M10: 0.057 | N10: 0.078 | O10: 0.078 | P10: 0.078 | Q10: 0.078 | R10: 0.057 | S10: 0.057 | T10: 0.057 | U10: 0.057 | V10: 0.057 | W10: 0.057 | X10: 0.057
F11: 2008-2018 | G11: 2013 | H11: Table 140.3-B | I11: 0.049 | J11: 0.039 | K11: 0.039 | L11: 0.039 | M11: 0.049 | N11: 0.075 | O11: 0.067 | P11: 0.067 | Q11: 0.039 | R11: 0.039 | S11: 0.039 | T11: 0.039 | U11: 0.039 | V11: 0.039 | W11: 0.039 | X11: 0.039
F12: 2019+ | G12: 2025 | H12: Table 140.3-B | I12: 0.028 | J12: 0.028 | K12: 0.028 | L12: 0.028 | M12: 0.028 | N12: 0.047 | O12: 0.047 | P12: 0.047 | Q12: 0.028 | R12: 0.028 | S12: 0.028 | T12: 0.028 | U12: 0.028 | V12: 0.028 | W12: 0.028 | X12: 0.028
A13: Windows | B13: =$B$3 -> SchoolHigh | C13: FixedWindow_NonRes | D13: Single pane | E13: U-value IP | F13: Pre 1978 | G13: N/A | H13: ASHRAE Handbook of Fundamentals (Table 4-Ch15) for single pane & T24, 2013 for double pane (33%-67%)* | I13: =0.33*1.12+0.67*I16 -> 0.6108 | J13: =0.33*1.12+0.67*J16 -> 0.6108 | K13: =0.33*1.12+0.67*K16 -> 0.6108 | L13: =0.33*1.12+0.67*L16 -> 0.6108 | M13: =0.33*1.12+0.67*M16 -> 0.6108 | N13: =0.33*1.12+0.67*N16 -> 0.6108 | O13: =0.33*1.12+0.67*O16 -> 0.6108 | P13: =0.33*1.12+0.67*P16 -> 0.6108 | ... X13: =0.33*1.12+0.67*X16 -> 0.6108
F14: 1978-1997 | G14: N/A | I14: =0.33*1.12+0.67*I16 -> 0.6108 | J14: =0.33*1.12+0.67*J16 -> 0.6108 | K14: =0.33*1.12+0.67*K16 -> 0.6108 | L14: =0.33*1.12+0.67*L16 -> 0.6108 | M14: =0.33*1.12+0.67*M16 -> 0.6108 | N14: =0.33*1.12+0.67*N16 -> 0.6108 | O14: =0.33*1.12+0.67*O16 -> 0.6108 | P14: =0.33*1.12+0.67*P16 -> 0.6108 | ... X14: =0.33*1.12+0.67*X16 -> 0.6108
D15: Double pane | F15: 1998-2007 | G15: 2001 | H15: Table 1-H | I15: 0.49 | J15: 0.49 | K15: 0.81 | L15: 0.81 | M15: 0.81 | N15: 0.81 | O15: 0.81 | P15: 0.81 | Q15: 0.81 | R15: 0.49 | S15: 0.49 | T15: 0.49 | U15: 0.49 | V15: 0.49 | W15: 0.49 | X15: 0.49
F16: 2008-2018 | G16: 2013 | H16: Table 140.3-B | I16: 0.36 | J16: 0.36 | K16: 0.36 | L16: 0.36 | M16: 0.36 | N16: 0.36 | O16: 0.36 | P16: 0.36 | Q16: 0.36 | R16: 0.36 | S16: 0.36 | T16: 0.36 | U16: 0.36 | V16: 0.36 | W16: 0.36 | X16: 0.36
F17: 2019+ | G17: 2025 | H17: Table 140.3-B | I17: 0.36 | J17: 0.36 | K17: 0.36 | L17: 0.36 | M17: 0.36 | N17: 0.36 | O17: 0.36 | P17: 0.36 | Q17: 0.34 | R17: 0.36 | S17: 0.34 | T17: 0.34 | U17: 0.34 | V17: 0.34 | W17: 0.34 | X17: 0.36
B18: =$B$3 -> SchoolHigh | C18: FixedWindow_NonRes | D18: Single pane | E18: SHGC | F18: Pre 1978 | G18: N/A | H18: ASHRAE Handbook of Fundamentals (Table 10-Ch15) for single pane & T24, 2013 for double pane (33%-67%)* | I18: =0.79*0.33+0.67*I21 -> 0.4282 | J18: =0.79*0.33+0.67*J21 -> 0.4282 | K18: =0.79*0.33+0.67*K21 -> 0.4282 | L18: =0.79*0.33+0.67*L21 -> 0.4282 | M18: =0.79*0.33+0.67*M21 -> 0.4282 | N18: =0.79*0.33+0.67*N21 -> 0.4282 | O18: =0.79*0.33+0.67*O21 -> 0.4282 | P18: =0.79*0.33+0.67*P21 -> 0.4282 | ... X18: =0.79*0.33+0.67*X21 -> 0.4282
F19: 1978-1997 | G19: N/A | I19: =0.79*0.33+0.67*I21 -> 0.4282 | J19: =0.79*0.33+0.67*J21 -> 0.4282 | K19: =0.79*0.33+0.67*K21 -> 0.4282 | L19: =0.79*0.33+0.67*L21 -> 0.4282 | M19: =0.79*0.33+0.67*M21 -> 0.4282 | N19: =0.79*0.33+0.67*N21 -> 0.4282 | O19: =0.79*0.33+0.67*O21 -> 0.4282 | P19: =0.79*0.33+0.67*P21 -> 0.4282 | ... X19: =0.79*0.33+0.67*X21 -> 0.4282
D20: Double pane | F20: 1998-2007 | G20: 2001 | H20: Table 1-H — WWR ≤10% (prototype 6.86%), SHGC non-north. | I20: 0.43 | J20: 0.31 | K20: 0.41 | L20: 0.41 | M20: 0.41 | N20: 0.34 | O20: 0.34 | P20: 0.34 | Q20: 0.34 | R20: 0.31 | S20: 0.31 | T20: 0.31 | U20: 0.31 | V20: 0.31 | W20: 0.31 | X20: 0.43
F21: 2008-2018 | G21: 2013 | H21: Table 140.3-B | I21: 0.25 | J21: 0.25 | K21: 0.25 | L21: 0.25 | M21: 0.25 | N21: 0.25 | O21: 0.25 | P21: 0.25 | Q21: 0.25 | R21: 0.25 | S21: 0.25 | T21: 0.25 | U21: 0.25 | V21: 0.25 | W21: 0.25 | X21: 0.25
F22: 2019+ | G22: 2025 | H22: Table 140.3-B | I22: 0.25 | J22: 0.25 | K22: 0.25 | L22: 0.25 | M22: 0.25 | N22: 0.25 | O22: 0.25 | P22: 0.25 | Q22: 0.22 | R22: 0.25 | S22: 0.22 | T22: 0.22 | U22: 0.22 | V22: 0.22 | W22: 0.22 | X22: 0.25
A23: Skylight | B23: SchoolHigh | C23: Skylight | D23: Plastic curb-mounted | E23: U-factor IP | F23: Pre 1978 | G23: 1992 | H23: Table 1-I Translucent (1992 term for this plastic curb product). CalBEM skylight 1,825 ft² vs CEC 547 ft²; SRR ~0.4–1.4% (0–2% bin). | I23: 0.85 | J23: 1.31 | K23: 1.31 | L23: 1.31 | M23: 1.31 | N23: 1.31 | O23: 1.31 | P23: 1.31 | Q23: 1.31 | R23: 1.31 | S23: 0.85 | T23: 0.85 | U23: 0.85 | V23: 0.85 | W23: 0.85 | X23: 0.85
F24: 1978-1997 | G24: 1992 | I24: 0.85 | J24: 1.31 | K24: 1.31 | L24: 1.31 | M24: 1.31 | N24: 1.31 | O24: 1.31 | P24: 1.31 | Q24: 1.31 | R24: 1.31 | S24: 0.85 | T24: 0.85 | U24: 0.85 | V24: 0.85 | W24: 0.85 | X24: 0.85
F25: 1998-2007 | G25: 2001 | H25: Table 1-H plastic w/curb U-factor (U does not vary by SRR). | I25: 0.87 | J25: 1.1 | K25: 1.3 | L25: 1.3 | M25: 1.3 | N25: 1.3 | O25: 1.3 | P25: 1.3 | Q25: 1.3 | R25: 1.1 | S25: 1.1 | T25: 1.1 | U25: 1.1 | V25: 1.1 | W25: 1.1 | X25: 0.87
F26: 2008-2018 | G26: 2013 | H26: Table 140.3-B | I26: 0.88 | J26: 0.88 | K26: 0.88 | L26: 0.88 | M26: 0.88 | N26: 0.88 | O26: 0.88 | P26: 0.88 | Q26: 0.88 | R26: 0.88 | S26: 0.88 | T26: 0.88 | U26: 0.88 | V26: 0.88 | W26: 0.88 | X26: 0.88
F27: 2019+ | G27: 2025 | H27: Table 140.3-B | I27: 0.88 | J27: 0.88 | K27: 0.88 | L27: 0.88 | M27: 0.88 | N27: 0.88 | O27: 0.88 | P27: 0.88 | Q27: 0.88 | R27: 0.88 | S27: 0.88 | T27: 0.88 | U27: 0.88 | V27: 0.88 | W27: 0.88 | X27: 0.88
E28: SHGC | F28: Pre 1978 | G28: 1992 | H28: Table 1-I Translucent SHGC (1992 term; same plastic curb product). | I28: 0.81 | J28: 0.86 | K28: 0.86 | L28: 0.86 | M28: 0.86 | N28: 0.86 | O28: 0.86 | P28: 0.86 | Q28: 0.86 | R28: 0.86 | S28: 0.81 | T28: 0.81 | U28: 0.81 | V28: 0.81 | W28: 0.81 | X28: 0.81
F29: 1978-1997 | G29: 1992 | I29: 0.81 | J29: 0.86 | K29: 0.86 | L29: 0.86 | M29: 0.86 | N29: 0.86 | O29: 0.86 | P29: 0.86 | Q29: 0.86 | R29: 0.86 | S29: 0.81 | T29: 0.81 | U29: 0.81 | V29: 0.81 | W29: 0.81 | X29: 0.81
F30: 1998-2007 | G30: 2001 | H30: Table 1-H plastic w/curb, SRR 0–2% (High ~0.4% CEC / ~1.4% CalBEM). Not 2.1–5%. | I30: 0.77 | J30: 0.77 | K30: 0.79 | L30: 0.79 | M30: 0.79 | N30: 0.77 | O30: 0.77 | P30: 0.77 | Q30: 0.77 | R30: 0.77 | S30: 0.77 | T30: 0.77 | U30: 0.77 | V30: 0.71 | W30: 0.71 | X30: 0.77
F31: 2008-2018 | G31: 2013 | H31: Table 140.3-B plastic curb SHGC = NR; used 2001 Table 1-H 0–2% SRR. | I31: 0.77 | J31: 0.77 | K31: 0.79 | L31: 0.79 | M31: 0.79 | N31: 0.77 | O31: 0.77 | P31: 0.77 | Q31: 0.77 | R31: 0.77 | S31: 0.77 | T31: 0.77 | U31: 0.77 | V31: 0.71 | W31: 0.71 | X31: 0.77
F32: 2019+ | G32: 2025 | H32: Table 140.3-B (2025) plastic curb SHGC = NR; same 2001 0–2% SRR values. | I32: 0.77 | J32: 0.77 | K32: 0.79 | L32: 0.79 | M32: 0.79 | N32: 0.77 | O32: 0.77 | P32: 0.77 | Q32: 0.77 | R32: 0.77 | S32: 0.77 | T32: 0.77 | U32: 0.77 | V32: 0.71 | W32: 0.71 | X32: 0.77
A34: Floor: SlabOnGrade_Unheated_NonRes is a 4 in. concrete slab-on-grade with no insulation. It is the same for every vintage (F-factor 0.73), so it is documented here instead of as a table row.
C36: Infiltration
D37: Building | E37: Zones | F37: Vintage | G37: I_75 6-Sided Inifltration rate @ 75 pa | H37: Note | I37: I-design (cfm/ft²) (4-sided Infiltration rate at normal presure) (Design flow rate approach and Flow/Exterior Wall Area calulation method)
C38: Infiltration | D38: SchoolHigh Admin/MPR | F38: Pre 1978 | G38: 1.1 | H38: 2022 CASE report (Table 38) | I38: =0.112*G38*#REF! -> #REF! | Z38: Floor or roof area (ft2) | AA38: 55686.18
F39: 1978-1997 | G39: 1.1 | H39: 2022 CASE report (Table 38) | I39: =0.112*G39*#REF! -> #REF! | Z39: Walls area (ft2) | AA39: 14075
F40: 1998-2007 | G40: 1.1 | H40: 2022 CASE report (Table 38) | I40: =0.112*G40*#REF! -> #REF! | Z40: Building 4 sided area (ft2)= | AA40: =AA39 -> 14075
F41: 2008-2018 | G41: 1 | H41: 2022 CASE report (Table 38) & T24, 2008-2016 (Table 140.3-B)--Air barrier is required in CZ 10-16 | I41: =0.112*G41*#REF! -> #REF! | Z41: Building 6 sided area (ft2)= | AA41: =AA39+(2*AA38) -> 125447.36
F42: 2019+ | G42: 0.6 | H42: 2022 CASE report (Table 38) & T24, 2025 (Table 140.3-B)--Air barrier is required in all CZs | I42: =0.112*G42*#REF! -> #REF!
...

Sheet HVAC System
A1: ="HVAC system - "&Prototype!A2 -> HVAC system - SchoolHigh
A2: Vintage | B2: Zones | C2: Heating | D2: Cooling | E2: Air Distribution | F2: Other Systems | G2: Source | H2: Note
A3: Exisiting | B3: All Space Types except MPR/refrigerated storage | C3: Gas Furnace | D3: PSZAC (DX cooling) | E3: CAV | F3: OA mixing. Air-side economizer: not modeled (see Economizer / ERV). | G3: Engineering Judgement | H3: System 3a
B4: Admin/MPR Multipurpose Room / Cafeteria | C4: SZHP (DX heating) | D4: SZHP (DX cooling) | E4: SZVAV (single-zone VAV) | F4: OA mixing. Air-side economizer: not modeled (see Economizer / ERV). | G4: Engineering Judgement | H4: VAV:NoReheat terminal, Fan:VariableVolume for the tall MPR/cafeteria volume. Theater and other Admin zones remain CAV.
B5: Admin/MPR_Storage - Refrigerated | C5: n/a (walk-in refrigeration) | D5: Walk-in cooler (not PSZ DX) | E5: n/a | F5: n/a — walk-in refrigeration, not an air-side HVAC OA system. | G5: Engineering Judgement | H5: Refrigeration system; 35°F product; equipment W/ft² on Equipment tab.
A6: New Construction | B6: All Space Types except MPR and refrigerated storage | C6: SZHP | D6: SZHP | E6: CAV | F6: OA mixing. Air-side economizer: not modeled (see Economizer / ERV). | G6: ACM 2025 | H6: System 3b
B7: Admin/MPR Multipurpose Room / Cafeteria | C7: SZHP (DX heating) | D7: SZHP (DX cooling) | E7: SZVAV (single-zone VAV) | F7: OA mixing. Air-side economizer: not modeled (see Economizer / ERV). | G7: Engineering Judgement | H7: VAV:NoReheat terminal, Fan:VariableVolume for the tall MPR/cafeteria volume. Theater and other Admin zones remain CAV.
B8: Admin/MPR_Storage - Refrigerated | C8: n/a (walk-in refrigeration) | D8: Walk-in cooler (not PSZ DX) | E8: n/a | F8: n/a — walk-in refrigeration, not an air-side HVAC OA system. | G8: Engineering Judgement | H8: Refrigeration system; 35°F product; equipment W/ft² on Equipment tab.
A13: Efficiency of HVAC System (Efficiency is capacity-dependent. The following table provides a general estimate of system efficiency based on preliminary simulations in one climate zone, or assuming cooling load based on rule of thumb)
A14: Vintage | B14: Upgrade/Installed year | C14: Gas Furnace | D14: Heating DX | E14: Cooling DX | F14: Sources | G14: Note
A15: Pre 1978 | B15: 2008 | C15: Thermal Efficiency of 80% | D15: n/a | E15: EER 11.2 for <65 kBtu/h EER 10.3 for 65-135 kBtu/h | F15: 2005 Title 20 Appliance Efficiency Regulations, 2005 T24 Standards, Tables 112-A, 112-B
A16: 1978-1997
A17: 1998-2007
A18: 2008-2018 | B18: 2013 | C18: Thermal Efficiency of 80% | D18: n/a | E18: EER 11.2 for <65 kBtu/h EER 11.2 for 65–135 kBtu/h | F18: 2013 Title 20 Appliance Efficiency Regulations, 2013 T24 Tables 110.2 | G18: 2013 T24 Table 110.2-A (air-cooled packaged AC). Existing vintage is PSZAC + gas furnace, not HP.
A19: New Construction | B19: 2025 | C19: n/a | D19: Heating @ 47°F: <65 kBtu/h (AHRI 210/240): federal minimum HSPF2 / 10 CFR 430 65–135 kBtu/h: COP 3.40 (10 CFR 431 / T24 Table 110.2-B) Heating @ 17°F: COP 2.25 (Table 110.2-B) | E19: <65 kBtu/h packaged HP (10 CFR 430.32): SEER2 13.4 (pair to HSPF2 6.7) 65–135 kBtu/h: EER 11.0 + federal min IEER (Table 110.2-B) 135–240 kBtu/h: EER 10.6 + federal min IEER (MPR bin) ≥240 kBtu/h: EER 9.5 + federal min IEER | F19: T24 2025 Table 110.2-B; 10 CFR 431.97 (COP @ 47°F); 10 CFR 430.32 (HSPF2/SEER2 <65 kBtu/h); AHRI 340/360 (≥65) / AHRI 210/240 (<65)
C21: * Et = Combustion efficiency | D21: * Et = Thermal efficiency
A23: Fan power
A24: Vintage | B24: Approach | C24: System | D24: Total Static Pressure (TSP) (in w.c.) | E24: Fan Efficiency [ACM 2025] | F24: Motor Efficiency | G24: Fan Power Index (W/cfm) | H24: Data Source
A25: Existing | B25: PNNL 90.1-2011, TSP | C25: CAV, PSZ classrooms/admin (except MPR/cafeteria), design airflow < 7,437 cfm | D25: 2.5 | E25: 0.65 | F25: ASHRAE 90.1, 2004, Table 10.8 * | H25: Fan power formula: PNNL 20405, 2010, section 5.2.2.5 TSP and fan efficiency: PNNL 20405, 2010, Table 5.11, 90.1-04ac values Motor and drive efficiency: ASHRAE 90.1, 2004, Table 10.8 | I25: PNNL 20405, 2010, Table 5.11
C26: SZVAV, Admin/MPR Multipurpose Room / Cafeteria, VAV > 4,648 cfm | D26: 5.58
A27: Brake horsepower (bhp) = (Supply cfm × TSP in w.c.) / (6356 × fan efficiency)
A28: Fan power (w/cfm) = (bhp × 746) / ( supply cfm × motor efficiency )
A29: New Construction | B29: ACM 2025 | C29: SZHP (System 3b), CAV classrooms/admin, ≤5,000 cfm | D29: TSP = fan power × motor efficiency × fan efficiency × 6356 / 746 | E29: 0.65 | F29: 2025 ACM Table 12 ** | G29: 0.744 | H29: Fan power index: [ACM 2025, Table 13] Motor efficiency: [ACM 2025, Table 12]
C30: SZVAVHP (System 7b), MPR/cafeteria, >10,000 cfm | D30: TSP = fan power × motor efficiency × fan efficiency × 6356 / 746 | G30: 0.676
A32: * According to PNNL 20405 section 5.2.2.5, the full-load efficiency of the motor serving the fan is taken from ASHRAE 90.1, 2004, Table 10.8, based on motor nameplate and assuming enclosed motors operating at 1,800 rotations per minute (rpm) Motor nameplate size (bhp) = brake horsepower (bhp) × 1.1 ( using a 10% oversizing factor)
A33: ** The full‑load efficiency of the motor serving the fan is taken from ACM 2025 Table 12 based on the cfm of the fan. Brake horsepower (bhp) = (Supply cfm from sizing run × fan power in W/cfm) / 746. Note: Packaged SZHP. Same index as Hotel Small System 3b ≤5,000 cfm. Note: Single-zone VAV heat pump, not System 6. ACM System 7b >10,000 cfm = 0.676; >5,000–10,000 cfm = 0.720. PNNL row was VAV >4,648 cfm.
A34: Economizer / ERV | B34: Air-side economizer: not modeled. EnergyPlus Controller:OutdoorAir Economizer Control Type = NoEconomizer on existing PSZAC and NC SZHP units. ERV: not modeled. T24 §140.4(e) would require an air economizer when cooling capacity ≥ 54,000 Btu/h (with listed exceptions); CBECC Standard Design uses FixedDryBulb on units that meet that threshold. This prototype does not include economizers.
A36: Background Data [To be deleted prior to publication]

Sheet Thermostat
A1: ="Thermostat Setpoints - "&Prototype!A2 -> Thermostat Setpoints - SchoolHigh
A2: Setpoint | B2: CZ1 | C2: CZ2 | D2: CZ3 | E2: CZ4 | F2: CZ5 | G2: CZ6 | H2: CZ7 | I2: CZ8 | J2: CZ9 | K2: CZ10 | L2: CZ11 | M2: CZ12 | N2: CZ13 | O2: CZ14 | P2: CZ15 | Q2: CZ16 | R2: Source
A3: School Heating Setpoint (F) | B3: 70 | C3: 70 | D3: 70 | E3: 70 | F3: 70 | G3: 70 | H3: 70 | I3: 70 | J3: 70 | K3: 70 | L3: 70 | M3: 70 | N3: 70 | O3: 70 | P3: 70 | Q3: 70 | R3: T24 2022 - Appendix 5.4B
A4: School Heating Setback (F) | B4: 60 | C4: 60 | D4: 60 | E4: 60 | F4: 60 | G4: 60 | H4: 60 | I4: 60 | J4: 60 | K4: 60 | L4: 60 | M4: 60 | N4: 60 | O4: 60 | P4: 60 | Q4: 60
A5: School Cooling Setpoint (F) | B5: 75 | C5: 75 | D5: 75 | E5: 75 | F5: 75 | G5: 75 | H5: 75 | I5: 75 | J5: 75 | K5: 75 | L5: 75 | M5: 75 | N5: 75 | O5: 75 | P5: 75 | Q5: 75 | R5: T24 2022 - Appendix 5.4B
A6: School Cooling Setback (F) | B6: 85 | C6: 85 | D6: 85 | E6: 85 | F6: 85 | G6: 85 | H6: 85 | I6: 85 | J6: 85 | K6: 85 | L6: 85 | M6: 85 | N6: 85 | O6: 85 | P6: 85 | Q6: 85
A7: Kitchen Heating Setpoint (F) | B7: 70 | C7: 70 | D7: 70 | E7: 70 | F7: 70 | G7: 70 | H7: 70 | I7: 70 | J7: 70 | K7: 70 | L7: 70 | M7: 70 | N7: 70 | O7: 70 | P7: 70 | Q7: 70 | R7: T24 2022 - Appendix 5.4B (school kitchen occupied 70/75; not commercial restaurant 66–79)
A8: Kitchen Heating Setback (F) | B8: 60 | C8: 60 | D8: 60 | E8: 60 | F8: 60 | G8: 60 | H8: 60 | I8: 60 | J8: 60 | K8: 60 | L8: 60 | M8: 60 | N8: 60 | O8: 60 | P8: 60 | Q8: 60
A9: Kitchen Cooling Setpoint (F) | B9: 75 | C9: 75 | D9: 75 | E9: 75 | F9: 75 | G9: 75 | H9: 75 | I9: 75 | J9: 75 | K9: 75 | L9: 75 | M9: 75 | N9: 75 | O9: 75 | P9: 75 | Q9: 75
A10: Kitchen Cooling Setback (F) | B10: 85 | C10: 85 | D10: 85 | E10: 85 | F10: 85 | G10: 85 | H10: 85 | I10: 85 | J10: 85 | K10: 85 | L10: 85 | M10: 85 | N10: 85 | O10: 85 | P10: 85 | Q10: 85
A11: Restrooms Heating Setpoint (F) | B11: 60 | C11: 60 | D11: 60 | E11: 60 | F11: 60 | G11: 60 | H11: 60 | I11: 60 | J11: 60 | K11: 60 | L11: 60 | M11: 60 | N11: 60 | O11: 60 | P11: 60 | Q11: 60 | R11: PNNL 90.1 Primary School bathroom (HTGSETP_SCH_Setback / CLGSETP_SCH_Setup)
A12: Restrooms Heating Setback (F) | B12: 60 | C12: 60 | D12: 60 | E12: 60 | F12: 60 | G12: 60 | H12: 60 | I12: 60 | J12: 60 | K12: 60 | L12: 60 | M12: 60 | N12: 60 | O12: 60 | P12: 60 | Q12: 60
A13: Restrooms Cooling Setpoint (F) | B13: 80 | C13: 80 | D13: 80 | E13: 80 | F13: 80 | G13: 80 | H13: 80 | I13: 80 | J13: 80 | K13: 80 | L13: 80 | M13: 80 | N13: 80 | O13: 80 | P13: 80 | Q13: 80
A14: Restrooms Cooling Setback (F) | B14: 80 | C14: 80 | D14: 80 | E14: 80 | F14: 80 | G14: 80 | H14: 80 | I14: 80 | J14: 80 | K14: 80 | L14: 80 | M14: 80 | N14: 80 | O14: 80 | P14: 80 | Q14: 80
A15: Storage and Electrical/Mechanical (non-refrigerated) Heating Setpoint (F) | B15: 60 | C15: 60 | D15: 60 | E15: 60 | F15: 60 | G15: 60 | H15: 60 | I15: 60 | J15: 60 | K15: 60 | L15: 60 | M15: 60 | N15: 60 | O15: 60 | P15: 60 | Q15: 60 | R15: Engineering Judgment (semi-conditioned storage / electrical-mechanical)
A16: Storage and Electrical/Mechanical (non-refrigerated) Heating Setback (F) | B16: 60 | C16: 60 | D16: 60 | E16: 60 | F16: 60 | G16: 60 | H16: 60 | I16: 60 | J16: 60 | K16: 60 | L16: 60 | M16: 60 | N16: 60 | O16: 60 | P16: 60 | Q16: 60
A17: Storage and Electrical/Mechanical (non-refrigerated) Cooling Setpoint (F) | B17: 85 | C17: 85 | D17: 85 | E17: 85 | F17: 85 | G17: 85 | H17: 85 | I17: 85 | J17: 85 | K17: 85 | L17: 85 | M17: 85 | N17: 85 | O17: 85 | P17: 85 | Q17: 85
A18: Storage and Electrical/Mechanical (non-refrigerated) Cooling Setback (F) | B18: 85 | C18: 85 | D18: 85 | E18: 85 | F18: 85 | G18: 85 | H18: 85 | I18: 85 | J18: 85 | K18: 85 | L18: 85 | M18: 85 | N18: 85 | O18: 85 | P18: 85 | Q18: 85
A19: Refrigerated storage setpoint (F) | B19: 35 | C19: 35 | D19: 35 | E19: 35 | F19: 35 | G19: 35 | H19: 35 | I19: 35 | J19: 35 | K19: 35 | L19: 35 | M19: 35 | N19: 35 | O19: 35 | P19: 35 | Q19: 35 | R19: Engineering judgment, medium-temp cooler within T24 28–55°F
A20: Refrigerated storage setback (F) | B20: 35 | C20: 35 | D20: 35 | E20: 35 | F20: 35 | G20: 35 | H20: 35 | I20: 35 | J20: 35 | K20: 35 | L20: 35 | M20: 35 | N20: 35 | O20: 35 | P20: 35 | Q20: 35

Sheet Ventilation
A1: ="Outdoor Airflow Rate - "&Prototype!A2 -> Outdoor Airflow Rate - SchoolHigh
A2: =Zones!C2 -> Space Type [Primarily from: T24, 2022 Appendix 5.4A] - See Notes column | B2: Space/Thermal Zone | C2: Number of People | D2: Floor Area (ft²) | E2: cfm/person [T24, 2025, Equation 120.1-F and Table 120.1-A] | F2: cfm/ft² [T24, 2025, Equation 120.1-F and Table 120.1-A] | G2: Required exhaust rate-CFM/ft²- [T24, 2025, Table 120.1-B – minimum exhaust rates] | H2: Total cfm driven by people | I2: Total cfm driven by area | J2: Total cfm driven by exhaust | K2: Total cfm | L2: Notes
A3: =Zones!C3 -> Lounge, Breakroom, or Waiting Area | B3: =Zones!B3 -> ADMIN/MPR_BREAKROOM_ZN | C3: =Zones!K3 -> 18.9816 | D3: =Zones!H3 -> 575.2 | E3: 15 | F3: 0.15 | H3: =C3*E3 -> 284.724 | I3: =D3*F3 -> 86.28 | J3: =G3*D3 -> 0 | K3: =MAX(H3,I3,J3) -> 284.724
A4: =Zones!C4 -> Dining Area (Cafeteria/Fast Food) | B4: =Zones!B4 -> ADMIN/MPR_CAFETERIA ZNS 3_ZN | C4: =Zones!K4 -> 181.90227 | D4: =Zones!H4 -> 5512.19 | E4: 15 | F4: 0.15 | H4: =C4*E4 -> 2728.534 | I4: =D4*F4 -> 826.8285 | J4: =G4*D4 -> 0 | K4: =MAX(H4,I4,J4) -> 2728.534
A5: =Zones!C5 -> Convention, Conference, Multipurpose and Meeting Area | B5: =Zones!B5 -> ADMIN/MPR_CONFERENCE ROOM ZNS 3_ZN | C5: =Zones!K5 -> 55.26642 | D5: =Zones!H5 -> 1674.74 | E5: 15 | F5: 0.15 | H5: =C5*E5 -> 828.9963 | I5: =D5*F5 -> 251.211 | J5: =G5*D5 -> 0 | K5: =MAX(H5,I5,J5) -> 828.9963
A6: =Zones!C6 -> Corridor Area | B6: =Zones!B6 -> ADMIN/MPR_CORRIDOR_ZN | C6: =Zones!K6 -> 5.8076 | D6: =Zones!H6 -> 1161.52 | E6: 15 | F6: 0.15 | H6: =C6*E6 -> 87.114 | I6: =D6*F6 -> 174.228 | J6: =G6*D6 -> 0 | K6: =MAX(H6,I6,J6) -> 174.228
A7: =Zones!C7 -> Electrical, Mechanical, Telephone Rooms | B7: =Zones!B7 -> ADMIN/MPR_EMT_ZN | C7: =Zones!K7 -> 1.39105 | D7: =Zones!H7 -> 278.21 | E7: 15 | F7: 0.15 | H7: =C7*E7 -> 20.86575 | I7: =D7*F7 -> 41.7315 | J7: =G7*D7 -> 0 | K7: =MAX(H7,I7,J7) -> 41.7315
A8: =Zones!C8 -> Electrical, Mechanical, Telephone Rooms | B8: =Zones!B8 -> ADMIN/MPR_IDF ROOM_ZN | C8: =Zones!K8 -> 1.70115 | D8: =Zones!H8 -> 340.23 | E8: 15 | F8: 0.15 | H8: =C8*E8 -> 25.51725 | I8: =D8*F8 -> 51.0345 | J8: =G8*D8 -> 0 | K8: =MAX(H8,I8,J8) -> 51.0345
A9: =Zones!C9 -> Kitchen/Food Preparation Area | B9: =Zones!B9 -> ADMIN/MPR_KITCHEN_ZN | C9: =Zones!K9 -> 4.37175 | D9: =Zones!H9 -> 1457.25 | E9: 15 | F9: 0.15 | G9: 0.7 | H9: =C9*E9 -> 65.57625 | I9: =D9*F9 -> 218.5875 | J9: =G9*D9 -> 1020.075 | K9: =MAX(H9,I9,J9) -> 1020.075 | L9: Table 120.1-B commercial kitchen exhaust, 0.70 cfm/ft². This is the kitchen hood rate.
A10: =Zones!C10 -> Lobby, Main Entry | B10: =Zones!B10 -> ADMIN/MPR_LOBBY_ZN | C10: =Zones!K10 -> 40.96851 | D10: =Zones!H10 -> 1241.47 | E10: 15 | F10: 0.15 | H10: =C10*E10 -> 614.52765 | I10: =D10*F10 -> 186.2205 | J10: =G10*D10 -> 0 | K10: =MAX(H10,I10,J10) -> 614.52765
A11: =Zones!C11 -> Office Area (<250 square feet) | B11: =Zones!B11 -> ADMIN/MPR_OFFICE - LT 250 SF ZNS 6_ZN | C11: =Zones!K11 -> 5.24175 | D11: =Zones!H11 -> 1048.35 | E11: 15 | F11: 0.15 | H11: =C11*E11 -> 78.62625 | I11: =D11*F11 -> 157.2525 | J11: =G11*D11 -> 0 | K11: =MAX(H11,I11,J11) -> 157.2525
A12: =Zones!C12 -> Restrooms | B12: =Zones!B12 -> ADMIN/MPR_RESTROOM ZNS 3_ZN | C12: =Zones!K12 -> 4.50585 | D12: =Zones!H12 -> 901.17 | E12: 0 | F12: 0 | G12: 0.5 | H12: =C12*E12 -> 0 | I12: =D12*F12 -> 0 | J12: =G12*D12 -> 450.585 | K12: =MAX(H12,I12,J12) -> 450.585 | L12: Exhaust 0.50 cfm/ft² on every restroom, same as School K-8.
A13: =Zones!C13 -> Storage (General) | B13: =Zones!B13 -> ADMIN/MPR_STORAGE - GENERAL_ZN | C13: =Zones!K13 -> 6.23865 | D13: =Zones!H13 -> 1247.73 | E13: 15 | F13: 0.15 | H13: =C13*E13 -> 93.57975 | I13: =D13*F13 -> 187.1595 | J13: =G13*D13 -> 0 | K13: =MAX(H13,I13,J13) -> 187.1595
A14: =Zones!C14 -> Storage, Commercial/Industrial (Refrigerated) | B14: =Zones!B14 -> ADMIN/MPR_STORAGE - REFRIGERATED_ZN | C14: =Zones!K14 -> 0 | D14: =Zones!H14 -> 251.72 | E14: 0 | F14: 0 | H14: =C14*E14 -> 0 | I14: =D14*F14 -> 0 | J14: =G14*D14 -> 0 | K14: =MAX(H14,I14,J14) -> 0
A15: =Zones!C15 -> Theater Area (Performance) | B15: =Zones!B15 -> ADMIN/MPR_THEATER - PERFORMANCE_ZN | C15: =Zones!K15 -> 35.16348 | D15: =Zones!H15 -> 1065.56 | E15: 15 | F15: 0.15 | H15: =C15*E15 -> 527.4522 | I15: =D15*F15 -> 159.834 | J15: =G15*D15 -> 0 | K15: =MAX(H15,I15,J15) -> 527.4522
A16: =Zones!C16 -> Electrical, Mechanical, Telephone Rooms | B16: =Zones!B16 -> CLASSRM LAB_FLR 1_EMT-01_ZN | C16: =Zones!K16 -> 0.60505 | D16: =Zones!H16 -> 121.01 | E16: 15 | F16: 0.15 | H16: =C16*E16 -> 9.07575 | I16: =D16*F16 -> 18.1515 | J16: =G16*D16 -> 0 | K16: =MAX(H16,I16,J16) -> 18.1515
A17: =Zones!C17 -> Electrical, Mechanical, Telephone Rooms | B17: =Zones!B17 -> CLASSRM LAB_FLR 1_EMT-02_ZN | C17: =Zones!K17 -> 0.49005 | D17: =Zones!H17 -> 98.01 | E17: 15 | F17: 0.15 | H17: =C17*E17 -> 7.35075 | I17: =D17*F17 -> 14.7015 | J17: =G17*D17 -> 0 | K17: =MAX(H17,I17,J17) -> 14.7015
A18: =Zones!C18 -> Laboratory, Scientific | B18: =Zones!B18 -> CLASSRM LAB_FLR 1_LAB ZNS 2_ZN | C18: =Zones!K18 -> 51.3735 | D18: =Zones!H18 -> 2054.94 | E18: 15 | F18: 0.15 | G18: 1 | H18: =C18*E18 -> 770.6025 | I18: =D18*F18 -> 308.241 | J18: =G18*D18 -> 2054.94 | K18: =MAX(H18,I18,J18) -> 2054.94 | L18: Table 120.1-B educational science laboratories, 1.00 cfm/ft².
A19: =Zones!C19 -> Library (Reading Area) | B19: =Zones!B19 -> CLASSRM LAB_FLR 1_LIBRARY - READING AREA_ZN | C19: =Zones!K19 -> 11.9713 | D19: =Zones!H19 -> 1197.13 | E19: 15 | F19: 0.15 | H19: =C19*E19 -> 179.5695 | I19: =D19*F19 -> 179.5695 | J19: =G19*D19 -> 0 | K19: =MAX(H19,I19,J19) -> 179.5695
A20: =Zones!C20 -> Restrooms | B20: =Zones!B20 -> CLASSRM LAB_FLR 1_RESTROOM_ZN | C20: =Zones!K20 -> 2.81525 | D20: =Zones!H20 -> 563.05 | E20: 0 | F20: 0 | G20: 0.5 | H20: =C20*E20 -> 0 | I20: =D20*F20 -> 0 | J20: =G20*D20 -> 281.525 | K20: =MAX(H20,I20,J20) -> 281.525
A21: =Zones!C21 -> Storage (General) | B21: =Zones!B21 -> CLASSRM LAB_FLR 1_STORAGE - GENERAL_ZN | C21: =Zones!K21 -> 1.9042 | D21: =Zones!H21 -> 380.84 | E21: 15 | F21: 0.15 | H21: =C21*E21 -> 28.563 | I21: =D21*F21 -> 57.126 | J21: =G21*D21 -> 0 | K21: =MAX(H21,I21,J21) -> 57.126
A22: =Zones!C22 -> Classroom, Lecture, Training, Vocational Areas | B22: =Zones!B22 -> CLASSRM LAB_FLR 2_CLASSROOM_ZN | C22: =Zones!K22 -> 9.521 | D22: =Zones!H22 -> 380.84 | E22: 15 | F22: 0.15 | H22: =C22*E22 -> 142.815 | I22: =D22*F22 -> 57.126 | J22: =G22*D22 -> 0 | K22: =MAX(H22,I22,J22) -> 142.815
A23: =Zones!C23 -> Electrical, Mechanical, Telephone Rooms | B23: =Zones!B23 -> CLASSRM LAB_FLR 2_IDF ROOM_ZN | C23: =Zones!K23 -> 0.60505 | D23: =Zones!H23 -> 121.01 | E23: 15 | F23: 0.15 | H23: =C23*E23 -> 9.07575 | I23: =D23*F23 -> 18.1515 | J23: =G23*D23 -> 0 | K23: =MAX(H23,I23,J23) -> 18.1515
A24: =Zones!C24 -> Laboratory, Scientific | B24: =Zones!B24 -> CLASSRM LAB_FLR 2_LAB ZNS 3_ZN | C24: =Zones!K24 -> 81.3015 | D24: =Zones!H24 -> 3252.06 | E24: 15 | F24: 0.15 | G24: 1 | H24: =C24*E24 -> 1219.5225 | I24: =D24*F24 -> 487.809 | J24: =G24*D24 -> 3252.06 | K24: =MAX(H24,I24,J24) -> 3252.06
A25: =Zones!C25 -> Restrooms | B25: =Zones!B25 -> CLASSRM LAB_FLR 2_RESTROOM_ZN | C25: =Zones!K25 -> 2.81525 | D25: =Zones!H25 -> 563.05 | E25: 0 | F25: 0 | G25: 0.5 | H25: =C25*E25 -> 0 | I25: =D25*F25 -> 0 | J25: =G25*D25 -> 281.525 | K25: =MAX(H25,I25,J25) -> 281.525
A26: =Zones!C26 -> Storage (General) | B26: =Zones!B26 -> CLASSRM LAB_FLR 2_STORAGE - GENERAL_ZN | C26: =Zones!K26 -> 0.49005 | D26: =Zones!H26 -> 98.01 | E26: 15 | F26: 0.15 | H26: =C26*E26 -> 7.35075 | I26: =D26*F26 -> 14.7015 | J26: =G26*D26 -> 0 | K26: =MAX(H26,I26,J26) -> 14.7015
A27: =Zones!C27 -> Classroom, Lecture, Training, Vocational Areas | B27: =Zones!B27 -> CLASSRM N_FLR 1_CLASSROOM-01_ZN | C27: =Zones!K27 -> 25.04375 | D27: =Zones!H27 -> 1001.75 | E27: 15 | F27: 0.15 | H27: =C27*E27 -> 375.65625 | I27: =D27*F27 -> 150.2625 | J27: =G27*D27 -> 0 | K27: =MAX(H27,I27,J27) -> 375.65625
A28: =Zones!C28 -> Classroom, Lecture, Training, Vocational Areas | B28: =Zones!B28 -> CLASSRM N_FLR 1_CLASSROOM-02 ZNS 6_ZN | C28: =Zones!K28 -> 151.35075 | D28: =Zones!H28 -> 6054.03 | E28: 15 | F28: 0.15 | H28: =C28*E28 -> 2270.2613 | I28: =D28*F28 -> 908.1045 | J28: =G28*D28 -> 0 | K28: =MAX(H28,I28,J28) -> 2270.2613
A29: =Zones!C29 -> Office Area (<250 square feet) | B29: =Zones!B29 -> CLASSRM N_FLR 1_OFFICE - LT 250 SF_ZN | C29: =Zones!K29 -> 1.44065 | D29: =Zones!H29 -> 288.13 | E29: 15 | F29: 0.15 | H29: =C29*E29 -> 21.60975 | I29: =D29*F29 -> 43.2195 | J29: =G29*D29 -> 0 | K29: =MAX(H29,I29,J29) -> 43.2195
A30: =Zones!C30 -> Restrooms | B30: =Zones!B30 -> CLASSRM N_FLR 1_RESTROOM_ZN | C30: =Zones!K30 -> 2.6635 | D30: =Zones!H30 -> 532.7 | E30: 0 | F30: 0 | G30: 0.5 | H30: =C30*E30 -> 0 | I30: =D30*F30 -> 0 | J30: =G30*D30 -> 266.35 | K30: =MAX(H30,I30,J30) -> 266.35
A31: =Zones!C31 -> Classroom, Lecture, Training, Vocational Areas | B31: =Zones!B31 -> CLASSRM N_FLR 2_CLASSROOM-01 ZNS 6_ZN | C31: =Zones!K31 -> 151.35075 | D31: =Zones!H31 -> 6054.03 | E31: 15 | F31: 0.15 | H31: =C31*E31 -> 2270.2613 | I31: =D31*F31 -> 908.1045 | J31: =G31*D31 -> 0 | K31: =MAX(H31,I31,J31) -> 2270.2613
A32: =Zones!C32 -> Classroom, Lecture, Training, Vocational Areas | B32: =Zones!B32 -> CLASSRM N_FLR 2_CLASSROOM-02_ZN | C32: =Zones!K32 -> 25.04375 | D32: =Zones!H32 -> 1001.75 | E32: 15 | F32: 0.15 | H32: =C32*E32 -> 375.65625 | I32: =D32*F32 -> 150.2625 | J32: =G32*D32 -> 0 | K32: =MAX(H32,I32,J32) -> 375.65625
A33: =Zones!C33 -> Office Area (<250 square feet) | B33: =Zones!B33 -> CLASSRM N_FLR 2_OFFICE - LT 250 SF_ZN | C33: =Zones!K33 -> 1.44065 | D33: =Zones!H33 -> 288.13 | E33: 15 | F33: 0.15 | H33: =C33*E33 -> 21.60975 | I33: =D33*F33 -> 43.2195 | J33: =G33*D33 -> 0 | K33: =MAX(H33,I33,J33) -> 43.2195
A34: =Zones!C34 -> Restrooms | B34: =Zones!B34 -> CLASSRM N_FLR 2_RESTROOM_ZN | C34: =Zones!K34 -> 2.6635 | D34: =Zones!H34 -> 532.7 | E34: 0 | F34: 0 | G34: 0.5 | H34: =C34*E34 -> 0 | I34: =D34*F34 -> 0 | J34: =G34*D34 -> 266.35 | K34: =MAX(H34,I34,J34) -> 266.35
A35: =Zones!C35 -> Electrical, Mechanical, Telephone Rooms | B35: =Zones!B35 -> CLASSRM SHOP_EMT_ZN | C35: =Zones!K35 -> 0.85435 | D35: =Zones!H35 -> 170.87 | E35: 15 | F35: 0.15 | H35: =C35*E35 -> 12.81525 | I35: =D35*F35 -> 25.6305 | J35: =G35*D35 -> 0 | K35: =MAX(H35,I35,J35) -> 25.6305
A36: =Zones!C36 -> Electrical, Mechanical, Telephone Rooms | B36: =Zones!B36 -> CLASSRM SHOP_IDF ROOM_ZN | C36: =Zones!K36 -> 0.4274 | D36: =Zones!H36 -> 85.48 | E36: 15 | F36: 0.15 | H36: =C36*E36 -> 6.411 | I36: =D36*F36 -> 12.822 | J36: =G36*D36 -> 0 | K36: =MAX(H36,I36,J36) -> 12.822
A37: =Zones!C37 -> Restrooms | B37: =Zones!B37 -> CLASSRM SHOP_RESTROOM_ZN | C37: =Zones!K37 -> 1.33015 | D37: =Zones!H37 -> 266.03 | E37: 0 | F37: 0 | G37: 0.5 | H37: =C37*E37 -> 0 | I37: =D37*F37 -> 0 | J37: =G37*D37 -> 133.015 | K37: =MAX(H37,I37,J37) -> 133.015
A38: =Zones!C38 -> Wood/Metal Shop Classroom | B38: =Zones!B38 -> CLASSRM SHOP_SHOP-01 ZNS 4_ZN | C38: =Zones!K38 -> 54.9454 | D38: =Zones!H38 -> 5494.54 | E38: 15 | F38: 0.15 | G38: 0.5 | H38: =C38*E38 -> 824.181 | I38: =D38*F38 -> 824.181 | J38: =G38*D38 -> 2747.27 | K38: =MAX(H38,I38,J38) -> 2747.27 | L38: Table 120.1-B woodwork shop/classrooms, 0.50 cfm/ft².
A39: =Zones!C39 -> Wood/Metal Shop Classroom | B39: =Zones!B39 -> CLASSRM SHOP_SHOP-02_ZN | C39: =Zones!K39 -> 14.4014 | D39: =Zones!H39 -> 1440.14 | E39: 15 | F39: 0.15 | G39: 0.5 | H39: =C39*E39 -> 216.021 | I39: =D39*F39 -> 216.021 | J39: =G39*D39 -> 720.07 | K39: =MAX(H39,I39,J39) -> 720.07
A40: =Zones!C40 -> Storage (General) | B40: =Zones!B40 -> CLASSRM SHOP_STORAGE - GENERAL_ZN | C40: =Zones!K40 -> 5.919 | D40: =Zones!H40 -> 1183.8 | E40: 15 | F40: 0.15 | H40: =C40*E40 -> 88.785 | I40: =D40*F40 -> 177.57 | J40: =G40*D40 -> 0 | K40: =MAX(H40,I40,J40) -> 177.57
...

Sheet Water Heater
A1: ="Water Heater -"&Prototype!A2 -> Water Heater -SchoolHigh
A2: Vintage | B2: WH Type | C2: Efficiency | D2: Number of WH | E2: Tank Volume (gal) | F2: Tank Loss | H2: Note
A3: Existing | B3: Electric | C3: 0.98 | D3: 5 | E3: See plant climate-zone tables, Storage Volume (col F) | F3: See plant climate-zone tables, Standby Loss (col G) | G3: See climate-zone HPWH tables | H3: five various WH
A4: New Construction | B4: HPWH | C4: =$B$70 -> 4.3 | D4: 5 | E4: =E3 -> See plant climate-zone tables, Storage Volume (col F) | F4: =F3 -> See plant climate-zone tables, Standby Loss (col G) | G4: =G3 -> See climate-zone HPWH tables | H4: five various WH
A6: Peak Hot Water Consumption
A7: Space Name | B7: Baseline WH Type [T24, 2022, Appendix 5.4A , sheet: "2022 SpaceFuncData-Input"] | C7: Total Area (ft²) | D7: Number of People | E7: Hot Water Usage Specification (gal/hr per person) [T24, 2022, Appendix 5.4A , sheet: "2022 SpaceFuncData-Input"] | F7: Peak Hot Water Usage (gal/hr) | G7: Peak Hot Water Usage (gal/min)
A8: =Zones!B3 -> ADMIN/MPR_BREAKROOM_ZN | B8: HPWH | C8: =Zones!H3 -> 575.2 | D8: =Zones!K3 -> 18.9816 | E8: 0.09 | F8: =E8*D8 -> 1.708344 | G8: =F8/60 -> 0.0284724
A9: =Zones!B4 -> ADMIN/MPR_CAFETERIA ZNS 3_ZN | B9: HPWH | C9: =Zones!H4 -> 5512.19 | D9: =Zones!K4 -> 181.90227 | E9: 0.578 | F9: =E9*D9 -> 105.13951 | G9: =F9/60 -> 1.7523252
A10: =Zones!B5 -> ADMIN/MPR_CONFERENCE ROOM ZNS 3_ZN | B10: HPWH | C10: =Zones!H5 -> 1674.74 | D10: =Zones!K5 -> 55.26642 | E10: 0.09 | F10: =E10*D10 -> 4.9739778 | G10: =F10/60 -> 0.08289963
A11: =Zones!B6 -> ADMIN/MPR_CORRIDOR_ZN | B11: HPWH | C11: =Zones!H6 -> 1161.52 | D11: =Zones!K6 -> 5.8076 | E11: 0 | F11: =E11*D11 -> 0 | G11: =F11/60 -> 0
A12: =Zones!B7 -> ADMIN/MPR_EMT_ZN | B12: HPWH | C12: =Zones!H7 -> 278.21 | D12: =Zones!K7 -> 1.39105 | E12: 0.18 | F12: =E12*D12 -> 0.250389 | G12: =F12/60 -> 0.00417315
A13: =Zones!B8 -> ADMIN/MPR_IDF ROOM_ZN | B13: HPWH | C13: =Zones!H8 -> 340.23 | D13: =Zones!K8 -> 1.70115 | E13: 0.18 | F13: =E13*D13 -> 0.306207 | G13: =F13/60 -> 0.00510345
A14: =Zones!B9 -> ADMIN/MPR_KITCHEN_ZN | B14: HPWH | C14: =Zones!H9 -> 1457.25 | D14: =Zones!K9 -> 4.37175 | E14: 0.578 | F14: =E14*D14 -> 2.5268715 | G14: =F14/60 -> 0.042114525
A15: =Zones!B10 -> ADMIN/MPR_LOBBY_ZN | B15: HPWH | C15: =Zones!H10 -> 1241.47 | D15: =Zones!K10 -> 40.96851 | E15: 0.09 | F15: =E15*D15 -> 3.6871659 | G15: =F15/60 -> 0.061452765
A16: =Zones!B11 -> ADMIN/MPR_OFFICE - LT 250 SF ZNS 6_ZN | B16: HPWH | C16: =Zones!H11 -> 1048.35 | D16: =Zones!K11 -> 5.24175 | E16: 0.18 | F16: =E16*D16 -> 0.943515 | G16: =F16/60 -> 0.01572525
A17: =Zones!B12 -> ADMIN/MPR_RESTROOM ZNS 3_ZN | B17: HPWH | C17: =Zones!H12 -> 901.17 | D17: =Zones!K12 -> 4.50585 | E17: 0 | F17: =E17*D17 -> 0 | G17: =F17/60 -> 0
A18: =Zones!B13 -> ADMIN/MPR_STORAGE - GENERAL_ZN | B18: HPWH | C18: =Zones!H13 -> 1247.73 | D18: =Zones!K13 -> 6.23865 | E18: 0 | F18: =E18*D18 -> 0 | G18: =F18/60 -> 0
A19: =Zones!B14 -> ADMIN/MPR_STORAGE - REFRIGERATED_ZN | B19: HPWH | C19: =Zones!H14 -> 251.72 | D19: =Zones!K14 -> 0 | E19: 0.18 | F19: =E19*D19 -> 0 | G19: =F19/60 -> 0
... A49: =Zones!B44 -> ROOMS & STUDIOS ZN | B49: HPWH | C49: =Zones!H44 -> 4608.45 | D49: =Zones!K44 -> 46.0845 | E49: 0.18 | F49: =E49*D49 -> 8.29521 | G49: =F49/60 -> 0.1382535
A54: Plant peak hot water (gal/hr)
A55: Water Heater Name | B55: WH type | C55: Peak Hot Water Usage (gal/hr) | D55: Notes
A56: HPWH - Admin | B56: HPWH | C56: =MAX(SUMIF($B$8:$B$20,"*HPWH*",$F$8:$F$20),75) -> 122.7007 | D56: Minimum peak hot water usage is 75 gal/hr according to ACM 2025
A57: HPWH - North Classroom | B57: HPWH | C57: =MAX(SUMIF($B$32:$B$39,"*HPWH*",$F$32:$F$39),75) -> 75
A58: HPWH - Lab Classroom | B58: HPWH | C58: =MAX(SUMIF($B$21:$B$31,"*HPWH*",$F$21:$F$31),75) -> 75
A59: HPWH - Shop Classroom | B59: HPWH | C59: =MAX(SUMIF($B$40:$B$45,"*HPWH*",$F$40:$F$45),75) -> 75
A60: HPWH - Sports | B60: HPWH | C60: =MAX(SUMIF($B$46:$B$49,"*HPWH*",$F$46:$F$49),75) -> 75
A62: Design supply temperature (°F) | B62: 135 | C62: Title 24 2022 Reference Appendices, Appendix 5.4B
A63: Design supply temperature used in CZ tables (°F) | B63: 135 | C63: Title 24 2022 Reference Appendices, Appendix 5.4B
A64: WH system factor | B64: 0.6 | C64: 2025 ACM §5.9.2 Rated Capacity
A65: Water mass conversion (lb/gal) | B65: 8.2877 | C65: 2025 ACM §5.9.2 Rated Capacity
A66: Reheat multiplier | B66: 0.4 | C66: 2025 ACM §5.9.2 Storage Volume
A67: Commercial HPWH configuration | B67: Unitary storage HPWH (integrated) | C67: Distributed unitary storage HPWH; retain the High School prototype's 5 water heaters / 5 service-water loops.
A68: Selected commercial COPh | B68: 4.3 | C68: ENERGY STAR Certified Commercial Water Heaters, integrated commercial 119-gal CHP family COPh = 4.3.
A69: ENERGY STAR minimum commercial COPh | B69: 3 | C69: ENERGY STAR commercial electric heat pump water-heater criterion.
A70: Design COPh | B70: =B68 -> 4.3 | C70: Use commercial COPh directly. Residential UEF-to-EF-to-COP conversion removed.
A73: Climate Zone Water Heater Sizing and Loss Coefficients
A74: Water Heater name | B74: Climate Zone | C74: Minimum Monthly Mains Temp (°F) [T24 2022 - Appendix 5.4B] | D74: Heat Output (Btu/hr) [ACM, 2025, 5.9.2: Rated capacity section] | E74: WH Capacity (Btu/hr) [ACM, 2025, 5.9.2: Rated capacity section] | F74: Required Electric Input (Btu/hr) [WH Capacity ÷ commercial COPh] | G74: Storage Volume (gal) [prototype unitary-storage sizing bin] | H74: Standby Loss (%/hr) [derived from DEER HPWH UA = 4.37 Btu/h·°F] | J74: Off/On Cycle Loss Coefficient to Ambient Temp [DEER HPWH UA] | L74: Source / Method Note
A75: HPWH - Admin | B75: CZ01 | C75: 47.9 | D75: =$C$56*($B$63-C75)*$B$65 -> 88572.561 | E75: =D75*$B$64 -> 53143.536 | F75: =_xlfn.LET(_xlpm.x,_xlfn.XLOOKUP(E75,$C$159:$C$163,$C$159:$C$163,"",1),IF(_xlpm.x="",E75/$B$70,_xlpm.x/$B$70)) -> 12358.962 | G75: =_xlfn.LET(_xlpm.v,MAX(30,$C$56*$B$66),_xlpm.x,_xlfn.XLOOKUP(_xlpm.v,$A$159:$A$163,$A$159:$A$163,"",1),IF(_xlpm.x="",ROUNDUP(_xlpm.v,0),_xlpm.x)) -> 50 | H75: =IF(AND(ISNUMBER(J75),G75>0),J75/(0.0834*G75),NA()) -> 1.0479616 | I75: %/hr | J75: 4.37 | K75: Btu/h·°F | L75: Approach: distributed unitary storage HPWH. Retain one plant per existing service-water loop on this prototype (5 plants). Efficiency: commercial COPh = 4.3 from ENERGY STAR certified integrated commercial HPWH. Electric input = WH Capacity / COPh. Tank UA = 4.37 Btu/h·°F (DEER commercial HPWH). Standby Loss (%/hr) = UA / (0.0834 × Storage Volume).
A76: HPWH - Admin | B76: CZ02 | C76: 50.8 | D76: =$C$56*($B$63-C76)*$B$65 -> 85623.532 | E76: =D76*$B$64 -> 51374.119 | F76: =_xlfn.LET(_xlpm.x,_xlfn.XLOOKUP(E76,$C$159:$C$163,$C$159:$C$163,"",1),IF(_xlpm.x="",E76/$B$70,_xlpm.x/$B$70)) -> 11947.47 | G76: =_xlfn.LET(_xlpm.v,MAX(30,$C$56*$B$66),_xlpm.x,_xlfn.XLOOKUP(_xlpm.v,$A$159:$A$163,$A$159:$A$163,"",1),IF(_xlpm.x="",ROUNDUP(_xlpm.v,0),_xlpm.x)) -> 50 | H76: =IF(AND(ISNUMBER(J76),G76>0),J76/(0.0834*G76),NA()) -> 1.0479616 | I76: %/hr | J76: 4.37 | K76: Btu/h·°F
A77: HPWH - Admin | B77: CZ03 | C77: 52.2 | D77: =$C$56*($B$63-C77)*$B$65 -> 84199.863 | E77: =D77*$B$64 -> 50519.918 | F77: =_xlfn.LET(_xlpm.x,_xlfn.XLOOKUP(E77,$C$159:$C$163,$C$159:$C$163,"",1),IF(_xlpm.x="",E77/$B$70,_xlpm.x/$B$70)) -> 11748.818 | G77: =_xlfn.LET(_xlpm.v,MAX(30,$C$56*$B$66),_xlpm.x,_xlfn.XLOOKUP(_xlpm.v,$A$159:$A$163,$A$159:$A$163,"",1),IF(_xlpm.x="",ROUNDUP(_xlpm.v,0),_xlpm.x)) -> 50 | H77: =IF(AND(ISNUMBER(J77),G77>0),J77/(0.0834*G77),NA()) -> 1.0479616 | I77: %/hr | J77: 4.37 | K77: Btu/h·°F
...

Sheet Interior Lights
A1: ="Interior Lighting - "&Prototype!A2 -> Interior Lighting - SchoolHigh
A2: Space Type | B2: New Construction | E2: Existing
B3: Lighting density (W/ft²) | C3: Additional lighting power for porTable lighting (W/ft²) | D3: Source | E3: LPD (W/ft²) | F3: Additional LPD for PorTable Lighting (W/ft²) | G3: Source
A4: Lounge, Breakroom, or Waiting Area | B4: 0.55 | C4: 0.25 | D4: T24, 2025, Table 140.6 C (Area category method) | E4: 0.9 | F4: 0.25 | G4: T24, 2016, Table 140.6 C (Area category method)
A5: Dining Area (Cafeteria/Fast Food) | B5: 0.45 | E5: 1
A6: Convention, Conference, Multipurpose and Meeting Area | B6: 0.75 | C6: 0.25 | E6: 1.2 | F6: 0.2
A7: Corridor Area | B7: 0.4 | E7: 0.6
A8: Electrical, Mechanical, Telephone Rooms | B8: 0.4 | E8: 0.55
A9: Kitchen/Food Preparation Area | B9: 0.95 | E9: 1.2
A10: Restrooms | B10: 0.65 | E10: 0.6
A11: Lobby, Main Entry | B11: 0.7 | C11: 0.25 | E11: 0.95 | F11: 0.2
A12: Office Area (<250 square feet) | B12: 0.65 | C12: 0.2 | E12: 1 | F12: 0.2
A13: Storage (General) | B13: 0.4 | E13: 0.6
A14: Storage, Commercial/Industrial (Refrigerated) | B14: 0.4 | E14: 0.7
A15: Theater Area (Performance) | B15: 0.8 | E15: 1.4
A16: Laboratory, Scientific | B16: 0.9 | C16: 0.35 | E16: 1.4 | F16: 0.2
A17: Library (Reading Area) | B17: 0.8 | E17: 1.1
A18: Classroom, Lecture, Training, Vocational Areas | B18: 0.6 | E18: 1.2
A19: Wood/Metal Shop Classroom | B19: 0.6 | E19: 1.2
A20: Locker Room | B20: 0.45 | E20: 0.8
A21: Exercise/Fitness Center and Gymnasium Areas | B21: 0.5 | E21: 1
A22: Exercise/Fitness Center and Gymnasium Areas | B22: 0.5 | E22: 1

Sheet Ext Lighting
A1: ="Exterior Lighting - "&Prototype!A2 -> Exterior Lighting - SchoolHigh
A2: Motion Controlled Luminaires (W) | B2: Non-motion Controlled Luminaires (W) | C2: Total (W) | D2: Source
A3: =G15 -> 4040.6229 | B3: =G16 -> 7440.8933 | C3: =A3+B3 -> 11481.516 | D3: T24, 2022 & 2025 2019 Outdoor Lighting CASE report PNNL 90.1-2010 TSD
A7: ="Exterior Lighting" -> Exterior Lighting
A8: Items (Assume LZ2) | B8: Assumptions [2019 Outdoor Lighting CASE Report & PNNL 90.1-2010 TS] | D8: Unit | E8: Lighting Power Allowance [T24, 2025, Table 140.7-A & 140.7-B] | F8: Unit | G8: Exterior Lighting Power (W)
A9: IWA (Initial Wattage Allowance) | E9: 200 | F9: (W) | G9: =$E9 -> 200
A10: Parking area | B10: 400 ft² for every parking space 1 parking space per 360 ft² of gross building area | C10: =B28/360*400 -> 194243.31 | D10: (ft²) | E10: 0.019 | F10: (W/ft²) | G10: =E10*C10 -> 3690.6229
A11: Building Entrance | B11: Two required exits per building (5 buildings). Exterior classroom access | C11: 10 | D11: (count) | E11: 15 | F11: (W/ea) | G11: =E11*C11 -> 150
A12: Hardscape Ornamental Light | B12: Hardscape ornamental: 0.1 ft² per 1 ft² GFA, then 25% of that area | C12: =B28*0.1*0.25 -> 4370.4745 | D12: (ft²) | E12: 0.007 | F12: (W/ft²) | G12: =E12*C12 -> 30.593322
A13: Building façade | B13: 0.1 W per 1 ft² of facade area Façade Area = Perimeter × 0.25 × max ( height and 34) (34 ft is the max height that is lit) * The 0.25 factor assumes that only half of the perimeter walls are lit. -Formula ia developed based on the 2019 Outdoor Lighting CASE report | C13: =0.25*4*(B21*B22+C21*C22+D21*D22+E21*E22+F21*F22) -> 72103 | D13: (ft²) | E13: 0.1 | F13: (W/ft²) | G13: =E13*C13 -> 7210.3
