Workbook
Name nonparticipating_forecastzone_scale_factor: #REF!
Name nonparticipating_forecastzone_scale_factor: #REF!
Name nonparticipating_forecastzone_scale_factor: 'Energy Usage'!#REF!
Name Space_Function: Data!$A$2:$A$76

Sheet Notes
A1: Data Sources
A2: Dataset | B2: Dodge 2023
B3: CEUS 2022
B4: CBECS 2018
B5: ComStock 2023
A6: Prototype | B6: CEC prototype (CBECC 2022.3.1) | C6: https://bees.noresco.com/software2022.html
B7: PNNL prototype (90.1-2022) | C7: https://www.energycodes.gov/prototype-building-models#Commercial
B8: DEERprototype (June 2023) | C8: https://github.com/sound-data/DEER-Prototypes-EnergyPlus
A10: Codes | B10: Title 24, part 6 (1984, 2001, 2007, 2013, 2022, 2025)
B11: ASHRAE 90.1 (2022)
B12: CFR Title 10 (2010, 2024)
A13: Others | B13: 2022 Reduced infiltration CASE report | C13: https://title24stakeholders.com/wp-content/uploads/2020/10/2022-T24-Final-CASE-Report_Reduce-Infiltration.pdf
B14: 2019 Outdoor Lighting CASE Report | C14: https://title24stakeholders.com/wp-content/uploads/2016/10/T24-2019-CASE-Study-Results-Report-Outdoor-Sources_Final_with-Attachments.pdf
B15: PNNL 20405, 2010 | C15: https://www.pnnl.gov/main/publications/external/technical_reports/PNNL-20405.pdf
B16: 2024 CASE Report: A Comprehensive, High Efficiency Solution for Water Heating in Multifamily Buildings | C16: https://www.energy.ca.gov/sites/default/files/2024-06/CEC-500-2024-054.pdf
B17: 2022 CASE Report: Multifamily Domestic Hot Water Distribution | C17: https://title24stakeholders.com/wp-content/uploads/2020/09/2022_T24_Final-CASE-Report-MF-DHW-Dist.pdf
A18: Construction Rate
A31: Notes

Sheet Prototype
A1: NORESCO, Updated November 2025
A2: ApartmentMidRise
A3: Characteristic | B3: Value | C3: Data Sources
A4: Building Type | B4: Mid-Rise Apartment
A5: Building Category | B5: Nonresidential
A6: Vintages | B6: 4 Vintages: Pre-1978 , 1978-1997 ,1998-2007 , 2008-2018 New Construction (2019+) | C6: Based on the vintage bin analysis | D6: NonRes-Vintage bins-Draft Report-30Nov2023-Final.docx
A7: Shape | C7: CEC Prototype model TRC Multifamily Prototypes study (2019)
A8: Total Floor Area (ft2) | B8: =Zones!J40 -> 141013.76 | C8: CEC Prototype model TRC Multifamily Prototypes study (2019)
A9: Aspect Ratio | B9: =180/155 -> 1.1612903
A10: Number of Floors | B10: 5 above-ground floors plus one underground parking garage (180 ft x 155 ft)
A11: Roof type | B11: Flat roof
A12: WWR (above grade) | B12: South: 22.0%, East: 22.0%, North: 22.0%, West: 22.0% Total 22.0%
A13: Window dimensions | B13: 5 * 3
A14: Shading Geometry | B14: -
A15: Floor to floor height (feet) | B15: Residential: 10 Non-residential: 10 Parking: 15
A16: Floor to ceiling height (feet) | B16: Residential: 9 Non-residential: 10 Parking: 14
A17: Glazing sill height (feet) | B17: 3.1 ft (in first floor), 2.95 ft. (in upper floors)
A21: Above grade wall area (ft²) | B21: 42304.13
A22: Gross wall area (ft²) | B22: 51685.04
A23: Roof area (ft²) | B23: 27902.72
A24: Underground Gross Wall Area (ft²) | B24: =B22-B21 -> 9380.91

Sheet Zones
A1: ="Proposed Layout - "&Prototype!A2 -> Proposed Layout - ApartmentMidRise
A2: Space Type | B2: Space/Thermal Zone | C2: Res/NR | D2: Schedule Category | E2: No. of Dwelling Units | F2: Dwelling Unit Type | G2: Thermal Zone (HVAC Zone) | H2: Conditioned [Y/N] | I2: Area Fraction | J2: Area (ft²) | K2: Volume [ft³] | L2: Multipliers | M2: People | N2: People (Persons/1,000 ft²) [T24, 2025,Table 120.1-A] | P2: Spaces and Zoning layout | T2: Spaces and Zoning layout
A3: Convention, Conference, Multipurpose and Meeting Area | B3: F1 BUSINESS CENTER | C3: NR | D3: ResidentialCommon | E3: NA | F3: NA | G3: AHU1 | H3: Y | I3: =J3*L3/$J$40 -> 0.002553226 | J3: 360.04 | K3: 3600.53 | L3: 1 | M3: =N3*J3/1000 -> 24.003867 | N3: 66.67
A4: Corridor Area | B4: F1 CORRIDOR | C4: NR | D4: ResidentialCommon | E4: NA | F4: NA | G4: AHU2 | H4: Y | I4: =J4*L4/$J$40 -> 0.01361704 | J4: 1920.19 | K4: 19202.81 | L4: 1 | M4: =N4*J4/1000 -> 19.2019 | N4: 10
A5: Exercise/Fitness Center and Gymnasium Areas | B5: F1 FITNESS CENTER | C5: NR | D5: ResidentialCommon | E5: NA | F5: NA | G5: AHU3 | H5: Y | I5: =J5*L5/$J$40 -> 0.0063829941 | J5: 900.09 | K5: 9001.32 | L5: 1 | M5: =N5*J5/1000 -> 18.0018 | N5: 20
A6: Office Area (>250 square feet) | B6: F1 LEASING OFFICE | C6: NR | D6: ResidentialCommon | E6: NA | F6: NA | G6: AHU4 | H6: Y | I6: =J6*L6/$J$40 -> 0.0024467825 | J6: 345.03 | K6: 3450.51 | L6: 1 | M6: =N6*J6/1000 -> 3.4503 | N6: 10
A7: Lobby, Main Entry | B7: F1 LOUNGE | C7: NR | D7: ResidentialCommon | E7: NA | F7: NA | G7: AHU5 | H7: Y | I7: =J7*L7/$J$40 -> 0.007446791 | J7: 1050.1 | K7: 10501.54 | L7: 1 | M7: =N7*J7/1000 -> 70.04167 | N7: 66.7
A8: Electrical, Mechanical, Telephone Rooms | B8: F1 MECHANICAL ROOM | C8: NR | D8: ResidentialCommon | E8: NA | F8: NA | G8: AHU6 | H8: Y | I8: =J8*L8/$J$40 -> 0.0030638145 | J8: 432.04 | K8: 4320.63 | L8: 1 | M8: =N8*J8/1000 -> 1.29612 | N8: 3
A9: Retail Sales Area (Retail Merchandise Sales) | B9: F1 RETAIL N-NW | C9: NR | D9: Retail | E9: NA | F9: NA | G9: AHU7 | H9: Y | I9: =J9*L9/$J$40 -> 0.04244678 | J9: 5985.58 | K9: 59858.76 | L9: 1 | M9: =N9*J9/1000 -> 99.759667 | N9: 16.666667
A10: Retail Sales Area (Retail Merchandise Sales) | B10: F1 RETAIL NE | C10: NR | D10: Retail | E10: NA | F10: NA | G10: AHU8 | H10: Y | I10: =J10*L10/$J$40 -> 0.030638287 | J10: 4320.42 | K10: 43206.32 | L10: 1 | M10: =N10*J10/1000 -> 72.007 | N10: 16.666667
A11: Retail Sales Area (Retail Merchandise Sales) | B11: F1 RETAIL SE | C11: NR | D11: Retail | E11: NA | F11: NA | G11: AHU9 | H11: Y | I11: =J11*L11/$J$40 -> 0.020425524 | J11: 2880.28 | K11: 28804.22 | L11: 1 | M11: =N11*J11/1000 -> 48.004667 | N11: 16.666667
A12: Retail Sales Area (Retail Merchandise Sales) | B12: F1 RETAIL SW | C12: NR | D12: Retail | E12: NA | F12: NA | G12: AHU10 | H12: Y | I12: =J12*L12/$J$40 -> 0.03140424 | J12: 4428.43 | K12: 44286.48 | L12: 1 | M12: =N12*J12/1000 -> 73.807167 | N12: 16.666667
A13: High-Rise Residential Living Spaces | B13: F2-4 1-BED CORE EAST | C13: Res | D13: ResidentialLiving | E13: =L13 -> 3 | F13: 1-Bed Type | G13: AHU11 | H13: Y | I13: =J13*L13/$J$40 -> 0.030638287 | J13: 1440.14 | K13: 14402.11 | L13: 3 | M13: =N13*J13/1000 -> 7.2007 | N13: 5
A14: High-Rise Residential Living Spaces | B14: F2-4 1-BED CORE N | C14: Res | D14: ResidentialLiving | E14: =L14 -> 3 | F14: 1-Bed Type | G14: AHU12 | H14: Y | I14: =J14*L14/$J$40 -> 0.015319143 | J14: 720.07 | K14: 7201.05 | L14: 3 | M14: =N14*J14/1000 -> 3.60035 | N14: 5
A15: High-Rise Residential Living Spaces | B15: F2-4 1-BED CORE WEST | C15: Res | D15: ResidentialLiving | E15: =L15 -> 3 | F15: 1-Bed Type | G15: AHU13 | H15: Y | I15: =J15*L15/$J$40 -> 0.030638287 | J15: 1440.14 | K15: 14402.11 | L15: 3 | M15: =N15*J15/1000 -> 7.2007 | N15: 5
A16: High-Rise Residential Living Spaces | B16: F2-4 1-BED NORTH | C16: Res | D16: ResidentialLiving | E16: =L16 -> 3 | F16: 1-Bed Type | G16: AHU14 | H16: Y | I16: =J16*L16/$J$40 -> 0.079148872 | J16: 3720.36 | K16: 37205.45 | L16: 3 | M16: =N16*J16/1000 -> 18.6018 | N16: 5
A17: High-Rise Residential Living Spaces | B17: F2-4 2-BED CORE NE-NW | C17: Res | D17: ResidentialLiving | E17: =L17 -> 3 | F17: 2-Bed Type | G17: AHU15 | H17: Y | I17: =J17*L17/$J$40 -> 0.04595743 | J17: 2160.21 | K17: 21603.16 | L17: 3 | M17: =N17*J17/1000 -> 10.80105 | N17: 5
A18: High-Rise Residential Living Spaces | B18: F2-4 2-BED EAST | C18: Res | D18: ResidentialLiving | E18: =L18 -> 3 | F18: 2-Bed Type | G18: AHU16 | H18: Y | I18: =J18*L18/$J$40 -> 0.068936251 | J18: 3240.32 | K18: 32404.74 | L18: 3 | M18: =N18*J18/1000 -> 16.2016 | N18: 5
A19: High-Rise Residential Living Spaces | B19: F2-4 2-BED WEST | C19: Res | D19: ResidentialLiving | E19: =L19 -> 3 | F19: 2-Bed Type | G19: AHU17 | H19: Y | I19: =J19*L19/$J$40 -> 0.068936251 | J19: 3240.32 | K19: 32404.74 | L19: 3 | M19: =N19*J19/1000 -> 16.2016 | N19: 5
A20: High-Rise Residential Living Spaces | B20: F2-4 3-BED NE | C20: Res | D20: ResidentialLiving | E20: =L20 -> 3 | F20: 3-Bed Type | G20: AHU18 | H20: Y | I20: =J20*L20/$J$40 -> 0.030000051 | J20: 1410.14 | K20: 14102.06 | L20: 3 | M20: =N20*J20/1000 -> 7.0507 | N20: 5
A21: High-Rise Residential Living Spaces | B21: F2-4 3-BED NW | C21: Res | D21: ResidentialLiving | E21: =L21 -> 3 | F21: 3-Bed Type | G21: AHU19 | H21: Y | I21: =J21*L21/$J$40 -> 0.030000051 | J21: 1410.14 | K21: 14102.06 | L21: 3 | M21: =N21*J21/1000 -> 7.0507 | N21: 5
A22: Corridor Area | B22: F2-4 CORRIDOR | C22: NR | D22: ResidentialCommon | E22: NA | F22: NA | G22: AHU20 | H22: Y | I22: =J22*L22/$J$40 -> 0.054893579 | J22: 2580.25 | K22: 25803.78 | L22: 3 | M22: =N22*J22/1000 -> 25.8025 | N22: 10
A23: Laundry Area | B23: F2-4 LAUNDRY | C23: NR | D23: ResidentialCommon | E23: NA | F23: NA | G23: AHU21 | H23: Y | I23: =J23*L23/$J$40 -> 0.003829839 | J23: 180.02 | K23: 1800.26 | L23: 3 | M23: =N23*J23/1000 -> 1.8002 | N23: 10
A24: High-Rise Residential Living Spaces | B24: F2-4 STUDIO SE | C24: Res | D24: ResidentialLiving | E24: =L24 -> 3 | F24: 1-Bed Type | G24: AHU22 | H24: Y | I24: =J24*L24/$J$40 -> 0.011489304 | J24: 540.05 | K24: 5400.79 | L24: 3 | M24: =N24*J24/1000 -> 2.70025 | N24: 5
A25: High-Rise Residential Living Spaces | B25: F2-4 STUDIO SW | C25: Res | D25: ResidentialLiving | E25: =L25 -> 3 | F25: Studio Type | G25: AHU23 | H25: Y | I25: =J25*L25/$J$40 -> 0.011489304 | J25: 540.05 | K25: 5400.79 | L25: 3 | M25: =N25*J25/1000 -> 2.70025 | N25: 5
A26: High-Rise Residential Living Spaces | B26: F5 1-BED CORE EAST | C26: Res | D26: ResidentialLiving | E26: =L26 -> 1 | F26: 1-Bed Type | G26: AHU24 | H26: Y | I26: =J26*L26/$J$40 -> 0.010212762 | J26: 1440.14 | K26: 14402.11 | L26: 1 | M26: =N26*J26/1000 -> 7.2007 | N26: 5
A27: High-Rise Residential Living Spaces | B27: F5 1-BED CORE N | C27: Res | D27: ResidentialLiving | E27: =L27 -> 1 | F27: 1-Bed Type | G27: AHU25 | H27: Y | I27: =J27*L27/$J$40 -> 0.0051063811 | J27: 720.07 | K27: 7201.05 | L27: 1 | M27: =N27*J27/1000 -> 3.60035 | N27: 5
A28: High-Rise Residential Living Spaces | B28: F5 1-BED CORE WEST | C28: Res | D28: ResidentialLiving | E28: =L28 -> 1 | F28: 1-Bed Type | G28: AHU26 | H28: Y | I28: =J28*L28/$J$40 -> 0.010212762 | J28: 1440.14 | K28: 14402.11 | L28: 1 | M28: =N28*J28/1000 -> 7.2007 | N28: 5
A29: High-Rise Residential Living Spaces | B29: F5 1-BED NORTH | C29: Res | D29: ResidentialLiving | E29: =L29 -> 1 | F29: 1-Bed Type | G29: AHU27 | H29: Y | I29: =J29*L29/$J$40 -> 0.026382957 | J29: 3720.36 | K29: 37205.45 | L29: 1 | M29: =N29*J29/1000 -> 18.6018 | N29: 5
A30: High-Rise Residential Living Spaces | B30: F5 2-BED CORE NE-NW | C30: Res | D30: ResidentialLiving | E30: =L30 -> 1 | F30: 2-Bed Type | G30: AHU28 | H30: Y | I30: =J30*L30/$J$40 -> 0.015319143 | J30: 2160.21 | K30: 21603.16 | L30: 1 | M30: =N30*J30/1000 -> 10.80105 | N30: 5
A31: High-Rise Residential Living Spaces | B31: F5 2-BED EAST | C31: Res | D31: ResidentialLiving | E31: =L31 -> 1 | F31: 2-Bed Type | G31: AHU29 | H31: Y | I31: =J31*L31/$J$40 -> 0.02297875 | J31: 3240.32 | K31: 32404.74 | L31: 1 | M31: =N31*J31/1000 -> 16.2016 | N31: 5
A32: High-Rise Residential Living Spaces | B32: F5 2-BED WEST | C32: Res | D32: ResidentialLiving | E32: =L32 -> 1 | F32: 2-Bed Type | G32: AHU30 | H32: Y | I32: =J32*L32/$J$40 -> 0.02297875 | J32: 3240.32 | K32: 32404.74 | L32: 1 | M32: =N32*J32/1000 -> 16.2016 | N32: 5
A33: High-Rise Residential Living Spaces | B33: F5 3-BED NE | C33: Res | D33: ResidentialLiving | E33: =L33 -> 1 | F33: 3-Bed Type | G33: AHU31 | H33: Y | I33: =J33*L33/$J$40 -> 0.010000017 | J33: 1410.14 | K33: 14102.06 | L33: 1 | M33: =N33*J33/1000 -> 7.0507 | N33: 5
A34: High-Rise Residential Living Spaces | B34: F5 3-BED NW | C34: Res | D34: ResidentialLiving | E34: =L34 -> 1 | F34: 3-Bed Type | G34: AHU32 | H34: Y | I34: =J34*L34/$J$40 -> 0.010000017 | J34: 1410.14 | K34: 14102.06 | L34: 1 | M34: =N34*J34/1000 -> 7.0507 | N34: 5
A35: Corridor Area | B35: F5 CORRIDOR | C35: NR | D35: ResidentialCommon | E35: NA | F35: NA | G35: AHU33 | H35: Y | I35: =J35*L35/$J$40 -> 0.01829786 | J35: 2580.25 | K35: 25803.78 | L35: 1 | M35: =N35*J35/1000 -> 25.8025 | N35: 10
A36: Laundry Area | B36: F5 LAUNDRY | C36: NR | D36: ResidentialCommon | E36: NA | F36: NA | G36: AHU34 | H36: Y | I36: =J36*L36/$J$40 -> 0.001276613 | J36: 180.02 | K36: 1800.26 | L36: 1 | M36: =N36*J36/1000 -> 1.8002 | N36: 10
A37: High-Rise Residential Living Spaces | B37: F5 STUDIO SE | C37: Res | D37: ResidentialLiving | E37: =L37 -> 1 | F37: Studio Type | G37: AHU35 | H37: Y | I37: =J37*L37/$J$40 -> 0.0038297681 | J37: 540.05 | K37: 5400.79 | L37: 1 | M37: =N37*J37/1000 -> 2.70025 | N37: 5
A38: High-Rise Residential Living Spaces | B38: F5 STUDIO SW | C38: Res | D38: ResidentialLiving | E38: =L38 -> 1 | F38: Studio Type | G38: AHU36 | H38: Y | I38: =J38*L38/$J$40 -> 0.0038297681 | J38: 540.05 | K38: 5400.79 | L38: 1 | M38: =N38*J38/1000 -> 2.70025 | N38: 5
A39: Parking Garage Area (Parking Zone and Ramps) | B39: PARKING GARAGE | C39: NR | D39: ResidentialCommon | E39: NA | F39: NA | G39: none | H39: N | I39: =J39*L39/$J$40 -> 0.19787232 | J39: 27902.72 | K39: 390657.19 | L39: 1 | M39: =N39*J39/1000 -> 139.5136 | N39: 5
A40: Total (11 Space Types) | B40: Total (37 Spaces) | E40: Total (37 Dwelling Units) | F40: Total (4 Dwelling Unit Types) | G40: Total (37 Thermal Zones) | H40: Total (36 Conditioned Zones, 1 Unconditioned Zones) | I40: =SUM(I3:I39) -> 1 | J40: =SUMPRODUCT(J3:J39,L3:L39) -> 141013.76 | K40: =SUM(K3:K39) -> 1069356.5 | M40: =SUM(M3:M39) -> 822.91256
...

Sheet Envelope
A1: ="Envelope - "&Prototype!A2 -> Envelope - ApartmentMidRise
A2: Element | B2: Prototype | C2: Assembly Type | D2: Construction | E2: Thermal Properties | F2: Vintage | G2: Selected T24 | I2: Note | J2: CZ1 | K2: CZ2 | L2: CZ3 | M2: CZ4 | N2: CZ5 | O2: CZ6 | P2: CZ7 | Q2: CZ8 | R2: CZ9 | S2: CZ10 | T2: CZ11 | U2: CZ12 | V2: CZ13 | W2: CZ14 | X2: CZ15 | Y2: CZ16
A3: External Wall (F1) | B3: =Prototype!$A$2 -> ApartmentMidRise | C3: ExtWall_MassLight_Nonres | D3: 8-in cast-in-place concrete wall + insulation + air/water barrier + exterior cladding + gypsum board | E3: U-factor IP | F3: Pre 1978 | G3: N/A | I3: ASHRAE 90.1, 2022, Table A3.3.3.1, 3.5", R-0 | J3: 0.352 | K3: 0.352 | L3: 0.352 | M3: 0.352 | N3: 0.352 | O3: 0.352 | P3: 0.352 | Q3: 0.352 | R3: 0.352 | S3: 0.352 | T3: 0.352 | U3: 0.352 | V3: 0.352 | W3: 0.352 | X3: 0.352 | Y3: 0.352
F4: 1978-1997 | G4: 1986 | I4: Copied from High-rise office alternative requirements (Table 2-53W): Package A with heat capacity around 10 (Btu/F-ft²) | J4: 0.213 | K4: 0.227 | L4: 0.227 | M4: 0.217 | N4: 0.217 | O4: 0.256 | P4: 0.256 | Q4: 0.256 | R4: 0.256 | S4: 0.256 | T4: 0.238 | U4: 0.238 | V4: 0.238 | W4: 0.208 | X4: 0.208 | Y4: 0.213
F5: 1998-2007 | G5: 2001 | I5: Table 1-H | J5: 0.182 | K5: 0.182 | L5: 0.189 | M5: 0.189 | N5: 0.189 | O5: 0.189 | P5: 0.189 | Q5: 0.189 | R5: 0.189 | S5: 0.182 | T5: 0.182 | U5: 0.182 | V5: 0.182 | W5: 0.182 | X5: 0.182 | Y5: 0.182
F6: 2008-2018 | G6: 2013 | I6: Table 140.3-B | J6: 0.098 | K6: 0.062 | L6: 0.082 | M6: 0.062 | N6: 0.062 | O6: 0.098 | P6: 0.098 | Q6: 0.062 | R6: 0.062 | S6: 0.062 | T6: 0.062 | U6: 0.062 | V6: 0.062 | W6: 0.062 | X6: 0.062 | Y6: 0.062
F7: 2019+ | G7: 2025 | I7: Table 140.3-B (Nonres) | J7: 0.06 | K7: 0.055 | L7: 0.071 | M7: 0.055 | N7: 0.055 | O7: 0.06 | P7: 0.06 | Q7: 0.055 | R7: 0.055 | S7: 0.055 | T7: 0.055 | U7: 0.055 | V7: 0.055 | W7: 0.055 | X7: 0.055 | Y7: 0.055
A8: External Wall | B8: =Prototype!$A$2 -> ApartmentMidRise | C8: ExtWall_WoodFramed_Res | D8: Wood-frame walls + insulation + Gypsum board | E8: U-factor IP | F8: Pre 1978 | G8: N/A | I8: ASHRAE 90.1 Table A3.4.3.1, 3.5", R-0 | J8: 0.292 | K8: 0.292 | L8: 0.292 | M8: 0.292 | N8: 0.292 | O8: 0.292 | P8: 0.292 | Q8: 0.292 | R8: 0.292 | S8: 0.292 | T8: 0.292 | U8: 0.292 | V8: 0.292 | W8: 0.292 | X8: 0.292 | Y8: 0.292
F9: 1978-1997 | G9: 1986 | I9: Title 24 1984 Table 2-53 BB, wall density less than 25 | J9: 0.095 | K9: 0.095 | L9: 0.095 | M9: 0.095 | N9: 0.095 | O9: 0.095 | P9: 0.095 | Q9: 0.095 | R9: 0.095 | S9: 0.095 | T9: 0.095 | U9: 0.095 | V9: 0.095 | W9: 0.095 | X9: 0.095 | Y9: 0.095
F10: 1998-2007 | G10: 2001 | I10: TABLE 1-H | J10: 0.084 | K10: 0.084 | L10: 0.092 | M10: 0.092 | N10: 0.092 | O10: 0.092 | P10: 0.092 | Q10: 0.092 | R10: 0.092 | S10: 0.084 | T10: 0.084 | U10: 0.084 | V10: 0.084 | W10: 0.084 | X10: 0.084 | Y10: 0.084
F11: 2008-2018 | G11: 2013 | I11: TABLE 140.3-B | J11: 0.102 | K11: 0.059 | L11: 0.11 | M11: 0.059 | N11: 0.102 | O11: 0.11 | P11: 0.11 | Q11: 0.102 | R11: 0.059 | S11: 0.059 | T11: 0.059 | U11: 0.059 | V11: 0.059 | W11: 0.059 | X11: 0.042 | Y11: 0.059
F12: 2019+ | G12: 2025 | I12: TABLE 170.2-A ENVELOPE COMPONENT PACKAGE – Multifamily Standard Building Design Assuming - >1hr fire rating | J12: 0.051 | K12: 0.051 | L12: 0.051 | M12: 0.051 | N12: 0.051 | O12: 0.065 | P12: 0.065 | Q12: 0.051 | R12: 0.051 | S12: 0.051 | T12: 0.051 | U12: 0.051 | V12: 0.051 | W12: 0.051 | X12: 0.051 | Y12: 0.051
A13: Roof | B13: =Prototype!$A$2 -> ApartmentMidRise | C13: FlatRoof_WoodFramedAndOther_Res | D13: Roof membrane or shingles + roof insulation + wood decking/sheathing + wood framing | E13: U-factor IP | F13: Pre 1978 | G13: N/A | I13: Considering 30 years for roof/ insulation replacement. | J13: 0.037 | K13: 0.051 | L13: 0.051 | M13: 0.051 | N13: 0.051 | O13: 0.051 | P13: 0.051 | Q13: 0.051 | R13: 0.051 | S13: 0.051 | T13: 0.037 | U13: 0.037 | V13: 0.037 | W13: 0.037 | X13: 0.037 | Y13: 0.037
F14: 1978-1997 | G14: N/A | J14: 0.037 | K14: 0.051 | L14: 0.051 | M14: 0.051 | N14: 0.051 | O14: 0.051 | P14: 0.051 | Q14: 0.051 | R14: 0.051 | S14: 0.051 | T14: 0.037 | U14: 0.037 | V14: 0.037 | W14: 0.037 | X14: 0.037 | Y14: 0.037
F15: 1998-2007 | G15: 2001 | I15: TABLE 1-I | J15: 0.037 | K15: 0.037 | L15: 0.051 | M15: 0.051 | N15: 0.051 | O15: 0.051 | P15: 0.051 | Q15: 0.051 | R15: 0.051 | S15: 0.037 | T15: 0.037 | U15: 0.037 | V15: 0.037 | W15: 0.037 | X15: 0.037 | Y15: 0.037
F16: 2008-2018 | G16: 2013 | I16: TABLE 140.3-C | J16: 0.034 | K16: 0.028 | L16: 0.039 | M16: 0.028 | N16: 0.039 | O16: 0.039 | P16: 0.039 | Q16: 0.028 | R16: 0.028 | S16: 0.028 | T16: 0.028 | U16: 0.028 | V16: 0.028 | W16: 0.028 | X16: 0.028 | Y16: 0.028
F17: 2019+ | G17: 2025 | I17: TABLE 170.2-A ENVELOPE COMPONENT PACKAGE – Multifamily Standard Building Design | J17: 0.028 | K17: 0.028 | L17: 0.034 | M17: 0.028 | N17: 0.034 | O17: 0.034 | P17: 0.039 | Q17: 0.028 | R17: 0.028 | S17: 0.028 | T17: 0.028 | U17: 0.028 | V17: 0.028 | W17: 0.028 | X17: 0.028 | Y17: 0.028
A18: Windows_ Dwelling Units | B18: =Prototype!$A$2 -> ApartmentMidRise | C18: FixedAndOperableWindow_Res | D18: CBECS 2018 shows that ~58% of Large Hotels that were built before 2000 are single pane | E18: U factor | F18: Pre 1978 | G18: N/A | I18: ASHRAE Handbook of Fundamentals for single pane & T24, 2013 for double pane (58%-42%) | J18: =0.42*J21+0.58*((1-$C$56)*1.12+$C$56*1.23) -> 0.82725 | K18: =0.42*K21+0.58*((1-$C$56)*1.12+$C$56*1.23) -> 0.82725 | L18: =0.42*L21+0.58*((1-$C$56)*1.12+$C$56*1.23) -> 0.82725 | M18: =0.42*M21+0.58*((1-$C$56)*1.12+$C$56*1.23) -> 0.82725 | N18: =0.42*N21+0.58*((1-$C$56)*1.12+$C$56*1.23) -> 0.82725 | O18: =0.42*O21+0.58*((1-$C$56)*1.12+$C$56*1.23) -> 0.82725 | P18: =0.42*P21+0.58*((1-$C$56)*1.12+$C$56*1.23) -> 0.82725 | Q18: =0.42*Q21+0.58*((1-$C$56)*1.12+$C$56*1.23) -> 0.82725 | ... Y18: =0.42*Y21+0.58*((1-$C$56)*1.12+$C$56*1.23) -> 0.82725
F19: 1978-1997 | G19: N/A | J19: =0.42*J21+0.58*((1-$C$56)*1.12+$C$56*1.23) -> 0.82725 | K19: =0.42*K21+0.58*((1-$C$56)*1.12+$C$56*1.23) -> 0.82725 | L19: =0.42*L21+0.58*((1-$C$56)*1.12+$C$56*1.23) -> 0.82725 | M19: =0.42*M21+0.58*((1-$C$56)*1.12+$C$56*1.23) -> 0.82725 | N19: =0.42*N21+0.58*((1-$C$56)*1.12+$C$56*1.23) -> 0.82725 | O19: =0.42*O21+0.58*((1-$C$56)*1.12+$C$56*1.23) -> 0.82725 | P19: =0.42*P21+0.58*((1-$C$56)*1.12+$C$56*1.23) -> 0.82725 | Q19: =0.42*Q21+0.58*((1-$C$56)*1.12+$C$56*1.23) -> 0.82725 | ... Y19: =0.42*Y21+0.58*((1-$C$56)*1.12+$C$56*1.23) -> 0.82725
D20: Double pane | F20: 1998-2007 | G20: 2001 | I20: Table 1-I | J20: =(1-$C$56)*J75+$C$56*J95 -> 0.49 | K20: =(1-$C$56)*K75+$C$56*K95 -> 0.49 | L20: =(1-$C$56)*L75+$C$56*L95 -> 0.49 | M20: =(1-$C$56)*M75+$C$56*M95 -> 0.49 | N20: =(1-$C$56)*N75+$C$56*N95 -> 0.49 | O20: =(1-$C$56)*O75+$C$56*O95 -> 0.49 | P20: =(1-$C$56)*P75+$C$56*P95 -> 0.49 | Q20: =(1-$C$56)*Q75+$C$56*Q95 -> 0.49 | ... Y20: =(1-$C$56)*Y75+$C$56*Y95 -> 0.49
F21: 2008-2018 | G21: 2013 | I21: Table 140.3-C | J21: =(1-$C$56)*J76+$C$56*J96 -> 0.385 | K21: =(1-$C$56)*K76+$C$56*K96 -> 0.385 | L21: =(1-$C$56)*L76+$C$56*L96 -> 0.385 | M21: =(1-$C$56)*M76+$C$56*M96 -> 0.385 | N21: =(1-$C$56)*N76+$C$56*N96 -> 0.385 | O21: =(1-$C$56)*O76+$C$56*O96 -> 0.385 | P21: =(1-$C$56)*P76+$C$56*P96 -> 0.385 | Q21: =(1-$C$56)*Q76+$C$56*Q96 -> 0.385 | ... Y21: =(1-$C$56)*Y76+$C$56*Y96 -> 0.385
F22: 2019+ | G22: 2025 | I22: TABLE 170.2-A (High rise residential in multifamily section) | J22: =(1-$C$56)*J77+$C$56*J97 -> 0.325 | K22: =(1-$C$56)*K77+$C$56*K97 -> 0.34 | L22: =(1-$C$56)*L77+$C$56*L97 -> 0.325 | M22: =(1-$C$56)*M77+$C$56*M97 -> 0.325 | N22: =(1-$C$56)*N77+$C$56*N97 -> 0.325 | O22: =(1-$C$56)*O77+$C$56*O97 -> 0.37 | P22: =(1-$C$56)*P77+$C$56*P97 -> 0.37 | Q22: =(1-$C$56)*Q77+$C$56*Q97 -> 0.34 | ... Y22: =(1-$C$56)*Y77+$C$56*Y97 -> 0.325
D23: CBECS 2018 shows that ~58% of Large Hotels that were built before 2000 are single pane | E23: SHGC | F23: Pre 1978 | G23: N/A | I23: =I18 -> ASHRAE Handbook of Fundamentals for single pane & T24, 2013 for double pane (58%-42%) | J23: =0.42*J26+0.58*((1-$C$56)*0.79+$C$56*0.78) -> 0.5586 | K23: =0.42*K26+0.58*((1-$C$56)*0.79+$C$56*0.78) -> 0.5586 | L23: =0.42*L26+0.58*((1-$C$56)*0.79+$C$56*0.78) -> 0.5586 | M23: =0.42*M26+0.58*((1-$C$56)*0.79+$C$56*0.78) -> 0.5586 | N23: =0.42*N26+0.58*((1-$C$56)*0.79+$C$56*0.78) -> 0.5586 | O23: =0.42*O26+0.58*((1-$C$56)*0.79+$C$56*0.78) -> 0.5586 | P23: =0.42*P26+0.58*((1-$C$56)*0.79+$C$56*0.78) -> 0.5586 | Q23: =0.42*Q26+0.58*((1-$C$56)*0.79+$C$56*0.78) -> 0.5586 | ... Y23: =0.42*Y26+0.58*((1-$C$56)*0.79+$C$56*0.78) -> 0.5586
F24: 1978-1997 | G24: N/A | J24: =0.42*J26+0.58*((1-$C$56)*0.79+$C$56*0.78) -> 0.5586 | K24: =0.42*K26+0.58*((1-$C$56)*0.79+$C$56*0.78) -> 0.5586 | L24: =0.42*L26+0.58*((1-$C$56)*0.79+$C$56*0.78) -> 0.5586 | M24: =0.42*M26+0.58*((1-$C$56)*0.79+$C$56*0.78) -> 0.5586 | N24: =0.42*N26+0.58*((1-$C$56)*0.79+$C$56*0.78) -> 0.5586 | O24: =0.42*O26+0.58*((1-$C$56)*0.79+$C$56*0.78) -> 0.5586 | P24: =0.42*P26+0.58*((1-$C$56)*0.79+$C$56*0.78) -> 0.5586 | Q24: =0.42*Q26+0.58*((1-$C$56)*0.79+$C$56*0.78) -> 0.5586 | ... Y24: =0.42*Y26+0.58*((1-$C$56)*0.79+$C$56*0.78) -> 0.5586
D25: Double pane | F25: 1998-2007 | G25: 2001 | I25: TABLE 1-I (based on non north with WWR 30-40%) | J25: =J118 -> 0.3 | K25: =K118 -> 0.26 | L25: =L118 -> 0.26 | M25: =M118 -> 0.26 | N25: =N118 -> 0.26 | O25: =O118 -> 0.31 | P25: =P118 -> 0.31 | Q25: =Q118 -> 0.31 | ... Y25: =Y118 -> 0.3
F26: 2008-2018 | G26: 2013 | I26: Table 140.3-C | J26: =(1-$C$56)*J81+$C$56*J101 -> 0.2425 | K26: =(1-$C$56)*K81+$C$56*K101 -> 0.2425 | L26: =(1-$C$56)*L81+$C$56*L101 -> 0.2425 | M26: =(1-$C$56)*M81+$C$56*M101 -> 0.2425 | N26: =(1-$C$56)*N81+$C$56*N101 -> 0.2425 | O26: =(1-$C$56)*O81+$C$56*O101 -> 0.2425 | P26: =(1-$C$56)*P81+$C$56*P101 -> 0.2425 | Q26: =(1-$C$56)*Q81+$C$56*Q101 -> 0.2425 | ... Y26: =(1-$C$56)*Y81+$C$56*Y101 -> 0.2425
F27: 2019+ | G27: 2025 | I27: TABLE 170.2-A (High rise residential in multifamily section) Table 110.6-B: Climate zones 1, 3, 5 and 16 | J27: =(1-$C$56)*J82+$C$56*J102 -> 0.5275 | K27: =(1-$C$56)*K82+$C$56*K102 -> 0.2275 | L27: =(1-$C$56)*L82+$C$56*L102 -> 0.5275 | M27: =(1-$C$56)*M82+$C$56*M102 -> 0.2275 | N27: =(1-$C$56)*N82+$C$56*N102 -> 0.5275 | O27: =(1-$C$56)*O82+$C$56*O102 -> 0.2275 | P27: =(1-$C$56)*P82+$C$56*P102 -> 0.2275 | Q27: =(1-$C$56)*Q82+$C$56*Q102 -> 0.2275 | ... Y27: =(1-$C$56)*Y82+$C$56*Y102 -> 0.5275
A28: Windows_ Nonres (F1) | B28: =Prototype!$A$2 -> ApartmentMidRise | C28: FixedWindow_NonRes | D28: CBECS 2018 shows that ~58% of Large Hotels that were built before 2000 are single pane | E28: U factor | F28: Pre 1978 | G28: N/A | I28: =I18 -> ASHRAE Handbook of Fundamentals for single pane & T24, 2013 for double pane (58%-42%) | J28: =1.12*0.58+J$31*0.42 -> 0.8008 | K28: =1.12*0.58+K$31*0.42 -> 0.8008 | L28: =1.12*0.58+L$31*0.42 -> 0.8008 | M28: =1.12*0.58+M$31*0.42 -> 0.8008 | N28: =1.12*0.58+N$31*0.42 -> 0.8008 | O28: =1.12*0.58+O$31*0.42 -> 0.8008 | P28: =1.12*0.58+P$31*0.42 -> 0.8008 | Q28: =1.12*0.58+Q$31*0.42 -> 0.8008 | ... Y28: =1.12*0.58+Y$31*0.42 -> 0.8008
F29: 1978-1997 | G29: N/A | J29: =1.12*0.58+J$31*0.42 -> 0.8008 | K29: =1.12*0.58+K$31*0.42 -> 0.8008 | L29: =1.12*0.58+L$31*0.42 -> 0.8008 | M29: =1.12*0.58+M$31*0.42 -> 0.8008 | N29: =1.12*0.58+N$31*0.42 -> 0.8008 | O29: =1.12*0.58+O$31*0.42 -> 0.8008 | P29: =1.12*0.58+P$31*0.42 -> 0.8008 | Q29: =1.12*0.58+Q$31*0.42 -> 0.8008 | ... Y29: =1.12*0.58+Y$31*0.42 -> 0.8008
D30: Double pane | F30: 1998-2007 | G30: 2001 | I30: Table1-H | J30: 0.49 | K30: 0.49 | L30: 0.49 | M30: 0.49 | N30: 0.49 | O30: 0.49 | P30: 0.49 | Q30: 0.49 | R30: 0.49 | S30: 0.49 | T30: 0.49 | U30: 0.49 | V30: 0.49 | W30: 0.49 | X30: 0.49 | Y30: 0.49
F31: 2008-2018 | G31: 2013 | I31: Table 140.3-B | J31: =J86 -> 0.36 | K31: =K86 -> 0.36 | L31: =L86 -> 0.36 | M31: =M86 -> 0.36 | N31: =N86 -> 0.36 | O31: =O86 -> 0.36 | P31: =P86 -> 0.36 | Q31: =Q86 -> 0.36 | ... Y31: =Y86 -> 0.36
F32: 2019+ | G32: 2025 | I32: Table 140.3-B | J32: =J87 -> 0.36 | K32: =K87 -> 0.36 | L32: =L87 -> 0.36 | M32: =M87 -> 0.36 | N32: =N87 -> 0.36 | O32: =O87 -> 0.36 | P32: =P87 -> 0.36 | Q32: =Q87 -> 0.36 | ... Y32: =Y87 -> 0.36
D33: CBECS 2018 shows that ~58% of Large Hotels that were built before 2000 are single pane | E33: SHGC | F33: Pre 1978 | G33: N/A | I33: =I18 -> ASHRAE Handbook of Fundamentals for single pane & T24, 2013 for double pane (58%-42%) | J33: =0.79*0.58+J$36*0.42 -> 0.5632 | K33: =0.79*0.58+K$36*0.42 -> 0.5632 | L33: =0.79*0.58+L$36*0.42 -> 0.5632 | M33: =0.79*0.58+M$36*0.42 -> 0.5632 | N33: =0.79*0.58+N$36*0.42 -> 0.5632 | O33: =0.79*0.58+O$36*0.42 -> 0.5632 | P33: =0.79*0.58+P$36*0.42 -> 0.5632 | Q33: =0.79*0.58+Q$36*0.42 -> 0.5632 | ... Y33: =0.79*0.58+Y$36*0.42 -> 0.5632
F34: 1978-1997 | G34: N/A | J34: =0.79*0.58+J$36*0.42 -> 0.5632 | K34: =0.79*0.58+K$36*0.42 -> 0.5632 | L34: =0.79*0.58+L$36*0.42 -> 0.5632 | M34: =0.79*0.58+M$36*0.42 -> 0.5632 | N34: =0.79*0.58+N$36*0.42 -> 0.5632 | O34: =0.79*0.58+O$36*0.42 -> 0.5632 | P34: =0.79*0.58+P$36*0.42 -> 0.5632 | Q34: =0.79*0.58+Q$36*0.42 -> 0.5632 | ... Y34: =0.79*0.58+Y$36*0.42 -> 0.5632
D35: Double pane | F35: 1998-2007 | G35: 2001 | I35: Table 1-H (based on non north with WWR 30-40% ) | J35: =J122 -> 0.43 | K35: =K122 -> 0.31 | L35: =L122 -> 0.41 | M35: =M122 -> 0.41 | N35: =N122 -> 0.41 | O35: =O122 -> 0.34 | P35: =P122 -> 0.34 | Q35: =Q122 -> 0.34 | ... Y35: =Y122 -> 0.43
F36: 2008-2018 | G36: 2013 | I36: Table 140.3-B (100% fixed, 0% operable) | J36: =J91 -> 0.25 | K36: =K91 -> 0.25 | L36: =L91 -> 0.25 | M36: =M91 -> 0.25 | N36: =N91 -> 0.25 | O36: =O91 -> 0.25 | P36: =P91 -> 0.25 | Q36: =Q91 -> 0.25 | ... Y36: =Y91 -> 0.25
F37: 2019+ | G37: 2025 | I37: Table 140.3-B (100% fixed, 0% operable) | J37: =J92 -> 0.25 | K37: =K92 -> 0.25 | L37: =L92 -> 0.25 | M37: =M92 -> 0.25 | N37: =N92 -> 0.25 | O37: =O92 -> 0.25 | P37: =P92 -> 0.25 | Q37: =Q92 -> 0.25 | ... Y37: =Y92 -> 0.25
A38: * Based on PNNL scorecard assumption.
E41: Infiltration
F42: Vintage | G42: Source | H42: Res/NR | I42: ACH50
...

Sheet HVAC System
A1: ="HVAC system - "&Prototype!A2 -> HVAC system - ApartmentMidRise
A2: Vintage | B2: Space Type | C2: Heating | D2: Cooling | E2: Air Distribution | F2: Source
A3: Existing | B3: Residential Tenant and common | C3: SZAC (Furnace) | D3: SZAC (DX) | E3: CAV | F3: ResStock 2022 & T24 (2008, 2013)
B4: Non-Residential Tenant (Retail) | C4: PVAV (Gas Boiler & hot water reheat) | D4: PVAV (DX) | E4: VAV | F4: ResStock 2022 & T24 (2008, 2013)
A5: New Construction | B5: Residential Tenant and common | C5: SZHP (DX) | D5: SZHP (DX) | E5: CAV | F5: T24 2025
B6: Non-Residential Tenant (Retail) | C6: PVAV (Gas Boiler & hot water reheat) | D6: PVAV (DX) | E6: VAV
A7: *Based on NR ACM 2025 - Table 26
A10: Efficiency of HVAC system
A11: Vintage | B11: Upgrade/Installed year | C11: Heating | D11: Cooling | E11: Source
A12: Pre 1978 | B12: 2008 | C12: Efficiency 80% (78% AFUE) | D12: EER=9 (<65,000 Btu/h) RES SEER: 13 | E12: T24, 2008 / 10 CFR Part 430, §430.32(c)(2)
A13: 1978-1997
A14: 1998-2007
A15: 2008-2018 | B15: 2013 | C15: Efficiency 80% (78% AFUE) | D15: EER=9 (<65,000 Btu/h) RES: SEER 13 (<65k) | E15: CFR Energy 2010:Title 10- Table 9
A16: New Construction | B16: 2025 | C16: RES: HSPF2:7.5 For SZHPDF: Furnace efficiency: 80% | D16: SEER2: 14.3 | E16: Title 20, 2023 Table E-6
C17: Non-Res: For ≥65k and <135k Btu/h: 11.0 EER and 14.1 IEER | D17: 11.0 EER, 14.1 IEER Dual Fuel: 10.8 EER, 13.9 IEER | E17: Title 24, 2025 able 110.2 footnote a
A20: Fan power
A21: Vintage | B21: Approach | C21: System | D21: Total Static Pressure (TSP) (in w.c.) [PNNL 20405, 2010, Table 5.11] | E21: Fan Efficiency [ACM 2025] | F21: Fan Motor and Drive Efficiency [ACM 2025, Table 14] | G21: W/cfm [ACM 2025, Table 15] | H21: Data Source | I21: Note
A22: Existing | B22: PNNL TSP | C22: VAV System >4,648 cfm | D22: 5.58 | E22: 0.65 | F22: The full-load efficiency of the motor serving the fan- will be determined based on ACM 2025, Table 14 | H22: ACM 2025, PNNL 2010 TSD
C23: SZAC/SZHP | D23: 1.33 | E23: 0.65
A24: Break horse power (bhp)=(Supply cfm*TSP in w.c.)/(6356*Fan efficiency)
A25: Fan power (w/cfm) = bhp/motor and drive efficiency *746
A26: New Construction | B26: ACM 2025 | C26: VAV System >4,648 cfm | D26: =G26*F26*E26/746*6356 -> 5.0490582 | E26: 0.65 | F26: 0.9 | G26: 1.013 | H26: ACM 2025 - Table 14 | I26: 5,000 <cfm; ≤ 10,000 cfm
C27: SZAC | D27: =G27*F26*E26/746*6356 -> 3.8877249 | G27: 0.78
C28: SZHP | D28: =G28*F26*E26/746*6356 -> 3.5886692 | G28: 0.72
A31: Background Data [To be deleted prior to publication]

Sheet Thermostat
A1: ="Thermostat Setpoints - "&Prototype!A2 & ":ResidentialLiving & ResidentialCommon" -> Thermostat Setpoints - ApartmentMidRise :ResidentialLiving & ResidentialCommon
A2: Setpoint | B2: CZ1 | C2: CZ2 | D2: CZ3 | E2: CZ4 | F2: CZ5 | G2: CZ6 | H2: CZ7 | I2: CZ8 | J2: CZ9 | K2: CZ10 | L2: CZ11 | M2: CZ12 | N2: CZ13 | O2: CZ14 | P2: CZ15 | Q2: CZ16 | R2: Source
A3: School Heating Setpoint (F) | B3: 68 | C3: 68 | D3: 68 | E3: 68 | F3: 68 | G3: 68 | H3: 68 | I3: 68 | J3: 68 | K3: 68 | L3: 68 | M3: 68 | N3: 68 | O3: 68 | P3: 68 | Q3: 68 | R3: T24 2025 - Appendix 5.4B
A4: School Heating Setback (F) | B4: 60 | C4: 60 | D4: 60 | E4: 60 | F4: 60 | G4: 60 | H4: 60 | I4: 60 | J4: 60 | K4: 60 | L4: 60 | M4: 60 | N4: 60 | O4: 60 | P4: 60 | Q4: 60
A5: School Cooling Setpoint (F) | B5: 78 | C5: 78 | D5: 78 | E5: 78 | F5: 78 | G5: 78 | H5: 78 | I5: 78 | J5: 78 | K5: 78 | L5: 78 | M5: 78 | N5: 78 | O5: 78 | P5: 78 | Q5: 78 | R5: T24 2025 - Appendix 5.4B
A6: School Cooling Setback (F) | B6: 78 | C6: 78 | D6: 78 | E6: 78 | F6: 78 | G6: 78 | H6: 78 | I6: 78 | J6: 78 | K6: 78 | L6: 78 | M6: 78 | N6: 78 | O6: 78 | P6: 78 | Q6: 78
A8: ="Thermostat Setpoints - "&Prototype!A2 & ":Retail" -> Thermostat Setpoints - ApartmentMidRise :Retail
A9: Setpoint | B9: CZ1 | C9: CZ2 | D9: CZ3 | E9: CZ4 | F9: CZ5 | G9: CZ6 | H9: CZ7 | I9: CZ8 | J9: CZ9 | K9: CZ10 | L9: CZ11 | M9: CZ12 | N9: CZ13 | O9: CZ14 | P9: CZ15 | Q9: CZ16 | R9: Source
A10: Heating Setpoint (F) | B10: 70 | C10: 70 | D10: 70 | E10: 70 | F10: 70 | G10: 70 | H10: 70 | I10: 70 | J10: 70 | K10: 70 | L10: 70 | M10: 70 | N10: 70 | O10: 70 | P10: 70 | Q10: 70 | R10: T24 2022 - Appendix 5.4B
A11: Heating Setback (F) | B11: 60 | C11: 60 | D11: 60 | E11: 60 | F11: 60 | G11: 60 | H11: 60 | I11: 60 | J11: 60 | K11: 60 | L11: 60 | M11: 60 | N11: 60 | O11: 60 | P11: 60 | Q11: 60
A12: Cooling Setpoint (F) | B12: 75 | C12: 75 | D12: 75 | E12: 75 | F12: 75 | G12: 75 | H12: 75 | I12: 75 | J12: 75 | K12: 75 | L12: 75 | M12: 75 | N12: 75 | O12: 75 | P12: 75 | Q12: 75
A13: Cooling Setback (F) | B13: 85 | C13: 85 | D13: 85 | E13: 85 | F13: 85 | G13: 85 | H13: 85 | I13: 85 | J13: 85 | K13: 85 | L13: 85 | M13: 85 | N13: 85 | O13: 85 | P13: 85 | Q13: 85

Sheet Ventilation
A1: ="Outdoor Airflow Rate - "&Prototype!A2 -> Outdoor Airflow Rate - ApartmentMidRise
A2: Space Thermal Zone | B2: Number of People | C2: Floor Area (ft2) | D2: cfm/person (T24, 2025, Equation 120.1-F and Table 120.1-A) | E2: cfm (whole-dwelling continuous mechanical ventilation rate) Res: Equation 160.2-B | F2: cfm/ft² (T24, 2025, Equation 120.1-F and Table 120.1-A) | G2: Required Exhaust Rate-CFM/ft²- (T24, 2025, Table 120.1-B – Minimum Exhaust Rates) | H2: Total cfm Driven by People | I2: Total cfm Driven by Area | J2: Total cfm Driven by Exhaust | K2: Total cfm | L2: Note
A3: =Zones!B3 -> F1 BUSINESS CENTER | B3: =Zones!M3 -> 24.003867 | C3: =Zones!J3 -> 360.04 | D3: 15 | F3: 0.15 | H3: =B3*D3 -> 360.058 | I3: =C3*F3 -> 54.006 | K3: =MAX(H3:J3) -> 360.058
A4: =Zones!B4 -> F1 CORRIDOR | B4: =Zones!M4 -> 19.2019 | C4: =Zones!J4 -> 1920.19 | D4: 15 | F4: 0.15 | H4: =B4*D4 -> 288.0285 | I4: =C4*F4 -> 288.0285 | K4: =MAX(H4:J4) -> 288.0285
A5: =Zones!B5 -> F1 FITNESS CENTER | B5: =Zones!M5 -> 18.0018 | C5: =Zones!J5 -> 900.09 | D5: 15 | F5: 0.15 | H5: =B5*D5 -> 270.027 | I5: =C5*F5 -> 135.0135 | K5: =MAX(H5:J5) -> 270.027
A6: =Zones!B6 -> F1 LEASING OFFICE | B6: =Zones!M6 -> 3.4503 | C6: =Zones!J6 -> 345.03 | D6: 15 | F6: 0.15 | H6: =B6*D6 -> 51.7545 | I6: =C6*F6 -> 51.7545 | K6: =MAX(H6:J6) -> 51.7545
A7: =Zones!B7 -> F1 LOUNGE | B7: =Zones!M7 -> 70.04167 | C7: =Zones!J7 -> 1050.1 | D7: 15 | F7: 0.15 | H7: =B7*D7 -> 1050.625 | I7: =C7*F7 -> 157.515 | K7: =MAX(H7:J7) -> 1050.625
A8: =Zones!B8 -> F1 MECHANICAL ROOM | B8: =Zones!M8 -> 1.29612 | C8: =Zones!J8 -> 432.04 | D8: 15 | F8: 0.15 | H8: =B8*D8 -> 19.4418 | I8: =C8*F8 -> 64.806 | K8: =MAX(H8:J8) -> 64.806
A9: =Zones!B9 -> F1 RETAIL N-NW | B9: =Zones!M9 -> 99.759667 | C9: =Zones!J9 -> 5985.58 | D9: 15 | F9: 0.15 | H9: =B9*D9 -> 1496.395 | I9: =C9*F9 -> 897.837 | K9: =MAX(H9:J9) -> 1496.395
A10: =Zones!B10 -> F1 RETAIL NE | B10: =Zones!M10 -> 72.007 | C10: =Zones!J10 -> 4320.42 | D10: 15 | F10: 0.15 | H10: =B10*D10 -> 1080.105 | I10: =C10*F10 -> 648.063 | K10: =MAX(H10:J10) -> 1080.105
A11: =Zones!B11 -> F1 RETAIL SE | B11: =Zones!M11 -> 48.004667 | C11: =Zones!J11 -> 2880.28 | D11: 15 | F11: 0.15 | H11: =B11*D11 -> 720.07 | I11: =C11*F11 -> 432.042 | K11: =MAX(H11:J11) -> 720.07
A12: =Zones!B12 -> F1 RETAIL SW | B12: =Zones!M12 -> 73.807167 | C12: =Zones!J12 -> 4428.43 | D12: 15 | F12: 0.15 | H12: =B12*D12 -> 1107.1075 | I12: =C12*F12 -> 664.2645 | K12: =MAX(H12:J12) -> 1107.1075
A13: =Zones!B13 -> F2-4 1-BED CORE EAST | B13: =Zones!M13 -> 7.2007 | C13: =Zones!J13 -> 1440.14 | D13: NA | E13: =0.03*C13+7.5*(1+Zones!E13) -> 73.2042 | I13: =E13 -> 73.2042 | J13: =I13 -> 73.2042 | K13: =MAX(H13:J13) -> 73.2042 | L13: Balanced IAQ fan - only applies to new construction
A14: =Zones!B14 -> F2-4 1-BED CORE N | B14: =Zones!M14 -> 3.60035 | C14: =Zones!J14 -> 720.07 | D14: NA | E14: =0.03*C14+7.5*(1+Zones!E14) -> 51.6021 | I14: =E14 -> 51.6021 | J14: =I14 -> 51.6021 | K14: =MAX(H14:J14) -> 51.6021 | L14: Balanced IAQ fan - only applies to new construction
A15: =Zones!B15 -> F2-4 1-BED CORE WEST | B15: =Zones!M15 -> 7.2007 | C15: =Zones!J15 -> 1440.14 | D15: NA | E15: =0.03*C15+7.5*(1+Zones!E15) -> 73.2042 | I15: =E15 -> 73.2042 | J15: =I15 -> 73.2042 | K15: =MAX(H15:J15) -> 73.2042 | L15: Balanced IAQ fan - only applies to new construction
A16: =Zones!B16 -> F2-4 1-BED NORTH | B16: =Zones!M16 -> 18.6018 | C16: =Zones!J16 -> 3720.36 | D16: NA | E16: =0.03*C16+7.5*(1+Zones!E16) -> 141.6108 | I16: =E16 -> 141.6108 | J16: =I16 -> 141.6108 | K16: =MAX(H16:J16) -> 141.6108 | L16: Balanced IAQ fan - only applies to new construction
A17: =Zones!B17 -> F2-4 2-BED CORE NE-NW | B17: =Zones!M17 -> 10.80105 | C17: =Zones!J17 -> 2160.21 | D17: NA | E17: =0.03*C17+7.5*(1+Zones!E17) -> 94.8063 | I17: =E17 -> 94.8063 | J17: =I17 -> 94.8063 | K17: =MAX(H17:J17) -> 94.8063 | L17: Balanced IAQ fan - only applies to new construction
A18: =Zones!B18 -> F2-4 2-BED EAST | B18: =Zones!M18 -> 16.2016 | C18: =Zones!J18 -> 3240.32 | D18: NA | E18: =0.03*C18+7.5*(1+Zones!E18) -> 127.2096 | I18: =E18 -> 127.2096 | J18: =I18 -> 127.2096 | K18: =MAX(H18:J18) -> 127.2096 | L18: Balanced IAQ fan - only applies to new construction
A19: =Zones!B19 -> F2-4 2-BED WEST | B19: =Zones!M19 -> 16.2016 | C19: =Zones!J19 -> 3240.32 | D19: NA | E19: =0.03*C19+7.5*(1+Zones!E19) -> 127.2096 | I19: =E19 -> 127.2096 | J19: =I19 -> 127.2096 | K19: =MAX(H19:J19) -> 127.2096 | L19: Balanced IAQ fan - only applies to new construction
A20: =Zones!B20 -> F2-4 3-BED NE | B20: =Zones!M20 -> 7.0507 | C20: =Zones!J20 -> 1410.14 | D20: NA | E20: =0.03*C20+7.5*(1+Zones!E20) -> 72.3042 | I20: =E20 -> 72.3042 | J20: =I20 -> 72.3042 | K20: =MAX(H20:J20) -> 72.3042 | L20: Balanced IAQ fan - only applies to new construction
A21: =Zones!B21 -> F2-4 3-BED NW | B21: =Zones!M21 -> 7.0507 | C21: =Zones!J21 -> 1410.14 | D21: NA | E21: =0.03*C21+7.5*(1+Zones!E21) -> 72.3042 | I21: =E21 -> 72.3042 | J21: =I21 -> 72.3042 | K21: =MAX(H21:J21) -> 72.3042 | L21: Balanced IAQ fan - only applies to new construction
A22: =Zones!B22 -> F2-4 CORRIDOR | B22: =Zones!M22 -> 25.8025 | C22: =Zones!J22 -> 2580.25 | D22: 15 | F22: 0.15 | H22: =B22*D22 -> 387.0375 | I22: =C22*F22 -> 387.0375 | K22: =MAX(H22:J22) -> 387.0375
A23: =Zones!B23 -> F2-4 LAUNDRY | B23: =Zones!M23 -> 1.8002 | C23: =Zones!J23 -> 180.02 | D23: 15 | F23: 0.15 | H23: =B23*D23 -> 27.003 | I23: =C23*F23 -> 27.003 | K23: =MAX(H23:J23) -> 27.003
A24: =Zones!B24 -> F2-4 STUDIO SE | B24: =Zones!M24 -> 2.70025 | C24: =Zones!J24 -> 540.05 | D24: NA | E24: =0.03*C24+7.5*(1+Zones!E24) -> 46.2015 | I24: =E24 -> 46.2015 | J24: =I24 -> 46.2015 | K24: =MAX(H24:J24) -> 46.2015 | L24: Balanced IAQ fan - only applies to new construction
A25: =Zones!B25 -> F2-4 STUDIO SW | B25: =Zones!M25 -> 2.70025 | C25: =Zones!J25 -> 540.05 | D25: NA | E25: =0.03*C25+7.5*(1+Zones!E25) -> 46.2015 | I25: =E25 -> 46.2015 | J25: =I25 -> 46.2015 | K25: =MAX(H25:J25) -> 46.2015 | L25: Balanced IAQ fan - only applies to new construction
A26: =Zones!B26 -> F5 1-BED CORE EAST | B26: =Zones!M26 -> 7.2007 | C26: =Zones!J26 -> 1440.14 | D26: NA | E26: =0.03*C26+7.5*(1+Zones!E26) -> 58.2042 | I26: =E26 -> 58.2042 | J26: =I26 -> 58.2042 | K26: =MAX(H26:J26) -> 58.2042 | L26: Balanced IAQ fan - only applies to new construction
A27: =Zones!B27 -> F5 1-BED CORE N | B27: =Zones!M27 -> 3.60035 | C27: =Zones!J27 -> 720.07 | D27: NA | E27: =0.03*C27+7.5*(1+Zones!E27) -> 36.6021 | I27: =E27 -> 36.6021 | J27: =I27 -> 36.6021 | K27: =MAX(H27:J27) -> 36.6021 | L27: Balanced IAQ fan - only applies to new construction
A28: =Zones!B28 -> F5 1-BED CORE WEST | B28: =Zones!M28 -> 7.2007 | C28: =Zones!J28 -> 1440.14 | D28: NA | E28: =0.03*C28+7.5*(1+Zones!E28) -> 58.2042 | I28: =E28 -> 58.2042 | J28: =I28 -> 58.2042 | K28: =MAX(H28:J28) -> 58.2042 | L28: Balanced IAQ fan - only applies to new construction
A29: =Zones!B29 -> F5 1-BED NORTH | B29: =Zones!M29 -> 18.6018 | C29: =Zones!J29 -> 3720.36 | D29: NA | E29: =0.03*C29+7.5*(1+Zones!E29) -> 126.6108 | I29: =E29 -> 126.6108 | J29: =I29 -> 126.6108 | K29: =MAX(H29:J29) -> 126.6108 | L29: Balanced IAQ fan - only applies to new construction
A30: =Zones!B30 -> F5 2-BED CORE NE-NW | B30: =Zones!M30 -> 10.80105 | C30: =Zones!J30 -> 2160.21 | D30: NA | E30: =0.03*C30+7.5*(1+Zones!E30) -> 79.8063 | I30: =E30 -> 79.8063 | J30: =I30 -> 79.8063 | K30: =MAX(H30:J30) -> 79.8063 | L30: Balanced IAQ fan - only applies to new construction
A31: =Zones!B31 -> F5 2-BED EAST | B31: =Zones!M31 -> 16.2016 | C31: =Zones!J31 -> 3240.32 | D31: NA | E31: =0.03*C31+7.5*(1+Zones!E31) -> 112.2096 | I31: =E31 -> 112.2096 | J31: =I31 -> 112.2096 | K31: =MAX(H31:J31) -> 112.2096 | L31: Balanced IAQ fan - only applies to new construction
A32: =Zones!B32 -> F5 2-BED WEST | B32: =Zones!M32 -> 16.2016 | C32: =Zones!J32 -> 3240.32 | D32: NA | E32: =0.03*C32+7.5*(1+Zones!E32) -> 112.2096 | I32: =E32 -> 112.2096 | J32: =I32 -> 112.2096 | K32: =MAX(H32:J32) -> 112.2096 | L32: Balanced IAQ fan - only applies to new construction
A33: =Zones!B33 -> F5 3-BED NE | B33: =Zones!M33 -> 7.0507 | C33: =Zones!J33 -> 1410.14 | D33: NA | E33: =0.03*C33+7.5*(1+Zones!E33) -> 57.3042 | I33: =E33 -> 57.3042 | J33: =I33 -> 57.3042 | K33: =MAX(H33:J33) -> 57.3042 | L33: Balanced IAQ fan - only applies to new construction
A34: =Zones!B34 -> F5 3-BED NW | B34: =Zones!M34 -> 7.0507 | C34: =Zones!J34 -> 1410.14 | D34: NA | E34: =0.03*C34+7.5*(1+Zones!E34) -> 57.3042 | I34: =E34 -> 57.3042 | J34: =I34 -> 57.3042 | K34: =MAX(H34:J34) -> 57.3042 | L34: Balanced IAQ fan - only applies to new construction
A35: =Zones!B35 -> F5 CORRIDOR | B35: =Zones!M35 -> 25.8025 | C35: =Zones!J35 -> 2580.25 | D35: 15 | F35: 0.15 | H35: =B35*D35 -> 387.0375 | I35: =C35*F35 -> 387.0375 | K35: =MAX(H35:J35) -> 387.0375
A36: =Zones!B36 -> F5 LAUNDRY | B36: =Zones!M36 -> 1.8002 | C36: =Zones!J36 -> 180.02 | D36: 15 | F36: 0.15 | H36: =B36*D36 -> 27.003 | I36: =C36*F36 -> 27.003 | K36: =MAX(H36:J36) -> 27.003
A37: =Zones!B37 -> F5 STUDIO SE | B37: =Zones!M37 -> 2.70025 | C37: =Zones!J37 -> 540.05 | D37: NA | E37: =0.03*C37+7.5*(1+Zones!E37) -> 31.2015 | I37: =E37 -> 31.2015 | J37: =I37 -> 31.2015 | K37: =MAX(H37:J37) -> 31.2015 | L37: Balanced IAQ fan - only applies to new construction
A38: =Zones!B38 -> F5 STUDIO SW | B38: =Zones!M38 -> 2.70025 | C38: =Zones!J38 -> 540.05 | D38: NA | E38: =0.03*C38+7.5*(1+Zones!E38) -> 31.2015 | I38: =E38 -> 31.2015 | J38: =I38 -> 31.2015 | K38: =MAX(H38:J38) -> 31.2015 | L38: Balanced IAQ fan - only applies to new construction
A39: =Zones!B39 -> PARKING GARAGE | B39: =Zones!M39 -> 139.5136 | C39: =Zones!J39 -> 27902.72 | D39: 15 | F39: 0.15 | G39: 0.75 | H39: =B39*D39 -> 2092.704 | I39: =C39*F39 -> 4185.408 | J39: =C39*G39 -> 20927.04 | K39: =MAX(H39:J39) -> 20927.04

Sheet Water Heater
A1: ="Water Heater - "&Prototype!A2 -> Water Heater - ApartmentMidRise
A2: Vintage | B2: WH Type | C2: Efficiency | D2: Tank volume (gal) | E2: Tank loss | F2: Source | G2: Note
A3: Existing | B3: Gas | C3: 0.8 | D3: =D4 -> 46.320848 | E3: =G54 -> 816.13487 | F3: 2024 CASE Report: A Comprehensive, High Efficiency Solution for Water Heating in Multifamily Buildings 2022 CASE Report: Multifamily Domestic Hot Water Distribution Engineering Judgment
A4: New Construction | B4: Gas | C4: 0.8 | D4: =F52 -> 46.320848 | E4: =G52 -> 816.13487
A5: * Title 24 2025: §170.2(d)3: Gas Storage with recirculation and solar water heating system)
A8: Peak Hot Water Consumption
A9: Space | B9: Baseline WH Type [T24, 2022, Appendix 5.4A , sheet: "2022 SpaceFuncData-Input"] | C9: Total Area (ft²) | D9: Number of People | E9: Hot Water Usage Specification (gal/hr per person) [T24, 2022, Appendix 5.4A , sheet: "2022 SpaceFuncData-Input"] | F9: Peak Hot Water Usage (gal/hr) | G9: Peak Hot Water Usage (gal/min)
A10: =Zones!B3 -> F1 BUSINESS CENTER | B10: Gas | C10: =Zones!J3*Zones!L3 -> 360.04 | D10: =Zones!M3*Zones!L3 -> 24.003867 | E10: 0.18 | F10: =D10*E10 -> 4.320696 | G10: =F10/60 -> 0.0720116
A11: =Zones!B4 -> F1 CORRIDOR | B11: Gas | C11: =Zones!J4*Zones!L4 -> 1920.19 | D11: =Zones!M4* Zones!L4 -> 19.2019 | E11: 0.18 | F11: =D11*E11 -> 3.456342 | G11: =F11/60 -> 0.0576057
A12: =Zones!B5 -> F1 FITNESS CENTER | B12: Gas | C12: =Zones!J5*Zones!L5 -> 900.09 | D12: =Zones!M5* Zones!L5 -> 18.0018 | E12: 0.18 | F12: =D12*E12 -> 3.240324 | G12: =F12/60 -> 0.0540054
A13: =Zones!B6 -> F1 LEASING OFFICE | B13: Gas | C13: =Zones!J6*Zones!L6 -> 345.03 | D13: =Zones!M6* Zones!L6 -> 3.4503 | E13: 0.18 | F13: =D13*E13 -> 0.621054 | G13: =F13/60 -> 0.0103509
A14: =Zones!B7 -> F1 LOUNGE | B14: Gas | C14: =Zones!J7*Zones!L7 -> 1050.1 | D14: =Zones!M7* Zones!L7 -> 70.04167 | E14: 0.18 | F14: =D14*E14 -> 12.607501 | G14: =F14/60 -> 0.21012501
A15: =Zones!B8 -> F1 MECHANICAL ROOM | B15: Gas | C15: =Zones!J8*Zones!L8 -> 432.04 | D15: =Zones!M8* Zones!L8 -> 1.29612 | E15: 0.18 | F15: =D15*E15 -> 0.2333016 | G15: =F15/60 -> 0.00388836
A16: =Zones!B9 -> F1 RETAIL N-NW | B16: Gas | C16: =Zones!J9*Zones!L9 -> 5985.58 | D16: =Zones!M9* Zones!L9 -> 99.759667 | E16: 0.18 | F16: =D16*E16 -> 17.95674 | G16: =F16/60 -> 0.299279
A17: =Zones!B10 -> F1 RETAIL NE | B17: Gas | C17: =Zones!J10*Zones!L10 -> 4320.42 | D17: =Zones!M10* Zones!L10 -> 72.007 | E17: 0.18 | F17: =D17*E17 -> 12.96126 | G17: =F17/60 -> 0.216021
A18: =Zones!B11 -> F1 RETAIL SE | B18: Gas | C18: =Zones!J11*Zones!L11 -> 2880.28 | D18: =Zones!M11* Zones!L11 -> 48.004667 | E18: 0.18 | F18: =D18*E18 -> 8.64084 | G18: =F18/60 -> 0.144014
A19: =Zones!B12 -> F1 RETAIL SW | B19: Gas | C19: =Zones!J12*Zones!L12 -> 4428.43 | D19: =Zones!M12* Zones!L12 -> 73.807167 | E19: 0.18 | F19: =D19*E19 -> 13.28529 | G19: =F19/60 -> 0.2214215
A20: =Zones!B13 -> F2-4 1-BED CORE EAST | B20: Gas | C20: =Zones!J13*Zones!L13 -> 4320.42 | D20: =Zones!M13* Zones!L13 -> 21.6021 | E20: 0.18 | F20: =D20*E20 -> 3.888378 | G20: =F20/60 -> 0.0648063
A21: =Zones!B14 -> F2-4 1-BED CORE N | B21: Gas | C21: =Zones!J14*Zones!L14 -> 2160.21 | D21: =Zones!M14* Zones!L14 -> 10.80105 | E21: 0.18 | F21: =D21*E21 -> 1.944189 | G21: =F21/60 -> 0.03240315
A22: =Zones!B15 -> F2-4 1-BED CORE WEST | B22: Gas | C22: =Zones!J15*Zones!L15 -> 4320.42 | D22: =Zones!M15* Zones!L15 -> 21.6021 | E22: 0.18 | F22: =D22*E22 -> 3.888378 | G22: =F22/60 -> 0.0648063
... A28: =Zones!B21 -> F2-4 3-BED NW | B28: Gas | C28: =Zones!J21*Zones!L21 -> 4230.42 | D28: =Zones!M21* Zones!L21 -> 21.1521 | E28: 0 | F28: =D28*E28 -> 0 | G28: =F28/60 -> 0
A29: =Zones!B22 -> F2-4 CORRIDOR | C29: =Zones!J22*Zones!L22 -> 7740.75 | D29: =Zones!M22* Zones!L22 -> 77.4075 | E29: 0 | F29: =D29*E29 -> 0 | G29: =F29/60 -> 0
A30: =Zones!B23 -> F2-4 LAUNDRY | B30: Gas | C30: =Zones!J23*Zones!L23 -> 540.06 | D30: =Zones!M23* Zones!L23 -> 5.4006 | E30: 0 | F30: =D30*E30 -> 0 | G30: =F30/60 -> 0
A31: =Zones!B24 -> F2-4 STUDIO SE | B31: Gas | C31: =Zones!J24*Zones!L24 -> 1620.15 | D31: =Zones!M24* Zones!L24 -> 8.10075 | E31: 0.18 | F31: =D31*E31 -> 1.458135 | G31: =F31/60 -> 0.02430225
A32: =Zones!B25 -> F2-4 STUDIO SW | B32: Gas | C32: =Zones!J25*Zones!L25 -> 1620.15 | D32: =Zones!M25* Zones!L25 -> 8.10075 | E32: 0 | F32: =D32*E32 -> 0 | G32: =F32/60 -> 0
A33: =Zones!B26 -> F5 1-BED CORE EAST | B33: Gas | C33: =Zones!J26*Zones!L26 -> 1440.14 | D33: =Zones!M26* Zones!L26 -> 7.2007 | E33: 0 | F33: =D33*E33 -> 0 | G33: =F33/60 -> 0
A34: =Zones!B27 -> F5 1-BED CORE N | B34: Gas | C34: =Zones!J27*Zones!L27 -> 720.07 | D34: =Zones!M27* Zones!L27 -> 3.60035 | E34: 0 | F34: =D34*E34 -> 0 | G34: =F34/60 -> 0
A35: =Zones!B28 -> F5 1-BED CORE WEST | B35: Gas | C35: =Zones!J28*Zones!L28 -> 1440.14 | D35: =Zones!M28* Zones!L28 -> 7.2007 | E35: 0.18 | F35: =D35*E35 -> 1.296126 | G35: =F35/60 -> 0.0216021
A36: =Zones!B29 -> F5 1-BED NORTH | B36: Gas | C36: =Zones!J29*Zones!L29 -> 3720.36 | D36: =Zones!M29* Zones!L29 -> 18.6018 | E36: 0 | F36: =D36*E36 -> 0 | G36: =F36/60 -> 0
A37: =Zones!B30 -> F5 2-BED CORE NE-NW | B37: Gas | C37: =Zones!J30*Zones!L30 -> 2160.21 | D37: =Zones!M30* Zones!L30 -> 10.80105 | E37: 0 | F37: =D37*E37 -> 0 | G37: =F37/60 -> 0
A38: =Zones!B31 -> F5 2-BED EAST | B38: Gas | C38: =Zones!J31*Zones!L31 -> 3240.32 | D38: =Zones!M31* Zones!L31 -> 16.2016 | E38: 0 | F38: =D38*E38 -> 0 | G38: =F38/60 -> 0
A39: =Zones!B32 -> F5 2-BED WEST | B39: Gas | C39: =Zones!J32*Zones!L32 -> 3240.32 | D39: =Zones!M32* Zones!L32 -> 16.2016 | E39: 0.18 | F39: =D39*E39 -> 2.916288 | G39: =F39/60 -> 0.0486048
A40: =Zones!B33 -> F5 3-BED NE | B40: Gas | C40: =Zones!J33*Zones!L33 -> 1410.14 | D40: =Zones!M33* Zones!L33 -> 7.0507 | E40: 0 | F40: =D40*E40 -> 0 | G40: =F40/60 -> 0
A41: =Zones!B34 -> F5 3-BED NW | B41: Gas | C41: =Zones!J34*Zones!L34 -> 1410.14 | D41: =Zones!M34* Zones!L34 -> 7.0507 | E41: 0 | F41: =D41*E41 -> 0 | G41: =F41/60 -> 0
A42: =Zones!B35 -> F5 CORRIDOR | C42: =Zones!J35*Zones!L35 -> 2580.25 | D42: =Zones!M35* Zones!L35 -> 25.8025 | E42: 0 | F42: =D42*E42 -> 0 | G42: =F42/60 -> 0
A43: =Zones!B36 -> F5 LAUNDRY | B43: Gas | C43: =Zones!J36*Zones!L36 -> 180.02 | D43: =Zones!M36* Zones!L36 -> 1.8002 | E43: 0.18 | F43: =D43*E43 -> 0.324036 | G43: =F43/60 -> 0.0054006
A44: =Zones!B37 -> F5 STUDIO SE | B44: Gas | C44: =Zones!J37*Zones!L37 -> 540.05 | D44: =Zones!M37* Zones!L37 -> 2.70025 | E44: 0 | F44: =D44*E44 -> 0 | G44: =F44/60 -> 0
A45: =Zones!B38 -> F5 STUDIO SW | B45: Gas | C45: =Zones!J38*Zones!L38 -> 540.05 | D45: =Zones!M38* Zones!L38 -> 2.70025 | E45: 0 | F45: =D45*E45 -> 0 | G45: =F45/60 -> 0
A46: =Zones!B39 -> PARKING GARAGE | C46: =Zones!J39*Zones!L39 -> 27902.72 | D46: =Zones!M39* Zones!L39 -> 139.5136 | E46: 0 | F46: =D46*E46 -> 0 | G46: =F46/60 -> 0
A49: Water Heater Capacity, Tank Capacity, and Tank Loss
...

Sheet Interior Lights
A1: ="Interior Lighting - "&Prototype!A2 -> Interior Lighting - ApartmentMidRise
A2: Space Type | B2: New Construction | E2: Existing
B3: LPD (W/ft²) | C3: Additional LPD for Portable Lighting (W/ft²) | D3: Source | E3: LPD (W/ft²) | F3: Additional LPD for Portable Lighting (W/ft²) | G3: Source
A4: =Zones!A3 -> Convention, Conference, Multipurpose and Meeting Area | B4: 0.75 | C4: NA | D4: T24, 2025, Table 170.2-M (Area category method | E4: 0.85 | F4: NA | G4: T24, 2016, Table 140.6 C (Area category method)
A5: =Zones!A4 -> Corridor Area | B5: 0.4 | E5: 0.6
A6: =Zones!A5 -> Exercise/Fitness Center and Gymnasium Areas | B6: 0.5 | E6: 1
A7: =Zones!A6 -> Office Area (>250 square feet) | B7: 0.65 | E7: 0.65
A8: =Zones!A7 -> Lobby, Main Entry | B8: 0.7 | E8: 0.95
A9: =Zones!A8 -> Electrical, Mechanical, Telephone Rooms | B9: 0.4 | E9: 0.4
A10: =Zones!A9 -> Retail Sales Area (Retail Merchandise Sales) | B10: 0.95 | E10: 1
A11: =Zones!A23 -> Laundry Area | B11: 0.45 | E11: 0.45
A12: =Zones!A39 -> Parking Garage Area (Parking Zone and Ramps) | B12: 0.1 | E12: 0.14
A13: =Zones!A13 -> High-Rise Residential Living Spaces | B13: 0.79 | D13: CEC 2025 Single-Family ACM Appendix E - Table 2 and 8 | E13: 0.79 | G13: CEC 2016 Single-Family ACM Section 2.2.12
A15: *Annual kWh=100+0.1775×CFA (ft²)(Eq. 1)
A17: Background Data [To be deleted prior to publication]

Sheet Ext Lighting
A1: ="Exterior Lighting - "&Prototype!A2 -> Exterior Lighting - ApartmentMidRise
A2: Motion Controlled Luminaires (W) | B2: Non-motion Controlled Luminaires (W) | C2: Total (W) | D2: Source
A3: =G16 -> 2229.9691 | B3: =G17 -> 1367.7096 | C3: =B3+A3 -> 3597.6788 | D3: T24, 2022 & 2025 2019 Outdoor Lighting CASE report PNNL 90.1-2010 TSD
A8: ="Exterior Lighting - "& Prototype!A2 -> Exterior Lighting - ApartmentMidRise
A9: Items (Assume LZ2) | B9: Assumptions [2019 Outdoor Lighting CASE Report & PNNL 90.1-2010 TSD] | D9: Unit | E9: Lighting Power Allowance [T24, 2025, Table 140.7-A & 140.7-B] | F9: Unit | G9: Exterior Lighting Power (W)
A10: IWA (Initial Wage Allowance) | E10: 200 | F10: (W) | G10: =$E10 -> 200
A11: Parking area | B11: 400 ft² for every parking space 1.5 parking space per living unit for residential 1 parking space per 360 ft² of gross building area | C11: =400*B25*1.5+B23/B24/360*400 -> 84136.391 | D11: (ft²) | E11: 0.019 | F11: (W/ft²) | G11: =$E11*C11 -> 1598.5914
A12: Building Entrance | B12: 3 building entrance for NR (1 per 10,000 ft² footprint) | C12: 3 | D12: (count) | E12: 15 | F12: (W/ea) | G12: =E12*C12 -> 45
A13: Hardscape Ornamental Light | B13: 0.1 ft² per ft² of gross building area for hardscape ornamental light | C13: =B23*0.1 -> 14101.376 | D13: (ft²) | E13: 0.007 | F13: (W/ft²) | G13: =E13*C13 -> 98.709632
A14: Building façade | B14: 0.1 W per ft² of facade area Façade Area = Perimeter × 0.5 × 30 ft (30 ft is the max height that is lit) * The 0.5 factor assumes that only half of the perimeter walls are lit. -Formula ia developed based on the 2019 Outdoor Lighting CASE report | C14: =B22*0.5*30 -> 12690 | D14: (ft²) | E14: 0.1 | F14: (W/ft²) | G14: =E14*C14 -> 1269
A15: Sales canopy | B15: 0.1 ft2 per ft2 of gross bldg area | C15: =(B23/B24)*0.1 -> 2820.2752 | D15: (ft²) | E15: 0.137 | F15: (W/ft²) | G15: =E15*C15 -> 386.3777
A16: Motion controlled Luminaires | G16: =G11+G10+G15+G12 -> 2229.9691
A17: Non-motion-controlled Luminaires | G17: =G13+G14 -> 1367.7096
A18: Total | G18: =G16+G17 -> 3597.6788
A22: Perimeter (ft) | B22: =(180+155)*2+(88*2) -> 846
A23: Total floor area (ft²) | B23: =Zones!J40 -> 141013.76
A24: Floors (above floor) | B24: 5
A25: Number of dwelling units | B25: 88
A28: Background Data [To be deleted prior to publication]
A31: Existing Prototypes:
A32: Exterior lighting load (W)
A33: PNNL 90.1 2022, San Diego | B33: CPUC 2024
A34: 9571 | B34: No
A39: T24, part6, 2025, 130.2(c)3

Sheet Equipment
A1: ="Equipment - "&Prototype!A2 -> Equipment - ApartmentMidRise
A2: Vintage | B2: Space Type | C2: Plug load Power Density (W/ft2) | D2: Source
A3: New Construction/Existing | B3: =Zones!A3 -> Convention, Conference, Multipurpose and Meeting Area | C3: 1 | D3: Plug load and schedules project with CEC, 2025
B4: =Zones!A4 -> Corridor Area | C4: 0
B5: =Zones!A5 -> Exercise/Fitness Center and Gymnasium Areas | C5: 0.5
B6: =Zones!A6 -> Office Area (>250 square feet) | C6: 1.5
B7: =Zones!A7 -> Lobby, Main Entry | C7: 0.5
B8: =Zones!A8 -> Electrical, Mechanical, Telephone Rooms | C8: 3
B9: =Zones!A9 -> Retail Sales Area (Retail Merchandise Sales) | C9: 0.7
B10: =Zones!A23 -> Laundry Area | C10: 3
B11: =Zones!A39 -> Parking Garage Area (Parking Zone and Ramps) | C11: 0
B12: =Zones!A34 -> High-Rise Residential Living Spaces | C12: 0.5 | D12: Plug load and schedules project with CBECC-COM, 2019
A16: Elevator
A17: Vintages | B17: No of Elevator | C17: Design Load (W) | D17: Source
A18: New Construction and Existing | B18: =ROUND((Prototype!B8*0.7/50000)+ROUND(5/2,0),0) -> 5 | C18: 4360.9 | D18: Design Load based on PNNL ASHRAE 90.1 2022 MidRise Apartment prototype --- per T24 2025 §120.6 (f)
A21: Assumptions for elevators:
A22: One elevator for approximately 50,000 ft² in use. | F22: https://buildingandinteriors.com/find-the-magic-number-elevators-per-building/
A23: For every two floors or two and a half floors, one more elevator was added.
A24: An in-use rate of 70% for the floor area was assumed, based on engineering judgment.
A25: Calculated number of Elevators: | C25: =ROUND((Prototype!B8*0.7/50000)+ROUND(5/2,0),0) -> 5 | D25: Same as PNNL assumptions
A26: Calculate Elevator load (kw)based on ACM 2022: | C26: =C25*C27 -> 50 | D26: 76 kW is PNNL ASHRE 90.1 2019 elevator load | F26: =4360.9/1000 -> 4.3609
A27: ACM 2022 suggestion for elevator load (kW): | C27: 10
A28: Elevator load will be defined as exterior load not equipment load (Same as PNNL ASHRAE 90.1 Large Hotel prototype).

Sheet Schedules
A1: ="Schedules - "&Prototype!A2 -> Schedules - ApartmentMidRise
A2: Zone | B2: Schedule Category | C2: Schedule | D2: Source | E2: Day | F2: Hour
F3: 1 | G3: 2 | H3: 3 | I3: 4 | J3: 5 | K3: 6 | L3: 7 | M3: 8 | N3: 9 | O3: 10 | P3: 11 | Q3: 12 | R3: 13 | S3: 14 | T3: 15 | U3: 16 | V3: 17 | W3: 18 | X3: 19 | Y3: 20 | Z3: 21 | AA3: 22 | AB3: 23 | AC3: 24
A4: Living Area | B4: ResidentialLiving | C4: Occupancy | D4: T24 2022 - Appendix 5.4B [ResidentialLiving] | E4: Weekday | F4: 0.9 | G4: 0.9 | H4: 0.9 | I4: 0.9 | J4: 0.9 | K4: 0.9 | L4: 0.7 | M4: 0.4 | N4: 0.4 | O4: 0.2 | P4: 0.2 | Q4: 0.2 | R4: 0.2 | S4: 0.2 | T4: 0.2 | U4: 0.3 | V4: 0.5 | W4: 0.5 | X4: 0.5 | Y4: 0.7 | Z4: 0.7 | AA4: 0.8 | AB4: 0.9 | AC4: 0.9
E5: Saturday | F5: 0.9 | G5: 0.9 | H5: 0.9 | I5: 0.9 | J5: 0.9 | K5: 0.9 | L5: 0.7 | M5: 0.4 | N5: 0.4 | O5: 0.2 | P5: 0.2 | Q5: 0.2 | R5: 0.2 | S5: 0.2 | T5: 0.2 | U5: 0.3 | V5: 0.5 | W5: 0.5 | X5: 0.5 | Y5: 0.7 | Z5: 0.7 | AA5: 0.8 | AB5: 0.9 | AC5: 0.9
E6: Sunday | F6: 0.9 | G6: 0.9 | H6: 0.9 | I6: 0.9 | J6: 0.9 | K6: 0.9 | L6: 0.7 | M6: 0.4 | N6: 0.4 | O6: 0.2 | P6: 0.2 | Q6: 0.2 | R6: 0.2 | S6: 0.2 | T6: 0.2 | U6: 0.3 | V6: 0.5 | W6: 0.5 | X6: 0.5 | Y6: 0.7 | Z6: 0.7 | AA6: 0.8 | AB6: 0.9 | AC6: 0.9
A7: Living Area | B7: =B4 -> ResidentialLiving | C7: Lights | D7: T24 2022 - Appendix 5.4B [ResidentialLiving] | E7: Weekday | F7: 0.1 | G7: 0.1 | H7: 0.1 | I7: 0.1 | J7: 0.1 | K7: 0.3 | L7: 0.45 | M7: 0.45 | N7: 0.45 | O7: 0.45 | P7: 0.3 | Q7: 0.3 | R7: 0.3 | S7: 0.3 | T7: 0.3 | U7: 0.3 | V7: 0.3 | W7: 0.3 | X7: 0.6 | Y7: 0.8 | Z7: 0.9 | AA7: 0.8 | AB7: 0.6 | AC7: 0.3
E8: Saturday | F8: 0.1 | G8: 0.1 | H8: 0.1 | I8: 0.1 | J8: 0.1 | K8: 0.3 | L8: 0.45 | M8: 0.45 | N8: 0.45 | O8: 0.45 | P8: 0.3 | Q8: 0.3 | R8: 0.3 | S8: 0.3 | T8: 0.3 | U8: 0.3 | V8: 0.3 | W8: 0.3 | X8: 0.6 | Y8: 0.8 | Z8: 0.9 | AA8: 0.8 | AB8: 0.6 | AC8: 0.3
E9: Sunday | F9: 0.1 | G9: 0.1 | H9: 0.1 | I9: 0.1 | J9: 0.1 | K9: 0.3 | L9: 0.45 | M9: 0.45 | N9: 0.45 | O9: 0.45 | P9: 0.3 | Q9: 0.3 | R9: 0.3 | S9: 0.3 | T9: 0.3 | U9: 0.3 | V9: 0.3 | W9: 0.3 | X9: 0.6 | Y9: 0.8 | Z9: 0.9 | AA9: 0.8 | AB9: 0.6 | AC9: 0.3
A10: Living Area | B10: =B4 -> ResidentialLiving | C10: ElecEquipment | D10: T24 2022 - Appendix 5.4B [ResidentialLiving] | E10: Weekday | F10: 0.1 | G10: 0.1 | H10: 0.1 | I10: 0.1 | J10: 0.1 | K10: 0.3 | L10: 0.45 | M10: 0.45 | N10: 0.45 | O10: 0.45 | P10: 0.3 | Q10: 0.3 | R10: 0.3 | S10: 0.3 | T10: 0.3 | U10: 0.3 | V10: 0.3 | W10: 0.3 | X10: 0.6 | Y10: 0.8 | Z10: 0.9 | AA10: 0.8 | AB10: 0.6 | AC10: 0.3
E11: Saturday | F11: 0.1 | G11: 0.1 | H11: 0.1 | I11: 0.1 | J11: 0.1 | K11: 0.3 | L11: 0.45 | M11: 0.45 | N11: 0.45 | O11: 0.45 | P11: 0.3 | Q11: 0.3 | R11: 0.3 | S11: 0.3 | T11: 0.3 | U11: 0.3 | V11: 0.3 | W11: 0.3 | X11: 0.6 | Y11: 0.8 | Z11: 0.9 | AA11: 0.8 | AB11: 0.6 | AC11: 0.3
E12: Sunday | F12: 0.1 | G12: 0.1 | H12: 0.1 | I12: 0.1 | J12: 0.1 | K12: 0.3 | L12: 0.45 | M12: 0.45 | N12: 0.45 | O12: 0.45 | P12: 0.3 | Q12: 0.3 | R12: 0.3 | S12: 0.3 | T12: 0.3 | U12: 0.3 | V12: 0.3 | W12: 0.3 | X12: 0.6 | Y12: 0.8 | Z12: 0.9 | AA12: 0.8 | AB12: 0.6 | AC12: 0.3
A13: Living Area | B13: =B4 -> ResidentialLiving | C13: HVACAvail | D13: T24 2022 - Appendix 5.4B [ResidentialLiving] | E13: Weekday | F13: 1 | G13: 1 | H13: 1 | I13: 1 | J13: 1 | K13: 1 | L13: 1 | M13: 1 | N13: 1 | O13: 1 | P13: 1 | Q13: 1 | R13: 1 | S13: 1 | T13: 1 | U13: 1 | V13: 1 | W13: 1 | X13: 1 | Y13: 1 | Z13: 1 | AA13: 1 | AB13: 1 | AC13: 1
E14: Saturday | F14: 1 | G14: 1 | H14: 1 | I14: 1 | J14: 1 | K14: 1 | L14: 1 | M14: 1 | N14: 1 | O14: 1 | P14: 1 | Q14: 1 | R14: 1 | S14: 1 | T14: 1 | U14: 1 | V14: 1 | W14: 1 | X14: 1 | Y14: 1 | Z14: 1 | AA14: 1 | AB14: 1 | AC14: 1
E15: Sunday | F15: 1 | G15: 1 | H15: 1 | I15: 1 | J15: 1 | K15: 1 | L15: 1 | M15: 1 | N15: 1 | O15: 1 | P15: 1 | Q15: 1 | R15: 1 | S15: 1 | T15: 1 | U15: 1 | V15: 1 | W15: 1 | X15: 1 | Y15: 1 | Z15: 1 | AA15: 1 | AB15: 1 | AC15: 1
A16: Living Area | B16: =B4 -> ResidentialLiving | C16: ServiceHotWater | D16: T24 2022 - Appendix 5.4B [ResidentialLiving] | E16: Weekday | F16: 0.131 | G16: 0.075 | H16: 0.084 | I16: 0.103 | J16: 0.187 | K16: 0.411 | L16: 0.832 | M16: 1 | N16: 0.832 | O16: 0.617 | P16: 0.486 | Q16: 0.355 | R16: 0.336 | S16: 0.308 | T16: 0.299 | U16: 0.243 | V16: 0.393 | W16: 0.449 | X16: 0.486 | Y16: 0.439 | Z16: 0.393 | AA16: 0.364 | AB16: 0.336 | AC16: 0.206
E17: Saturday | F17: 0.217 | G17: 0.12 | H17: 0.108 | I17: 0.096 | J17: 0.181 | K17: 0.277 | L17: 0.313 | M17: 0.566 | N17: 0.928 | O17: 1 | P17: 0.892 | Q17: 0.735 | R17: 0.614 | S17: 0.518 | T17: 0.47 | U17: 0.47 | V17: 0.627 | W17: 0.699 | X17: 0.675 | Y17: 0.627 | Z17: 0.566 | AA17: 0.53 | AB17: 0.482 | AC17: 0.337
