Workbook
Name nonparticipating_forecastzone_scale_factor: 'Energy Usage'!#REF!
Name Space_Function: Data!$A$2:$A$76

Sheet Notes
A1: Data Sources
A2: Dataset | B2: Dodge 2023
B3: CEUS 2022
B4: CBECS 2018
B5: ComStock 2023
A6: Prototype | B6: CEC Small Hotel prototype (CBECC 2022.3.1) | C6: https://bees.noresco.com/software2022.html
B7: PNNL Small Hotel prototype (90.1-2022, 2019) | C7: https://www.energycodes.gov/prototype-building-models#Commercial
B8: DEER Small Hotel prototype (June 2023) | C8: https://github.com/sound-data/DEER-Prototypes-EnergyPlus
A10: Codes | B10: Title 24, part 6, referred to as T24 (1984, 2001, 2007, 2013, 2022, 2025)
B11: ASHRAE 90.1 (2022)
B12: CFR Title 10 (2009) | C12: https://www.govinfo.gov/content/pkg/FR-2009-03-23/pdf/FR-2009-03-23.pdf
B13: CFR Title 10 ( 2013) | C13: https://www.govinfo.gov/content/pkg/CFR-2013-title10-vol3/pdf/CFR-2013-title10-vol3-part431.pdf
B14: CFR Title 10 ( 2024) | C14: https://www.govinfo.gov/content/pkg/CFR-2024-title10-vol3/pdf/CFR-2024-title10-vol3-part431-subpartF.pdf
A16: Others | B16: ACM (2022)
B17: Title 24, 2022 - Appendix 5.4A and Appendix 5.4B | C17: https://www.energy.ca.gov/publications/2022/2022-nonresidential-and-multifamily-alternative-calculation-method-reference
B18: 2022 Reduced infiltration CASE report | C18: https://title24stakeholders.com/wp-content/uploads/2020/10/2022-T24-Final-CASE-Report_Reduce-Infiltration.pdf
B19: Honeywell, INNCOM e7 Thermostat User Guide, 2017 | C19: https://prod-edam.honeywell.com/content/dam/honeywell-edam/hbt/en-us/documents/manuals-and-guides/installation-guides/inncom/hbt-bms-INNCOM-e7-USER-GUIDE.pdf?download=false
B20: 2019 Outdoor Lighting CASE Report | C20: https://title24stakeholders.com/wp-content/uploads/2016/10/T24-2019-CASE-Study-Results-Report-Outdoor-Sources_Final_with-Attachments.pdf
B21: 2025 State of the Industry Report | C21: https://www.ahla.com/sites/default/files/25_SOTI.pdf
B22: PNNL 20405, 2010 | C22: https://www.pnnl.gov/main/publications/external/technical_reports/PNNL-20405.pdf
B23: Air leakage Memo, NORESCO, 2025 | C23: Infiltration_rate_report_14May2025-Short-Version.docx
B24: Proposed Updates to Equipment Power Densities and Building Schedules for the 2028 Energy Code, referred to as "Plug load and schedules project with CEC, 2025" (Docket Number =25-BSTD-03 & TN=265693) | C24: https://efiling.energy.ca.gov/GetDocument.aspx?tn=265693&DocumentContentId=102545
A26: Construction Rate
A39: Notes
A40: Small Hotel | B40: is defined as any hotel with floor area below 60,000 ft² , no matter of their number of stories.
A41: EIA, 2018 CBECS | B41: Approximately 42% of lodging buildings were between 1,001 ft² and 10,000 ft². On average, lodging buildings were among the largest commercial building types (33,700 ft² per building). More than one-half (56%) of lodging buildings were on a campus or complex. The majority of lodging buildings were not tall—only 2% of lodging buildings had 10 or more floors. Buildings that had one or two floors accounted for 71% of all lodging buildings.
A63: Dodge 2023

Sheet Prototype
A1: NORESCO, Updated August 2025
A2: HotelSmall
A3: Characteristic | B3: Value | C3: Data Sources
A4: Building Type | B4: Small Hotel
A5: Building Category | B5: Nonresidential
A6: Vintages | B6: 4 Vintages: Pre-1978 , 1978-1997 ,1998-2007 , 2008-2018 New Construction (2019+) | C6: Based on the vintage bin analysis | D6: NonRes-Vintage bins-Draft Report-30Nov2023-Final.docx
A7: Shape | C7: Same as CEC and PNNL, except CalBEM is three stories whereas CEC and PNNL have four stories
A8: Total Floor Area (ft²) | B8: 32,400 (180 ft x 60 ft) | C8: Footprint same as CEC and PNNL, but total floor area based on Dodge 2023 data
A9: Aspect Ratio | B9: 3 | C9: Same as CEC and PNNL
A10: Number of Floors | B10: 3 | C10: Based on Dodge 2023 data (Median number of stories)
A11: Roof type | B11: Flat Wood-Framed Roof for Guest rooms of Hotel/Motel | C11: Same as CEC and PNNL
A12: WWR | B12: South: 15.2%, East: 3.1%, North: 11.4%, West: 4.0% Average Total: 10.9%
A13: Shading Geometry | B13: No Shades | C13: Same as CEC and PNNL
A14: Floor to floor height (ft) | B14: Ground floor: 11 ft Upper floors: 9 ft | C14: Same as CEC and PNNL
A15: Floor to ceiling height (ft) | B15: Same as above | C15: Same as CEC and PNNL
A16: Glazing sill height (ft) | B16: 3 ft in ground floor, 2 ft. in upper floors | C16: Same as CEC and PNNL
A21: Existing prototypes:
A22: DEER motel model | C22: PNNL
C23: #VALUE!

Sheet Zones
A1: Proposed Layout - HotelSmall
A2: Space/Thermal Zone | B2: Space Type | C2: HVAC Zone | D2: Schedule Category | E2: Conditioned [Y/N] | F2: Area Fraction | G2: Area (ft²) | H2: Volume [ft³] | I2: Multipliers | J2: People | K2: People (Persons/1,000 ft²) [T24, 2025,Table 120.1-A]
A3: Corridor_FloorG | B3: Corridor Area | C3: BaseAirSys5 | D3: ResidentialCommon | E3: Yes | F3: =G3/$G$51 -> 0.054998656 | G3: 1782.21 | H3: 19605.24 | I3: 1 | J3: =(G3/1000)*K3 -> 8.91105 | K3: 5
A4: Corridor_FloorM | B4: Corridor Area | C4: BaseAirSys5-2 | D4: ResidentialCommon | E4: Yes | F4: =G4/$G$51 -> 0.046664965 | G4: 1512.16 | H4: 13610.11 | I4: 1 | J4: =(G4/1000)*K4 -> 7.5608 | K4: 5
A5: Corridor_FloorT | B5: Corridor Area | C5: BaseAirSys5-3 | D5: ResidentialCommon | E5: Yes | F5: =G5/$G$51 -> 0.046664965 | G5: 1512.16 | H5: 13610.11 | I5: 1 | J5: =(G5/1000)*K5 -> 7.5608 | K5: 5
A6: Lounge_FloorG | B6: Lounge, Breakroom, or Waiting Area | C6: BaseAirSys5 | D6: ResidentialCommon | E6: Yes | F6: =G6/$G$51 -> 0.010832718 | G6: 351.03 | H6: 3861.57 | I6: 1 | J6: =(G6/1000)*K6 -> 11.58399 | K6: 33
A7: Gym_FloorG | B7: Exercise/Fitness Center and Gymnasium Areas | C7: BaseAirSys5 | D7: Assembly | E7: Yes | F7: =G7/$G$51 -> 0.010832718 | G7: 351.03 | H7: 3861.57 | I7: 1 | J7: =(G7/1000)*K7 -> 3.5103 | K7: 10
A8: Front_Lounge_FloorG | B8: Lounge, Breakroom, or Waiting Area | C8: BaseAirSys5 | D8: ResidentialCommon | E8: Yes | F8: =G8/$G$51 -> 0.054168219 | G8: 1755.3 | H8: 19309.26 | I8: 1 | J8: =(G8/1000)*K8 -> 57.9249 | K8: 33
A9: Front_Office_FloorG | B9: Office Area (>250 square feet) | C9: BaseAirSys5 | D9: Office | E9: Yes | F9: =G9/$G$51 -> 0.043331489 | G9: 1404.14 | H9: 15446.26 | I9: 1 | J9: =(G9/1000)*K9 -> 7.0207 | K9: 5
A10: Front_Stair_FloorG | B10: Stairwell | C10: BaseAirSys5 | D10: ResidentialCommon | E10: Yes | F10: =G10/$G$51 -> 0.0066663354 | G10: 216.02 | H10: 2376.35 | I10: 1 | J10: =(G10/1000)*K10 -> 0 | K10: 0
A11: Front_Stair_FloorM | B11: Stairwell | C11: BaseAirSys5-2 | D11: ResidentialCommon | E11: Yes | F11: =G11/$G$51 -> 0.0066663354 | G11: 216.02 | H11: 1944.29 | I11: 1 | J11: =(G11/1000)*K11 -> 0 | K11: 0
A12: Front_Stair_FloorT | B12: Stairwell | C12: BaseAirSys5-3 | D12: ResidentialCommon | E12: Yes | F12: =G12/$G$51 -> 0.0066663354 | G12: 216.02 | H12: 1944.29 | I12: 1 | J12: =(G12/1000)*K12 -> 0 | K12: 0
A13: Front_Storage_FloorG | B13: Storage (General) | C13: BaseAirSys5 | D13: Assembly | E13: Yes | F13: =G13/$G$51 -> 0.0041663825 | G13: 135.01 | H13: 1485.22 | I13: 1 | J13: =(G13/1000)*K13 -> 0.27002 | K13: 2
A14: Front_Storage_FloorM | B14: Storage (General) | C14: BaseAirSys5-2 | D14: Assembly | E14: Yes | F14: =G14/$G$51 -> 0.0041663825 | G14: 135.01 | H14: 1215.18 | I14: 1 | J14: =(G14/1000)*K14 -> 0.27002 | K14: 2
... A50: Restroom_FloorG | B50: Restrooms | C50: BaseAirSys5 | D50: ResidentialCommon | E50: Yes | F50: =G50/$G$51 -> 0.010833644 | G50: 351.06 | H50: 3861.85 | I50: 1 | J50: =(G50/1000)*K50 -> 1.7553 | K50: 5
A51: Total (48 spaces/Thermal zones) | B51: Total (11 Space types) | C51: Total (28 HVAC Zones) | D51: Total (3 Schedule Categories) | E51: Total (48 Conditioned zones) | F51: =SUM(F3:F50) -> 1 | G51: =SUM(G3:G50) -> 32404.61 | J51: =SUM(J3:J50) -> 201.26094 | K51: 0
B53: Ref: Geometry and zones: PNNL 2022 small hotel prototype
A63: Background Data [To be deleted prior to publication]

Sheet HVAC System
A1: ="HVAC system - "&Prototype!A2 -> HVAC system - HotelSmall
A2: Vintage | B2: Zones | C2: Heating | D2: Cooling | E2: Air Distribution | F2: Source | G2: Note
A3: Existing | B3: Guest Rooms | C3: Electric resistance | D3: PTAC | E3: CAV | F3: CEUS 2022
B4: All other conditioned zones | C4: Electric resistance | D4: PTAC | E4: CAV | F4: CEUS 2022
A6: New Construction | B6: Guest Rooms | C6: PTHP | D6: PTAC | E6: CAV | F6: T24 2025 | G6: Residential air conditioner- System1-RAC
B7: All other conditioned zones | C7: Gas Boiler | D7: PVAV | E7: VAV + Hydronic Reheat | F7: T24 2025 | G7: Packaged VAV-System5
A11: Efficiency of HVAC system (Efficiency is capacity-dependent. The following Table provides a general estimate of system efficiency based on what we saw in the existing prototype runs, or assuming cooling load based on rule of thumb)
A12: Vintage | B12: Upgrade/Installed year | C12: DX Cooling-Guest Rooms | D12: DX Cooling-All Other Conditioned Zones | E12: Gas Boiler- Guest rooms and All Other Conditioned Zones | F12: Sources | G12: Note
A13: Pre 1978 | B13: 2008 | C13: EER=9 (<65,000 Btu/h) | D13: - | E13: - | F13: CFR Energy 2008 (for DX Cooling)
A14: 1978-1997
A15: 1998-2007
A16: 2008-2018 | B16: 2013 | C16: EER=9 (<65,000 Btu/h) | D16: - | E16: - | F16: CFR Energy 2010:Title 10- Table 9 (for DX Cooling)
A17: New Construction | B17: 2025 | C17: EER=9 (<65,000 Btu/h) | D17: EER=10 (≥ 240,000 Btu/h and < 760,000 Btu/h) and EER=9 (<65,000 Btu/h) | E17: Thermal Efficiency (Et) of 84% | F17: CFR Energy 2025, Table 12 (for DX Coils) T24, 2022 ,Table 110.2-J (for Boiler thermal efficiency) | G17: Deduct 0.2 from the required EERs and IEERs for units with a heating section other than electric resistance heat.
A21: Fan power
A22: Vintage | B22: Approach | C22: System | D22: Total Static Pressure (TSP) (in w.c.) [PNNL 20405, 2010, Table 5.11] | E22: Fan Efficiency [ACM 2025] | F22: Fan Motor and Drive Efficiency [ACM 2025, Table 13] | G22: W/cfm [ACM 2025, Table 14 and 15] | H22: Data Source
A23: Existing | B23: PNNL TSP | C23: PTAC, PTHP | D23: 1.33 | E23: 0.65 | F23: ~0.9 (The full-load efficiency of the motor serving the fan- will be determined based on ACM 2025, Table 13) | H23: PNNL 20405, 2010, Table 5.11
A24: Brake horse power (bhp)=(Supply cfm*TSP in w.c.)/(6356*Fan efficiency)
A25: Fan power (w/cfm) = bhp/motor and drive efficiency *746
A26: cfm = supply fan airflow as determined by EnergyPlus sizing runs
A27: Nameplate horsepower = brake horsepower × (1+10% oversizing factor)
A28: Motor nameplate horsepower will be determined based of NEMA standards
A29: New Construction | B29: ACM 2025 | C29: System 3b-SZHP, <5000 | D29: =G29*$F$29*$E$29/746*6356 -> 3.7082915 | E29: 0.65 | F29: 0.9 | G29: 0.744 | H29: ACM 2025
C30: PVAV System >10,000 cfm | D30: =G30*$F$29*$E$29/746*6356 -> 4.8048293 | G30: 0.964
F31: * 0.9 is an average fan efficiency according to ACM 2025, Table 13
A32: Fan total eff (E+ input) = 0.65 x Motor_eff
A33: TSP (E+ input) in w.c. = Motor_eff/746 x (6356 x Fan_eff) x W/cfm
A34: Fan_eff=0.65
A36: Background Data [To be deleted prior to publication]
A41: CEUS 2022 | B41: Heating | F41: Cooling | H41: Air Distribution | I41: Water Heater
B42: Floorspace Heated | C42: Primary Heating The default is the floorspace method unless otherwise specified | D42: Fuel Type | F42: Floorspace Cooled | G42: Primary Cooling The default is the floorspace method unless otherwise specified | H42: Primary Air Dis The default is the floorspace method unless otherwise specified | I42: Fuel Type
D43: Elec | E43: Gas | I43: Elec | J43: Gas
A44: Lodging | B44: 0.99109826 | C44: Floorspace method: Package System / Heat Pump (37.5%) Boiler/ Hydronic (30.5%) Site method: Package System / Heat Pump (53.3%) Boiler/ Hydronic (8.8%) | D44: 0.4024 | E44: 0.566 | F44: 0.97514167 | G44: Floorspace method: Package System / Heat Pump (37.4%) Central Plant (Chiller) (29.8%) Site method: Package System / Heat Pump (53.2%) Central Plant (Chiller) (6.8%) | H44: Single Duct CAV (53.9%) Fan Coil Unit/Ventilator (33.2%) | I44: 0.033100835 | J44: 0.83999183

Sheet Envelope
A1: Envelope - HotelSmall
A2: Element | B2: Prototype | C2: Assembly Type | D2: Construction | E2: Thermal Properties | F2: Vintage | G2: Selected T24 | H2: Note | I2: CZ1 | J2: CZ2 | K2: CZ3 | L2: CZ4 | M2: CZ5 | N2: CZ6 | O2: CZ7 | P2: CZ8 | Q2: CZ9 | R2: CZ10 | S2: CZ11 | T2: CZ12 | U2: CZ13 | V2: CZ14 | W2: CZ15 | X2: CZ16
A3: External Wall_Guest Room | B3: HotelSmall | C3: ExtWall_MetalFramed_GuestRooms | D3: Stucco + Metal-frame (2x4 16 in. OC) + insulation + Gypsum board | E3: U-factor IP | F3: Pre 1978 | G3: N/A | H3: ASHRAE 90.1, 2022, Table A3.3.3.1, 3.5", R-0 | I3: 0.352 | J3: 0.352 | K3: 0.352 | L3: 0.352 | M3: 0.352 | N3: 0.352 | O3: 0.352 | P3: 0.352 | Q3: 0.352 | R3: 0.352 | S3: 0.352 | T3: 0.352 | U3: 0.352 | V3: 0.352 | W3: 0.352 | X3: 0.352
F4: 1978-1997 | G4: 1986 | H4: Copied from High-rise office alternative requirements (Table 2-53W): Package A with heat capacity between 10-14.99 (Btu/F-ft²) *T24, 1986, Table 2-53BB presents U-factors less than the next vintage (for wall density of 26-40 lb/ft² & Degree day<3500)! | I4: =1/4.7 -> 0.21276596 | J4: =1/4.4 -> 0.22727273 | K4: =1/4.4 -> 0.22727273 | L4: =1/4.6 -> 0.2173913 | M4: =1/3.9 -> 0.25641026 | N4: =1/3.9 -> 0.25641026 | O4: =1/3.9 -> 0.25641026 | P4: =1/3.9 -> 0.25641026 | Q4: =1/3.9 -> 0.25641026 | R4: =1/3.9 -> 0.25641026 | S4: =1/4.2 -> 0.23809524 | T4: =1/4.2 -> 0.23809524 | U4: =1/4.2 -> 0.23809524 | V4: =1/4.8 -> 0.20833333 | W4: =1/4.8 -> 0.20833333 | X4: =1/4.7 -> 0.21276596
F5: 1998-2007 | G5: 2001 | H5: Table 1-I-Guest rooms of Hotel/Motel | I5: 0.14 | J5: 0.175 | K5: 0.181 | L5: 0.181 | M5: 0.181 | N5: 0.181 | O5: 0.181 | P5: 0.181 | Q5: 0.181 | R5: 0.175 | S5: 0.175 | T5: 0.175 | U5: 0.175 | V5: 0.175 | W5: 0.175 | X5: 0.14
F6: 2008-2018 | G6: 2013 | H6: Table 140.3-C-Guest rooms of Hotel/Motel | I6: 0.105 | J6: 0.105 | K6: 0.105 | L6: 0.105 | M6: 0.105 | N6: 0.105 | O6: 0.105 | P6: 0.105 | Q6: 0.105 | R6: 0.105 | S6: 0.105 | T6: 0.105 | U6: 0.105 | V6: 0.105 | W6: 0.105 | X6: 0.105
F7: 2019+ | G7: 2025 | H7: Table 140.3-C-Guest rooms of Hotel/Motel | I7: 0.069 | J7: 0.069 | K7: 0.069 | L7: 0.069 | M7: 0.069 | N7: 0.069 | O7: 0.105 | P7: 0.069 | Q7: 0.069 | R7: 0.069 | S7: 0.069 | T7: 0.069 | U7: 0.069 | V7: 0.069 | W7: 0.048 | X7: 0.069
A8: External Wall_Nonres | B8: HotelSmall | C8: ExtWall_MetalFramed_NonRes | D8: Stucco + Metal frame (2x4 16 in. OC) + insulation + Gypsum board | E8: U-factor IP | F8: Pre 1978 | G8: N/A | H8: ASHRAE 90.1, 2022, Table A3.3.3.1, 3.5", R-0 | I8: 0.352 | J8: 0.352 | K8: 0.352 | L8: 0.352 | M8: 0.352 | N8: 0.352 | O8: 0.352 | P8: 0.352 | Q8: 0.352 | R8: 0.352 | S8: 0.352 | T8: 0.352 | U8: 0.352 | V8: 0.352 | W8: 0.352 | X8: 0.352
F9: 1978-1997 | G9: 1986 | H9: Copied from High-rise office alternative requirements (Table 2-53W): Package A with heat capacity between 10-14.99 (Btu/F-ft²) *T24, 1986, Table 2-53BB presents U-factors less than the next vintage (for wall density of 26-40 lb/ft² & Degree day<3500)! | I9: 0.21276596 | J9: 0.22727273 | K9: 0.22727273 | L9: 0.2173913 | M9: 0.25641026 | N9: 0.25641026 | O9: 0.25641026 | P9: 0.25641026 | Q9: 0.25641026 | R9: 0.25641026 | S9: 0.23809524 | T9: 0.23809524 | U9: 0.23809524 | V9: 0.20833333 | W9: 0.20833333 | X9: 0.21276596
F10: 1998-2007 | G10: 2001 | H10: Table 1-H-NonRes Bldgs | I10: 0.182 | J10: 0.182 | K10: 0.189 | L10: 0.189 | M10: 0.189 | N10: 0.189 | O10: 0.189 | P10: 0.189 | Q10: 0.189 | R10: 0.182 | S10: 0.182 | T10: 0.182 | U10: 0.182 | V10: 0.182 | W10: 0.182 | X10: 0.182
F11: 2008-2018 | G11: 2013 | H11: Table 140.3-B-NonRes Bldgs | I11: 0.098 | J11: 0.062 | K11: 0.082 | L11: 0.062 | M11: 0.062 | N11: 0.098 | O11: 0.098 | P11: 0.062 | Q11: 0.062 | R11: 0.062 | S11: 0.062 | T11: 0.062 | U11: 0.062 | V11: 0.062 | W11: 0.062 | X11: 0.062
F12: 2019+ | G12: 2025 | H12: Table 140.3-B-NonRes Bldgs | I12: 0.06 | J12: 0.055 | K12: 0.071 | L12: 0.055 | M12: 0.055 | N12: 0.06 | O12: 0.06 | P12: 0.055 | Q12: 0.055 | R12: 0.055 | S12: 0.055 | T12: 0.055 | U12: 0.055 | V12: 0.055 | W12: 0.055 | X12: 0.055
A13: Roof_Guest Room | B13: HotelSmall | C13: FlatRoof_WoodFramedAndOther_GuestRooms | D13: Roof membrane or shingles + roof insulation + wood decking/sheathing + wood framing | E13: U-factor IP | F13: Pre 1978 | G13: N/A | H13: Considering 30 years for roof/ insulation replacement. | I13: 0.037 | J13: 0.051 | K13: 0.051 | L13: 0.051 | M13: 0.051 | N13: 0.051 | O13: 0.051 | P13: 0.051 | Q13: 0.051 | R13: 0.051 | S13: 0.037 | T13: 0.037 | U13: 0.037 | V13: 0.037 | W13: 0.037 | X13: 0.037
F14: 1978-1997 | G14: N/A | I14: 0.037 | J14: 0.051 | K14: 0.051 | L14: 0.051 | M14: 0.051 | N14: 0.051 | O14: 0.051 | P14: 0.051 | Q14: 0.051 | R14: 0.051 | S14: 0.037 | T14: 0.037 | U14: 0.037 | V14: 0.037 | W14: 0.037 | X14: 0.037
F15: 1998-2007 | G15: 2001 | H15: Table 1-I-Guest rooms of Hotel/Motel | I15: 0.037 | J15: 0.037 | K15: 0.051 | L15: 0.051 | M15: 0.051 | N15: 0.051 | O15: 0.051 | P15: 0.051 | Q15: 0.051 | R15: 0.037 | S15: 0.037 | T15: 0.037 | U15: 0.037 | V15: 0.037 | W15: 0.037 | X15: 0.037
F16: 2008-2018 | G16: 2013 | H16: Table 140.3-C-Guest rooms of Hotel/Motel | I16: 0.034 | J16: 0.028 | K16: 0.039 | L16: 0.028 | M16: 0.039 | N16: 0.039 | O16: 0.039 | P16: 0.028 | Q16: 0.028 | R16: 0.028 | S16: 0.028 | T16: 0.028 | U16: 0.028 | V16: 0.028 | W16: 0.028 | X16: 0.028
F17: 2019+ | G17: 2025 | H17: Table 140.3-C-Guest rooms of Hotel/Motel | I17: 0.028 | J17: 0.028 | K17: 0.034 | L17: 0.028 | M17: 0.034 | N17: 0.034 | O17: 0.039 | P17: 0.028 | Q17: 0.028 | R17: 0.028 | S17: 0.028 | T17: 0.028 | U17: 0.028 | V17: 0.028 | W17: 0.028 | X17: 0.028
A18: Windows_ Guest Room | B18: HotelSmall | C18: FixedWindow_GuestRoom | D18: Single pane | E18: U-factor IP | F18: Pre 1978 | G18: N/A | H18: ASHRAE Handbook of Fundamentals (Table 4-Ch15) for single pane & T24, 2013 for double pane(33%-67%)* | I18: =0.33*1.12+0.67*0.36 -> 0.6108 | J18: =0.33*1.12+0.67*0.36 -> 0.6108 | K18: =0.33*1.12+0.67*0.36 -> 0.6108 | L18: =0.33*1.12+0.67*0.36 -> 0.6108 | M18: =0.33*1.12+0.67*0.36 -> 0.6108 | N18: =0.33*1.12+0.67*0.36 -> 0.6108 | O18: =0.33*1.12+0.67*0.36 -> 0.6108 | P18: =0.33*1.12+0.67*0.36 -> 0.6108 | ... X18: =0.33*1.12+0.67*0.36 -> 0.6108
F19: 1978-1997 | G19: N/A | I19: =0.33*1.12+0.67*0.36 -> 0.6108 | J19: =0.33*1.12+0.67*0.36 -> 0.6108 | K19: =0.33*1.12+0.67*0.36 -> 0.6108 | L19: =0.33*1.12+0.67*0.36 -> 0.6108 | M19: =0.33*1.12+0.67*0.36 -> 0.6108 | N19: =0.33*1.12+0.67*0.36 -> 0.6108 | O19: =0.33*1.12+0.67*0.36 -> 0.6108 | P19: =0.33*1.12+0.67*0.36 -> 0.6108 | ... X19: =0.33*1.12+0.67*0.36 -> 0.6108
D20: Double pane | F20: 1998-2007 | G20: 2001 | H20: Table 1-I-Guest rooms of Hotel/Motel | I20: 0.49 | J20: 0.49 | K20: 0.49 | L20: 0.49 | M20: 0.49 | N20: 0.49 | O20: 0.49 | P20: 0.49 | Q20: 0.49 | R20: 0.49 | S20: 0.49 | T20: 0.49 | U20: 0.49 | V20: 0.49 | W20: 0.49 | X20: 0.49
F21: 2008-2018 | G21: 2013 | H21: Table 140.3-C-Guest rooms of Hotel/Motel | I21: 0.36 | J21: 0.36 | K21: 0.36 | L21: 0.36 | M21: 0.36 | N21: 0.36 | O21: 0.36 | P21: 0.36 | Q21: 0.36 | R21: 0.36 | S21: 0.36 | T21: 0.36 | U21: 0.36 | V21: 0.36 | W21: 0.36 | X21: 0.36
F22: 2019+ | G22: 2025 | H22: Table 140.3-C-Guest rooms of Hotel/Motel | I22: 0.36 | J22: 0.36 | K22: 0.36 | L22: 0.36 | M22: 0.36 | N22: 0.36 | O22: 0.36 | P22: 0.36 | Q22: 0.36 | R22: 0.36 | S22: 0.36 | T22: 0.36 | U22: 0.36 | V22: 0.36 | W22: 0.36 | X22: 0.36
D23: Single pane | E23: SHGC | F23: Pre 1978 | G23: N/A | H23: ASHRAE Handbook of Fundamentals (Table 10-Ch15) for single pane & T24, 2013 for double pane(33%-67%)* | I23: =0.79*0.33+0.67*I36 -> 0.4282 | J23: =0.79*0.33+0.67*J36 -> 0.4282 | K23: =0.79*0.33+0.67*K36 -> 0.4282 | L23: =0.79*0.33+0.67*L36 -> 0.4282 | M23: =0.79*0.33+0.67*M36 -> 0.4282 | N23: =0.79*0.33+0.67*N36 -> 0.4282 | O23: =0.79*0.33+0.67*O36 -> 0.4282 | P23: =0.79*0.33+0.67*P36 -> 0.4282 | ... X23: =0.79*0.33+0.67*X36 -> 0.4282
F24: 1978-1997 | G24: N/A | I24: =0.79*0.33+0.67*I26 -> 0.4282 | J24: =0.79*0.33+0.67*J26 -> 0.4282 | K24: =0.79*0.33+0.67*K26 -> 0.4282 | L24: =0.79*0.33+0.67*L26 -> 0.4282 | M24: =0.79*0.33+0.67*M26 -> 0.4282 | N24: =0.79*0.33+0.67*N26 -> 0.4282 | O24: =0.79*0.33+0.67*O26 -> 0.4282 | P24: =0.79*0.33+0.67*P26 -> 0.4282 | ... X24: =0.79*0.33+0.67*X26 -> 0.4282
D25: Double pane | F25: 1998-2007 | G25: 2001 | H25: Table 1-I-Guest rooms of Hotel/Motel (WWR:10-20% / SHGC Non-north) | I25: 0.46 | J25: 0.36 | K25: 0.4 | L25: 0.4 | M25: 0.4 | N25: 0.4 | O25: 0.4 | P25: 0.4 | Q25: 0.4 | R25: 0.36 | S25: 0.36 | T25: 0.36 | U25: 0.36 | V25: 0.31 | W25: 0.31 | X25: 0.46
F26: 2008-2018 | G26: 2013 | H26: Table 140.3-C-Guest rooms of Hotel/Motel | I26: 0.25 | J26: 0.25 | K26: 0.25 | L26: 0.25 | M26: 0.25 | N26: 0.25 | O26: 0.25 | P26: 0.25 | Q26: 0.25 | R26: 0.25 | S26: 0.25 | T26: 0.25 | U26: 0.25 | V26: 0.25 | W26: 0.25 | X26: 0.25
F27: 2019+ | G27: 2025 | H27: Table 140.3-C-Guest rooms of Hotel/Motel | I27: 0.25 | J27: 0.25 | K27: 0.25 | L27: 0.25 | M27: 0.25 | N27: 0.25 | O27: 0.25 | P27: 0.25 | Q27: 0.25 | R27: 0.25 | S27: 0.25 | T27: 0.25 | U27: 0.25 | V27: 0.25 | W27: 0.25 | X27: 0.25
A28: Windows_ Nonres | B28: HotelSmall | C28: FixedWindow_NonRes | D28: Single pane | E28: U-factor IP | F28: Pre 1978 | G28: N/A | H28: ASHRAE Handbook of Fundamentals (Table 4-Ch15) for single pane & T24, 2013 for double pane(33%-67%)* | I28: =0.338*1.12+0.67*0.36 -> 0.61976 | J28: =0.338*1.12+0.67*0.36 -> 0.61976 | K28: =0.338*1.12+0.67*0.36 -> 0.61976 | L28: =0.338*1.12+0.67*0.36 -> 0.61976 | M28: =0.338*1.12+0.67*0.36 -> 0.61976 | N28: =0.338*1.12+0.67*0.36 -> 0.61976 | O28: =0.338*1.12+0.67*0.36 -> 0.61976 | P28: =0.338*1.12+0.67*0.36 -> 0.61976 | ... X28: =0.338*1.12+0.67*0.36 -> 0.61976
F29: 1978-1997 | G29: N/A | I29: =0.338*1.12+0.67*0.36 -> 0.61976 | J29: =0.338*1.12+0.67*0.36 -> 0.61976 | K29: =0.338*1.12+0.67*0.36 -> 0.61976 | L29: =0.338*1.12+0.67*0.36 -> 0.61976 | M29: =0.338*1.12+0.67*0.36 -> 0.61976 | N29: =0.338*1.12+0.67*0.36 -> 0.61976 | O29: =0.338*1.12+0.67*0.36 -> 0.61976 | P29: =0.338*1.12+0.67*0.36 -> 0.61976 | ... X29: =0.338*1.12+0.67*0.36 -> 0.61976
D30: Double pane | F30: 1998-2007 | G30: 2001 | H30: Table 1-H-NonRes Bldgs | I30: 0.49 | J30: 0.49 | K30: 0.81 | L30: 0.81 | M30: 0.81 | N30: 0.81 | O30: 0.81 | P30: 0.81 | Q30: 0.81 | R30: 0.49 | S30: 0.49 | T30: 0.49 | U30: 0.49 | V30: 0.49 | W30: 0.49 | X30: 0.49
F31: 2008-2018 | G31: 2013 | H31: Table 140.3-B-NonRes Bldgs | I31: 0.36 | J31: 0.36 | K31: 0.36 | L31: 0.36 | M31: 0.36 | N31: 0.36 | O31: 0.36 | P31: 0.36 | Q31: 0.36 | R31: 0.36 | S31: 0.36 | T31: 0.36 | U31: 0.36 | V31: 0.36 | W31: 0.36 | X31: 0.36
F32: 2019+ | G32: 2025 | H32: Table 140.3-B-NonRes Bldgs | I32: 0.36 | J32: 0.36 | K32: 0.36 | L32: 0.36 | M32: 0.36 | N32: 0.36 | O32: 0.36 | P32: 0.36 | Q32: 0.34 | R32: 0.36 | S32: 0.34 | T32: 0.34 | U32: 0.34 | V32: 0.34 | W32: 0.34 | X32: 0.36
D33: Single pane | E33: SHGC | F33: Pre 1978 | G33: N/A | H33: ASHRAE Handbook of Fundamentals (Table 10-Ch15) for single pane & T24, 2013 for double pane(33%-67%)* | I33: =0.79*0.33+0.67*I36 -> 0.4282 | J33: =0.79*0.33+0.67*J36 -> 0.4282 | K33: =0.79*0.33+0.67*K36 -> 0.4282 | L33: =0.79*0.33+0.67*L36 -> 0.4282 | M33: =0.79*0.33+0.67*M36 -> 0.4282 | N33: =0.79*0.33+0.67*N36 -> 0.4282 | O33: =0.79*0.33+0.67*O36 -> 0.4282 | P33: =0.79*0.33+0.67*P36 -> 0.4282 | ... X33: =0.79*0.33+0.67*X36 -> 0.4282
F34: 1978-1997 | G34: N/A | I34: =0.79*0.33+0.67*I36 -> 0.4282 | J34: =0.79*0.33+0.67*J36 -> 0.4282 | K34: =0.79*0.33+0.67*K36 -> 0.4282 | L34: =0.79*0.33+0.67*L36 -> 0.4282 | M34: =0.79*0.33+0.67*M36 -> 0.4282 | N34: =0.79*0.33+0.67*N36 -> 0.4282 | O34: =0.79*0.33+0.67*O36 -> 0.4282 | P34: =0.79*0.33+0.67*P36 -> 0.4282 | ... X34: =0.79*0.33+0.67*X36 -> 0.4282
D35: Double pane | F35: 1998-2007 | G35: 2001 | H35: Table 1-H-NonRes Bldgs (WWR:10-20% / SHGC Non-north) | I35: 0.43 | J35: 0.36 | K35: 0.55 | L35: 0.55 | M35: 0.55 | N35: 0.61 | O35: 0.61 | P35: 0.61 | Q35: 0.61 | R35: 0.36 | S35: 0.36 | T35: 0.36 | U35: 0.36 | V35: 0.36 | W35: 0.36 | X35: 0.43
F36: 2008-2018 | G36: 2013 | H36: Table 140.3-B-NonRes Bldgs | I36: 0.25 | J36: 0.25 | K36: 0.25 | L36: 0.25 | M36: 0.25 | N36: 0.25 | O36: 0.25 | P36: 0.25 | Q36: 0.25 | R36: 0.25 | S36: 0.25 | T36: 0.25 | U36: 0.25 | V36: 0.25 | W36: 0.25 | X36: 0.25
F37: 2019+ | G37: 2025 | H37: Table 140.3-B-NonRes Bldgs | I37: 0.25 | J37: 0.25 | K37: 0.25 | L37: 0.25 | M37: 0.25 | N37: 0.25 | O37: 0.25 | P37: 0.25 | Q37: 0.22 | R37: 0.25 | S37: 0.22 | T37: 0.22 | U37: 0.22 | V37: 0.22 | W37: 0.22 | X37: 0.25
E39: Infiltration
F40: Vintage | G40: I_75 (cfm/ft²) 6-sdied Infiltration rate @ 75 pa | H40: Source | I40: I-design (cfm/ft²) (4-sided Infiltration rate at normal pressure) (Design flow rate approach and Flow/Exterior Wall Area calculation method)
E41: Infiltration | F41: Pre 1978 | G41: 1.1 | H41: 2022 CASE report (Table 38) | I41: 0.3144
...

Sheet Thermostat
A1: Thermostat Setpoints - HotelSmall
A2: Setpoint | B2: CZ1 | C2: CZ2 | D2: CZ3 | E2: CZ4 | F2: CZ5 | G2: CZ6 | H2: CZ7 | I2: CZ8 | J2: CZ9 | K2: CZ10 | L2: CZ11 | M2: CZ12 | N2: CZ13 | O2: CZ14 | P2: CZ15 | Q2: CZ16 | R2: Source
A3: Assembly and Office Heating Setpoint (F) | B3: 70 | C3: 70 | D3: 70 | E3: 70 | F3: 70 | G3: 70 | H3: 70 | I3: 70 | J3: 70 | K3: 70 | L3: 70 | M3: 70 | N3: 70 | O3: 70 | P3: 70 | Q3: 70 | R3: T24 2022 - Appendix 5.4B
A4: Assembly and Office Heating Setback (F) | B4: 60 | C4: 60 | D4: 60 | E4: 60 | F4: 60 | G4: 60 | H4: 60 | I4: 60 | J4: 60 | K4: 60 | L4: 60 | M4: 60 | N4: 60 | O4: 60 | P4: 60 | Q4: 60
A5: Assembly and Office Cooling Setpoint (F) | B5: 75 | C5: 75 | D5: 75 | E5: 75 | F5: 75 | G5: 75 | H5: 75 | I5: 75 | J5: 75 | K5: 75 | L5: 75 | M5: 75 | N5: 75 | O5: 75 | P5: 75 | Q5: 75
A6: Assembly and Office Cooling Setback (F) | B6: 85 | C6: 85 | D6: 85 | E6: 85 | F6: 85 | G6: 85 | H6: 85 | I6: 85 | J6: 85 | K6: 85 | L6: 85 | M6: 85 | N6: 85 | O6: 85 | P6: 85 | Q6: 85
A7: ResidentialCommon Heating Setpoint (F) | B7: 68 | C7: 68 | D7: 68 | E7: 68 | F7: 68 | G7: 68 | H7: 68 | I7: 68 | J7: 68 | K7: 68 | L7: 68 | M7: 68 | N7: 68 | O7: 68 | P7: 68 | Q7: 68 | R7: T24 2022 - Appendix 5.4B
A8: ResidentialCommon Heating Setback (F) | B8: 68 | C8: 68 | D8: 68 | E8: 68 | F8: 68 | G8: 68 | H8: 68 | I8: 68 | J8: 68 | K8: 68 | L8: 68 | M8: 68 | N8: 68 | O8: 68 | P8: 68 | Q8: 68
A9: ResidentialCommon Cooling Setpoint (F) | B9: 78 | C9: 78 | D9: 78 | E9: 78 | F9: 78 | G9: 78 | H9: 78 | I9: 78 | J9: 78 | K9: 78 | L9: 78 | M9: 78 | N9: 78 | O9: 78 | P9: 78 | Q9: 78
A10: ResidentialCommon Cooling Setback (F) | B10: 78 | C10: 78 | D10: 78 | E10: 78 | F10: 78 | G10: 78 | H10: 78 | I10: 78 | J10: 78 | K10: 78 | L10: 78 | M10: 78 | N10: 78 | O10: 78 | P10: 78 | Q10: 78
A11: ResidentialLiving Heating Setpoint (F) | B11: 70 | C11: 70 | D11: 70 | E11: 70 | F11: 70 | G11: 70 | H11: 70 | I11: 70 | J11: 70 | K11: 70 | L11: 70 | M11: 70 | N11: 70 | O11: 70 | P11: 70 | Q11: 70
A12: ResidentialLiving Heating Setback (F) | B12: 70 | C12: 70 | D12: 70 | E12: 70 | F12: 70 | G12: 70 | H12: 70 | I12: 70 | J12: 70 | K12: 70 | L12: 70 | M12: 70 | N12: 70 | O12: 70 | P12: 70 | Q12: 70
A13: ResidentialLiving Cooling Setpoint (F) | B13: 72 | C13: 72 | D13: 72 | E13: 72 | F13: 72 | G13: 72 | H13: 72 | I13: 72 | J13: 72 | K13: 72 | L13: 72 | M13: 72 | N13: 72 | O13: 72 | P13: 72 | Q13: 72 | R13: Honeywell-INNCOM e7 Thermostat User Guide
A14: ResidentialLiving Cooling Setback (F) | B14: 72 | C14: 72 | D14: 72 | E14: 72 | F14: 72 | G14: 72 | H14: 72 | I14: 72 | J14: 72 | K14: 72 | L14: 72 | M14: 72 | N14: 72 | O14: 72 | P14: 72 | Q14: 72 | R14: & Engineering Judgment
A15: PNNL had 70F for both cooling and heating setpoint without setback.
A16: 72F is the default setting for one of the most prominent thermostats (Inncom) in California hotels.
A17: It has a limit by which a hotel guest can override the default setting. For instance: if the default cooling setpoint is 72, the coolest that a user can set the cooling setpoint is 72-5 = 67F.
A18: Ref: https://prod-edam.honeywell.com/content/dam/honeywell-edam/hbt/en-us/documents/manuals-and-guides/installation-guides/inncom/hbt-bms-INNCOM-e7-USER-GUIDE.pdf
A22: Background Data [To be deleted prior to publication]
B23: Heating | E23: Cooling
B24: Weekday | C24: Saturday | D24: Sunday | E24: Weekday | F24: Saturday | G24: Sunday
A25: DEER | B25: 0:00 to 5:00 | C25: 0:00 to 5:00 | D25: 0:00 to 24:00 | E25: 0:00 to 5:00 | F25: 0:00 to 5:00 | G25: 0:00 to 24:00
B26: 15.56 | C26: 15.56 | D26: 15.56 | E26: 29.22 | F26: 29.22 | G26: 29.22
B27: 5:00 to 24:00 | C27: 5:00 to 19:00 | E27: 5:00 to 24:00 | F27: 5:00 to 19:00
B28: 21.11 | C28: 21.11 | E28: 23.88 | F28: 23.88
A31: T24, Appendix JA5-4 : Occupant Controlled Smart Thermostat (OCST)

Sheet Ventilation
A1: Outdoor Airflow Rate - HotelSmall
A2: Space | B2: Number of People | C2: Floor Area (ft²) | D2: cfm/person (T24, 2025, Equation 120.1-F and Table 120.1-A) | E2: cfm/ft² (T24, 2025, Equation 120.1-F and Table 120.1-A) | F2: Required Exhaust Rate (T24, 2025, Table 120.1-B – Minimum Exhaust Rates) | G2: Total cfm Driven by People | H2: Total cfm Driven by Area | I2: Total cfm Driven by Exhaust | J2: Total cfm | K2: Note
A3: =Zones!A3 -> Corridor_FloorG | B3: =Zones!J3 -> 8.91105 | C3: =Zones!G3 -> 1782.21 | D3: 15 | E3: 0.15 | G3: =B3*D3 -> 133.66575 | H3: =C3*E3 -> 267.3315 | J3: =MAX(G3:I3) -> 267.3315
A4: =Zones!A4 -> Corridor_FloorM | B4: =Zones!J4 -> 7.5608 | C4: =Zones!G4 -> 1512.16 | D4: 15 | E4: 0.15 | G4: =B4*D4 -> 113.412 | H4: =C4*E4 -> 226.824 | J4: =MAX(G4:I4) -> 226.824
A5: =Zones!A5 -> Corridor_FloorT | B5: =Zones!J5 -> 7.5608 | C5: =Zones!G5 -> 1512.16 | D5: 15 | E5: 0.15 | G5: =B5*D5 -> 113.412 | H5: =C5*E5 -> 226.824 | J5: =MAX(G5:I5) -> 226.824
A6: =Zones!A6 -> Lounge_FloorG | B6: =Zones!J6 -> 11.58399 | C6: =Zones!G6 -> 351.03 | D6: 15 | E6: 0.15 | G6: =B6*D6 -> 173.75985 | H6: =C6*E6 -> 52.6545 | J6: =MAX(G6:I6) -> 173.75985
A7: =Zones!A7 -> Gym_FloorG | B7: =Zones!J7 -> 3.5103 | C7: =Zones!G7 -> 351.03 | D7: 15 | E7: 0.15 | G7: =B7*D7 -> 52.6545 | H7: =C7*E7 -> 52.6545 | J7: =MAX(G7:I7) -> 52.6545
A8: =Zones!A8 -> Front_Lounge_FloorG | B8: =Zones!J8 -> 57.9249 | C8: =Zones!G8 -> 1755.3 | D8: 15 | E8: 0.15 | G8: =B8*D8 -> 868.8735 | H8: =C8*E8 -> 263.295 | J8: =MAX(G8:I8) -> 868.8735
A9: =Zones!A9 -> Front_Office_FloorG | B9: =Zones!J9 -> 7.0207 | C9: =Zones!G9 -> 1404.14 | D9: 15 | E9: 0.15 | G9: =B9*D9 -> 105.3105 | H9: =C9*E9 -> 210.621 | J9: =MAX(G9:I9) -> 210.621
A10: =Zones!A10 -> Front_Stair_FloorG | B10: =Zones!J10 -> 0 | C10: =Zones!G10 -> 216.02 | D10: 15 | E10: 0.15 | G10: =B10*D10 -> 0 | H10: =C10*E10 -> 32.403 | J10: =MAX(G10:I10) -> 32.403
A11: =Zones!A11 -> Front_Stair_FloorM | B11: =Zones!J11 -> 0 | C11: =Zones!G11 -> 216.02 | D11: 15 | E11: 0.15 | G11: =B11*D11 -> 0 | H11: =C11*E11 -> 32.403 | J11: =MAX(G11:I11) -> 32.403
A12: =Zones!A12 -> Front_Stair_FloorT | B12: =Zones!J12 -> 0 | C12: =Zones!G12 -> 216.02 | D12: 15 | E12: 0.15 | G12: =B12*D12 -> 0 | H12: =C12*E12 -> 32.403 | J12: =MAX(G12:I12) -> 32.403
A13: =Zones!A13 -> Front_Storage_FloorG | B13: =Zones!J13 -> 0.27002 | C13: =Zones!G13 -> 135.01 | D13: 15 | E13: 0.15 | G13: =B13*D13 -> 4.0503 | H13: =C13*E13 -> 20.2515 | J13: =MAX(G13:I13) -> 20.2515
A14: =Zones!A14 -> Front_Storage_FloorM | B14: =Zones!J14 -> 0.27002 | C14: =Zones!G14 -> 135.01 | D14: 15 | E14: 0.15 | G14: =B14*D14 -> 4.0503 | H14: =C14*E14 -> 20.2515 | J14: =MAX(G14:I14) -> 20.2515
A15: =Zones!A15 -> Front_Storage_FloorT | B15: =Zones!J15 -> 0.27002 | C15: =Zones!G15 -> 135.01 | D15: 15 | E15: 0.15 | G15: =B15*D15 -> 4.0503 | H15: =C15*E15 -> 20.2515 | J15: =MAX(G15:I15) -> 20.2515
A16: =Zones!A16 -> GuestRoom_1_FloorG | B16: =Zones!J16 -> 1.05318 | C16: =Zones!G16 -> 351.06 | D16: 15 | E16: 0.15 | F16: 20/50 cfm/unit per shower head | G16: =B16*D16 -> 15.7977 | H16: =C16*E16 -> 52.659 | I16: =50 -> 50 | J16: =MAX(G16:I16) -> 52.659 | K16: Ventilation air for this occupancy category shall be permitted to be reduced to zero when the space is in occupied-standby mode
A17: =Zones!A17 -> GuestRoom_2_FloorG | B17: =Zones!J17 -> 1.05318 | C17: =Zones!G17 -> 351.06 | D17: 15 | E17: 0.15 | F17: 20/50 cfm/unit per shower head | G17: =B17*D17 -> 15.7977 | H17: =C17*E17 -> 52.659 | I17: =50 -> 50 | J17: =MAX(G17:I17) -> 52.659
A18: =Zones!A18 -> GuestRoom_3_FloorG | B18: =Zones!J18 -> 1.05318 | C18: =Zones!G18 -> 351.06 | D18: 15 | E18: 0.15 | F18: 20/50 cfm/unit per shower head | G18: =B18*D18 -> 15.7977 | H18: =C18*E18 -> 52.659 | I18: =50 -> 50 | J18: =MAX(G18:I18) -> 52.659
A19: =Zones!A19 -> GuestRoom_4_FloorG | B19: =Zones!J19 -> 1.05309 | C19: =Zones!G19 -> 351.03 | D19: 15 | E19: 0.15 | F19: 20/50 cfm/unit per shower head | G19: =B19*D19 -> 15.79635 | H19: =C19*E19 -> 52.6545 | I19: =50 -> 50 | J19: =MAX(G19:I19) -> 52.6545
A20: =Zones!A20 -> GuestRoom_5_FloorG | B20: =Zones!J20 -> 1.05309 | C20: =Zones!G20 -> 351.03 | D20: 15 | E20: 0.15 | F20: 20/50 cfm/unit per shower head | G20: =B20*D20 -> 15.79635 | H20: =C20*E20 -> 52.6545 | I20: =50 -> 50 | J20: =MAX(G20:I20) -> 52.6545
A21: =Zones!A21 -> GuestRoom_1_FloorM | B21: =Zones!J21 -> 1.05318 | C21: =Zones!G21 -> 351.06 | D21: 15 | E21: 0.15 | F21: 20/50 cfm/unit per shower head | G21: =B21*D21 -> 15.7977 | H21: =C21*E21 -> 52.659 | I21: =50 -> 50 | J21: =MAX(G21:I21) -> 52.659
A22: =Zones!A22 -> GuestRoom_2_5_FloorM | B22: =Zones!J22 -> 4.21272 | C22: =Zones!G22 -> 1404.24 | D22: 15 | E22: 0.15 | F22: 20/50 cfm/unit per shower head | G22: =B22*D22 -> 63.1908 | H22: =C22*E22 -> 210.636 | I22: =50*B22 -> 210.636 | J22: =MAX(G22:I22) -> 210.636
A23: =Zones!A23 -> GuestRoom_6_8_FloorM | B23: =Zones!J23 -> 3.4026 | C23: =Zones!G23 -> 1134.2 | D23: 15 | E23: 0.15 | F23: 20/50 cfm/unit per shower head | G23: =B23*D23 -> 51.039 | H23: =C23*E23 -> 170.13 | I23: =50*B23 -> 170.13 | J23: =MAX(G23:I23) -> 170.13
A24: =Zones!A24 -> GuestRoom_9_12_FloorM | B24: =Zones!J24 -> 4.21272 | C24: =Zones!G24 -> 1404.24 | D24: 15 | E24: 0.15 | F24: 20/50 cfm/unit per shower head | G24: =B24*D24 -> 63.1908 | H24: =C24*E24 -> 210.636 | I24: =50*B24 -> 210.636 | J24: =MAX(G24:I24) -> 210.636
A25: =Zones!A25 -> GuestRoom_13_FloorM | B25: =Zones!J25 -> 1.05318 | C25: =Zones!G25 -> 351.06 | D25: 15 | E25: 0.15 | F25: 20/50 cfm/unit per shower head | G25: =B25*D25 -> 15.7977 | H25: =C25*E25 -> 52.659 | I25: =50*B25 -> 52.659 | J25: =MAX(G25:I25) -> 52.659
A26: =Zones!A26 -> GuestRoom_14_FloorM | B26: =Zones!J26 -> 1.05309 | C26: =Zones!G26 -> 351.03 | D26: 15 | E26: 0.15 | F26: 20/50 cfm/unit per shower head | G26: =B26*D26 -> 15.79635 | H26: =C26*E26 -> 52.6545 | I26: =50*B26 -> 52.6545 | J26: =MAX(G26:I26) -> 52.6545
A27: =Zones!A27 -> GuestRoom_15_18_FloorM | B27: =Zones!J27 -> 4.21242 | C27: =Zones!G27 -> 1404.14 | D27: 15 | E27: 0.15 | F27: 20/50 cfm/unit per shower head | G27: =B27*D27 -> 63.1863 | H27: =C27*E27 -> 210.621 | I27: =50*B27 -> 210.621 | J27: =MAX(G27:I27) -> 210.621
A28: =Zones!A28 -> GuestRoom_19_FloorM | B28: =Zones!J28 -> 1.05312 | C28: =Zones!G28 -> 351.04 | D28: 15 | E28: 0.15 | F28: 20/50 cfm/unit per shower head | G28: =B28*D28 -> 15.7968 | H28: =C28*E28 -> 52.656 | I28: =50*B28 -> 52.656 | J28: =MAX(G28:I28) -> 52.656
A29: =Zones!A29 -> GuestRoom_20_23_FloorM | B29: =Zones!J29 -> 4.21242 | C29: =Zones!G29 -> 1404.14 | D29: 15 | E29: 0.15 | F29: 20/50 cfm/unit per shower head | G29: =B29*D29 -> 63.1863 | H29: =C29*E29 -> 210.621 | I29: =50*B29 -> 210.621 | J29: =MAX(G29:I29) -> 210.621
A30: =Zones!A30 -> GuestRoom_24_FloorM | B30: =Zones!J30 -> 1.05309 | C30: =Zones!G30 -> 351.03 | D30: 15 | E30: 0.15 | F30: 20/50 cfm/unit per shower head | G30: =B30*D30 -> 15.79635 | H30: =C30*E30 -> 52.6545 | I30: =50*B30 -> 52.6545 | J30: =MAX(G30:I30) -> 52.6545
A31: =Zones!A31 -> GuestRoom_1_FloorT | B31: =Zones!J31 -> 1.05318 | C31: =Zones!G31 -> 351.06 | D31: 15 | E31: 0.15 | F31: 20/50 cfm/unit per shower head | G31: =B31*D31 -> 15.7977 | H31: =C31*E31 -> 52.659 | I31: =50*B31 -> 52.659 | J31: =MAX(G31:I31) -> 52.659
A32: =Zones!A32 -> GuestRoom_2_5_FloorT | B32: =Zones!J32 -> 4.21272 | C32: =Zones!G32 -> 1404.24 | D32: 15 | E32: 0.15 | F32: 20/50 cfm/unit per shower head | G32: =B32*D32 -> 63.1908 | H32: =C32*E32 -> 210.636 | I32: =50*B32 -> 210.636 | J32: =MAX(G32:I32) -> 210.636
A33: =Zones!A33 -> GuestRoom_6_8_FloorT | B33: =Zones!J33 -> 3.4026 | C33: =Zones!G33 -> 1134.2 | D33: 15 | E33: 0.15 | F33: 20/50 cfm/unit per shower head | G33: =B33*D33 -> 51.039 | H33: =C33*E33 -> 170.13 | I33: =50*B33 -> 170.13 | J33: =MAX(G33:I33) -> 170.13
... A40: =Zones!A40 -> GuestRoom_24_FloorT | B40: =Zones!J40 -> 1.05309 | C40: =Zones!G40 -> 351.03 | D40: 15 | E40: 0.15 | F40: 20/50 cfm/unit per shower head | G40: =B40*D40 -> 15.79635 | H40: =C40*E40 -> 52.6545 | I40: =50*B40 -> 52.6545 | J40: =MAX(G40:I40) -> 52.6545
A41: =Zones!A41 -> Laundry_FloorG | B41: =Zones!J41 -> 5.26555 | C41: =Zones!G41 -> 1053.11 | D41: 15 | E41: 0.15 | F41: 1 cfm/ft2 for Soiled laundry storage rooms | G41: =B41*D41 -> 78.98325 | H41: =C41*E41 -> 157.9665 | I41: =1*0.2*C41 -> 210.622 | J41: =MAX(G41:I41) -> 210.622 | K41: Only 20% of the laundry space is assumed as "Solied laundry storage room"
A42: =Zones!A42 -> Mech_FloorG | B42: =Zones!J42 -> 0 | C42: =Zones!G42 -> 351.06 | D42: 15 | E42: 0.15 | G42: =B42*D42 -> 0 | H42: =C42*E42 -> 52.659 | J42: =MAX(G42:I42) -> 52.659
A43: =Zones!A43 -> Conference_FloorG | B43: =Zones!J43 -> 28.51695 | C43: =Zones!G43 -> 864.15 | D43: 15 | E43: 0.15 | G43: =B43*D43 -> 427.75425 | H43: =C43*E43 -> 129.6225 | J43: =MAX(G43:I43) -> 427.75425
A44: =Zones!A44 -> Rear_Stair_FloorG | B44: =Zones!J44 -> 1.0804 | C44: =Zones!G44 -> 216.08 | D44: 15 | E44: 0.15 | G44: =B44*D44 -> 16.206 | H44: =C44*E44 -> 32.412 | J44: =MAX(G44:I44) -> 32.412
A45: =Zones!A45 -> Rear_Stair_FloorT | B45: =Zones!J45 -> 1.0804 | C45: =Zones!G45 -> 216.08 | D45: 15 | E45: 0.15 | G45: =B45*D45 -> 16.206 | H45: =C45*E45 -> 32.412 | J45: =MAX(G45:I45) -> 32.412
A46: =Zones!A46 -> Rear_Stair_FloorM | B46: =Zones!J46 -> 1.0804 | C46: =Zones!G46 -> 216.08 | D46: 15 | E46: 0.15 | G46: =B46*D46 -> 16.206 | H46: =C46*E46 -> 32.412 | J46: =MAX(G46:I46) -> 32.412
...

Sheet Water Heater
A1: Water Heater - HotelSmall
A2: Vintage | B2: WH Type | C2: Efficiency | D2: Tank volume (gal) | E2: Tank Loss | G2: Note
A3: Existing | B3: Gas | C3: 0.8 | D3: =F64 -> 107 | E3: =G62 -> 1292.8535 | F3: (Btu/hr)
A4: New Construction | B4: Gas | C4: 0.8 | D4: =F62 -> 107 | E4: =G66 -> 1292.8535 | F4: (Btu/hr)
A6: Peak Hot Water Consumption
A7: Space Name | B7: Baseline WH Type [CEUS 2022] | C7: Total Area (ft²) | D7: Number of People | E7: Hot Water Usage Specification (gal/hr per person) [T24, 2022, Appendix 5.4A , sheet: "2022 SpaceFuncData-Input"] | F7: Peak Hot Water Usage (gal/hr) | G7: Peak Hot Water Usage (gal/min)
A8: =Zones!A3 -> Corridor_FloorG | B8: Gas | C8: =Zones!G3 -> 1782.21 | D8: =Zones!J3 -> 8.91105 | E8: 0 | F8: =E8*D8 -> 0 | G8: =F8/60 -> 0
A9: =Zones!A4 -> Corridor_FloorM | B9: Gas | C9: =Zones!G4 -> 1512.16 | D9: =Zones!J4 -> 7.5608 | E9: 0 | F9: =E9*D9 -> 0 | G9: =F9/60 -> 0
A10: =Zones!A5 -> Corridor_FloorT | B10: Gas | C10: =Zones!G5 -> 1512.16 | D10: =Zones!J5 -> 7.5608 | E10: 0 | F10: =E10*D10 -> 0 | G10: =F10/60 -> 0
A11: =Zones!A6 -> Lounge_FloorG | B11: Gas | C11: =Zones!G6 -> 351.03 | D11: =Zones!J6 -> 11.58399 | E11: 0.09 | F11: =E11*D11 -> 1.0425591 | G11: =F11/60 -> 0.017375985
A12: =Zones!A7 -> Gym_FloorG | B12: Gas | C12: =Zones!G7 -> 351.03 | D12: =Zones!J7 -> 3.5103 | E12: 0.18 | F12: =E12*D12 -> 0.631854 | G12: =F12/60 -> 0.0105309
A13: =Zones!A8 -> Front_Lounge_FloorG | B13: Gas | C13: =Zones!G8 -> 1755.3 | D13: =Zones!J8 -> 57.9249 | E13: 0.09 | F13: =E13*D13 -> 5.213241 | G13: =F13/60 -> 0.08688735
A14: =Zones!A9 -> Front_Office_FloorG | B14: Gas | C14: =Zones!G9 -> 1404.14 | D14: =Zones!J9 -> 7.0207 | E14: 0.18 | F14: =E14*D14 -> 1.263726 | G14: =F14/60 -> 0.0210621
A15: =Zones!A10 -> Front_Stair_FloorG | B15: Gas | C15: =Zones!G10 -> 216.02 | D15: =Zones!J10 -> 0 | E15: 0 | F15: =E15*D15 -> 0 | G15: =F15/60 -> 0
A16: =Zones!A11 -> Front_Stair_FloorM | B16: Gas | C16: =Zones!G11 -> 216.02 | D16: =Zones!J11 -> 0 | E16: 0 | F16: =E16*D16 -> 0 | G16: =F16/60 -> 0
A17: =Zones!A12 -> Front_Stair_FloorT | B17: Gas | C17: =Zones!G12 -> 216.02 | D17: =Zones!J12 -> 0 | E17: 0 | F17: =E17*D17 -> 0 | G17: =F17/60 -> 0
A18: =Zones!A13 -> Front_Storage_FloorG | B18: Gas | C18: =Zones!G13 -> 135.01 | D18: =Zones!J13 -> 0.27002 | E18: 0 | F18: =E18*D18 -> 0 | G18: =F18/60 -> 0
A19: =Zones!A14 -> Front_Storage_FloorM | B19: Gas | C19: =Zones!G14 -> 135.01 | D19: =Zones!J14 -> 0.27002 | E19: 0 | F19: =E19*D19 -> 0 | G19: =F19/60 -> 0
... A55: =Zones!A50 -> Restroom_FloorG | B55: Gas | C55: =Zones!G50 -> 351.06 | D55: =Zones!J50 -> 1.7553 | E55: 0 | F55: =E55*D55 -> 0 | G55: =F55/60 -> 0
A56: Total | C56: =SUM(C8:C55) -> 32404.61 | D56: =SUM(D8:D55) -> 201.26094 | F56: =SUM(F8:F55) -> 265.99794 | G56: =SUM(G8:G55) -> 4.433299
A60: Water Heater Capacity, Tank Capacity, and Tank Loss
A61: WH Type | B61: Peak Hot Water Usage (gal/hr) | C61: Heat Output (Btu/hr) [ACM, 2025, 5.9.2: Rated capacity section] | D61: WH Capacity (Btu/hr) [ACM, 2025, 5.9.2: Rated capacity section] | E61: Required Energy Input (Btu/hr) | F61: Storage Volume (gal) | G61: Standby Loss | H61: Unit | I61: Off/On Cycle Loss Coefficient to Ambient Temp (Btu/h-F) | J61: Source
A62: Gas storage WH | B62: =SUMIFS(F8:F55,B8:B55,"Gas") -> 265.99794 | C62: =B62*(B66-B67)*8.2877*1 -> 165338.33 | D62: =C62*B68 -> 99203 | E62: =D62/C4 -> 124003.75 | F62: =ROUNDUP((B62*F64)/B64,0) -> 107 | G62: =(E62/800)+110*SQRT(F62) -> 1292.8535 | H62: Btu/hr | I62: =G62/B73 -> 20.852476 | J62: Standby loss equation: Title 20, §1605.1 Table F-4 WH capacity equation: ACM, 2025, 5.9.2: Rated capacity section)
A63: Electric resistance WH | B63: =SUMIFS(F8:F55,B8:B55,"Electric") -> 0 | C63: =B63*(B66-B67)*8.2877*1 -> 0 | D63: =C63*B68 -> 0 | F63: =ROUNDUP((B63*F64)/B64,0) -> 0 | H63: %/hr | I63: =0.0834*G63*F63 -> 0
A64: Total | B64: =B62+B63 -> 265.99794 | F64: =ROUNDUP(B64*1*B69,0) -> 107
A66: Design supply temperature (F) | B66: 130 | C66: Ref: T24 2022 - Appendix 5.4B | F66: Standby Loss for Existing | G66: =(E62/800)+110*SQRT(F64) -> 1292.8535 | H66: Btu/hr | I66: =G66/B73 -> 20.852476
A67: Cold Water supply temperature (F) | B67: 55 | C67: Ref: ACM, 2025, 5.9.2: Rated capacity section
A68: WH system factor | B68: 0.6 | C68: Ref: ACM, 2025, 5.9.2: Rated capacity section
A69: Reheat multiplier | B69: 0.4 | C69: Ref: ACM, 2025, 5.9.2: Storage Volume
A70: * The 0.40 multiplier is a storage sizing factor used to account for the fact that the water heater doesn't need to store the full peak hour demand—it can reheat water during that time. This factor assumes that the heater will recover part of the hot water used during the peak hour, so only 40% of the peak hour demand needs to be stored at any given moment.
A72: Ambient temp | B72: 68
A73: Delta T | B73: =B66-B72 -> 62
A74: ** For Electric Water Heater: UA(Btu/h-°F)​= 0.0834 *SL​ (%/hr)*V gal

Sheet Ext Lighting
A1: Exterior Lighting - HotelSmall
A2: Motion Controlled Luminaires (W) | B2: Non-motion Controlled Luminaires (W) | C2: Total (W) | D2: Source
A3: =G16 -> 1062.0784 | B3: =G17 -> 742.68323 | C3: =A3+B3 -> 1804.7616 | D3: T24, 2025
A8: Exterior Lighting
A9: Items (Assume LZ2) | B9: Assumptions [2019 Outdoor Lighting CASE Report & PNNL 90.1-2010 TSD] | D9: Unit | E9: Lighting Power Allowance [T24, 2025, Table 140.7-A & 140.7-B] | F9: Unit | G9: Exterior Lighting Power (W)
A10: IWA (Initial Wage Allowance) | E10: 200 | F10: (W) | G10: =$E10 -> 200
A11: Parking area | B11: 400 ft² for every parking space 1 parking space per 360 ft² of gross building area | C11: =B23/360*400 -> 36005.122 | D11: (ft²) | E11: 0.019 | F11: (W/ft²) | G11: =$E11*C11 -> 684.09732
A12: Building Entrance | B12: 2 building entrance (1 per 10,000 ft² footprint) | C12: =2 -> 2 | D12: (count) | E12: 15 | F12: (W/ea) | G12: =E12*2 -> 30
A13: Hardscape Ornamental Light | B13: 0.1 ft² per 1 ft² of gross building area for hardscape ornamental light | C13: =B23*0.1 -> 3240.461 | D13: (ft²) | E13: 0.007 | F13: (W/ft²) | G13: =E13*C13 -> 22.683227
A14: Building façade | B14: 0.1 W per 1 ft² of facade area Façade Area = Perimeter × 0.5 × 29 ft (30 ft is the max height that is lit) * The 0.5 factor assumes that only half of the perimeter walls are lit. -Formula ia developed based on the 2019 Outdoor Lighting CASE report | C14: =B22*0.5*30 -> 7200 | D14: (ft²) | E14: 0.1 | F14: (W/ft²) | G14: =E14*C14 -> 720
A15: Non-sales canopy | C15: =(B23/B24)*0.1 -> 1080.1537 | D15: (ft²) | E15: 0.137 | F15: (W/ft²) | G15: =E15*C15 -> 147.98105
A16: Motion controlled Luminaires | G16: =G11+G10+G15+G12 -> 1062.0784
A17: Non-motion-controlled Luminaires | G17: =G13+G14 -> 742.68323
A18: Total | G18: =G16+G17 -> 1804.7616
A20: *Developed based on 2019 Outdoor Lighting CASE Report
A22: Perimeter (ft) | B22: =(180+60)*2 -> 480
A23: Total floor area (ft²) | B23: =Zones!G51 -> 32404.61
A24: Floors | B24: 3

Sheet Interior Lights
A1: Interior Lighting - HotelSmall
A2: Space Type | B2: New Construction | E2: Existing
B3: LPD (W/ft²) | C3: Additional LPD for Portable Lighting (W/ft²) | D3: Source | E3: LPD (W/ft²) | F3: Additional LPD for Portable Lighting (W/ft²) | G3: Source
A4: =Zones!B3 -> Corridor Area | B4: 0.4 | D4: T24, 2025, Table 140.6-C PNNL ASHRAE 90.1 2022 for Guest Room (Area category method) | E4: 0.6 | G4: T24, 2019, Table 140.6-C CBECC 2019 for Guest Room (Area category method)
A5: =Zones!B6 -> Lounge, Breakroom, or Waiting Area | B5: 0.55 | E5: 0.85
A6: =Zones!B7 -> Exercise/Fitness Center and Gymnasium Areas | B6: 0.5 | E6: 0.5
A7: =Zones!B9 -> Office Area (>250 square feet) | B7: 0.6 | E7: 0.7
A8: =Zones!B10 -> Stairwell | B8: 0.6 | E8: 0.5
A9: =Zones!B13 -> Storage (General) | B9: 0.4 | E9: 0.4
A10: =Zones!B16 -> Hotel/Motel Guest Room | B10: 0.41 | E10: 1.27
A11: =Zones!B41 -> Laundry Area | B11: 0.45 | E11: 0.45
A12: =Zones!B42 -> Electrical, Mechanical, Telephone Rooms | B12: 0.4 | E12: 0.4
A13: =Zones!B43 -> Convention, Conference, Multipurpose and Meeting Area | B13: 0.75 | E13: 0.85
A14: =Zones!B50 -> Restrooms | B14: 0.65 | E14: 0.65
A16: Comply with 130.1(c)8: Hotel/motel guest rooms shall be controlled with one of the following controls such that, no longer than 20 minutes after the guest room has been vacated, lighting power is switched off: i. Captive card key controls; or ii. Occupant sensing controls; or iii. Other automatic controls.
A22: Background Data [To be deleted prior to publication]

Sheet Equipment
A1: Equipment - HotelSmall
A2: Space Type | B2: Plug load Power Density (W/ft²) | C2: Gas Power Density (Btu/hr-ft²) | D2: Refrigeration Power Density (W/ft²) | E2: Source | F2: Note
A3: =Zones!B3 -> Corridor Area | B3: 0 | E3: T24 2022 - Appendix 5.4A
A4: =Zones!B6 -> Lounge, Breakroom, or Waiting Area | B4: 1
A5: =Zones!B7 -> Exercise/Fitness Center and Gymnasium Areas | B5: 0.5
A6: =Zones!B9 -> Office Area (>250 square feet) | B6: 0.7 | E6: Plug load and schedules project with CEC, 2025
A7: =Zones!B10 -> Stairwell | B7: 0 | E7: T24 2022 - Appendix 5.4A
A8: =Zones!B13 -> Storage (General) | B8: 0.2
A9: =Zones!B16 -> Hotel/Motel Guest Room | B9: 0.5 | E9: Plug load and schedules project with CEC, 2025
A10: =Zones!B41 -> Laundry Area | B10: 3 | C10: 0.75 | E10: T24 2022 - Appendix 5.4A | F10: Appendix 5.4A: Gas equipment=0.75 Btu/hr-ft² (CEC model (small Hotel) has the Gas equipment for 3.6 Btu/hr-ft²)
A11: =Zones!B42 -> Electrical, Mechanical, Telephone Rooms | B11: 3
A12: =Zones!B43 -> Convention, Conference, Multipurpose and Meeting Area | B12: 1
A13: =Zones!B50 -> Restrooms | B13: 0
A15: Elevator-Hotel Small
A16: Vintage | B16: No. of Elevators | C16: Cab Lighting Power Limit | D16: Lighting Shutoff | E16: Cab Fan Control | F16: Fan Power Limit | G16: Regenerative Drive Threshold | H16: Design load (W) | I16: Note
A17: Existing | B17: =ROUND((32400*0.7/50000)+ROUND(3/2,0),0) -> 2 | C17: n/a | D17: n/a | E17: n/a | F17: n/a | G17: n/a | H17: 16000 | I17: Design Load based on PNNL ASHRAE 90.1 2013 Small Hotel prototype
A18: New Construction | B18: =ROUND((32400*0.7/50000)+ROUND(3/2,0),0) -> 2 | C18: ≤ 0.6 W/ft² of cab floor area- Exempt (covered process) | D18: Automatic shut‑off after ≤ 5 min no‑occupancy | E18: When the elevator cab is stopped and unoccupied with doors closed for over 15 minutes, the cab interior lighting and ventilation fans shall be switched off until elevator cab operation resumes. | F18: ≤ 0.33 W per cfm of fan airflow | G18: n/a | H18: 9000 | I18: Design Load based on PNNL ASHRAE 90.1 2022 Small Hotel prototype --- per T24 2025 §120.6 (f)
A21: Background Data [To be deleted prior to publication]
C22: Equipment (Plug load)
C23: Zones | D23: floor area (ft²) | E23: Plug load Intensity (W/ft²) | F23: Total equipment load (W)
C24: Open_Office_N | D24: 913.68642 | E24: 1.5 | F24: =E24*D24/SUM($D$24:$D$33) -> 0.24918721
C25: Closed_Office_W | D25: 909.75659 | E25: 1.5 | F25: =E25*D25/SUM($D$24:$D$33) -> 0.24811543
C26: Closed_Office_E | D26: 909.75659 | E26: 1.5 | F26: =E26*D26/SUM($D$24:$D$33) -> 0.24811543
C27: Conference | D27: 456.84321 | E27: 1 | F27: =E27*D27/SUM($D$24:$D$33) -> 0.083062402
C28: Lobby + Lounge | D28: 456.84321 | E28: 0.5 | F28: =E28*D28/SUM($D$24:$D$33) -> 0.041531201
C29: Storage | D29: 763.37881 | E29: 0.2 | F29: =E29*D29/SUM($D$24:$D$33) -> 0.027759229
C30: Mechanical/Electrical | D30: 118.61264 | E30: 3 | F30: =E30*D30/SUM($D$24:$D$33) -> 0.064697806
C31: Restroom | D31: 237.22529 | E31: 0 | F31: =E31*D31/SUM($D$24:$D$33) -> 0
C32: Break/Copy Room | D32: 118.61264 | E32: 1 | F32: =E32*D32/SUM($D$24:$D$33) -> 0.021565935
C33: Corridor | D33: 615.2846 | E33: 0 | F33: =E33*D33/SUM($D$24:$D$33) -> 0
F34: =SUM(F24:F33) -> 0.98403464
B37: Equipment (Plug Load )- Prototypes comparison
B38: Unit | C38: CEC OffSml | D38: DEER OFS | E38: PNNL | F38: ComStock | G38: Note
B39: W/m2 | C39: 16.145866 | D39: 16.145866 | E39: 6.78 | G39: PNNL considers higher load for electric equipment
B40: Yearly Load multiplier | C40: =B83*249+C83*52+D83*(364-249-52) -> 2835.7 | D40: =K83*249+L83*52+M83*(364-249-52) -> 2835.7 | E40: =F83*249+G83*52+I83*(364-249-52) -> 3837.815 | K40: =D39*D40 -> 45784.831 | L40: =E39*E40 -> 26020.386
F57: PNNL 2022 | K57: DEER 2024
B58: CEC-Weekday | C58: CEC-Saturday | D58: CEC-Sunday | F58: PNNL-Weekday | G58: PNNL-Saturday | I58: PNNL-Sunday | K58: DEER-Weekday | L58: DEER-Saturday | M58: DEER-OtherDays
A59: 1 | B59: 0.05 | C59: 0.05 | D59: 0.05 | F59: 0.40947756 | G59: 0.16379102 | I59: 0.16379102 | K59: 0.05 | L59: 0.05 | M59: 0.05
A60: =A59+1 -> 2 | B60: 0.05 | C60: 0.05 | D60: 0.05 | F60: 0.40947756 | G60: 0.16379102 | I60: 0.16379102 | K60: 0.05 | L60: 0.05 | M60: 0.05
A61: =A60+1 -> 3 | B61: 0.05 | C61: 0.05 | D61: 0.05 | F61: 0.40947756 | G61: 0.16379102 | I61: 0.16379102 | K61: 0.05 | L61: 0.05 | M61: 0.05
...

Sheet Schedules
A1: Schedules - HotelSmall
A2: Zone | B2: Schedule Category | C2: Schedule | D2: Source | E2: Day | F2: Hour
F3: 1 | G3: 2 | H3: 3 | I3: 4 | J3: 5 | K3: 6 | L3: 7 | M3: 8 | N3: 9 | O3: 10 | P3: 11 | Q3: 12 | R3: 13 | S3: 14 | T3: 15 | U3: 16 | V3: 17 | W3: 18 | X3: 19 | Y3: 20 | Z3: 21 | AA3: 22 | AB3: 23 | AC3: 24
A4: Gym,Storage,Laundry,Mech,Conferences | B4: Assembly | C4: Occupancy | D4: T24 2022 - Appendix 5.4B, [Assembly] | E4: Weekday | F4: 0 | G4: 0 | H4: 0 | I4: 0 | J4: 0 | K4: 0 | L4: 0 | M4: 0 | N4: 0.2 | O4: 0.2 | P4: 0.2 | Q4: 0.8 | R4: 0.8 | S4: 0.8 | T4: 0.8 | U4: 0.8 | V4: 0.8 | W4: 0.8 | X4: 0.2 | Y4: 0.2 | Z4: 0.2 | AA4: 0.2 | AB4: 0.1 | AC4: 0
E5: Saturday | F5: 0 | G5: 0 | H5: 0 | I5: 0 | J5: 0 | K5: 0 | L5: 0 | M5: 0 | N5: 0.2 | O5: 0.2 | P5: 0.2 | Q5: 0.6 | R5: 0.6 | S5: 0.6 | T5: 0.6 | U5: 0.6 | V5: 0.6 | W5: 0.6 | X5: 0.6 | Y5: 0.6 | Z5: 0.6 | AA5: 0.8 | AB5: 0.1 | AC5: 0
E6: Sunday | F6: 0 | G6: 0 | H6: 0 | I6: 0 | J6: 0 | K6: 0 | L6: 0 | M6: 0 | N6: 0.1 | O6: 0.1 | P6: 0.1 | Q6: 0.1 | R6: 0.1 | S6: 0.7 | T6: 0.7 | U6: 0.7 | V6: 0.7 | W6: 0.7 | X6: 0.7 | Y6: 0.7 | Z6: 0.7 | AA6: 0.7 | AB6: 0.2 | AC6: 0
A7: Gym,Laundry,Mech,Conference | B7: Assembly | C7: Lights | D7: T24 2022 - Appendix 5.4B, [Assembly] | E7: Weekday | F7: 0.05 | G7: 0.05 | H7: 0.05 | I7: 0.05 | J7: 0.05 | K7: 0.05 | L7: 0.35 | M7: 0.35 | N7: 0.35 | O7: 0.65 | P7: 0.65 | Q7: 0.65 | R7: 0.65 | S7: 0.65 | T7: 0.65 | U7: 0.65 | V7: 0.65 | W7: 0.65 | X7: 0.65 | Y7: 0.65 | Z7: 0.65 | AA7: 0.65 | AB7: 0.25 | AC7: 0.05
E8: Saturday | F8: 0.05 | G8: 0.05 | H8: 0.05 | I8: 0.05 | J8: 0.05 | K8: 0.05 | L8: 0.05 | M8: 0.3 | N8: 0.3 | O8: 0.4 | P8: 0.4 | Q8: 0.4 | R8: 0.4 | S8: 0.4 | T8: 0.4 | U8: 0.4 | V8: 0.4 | W8: 0.4 | X8: 0.4 | Y8: 0.4 | Z8: 0.4 | AA8: 0.4 | AB8: 0.4 | AC8: 0.05
E9: Sunday | F9: 0.05 | G9: 0.05 | H9: 0.05 | I9: 0.05 | J9: 0.05 | K9: 0.05 | L9: 0.05 | M9: 0.3 | N9: 0.3 | O9: 0.3 | P9: 0.3 | Q9: 0.3 | R9: 0.55 | S9: 0.55 | T9: 0.55 | U9: 0.55 | V9: 0.55 | W9: 0.55 | X9: 0.55 | Y9: 0.55 | Z9: 0.55 | AA9: 0.55 | AB9: 0.05 | AC9: 0.05
A10: Gym,Storage,Laundry,Mech,Conference | B10: Assembly | C10: ElecEquipment | D10: T24 2022 - Appendix 5.4B, [Assembly] | E10: Weekday | F10: 0.05 | G10: 0.05 | H10: 0.05 | I10: 0.05 | J10: 0.05 | K10: 0.05 | L10: 0.4 | M10: 0.4 | N10: 0.4 | O10: 0.75 | P10: 0.75 | Q10: 0.75 | R10: 0.75 | S10: 0.75 | T10: 0.75 | U10: 0.75 | V10: 0.75 | W10: 0.75 | X10: 0.75 | Y10: 0.75 | Z10: 0.75 | AA10: 0.75 | AB10: 0.25 | AC10: 0.05
E11: Saturday | F11: 0.05 | G11: 0.05 | H11: 0.05 | I11: 0.05 | J11: 0.05 | K11: 0.05 | L11: 0.05 | M11: 0.3 | N11: 0.3 | O11: 0.5 | P11: 0.5 | Q11: 0.5 | R11: 0.5 | S11: 0.5 | T11: 0.5 | U11: 0.5 | V11: 0.5 | W11: 0.5 | X11: 0.5 | Y11: 0.5 | Z11: 0.5 | AA11: 0.5 | AB11: 0.5 | AC11: 0.05
E12: Sunday | F12: 0.05 | G12: 0.05 | H12: 0.05 | I12: 0.05 | J12: 0.05 | K12: 0.05 | L12: 0.05 | M12: 0.3 | N12: 0.3 | O12: 0.3 | P12: 0.3 | Q12: 0.3 | R12: 0.65 | S12: 0.65 | T12: 0.65 | U12: 0.65 | V12: 0.65 | W12: 0.65 | X12: 0.65 | Y12: 0.65 | Z12: 0.65 | AA12: 0.65 | AB12: 0.05 | AC12: 0.05
A13: Gym,Storage,Laundry,Mech,Conference | B13: Assembly | C13: HVACAvail | D13: T24 2022 - Appendix 5.4B, [Assembly] | E13: Weekday | F13: 0 | G13: 0 | H13: 0 | I13: 0 | J13: 0 | K13: 0 | L13: 0 | M13: 1 | N13: 1 | O13: 1 | P13: 1 | Q13: 1 | R13: 1 | S13: 1 | T13: 1 | U13: 1 | V13: 1 | W13: 1 | X13: 1 | Y13: 1 | Z13: 1 | AA13: 1 | AB13: 1 | AC13: 0
E14: Saturday | F14: 0 | G14: 0 | H14: 0 | I14: 0 | J14: 0 | K14: 0 | L14: 0 | M14: 1 | N14: 1 | O14: 1 | P14: 1 | Q14: 1 | R14: 1 | S14: 1 | T14: 1 | U14: 1 | V14: 1 | W14: 1 | X14: 1 | Y14: 1 | Z14: 1 | AA14: 1 | AB14: 1 | AC14: 0
E15: Sunday | F15: 0 | G15: 0 | H15: 0 | I15: 0 | J15: 0 | K15: 0 | L15: 0 | M15: 1 | N15: 1 | O15: 1 | P15: 1 | Q15: 1 | R15: 1 | S15: 1 | T15: 1 | U15: 1 | V15: 1 | W15: 1 | X15: 1 | Y15: 1 | Z15: 1 | AA15: 1 | AB15: 1 | AC15: 0
A16: Gym,Storage,Laundry,Mech,Conference | B16: Assembly | C16: ServiceHotWater | D16: T24 2022 - Appendix 5.4B, [Assembly] | E16: Weekday | F16: 0 | G16: 0 | H16: 0 | I16: 0 | J16: 0 | K16: 0 | L16: 0 | M16: 0 | N16: 0 | O16: 0.05 | P16: 0.05 | Q16: 0.35 | R16: 0.05 | S16: 0.05 | T16: 0.05 | U16: 0.05 | V16: 0.05 | W16: 0 | X16: 0 | Y16: 0 | Z16: 0 | AA16: 0 | AB16: 0 | AC16: 0
E17: Saturday | F17: 0 | G17: 0 | H17: 0 | I17: 0 | J17: 0 | K17: 0 | L17: 0 | M17: 0 | N17: 0 | O17: 0.05 | P17: 0.05 | Q17: 0.2 | R17: 0 | S17: 0 | T17: 0 | U17: 0 | V17: 0 | W17: 0 | X17: 0 | Y17: 0.65 | Z17: 0.3 | AA17: 0 | AB17: 0 | AC17: 0
E18: Sunday | F18: 0 | G18: 0 | H18: 0 | I18: 0 | J18: 0 | K18: 0 | L18: 0 | M18: 0 | N18: 0 | O18: 0.05 | P18: 0.05 | Q18: 0.1 | R18: 0 | S18: 0 | T18: 0 | U18: 0 | V18: 0 | W18: 0 | X18: 0 | Y18: 0.65 | Z18: 0.3 | AA18: 0 | AB18: 0 | AC18: 0
A19: Gym,Storage,Laundry,Mech,Conference | B19: Assembly | C19: Infiltration | D19: T24 2022 - Appendix 5.4B, [Assembly] | E19: Weekday | F19: 1 | G19: 1 | H19: 1 | I19: 1 | J19: 1 | K19: 1 | L19: 1 | M19: 0.25 | N19: 0.25 | O19: 0.25 | P19: 0.25 | Q19: 0.25 | R19: 0.25 | S19: 0.25 | T19: 0.25 | U19: 0.25 | V19: 0.25 | W19: 0.25 | X19: 0.25 | Y19: 0.25 | Z19: 0.25 | AA19: 0.25 | AB19: 0.25 | AC19: 1
E20: Saturday | F20: 1 | G20: 1 | H20: 1 | I20: 1 | J20: 1 | K20: 1 | L20: 1 | M20: 0.25 | N20: 0.25 | O20: 0.25 | P20: 0.25 | Q20: 0.25 | R20: 0.25 | S20: 0.25 | T20: 0.25 | U20: 0.25 | V20: 0.25 | W20: 0.25 | X20: 0.25 | Y20: 0.25 | Z20: 0.25 | AA20: 0.25 | AB20: 0.25 | AC20: 1
E21: Sunday | F21: 1 | G21: 1 | H21: 1 | I21: 1 | J21: 1 | K21: 1 | L21: 1 | M21: 0.25 | N21: 0.25 | O21: 0.25 | P21: 0.25 | Q21: 0.25 | R21: 0.25 | S21: 0.25 | T21: 0.25 | U21: 0.25 | V21: 0.25 | W21: 0.25 | X21: 0.25 | Y21: 0.25 | Z21: 0.25 | AA21: 0.25 | AB21: 0.25 | AC21: 1
A22: Laundry | B22: Assembly | C22: GasEquipment | D22: T24 2022 - Appendix 5.4B, [Assembly] | E22: Weekday | F22: 0 | G22: 0 | H22: 0 | I22: 0 | J22: 0 | K22: 0 | L22: 0 | M22: 0 | N22: 0.3 | O22: 0.3 | P22: 0.2 | Q22: 0.9 | R22: 0.9 | S22: 0.9 | T22: 0.2 | U22: 0.2 | V22: 0.2 | W22: 0.5 | X22: 0.5 | Y22: 0.1 | Z22: 0.1 | AA22: 0.1 | AB22: 0 | AC22: 0
E23: Saturday | F23: 0 | G23: 0 | H23: 0 | I23: 0 | J23: 0 | K23: 0 | L23: 0 | M23: 0 | N23: 0.3 | O23: 0.3 | P23: 0.2 | Q23: 0.7 | R23: 0.7 | S23: 0.7 | T23: 0.2 | U23: 0.2 | V23: 0.2 | W23: 0.4 | X23: 0.4 | Y23: 0.1 | Z23: 0.1 | AA23: 0.1 | AB23: 0 | AC23: 0
E24: Sunday | F24: 0 | G24: 0 | H24: 0 | I24: 0 | J24: 0 | K24: 0 | L24: 0 | M24: 0 | N24: 0.2 | O24: 0.2 | P24: 0.1 | Q24: 0.1 | R24: 0.3 | S24: 0.8 | T24: 0.2 | U24: 0.2 | V24: 0.2 | W24: 0.5 | X24: 0.5 | Y24: 0.1 | Z24: 0.1 | AA24: 0.1 | AB24: 0 | AC24: 0
A25: Gym,Storage,Laundry,Mech,Conference | B25: Assembly | C25: HtgSetpt | D25: Honeywell-INNCOM e7 Thermostat User Guide & Engineering Judgement | E25: Weekday | F25: =IF((F13=1),Thermostat!$B$3,Thermostat!$B$4) -> 60 | G25: =IF((G13=1),Thermostat!$B$3,Thermostat!$B$4) -> 60 | H25: =IF((H13=1),Thermostat!$B$3,Thermostat!$B$4) -> 60 | I25: =IF((I13=1),Thermostat!$B$3,Thermostat!$B$4) -> 60 | J25: =IF((J13=1),Thermostat!$B$3,Thermostat!$B$4) -> 60 | K25: =IF((K13=1),Thermostat!$B$3,Thermostat!$B$4) -> 60 | L25: =IF((L13=1),Thermostat!$B$3,Thermostat!$B$4) -> 60 | M25: =IF((M13=1),Thermostat!$B$3,Thermostat!$B$4) -> 70 | ... AC25: =IF((AC13=1),Thermostat!$B$3,Thermostat!$B$4) -> 60
E26: Saturday | F26: =IF((F14=1),Thermostat!$B$3,Thermostat!$B$4) -> 60 | G26: =IF((G14=1),Thermostat!$B$3,Thermostat!$B$4) -> 60 | H26: =IF((H14=1),Thermostat!$B$3,Thermostat!$B$4) -> 60 | I26: =IF((I14=1),Thermostat!$B$3,Thermostat!$B$4) -> 60 | J26: =IF((J14=1),Thermostat!$B$3,Thermostat!$B$4) -> 60 | K26: =IF((K14=1),Thermostat!$B$3,Thermostat!$B$4) -> 60 | L26: =IF((L14=1),Thermostat!$B$3,Thermostat!$B$4) -> 60 | M26: =IF((M14=1),Thermostat!$B$3,Thermostat!$B$4) -> 70 | ... AC26: =IF((AC14=1),Thermostat!$B$3,Thermostat!$B$4) -> 60
E27: Sunday | F27: =IF((F15=1),Thermostat!$B$3,Thermostat!$B$4) -> 60 | G27: =IF((G15=1),Thermostat!$B$3,Thermostat!$B$4) -> 60 | H27: =IF((H15=1),Thermostat!$B$3,Thermostat!$B$4) -> 60 | I27: =IF((I15=1),Thermostat!$B$3,Thermostat!$B$4) -> 60 | J27: =IF((J15=1),Thermostat!$B$3,Thermostat!$B$4) -> 60 | K27: =IF((K15=1),Thermostat!$B$3,Thermostat!$B$4) -> 60 | L27: =IF((L15=1),Thermostat!$B$3,Thermostat!$B$4) -> 60 | M27: =IF((M15=1),Thermostat!$B$3,Thermostat!$B$4) -> 70 | ... AC27: =IF((AC15=1),Thermostat!$B$3,Thermostat!$B$4) -> 60
