Workbook
Name nonparticipating_forecastzone_scale_factor: #REF!
Name nonparticipating_forecastzone_scale_factor: 'Energy Usage'!$P$27
Name Space_Function: Data!$A$2:$A$76

Sheet Notes
A1: Data Sources
A2: Dataset | B2: Dodge 2023
B3: CEUS 2022
B4: CBECS 2018
B5: ComStock 2023
A6: Prototype | B6: CEC Small Office prototype (CBECC 2022.3.1) | C6: https://bees.noresco.com/software2022.html
B7: PNNL Small Office prototype (90.1-2022) | C7: https://www.energycodes.gov/prototype-building-models#Commercial
B8: DEER Small Office prototype (June 2023) | C8: https://github.com/sound-data/DEER-Prototypes-EnergyPlus
B9: ORNL 2019 Small Office prototype zoning | C9: https://web.eecs.utk.edu/~jnew1/publications/2019_IBPSA_OpenStudioOffice.pdf
A10: Codes | B10: T24, referred to as T24 (1984, 1992,1998, 2001, 2005, 2008, 2013, 2016,2019, 2022, 2025)
B11: ASHRAE 90.1 (2022)
B12: CFR Title 10 (2010) | C12: https://www.govinfo.gov/content/pkg/FR-2009-03-23/pdf/FR-2009-03-23.pdf
B13: CFR Title 10 (2013) | C13: https://www.govinfo.gov/content/pkg/CFR-2013-title10-vol3/pdf/CFR-2013-title10-vol3-part431.pdf
B14: CFR Title 10 (2024) | C14: https://www.govinfo.gov/content/pkg/CFR-2024-title10-vol3/pdf/CFR-2024-title10-vol3-part431-subpartF.pdf
A15: Others | B15: https://www.mass.gov/doc/small-office-prototype-basis-of-design-report/download | C15: https://www.mass.gov/lists/stretch-energy-code-development-support-documentation
B16: Massachusetts uses commercial prototype for its stretch code energy analysis and the above ones are the supporting documents for small office prototype
B17: ACM (2022)
B18: Title 24, 2022 - Appendix 5.4A and Appendix 5.4B | C18: https://www.energy.ca.gov/publications/2022/2022-nonresidential-and-multifamily-alternative-calculation-method-reference | D18: https://www.energy.ca.gov/publications/2022/2022-nonresidential-and-multifamily-alternative-calculation-method-reference | E18: https://www.energy.ca.gov/publications/2022/2022-nonresidential-and-multifamily-alternative-calculation-method-reference | F18: https://www.energy.ca.gov/publications/2022/2022-nonresidential-and-multifamily-alternative-calculation-method-reference
B19: 2022 Reduced infiltration CASE report | C19: https://title24stakeholders.com/wp-content/uploads/2020/10/2022-T24-Final-CASE-Report_Reduce-Infiltration.pdf | D19: https://title24stakeholders.com/wp-content/uploads/2020/10/2022-T24-Final-CASE-Report_Reduce-Infiltration.pdf | E19: https://title24stakeholders.com/wp-content/uploads/2020/10/2022-T24-Final-CASE-Report_Reduce-Infiltration.pdf | F19: https://title24stakeholders.com/wp-content/uploads/2020/10/2022-T24-Final-CASE-Report_Reduce-Infiltration.pdf
B20: PNNL 20405, 2010 | C20: https://www.pnnl.gov/main/publications/external/technical_reports/PNNL-20405.pdf | D20: file:///N:/Prj_SUS/2023/S23668%20SCE%20CA%20Prototypes%20Development/Technical/NR/0_Input%20data/Lighting/PNNL-20405.pdf | E20: file:///N:/Prj_SUS/2023/S23668%20SCE%20CA%20Prototypes%20Development/Technical/NR/0_Input%20data/Lighting/PNNL-20405.pdf | F20: file:///N:/Prj_SUS/2023/S23668%20SCE%20CA%20Prototypes%20Development/Technical/NR/0_Input%20data/Lighting/PNNL-20405.pdf
B21: Air leakage Memo, NORESCO, 2025 | C21: Infiltration_rate_report_14May2025-Short-Version.docx | D21: Infiltration_rate_report_14May2025-Short-Version.docx | E21: Infiltration_rate_report_14May2025-Short-Version.docx | F21: Infiltration_rate_report_14May2025-Short-Version.docx
A24: Construction Rate
A37: Notes
B38: Saturation is defined as the % of total floorspace for each combination of end-use and fuel-type. | I38: 1978-84 | J38: 1985-97 | K38: 1992-1997
A39: 1986 is the representative year for the 1984-1997 vintage bin | B39: Most offices in this vintage bin were built after 1984 (more than 53% ) and the CA energy code did not noticeably changed between 1984 to 1992) . Edition 1986 included 6 prescriptive package per CZ for office buildings compared to 1984 with 3 package per CZ. Also "Heat Capacity" for external wall is considered between 10.0 to 14.99 (BTU/F/ft²) Package A was selected for the thermal properties | H39: Construction rate (Dodge 2023 data for new small offices) | I39: 0.46536943 | J39: 0.53462988 | K39: 0.093651419
A40: 2001 is the representative year for the 1998-2007 vintage bin | B40: Wall and roof prescriptive criteria from 1998 to 2005 remain unchanged except for CZ2 and 6 in 2001 code (the percentage of change is less than 10%). Since the construction rate between 1998-2005 is greater than the 2006-2007 period, the envelope properties of 1998 -2005 were chosen for envelope properties. Since the windows requirement considerably changed in the 2001 code, the nominated year for this vintage is 2001. It should be noticed that, only one Title 24 should be chosen within each vintage bin for building envelope properties since the entire envelope is built at once. We can't choose 1998 for walls and 2001 for windows. Wall and roof prescriptive criteria from 1998 to 2005 remain unchanged except for CZ2 and 6 in 2001 version (the percentage of change is less than 10%).
A41: 2013 is the representative year for the 2008-2018 vintage bin | B41: Wall properties remain unchanged from the 2008 code to the 2016 code but the roof did changed. Although the 2016 code introduced improvement for roof in nearly all CZ and for wall in a few CZ, and construction activity surged between 2017 and 2018, the extended period from 2008 to 2016 resulted in a higher construction rate during that time . As a result, it was decided to select the code that was effective during 2008-2016. The 2013 code modified the solar reflectance requirement for low-sloped roof products ( by approximately 15%), and enhanced window properties. Therefore, the 2013 code was chosen as the representative code. Additionally, construction activity from 2014-2018 was higher compared to 2008-2013 period.

Sheet Prototype
A1: NORESCO, Updated November 2025
A2: OfficeSmall
A3: Characteristic | B3: Value | C3: Data Sources
A4: Building Type | B4: Small Office
A5: Building Category | B5: Nonresidential
A6: Vintages | B6: 4 Vintages: Pre-1978 , 1978-1997 ,1998-2007 , 2008-2018 New Construction (2019+) | C6: Based on the vintage bin analysis | D6: NonRes-Vintage bins-Draft Report-30Nov2023-Final.docx
A7: Shape | C7: Rectangular shape is supported by CBECS, CEC, and PNNL
A8: Total Floor Area (ft²) | B8: 5502 (90.8 ft x 60.5ft) | C8: Supported by Dodge 2023 data (Same as CEC and PNNL)
A9: Aspect Ratio | B9: 1.5 | C9: Same as CEC and PNNL
A10: Number of Floors | B10: 1 | C10: Supported by Dodge 2023 data -(Same as CEC and PNNL) DEER considered two floors
A11: Roof type | B11: Tilted (Steep-Sloped) | C11: Supported by CBECS 2018 data (Same as CEC and PNNL)
A12: WWR | B12: 24.4% for South and 19.8% for the other three orientations | C12: CEC: overall 21.2% same as PNNL DEER: 33% in all directions CBECS: 2-25%
A13: Shading Geometry | B13: No Shades | C13: Same as CEC and PNNL
A14: Floor to floor height (feet) | B14: 10 | C14: Same as CEC and PNNL
A15: Floor to ceiling height (feet) | B15: 10 | C15: Same as CEC and PNNL
A16: Glazing sill height (feet) | B16: 3 (top of the window is 8 ft high with 5 ft high glass) | C16: Same as CEC and PNNL
A34: Background Data [To be deleted prior to publication]
D40: Equipment (Plug Load )- Prototypes comparison
D41: Unit | E41: CEC OffSml | F41: DEER OFS | G41: PNNL | H41: ComStock | I41: Note
D42: W/ft2 | E42: 1.5 | F42: 1.5 | G42: 0.63 | I42: PNNL considers higher load for electric equipment
D43: Yearly Load multiplier | E43: =SUM(Schedules!F77:AC77)*249+SUM(Schedules!F78:AC78)*52+SUM(Schedules!F79:AC79)*(364-249-52) -> 2835.7 | F43: =SUM(Schedules!F83:AC83)*249+SUM(Schedules!F84:AC84)*52+SUM(Schedules!F85:AC85)*(364-249-52) -> 2835.7 | G43: =SUM(Schedules!F80:AC80)*249+SUM(Schedules!F81:AC81)*52+SUM(Schedules!F82:AC82)*(364-249-52) -> 3837.815

Sheet Zones
A1: ="Proposed Layout - "&Prototype!A2 -> Proposed Layout - OfficeSmall
A2: Space/Thermal Zone | B2: Space Type | C2: HVAC System Name/AHU Name | D2: Schedule Category | E2: Conditioned (Y/N) | F2: Area Fraction | G2: Area (ft²) | H2: Volume (ft³) | I2: Multipliers | J2: Number of People | K2: People (Persons/1,000 ft²) [T24, 2025,Table 120.1-A]
A3: Open_Office_N | B3: Office Area (>250 square feet) | C3: AHU_N | D3: Office | E3: Yes | F3: =G3/$G$17 -> 0.16588271 | G3: 912.6975 | H3: =G3*10 -> 9126.975 | I3: 1 | J3: =K3*G3/1000 -> 4.5634875 | K3: 5
A4: Closed_Office_W | B4: Office Area (>250 square feet) | C4: AHU_W | D4: Office | E4: Yes | F4: =G4/$G$17 -> 0.16511254 | G4: 908.46 | H4: =G4*10 -> 9084.6 | I4: 1 | J4: =K4*G4/1000 -> 4.5423 | K4: 5
A5: Closed_Office_E | B5: Office Area (>250 square feet) | C5: AHU_E | D5: Office | E5: Yes | F5: =G5/$G$17 -> 0.16511254 | G5: 908.46 | H5: =G5*10 -> 9084.6 | I5: 1 | J5: =K5*G5/1000 -> 4.5423 | K5: 5
A6: Conference | B6: Convention, Conference, Multipurpose and Meeting Area | C6: AHU_S | D6: Office | E6: Yes | F6: =G6/$G$17 -> 0.08294158 | G6: 456.35 | H6: =G6*10 -> 4563.5 | I6: 1 | J6: =K6*G6/1000 -> 15.05955 | K6: 33
A7: Lobby_Lounge | B7: Lobby, Main Entry | C7: AHU_S | D7: Office | E7: Yes | F7: =G7/$G$17 -> 0.08294158 | G7: 456.35 | H7: =G7*10 -> 4563.5 | I7: 1 | J7: =K7*G7/1000 -> 4.5635 | K7: 10 | L7: People: 10 according to ASHRAE 62.1, Table 6-1 for main entry lobbies T24: 33 for main Entry lobbies & 5 for reception area
A8: Storage | B8: Storage (General) | C8: AHU_W | D8: Office | E8: Yes | F8: =G8/$G$17 -> 0.13520158 | G8: 743.88791 | H8: =G8*10 -> 7438.8791 | I8: 1 | J8: =K8*G8/1000 -> 1.4877758 | K8: 2
A9: Mechanical_Electrical | B9: Electrical, Mechanical, Telephone Rooms | C9: AHU_S | D9: Office | E9: Yes | F9: =G9/$G$17 -> 0.020761294 | G9: 114.23 | H9: =G9*10 -> 1142.3 | I9: 1 | K9: -
A10: Restroom | B10: Restrooms | C10: AHU_W | D10: Office | E10: Yes | F10: =G10/$G$17 -> 0.040762874 | G10: 224.28 | H10: =G10*10 -> 2242.8 | I10: 1 | K10: -
A11: Break_CopyRoom | B11: Lounge, Breakroom, or Waiting Area | C11: AHU_S | D11: Office | E11: Yes | F11: =G11/$G$17 -> 0.02000158 | G11: 110.05 | H11: =G11*10 -> 1100.5 | I11: 1 | J11: =K11*G11/1000 -> 3.63165 | K11: 33
A12: Corridor_W | B12: Corridor Area | C12: AHU_W | D12: Office | E12: Yes | F12: =G12/$G$17 -> 0.022220746 | G12: 122.26 | H12: =G12*10 -> 1222.6 | I12: 1 | J12: =K12*G12/1000 -> 0.6113 | K12: 5
A13: Corridor_N | B13: Corridor Area | C13: AHU_N | D13: Office | E13: Yes | F13: =G13/$G$17 -> 0.038420118 | G13: 211.39 | H13: =G13*10 -> 2113.9 | I13: 1 | J13: =K13*G13/1000 -> 1.05695 | K13: 5
A14: Corridor_E | B14: Corridor Area | C14: AHU_E | D14: Office | E14: Yes | F14: =G14/$G$17 -> 0.022220746 | G14: 122.26 | H14: =G14*10 -> 1222.6 | I14: 1 | J14: =K14*G14/1000 -> 0.6113 | K14: 5
A15: Corridor_S | B15: Corridor Area | C15: AHU_S | D15: Office | E15: Yes | F15: =G15/$G$17 -> 0.038420118 | G15: 211.39 | H15: =G15*10 -> 2113.9 | I15: 1 | J15: =K15*G15/1000 -> 1.05695 | K15: 5
A16: Attic | B16: Attic | D16: n/a | E16: No | F16: 1 | G16: 6114.3047 | H16: 25437.111 | I16: 1 | K16: -
A17: Total (14 Space) | B17: Total (9 Space) | C17: Total (4 HVAC system) | D17: Total (1 category) | E17: Total (4 Conditioned zones, 1 Unconditioned Zones) | F17: =SUM(F3:F15) -> 1 | G17: =SUM(G3:G15) -> 5502.0654 | H17: =SUM(H3:H16) -> 80457.765 | I17: 1
B19: Ref: Geometry and zones: ORNL 2019 small office prototype with modification
B20: https://web.eecs.utk.edu/~jnew1/publications/2019_IBPSA_OpenStudioOffice.pdf
B21: https://web.eecs.utk.edu/~jnew1/presentations/2019_IBPSA_OpenStudioOffice.pdf
B29: Background Data [To be deleted prior to publication]
B34: Review zones of Existing Small Office Prototype
B36: Parameter | C36: PNNL | E36: CEC | F36: DEER
B37: Number of Zones | C37: 5 conditioned (1 core, 4 perm, 1 attic) | E37: 5 conditioned (1 core, 4 perm, 1 attic) | F37: 20 (10 per floor: 5 conditioned zones and 5 plenum unconditioned zones)
B38: Floor area of spaces (ft²) | C38: 1610.9268 | E38: 1610.9268 | F38: 1570.6698
C39: 1221.1656 | E39: 1221.1656 | F39: 1074.023
C40: 724.41117 | E40: 724.41117 | F40: 641.20614
C41: 6113.6858 | E41: 6113.6858 | F41: 0
C42: 5502.0804 | E42: 5502.0804 | F42: 5001.1819
C43: 5502.0804 | E43: 5502.0804 | F43: 10002.364
B45: People | C45: 120 | E45: 131.9 | F45: 120
E46: 0.55555556

Sheet Envelope
A1: ="Envelope - "&Prototype!A2 -> Envelope - OfficeSmall
A2: Element | B2: Prototype | C2: Assembly Type | D2: Construction | E2: Thermal Properties | F2: Vintage | G2: Selected T24 | H2: Note | I2: CZ1 | J2: CZ2 | K2: CZ3 | L2: CZ4 | M2: CZ5 | N2: CZ6 | O2: CZ7 | P2: CZ8 | Q2: CZ9 | R2: CZ10 | S2: CZ11 | T2: CZ12 | U2: CZ13 | V2: CZ14 | W2: CZ15 | X2: CZ16
A3: External Wall | B3: OfficeSmall | C3: ExtWall_WoodFramed_NonRes | D3: Wood-frame walls* + insulation + Gypsum board | E3: U-factor IP | F3: Pre 1978 | G3: N/A | H3: ASHRAE 90.1, 2022, Table A3.4.3.1, 3.5", R-0 | I3: 0.292 | J3: 0.292 | K3: 0.292 | L3: 0.292 | M3: 0.292 | N3: 0.292 | O3: 0.292 | P3: 0.292 | Q3: 0.292 | R3: 0.292 | S3: 0.292 | T3: 0.292 | U3: 0.292 | V3: 0.292 | W3: 0.292 | X3: 0.292
F4: 1978-1997 | G4: 1986 | H4: Table 2-53V-16: Package A/ Heat Capacity was considered 10.0-14.99 (BTU/F/ft²) | I4: =1/6.63 -> 0.15082956 | J4: =1/6.35 -> 0.15748031 | K4: =1/6.35 -> 0.15748031 | L4: =1/6.96 -> 0.14367816 | M4: =1/6.96 -> 0.14367816 | N4: =1/4.62 -> 0.21645022 | O4: =1/4.62 -> 0.21645022 | P4: =1/4.62 -> 0.21645022 | Q4: =1/4.62 -> 0.21645022 | R4: =1/4.62 -> 0.21645022 | S4: =1/5.37 -> 0.18621974 | T4: =1/5.37 -> 0.18621974 | U4: =1/5.37 -> 0.18621974 | V4: =1/6.3 -> 0.15873016 | W4: =1/6.3 -> 0.15873016 | X4: =1/6.63 -> 0.15082956
F5: 1998-2007 | G5: 2001 | H5: Table 1-H | I5: 0.084 | J5: 0.084 | K5: 0.092 | L5: 0.092 | M5: 0.092 | N5: 0.092 | O5: 0.092 | P5: 0.092 | Q5: 0.092 | R5: 0.084 | S5: 0.084 | T5: 0.084 | U5: 0.084 | V5: 0.084 | W5: 0.084 | X5: 0.084
F6: 2008-2018 | G6: 2013 | H6: Table 140.3-B | I6: 0.102 | J6: 0.059 | K6: 0.11 | L6: 0.059 | M6: 0.102 | N6: 0.11 | O6: 0.11 | P6: 0.102 | Q6: 0.059 | R6: 0.059 | S6: 0.059 | T6: 0.059 | U6: 0.059 | V6: 0.059 | W6: 0.042 | X6: 0.059
F7: 2019+ | G7: 2025 | H7: Table 140.3-B | I7: 0.078 | J7: 0.053 | K7: 0.102 | L7: 0.053 | M7: 0.095 | N7: 0.102 | O7: 0.102 | P7: 0.095 | Q7: 0.053 | R7: 0.053 | S7: 0.042 | T7: 0.053 | U7: 0.053 | V7: 0.053 | W7: 0.038 | X7: 0.053
A8: Flat Roof | B8: OfficeSmall | C8: AtticFloor Reversed | D8: Ceiling: Wood-frame roof + insulation + Acoustic tile/Gypsum board (Attic Roof: Asphalt shingle + Plywood) | E8: U-factor IP | F8: Pre 1978 | G8: 1992 | H8: Table 2-53V-16: Considering 30 years for roof/ insulation replacement. | I8: 0.057 | J8: 0.057 | K8: 0.057 | L8: 0.057 | M8: 0.057 | N8: 0.078 | O8: 0.078 | P8: 0.078 | Q8: 0.078 | R8: 0.078 | S8: 0.057 | T8: 0.057 | U8: 0.057 | V8: 0.057 | W8: 0.057 | X8: 0.057
F9: 1978-1997 | G9: 1992 | I9: 0.057 | J9: 0.057 | K9: 0.057 | L9: 0.057 | M9: 0.057 | N9: 0.078 | O9: 0.078 | P9: 0.078 | Q9: 0.078 | R9: 0.078 | S9: 0.057 | T9: 0.057 | U9: 0.057 | V9: 0.057 | W9: 0.057 | X9: 0.057
F10: 1998-2007 | G10: 2001 | H10: Table 1-H | I10: 0.057 | J10: 0.057 | K10: 0.057 | L10: 0.057 | M10: 0.057 | N10: 0.078 | O10: 0.078 | P10: 0.078 | Q10: 0.078 | R10: 0.057 | S10: 0.057 | T10: 0.057 | U10: 0.057 | V10: 0.057 | W10: 0.057 | X10: 0.057
F11: 2008-2018 | G11: 2013 | H11: Table 140.3-B | I11: 0.049 | J11: 0.039 | K11: 0.039 | L11: 0.039 | M11: 0.049 | N11: 0.075 | O11: 0.067 | P11: 0.067 | Q11: 0.039 | R11: 0.039 | S11: 0.039 | T11: 0.039 | U11: 0.039 | V11: 0.039 | W11: 0.039 | X11: 0.039
F12: 2019+ | G12: 2025 | H12: Table 140.3-B | I12: 0.028 | J12: 0.028 | K12: 0.028 | L12: 0.028 | M12: 0.028 | N12: 0.047 | O12: 0.047 | P12: 0.047 | Q12: 0.028 | R12: 0.028 | S12: 0.028 | T12: 0.028 | U12: 0.028 | V12: 0.028 | W12: 0.028 | X12: 0.028
A13: Windows | B13: OfficeSmall | C13: FixedWindow_NonRes | D13: Mix Single and Double: CBECS 2018 shows that ~53% of small offices that were built before 2000 are single pane | E13: U-factor IP | F13: Pre 1978 | G13: N/A | H13: ASHRAE Handbook of Fundamentals (Table 10-Ch15) for single pane & T24, 2013 for double pane(53%-47%)* | I13: =1.12*0.53+I$15*0.47 -> 0.8239 | J13: =1.12*0.53+J$15*0.47 -> 0.8239 | K13: =1.12*0.53+K$15*0.47 -> 0.9743 | L13: =1.12*0.53+L$15*0.47 -> 0.9743 | M13: =1.12*0.53+M$15*0.47 -> 0.9743 | N13: =1.12*0.53+N$15*0.47 -> 0.9743 | O13: =1.12*0.53+O$15*0.47 -> 0.9743 | P13: =1.12*0.53+P$15*0.47 -> 0.9743 | ... X13: =1.12*0.53+X$15*0.47 -> 0.8239
F14: 1978-1997 | G14: N/A | I14: =1.12*0.53+I$15*0.47 -> 0.8239 | J14: =1.12*0.53+J$15*0.47 -> 0.8239 | K14: =1.12*0.53+K$15*0.47 -> 0.9743 | L14: =1.12*0.53+L$15*0.47 -> 0.9743 | M14: =1.12*0.53+M$15*0.47 -> 0.9743 | N14: =1.12*0.53+N$15*0.47 -> 0.9743 | O14: =1.12*0.53+O$15*0.47 -> 0.9743 | P14: =1.12*0.53+P$15*0.47 -> 0.9743 | ... X14: =1.12*0.53+X$15*0.47 -> 0.8239
D15: Double pane | F15: 1998-2007 | G15: 2001 | H15: Table 1-H | I15: 0.49 | J15: 0.49 | K15: 0.81 | L15: 0.81 | M15: 0.81 | N15: 0.81 | O15: 0.81 | P15: 0.81 | Q15: 0.81 | R15: 0.49 | S15: 0.49 | T15: 0.49 | U15: 0.49 | V15: 0.49 | W15: 0.49 | X15: 0.49
F16: 2008-2018 | G16: 2013 | H16: Table 140.3-B | I16: 0.36 | J16: 0.36 | K16: 0.36 | L16: 0.36 | M16: 0.36 | N16: 0.36 | O16: 0.36 | P16: 0.36 | Q16: 0.36 | R16: 0.36 | S16: 0.36 | T16: 0.36 | U16: 0.36 | V16: 0.36 | W16: 0.36 | X16: 0.36
F17: 2019+ | G17: 2025 | H17: Table 140.3-B | I17: 0.36 | J17: 0.36 | K17: 0.36 | L17: 0.36 | M17: 0.36 | N17: 0.36 | O17: 0.36 | P17: 0.36 | Q17: 0.34 | R17: 0.36 | S17: 0.34 | T17: 0.34 | U17: 0.34 | V17: 0.34 | W17: 0.34 | X17: 0.36
B18: OfficeSmall | C18: FixedWindow_NonRes | D18: Mix Single and Double: CBECS 2018 shows that ~53% of small offices that were built before 2000 are single pane | E18: SHGC | F18: Pre 1978 | G18: N/A | H18: ASHRAE Handbook of Fundamentals (Table 10-Ch15) for single pane & T24, 2013 for double pane(53%-47%)* | I18: =0.79*0.53+I20*0.47 -> 0.6208 | J18: =0.79*0.53+J20*0.47 -> 0.5879 | K18: =0.79*0.53+K20*0.47 -> 0.6114 | L18: =0.79*0.53+L20*0.47 -> 0.6114 | M18: =0.79*0.53+M20*0.47 -> 0.6114 | N18: =0.79*0.53+N20*0.47 -> 0.602 | O18: =0.79*0.53+O20*0.47 -> 0.602 | P18: =0.79*0.53+P20*0.47 -> 0.602 | ... X18: =0.79*0.53+X20*0.47 -> 0.6208
F19: 1978-1997 | G19: 1986 | I19: =0.79*0.53+I20*0.47 -> 0.6208 | J19: =0.79*0.53+J20*0.47 -> 0.5879 | K19: =0.79*0.53+K20*0.47 -> 0.6114 | L19: =0.79*0.53+L20*0.47 -> 0.6114 | M19: =0.79*0.53+M20*0.47 -> 0.6114 | N19: =0.79*0.53+N20*0.47 -> 0.602 | O19: =0.79*0.53+O20*0.47 -> 0.602 | P19: =0.79*0.53+P20*0.47 -> 0.602 | ... X19: =0.79*0.53+X20*0.47 -> 0.6208
F20: 1998-2007 | G20: 2001 | H20: Table 1-H : WWR:20-30 / SHGC non-north | I20: 0.43 | J20: 0.36 | K20: 0.41 | L20: 0.41 | M20: 0.41 | N20: 0.39 | O20: 0.39 | P20: 0.39 | Q20: 0.39 | R20: 0.36 | S20: 0.36 | T20: 0.36 | U20: 0.36 | V20: 0.36 | W20: 0.36 | X20: 0.43
F21: 2008-2018 | G21: 2013 | H21: Table 140.3-B | I21: 0.25 | J21: 0.25 | K21: 0.25 | L21: 0.25 | M21: 0.25 | N21: 0.25 | O21: 0.25 | P21: 0.25 | Q21: 0.25 | R21: 0.25 | S21: 0.25 | T21: 0.25 | U21: 0.25 | V21: 0.25 | W21: 0.25 | X21: 0.25
F22: 2019+ | G22: 2025 | H22: Table 140.3-B | I22: 0.25 | J22: 0.25 | K22: 0.25 | L22: 0.25 | M22: 0.25 | N22: 0.25 | O22: 0.25 | P22: 0.25 | Q22: 0.22 | R22: 0.25 | S22: 0.22 | T22: 0.22 | U22: 0.22 | V22: 0.22 | W22: 0.22 | X22: 0.25
E24: Infiltration
F25: Vintage | G25: I_75 6-sided Infiltration rate @ 75 pa | H25: Note | I25: I-design (cfm/ft²) (4-sided Infiltration rate at normal pressure) (Design flow rate approach and Flow/Exterior Wall Area calculation method)
E26: Infiltration | F26: Pre 1978 | G26: 1.1 | H26: 2022 CASE report (Table 38) | I26: 0.5667
F27: 1978-1997 | G27: 1.1 | H27: 2022 CASE report (Table 38) | I27: 0.5667
F28: 1998-2007 | G28: 1.1 | H28: 2022 CASE report (Table 38) | I28: 0.5667
F29: 2008-2018 | G29: 1 | H29: 2022 CASE report (Table 38) & T24, 2008-2016 (Table 140.3-C) | I29: 0.5185
F30: 2019+ | G30: 0.6* | H30: 2022 CASE report (Table 38) & T24, 2025 (Table 140.3-C) | I30: 0.3091
E31: Source: Title 24 air barrier requirements (all editions) and the standardized infiltration rate reported in the 2022 CASE report and Dodge 2023 data
E32: * Better to consider 0.6 for New construction instead of being very stringent align with the Appendix G of ASHRAE 90.1 (which is almost 0.4)
E33: Air Leakage Memo: | G33: Infiltration_rate_report_14May2025-Short-Version.docx
A40: Background Data [To be deleted prior to publication]
A42: Interior wall
A43: Gypsum board
A44: Wood stud | C44: R=0.32 | D44: wood stud 2*4, covers 25% of the interior wall volume between two layer of gypsum board , | E44: =0.32*0.25+0.16*0.75 -> 0.2
A45: Air (or insulation) | C45: R=0.16 | D45: air covers the rest 75%.
A46: Gypsum board
A51: Infiltration | B51: Pre 1978
B52: 1978-1997 | C52: 1984 | D52: Title 24, 1984/Table 2-53J | E52: 0.5 cfm/ft for sash crack of windows, 0.5 cfm/ft² of door area for single door or 0.1 cfm/ft² of door area for double door
...

Sheet HVAC System
A1: ="HVAC System - "&Prototype!A2 -> HVAC System - OfficeSmall
A2: Vintage | B2: Heating | C2: Cooling | D2: Air Distribution | E2: Source
A3: Existing | B3: Furnace (Gas) | C3: Packaged (DX) | D3: Single Duct Constant Air Volume | E3: CEUS 2022 | F3: PTAC
A4: New Construction | B4: Packaged SZ HP | C4: Packaged SZ HP | D4: Single Duct Constant Air Volume | E4: T24 2025 | F4: PTHP
A8: Efficiency of HVAC system
A9: Vintage | B9: Upgrade Code | C9: Heating | D9: Cooling | E9: Source | G9: COP | H9: Source | I9: R (Adjustment factor)
A10: Pre 1978 | B10: 2008 | C10: Efficiency 80% | D10: EER=9.0 | E10: T24, Part 6, 2007 /CFR Energy 2009 page 12074 | G10: =((9-0.2)/3.413+$I$10)/(1-$I$10) -> 3.0663373 | H10: PNNL,2010,"Technical Support Document: 50% Energy Savings for Small Office Buildings" | I10: 0.12
A11: 1978-1997 | G11: =((9-0.2)/3.413+$I$10)/(1-$I$10) -> 3.0663373
A12: 1998-2007 | G12: =((9-0.2)/3.413+$I$10)/(1-$I$10) -> 3.0663373
A13: 2008-2018 | B13: 2010 | C13: COP=3 / Efficiency 80% | D13: EER=9.0 SEER=13 | E13: CFR Energy 2010:Title 10- Table 9 10 CFR 2013 (431.97, Table 1) | G13: =((9-0.2)/3.413+$I$10)/(1-$I$10) -> 3.0663373
A14: New Construction | B14: 2025 | C14: COP=3.3 / Efficiency 80% | D14: SEER2=13.4 | E14: CFR Energy 2024:Title 10- Table 19 - § 431.97 | G14: =((-0.0182*13.4^2+1.1088*13.4)/3.413+I10)/(1-I10) -> 3.9952481
A19: Fan power
A20: Vintage | B20: Approach | C20: System | D20: Total Static Pressure (TSP) (in w.c.) [PNNL 20405, 2010, Table 5.11] | E20: Fan Efficiency [ACM 2025] | F20: Fan Motor and Drive Efficiency [ACM 2025, Table 13] | G20: W/cfm [ACM 2025, Table 14 and 15] | H20: Data Source
A21: Existing | B21: PNNL TSP | C21: CAV (system < 7,437 cfm) | D21: 1.33 | E21: 0.65 | F21: ~0.9 (The full-load efficiency of the motor serving the fan- will be determined based on ACM 2025, Table 13) | H21: PNNL 20405, 2010, Table 5.11
A22: Brake horse power (bhp)=(Supply cfm*TSP in w.c.)/(6356*Fan efficiency)
A23: Fan power (w/cfm) = bhp/motor and drive efficiency *746
A24: New Construction | B24: ACM 2025 | C24: System 3b-SZHP, <5000 | D24: =G24*$F$23*$E$23/746*6356 -> 0 | E24: 0.65 | F24: 0.9 | G24: 0.744 | H24: ACM 2025
C25: PVAV System >10,000 cfm | D25: =G25*$F$23*$E$23/746*6356 -> 0 | G25: 0.964
F26: * 0.9 is an average fan efficiency according to ACM 2025, Table 13
A27: Fan total eff (E+ input) = 0.65 x Motor_eff
A28: TSP (E+ input) in w.c. = Motor_eff/746 x (6356 x Fan_eff) x W/cfm
A29: Fan_eff=0.65
A35: Background Data [To be deleted prior to publication]
B37: CEC | C37: PNNL | D37: DEER | E37: ComStock
A38: Zone cooling design supply air temperature (F) | B38: 57.5 | C38: 55 | D38: 55
A39: Air distribution system | B39: CAV | C39: CAV | D39: VAV | E39: CAV
A40: Max air flow rate | B40: Values | C40: Autosize | D40: Autosize | E40: Values
A42: Reference for Efficiency
U43: FCZ12 | V43: =(#REF!+#REF!)/2 -> #REF! | W43: =$V43*#REF!*#REF! -> #REF! | X43: =$V43*#REF!*#REF! -> #REF! | Y43: =$V43*#REF!*#REF! -> #REF! | Z43: =$V43*#REF!*#REF! -> #REF! | AA43: =$V43*#REF!*#REF! -> #REF! | AB43: =$V43*#REF!*#REF! -> #REF! | AC43: =$V43*#REF!*#REF! -> #REF! | AD43: =$V43*#REF!*#REF! -> #REF! | ... AL43: =$V43*#REF!*#REF! -> #REF!
D44: 10CFR 2024 | F44: CFR 2025 (not for Hp which is New construction) | I44: 74 FR 12058 : 2009 | K44: FR-2009-03-23.pdf
L59: ASHRAE 2010 : SEER 13
A68: Referenced Ventilation
A81: Discussion behind HVAC system selection
A83: CEUS 2022 data | B83: Heating | C83: Cooling | D83: Air Distribution
A84: % of total impacted floor area | B84: 0.9118 | C84: 0.89993095 | D84: 0.93097448
A85: Dominated system | B85: Package System / Heat Pump | C85: Package System / Heat Pump | D85: Single Duct Constant Air Volume in all vintage
A86: % of impacted floor area covered by the dominant system | B86: 0.73 | C86: 0.73359924 | D86: 0.92
A87: Fuel and Share | B87: 43.4% Electric and 55.5% Gas | C87: 99.9% by Electric
A89: 2% degradation for HVAC system per year
A91: A study measured losses of a median of 1.2 W/m2 (of gross floor area) from the distribution piping in 7 large commercial buildings
...

Sheet Thermostat
A1: ="Thermostat Setpoints - "&Prototype!A2 -> Thermostat Setpoints - OfficeSmall
A2: Setpoint | B2: CZ1 | C2: CZ2 | D2: CZ3 | E2: CZ4 | F2: CZ5 | G2: CZ6 | H2: CZ7 | I2: CZ8 | J2: CZ9 | K2: CZ10 | L2: CZ11 | M2: CZ12 | N2: CZ13 | O2: CZ14 | P2: CZ15 | Q2: CZ16
A3: Heating Setpoint (F) | B3: 70 | C3: 70 | D3: 70 | E3: 70 | F3: 70 | G3: 70 | H3: 70 | I3: 70 | J3: 70 | K3: 70 | L3: 70 | M3: 70 | N3: 70 | O3: 70 | P3: 70 | Q3: 70
A4: Heating Setback (F) | B4: 60 | C4: 60 | D4: 60 | E4: 60 | F4: 60 | G4: 60 | H4: 60 | I4: 60 | J4: 60 | K4: 60 | L4: 60 | M4: 60 | N4: 60 | O4: 60 | P4: 60 | Q4: 60
A5: Cooling Setpoint (F) | B5: 75 | C5: 75 | D5: 75 | E5: 75 | F5: 75 | G5: 75 | H5: 75 | I5: 75 | J5: 75 | K5: 75 | L5: 75 | M5: 75 | N5: 75 | O5: 75 | P5: 75 | Q5: 75
A6: Cooling Setback (F) | B6: 85 | C6: 85 | D6: 85 | E6: 85 | F6: 85 | G6: 85 | H6: 85 | I6: 85 | J6: 85 | K6: 85 | L6: 85 | M6: 85 | N6: 85 | O6: 85 | P6: 85 | Q6: 85
A9: The Small Office prototypes by CEC and DEER both use the same setpoints.
A10: The Small Office prototype by PNNL also uses the same setpoints, except for one of the perimeter zones, which has a heating setpoint of 69 °F and a cooling setpoint of 76 °F during hours of 10:00-11:00, 12:00-13:00, and 14:00-15:00 .
A17: Background Data [To be deleted prior to publication]
B19: Heating | E19: Cooling
B20: Weekday | C20: Saturday | D20: Sunday | E20: Weekday | F20: Saturday | G20: Sunday | J20: Heating and Cooling setback schedule | K20: Weekday | L20: 12:am-5:00 am
A21: DEER | B21: 0:00 to 5:00 | C21: 0:00 to 5:00 | D21: 0:00 to 24:00 | E21: 0:00 to 5:00 | F21: 0:00 to 5:00 | G21: 0:00 to 24:00 | K21: Saturday | L21: 7:00 pm-5:00 am
B22: 15.56 | C22: 15.56 | D22: 15.56 | E22: 29.22 | F22: 29.22 | G22: 29.22 | K22: Sunday | L22: All the day
B23: 5:00 to 24:00 | C23: 5:00 to 19:00 | E23: 5:00 to 24:00 | F23: 5:00 to 19:00
B24: 21.11 | C24: 21.11 | E24: 23.88 | F24: 23.88
A28: T24, Appendix JA5-4 : Occupant Controlled Smart Thermostat (OCST)
A39: The findings indicated that households engaged in teleworking raised their winter thermostat setpoints by an average of 0.66 °C and decreased their summer thermostat setpoint by an average of 1.62 °C compared to the period that their home was vacant during office hours
A40: 2025, "Analyzing smart thermostat data to uncover trends in remote work behaviors"
A41: https://www.sciencedirect.com/science/article/pii/S0378778825000507

Sheet Ventilation
A1: ="Outdoor Airflow Rate - "&Prototype!A2 -> Outdoor Airflow Rate - OfficeSmall
A2: Space/Thermal Zone | B2: Number of People | C2: Floor Area (ft²) | D2: cfm/person (T24, 2025, Equation 120.1-F and Table 120.1-A) | E2: cfm/ft² (T24, 2025, Equation 120.1-F and Table 120.1-A) | F2: Required Exhaust Rate (T24, 2025, Table 120.1-B – Minimum Exhaust Rates) | G2: Total cfm Driven by People | H2: Total cfm Driven by Area | I2: Total cfm Driven by Exhaust | J2: Total cfm | K2: Note
A3: =Zones!A3 -> Open_Office_N | B3: =Zones!J3 -> 4.5634875 | C3: =Zones!G3 -> 912.6975 | D3: 15 | E3: 0.15 | G3: =B3*D3 -> 68.452313 | H3: =C3*E3 -> 136.90462 | J3: =MAX(G3,H3,I3) -> 136.90462 | N3: AHU | O3: cfm
A4: =Zones!A4 -> Closed_Office_W | B4: 15 | C4: 0.15 | D4: 15 | E4: 0.15 | G4: =B4*D4 -> 225 | H4: =C4*E4 -> 0.0225 | J4: =MAX(G4,H4,I4) -> 225 | N4: AHU_N | O4: =J3+J12 -> 361.90463
A5: =Zones!A5 -> Closed_Office_E | B5: 15 | C5: 0.15 | D5: 15 | E5: 0.15 | G5: =B5*D5 -> 225 | H5: =C5*E5 -> 0.0225 | J5: =MAX(G5,H5,I5) -> 225 | N5: AHU_W | O5: =J4+J8+J12 -> 675
A6: =Zones!A6 -> Conference | B6: 15 | C6: 0.15 | D6: 15 | E6: 0.15 | G6: =B6*D6 -> 225 | H6: =C6*E6 -> 0.0225 | J6: =MAX(G6,H6,I6) -> 225 | N6: AHU_E | O6: =J5+J10+J14 -> 675
A7: =Zones!A7 -> Lobby_Lounge | B7: 15 | C7: 0.15 | D7: 15 | E7: 0.15 | G7: =B7*D7 -> 225 | H7: =C7*E7 -> 0.0225 | J7: =MAX(G7,H7,I7) -> 225 | N7: AHU_S | O7: =J6+J7+J15+J11+J9 -> 1125
A8: =Zones!A8 -> Storage | B8: 15 | C8: 0.15 | D8: 15 | E8: 0.15 | G8: =B8*D8 -> 225 | H8: =C8*E8 -> 0.0225 | J8: =MAX(G8,H8,I8) -> 225
A9: =Zones!A9 -> Mechanical_Electrical | B9: 15 | C9: 0.15 | D9: 15 | E9: 0.15 | G9: =B9*D9 -> 225 | H9: =C9*E9 -> 0.0225 | J9: =MAX(G9,H9,I9) -> 225
A10: =Zones!A10 -> Restroom | B10: 15 | C10: 0.15 | D10: 15 | E10: 0.15 | F10: 25/50 per unit | G10: =B10*D10 -> 225 | H10: =C10*E10 -> 0.0225 | I10: 50 | J10: =MAX(G10,H10,I10) -> 225
A11: =Zones!A11 -> Break_CopyRoom | B11: 15 | C11: 0.15 | D11: 15 | E11: 0.15 | G11: =B11*D11 -> 225 | H11: =C11*E11 -> 0.0225 | J11: =MAX(G11,H11,I11) -> 225
A12: =Zones!A12 -> Corridor_W | B12: 15 | C12: 0.15 | D12: 15 | E12: 0.15 | G12: =B12*D12 -> 225 | H12: =C12*E12 -> 0.0225 | J12: =MAX(G12,H12,I12) -> 225
A13: =Zones!A13 -> Corridor_N | B13: 15 | C13: 0.15 | D13: 15 | E13: 0.15 | G13: =B13*D13 -> 225 | H13: =C13*E13 -> 0.0225 | J13: =MAX(G13,H13,I13) -> 225
A14: =Zones!A14 -> Corridor_E | B14: 15 | C14: 0.15 | D14: 15 | E14: 0.15 | G14: =B14*D14 -> 225 | H14: =C14*E14 -> 0.0225 | J14: =MAX(G14,H14,I14) -> 225
A15: =Zones!A15 -> Corridor_S | B15: 15 | C15: 0.15 | D15: 15 | E15: 0.15 | G15: =B15*D15 -> 225 | H15: =C15*E15 -> 0.0225 | J15: =MAX(G15,H15,I15) -> 225
A16: =Zones!A16 -> Attic | B16: 15 | C16: 0.15
A25: Background Data [To be deleted prior to publication]
A27: CEUS 2022 Data shows that about 50% of the unconditioned floor area belongs to the first vintage bin (Pre-1978)
A29: Ref: CEUS 2022
B31: Ventilated | D31: Ventilated Only | G31: Conditioned - Floorspace that is heated and/or cooled
A32: Statewide/ Utility/ FCZ | B32: K SqFt | C32: % of Tot. Comm. Floorspace | D32: K SqFt | E32: % of Tot. Comm. Floorspace | F32: Total | G32: Unconditioned - Floorspace that is not heated and/or cooled
A33: Statewide | B33: 717924.25 | C33: 0.93097448 | D33: 5720.4277 | E33: 0.0074180141 | F33: 771153.52 | G33: Ventilated - Total floorspace that is Conditioned (heated and/or cooled), plus unconditioned spaces that are Ventilated
A34: FCZ01 Tot | B34: 110607.69 | C34: 0.92484767 | D34: 110607.69 | E34: 0.92484767 | F34: 119595.58 | G34: Ventilated Only - Unconditioned floorspace that is ventilated
A35: FCZ02 Tot | B35: 28894.052 | C35: 0.85950722 | D35: 0 | E35: 0 | F35: 33616.997 | G35: Refrigerated - Floorspace occupied by built-in commercial grade refrigerators (including walk-ins)
A36: FCZ03 Tot | B36: 9152.9953 | C36: 0.97318827 | D36: 0 | E36: 0 | F36: 9405.1639 | G36: Frozen - Floorspace that is occupied by built-in commercial grade freezers (including walk-ins)
A37: FCZ04 Tot | B37: 40764.035 | C37: 0.90087603 | D37: 40764.035 | E37: 0.90087603 | F37: 45249.328 | G37: Refrigerated & Frozen Combined - Refrigerated and/or Frozen floorspace
A38: FCZ05 Tot | B38: 40651.537 | C38: 0.94203038 | D38: 0 | E38: 0 | F38: 43153.106
A39: FCZ06 Tot | B39: 33601.154 | C39: 0.96127371 | D39: 33601.154 | E39: 0.96127371 | F39: 34954.825
A40: FCZ07 Tot | B40: 162052.06 | C40: 0.96386079 | D40: 162052.06 | E40: 0.96386079 | F40: 168128.08
A41: FCZ08 Tot | B41: 22464.066 | C41: 0.9271228 | D41: 0 | E41: 0 | F41: 24229.871
A42: FCZ09 Tot | B42: 11190.391 | C42: 0.95705946 | D42: 0 | E42: 0 | F42: 11692.472
A43: FCZ10 Tot | B43: 31510.45 | C43: 0.93602622 | D43: 0 | E43: 0 | F43: 33664.068
A44: FCZ11 Tot | B44: 34908.687 | C44: 0.98090646 | D44: 0 | E44: 0 | F44: 35588.191
A45: FCZ12c Tot | B45: 60257.386 | C45: 0.90695051 | D45: 60257.386 | E45: 0.90695051 | F45: 66439.553
A46: FCZ12i Tot | B46: 18564.585 | C46: 0.8786896 | D46: 18564.585 | E46: 0.8786896 | F46: 21127.58
A47: FCZ13 Tot | B47: 25391.21 | C47: 0.87254045 | D47: 25391.21 | E47: 0.87254045 | F47: 29100.324
A48: FCZ16 Tot | B48: 35458.851 | C48: 0.91743582 | D48: 35458.851 | E48: 0.91743582 | F48: 38649.953
A49: FCZ17 Tot | B49: 13427.377 | C49: 0.91735432 | D49: 0 | E49: 0 | F49: 14637.068
B53: Ventilated (k SqFt) | H53: Ventilated-Only (k SqFt)
A54: Statewide/ Utility/ FCZ | B54: Pre-1978 | C54: 1978-1997 | D54: 1998-2007 | E54: 2008-2018 | F54: Not Available | G54: Total | H54: Pre-1978 | I54: 1978-1997 | J54: 1998-2007 | K54: 2008-2018 | L54: Not Available | M54: Total
...

Sheet Water Heater
A1: ="Water Heater - "&Prototype!A2 -> Water Heater - OfficeSmall
A2: Vintage | B2: WH Type | C2: Efficiency | D2: Tank Volume (gal) | E2: Tank Loss | F2: Unit | G2: Source
A3: Existing | B3: Gas | C3: 0.8 | D3: =F30 -> 50 | E3: =G30 -> 855.51465 | F3: Btu/hr | G3: Loss per hour, 10 CFR 431.110(a) Table F-4
A4: New Construction | B4: Gas | C4: 0.8 | D4: =F30 -> 50 | E4: =G34 -> 855.51465 | F4: Btu/hr
A8: Peak Hot Water Consumption
A9: Space Name | B9: Baseline WH Type [T24, 2022, Appendix 5.4A , sheet: "2022 SpaceFuncData-Input"] | C9: Total Area (ft²) | D9: Number of People | E9: Hot Water Usage Specification (gal/hr per person) [T24, 2022, Appendix 5.4A , sheet: "2022 SpaceFuncData-Input"] | F9: Peak Hot Water Usage (gal/hr) | G9: Peak Hot Water Usage (gal/min)
A10: =Zones!A3 -> Open_Office_N | B10: Gas | C10: =Zones!G3*Zones!I3 -> 912.6975 | D10: =Zones!J3*Zones!I3 -> 4.5634875 | E10: 0.18 | F10: =E10*D10 -> 0.82142775 | G10: =F10/60 -> 0.013690462
A11: =Zones!A4 -> Closed_Office_W | B11: Gas | C11: =Zones!G4*Zones!I4 -> 908.46 | D11: =Zones!J4*Zones!I4 -> 4.5423 | E11: 0.18 | F11: =E11*D11 -> 0.817614 | G11: =F11/60 -> 0.0136269
A12: =Zones!A5 -> Closed_Office_E | B12: Gas | C12: =Zones!G5*Zones!I5 -> 908.46 | D12: =Zones!J5*Zones!I5 -> 4.5423 | E12: 0.18 | F12: =E12*D12 -> 0.817614 | G12: =F12/60 -> 0.0136269
A13: =Zones!A6 -> Conference | B13: Gas | C13: =Zones!G6*Zones!I6 -> 456.35 | D13: =Zones!J6*Zones!I6 -> 15.05955 | E13: 0.09 | F13: =E13*D13 -> 1.3553595 | G13: =F13/60 -> 0.022589325
A14: =Zones!A7 -> Lobby_Lounge | B14: Gas | C14: =Zones!G7*Zones!I7 -> 456.35 | D14: =Zones!J7*Zones!I7 -> 4.5635 | E14: 0.09 | F14: =E14*D14 -> 0.410715 | G14: =F14/60 -> 0.00684525
A15: =Zones!A8 -> Storage | B15: Gas | C15: =Zones!G8*Zones!I8 -> 743.88791 | D15: =Zones!J8*Zones!I8 -> 1.4877758 | E15: 0 | F15: =E15*D15 -> 0 | G15: =F15/60 -> 0
A16: =Zones!A9 -> Mechanical_Electrical | B16: Gas | C16: =Zones!G9*Zones!I9 -> 114.23 | D16: =Zones!J9*Zones!I9 -> 0 | E16: 0.18 | F16: =E16*D16 -> 0 | G16: =F16/60 -> 0
A17: =Zones!A10 -> Restroom | B17: Gas | C17: =Zones!G10*Zones!I10 -> 224.28 | D17: =Zones!J10*Zones!I10 -> 0 | E17: 0 | F17: =E17*D17 -> 0 | G17: =F17/60 -> 0
A18: =Zones!A11 -> Break_CopyRoom | B18: Gas | C18: =Zones!G11*Zones!I11 -> 110.05 | D18: =Zones!J11*Zones!I11 -> 3.63165 | E18: 0.09 | F18: =E18*D18 -> 0.3268485 | G18: =F18/60 -> 0.005447475
A19: =Zones!A12 -> Corridor_W | B19: Gas | C19: =Zones!G12*Zones!I12 -> 122.26 | D19: =Zones!J12*Zones!I12 -> 0.6113 | E19: 0 | F19: =E19*D19 -> 0 | G19: =F19/60 -> 0
A20: =Zones!A13 -> Corridor_N | B20: Gas | C20: =Zones!G13*Zones!I13 -> 211.39 | D20: =Zones!J13*Zones!I13 -> 1.05695 | E20: 0 | F20: =E20*D20 -> 0 | G20: =F20/60 -> 0
A21: =Zones!A14 -> Corridor_E | B21: Gas | C21: =Zones!G14*Zones!I14 -> 122.26 | D21: =Zones!J14*Zones!I14 -> 0.6113 | E21: 0 | F21: =E21*D21 -> 0 | G21: =F21/60 -> 0
... A23: =Zones!A16 -> Attic | B23: Gas | C23: =Zones!G16*Zones!I16 -> 6114.3047 | D23: =Zones!J16*Zones!I16 -> 0 | E23: 0 | F23: =E23*D23 -> 0 | G23: =F23/60 -> 0
A28: Water Heater Capacity, Tank Capacity, and Tank Loss
A29: WH Type | B29: Peak Hot Water Usage (gal/hr) | C29: Heat Output (Btu/hr) [ACM, 2025, 5.9.2: Rated capacity section] | D29: WH Capacity (Btu/hr) [ACM, 2025, 5.9.2: Rated capacity section] | E29: Required Energy Input (Btu/hr) | F29: Storage Volume (gal) | G29: Standby Loss | I29: Off/On Cycle Loss Coefficient to Ambient Temp (Btu/h-F) | J29: Source
A30: Gas Storage WH | B30: =MAX(125,SUMIFS(F10:F23,B10:B23,"Gas")) -> 125 | C30: =B30*(B34-B35)*8.2877*1 -> 82877 | D30: =C30*B36 -> 49726.2 | E30: =D30/C3 -> 62157.75 | F30: =ROUNDUP((B30*F32)/B32,0) -> 50 | G30: =(E30/800)+110*SQRT(F30) -> 855.51465 | H30: Btu/hr | I30: =G30/B41 -> 12.581098 | J30: Standby loss equation: Title 20, §1605.1 Table F-4 WH capacity equation: ACM, 2025, 5.9.2: Rated capacity section)
A31: Electric resistance WH | D31: =C31*B36 -> 0 | E31: =D31/1 -> 0 | F31: =ROUNDUP((B31*F32)/B32,0) -> 0 | G31: =IFERROR(0.3+(27/F31),0) -> 0 | H31: %/hr | I31: =0.0834*G31*F31 -> 0
A32: Total | B32: =B30+B31 -> 125 | F32: =B32*1*B37 -> 50
A34: Design supply temperature (F) | B34: 135 | C34: Ref: T24 2022 - Appendix 5.4B | F34: Standby Loss for Existing | G34: =G30 -> 855.51465 | H34: (Btu/hr) | I34: =I30 -> 12.581098
A35: Cold Water supply temperature (F) | B35: 55 | C35: Ref: ACM, 2025, 5.9.2: Rated capacity section
A36: WH system factor | B36: 0.6 | C36: Ref: ACM, 2025, 5.9.2: Rated capacity section
A37: Reheat multiplier | B37: 0.4 | C37: Ref: ACM, 2025, 5.9.2: Storage Volume
A38: * The 0.40 multiplier is a storage sizing factor used to account for the fact that the water heater doesn't need to store the full peak hour demand—it can reheat water during that time. This factor assumes that the heater will recover part of the hot water used during the peak hour, so only 40% of the peak hour demand needs to be stored at any given moment.
A41: Ambient temp | B41: 68
A42: Delta T | B42: =B34-B41 -> 67
A47: Background Data [To be deleted prior to publication]
A49: Water use: | B49: PNNL (for Core zone) | C49: DEER | D49: CEC
A50: peak flow rate (gal/min) | B50: =6.416*10^-2 -> 0.06416 | C50: 0.0322 for N&S ZN - 0.0192 for E&W ZN | D50: 0.0242 for Core ZN- 0.0109 for two ZN - 0.0183 for two other ZN | E50: NOR Flow rate schedule follows CEC
A51: Target Temperature | B51: 120 | C51: 135 | D51: 135
A52: Sensible Fraction | B52: 0.2 | C52: 0.2 | D52: N/A
A53: Latent Fraction | B53: 0.05 | C53: 0.05 | D53: N/A
A56: CEUS 2022 data | B56: Water Heater
A57: % of total impacted floor area | B57: 0.92962911
A58: Dominated system | B58: Package System / Heat Pump
...

Sheet Interior Lights
A1: ="Interior Lighting - " & Prototype!A2 -> Interior Lighting - OfficeSmall
A2: Space Type | B2: New Construction | E2: Existing | H2: Note
B3: LPD (W/ft²) | C3: Additional LPD for Portable Lighting (W/ft²) | D3: Source | E3: LPD (W/ft²) | F3: Additional LPD for Portable Lighting (W/ft²) | G3: Source
A4: Office Area (>250 square feet) | B4: 0.6 | D4: T24, part 6, 2025, Table 140.6 C Technology : LED | E4: 0.75 | G4: T24, part 6, 2013, Table 140.6 C Technology: 59% LED, 31% halogen, 7% CFL (Comstock 2023)
A5: Convention, Conference, Multipurpose and Meeting Area | B5: 0.75 | E5: 1.4
A6: Lobby, Main Entry | B6: 0.7 | E6: 1.5
A7: Storage (General) | B7: 0.4 | E7: 0.6
A8: Electrical, Mechanical, Telephone Rooms | B8: 0.4 | E8: 0.7
A9: Restrooms | B9: 0.6 | E9: 0.6
A10: Lounge, Breakroom, or Waiting Area | B10: 0.55 | E10: 1.1 | H10: 2013 LPD is for "Lounge" area
A11: Corridor Area | B11: 0.4 | E11: 0.6
A12: Attic
A14: According to CEUS, more than 80% of existing small office upgraded their lighting system between 2014-2018 and it conflicts the lighting generation considered by Comstock.
B17: Whole Building method
B18: 2025 | C18: 2013
A19: LPD for Office Building ((W/ft²) | B19: 0.6 | C19: 0.8 | D19: Ref: T24, Table 140.6 B
A24: Background Data [To be deleted24:77 prior to publication]
A26: Ref: T24- Table 140.6-C (office area >250nSF)
A27: T24 Code cycle | B27: Lighting density for office Buildings: (complete building Method) | C27: Lighting density for office area >250 sf Floor area Method | D27: Table | E27: Note
A28: 2025 | B28: 0.6 | C28: 0.6, 0.2 (additional) | D28: Table 140.6 C
A29: 2022 | B29: 0.6 | C29: 0.6, 0.2 (additional)
A30: 2019 | B30: 0.65
A31: 2016 | B31: 0.8
A32: 2013 | B32: 0.8 | C32: 0.75
A33: 2010 | B33: 0.85
A34: 2008 | B34: 0.085 | C34: 0.9 | D34: Table 146-E
A35: 2005 | C35: 1.2
A36: TBD: Review the CASE report on 2016 for lighting
B40: Lighting density for office area >250 sf (Watts/ft²) | C40: Additional lighting power for Table lighting (Watts/ft²) | E40: T24, part 6 2022 | F40: file://carcgl.com/amer/NOR/Groups/CodesStds/Standards/California/2022%20Building%20Energy%20Efficiency%20Standards%20for%20Residential%20and%20Nonresidential%20Buildings.pdf
A41: Title 24, 2016 | B41: 0.8 | E41: T24, part 6 2019 | F41: file://carcgl.com/amer/NOR/Groups/CodesStds/Standards/California/2016-CEC-400-2015-037-CMF.pdf
B42: 0.75 (1 for office <=250) | E42: T24, part 6 2016 | F42: file://carcgl.com/amer/NOR/Groups/CodesStds/Standards/California/2016-CEC-400-2015-037-CMF.pdf
B43: 1.2
B44: 0.6
B45: 0.55
B46: 0.95 | C46: 0.5
B47: 0.9 | C47: 0.5
B48: 0.6
B49: 0.6
B50: 0.6
A51: Review of existing prototype
...

Sheet Ext Lighting
A1: ="Exterior Lighting - " & Prototype!A2 -> Exterior Lighting - OfficeSmall
A2: Motion Controlled Luminaires (W) | B2: Non-motion Controlled Luminaires (W) | C2: Total (W) | D2: Source
A3: =G12 -> 382.26279 | B3: =G13 -> 155.15145 | C3: =A3+B3 -> 537.41423 | D3: T24, 2022 & 2025 2019 Outdoor Lighting CASE report PNNL 90.1-2010 TSD
A5: Exterior Lighting
A6: Items (Assume LZ2) | B6: Assumptions [2019 Outdoor Lighting CASE Report & PNNL 90.1-2010 TSD] | D6: Unit | E6: Lighting Power Allowance [T24, 2025, Table 140.7-A & 140.7-B] | F6: Unit | G6: Exterior Lighting Power (W)
A7: IWA (Initial Wage Allowance) | E7: 200 | F7: (W) | G7: =$E7 -> 200
A8: Parking area | B8: 400 ft² for every parking space 1 parking space per 250 ft² of gross building area | C8: =B19/250*400 -> 8803.3047 | D8: (ft²) | E8: 0.019 | F8: (W/ft²) | G8: =$E8*C8 -> 167.26279
A9: Building Entrance | B9: 2 building entrance (1 per 10,000 ft² footprint) | C9: 1 | D9: (count) | E9: 15 | F9: (W/ea) | G9: =E9*C9 -> 15
A10: Hardscape Ornamental Light | B10: 0.1 ft² per 1 ft² of gross building area for hardscape ornamental light | C10: =B19*0.1 -> 550.20654 | D10: (ft²) | E10: 0.007 | F10: (W/ft²) | G10: =E10*C10 -> 3.8514458
A11: Building façade | B11: 0.1 W per ft² of facade area Façade Area* = Perimeter × 0.5 × height (30 ft is the max height that is lit) The 0.5 factor assumes that only half of the perimeter walls are lit. -Formula ia developed based on the 2019 Outdoor Lighting CASE report | C11: =B18*0.5*10 -> 1513 | D11: (ft²) | E11: 0.1 | F11: (W/ft²) | G11: =E11*C11 -> 151.3
A12: Motion controlled Luminaires | G12: =G8+G7+G9 -> 382.26279
A13: Non-motion-controlled Luminaires | G13: =G10+G11 -> 155.15145
A14: Total | G14: =G12+G13 -> 537.41423
A16: *Developed based on 2019 Outdoor Lighting CASE Report
A18: Perimeter (ft) | B18: =(90.8+60.5)*2 -> 302.6
A19: Total floor area (ft²) | B19: =Zones!G17 -> 5502.0654
A20: Floors (above ground) | B20: 1
A31: Background Data [To be deleted prior to publication]
A33: PNNL
A34: NonMotion Control | B34: Motion Control
A35: from 6:00 am until 12 am: 1 Rest: 0 | B35: from 6 am-until 7 pm: 1 Rest: 0.5
A37: Exterior Lighting
A38: Ref: T24- Table 140.6-C (office area >250 SF)
A39: T24 Code cycle | B39: Lighting for parking area | C39: Daylight Adaptation Zones**
A40: 2022 | B40: 0.1 | C40: 1
A41: 2019 | B41: 0.1 | C41: 0.5
A42: 2016 | B42: 0.14 | C42: 0.6
A43: **Daylight Adaptation Zones shall be no farther than 66 feet from the entrance to the parking garage
A46: Exterior Lighting - OfficeSmall (CEUS 2022 data)
A47: Prototype | B47: CZ | C47: Exterior Lighting Saturation
A48: OfficeSmall | B48: 1 | C48: 0.71923409
B49: 2 | C49: 0.79760196
B50: 3 | C50: 0.68666482
B51: 4 | C51: 0.68665488
B52: 5 | C52: 0.66513285
B53: 6 | C53: 0.61362552
B54: 7 | C54: 0.55425225
B55: 8 | C55: 0.60372866
B56: 9 | C56: 0.63197902
B57: 10 | C57: 0.53255875
...

Sheet Equipment
A1: ="Equipment - " & Prototype!A2 -> Equipment - OfficeSmall
A2: Space Name | B2: Plug load Power Density (W/ft²) | C2: Gas Power Density (Btu/hr-ft²) | D2: Refrigeration Power Density (W/ft²) | E2: Source
A3: Office Area (>250 square feet) | B3: 0.7 | E3: Plug load and schedules project with CEC, 2025
A4: Convention, Conference, Multipurpose and Meeting Area | B4: 0.8 | E4: T24 2022 - Appendix 5.4A
A5: Lobby, Main Entry | B5: 0.5
A6: Storage (General) | B6: 0.2
A7: Electrical, Mechanical, Telephone Rooms | B7: 3
A8: Restrooms | B8: 0
A9: Lounge, Breakroom, or Waiting Area | B9: 0.5
A10: Corridor Area | B10: 0

Sheet Schedules
A1: ="Schedules - "&Prototype!A2 -> Schedules - OfficeSmall
A2: Zone | B2: Schedule Category | C2: Schedule | D2: Source | E2: Type | F2: Hour
F3: 1 | G3: 2 | H3: 3 | I3: 4 | J3: 5 | K3: 6 | L3: 7 | M3: 8 | N3: 9 | O3: 10 | P3: 11 | Q3: 12 | R3: 13 | S3: 14 | T3: 15 | U3: 16 | V3: 17 | W3: 18 | X3: 19 | Y3: 20 | Z3: 21 | AA3: 22 | AB3: 23 | AC3: 24
A4: All zones | B4: Office | C4: Occupancy | D4: T24 2022 - Appendix 5.4B, [Office] Updated base on Plug load and schedules project with CEC, 2025 | E4: Weekday | F4: 0 | G4: 0 | H4: 0 | I4: 0 | J4: 0 | K4: 0 | L4: 0.1 | M4: 0.2 | N4: 0.95 | O4: 0.95 | P4: 0.95 | Q4: 0.95 | R4: 0.5 | S4: 0.95 | T4: 0.95 | U4: 0.95 | V4: 0.95 | W4: 0.3 | X4: 0.1 | Y4: 0.1 | Z4: 0.1 | AA4: 0.1 | AB4: 0.05 | AC4: 0.05
E5: Saturday | F5: 0 | G5: 0 | H5: 0 | I5: 0 | J5: 0 | K5: 0 | L5: 0.05 | M5: 0.05 | N5: 0.05 | O5: 0.05 | P5: 0.05 | Q5: 0.05 | R5: 0.05 | S5: 0.05 | T5: 0.05 | U5: 0.05 | V5: 0.05 | W5: 0.05 | X5: 0 | Y5: 0 | Z5: 0 | AA5: 0 | AB5: 0 | AC5: 0
E6: Sunday | F6: 0 | G6: 0 | H6: 0 | I6: 0 | J6: 0 | K6: 0 | L6: 0.05 | M6: 0.05 | N6: 0.05 | O6: 0.05 | P6: 0.05 | Q6: 0.05 | R6: 0.05 | S6: 0.05 | T6: 0.05 | U6: 0.05 | V6: 0.05 | W6: 0.05 | X6: 0 | Y6: 0 | Z6: 0 | AA6: 0 | AB6: 0 | AC6: 0
A7: =A4 -> All zones | B7: Office | C7: Lights | D7: T24 2022 - Appendix 5.4B, [Office] | E7: Weekday | F7: 0.05 | G7: 0.05 | H7: 0.05 | I7: 0.05 | J7: 0.05 | K7: 0.1 | L7: 0.1 | M7: 0.3 | N7: 0.65 | O7: 0.65 | P7: 0.65 | Q7: 0.65 | R7: 0.65 | S7: 0.65 | T7: 0.65 | U7: 0.65 | V7: 0.65 | W7: 0.35 | X7: 0.3 | Y7: 0.3 | Z7: 0.2 | AA7: 0.2 | AB7: 0.1 | AC7: 0.05
E8: Saturday | F8: 0.05 | G8: 0.05 | H8: 0.05 | I8: 0.05 | J8: 0.05 | K8: 0.05 | L8: 0.05 | M8: 0.05 | N8: 0.05 | O8: 0.05 | P8: 0.05 | Q8: 0.05 | R8: 0.05 | S8: 0.05 | T8: 0.05 | U8: 0.05 | V8: 0.05 | W8: 0.05 | X8: 0.05 | Y8: 0.05 | Z8: 0.05 | AA8: 0.05 | AB8: 0.05 | AC8: 0.05
E9: Sunday | F9: 0.05 | G9: 0.05 | H9: 0.05 | I9: 0.05 | J9: 0.05 | K9: 0.05 | L9: 0.05 | M9: 0.05 | N9: 0.05 | O9: 0.05 | P9: 0.05 | Q9: 0.05 | R9: 0.05 | S9: 0.05 | T9: 0.05 | U9: 0.05 | V9: 0.05 | W9: 0.05 | X9: 0.05 | Y9: 0.05 | Z9: 0.05 | AA9: 0.05 | AB9: 0.05 | AC9: 0.05
A10: =A7 -> All zones | B10: Office | C10: ElecEquipment | D10: Plug load and schedules project with CEC, 2025 | E10: Weekday | F10: 0.45 | G10: 0.45 | H10: 0.45 | I10: 0.45 | J10: 0.45 | K10: 0.45 | L10: 0.45 | M10: 0.74 | N10: 0.87 | O10: 0.9 | P10: 0.9 | Q10: 0.9 | R10: 0.9 | S10: 0.9 | T10: 0.9 | U10: 0.9 | V10: 0.9 | W10: 0.7 | X10: 0.5 | Y10: 0.5 | Z10: 0.5 | AA10: 0.45 | AB10: 0.45 | AC10: 0.45
E11: Saturday | F11: 0.43 | G11: 0.43 | H11: 0.43 | I11: 0.43 | J11: 0.43 | K11: 0.43 | L11: 0.43 | M11: 0.43 | N11: 0.43 | O11: 0.43 | P11: 0.43 | Q11: 0.43 | R11: 0.43 | S11: 0.43 | T11: 0.43 | U11: 0.43 | V11: 0.43 | W11: 0.43 | X11: 0.43 | Y11: 0.43 | Z11: 0.43 | AA11: 0.43 | AB11: 0.43 | AC11: 0.43
E12: Sunday | F12: 0.43 | G12: 0.43 | H12: 0.43 | I12: 0.43 | J12: 0.43 | K12: 0.43 | L12: 0.43 | M12: 0.43 | N12: 0.43 | O12: 0.43 | P12: 0.43 | Q12: 0.43 | R12: 0.43 | S12: 0.43 | T12: 0.43 | U12: 0.43 | V12: 0.43 | W12: 0.43 | X12: 0.43 | Y12: 0.43 | Z12: 0.43 | AA12: 0.43 | AB12: 0.43 | AC12: 0.43
A13: =A4 -> All zones | B13: Office | C13: HVACAvail | D13: T24 2022 - Appendix 5.4B, [Office] Updated base on Plug load and schedules project with CEC, 202 | E13: Weekday | F13: 0 | G13: 0 | H13: 0 | I13: 0 | J13: 0 | K13: 1 | L13: 1 | M13: 1 | N13: 1 | O13: 1 | P13: 1 | Q13: 1 | R13: 1 | S13: 1 | T13: 1 | U13: 1 | V13: 1 | W13: 1 | X13: 1 | Y13: 1 | Z13: 1 | AA13: 1 | AB13: 1 | AC13: 1
E14: Saturday | F14: 0 | G14: 0 | H14: 0 | I14: 0 | J14: 0 | K14: 0 | L14: 0 | M14: 0 | N14: 0 | O14: 0 | P14: 0 | Q14: 0 | R14: 0 | S14: 0 | T14: 0 | U14: 0 | V14: 0 | W14: 0 | X14: 0 | Y14: 0 | Z14: 0 | AA14: 0 | AB14: 0 | AC14: 0
E15: Sunday | F15: 0 | G15: 0 | H15: 0 | I15: 0 | J15: 0 | K15: 0 | L15: 0 | M15: 0 | N15: 0 | O15: 0 | P15: 0 | Q15: 0 | R15: 0 | S15: 0 | T15: 0 | U15: 0 | V15: 0 | W15: 0 | X15: 0 | Y15: 0 | Z15: 0 | AA15: 0 | AB15: 0 | AC15: 0
A16: =A4 -> All zones | B16: Office | C16: ServiceHotWater | D16: T24 2022 - Appendix 5.4B, [Office] | E16: Weekday | F16: 0.05 | G16: 0.05 | H16: 0.05 | I16: 0.05 | J16: 0.05 | K16: 0.08 | L16: 0.07 | M16: 0.19 | N16: 0.35 | O16: 0.38 | P16: 0.39 | Q16: 0.47 | R16: 0.57 | S16: 0.54 | T16: 0.34 | U16: 0.33 | V16: 0.44 | W16: 0.26 | X16: 0.21 | Y16: 0.15 | Z16: 0.17 | AA16: 0.08 | AB16: 0.05 | AC16: 0.05
E17: Saturday | F17: 0.05 | G17: 0.05 | H17: 0.05 | I17: 0.05 | J17: 0.05 | K17: 0.08 | L17: 0.07 | M17: 0.11 | N17: 0.15 | O17: 0.21 | P17: 0.19 | Q17: 0.23 | R17: 0.2 | S17: 0.19 | T17: 0.15 | U17: 0.12 | V17: 0.14 | W17: 0.07 | X17: 0.07 | Y17: 0.07 | Z17: 0.07 | AA17: 0.09 | AB17: 0.05 | AC17: 0.05
E18: Sunday | F18: 0.04 | G18: 0.04 | H18: 0.04 | I18: 0.04 | J18: 0.04 | K18: 0.07 | L18: 0.04 | M18: 0.04 | N18: 0.04 | O18: 0.04 | P18: 0.04 | Q18: 0.06 | R18: 0.06 | S18: 0.09 | T18: 0.06 | U18: 0.04 | V18: 0.04 | W18: 0.04 | X18: 0.04 | Y18: 0.04 | Z18: 0.04 | AA18: 0.07 | AB18: 0.04 | AC18: 0.04
A19: =A4 -> All zones | B19: Office | C19: Infiltration | D19: T24 2022 - Appendix 5.4B, [Office] Updated base on Plug load and schedules project with CEC, 202 | E19: Weekday | F19: 1 | G19: 1 | H19: 1 | I19: 1 | J19: 1 | K19: 0.25 | L19: 0.25 | M19: 0.25 | N19: 0.25 | O19: 0.25 | P19: 0.25 | Q19: 0.25 | R19: 0.25 | S19: 0.25 | T19: 0.25 | U19: 0.25 | V19: 0.25 | W19: 0.25 | X19: 0.25 | Y19: 0.25 | Z19: 0.25 | AA19: 0.25 | AB19: 0.25 | AC19: 0.25
E20: Saturday | F20: 1 | G20: 1 | H20: 1 | I20: 1 | J20: 1 | K20: 1 | L20: 1 | M20: 1 | N20: 1 | O20: 1 | P20: 1 | Q20: 1 | R20: 1 | S20: 1 | T20: 1 | U20: 1 | V20: 1 | W20: 1 | X20: 1 | Y20: 1 | Z20: 1 | AA20: 1 | AB20: 1 | AC20: 1
E21: Sunday | F21: 1 | G21: 1 | H21: 1 | I21: 1 | J21: 1 | K21: 1 | L21: 1 | M21: 1 | N21: 1 | O21: 1 | P21: 1 | Q21: 1 | R21: 1 | S21: 1 | T21: 1 | U21: 1 | V21: 1 | W21: 1 | X21: 1 | Y21: 1 | Z21: 1 | AA21: 1 | AB21: 1 | AC21: 1
A22: =A7 -> All zones | B22: Office | C22: HtgSetpt | E22: Weekday | F22: =IF((F13=1),Thermostat!$B$3,Thermostat!$B$4) -> 60 | G22: =IF((G13=1),Thermostat!$B$3,Thermostat!$B$4) -> 60 | H22: =IF((H13=1),Thermostat!$B$3,Thermostat!$B$4) -> 60 | I22: =IF((I13=1),Thermostat!$B$3,Thermostat!$B$4) -> 60 | J22: =IF((J13=1),Thermostat!$B$3,Thermostat!$B$4) -> 60 | K22: =IF((K13=1),Thermostat!$B$3,Thermostat!$B$4) -> 70 | L22: =IF((L13=1),Thermostat!$B$3,Thermostat!$B$4) -> 70 | M22: =IF((M13=1),Thermostat!$B$3,Thermostat!$B$4) -> 70 | ... AC22: =IF((AC13=1),Thermostat!$B$3,Thermostat!$B$4) -> 70
E23: Saturday | F23: =IF((F14=1),Thermostat!$B$3,Thermostat!$B$4) -> 60 | G23: =IF((G14=1),Thermostat!$B$3,Thermostat!$B$4) -> 60 | H23: =IF((H14=1),Thermostat!$B$3,Thermostat!$B$4) -> 60 | I23: =IF((I14=1),Thermostat!$B$3,Thermostat!$B$4) -> 60 | J23: =IF((J14=1),Thermostat!$B$3,Thermostat!$B$4) -> 60 | K23: =IF((K14=1),Thermostat!$B$3,Thermostat!$B$4) -> 60 | L23: =IF((L14=1),Thermostat!$B$3,Thermostat!$B$4) -> 60 | M23: =IF((M14=1),Thermostat!$B$3,Thermostat!$B$4) -> 60 | ... AC23: =IF((AC14=1),Thermostat!$B$3,Thermostat!$B$4) -> 60
E24: Sunday | F24: =IF((F15=1),Thermostat!$B$3,Thermostat!$B$4) -> 60 | G24: =IF((G15=1),Thermostat!$B$3,Thermostat!$B$4) -> 60 | H24: =IF((H15=1),Thermostat!$B$3,Thermostat!$B$4) -> 60 | I24: =IF((I15=1),Thermostat!$B$3,Thermostat!$B$4) -> 60 | J24: =IF((J15=1),Thermostat!$B$3,Thermostat!$B$4) -> 60 | K24: =IF((K15=1),Thermostat!$B$3,Thermostat!$B$4) -> 60 | L24: =IF((L15=1),Thermostat!$B$3,Thermostat!$B$4) -> 60 | M24: =IF((M15=1),Thermostat!$B$3,Thermostat!$B$4) -> 60 | ... AC24: =IF((AC15=1),Thermostat!$B$3,Thermostat!$B$4) -> 60
A25: =A10 -> All zones | B25: Office | C25: ClgSetpt | E25: Weekday | F25: =IF((F13=1),Thermostat!$B$5,Thermostat!$B$6) -> 85 | G25: =IF((G13=1),Thermostat!$B$5,Thermostat!$B$6) -> 85 | H25: =IF((H13=1),Thermostat!$B$5,Thermostat!$B$6) -> 85 | I25: =IF((I13=1),Thermostat!$B$5,Thermostat!$B$6) -> 85 | J25: =IF((J13=1),Thermostat!$B$5,Thermostat!$B$6) -> 85 | K25: =IF((K13=1),Thermostat!$B$5,Thermostat!$B$6) -> 75 | L25: =IF((L13=1),Thermostat!$B$5,Thermostat!$B$6) -> 75 | M25: =IF((M13=1),Thermostat!$B$5,Thermostat!$B$6) -> 75 | ... AC25: =IF((AC13=1),Thermostat!$B$5,Thermostat!$B$6) -> 75
E26: Saturday | F26: =IF((F14=1),Thermostat!$B$5,Thermostat!$B$6) -> 85 | G26: =IF((G14=1),Thermostat!$B$5,Thermostat!$B$6) -> 85 | H26: =IF((H14=1),Thermostat!$B$5,Thermostat!$B$6) -> 85 | I26: =IF((I14=1),Thermostat!$B$5,Thermostat!$B$6) -> 85 | J26: =IF((J14=1),Thermostat!$B$5,Thermostat!$B$6) -> 85 | K26: =IF((K14=1),Thermostat!$B$5,Thermostat!$B$6) -> 85 | L26: =IF((L14=1),Thermostat!$B$5,Thermostat!$B$6) -> 85 | M26: =IF((M14=1),Thermostat!$B$5,Thermostat!$B$6) -> 85 | ... AC26: =IF((AC14=1),Thermostat!$B$5,Thermostat!$B$6) -> 85
E27: Sunday | F27: =IF((F15=1),Thermostat!$B$5,Thermostat!$B$6) -> 85 | G27: =IF((G15=1),Thermostat!$B$5,Thermostat!$B$6) -> 85 | H27: =IF((H15=1),Thermostat!$B$5,Thermostat!$B$6) -> 85 | I27: =IF((I15=1),Thermostat!$B$5,Thermostat!$B$6) -> 85 | J27: =IF((J15=1),Thermostat!$B$5,Thermostat!$B$6) -> 85 | K27: =IF((K15=1),Thermostat!$B$5,Thermostat!$B$6) -> 85 | L27: =IF((L15=1),Thermostat!$B$5,Thermostat!$B$6) -> 85 | M27: =IF((M15=1),Thermostat!$B$5,Thermostat!$B$6) -> 85 | ... AC27: =IF((AC15=1),Thermostat!$B$5,Thermostat!$B$6) -> 85
A28: Corridors | B28: Office | C28: HtgSetpt_Corridor | E28: Weekday | F28: 60 | G28: 60 | H28: 60 | I28: 60 | J28: 60 | K28: 65 | L28: 65 | M28: 65 | N28: 65 | O28: 65 | P28: 65 | Q28: 65 | R28: 65 | S28: 65 | T28: 65 | U28: 65 | V28: 65 | W28: 65 | X28: 65 | Y28: 65 | Z28: 65 | AA28: 65 | AB28: 65 | AC28: 65
E29: Saturday | F29: 60 | G29: 60 | H29: 60 | I29: 60 | J29: 60 | K29: 60 | L29: 60 | M29: 60 | N29: 60 | O29: 60 | P29: 60 | Q29: 60 | R29: 60 | S29: 60 | T29: 60 | U29: 60 | V29: 60 | W29: 60 | X29: 60 | Y29: 60 | Z29: 60 | AA29: 60 | AB29: 60 | AC29: 60
E30: Sunday | F30: 60 | G30: 60 | H30: 60 | I30: 60 | J30: 60 | K30: 60 | L30: 60 | M30: 60 | N30: 60 | O30: 60 | P30: 60 | Q30: 60 | R30: 60 | S30: 60 | T30: 60 | U30: 60 | V30: 60 | W30: 60 | X30: 60 | Y30: 60 | Z30: 60 | AA30: 60 | AB30: 60 | AC30: 60
A31: Corridors | B31: Office | C31: ClgSetpt_Corridor | E31: Weekday | F31: 85 | G31: 85 | H31: 85 | I31: 85 | J31: 85 | K31: 78 | L31: 78 | M31: 78 | N31: 78 | O31: 78 | P31: 78 | Q31: 78 | R31: 78 | S31: 78 | T31: 78 | U31: 78 | V31: 78 | W31: 78 | X31: 78 | Y31: 78 | Z31: 78 | AA31: 78 | AB31: 78 | AC31: 78
E32: Saturday | F32: 85 | G32: 85 | H32: 85 | I32: 85 | J32: 85 | K32: 85 | L32: 85 | M32: 85 | N32: 85 | O32: 85 | P32: 85 | Q32: 85 | R32: 85 | S32: 85 | T32: 85 | U32: 85 | V32: 85 | W32: 85 | X32: 85 | Y32: 85 | Z32: 85 | AA32: 85 | AB32: 85 | AC32: 85
E33: Sunday | F33: 85 | G33: 85 | H33: 85 | I33: 85 | J33: 85 | K33: 85 | L33: 85 | M33: 85 | N33: 85 | O33: 85 | P33: 85 | Q33: 85 | R33: 85 | S33: 85 | T33: 85 | U33: 85 | V33: 85 | W33: 85 | X33: 85 | Y33: 85 | Z33: 85 | AA33: 85 | AB33: 85 | AC33: 85
A34: Other
B35: Building | C35: ExtLightingNonMotionCtrl | E35: Weekday | F35: 1 | G35: 1 | H35: 1 | I35: 1 | J35: 1 | K35: 1 | L35: 1 | M35: 1 | N35: 1 | O35: 1 | P35: 1 | Q35: 1 | R35: 1 | S35: 1 | T35: 1 | U35: 1 | V35: 1 | W35: 1 | X35: 1 | Y35: 1 | Z35: 1 | AA35: 1 | AB35: 1 | AC35: 1
E36: Saturday | F36: 1 | G36: 1 | H36: 1 | I36: 1 | J36: 1 | K36: 1 | L36: 1 | M36: 1 | N36: 1 | O36: 1 | P36: 1 | Q36: 1 | R36: 1 | S36: 1 | T36: 1 | U36: 1 | V36: 1 | W36: 1 | X36: 1 | Y36: 1 | Z36: 1 | AA36: 1 | AB36: 1 | AC36: 1
E37: Sunday | F37: 1 | G37: 1 | H37: 1 | I37: 1 | J37: 1 | K37: 1 | L37: 1 | M37: 1 | N37: 1 | O37: 1 | P37: 1 | Q37: 1 | R37: 1 | S37: 1 | T37: 1 | U37: 1 | V37: 1 | W37: 1 | X37: 1 | Y37: 1 | Z37: 1 | AA37: 1 | AB37: 1 | AC37: 1
B38: Building | C38: ExtLightingMotionCtrl | E38: Weekday | F38: 0 | G38: 0 | H38: 0 | I38: 0 | J38: 0 | K38: 1 | L38: 1 | M38: 1 | N38: 1 | O38: 1 | P38: 1 | Q38: 1 | R38: 1 | S38: 1 | T38: 1 | U38: 1 | V38: 1 | W38: 1 | X38: 1 | Y38: 1 | Z38: 1 | AA38: 1 | AB38: 0 | AC38: 0
E39: Saturday | F39: 0 | G39: 0 | H39: 0 | I39: 0 | J39: 0 | K39: 1 | L39: 1 | M39: 1 | N39: 1 | O39: 1 | P39: 1 | Q39: 1 | R39: 1 | S39: 1 | T39: 1 | U39: 1 | V39: 1 | W39: 1 | X39: 1 | Y39: 1 | Z39: 1 | AA39: 1 | AB39: 1 | AC39: 1
E40: Sunday | F40: 0 | G40: 0 | H40: 0 | I40: 0 | J40: 0 | K40: 1 | L40: 1 | M40: 1 | N40: 1 | O40: 1 | P40: 1 | Q40: 1 | R40: 1 | S40: 1 | T40: 1 | U40: 1 | V40: 1 | W40: 1 | X40: 1 | Y40: 1 | Z40: 1 | AA40: 1 | AB40: 1 | AC40: 1
...

Sheet Energy Usage
A1: CalBEM Energy Consumption - OfficeSmall | I1: National Average (EnergyStar Portfolio Manager) | N1: CEUS Energy Consumption - OfficeSmall
A2: Prototype | B2: CZ | C2: CalBEM Electricity EUI (KBTU/ft²) | D2: CalBEM Gas EUI (KBTU/ft²) | E2: CalBEM Total EUI (KBTU/ft²) | F2: New Construction Electricity EUI (KBTU/ft²) | G2: New Construction Gas EUI (KBTU/ft²) | H2: New Construction Total EUI (KBTU/ft²) | I2: National Average | J2: Acceptable RangeRange (25% Higher) | K2: Acceptable RangeRange (25% Lower) | L2: National Average Acceptable Range | M2: Zip code | N2: Prototype | O2: CZ | P2: Total Floorspace (Thousand of ft2) | Q2: CEUS 2022 Electric Energy Intensity (kWh/ft²) | R2: CEUS 2022 Annual Gas Intensity (kWh/ft²) | S2: CEUS 2022 Total EUI (kBtu/ft²) | T2: Acceptable Range (25% Higher) | U2: Acceptable Range (25% Lower) | V2: CEUS 2022 Acceptable Range
A3: HotelSmall | B3: 1 | C3: 37.4 | D3: 33.4 | E3: 70.8 | F3: 33.6 | G3: 2.8 | H3: 36.4 | I3: 61.7 | J3: =I3*1.25 -> 77.125 | K3: =I3*0.75 -> 46.275 | L3: =J3-K3 -> 30.85 | M3: 95521 | N3: OfficeSmall | O3: 1 | P3: 12266 | Q3: 9.77 | R3: 4.88 | S3: =(Q3+R3)*3.412 -> 49.9858 | T3: =S3*1.25 -> 62.48225 | U3: =S3*0.75 -> 37.48935 | V3: =T3-U3 -> 24.9929
B4: 2 | C4: 45 | D4: 23.6 | E4: 68.6 | F4: 35.3 | G4: 2.7 | H4: 38 | I4: 67.5 | J4: =I4*1.25 -> 84.375 | K4: =I4*0.75 -> 50.625 | L4: =J4-K4 -> 33.75 | M4: 95476 | O4: 2 | P4: 27044 | Q4: 7.5 | R4: 5.6 | S4: =(Q4+R4)*3.412 -> 44.6972 | T4: =S4*1.25 -> 55.8715 | U4: =S4*0.75 -> 33.5229 | V4: =T4-U4 -> 22.3486
B5: 3 | C5: 38.7 | D5: 16.5 | E5: 55.3 | F5: 32.9 | G5: 2.7 | H5: 35.6 | I5: 64.2 | J5: =I5*1.25 -> 80.25 | K5: =I5*0.75 -> 48.15 | L5: =J5-K5 -> 32.1 | M5: 94612 | O5: 3 | P5: 84735 | Q5: 8.62 | R5: 7.47 | S5: =(Q5+R5)*3.412 -> 54.89908 | T5: =S5*1.25 -> 68.62385 | U5: =S5*0.75 -> 41.17431 | V5: =T5-U5 -> 27.44954
B6: 4 | C6: 47.6 | D6: 20.7 | E6: 68.3 | F6: 37.8 | G6: 2.7 | H6: 40.5 | I6: 69.7 | J6: =I6*1.25 -> 87.125 | K6: =I6*0.75 -> 52.275 | L6: =J6-K6 -> 34.85 | M6: 93446 | O6: 4 | P6: 41723 | Q6: 8.85 | R6: 7.21 | S6: =(Q6+R6)*3.412 -> 54.79672 | T6: =S6*1.25 -> 68.4959 | U6: =S6*0.75 -> 41.09754 | V6: =T6-U6 -> 27.39836
