Workbook
Name nonparticipating_forecastzone_scale_factor: 'Energy Usage'!#REF!
Name Space_Function: Data!$A$2:$A$76

Sheet Notes
A1: Data Sources
A2: Dataset | B2: Dodge 2023
B3: CEUS 2022
B4: ComStock 2023
A6: Prototype | B6: PNNL Outpatient prototype (90.1-2022) | C6: https://www.energycodes.gov/prototype-building-models#Commercial
A9: Codes | B9: Title 24, part 6, referred to as T24 (1984, 2001, 2007, 2013, 2016, 2022, 2025)
B10: ASHRAE 90.1 (2022)
B11: CFR Title 10 (2008, 2010, 2025)
B12: ASHRAE 170/OSHPD
B13: 2022 California Mechanical Code (Title 24, Part 4)
B14: ACM 2022
B15: T24 2022 - Appendix 5.4A and Appendix 5.4B | C15: https://www.energy.ca.gov/publications/2022/2022-nonresidential-and-multifamily-alternative-calculation-method-reference
A17: Other | B17: 2022 Reduced infiltration CASE report | C17: https://title24stakeholders.com/wp-content/uploads/2020/10/2022-T24-Final-CASE-Report_Reduce-Infiltration.pdf
B18: 2019 Outdoor Lighting CASE Report | C18: https://title24stakeholders.com/wp-content/uploads/2016/10/T24-2019-CASE-Study-Results-Report-Outdoor-Sources_Final_with-Attachments.pdf
B19: PNNL 20405, 2010 | C19: https://www.pnnl.gov/main/publications/external/technical_reports/PNNL-20405.pdf
B20: Air leakage Memo, NORESCO, 2025 | C20: https://2050partners.sharepoint.com/:w:/r/sites/CalBEMCollaborativeEfforts/_layouts/15/Doc.aspx?sourcedoc=%7B3BEF8F74-7FAC-44F2-A70C-D76617660066%7D&file=Infiltration_rate_report_14May2025-Short-Version.docx&wdLOR=c494C5A60-5F8A-438B-874B-578DCB850072&action=default&mobileredirect=true
B21: 2019 High Efficiency Fume Hoods in Laboratory Spaces CASE Report | C21: https://title24stakeholders.com/wp-content/uploads/2017/09/2019-T24-CASE-Report_Fume-Hoods_Final_September-2017.pdf?
A23: Construction Rate
A36: Notes
A37: Outpatient | B37: An outpatient facility, is a medical building that provides scheduled, non-emergency services such as diagnostic imaging, minor procedures, and consultations without overnight stays. It operates during standard business hours and includes exam rooms, procedure rooms, labs, waiting areas, and administrative spaces. HVAC systems are typically partial outdoor air systems, with moderate ventilation and pressurization controls tailored to specific healthcare spaces.
A38: EIA, 2018 CBECS | B38: On average, hospitals were 264,800 square feet per building, but outpatient health care buildings averaged 13,700 square feet.
A39: Source | B39: https://www.eia.gov/consumption/commercial/

Sheet Prototype
A1: NORESCO, Updated August 2025
A2: Outpatient
A3: Characteristic | B3: Value | C3: Data Sources
A4: Building Type | B4: Outpatient
A5: Building Category | B5: Nonresidential
A6: Vintages | B6: 4 Vintages: Pre-1978 , 1978-1997 ,1998-2007 , 2008-2018 New Construction (2019+) | C6: Based on the vintage bin analysis | D6: NonRes-Vintage bins-Draft Report-30Nov2023-Final.docx
A7: Shape | C7: The analysis uses prototype geometry originally developed by PNNL.
A8: Total Floor Area (ft²) | B8: 40950 | C8: Same as PNNL
A9: Aspect Ratio | B9: n/a | C9: Same as PNNL
A10: Number of Floors | B10: 3 | C10: Same as PNNL
A11: Roof type | B11: Flat roof | C11: Same as PNNL
A12: WWR | B12: North: 20.5%, East:19.1%, South: 24.1%, West: 12.9% Average Total: 20%
A13: Shading Geometry | B13: No Shades | C13: Same as PNNL
A14: Floor to floor height (feet) | B14: 10 ft | C14: Same as PNNL
A15: Floor to ceiling height (feet) | B15: 10 ft | C15: Same as PNNL
A16: Glazing sill height (feet) | B16: 3 ft (4 ft high windows) | C16: Same as PNNL
A20: Above grade wall area (ft²) | B20: 16716.353
A21: Gross wall area (ft²) | B21: 16716.353
A22: Roof area (ft²) | B22: 14778.849
A23: Underground Gross Wall Area (ft²) | B23: 0

Sheet Zones
A1: ="Proposed Layout - "&Prototype!A2 -> Proposed Layout - Outpatient
A2: Space Type | B2: Space/ Thermal Zone | C2: HVAC System Name/AHU Name | D2: Schedule Category | E2: Conditioned (Y/N) | F2: Area Fraction | G2: Area (ft²) | H2: Volume (ft³) | I2: Multipliers | J2: Number of People | K2: People (Persons/1,000 ft²) [T24, 2025,Table 120.1-A]
A3: Healthcare Facility and Hospitals (Exam/Treatment Room) | B3: Floor 1 Anesthesia | C3: AHU-1 | D3: Health | E3: Yes | F3: =G3/$G$121 -> 0.0026376203 | G3: 108 | H3: 1080 | I3: 1 | J3: =K3*G3/1000 -> 1.08 | K3: 10
A4: Healthcare Facility and Hospitals (Medical Supply Room) | B4: Floor 1 Bio Haz | C4: AHU-1 | D4: Health | E4: Yes | F4: =G4/$G$121 -> 0.001367655 | G4: 56 | H4: 560 | I4: 1 | J4: =K4*G4/1000 -> 0.56 | K4: 10
A5: Dining Area (Cafeteria/Fast Food) | B5: Floor 1 Café | C5: AHU-1 | D5: Health | E5: Yes | F5: =G5/$G$121 -> 0.010257412 | G5: 420 | H5: 4200 | I5: 1 | J5: =K5*G5/1000 -> 13.86 | K5: 33
A6: Healthcare Facility and Hospitals (Medical Supply Room) | B6: Floor 1 Clean | C6: AHU-1 | D6: Health | E6: Yes | F6: =G6/$G$121 -> 0.0030772237 | G6: 126 | H6: 1260 | I6: 1 | J6: =K6*G6/1000 -> 1.26 | K6: 10
A7: Healthcare Facility and Hospitals (Medical Supply Room) | B7: Floor 1 Clean Work | C7: AHU-1 | D7: Health | E7: Yes | F7: =G7/$G$121 -> 0.0040296977 | G7: 165 | H7: 1650 | I7: 1 | J7: =K7*G7/1000 -> 1.65 | K7: 10
A8: Office Area (<250 square feet) | B8: Floor 1 Dictation | C8: AHU-1 | D8: Office | E8: Yes | F8: =G8/$G$121 -> 0.0030772237 | G8: 126 | H8: 1260 | I8: 1 | J8: =K8*G8/1000 -> 0.63 | K8: 5
A9: Office Area (<250 square feet) | B9: Floor 1 Dressing Room | C9: AHU-1 | D9: Office | E9: Yes | F9: =G9/$G$121 -> 0.0010990085 | G9: 45 | H9: 450 | I9: 1 | J9: =K9*G9/1000 -> 0.225 | K9: 5
A10: Electrical, Mechanical, Telephone Rooms | B10: Floor 1 Electrical Room | C10: AHU-1 | D10: Health | E10: Yes | F10: =G10/$G$121 -> 0.0023933962 | G10: 98 | H10: 980 | I10: 1 | J10: =K10*G10/1000 -> 0.294 | K10: 3
A11: Electrical, Mechanical, Telephone Rooms | B11: Floor 1 Elevator Pump Room | C11: AHU-1 | D11: Health | E11: Yes | F11: =G11/$G$121 -> 0.0022224393 | G11: 91 | H11: 910 | I11: 1 | J11: =K11*G11/1000 -> 0.273 | K11: 3
A12: Office Area (<250 square feet) | B12: Floor 1 Humid | C12: AHU-1 | D12: Office | E12: Yes | F12: =G12/$G$121 -> 0.0013188101 | G12: 54 | H12: 540 | I12: 1 | J12: =K12*G12/1000 -> 0.27 | K12: 5
A13: Corridor Area | B13: Floor 1 IT Hall | C13: AHU-1 | D13: Health | E13: Yes | F13: =G13/$G$121 -> 0.0034191374 | G13: 140 | H13: 1400 | I13: 1 | J13: =K13*G13/1000 -> 0.7 | K13: 5
A14: Office Area (<250 square feet) | B14: Floor 1 IT Room | C14: AHU-1 | D14: Office | E14: Yes | F14: =G14/$G$121 -> 0.0027353099 | G14: 112 | H14: 1120 | I14: 1 | J14: =K14*G14/1000 -> 0.56 | K14: 5
... A120: Stairwell | B120: SW Stair | C120: AHU-3 | D120: Health | E120: Yes | F120: =G120/$G$121 -> 0.0023445514 | G120: 96 | H120: 2880 | I120: 1 | J120: =K120*G120/1000 -> 0.48 | K120: 5
A121: Total (23 Space types) | B121: Total ( 118 spaces) | C121: Total ( Thermal Zones) | E121: Total ( 118 Conditioned zones) | G121: =SUM(G3:G120) -> 40946 | I121: =SUM(I3:I120) -> 118 | J121: =SUM(J3:J120) -> 329.193
A133: Background Data [To be deleted prior to publication]

Sheet Envelope
A1: ="Envelope - "&Prototype!A2 -> Envelope - Outpatient
A2: Element | B2: Prototype | C2: Assembly Type | D2: Construction | E2: Unit | F2: Vintage | G2: Selected T24 | H2: Note | I2: CZ1 | J2: CZ2 | K2: CZ3 | L2: CZ4 | M2: CZ5 | N2: CZ6 | O2: CZ7 | P2: CZ8 | Q2: CZ9 | R2: CZ10 | S2: CZ11 | T2: CZ12 | U2: CZ13 | V2: CZ14 | W2: CZ15 | X2: CZ16
A3: External Wall | B3: =Prototype!A2 -> Outpatient | C3: ExtWall_MetalFramed_NonRes | D3: Metal frame + insulation + gypsum board | E3: U-value IP | F3: Pre 1978 | G3: N/A | H3: ASHRAE 90.1,2022 Table A3.3.3.1, 3.5", R-0 | I3: 0.352 | J3: 0.352 | K3: 0.352 | L3: 0.352 | M3: 0.352 | N3: 0.352 | O3: 0.352 | P3: 0.352 | Q3: 0.352 | R3: 0.352 | S3: 0.352 | T3: 0.352 | U3: 0.352 | V3: 0.352 | W3: 0.352 | X3: 0.352
F4: 1978-1997 | G4: 1986 | H4: Package A with heat capacity around 10 (Btu/F/ft²) | I4: 0.213 | J4: 0.227 | K4: 0.227 | L4: 0.217 | M4: 0.256 | N4: 0.256 | O4: 0.256 | P4: 0.256 | Q4: 0.256 | R4: 0.256 | S4: 0.238 | T4: 0.238 | U4: 0.238 | V4: 0.208 | W4: 0.208 | X4: 0.213
F5: 1998-2007 | G5: 2001 | H5: Table 1-H | I5: 0.182 | J5: 0.182 | K5: 0.189 | L5: 0.189 | M5: 0.189 | N5: 0.189 | O5: 0.189 | P5: 0.189 | Q5: 0.189 | R5: 0.182 | S5: 0.182 | T5: 0.182 | U5: 0.182 | V5: 0.182 | W5: 0.182 | X5: 0.182
F6: 2008-2018 | G6: 2013 | H6: Table 140.3-B | I6: 0.098 | J6: 0.062 | K6: 0.082 | L6: 0.062 | M6: 0.062 | N6: 0.098 | O6: 0.098 | P6: 0.062 | Q6: 0.062 | R6: 0.062 | S6: 0.062 | T6: 0.062 | U6: 0.062 | V6: 0.062 | W6: 0.062 | X6: 0.062
F7: 2019+ | G7: 2025 | H7: Table 140.3-B | I7: 0.06 | J7: 0.055 | K7: 0.071 | L7: 0.055 | M7: 0.055 | N7: 0.06 | O7: 0.06 | P7: 0.055 | Q7: 0.055 | R7: 0.055 | S7: 0.055 | T7: 0.055 | U7: 0.055 | V7: 0.055 | W7: 0.055 | X7: 0.055
A8: Roof | B8: =$B$3 -> Outpatient | C8: FlatRoof_WoodFramedAndOther_NonRes | D8: Built-up Roof (Metal Decking Roof): Roof membrane + roof insulation + metal decking | E8: U-value IP | F8: Pre 1978 | G8: N/A | H8: Considering 30 years for roof/ insulation replacement. | I8: 0.057 | J8: 0.057 | K8: 0.057 | L8: 0.057 | M8: 0.057 | N8: 0.078 | O8: 0.078 | P8: 0.078 | Q8: 0.078 | R8: 0.078 | S8: 0.057 | T8: 0.057 | U8: 0.057 | V8: 0.057 | W8: 0.057 | X8: 0.057
F9: 1978-1997 | G9: 1992 | I9: 0.057 | J9: 0.057 | K9: 0.057 | L9: 0.057 | M9: 0.057 | N9: 0.078 | O9: 0.078 | P9: 0.078 | Q9: 0.078 | R9: 0.078 | S9: 0.057 | T9: 0.057 | U9: 0.057 | V9: 0.057 | W9: 0.057 | X9: 0.057
F10: 1998-2007 | G10: 2001 | H10: Table 1-H | I10: 0.057 | J10: 0.057 | K10: 0.057 | L10: 0.057 | M10: 0.057 | N10: 0.078 | O10: 0.078 | P10: 0.078 | Q10: 0.078 | R10: 0.057 | S10: 0.057 | T10: 0.057 | U10: 0.057 | V10: 0.057 | W10: 0.057 | X10: 0.057
F11: 2008-2018 | G11: 2013 | H11: Table 140.3-B | I11: 0.049 | J11: 0.039 | K11: 0.039 | L11: 0.039 | M11: 0.049 | N11: 0.075 | O11: 0.067 | P11: 0.067 | Q11: 0.039 | R11: 0.039 | S11: 0.039 | T11: 0.039 | U11: 0.039 | V11: 0.039 | W11: 0.039 | X11: 0.039
F12: 2019+ | G12: 2025 | H12: Table 140.3-B | I12: 0.038 | J12: 0.038 | K12: 0.038 | L12: 0.038 | M12: 0.038 | N12: 0.038 | O12: 0.038 | P12: 0.038 | Q12: 0.038 | R12: 0.038 | S12: 0.038 | T12: 0.038 | U12: 0.038 | V12: 0.038 | W12: 0.038 | X12: 0.038
A13: Windows | B13: =$B$3 -> Outpatient | C13: FixedWindow_NonRes | D13: Single pane | E13: U-value IP | F13: Pre 1978 | G13: N/A | H13: ASHRAE Handbook of Fundamentals (Table 4-Ch15) for single pane & T24, 2013 for double pane(88%-12%)* | I13: =0.88*1.12+0.12*0.36 -> 1.0288 | J13: =0.88*1.12+0.12*0.36 -> 1.0288 | K13: =0.88*1.12+0.12*0.36 -> 1.0288 | L13: =0.88*1.12+0.12*0.36 -> 1.0288 | M13: =0.88*1.12+0.12*0.36 -> 1.0288 | N13: =0.88*1.12+0.12*0.36 -> 1.0288 | O13: =0.88*1.12+0.12*0.36 -> 1.0288 | P13: =0.88*1.12+0.12*0.36 -> 1.0288 | ... X13: =0.88*1.12+0.12*0.36 -> 1.0288
F14: 1978-1997 | G14: N/A | I14: =0.88*1.12+0.12*0.36 -> 1.0288 | J14: =0.88*1.12+0.12*0.36 -> 1.0288 | K14: =0.88*1.12+0.12*0.36 -> 1.0288 | L14: =0.88*1.12+0.12*0.36 -> 1.0288 | M14: =0.88*1.12+0.12*0.36 -> 1.0288 | N14: =0.88*1.12+0.12*0.36 -> 1.0288 | O14: =0.88*1.12+0.12*0.36 -> 1.0288 | P14: =0.88*1.12+0.12*0.36 -> 1.0288 | ... X14: =0.88*1.12+0.12*0.36 -> 1.0288
D15: Double pane | F15: 1998-2007 | G15: 2001 | H15: Table 1-H | I15: 0.49 | J15: 0.49 | K15: 0.81 | L15: 0.81 | M15: 0.81 | N15: 0.81 | O15: 0.81 | P15: 0.81 | Q15: 0.81 | R15: 0.49 | S15: 0.49 | T15: 0.49 | U15: 0.49 | V15: 0.49 | W15: 0.49 | X15: 0.49
F16: 2008-2018 | G16: 2013 | H16: Table 140.3-B | I16: 0.36 | J16: 0.36 | K16: 0.36 | L16: 0.36 | M16: 0.36 | N16: 0.36 | O16: 0.36 | P16: 0.36 | Q16: 0.36 | R16: 0.36 | S16: 0.36 | T16: 0.36 | U16: 0.36 | V16: 0.36 | W16: 0.36 | X16: 0.36
F17: 2019+ | G17: 2025 | H17: Table 140.3-B | I17: 0.36 | J17: 0.36 | K17: 0.36 | L17: 0.36 | M17: 0.36 | N17: 0.36 | O17: 0.36 | P17: 0.36 | Q17: 0.34 | R17: 0.36 | S17: 0.34 | T17: 0.34 | U17: 0.34 | V17: 0.34 | W17: 0.34 | X17: 0.36
B18: =$B$3 -> Outpatient | C18: FixedWindow_NonRes | D18: Single pane | E18: SHGC | F18: Pre 1978 | G18: N/A | H18: ASHRAE Handbook of Fundamentals (Table 10-Ch15) for single pane & T24, 2013 for double pane(88%-12%)* | I18: =0.79*0.88+0.12*I21 -> 0.7252 | J18: =0.79*0.88+0.12*J21 -> 0.7252 | K18: =0.79*0.88+0.12*K21 -> 0.7252 | L18: =0.79*0.88+0.12*L21 -> 0.7252 | M18: =0.79*0.88+0.12*M21 -> 0.7252 | N18: =0.79*0.88+0.12*N21 -> 0.7252 | O18: =0.79*0.88+0.12*O21 -> 0.7252 | P18: =0.79*0.88+0.12*P21 -> 0.7252 | ... X18: =0.79*0.88+0.12*X21 -> 0.7252
F19: 1978-1997 | G19: N/A | I19: =0.79*0.88+0.12*I21 -> 0.7252 | J19: =0.79*0.88+0.12*J21 -> 0.7252 | K19: =0.79*0.88+0.12*K21 -> 0.7252 | L19: =0.79*0.88+0.12*L21 -> 0.7252 | M19: =0.79*0.88+0.12*M21 -> 0.7252 | N19: =0.79*0.88+0.12*N21 -> 0.7252 | O19: =0.79*0.88+0.12*O21 -> 0.7252 | P19: =0.79*0.88+0.12*P21 -> 0.7252 | ... X19: =0.79*0.88+0.12*X21 -> 0.7252
D20: Double pane | F20: 1998-2007 | G20: 2001 | H20: Table 1-H - WWR:10-20% / SHGC non-north | I20: 0.43 | J20: 0.36 | K20: 0.55 | L20: 0.55 | M20: 0.55 | N20: 0.61 | O20: 0.61 | P20: 0.61 | Q20: 0.61 | R20: 0.36 | S20: 0.36 | T20: 0.36 | U20: 0.36 | V20: 0.36 | W20: 0.36 | X20: 0.43
F21: 2008-2018 | G21: 2013 | H21: Table 140.3-B | I21: 0.25 | J21: 0.25 | K21: 0.25 | L21: 0.25 | M21: 0.25 | N21: 0.25 | O21: 0.25 | P21: 0.25 | Q21: 0.25 | R21: 0.25 | S21: 0.25 | T21: 0.25 | U21: 0.25 | V21: 0.25 | W21: 0.25 | X21: 0.25
F22: 2019+ | G22: 2025 | H22: Table 140.3-B | I22: 0.25 | J22: 0.25 | K22: 0.25 | L22: 0.25 | M22: 0.25 | N22: 0.25 | O22: 0.25 | P22: 0.25 | Q22: 0.22 | R22: 0.25 | S22: 0.22 | T22: 0.22 | U22: 0.22 | V22: 0.22 | W22: 0.22 | X22: 0.25
A23: PNNL models have steel-framed walls.
E25: Infiltration
F26: Vintage | G26: I_75 6-sdied Infiltration rate @ 75 pa | H26: Note | I26: I-design (cfm/ft²) (4-sided Infiltration rate at normal pressure) (Design flow rate approach and Flow/Exterior Wall Area calculation method)
E27: Infiltration | F27: Pre 1978 | G27: 1.1 | H27: 2022 CASE report (Table 38) | I27: 0.341
F28: 1978-1997 | G28: 1.1 | H28: 2022 CASE report (Table 38) | I28: 0.341
F29: 1998-2007 | G29: 1.1 | H29: 2022 CASE report (Table 38) | I29: 0.341
F30: 2008-2018 | G30: 1 | H30: 2022 CASE report (Table 38) & T24, 2008-2016 (Table 140.3-B)--Air barrier is required in CZ 10-16 | I30: 0.3121
F31: 2019+ | G31: 0.6 | H31: 2022 CASE report (Table 38) & T24, 2025 (Table 140.3-B)--Air barrier is required in all CZs | I31: 0.186
E32: Source: Title 24 air barrier requirements (all editions) and the standardized infiltration rate reported in the 2022 CASE report and Dodge 2023 data
E33: Air Leakage Memo: | G33: Infiltration_rate_report_14May2025-Short-Version.docx

Sheet Thermostat
A1: ="Thermostat - "&Prototype!A2 -> Thermostat - Outpatient
A2: Setpoint | B2: CZ1 | C2: CZ2 | D2: CZ3 | E2: CZ4 | F2: CZ5 | G2: CZ6 | H2: CZ7 | I2: CZ8 | J2: CZ9 | K2: CZ10 | L2: CZ11 | M2: CZ12 | N2: CZ13 | O2: CZ14 | P2: CZ15 | Q2: CZ16 | R2: Source | S2: Note
A3: Health Heating Setpoint (F) | B3: 70 | C3: 70 | D3: 70 | E3: 70 | F3: 70 | G3: 70 | H3: 70 | I3: 70 | J3: 70 | K3: 70 | L3: 70 | M3: 70 | N3: 70 | O3: 70 | P3: 70 | Q3: 70 | R3: T24 2022 - Appendix 5.4B | S3: PNNL Healthcare-Outpatient prototype use this setpoints: Administration zones: 72°F Cooling/70°F Heating, Critical zones: 72°F Cooling/70°F Heating, Operating rooms: 65°F Cooling/65°F Heating---PNNL Healthcare-Outpatient prototype use this setbacks: 77°F Cooling/65°F Heating, Critical zones: no setback, Operating rooms: 72°F Cooling/65°F Heating
A4: Health Heating Setback (F) | B4: 70 | C4: 70 | D4: 70 | E4: 70 | F4: 70 | G4: 70 | H4: 70 | I4: 70 | J4: 70 | K4: 70 | L4: 70 | M4: 70 | N4: 70 | O4: 70 | P4: 70 | Q4: 70
A5: Health Cooling Setpoint (F) | B5: 75 | C5: 75 | D5: 75 | E5: 75 | F5: 75 | G5: 75 | H5: 75 | I5: 75 | J5: 75 | K5: 75 | L5: 75 | M5: 75 | N5: 75 | O5: 75 | P5: 75 | Q5: 75
A6: Health Cooling Setback (F) | B6: 75 | C6: 75 | D6: 75 | E6: 75 | F6: 75 | G6: 75 | H6: 75 | I6: 75 | J6: 75 | K6: 75 | L6: 75 | M6: 75 | N6: 75 | O6: 75 | P6: 75 | Q6: 75
A7: Kitchen Heating Setpoint (F) | B7: 66 | C7: 66 | D7: 66 | E7: 66 | F7: 66 | G7: 66 | H7: 66 | I7: 66 | J7: 66 | K7: 66 | L7: 66 | M7: 66 | N7: 66 | O7: 66 | P7: 66 | Q7: 66 | R7: PNNL 09.1, 2022 Restaurant prototype
A8: Kitchen Heating Setback (F) | B8: 60 | C8: 60 | D8: 60 | E8: 60 | F8: 60 | G8: 60 | H8: 60 | I8: 60 | J8: 60 | K8: 60 | L8: 60 | M8: 60 | N8: 60 | O8: 60 | P8: 60 | Q8: 60
A9: Kitchen Cooling Setpoint (F) | B9: 79 | C9: 79 | D9: 79 | E9: 79 | F9: 79 | G9: 79 | H9: 79 | I9: 79 | J9: 79 | K9: 79 | L9: 79 | M9: 79 | N9: 79 | O9: 79 | P9: 79 | Q9: 79
A10: Kitchen Cooling Setback (F) | B10: 86 | C10: 86 | D10: 86 | E10: 86 | F10: 86 | G10: 86 | H10: 86 | I10: 86 | J10: 86 | K10: 86 | L10: 86 | M10: 86 | N10: 86 | O10: 86 | P10: 86 | Q10: 86

Sheet HVAC System
A1: ="HVAC System - "&Prototype!A2 -> HVAC System - Outpatient
A2: Vintage | B2: Spaces | C2: Heating | D2: Cooling | E2: Air Distribution | F2: Source | G2: Note
A3: Existing | B3: Conditioned zones | C3: Gas Boiler for Hydronic Reheat and Gas Furnace for Heating | D3: RTU DX | E3: Single Duct CAV--Outdoor air often supplied through RTU economizers or dedicated OA section | F3: CEUS 2022 (Other system based on T24 and Engineering judgement) | G3: Packaged RTU
A4: New Construction | B4: Conditioned zones | C4: Gas Boiler for Hydronic Reheat and Gas Furnace for Heating | D4: RTU DX | E4: VAV + Hydronic Reheat | F4: T24 2025 ACM 2025, Table 2 and 3 | G4: System 5 – PVAV
A8: Efficiency of HVAC system
A9: Vintage | B9: Upgrade/Installed year | C9: DX Cooling | D9: Gas Furnace | E9: Gas Boiler | F9: Source | G9: Note
A10: Pre 1978 | B10: 2008 | C10: EER=9.5 (≥ 240,000 Btu/h and < 760,000 Btu/h) | D10: . Gas-fired forced air furnaces with input ratings ≥225,000 Btu/h--75% of the input rating | E10: n/a | F10: T24, 2008 , Table 112-A (for DX Coil)
A11: 1978-1997
A12: 1998-2007
A13: 2008-2018 | B13: 2013 | C13: EER=10 (≥ 240,000 Btu/h and < 760,000 Btu/h) | D13: Warm-Air Duct Furnaces, Gas-Fired-All Capacities--80% Ec | E13: n/a | F13: T24, 2013 , Table 110.2-D (for DX Coil) -Table 110.2-I (for Gas Furnace thermal efficiency)
A14: New Construction | B14: 2025 | C14: EER=10 (≥ 240,000 Btu/h and < 760,000 Btu/h) | D14: Warm-Air Duct Furnaces, Gas-Fired-All Capacities--80% Ec | E14: Gas-Fired Boiler ≥ 300,000 Btu/h and ≤ 2,500,000 Btu/h-- 84% Et | F14: T24, 2013 , Table 110.2-A (for DX Coil) - Table 110.2-J (for Boiler thermal efficiency)-Table 110.2-I (for Gas Furnace thermal efficiency)
C16: * Et = Combustion efficiency | D16: * Et = Thermal efficiency
A19: Fan power
A20: Vintage | B20: Approach | C20: System | D20: Total Static Pressure (TSP) in w.c. [PNNL 20405, 2010, Table 5.11] | E20: Fan Efficiency [ACM, 2025] | F20: Fan Motor and Drive Efficiency [ACM 2025, Table 13] | G20: W/cfm [ACM 2025, Table 14 and 15] | H20: Data Source | I20: Note
A21: Existing | B21: PNNL TSP | C21: Packaged RTU-CAV | D21: 4.09 | E21: 0.65 | F21: 0.9 | H21: ACM 2025, PNNL 2010 TSD
A22: Brake horse power (bhp)=(Supply cfm*TSP in w.c.)/(6356*Fan efficiency)
A23: Fan power (w/cfm) = bhp/motor and drive efficiency *746
A24: New Construction | B24: ACM 2025 | C24: Packaged RTU-CAV | D24: =G24*E24*F24/746*6356 -> 3.8877249 | E24: 0.65 | F24: 0.9 | G24: 0.78 | H24: 2025 ACM, PNNL 2010 TSD
C25: System 5-PVAV System >5,000 cfm; < 10,000 cfm | D25: =G25*E24*F24/746*6356 -> 5.0939165 | G25: 1.022
C26: System 5-PVAV System >10,000 cfm | D26: =G26*E24*F24/746*6356 -> 4.8048293 | G26: 0.964
F27: * 0.9 is an average fan efficiency according to ACM 2025, Table 13
A29: Fan total eff (E+ input) = 0.65 x Motor_eff
A30: TSP (E+ input) in w.c. = Motor_eff/746 x (6356 x Fan_eff) x W/cfm
A31: Fan_eff=0.65
A38: Background Data [To be deleted prior to publication]
A42: CEUS 2022 data | B42: Heating | F42: Cooling | H42: Air Distribution | I42: Water Heater
B43: Floorspace Heated | C43: Primary Heating | D43: Fuel Type | F43: Floorspace Cooled | G43: Primary Cooling | H43: Primary Air Dis | I43: Fuel Type
C44: The default is the floorspace method unless otherwise specified | D44: Elec | E44: Gas | G44: The default is the floorspace method unless otherwise specified | H44: The default is the floorspace method unless otherwise specified | I44: Elec | J44: Gas
A45: Health Care | B45: 0.99 | C45: Floorspace method: | D45: 0.17 | E45: 0.81 | F45: 0.98 | G45: Floorspace method: | H45: Floorspace method: | I45: 0.1 | J45: 0.85
C46: Boiler/ Hydronic (43.9%) | G46: Central Plant (Chiller) (43.5%) | H46: Single Duct CAV (53.4%)
C47: Package System / Heat Pump (40.8%) | G47: Package System / Heat Pump (40.7%) | H47: Fan Coil/Unit Ventilator (21.3%)
C48: Site method: | G48: Site method: | H48: Site method:
C49: Boiler/ Hydronic (6.8%) | G49: Central Plant (Chiller) (6.5%) | H49: Single Duct CAV (91.4%)
C50: Package System / Heat Pump (72.1%) | G50: Package System / Heat Pump (71.5%) | H50: Fan Coil/Unit Ventilator (5.7%)

Sheet Ventilation
A1: ="Outdoor Airflow Rate - "&Prototype!A2 -> Outdoor Airflow Rate - Outpatient
A2: Space Type | B2: Space/Thermal Zone | C2: Number of People | D2: Floor Area (ft²) | E2: cfm/person [T24, 2025, Equation 120.1-F and Table 120.1-A] | F2: cfm/ft² [T24, 2025, Equation 120.1-F and Table 120.1-A] | G2: Required Exhaust Rate (cfm/ft²) [T24, 2025, Table 120.1-B – minimum exhaust rates] | H2: Required Exhaust Rate (cfm) [T24, 2025, Table 120.1-B – minimum exhaust rates] | I2: Min OA Ventilation Requirement (cfm/ft²) [Table 4-A, 2022 California Mechanical Code] | J2: Total cfm Driven by People | K2: Total cfm Driven by Area | L2: Total cfm Driven by Exhaust | M2: Total cfm | N2: Note
A3: =Zones!A3 -> Healthcare Facility and Hospitals (Exam/Treatment Room) | B3: =Zones!B3 -> Floor 1 Anesthesia | C3: =Zones!J3 -> 1.08 | D3: =Zones!G3 -> 108 | E3: 15 | F3: =VLOOKUP(A3,A$183:E$205,5,FALSE) -> n/a | G3: 1.37 | I3: =VLOOKUP(A3,A$183:H$205,8,FALSE) -> 0.33333333 | J3: =E3*C3 -> 16.2 | K3: =IF(F3="n/a",D3*I3,F3*D3) -> 36 | L3: =G3*D3 -> 147.96 | M3: =MAX(J3:L3) -> 147.96 | N3: All Room air exhausted directly to the outdoor, according to Table 4-A, 2022 California Mechanical Code)
A4: =Zones!A4 -> Healthcare Facility and Hospitals (Medical Supply Room) | B4: =Zones!B4 -> Floor 1 Bio Haz | C4: =Zones!J4 -> 0.56 | D4: =Zones!G4 -> 56 | E4: 15 | F4: =VLOOKUP(A4,A$183:E$205,5,FALSE) -> n/a | I4: =VLOOKUP(A4,A$183:H$205,8,FALSE) -> 0.33333333 | J4: =E4*C4 -> 8.4 | K4: =IF(F4="n/a",D4*I4,F4*D4) -> 18.666667 | L4: =G4*D4 -> 0 | M4: =MAX(J4:L4) -> 18.666667
A5: =Zones!A5 -> Dining Area (Cafeteria/Fast Food) | B5: =Zones!B5 -> Floor 1 Café | C5: =Zones!J5 -> 13.86 | D5: =Zones!G5 -> 420 | E5: 15 | F5: =VLOOKUP(A5,A$183:E$205,5,FALSE) -> 0.15 | I5: =VLOOKUP(A5,A$183:H$205,8,FALSE) -> 0 | J5: =E5*C5 -> 207.9 | K5: =IF(F5="n/a",D5*I5,F5*D5) -> 63 | L5: =G5*D5 -> 0 | M5: =MAX(J5:L5) -> 207.9
A6: =Zones!A6 -> Healthcare Facility and Hospitals (Medical Supply Room) | B6: =Zones!B6 -> Floor 1 Clean | C6: =Zones!J6 -> 1.26 | D6: =Zones!G6 -> 126 | E6: 15 | F6: =VLOOKUP(A6,A$183:E$205,5,FALSE) -> n/a | I6: =VLOOKUP(A6,A$183:H$205,8,FALSE) -> 0.33333333 | J6: =E6*C6 -> 18.9 | K6: =IF(F6="n/a",D6*I6,F6*D6) -> 42 | L6: =G6*D6 -> 0 | M6: =MAX(J6:L6) -> 42
A7: =Zones!A7 -> Healthcare Facility and Hospitals (Medical Supply Room) | B7: =Zones!B7 -> Floor 1 Clean Work | C7: =Zones!J7 -> 1.65 | D7: =Zones!G7 -> 165 | E7: 15 | F7: =VLOOKUP(A7,A$183:E$205,5,FALSE) -> n/a | I7: =VLOOKUP(A7,A$183:H$205,8,FALSE) -> 0.33333333 | J7: =E7*C7 -> 24.75 | K7: =IF(F7="n/a",D7*I7,F7*D7) -> 55 | L7: =G7*D7 -> 0 | M7: =MAX(J7:L7) -> 55
A8: =Zones!A8 -> Office Area (<250 square feet) | B8: =Zones!B8 -> Floor 1 Dictation | C8: =Zones!J8 -> 0.63 | D8: =Zones!G8 -> 126 | E8: 15 | F8: =VLOOKUP(A8,A$183:E$205,5,FALSE) -> 0.15 | I8: =VLOOKUP(A8,A$183:H$205,8,FALSE) -> 0 | J8: =E8*C8 -> 9.45 | K8: =IF(F8="n/a",D8*I8,F8*D8) -> 18.9 | L8: =G8*D8 -> 0 | M8: =MAX(J8:L8) -> 18.9
A9: =Zones!A9 -> Office Area (<250 square feet) | B9: =Zones!B9 -> Floor 1 Dressing Room | C9: =Zones!J9 -> 0.225 | D9: =Zones!G9 -> 45 | E9: 15 | F9: =VLOOKUP(A9,A$183:E$205,5,FALSE) -> 0.15 | I9: =VLOOKUP(A9,A$183:H$205,8,FALSE) -> 0 | J9: =E9*C9 -> 3.375 | K9: =IF(F9="n/a",D9*I9,F9*D9) -> 6.75 | L9: =G9*D9 -> 0 | M9: =MAX(J9:L9) -> 6.75
A10: =Zones!A10 -> Electrical, Mechanical, Telephone Rooms | B10: =Zones!B10 -> Floor 1 Electrical Room | C10: =Zones!J10 -> 0.294 | D10: =Zones!G10 -> 98 | E10: 15 | F10: =VLOOKUP(A10,A$183:E$205,5,FALSE) -> 0.15 | I10: =VLOOKUP(A10,A$183:H$205,8,FALSE) -> 0 | J10: =E10*C10 -> 4.41 | K10: =IF(F10="n/a",D10*I10,F10*D10) -> 14.7 | L10: =G10*D10 -> 0 | M10: =MAX(J10:L10) -> 14.7
A11: =Zones!A11 -> Electrical, Mechanical, Telephone Rooms | B11: =Zones!B11 -> Floor 1 Elevator Pump Room | C11: =Zones!J11 -> 0.273 | D11: =Zones!G11 -> 91 | E11: 15 | F11: =VLOOKUP(A11,A$183:E$205,5,FALSE) -> 0.15 | I11: =VLOOKUP(A11,A$183:H$205,8,FALSE) -> 0 | J11: =E11*C11 -> 4.095 | K11: =IF(F11="n/a",D11*I11,F11*D11) -> 13.65 | L11: =G11*D11 -> 0 | M11: =MAX(J11:L11) -> 13.65
A12: =Zones!A12 -> Office Area (<250 square feet) | B12: =Zones!B12 -> Floor 1 Humid | C12: =Zones!J12 -> 0.27 | D12: =Zones!G12 -> 54 | E12: 15 | F12: =VLOOKUP(A12,A$183:E$205,5,FALSE) -> 0.15 | I12: =VLOOKUP(A12,A$183:H$205,8,FALSE) -> 0 | J12: =E12*C12 -> 4.05 | K12: =IF(F12="n/a",D12*I12,F12*D12) -> 8.1 | L12: =G12*D12 -> 0 | M12: =MAX(J12:L12) -> 8.1
A13: =Zones!A13 -> Corridor Area | B13: =Zones!B13 -> Floor 1 IT Hall | C13: =Zones!J13 -> 0.7 | D13: =Zones!G13 -> 140 | E13: 15 | F13: =VLOOKUP(A13,A$183:E$205,5,FALSE) -> 0.15 | I13: =VLOOKUP(A13,A$183:H$205,8,FALSE) -> 0 | J13: =E13*C13 -> 10.5 | K13: =IF(F13="n/a",D13*I13,F13*D13) -> 21 | L13: =G13*D13 -> 0 | M13: =MAX(J13:L13) -> 21
A14: =Zones!A14 -> Office Area (<250 square feet) | B14: =Zones!B14 -> Floor 1 IT Room | C14: =Zones!J14 -> 0.56 | D14: =Zones!G14 -> 112 | E14: 15 | F14: =VLOOKUP(A14,A$183:E$205,5,FALSE) -> 0.15 | I14: =VLOOKUP(A14,A$183:H$205,8,FALSE) -> 0 | J14: =E14*C14 -> 8.4 | K14: =IF(F14="n/a",D14*I14,F14*D14) -> 16.8 | L14: =G14*D14 -> 0 | M14: =MAX(J14:L14) -> 16.8
A15: =Zones!A15 -> Lobby, Main Entry | B15: =Zones!B15 -> Floor 1 Lobby | C15: =Zones!J15 -> 20.526 | D15: =Zones!G15 -> 622 | E15: 15 | F15: =VLOOKUP(A15,A$183:E$205,5,FALSE) -> 0.15 | I15: =VLOOKUP(A15,A$183:H$205,8,FALSE) -> 0 | J15: =E15*C15 -> 307.89 | K15: =IF(F15="n/a",D15*I15,F15*D15) -> 93.3 | L15: =G15*D15 -> 0 | M15: =MAX(J15:L15) -> 307.89
A16: =Zones!A16 -> Corridor Area | B16: =Zones!B16 -> Floor 1 Lobby Hall | C16: =Zones!J16 -> 1.2 | D16: =Zones!G16 -> 240 | E16: 15 | F16: =VLOOKUP(A16,A$183:E$205,5,FALSE) -> 0.15 | I16: =VLOOKUP(A16,A$183:H$205,8,FALSE) -> 0 | J16: =E16*C16 -> 18 | K16: =IF(F16="n/a",D16*I16,F16*D16) -> 36 | L16: =G16*D16 -> 0 | M16: =MAX(J16:L16) -> 36
A17: =Zones!A17 -> Restrooms | B17: =Zones!B17 -> Floor 1 Lobby Toilet | C17: =Zones!J17 -> 0.27 | D17: =Zones!G17 -> 54 | E17: 15 | F17: 0 | H17: 50 | I17: =VLOOKUP(A17,A$183:H$205,8,FALSE) -> 0 | J17: =E17*C17 -> 4.05 | K17: =IF(F17="n/a",D17*I17,F17*D17) -> 0 | L17: 50 | M17: 0 | N17: *Restrooms in California per 2025 T24 and CALGreen (Part 11) require mechanical exhaust ventilation, but they do not require additional dedicated outdoor air (OA) beyond that local exhaust. Bathroom exhaust and exhaust fan energy will be captured in the models. We will assume make-up air is drawn from adjacent spaces.
A18: =Zones!A18 -> Locker Room | B18: =Zones!B18 -> Floor 1 Locker Room | C18: =Zones!J18 -> 13.2 | D18: =Zones!G18 -> 660 | E18: 15 | F18: =VLOOKUP(A18,A$183:E$205,5,FALSE) -> 0.15 | G18: 0.25 | I18: =VLOOKUP(A18,A$183:H$205,8,FALSE) -> 0 | J18: =E18*C18 -> 198 | K18: =IF(F18="n/a",D18*I18,F18*D18) -> 99 | L18: =G18*D18 -> 165 | M18: =MAX(J18:L18) -> 198
A19: =Zones!A19 -> Corridor Area | B19: =Zones!B19 -> Floor 1 Locker Room Hall | C19: =Zones!J19 -> 2.48 | D19: =Zones!G19 -> 496 | E19: 15 | F19: =VLOOKUP(A19,A$183:E$205,5,FALSE) -> 0.15 | I19: =VLOOKUP(A19,A$183:H$205,8,FALSE) -> 0 | J19: =E19*C19 -> 37.2 | K19: =IF(F19="n/a",D19*I19,F19*D19) -> 74.4 | L19: =H19*D19 -> 0 | M19: =MAX(J19:L19) -> 74.4
A20: =Zones!A20 -> Lounge, Breakroom, or Waiting Area | B20: =Zones!B20 -> Floor 1 Lounge | C20: =Zones!J20 -> 11.88 | D20: =Zones!G20 -> 360 | E20: 15 | F20: =VLOOKUP(A20,A$183:E$205,5,FALSE) -> 0.15 | I20: =VLOOKUP(A20,A$183:H$205,8,FALSE) -> 0 | J20: =E20*C20 -> 178.2 | K20: =IF(F20="n/a",D20*I20,F20*D20) -> 54 | L20: =H20*D20 -> 0 | M20: =MAX(J20:L20) -> 178.2
A21: =Zones!A21 -> Healthcare Facility and Hospitals (Medical Supply Room) | B21: =Zones!B21 -> Floor 1 Med Gas | C21: =Zones!J21 -> 0.56 | D21: =Zones!G21 -> 56 | E21: 15 | F21: =VLOOKUP(A21,A$183:E$205,5,FALSE) -> n/a | I21: =VLOOKUP(A21,A$183:H$205,8,FALSE) -> 0.33333333 | J21: =E21*C21 -> 8.4 | K21: =IF(F21="n/a",D21*I21,F21*D21) -> 18.666667 | L21: =H21*D21 -> 0 | M21: =MAX(J21:L21) -> 18.666667
A22: =Zones!A22 -> Healthcare Facility and Hospitals (Imaging Room) | B22: =Zones!B22 -> Floor 1 MRI Control Room | C22: =Zones!J22 -> 1.68 | D22: =Zones!G22 -> 168 | E22: 15 | F22: =VLOOKUP(A22,A$183:E$205,5,FALSE) -> n/a | G22: 2.02 | I22: =VLOOKUP(A22,A$183:H$205,8,FALSE) -> 0.33333333 | J22: =E22*C22 -> 25.2 | K22: =IF(F22="n/a",D22*I22,F22*D22) -> 56 | L22: =G22*D22 -> 339.36 | M22: =MAX(J22:L22) -> 339.36 | N22: Exhaust Rate assumed according to PNNL outpatient model.
A23: =Zones!A23 -> Corridor Area | B23: =Zones!B23 -> Floor 1 MRI Hall | C23: =Zones!J23 -> 0.735 | D23: =Zones!G23 -> 147 | E23: 15 | F23: =VLOOKUP(A23,A$183:E$205,5,FALSE) -> 0.15 | I23: =VLOOKUP(A23,A$183:H$205,8,FALSE) -> 0 | J23: =E23*C23 -> 11.025 | K23: =IF(F23="n/a",D23*I23,F23*D23) -> 22.05 | L23: =H23*D23 -> 0 | M23: =MAX(J23:L23) -> 22.05
A24: =Zones!A24 -> Healthcare Facility and Hospitals (Imaging Room) | B24: =Zones!B24 -> Floor 1 MRI Room | C24: =Zones!J24 -> 4.4 | D24: =Zones!G24 -> 440 | E24: 15 | F24: =VLOOKUP(A24,A$183:E$205,5,FALSE) -> n/a | G24: 2.02 | I24: =VLOOKUP(A24,A$183:H$205,8,FALSE) -> 0.33333333 | J24: =E24*C24 -> 66 | K24: =IF(F24="n/a",D24*I24,F24*D24) -> 146.66667 | L24: =G24*D24 -> 888.8 | M24: =MAX(J24:L24) -> 888.8 | N24: Exhaust Rate assumed according to PNNL outpatient model.
A25: =Zones!A25 -> Restrooms | B25: =Zones!B25 -> Floor 1 MRI Toilet | C25: =Zones!J25 -> 0.27 | D25: =Zones!G25 -> 54 | E25: 15 | F25: 0 | H25: 50 | I25: =VLOOKUP(A25,A$183:H$205,8,FALSE) -> 0 | J25: =E25*C25 -> 4.05 | K25: =IF(F25="n/a",D25*I25,F25*D25) -> 0 | L25: =H25 -> 50 | M25: =MAX(J25:L25) -> 50 | N25: Toilet rooms, intermittent exhaust 50 cfm per toilet
A26: =Zones!A26 -> Kitchen/Food Preparation Area | B26: =Zones!B26 -> Floor 1 Nourishment | C26: =Zones!J26 -> 0.546 | D26: =Zones!G26 -> 182 | E26: 15 | F26: =VLOOKUP(A26,A$183:E$205,5,FALSE) -> 0.15 | G26: 0.3 | I26: =VLOOKUP(A26,A$183:H$205,8,FALSE) -> 0 | J26: =E26*C26 -> 8.19 | K26: =IF(F26="n/a",D26*I26,F26*D26) -> 27.3 | L26: =G26*D26 -> 54.6 | M26: =MAX(J26:L26) -> 54.6
A27: =Zones!A27 -> Corridor Area | B27: =Zones!B27 -> Floor 1 Nurse Hall | C27: =Zones!J27 -> 2.48 | D27: =Zones!G27 -> 496 | E27: 15 | F27: =VLOOKUP(A27,A$183:E$205,5,FALSE) -> 0.15 | I27: =VLOOKUP(A27,A$183:H$205,8,FALSE) -> 0 | J27: =E27*C27 -> 37.2 | K27: =IF(F27="n/a",D27*I27,F27*D27) -> 74.4 | L27: =H27*D27 -> 0 | M27: =MAX(J27:L27) -> 74.4
A28: =Zones!A28 -> Storage (General) | B28: =Zones!B28 -> Floor 1 Nurse Janitor | C28: =Zones!J28 -> 0.108 | D28: =Zones!G28 -> 54 | E28: 15 | F28: =VLOOKUP(A28,A$183:E$205,5,FALSE) -> 0.15 | I28: =VLOOKUP(A28,A$183:H$205,8,FALSE) -> 0 | J28: =E28*C28 -> 1.62 | K28: =IF(F28="n/a",D28*I28,F28*D28) -> 8.1 | L28: =H28*D28 -> 0 | M28: =MAX(J28:L28) -> 8.1
A29: =Zones!A29 -> Healthcare Facility and Hospitals (Nurse's Station) | B29: =Zones!B29 -> Floor 1 Nurse Station | C29: =Zones!J29 -> 2.61 | D29: =Zones!G29 -> 261 | E29: 15 | F29: =VLOOKUP(A29,A$183:E$205,5,FALSE) -> n/a | I29: =VLOOKUP(A29,A$183:H$205,8,FALSE) -> 0.33333333 | J29: =E29*C29 -> 39.15 | K29: =IF(F29="n/a",D29*I29,F29*D29) -> 87 | L29: =H29*D29 -> 0 | M29: =MAX(J29:L29) -> 87
A30: =Zones!A30 -> Restrooms | B30: =Zones!B30 -> Floor 1 Nurse Toilet | C30: =Zones!J30 -> 0.27 | D30: =Zones!G30 -> 54 | E30: 15 | F30: 0 | H30: 50 | I30: =VLOOKUP(A30,A$183:H$205,8,FALSE) -> 0 | J30: =E30*C30 -> 4.05 | K30: =IF(F30="n/a",D30*I30,F30*D30) -> 0 | L30: =H30 -> 50 | M30: =MAX(J30:L30) -> 50 | N30: Toilet rooms, intermittent exhaust 50 cfm per toilet
A31: =Zones!A31 -> Office Area (>250 square feet) | B31: =Zones!B31 -> Floor 1 Office | C31: =Zones!J31 -> 2.415 | D31: =Zones!G31 -> 483 | E31: 15 | F31: =VLOOKUP(A31,A$183:E$205,5,FALSE) -> 0.15 | I31: =VLOOKUP(A31,A$183:H$205,8,FALSE) -> 0 | J31: =E31*C31 -> 36.225 | K31: =IF(F31="n/a",D31*I31,F31*D31) -> 72.45 | L31: =H31*D31 -> 0 | M31: =MAX(J31:L31) -> 72.45
A32: =Zones!A32 -> Healthcare Facility and Hospitals (Operating Room) | B32: =Zones!B32 -> Floor 1 Operating Room 1 | C32: =Zones!J32 -> 4.6 | D32: =Zones!G32 -> 460 | E32: 15 | F32: =VLOOKUP(A32,A$183:E$205,5,FALSE) -> n/a | I32: =VLOOKUP(A32,A$183:H$205,8,FALSE) -> 0.33333333 | J32: =E32*C32 -> 69 | K32: =IF(F32="n/a",D32*I32,F32*D32) -> 153.33333 | L32: =H32*D32 -> 0 | M32: =MAX(J32:L32) -> 153.33333
A33: =Zones!A33 -> Healthcare Facility and Hospitals (Operating Room) | B33: =Zones!B33 -> Floor 1 Operating Room 2 | C33: =Zones!J33 -> 4.8 | D33: =Zones!G33 -> 480 | E33: 15 | F33: =VLOOKUP(A33,A$183:E$205,5,FALSE) -> n/a | I33: =VLOOKUP(A33,A$183:H$205,8,FALSE) -> 0.33333333 | J33: =E33*C33 -> 72 | K33: =IF(F33="n/a",D33*I33,F33*D33) -> 160 | L33: =H33*D33 -> 0 | M33: =MAX(J33:L33) -> 160
A34: =Zones!A34 -> Healthcare Facility and Hospitals (Operating Room) | B34: =Zones!B34 -> Floor 1 Operating Room 3 | C34: =Zones!J34 -> 4.76 | D34: =Zones!G34 -> 476 | E34: 15 | F34: =VLOOKUP(A34,A$183:E$205,5,FALSE) -> n/a | I34: =VLOOKUP(A34,A$183:H$205,8,FALSE) -> 0.33333333 | J34: =E34*C34 -> 71.4 | K34: =IF(F34="n/a",D34*I34,F34*D34) -> 158.66667 | L34: =H34*D34 -> 0 | M34: =MAX(J34:L34) -> 158.66667
A35: =Zones!A35 -> Healthcare Facility and Hospitals (Recovery Room) | B35: =Zones!B35 -> Floor 1 PACU | C35: =Zones!J35 -> 1.08 | D35: =Zones!G35 -> 108 | E35: 15 | F35: =VLOOKUP(A35,A$183:E$205,5,FALSE) -> n/a | I35: =VLOOKUP(A35,A$183:H$205,8,FALSE) -> 0.33333333 | J35: =E35*C35 -> 16.2 | K35: =IF(F35="n/a",D35*I35,F35*D35) -> 36 | L35: =H35*D35 -> 0 | M35: =MAX(J35:L35) -> 36
A36: =Zones!A36 -> Corridor Area | B36: =Zones!B36 -> Floor 1 Pre-Op Hall | C36: =Zones!J36 -> 2.64 | D36: =Zones!G36 -> 528 | E36: 15 | F36: =VLOOKUP(A36,A$183:E$205,5,FALSE) -> 0.15 | I36: =VLOOKUP(A36,A$183:H$205,8,FALSE) -> 0 | J36: =E36*C36 -> 39.6 | K36: =IF(F36="n/a",D36*I36,F36*D36) -> 79.2 | L36: =H36*D36 -> 0 | M36: =MAX(J36:L36) -> 79.2
A37: =Zones!A37 -> Healthcare Facility and Hospitals (Patient Room) | B37: =Zones!B37 -> Floor 1 Pre-Op Room 1 | C37: =Zones!J37 -> 1.89 | D37: =Zones!G37 -> 189 | E37: 15 | F37: =VLOOKUP(A37,A$183:E$205,5,FALSE) -> n/a | I37: =VLOOKUP(A37,A$183:H$205,8,FALSE) -> 0.33333333 | J37: =E37*C37 -> 28.35 | K37: =IF(F37="n/a",D37*I37,F37*D37) -> 63 | L37: =H37*D37 -> 0 | M37: =MAX(J37:L37) -> 63
A38: =Zones!A38 -> Healthcare Facility and Hospitals (Patient Room) | B38: =Zones!B38 -> Floor 1 Pre-Op Room 2 | C38: =Zones!J38 -> 3.38 | D38: =Zones!G38 -> 338 | E38: 15 | F38: =VLOOKUP(A38,A$183:E$205,5,FALSE) -> n/a | I38: =VLOOKUP(A38,A$183:H$205,8,FALSE) -> 0.33333333 | J38: =E38*C38 -> 50.7 | K38: =IF(F38="n/a",D38*I38,F38*D38) -> 112.66667 | L38: =H38*D38 -> 0 | M38: =MAX(J38:L38) -> 112.66667
A39: =Zones!A39 -> Restrooms | B39: =Zones!B39 -> Floor 1 Pre-Op Toilet | C39: =Zones!J39 -> 0.27 | D39: =Zones!G39 -> 54 | E39: 15 | F39: 0 | H39: 50 | I39: =VLOOKUP(A39,A$183:H$205,8,FALSE) -> 0 | J39: =E39*C39 -> 4.05 | K39: =IF(F39="n/a",D39*I39,F39*D39) -> 0 | L39: =H39 -> 50 | M39: =MAX(J39:L39) -> 50 | N39: Toilet rooms, intermittent exhaust 50 cfm per toilet
A40: =Zones!A40 -> Healthcare Facility and Hospitals (Exam/Treatment Room) | B40: =Zones!B40 -> Floor 1 Procedure Room | C40: =Zones!J40 -> 2.85 | D40: =Zones!G40 -> 285 | E40: 15 | F40: =VLOOKUP(A40,A$183:E$205,5,FALSE) -> n/a | I40: =VLOOKUP(A40,A$183:H$205,8,FALSE) -> 0.33333333 | J40: =E40*C40 -> 42.75 | K40: =IF(F40="n/a",D40*I40,F40*D40) -> 95 | L40: =H40*D40 -> 0 | M40: =MAX(J40:L40) -> 95
...

Sheet Water Heater
A1: ="Water Heater - "&Prototype!A2 -> Water Heater - Outpatient
A2: Vintage | B2: WH Type | C2: Efficiency | D2: Tank Volume (gal) | E2: Tank Loss | G2: Note
A3: Existing | B3: Gas | C3: 0.8 | D3: =F135 -> 30 | E3: =G137 -> 649.11313 | F3: (Btu/hr)
A4: New Construction | B4: Gas | C4: 0.8 | D4: =F133 -> 30 | E4: =G133 -> 649.11313 | F4: (Btu/hr)
A7: Peak Hot Water Consumption
A8: Space Name | B8: Baseline WH Type [CEUS 2022] | C8: Total Area (ft²) | D8: Number of People | E8: Hot Water Usage Specification (gal/hr per person) [T24, 2022, Appendix 5.4A , sheet: "2022 SpaceFuncData-Input"] | F8: Peak Hot Water Usage (gal/hr) | G8: Peak Hot Water Usage (gal/min)
A9: =Zones!B3 -> Floor 1 Anesthesia | B9: Gas | C9: =Zones!G3 -> 108 | D9: =Zones!J3 -> 1.08 | E9: =VLOOKUP(Zones!A3,'Water Heater'!$A$201:$B$222, 2, FALSE) -> 0.24 | F9: =E9*D9 -> 0.2592 | G9: =F9/60 -> 0.00432
A10: =Zones!B4 -> Floor 1 Bio Haz | B10: Gas | C10: =Zones!G4 -> 56 | D10: =Zones!J4 -> 0.56 | E10: =VLOOKUP(Zones!A4,'Water Heater'!$A$201:$B$222, 2, FALSE) -> 0.24 | F10: =E10*D10 -> 0.1344 | G10: =F10/60 -> 0.00224
A11: =Zones!B5 -> Floor 1 Café | B11: Gas | C11: =Zones!G5 -> 420 | D11: =Zones!J5 -> 13.86 | E11: =VLOOKUP(Zones!A5,'Water Heater'!$A$201:$B$222, 2, FALSE) -> 0.578 | F11: =E11*D11 -> 8.01108 | G11: =F11/60 -> 0.133518
A12: =Zones!B6 -> Floor 1 Clean | B12: Gas | C12: =Zones!G6 -> 126 | D12: =Zones!J6 -> 1.26 | E12: =VLOOKUP(Zones!A6,'Water Heater'!$A$201:$B$222, 2, FALSE) -> 0.24 | F12: =E12*D12 -> 0.3024 | G12: =F12/60 -> 0.00504
A13: =Zones!B7 -> Floor 1 Clean Work | B13: Gas | C13: =Zones!G7 -> 165 | D13: =Zones!J7 -> 1.65 | E13: =VLOOKUP(Zones!A7,'Water Heater'!$A$201:$B$222, 2, FALSE) -> 0.24 | F13: =E13*D13 -> 0.396 | G13: =F13/60 -> 0.0066
A14: =Zones!B8 -> Floor 1 Dictation | B14: Gas | C14: =Zones!G8 -> 126 | D14: =Zones!J8 -> 0.63 | E14: =VLOOKUP(Zones!A8,'Water Heater'!$A$201:$B$222, 2, FALSE) -> 0.18 | F14: =E14*D14 -> 0.1134 | G14: =F14/60 -> 0.00189
A15: =Zones!B9 -> Floor 1 Dressing Room | B15: Gas | C15: =Zones!G9 -> 45 | D15: =Zones!J9 -> 0.225 | E15: =VLOOKUP(Zones!A9,'Water Heater'!$A$201:$B$222, 2, FALSE) -> 0.18 | F15: =E15*D15 -> 0.0405 | G15: =F15/60 -> 0.000675
A16: =Zones!B10 -> Floor 1 Electrical Room | B16: Gas | C16: =Zones!G10 -> 98 | D16: =Zones!J10 -> 0.294 | E16: =VLOOKUP(Zones!A10,'Water Heater'!$A$201:$B$222, 2, FALSE) -> 0.18 | F16: =E16*D16 -> 0.05292 | G16: =F16/60 -> 0.000882
A17: =Zones!B11 -> Floor 1 Elevator Pump Room | B17: Gas | C17: =Zones!G11 -> 91 | D17: =Zones!J11 -> 0.273 | E17: =VLOOKUP(Zones!A11,'Water Heater'!$A$201:$B$222, 2, FALSE) -> 0.18 | F17: =E17*D17 -> 0.04914 | G17: =F17/60 -> 0.000819
A18: =Zones!B12 -> Floor 1 Humid | B18: Gas | C18: =Zones!G12 -> 54 | D18: =Zones!J12 -> 0.27 | E18: =VLOOKUP(Zones!A12,'Water Heater'!$A$201:$B$222, 2, FALSE) -> 0.18 | F18: =E18*D18 -> 0.0486 | G18: =F18/60 -> 0.00081
A19: =Zones!B13 -> Floor 1 IT Hall | B19: Gas | C19: =Zones!G13 -> 140 | D19: =Zones!J13 -> 0.7 | E19: =VLOOKUP(Zones!A13,'Water Heater'!$A$201:$B$222, 2, FALSE) -> 0 | F19: =E19*D19 -> 0 | G19: =F19/60 -> 0
A20: =Zones!B14 -> Floor 1 IT Room | B20: Gas | C20: =Zones!G14 -> 112 | D20: =Zones!J14 -> 0.56 | E20: =VLOOKUP(Zones!A14,'Water Heater'!$A$201:$B$222, 2, FALSE) -> 0.18 | F20: =E20*D20 -> 0.1008 | G20: =F20/60 -> 0.00168
... A123: =Zones!B117 -> NE Stair | B123: Gas | C123: =Zones!G117 -> 168 | D123: =Zones!J117 -> 0.84 | E123: =VLOOKUP(Zones!A117,'Water Heater'!$A$201:$B$222, 2, FALSE) -> 0 | F123: =E123*D123 -> 0 | G123: =F123/60 -> 0
A124: =Zones!B118 -> NW Elevator | B124: Gas | C124: =Zones!G118 -> 140 | D124: =Zones!J118 -> 0 | E124: 0 | F124: =E124*D124 -> 0 | G124: =F124/60 -> 0
A125: =Zones!B119 -> NW Stair | B125: Gas | C125: =Zones!G119 -> 192 | D125: =Zones!J119 -> 0.96 | E125: =VLOOKUP(Zones!A119,'Water Heater'!$A$201:$B$222, 2, FALSE) -> 0 | F125: =E125*D125 -> 0 | G125: =F125/60 -> 0
A126: =Zones!B120 -> SW Stair | B126: Gas | C126: =Zones!G120 -> 96 | D126: =Zones!J120 -> 0.48 | E126: =VLOOKUP(Zones!A120,'Water Heater'!$A$201:$B$222, 2, FALSE) -> 0 | F126: =E126*D126 -> 0 | G126: =F126/60 -> 0
A127: =Zones!B121 -> Total ( 118 spaces) | B127: Gas | C127: =Zones!G121 -> 40946 | D127: =Zones!J121 -> 329.193 | F127: =SUM(F9:F126) -> 61.708218 | G127: =F127/60 -> 1.0284703
A131: Water Heater Capacity, Tank Capacity, and Tank Loss
A132: WH Type | B132: Peak Hot Water Usage (gal/hr) | C132: Heat Output (Btu/hr) [ACM, 2025, 5.9.2: Rated capacity section] | D132: WH Capacity (Btu/hr) [ACM, 2025, 5.9.2: Rated capacity section] | E132: Required Energy Input (Btu/hr) | F132: Storage Volume (gal) | G132: Standby Loss | I132: Off/On Cycle Loss Coefficient to Ambient Temp (Btu/h-F) | J132: Source
A133: Gas Storage WH | B133: =MAX(SUMIF(B9:B30, "*Gas*", F9:F30),75) -> 75 | C133: =B133*(135-55)*8.2877*1 -> 49726.2 | D133: =C133*B139 -> 29835.72 | E133: =D133/0.8 -> 37294.65 | F133: =F135-F134 -> 30 | G133: =(E133/800)+110*SQRT(F133) -> 649.11313 | H133: Btu/hr | I133: =G133/B145 -> 9.6882556 | J133: Standby loss equation: Title 20, §1605.1 Table F-4 WH capacity equation: ACM, 2025, 5.9.2: Rated capacity section)
A134: Electric resistance WH | B134: =SUMIF(B9:B30, "*Electric*", F9:F30) -> 0 | C134: =B134*(135-55)*8.2877*1 -> 0 | D134: =C134*0.85 -> 0 | E134: =D134/1 -> 0 | F134: =(B134*F135)/B135 -> 0 | H134: %hr | I134: =0.0834*G134*F134 -> 0
A135: Total | B135: =MAX(B133+B134,75) -> 75 | C135: =B135*(135-55)*8.2877*1 -> 49726.2 | D135: =C135*B139 -> 29835.72 | E135: =D135/0.8 -> 37294.65 | F135: =B135*1*B140 -> 30
A137: Design supply temperature (F) | B137: 135 | C137: Ref: T24 2022 - Appendix 5.4B | F137: Standby Loss for Existing | G137: =(E135/800)+110*SQRT(F135) -> 649.11313 | H137: Btu/hr | I137: =G137/B145 -> 9.6882556
A138: Cold Water supply temperature (F) | B138: 55 | C138: Ref: ACM, 2025, 5.9.2: Rated capacity section
A139: WH system factor | B139: 0.6 | C139: Ref: ACM, 2025, 5.9.2: Rated capacity section
A140: Reheat multiplier | B140: 0.4
A141: * The 0.40 multiplier is a storage sizing factor used to account for the fact that the water heater doesn't need to store the full peak hour demand—it can reheat water during that time. This factor assumes that the heater will recover part of the hot water used during the peak hour, so only 40% of the peak hour demand needs to be stored at any given moment.
A143: **For Gas Water Heater: UA(Btu/h-°F)​=Q˙​SL​ (Btu/h)/ΔT (∘F)​
A144: Ambient temp | B144: 68
A145: Delta T | B145: =B137-B144 -> 67
A146: ** For Electric Water Heater: UA(Btu/h-°F)​= 0.0834 *SL​ (%/hr)*V gal
A156: Background Data [To be deleted prior to publication]
A200: Space Type | B200: Hot Water Usage Specification (gal/hr per person) [T24, 2022, Appendix 5.4A , sheet: "2022 SpaceFuncData-Input"]
A201: Healthcare Facility and Hospitals (Exam/Treatment Room) | B201: 0.24
...

Sheet Interior Lights
A1: ="Interior Lighting - "&Prototype!A2 -> Interior Lighting - Outpatient
A2: Space | B2: New Construction | E2: Existing
B3: LPD (W/ft²) | C3: Additional LPD for PorTable Lighting (W/ft²) | D3: Source | E3: LPD (W/ft²) | F3: Additional LPD for PorTable Lighting (W/ft²) | G3: Source
A4: =Ventilation!A184 -> Healthcare Facility and Hospitals (Exam/Treatment Room) | B4: 1.15 | D4: T24, 2025, Table 140.6 C (Area category method) | E4: 1.15 | G4: T24, 2019, Table 140.6 C Room (Area category method)
A5: =Ventilation!A185 -> Healthcare Facility and Hospitals (Medical Supply Room) | B5: 0.55 | E5: 0.55
A6: =Ventilation!A186 -> Healthcare Facility and Hospitals (Imaging Room) | B6: 0.6 | E6: 1
A7: =Ventilation!A187 -> Healthcare Facility and Hospitals (Nurse's Station) | B7: 0.85 | E7: 0.75
A8: =Ventilation!A188 -> Healthcare Facility and Hospitals (Operating Room) | B8: 1.9 | E8: 1.9
A9: =Ventilation!A189 -> Healthcare Facility and Hospitals (Recovery Room) | B9: 0.9 | E9: 0.9
A10: =Ventilation!A190 -> Healthcare Facility and Hospitals (Physical Therapy Room) | B10: 0.75 | E10: 0.85
A11: =Ventilation!A191 -> Healthcare Facility and Hospitals (Patient Room) | B11: 0.7 | E11: 0.55
A12: =Ventilation!A192 -> Dining Area (Cafeteria/Fast Food) | B12: 0.45 | E12: 0.4
A13: =Ventilation!A193 -> Office Area (<250 square feet) | B13: 0.65 | E13: 0.7
A14: =Ventilation!A194 -> Office Area (>250 square feet) | B14: 0.6 | E14: 0.65
A15: =Ventilation!A195 -> Convention, Conference, Multipurpose and Meeting Area | B15: 0.75 | E15: 0.85
A16: =Ventilation!A196 -> Lobby, Main Entry | B16: 0.7 | E16: 0.85
... A22: =Ventilation!A202 -> Lounge, Breakroom, or Waiting Area | B22: 0.55 | E22: 0.65
A23: =Ventilation!A204 -> Stairwell | B23: 0.6 | E23: 0.5
A24: =Ventilation!A205 -> Electrical, Mechanical, Telephone Rooms | B24: 0.4 | E24: 0.4
A25: =Zones!A82 -> Reception area | B25: =0.7 -> 0.7 | E25: 0.85
A26: =Zones!A118 -> Elevator | B26: 0 | E26: 0
A29: *Healthcare Buildings are expected to update their lighting systems more frequently than offices. Therefore code edition of 2019 was considered as the reference for LPD of the existing prototypes.

Sheet Ext Lighting
A1: ="Exterior Lighting - "&Prototype!A2 -> Exterior Lighting - Outpatient
A2: Motion Controlled Luminaires (W) | B2: Non-motion Controlled Luminaires (W) | C2: Total (W) | D2: Source
A3: =G14 -> 1841.885 | B3: =G15 -> 1030.665 | C3: =B3+A3 -> 2872.55 | D3: T24, 2022 & 2025 2019 Outdoor Lighting CASE report PNNL 90.1-2010 TSD
A6: ="Exterior Lighting " -> Exterior Lighting
A7: Items (Assume LZ2) | B7: Assumptions [2019 Outdoor Lighting CASE Report & PNNL 90.1-2010 TSD] | D7: Unit | E7: Lighting Power Allowance [Title 24, 2025, Table 140.7-A & 140.7-B] | F7: Unit | G7: Exterior Lighting Power (W)
A8: IWA (Initial Wattage Allowance) | E8: 200 | F8: (W) | G8: =$E8 -> 200
A9: Parking area | B9: 400 ft² for every parking space 1 parking space per 830 ft² of gross building area | C9: =B20/250*400 -> 65520 | D9: (ft²) | E9: 0.019 | F9: (W/ft²) | G9: =$E9*65520 -> 1244.88
A10: Building Entrance | B10: 14 building entrance per PNNL Model | C10: 14 | D10: (count) | E10: 15 | F10: (W/ea) | G10: =E10*C10 -> 210
A11: Hardscape Ornamental Light | B11: 0.1 ft² per 1 ft² of gross building area for hardscape ornamental light | C11: 4095 | D11: (ft²) | E11: 0.007 | F11: (W/ft²) | G11: =E11*C11 -> 28.665
A12: Building façade | B12: 0.1 W per 1 ft² of facade area Façade Area = Perimeter × 0.5 × 28 ft (30 ft is the max height that is lit) * The 0.5 factor assumes that only half of the perimeter walls are lit. -Formula ia developed based on the 2019 Outdoor Lighting CASE report | C12: =B21*0.5*30 -> 10020 | D12: (ft²) | E12: 0.1 | F12: (W/ft²) | G12: =E12*C12 -> 1002
A13: Non-sales canopy | C13: 1365 | D13: (ft²) | E13: 0.137 | F13: (W/ft²) | G13: =E13*C13 -> 187.005
A14: Motion Controlled Luminaires (W) | G14: =G9+G8+G13+G10 -> 1841.885
A15: Non-motion-controlled Luminaires | G15: =G11+G12 -> 1030.665
A16: Total | G16: =G14+G15 -> 2872.55
A20: Total floor area | B20: =Prototype!B8 -> 40950
A21: Perimeter | B21: =10020/0.5/30 -> 668
A22: Floors | B22: 3
A25: Background Data [To be deleted prior to publication]

Sheet Equipment
A1: ="Equipment - "&Prototype!A2 -> Equipment - Outpatient
A2: Spaces | B2: Plug load Power Density (W/ft²) | C2: Gas Power Density (Btu/hr-ft²) | D2: Refrigeration Power Density (W/ft²) | E2: Source | F2: Note
A3: =Ventilation!A184 -> Healthcare Facility and Hospitals (Exam/Treatment Room) | B3: 1.5 | C3: 1.1259 | E3: T24 2022 - Appendix 5.4A | F3: Appendix 5.4A: Gas equipment=1.1259 Btu/h-ft²--CEC model has the Gas equipment for 3.59 Btu/h-ft²
A4: =Ventilation!A185 -> Healthcare Facility and Hospitals (Medical Supply Room) | B4: 1.5
A5: =Ventilation!A186 -> Healthcare Facility and Hospitals (Imaging Room) | B5: 10 | F5: PNNL has EPD=10 for Imaging room
A6: =Ventilation!A187 -> Healthcare Facility and Hospitals (Nurse's Station) | B6: 2 | F6: PNNL has EPD=2 for Nurse station
A7: =Ventilation!A188 -> Healthcare Facility and Hospitals (Operating Room) | B7: 11 | C7: 3.62 | F7: PNNL has EPD=11 for Operating room--CEC: Gas equipment=3.62 Btu/h-ft²
A8: =Ventilation!A189 -> Healthcare Facility and Hospitals (Recovery Room) | B8: 1.5
A9: =Ventilation!A190 -> Healthcare Facility and Hospitals (Physical Therapy Room) | B9: 1.5
A10: =Ventilation!A191 -> Healthcare Facility and Hospitals (Patient Room) | B10: 1.5
A11: =Ventilation!A192 -> Dining Area (Cafeteria/Fast Food) | B11: 0.5 | D11: 0.25 | F11: CEC: Refrig Load = 0.25 w/ft²
A12: =Ventilation!A193 -> Office Area (<250 square feet) | B12: 0.7 | F12: Plug load and schedules project with CEC, 2025
A13: =Ventilation!A194 -> Office Area (>250 square feet) | B13: 0.7 | F13: Plug load and schedules project with CEC, 2025
A14: =Ventilation!A195 -> Convention, Conference, Multipurpose and Meeting Area | B14: 1
A15: =Ventilation!A196 -> Lobby, Main Entry | B15: 0.5
A16: =Ventilation!A197 -> Corridor Area | B16: 0
A17: =Ventilation!A198 -> Restrooms | B17: 0
A18: =Ventilation!A199 -> Locker Room | B18: 0.5
A19: =Ventilation!A200 -> Kitchen/Food Preparation Area | B19: 1.5 | C19: 17.53768 | D19: 1.12 | F19: Appendix 5.4A: Gas equipment=17.53768 -- CEC: Refrig Load = 1.12 w/ft²
A20: =Ventilation!A201 -> Storage (General) | B20: 0.2
A21: =Ventilation!A202 -> Lounge, Breakroom, or Waiting Area | B21: 1
A22: =Ventilation!A204 -> Stairwell | B22: 0
A23: =Ventilation!A205 -> Electrical, Mechanical, Telephone Rooms | B23: 3
A24: =Zones!A41 -> Reception area | B24: =B15 -> 0.5
A25: =Zones!A118 -> Elevator | B25: 0
A27: Elevator
A28: Vintage | B28: No. of Elevators | C28: Cab Lighting Power Limit (W/ft²) | D28: Lighting Shutoff | E28: Cab Fan Control | F28: Fan Power Limit | G28: Regenerative Drive Threshold | H28: Design load (W) | I28: Note
A29: Existing | B29: =C37 -> 3 | C29: 1.65 | D29: n/a | E29: n/a | F29: n/a | G29: n/a | H29: =D47 -> 13860.78 | I29: Design Load based on PNNL ASHRAE 90.1 2013 Outpatient prototype
A30: New Construction | B30: =C37 -> 3 | C30: ≤ 0.6 W/ft² of cab floor area- Exempt (covered process) | D30: Automatic shut‑off after ≤ 5 min no‑occupancy | E30: When the elevator cab is stopped and unoccupied with doors closed for over 15 minutes, the cab interior lighting and ventilation fans shall be switched off until elevator cab operation resumes. | F30: ≤ 0.33 W per cfm of fan airflow | G30: n/a | H30: =B47 -> 7611.31 | I30: Design Load based on PNNL ASHRAE 90.1 2022 Outpatient prototype --- per T24 2025 §120.6 (f)
A33: Assumptions for elevators:
A34: One elevator for approximately 50,000 square feet in use.
A35: For every two floors or two and a half floors, one more elevator was added.
A36: An in-use rate of 70% for the floor area was assumed, based on engineering judgment.
A37: Calculated number of Elevators: | C37: =ROUND((40950*0.7/50000)+ROUND(3/2,0),0) -> 3 | D37: Same as PNNL assumptions
A38: Calculate Elevator load (kw)based on ACM 2022: | C38: =C37*C39 -> 30 | D38: 30 kw is PNNL ASHRE 90.1 2019 elevator load (Lift,light and Fan)--CEC Model has 80K for the elevator load.
A39: ACM 2022 suggestion for elevator load (kw): | C39: 10
A40: Elevator load will be defined as exterior load not equipment load
A42: Elevator Load= Elevator Lift+ Elevator Light+Fan | B42: 2022 | C42: 2019 | D42: 2013
A43: Elevator Lift (W) | B43: 7453.34 | C43: 13672.78 | D43: 13672.78
A44: Elevator Fan | B44: 157.97 | C44: 188 | D44: 188
...

Sheet Schedules
A1: ="Schedules - "&Prototype!A2 -> Schedules - Outpatient
A2: Zone | B2: Schedule Category | C2: Schedule | D2: Source | E2: Type | F2: Hour
F3: 1 | G3: 2 | H3: 3 | I3: 4 | J3: 5 | K3: 6 | L3: 7 | M3: 8 | N3: 9 | O3: 10 | P3: 11 | Q3: 12 | R3: 13 | S3: 14 | T3: 15 | U3: 16 | V3: 17 | W3: 18 | X3: 19 | Y3: 20 | Z3: 21 | AA3: 22 | AB3: 23 | AC3: 24
A4: All Zones at level 2 and 3 | B4: Health | C4: Occupancy | D4: T24 2022 - Appendix 5.4B, [Health] | E4: Weekday | F4: 0 | G4: 0 | H4: 0 | I4: 0 | J4: 0 | K4: 0 | L4: 0 | M4: 0.1 | N4: 0.5 | O4: 0.8 | P4: 0.8 | Q4: 0.8 | R4: 0.8 | S4: 0.8 | T4: 0.8 | U4: 0.8 | V4: 0.8 | W4: 0.5 | X4: 0.3 | Y4: 0.3 | Z4: 0.2 | AA4: 0.2 | AB4: 0 | AC4: 0
E5: Saturday | F5: 0 | G5: 0 | H5: 0 | I5: 0 | J5: 0 | K5: 0 | L5: 0 | M5: 0.1 | N5: 0.3 | O5: 0.4 | P5: 0.4 | Q5: 0.4 | R5: 0.4 | S5: 0.4 | T5: 0.4 | U5: 0.4 | V5: 0.4 | W5: 0.1 | X5: 0.1 | Y5: 0 | Z5: 0 | AA5: 0 | AB5: 0 | AC5: 0
E6: Sunday | F6: 0 | G6: 0 | H6: 0 | I6: 0 | J6: 0 | K6: 0 | L6: 0 | M6: 0 | N6: 0.05 | O6: 0.05 | P6: 0.05 | Q6: 0.05 | R6: 0.05 | S6: 0.05 | T6: 0.05 | U6: 0.05 | V6: 0 | W6: 0 | X6: 0 | Y6: 0 | Z6: 0 | AA6: 0 | AB6: 0 | AC6: 0
A7: All Zones at level 2 and 3 | B7: Health | C7: Lights | D7: T24 2022 - Appendix 5.4B, [Health] | E7: Weekday | F7: 0.1 | G7: 0.1 | H7: 0.1 | I7: 0.1 | J7: 0.1 | K7: 0.1 | L7: 0.1 | M7: 0.45 | N7: 0.8 | O7: 0.8 | P7: 0.8 | Q7: 0.8 | R7: 0.8 | S7: 0.8 | T7: 0.8 | U7: 0.8 | V7: 0.3 | W7: 0.3 | X7: 0.3 | Y7: 0.3 | Z7: 0.3 | AA7: 0.3 | AB7: 0.3 | AC7: 0.1
E8: Saturday | F8: 0.1 | G8: 0.1 | H8: 0.1 | I8: 0.1 | J8: 0.1 | K8: 0.1 | L8: 0.1 | M8: 0.2 | N8: 0.35 | O8: 0.35 | P8: 0.35 | Q8: 0.35 | R8: 0.35 | S8: 0.35 | T8: 0.35 | U8: 0.35 | V8: 0.35 | W8: 0.35 | X8: 0.1 | Y8: 0.1 | Z8: 0.1 | AA8: 0.1 | AB8: 0.1 | AC8: 0.1
E9: Sunday | F9: 0.05 | G9: 0.05 | H9: 0.05 | I9: 0.05 | J9: 0.05 | K9: 0.05 | L9: 0.05 | M9: 0.05 | N9: 0.1 | O9: 0.1 | P9: 0.1 | Q9: 0.1 | R9: 0.1 | S9: 0.1 | T9: 0.1 | U9: 0.1 | V9: 0.05 | W9: 0.05 | X9: 0.05 | Y9: 0.05 | Z9: 0.05 | AA9: 0.05 | AB9: 0.05 | AC9: 0.05
A10: All Zones at level 2 and 3 | B10: Health | C10: ElecEquipment | D10: T24 2022 - Appendix 5.4B, [Health] | E10: Weekday | F10: 0.1 | G10: 0.1 | H10: 0.1 | I10: 0.1 | J10: 0.1 | K10: 0.1 | L10: 0.1 | M10: 0.5 | N10: 0.9 | O10: 0.9 | P10: 0.9 | Q10: 0.9 | R10: 0.9 | S10: 0.9 | T10: 0.9 | U10: 0.9 | V10: 0.3 | W10: 0.3 | X10: 0.3 | Y10: 0.3 | Z10: 0.3 | AA10: 0.3 | AB10: 0.3 | AC10: 0.1
E11: Saturday | F11: 0.1 | G11: 0.1 | H11: 0.1 | I11: 0.1 | J11: 0.1 | K11: 0.1 | L11: 0.1 | M11: 0.2 | N11: 0.4 | O11: 0.4 | P11: 0.4 | Q11: 0.4 | R11: 0.4 | S11: 0.4 | T11: 0.4 | U11: 0.4 | V11: 0.4 | W11: 0.4 | X11: 0.1 | Y11: 0.1 | Z11: 0.1 | AA11: 0.1 | AB11: 0.1 | AC11: 0.1
E12: Sunday | F12: 0.05 | G12: 0.05 | H12: 0.05 | I12: 0.05 | J12: 0.05 | K12: 0.05 | L12: 0.05 | M12: 0.05 | N12: 0.1 | O12: 0.1 | P12: 0.1 | Q12: 0.1 | R12: 0.1 | S12: 0.1 | T12: 0.1 | U12: 0.1 | V12: 0.05 | W12: 0.05 | X12: 0.05 | Y12: 0.05 | Z12: 0.05 | AA12: 0.05 | AB12: 0.05 | AC12: 0.05
A13: All Zones at level 2 and 3 | B13: Health | C13: ServiceHotWater | D13: T24 2022 - Appendix 5.4B, [Health] | E13: Weekday | F13: 0.01 | G13: 0.01 | H13: 0.01 | I13: 0.01 | J13: 0.01 | K13: 0.01 | L13: 0.01 | M13: 0.17 | N13: 0.58 | O13: 0.66 | P13: 0.78 | Q13: 0.82 | R13: 0.71 | S13: 0.82 | T13: 0.78 | U13: 0.74 | V13: 0.63 | W13: 0.41 | X13: 0.18 | Y13: 0.18 | Z13: 0.18 | AA13: 0.1 | AB13: 0.01 | AC13: 0.01
E14: Saturday | F14: 0.01 | G14: 0.01 | H14: 0.01 | I14: 0.01 | J14: 0.01 | K14: 0.01 | L14: 0.01 | M14: 0.01 | N14: 0.2 | O14: 0.28 | P14: 0.3 | Q14: 0.3 | R14: 0.24 | S14: 0.24 | T14: 0.23 | U14: 0.23 | V14: 0.23 | W14: 0.1 | X14: 0.01 | Y14: 0.01 | Z14: 0.01 | AA14: 0.01 | AB14: 0.01 | AC14: 0.01
E15: Sunday | F15: 0.01 | G15: 0.01 | H15: 0.01 | I15: 0.01 | J15: 0.01 | K15: 0.01 | L15: 0.01 | M15: 0.01 | N15: 0.01 | O15: 0.01 | P15: 0.01 | Q15: 0.01 | R15: 0.01 | S15: 0.01 | T15: 0.01 | U15: 0.01 | V15: 0.01 | W15: 0.01 | X15: 0.01 | Y15: 0.01 | Z15: 0.01 | AA15: 0.01 | AB15: 0.01 | AC15: 0.01
A16: All Zones at level 2 and 3 | B16: Health | C16: GasEquipment | D16: T24 2022 - Appendix 5.4B, [Health] | E16: Weekday | F16: 0 | G16: 0 | H16: 0 | I16: 0 | J16: 0 | K16: 0 | L16: 0 | M16: 0.75 | N16: 0.9 | O16: 0.9 | P16: 0.9 | Q16: 0.9 | R16: 0.9 | S16: 0.9 | T16: 0.9 | U16: 0.9 | V16: 0.9 | W16: 0.75 | X16: 0.2 | Y16: 0.1 | Z16: 0 | AA16: 0 | AB16: 0 | AC16: 0
E17: Saturday | F17: 0 | G17: 0 | H17: 0 | I17: 0 | J17: 0 | K17: 0 | L17: 0 | M17: 0.3 | N17: 0.5 | O17: 0.5 | P17: 0.5 | Q17: 0.5 | R17: 0.5 | S17: 0.5 | T17: 0.5 | U17: 0.5 | V17: 0.5 | W17: 0.3 | X17: 0 | Y17: 0 | Z17: 0 | AA17: 0 | AB17: 0 | AC17: 0
E18: Sunday | F18: 0 | G18: 0 | H18: 0 | I18: 0 | J18: 0 | K18: 0 | L18: 0 | M18: 0 | N18: 0 | O18: 0 | P18: 0 | Q18: 0 | R18: 0 | S18: 0 | T18: 0 | U18: 0 | V18: 0 | W18: 0 | X18: 0 | Y18: 0 | Z18: 0 | AA18: 0 | AB18: 0 | AC18: 0
A19: All Zones at level 2 and 3 | B19: Health | C19: Refrigeration | D19: T24 2022 - Appendix 5.4B, [Health] | E19: Weekday | F19: 0.9 | G19: 0.9 | H19: 0.9 | I19: 0.9 | J19: 0.9 | K19: 0.9 | L19: 0.9 | M19: 0.9 | N19: 0.9 | O19: 0.9 | P19: 0.9 | Q19: 0.9 | R19: 0.9 | S19: 0.9 | T19: 0.9 | U19: 0.9 | V19: 0.9 | W19: 0.9 | X19: 0.9 | Y19: 0.9 | Z19: 0.9 | AA19: 0.9 | AB19: 0.9 | AC19: 0.9
E20: Saturday | F20: 0.9 | G20: 0.9 | H20: 0.9 | I20: 0.9 | J20: 0.9 | K20: 0.9 | L20: 0.9 | M20: 0.9 | N20: 0.9 | O20: 0.9 | P20: 0.9 | Q20: 0.9 | R20: 0.9 | S20: 0.9 | T20: 0.9 | U20: 0.9 | V20: 0.9 | W20: 0.9 | X20: 0.9 | Y20: 0.9 | Z20: 0.9 | AA20: 0.9 | AB20: 0.9 | AC20: 0.9
E21: Sunday | F21: 0.9 | G21: 0.9 | H21: 0.9 | I21: 0.9 | J21: 0.9 | K21: 0.9 | L21: 0.9 | M21: 0.9 | N21: 0.9 | O21: 0.9 | P21: 0.9 | Q21: 0.9 | R21: 0.9 | S21: 0.9 | T21: 0.9 | U21: 0.9 | V21: 0.9 | W21: 0.9 | X21: 0.9 | Y21: 0.9 | Z21: 0.9 | AA21: 0.9 | AB21: 0.9 | AC21: 0.9
A22: All Zones at level 2 and 4 | B22: Health | C22: Infiltration | D22: T24 2022 - Appendix 5.4B, [Health] | E22: Weekday | F22: =IF(F25=1,0.25,1) -> 1 | G22: =IF(G25=1,0.25,1) -> 1 | H22: =IF(H25=1,0.25,1) -> 1 | I22: =IF(I25=1,0.25,1) -> 1 | J22: =IF(J25=1,0.25,1) -> 1 | K22: =IF(K25=1,0.25,1) -> 1 | L22: =IF(L25=1,0.25,1) -> 0.25 | M22: =IF(M25=1,0.25,1) -> 0.25 | ... AC22: =IF(AC25=1,0.25,1) -> 1
E23: Saturday | F23: =IF(F26=1,0.25,1) -> 1 | G23: =IF(G26=1,0.25,1) -> 1 | H23: =IF(H26=1,0.25,1) -> 1 | I23: =IF(I26=1,0.25,1) -> 1 | J23: =IF(J26=1,0.25,1) -> 1 | K23: =IF(K26=1,0.25,1) -> 1 | L23: =IF(L26=1,0.25,1) -> 0.25 | M23: =IF(M26=1,0.25,1) -> 0.25 | ... AC23: =IF(AC26=1,0.25,1) -> 1
E24: Sunday | F24: =IF(F27=1,0.25,1) -> 1 | G24: =IF(G27=1,0.25,1) -> 1 | H24: =IF(H27=1,0.25,1) -> 1 | I24: =IF(I27=1,0.25,1) -> 1 | J24: =IF(J27=1,0.25,1) -> 1 | K24: =IF(K27=1,0.25,1) -> 1 | L24: =IF(L27=1,0.25,1) -> 1 | M24: =IF(M27=1,0.25,1) -> 0.25 | ... AC24: =IF(AC27=1,0.25,1) -> 1
A25: All Zones at level 2 and 3 | B25: Health | C25: HVACAvail | D25: T24 2022 - Appendix 5.4B, [Health] | E25: Weekday | F25: 0 | G25: 0 | H25: 0 | I25: 0 | J25: 0 | K25: 0 | L25: 1 | M25: 1 | N25: 1 | O25: 1 | P25: 1 | Q25: 1 | R25: 1 | S25: 1 | T25: 1 | U25: 1 | V25: 1 | W25: 1 | X25: 1 | Y25: 1 | Z25: 1 | AA25: 1 | AB25: 0 | AC25: 0
E26: Saturday | F26: 0 | G26: 0 | H26: 0 | I26: 0 | J26: 0 | K26: 0 | L26: 1 | M26: 1 | N26: 1 | O26: 1 | P26: 1 | Q26: 1 | R26: 1 | S26: 1 | T26: 1 | U26: 1 | V26: 1 | W26: 1 | X26: 1 | Y26: 0 | Z26: 0 | AA26: 0 | AB26: 0 | AC26: 0
E27: Sunday | F27: 0 | G27: 0 | H27: 0 | I27: 0 | J27: 0 | K27: 0 | L27: 0 | M27: 1 | N27: 1 | O27: 1 | P27: 1 | Q27: 1 | R27: 1 | S27: 1 | T27: 1 | U27: 1 | V27: 0 | W27: 0 | X27: 0 | Y27: 0 | Z27: 0 | AA27: 0 | AB27: 0 | AC27: 0
A28: All the zones | B28: Health | C28: HtgSetpt | E28: Weekday | F28: =IF(F25=1,Thermostat!$B$3,Thermostat!$B$4) -> 70 | G28: =IF(G25=1,Thermostat!$B$3,Thermostat!$B$4) -> 70 | H28: =IF(H25=1,Thermostat!$B$3,Thermostat!$B$4) -> 70 | I28: =IF(I25=1,Thermostat!$B$3,Thermostat!$B$4) -> 70 | J28: =IF(J25=1,Thermostat!$B$3,Thermostat!$B$4) -> 70 | K28: =IF(K25=1,Thermostat!$B$3,Thermostat!$B$4) -> 70 | L28: =IF(L25=1,Thermostat!$B$3,Thermostat!$B$4) -> 70 | M28: =IF(M25=1,Thermostat!$B$3,Thermostat!$B$4) -> 70 | ... AC28: =IF(AC25=1,Thermostat!$B$3,Thermostat!$B$4) -> 70
