Workbook
Name nonparticipating_forecastzone_scale_factor: #REF!
Name nonparticipating_forecastzone_scale_factor: 'Energy Usage'!#REF!
Name Space_Function: Data!$A$2:$A$76

Sheet Notes
A1: Data Sources
A2: Dataset | B2: Dodge 2023
B3: CEUS 2022
B4: CBECS 2018
B5: ComStock 2023
A6: Prototype | B6: CEC prototype (CBECC 2022.3.1) | C6: https://bees.noresco.com/software2022.html
B7: PNNL prototype (90.1-2022) | C7: https://www.energycodes.gov/prototype-building-models#Commercial
B8: DEER prototype (June 2023) | C8: https://github.com/sound-data/DEER-Prototypes-EnergyPlus
A10: Codes | B10: Title 24, part 6, referred to as T24 (1986, 1992, 2001, 2007, 2013, 2016, 2019, 2022, 2025)
B11: ASHRAE 90.1 (2022)
B12: CFR Title 10 (2009) | C12: https://www.govinfo.gov/content/pkg/FR-2009-03-23/pdf/FR-2009-03-23.pdf
B13: CFR Title 10 ( 2013) | C13: https://www.govinfo.gov/content/pkg/CFR-2013-title10-vol3/pdf/CFR-2013-title10-vol3-part431.pdf
B14: CFR Title 10 ( 2024) | C14: https://www.govinfo.gov/content/pkg/CFR-2024-title10-vol3/pdf/CFR-2024-title10-vol3-part431-subpartF.pdf
A16: Others | B16: ACM (2013, 2019, 2022, 2025)
B17: Title 24, 2022 - Appendix 5.4A and Appendix 5.4B | C17: https://www.energy.ca.gov/publications/2022/2022-nonresidential-and-multifamily-alternative-calculation-method-reference
B18: 2022 Reduced infiltration CASE report | C18: https://title24stakeholders.com/wp-content/uploads/2020/10/2022-T24-Final-CASE-Report_Reduce-Infiltration.pdf
B19: 2019 Outdoor Lighting CASE Report | C19: https://title24stakeholders.com/wp-content/uploads/2016/10/T24-2019-CASE-Study-Results-Report-Outdoor-Sources_Final_with-Attachments.pdf
B20: PNNL 20405, 2011 | C20: https://www.pnnl.gov/main/publications/external/technical_reports/PNNL-20405.pdf
B21: Air leakage Memo, NORESCO, 2025 | C21: https://2050partners.sharepoint.com/:w:/r/sites/CalBEMCollaborativeEfforts/_layouts/15/Doc.aspx?sourcedoc=%7B3BEF8F74-7FAC-44F2-A70C-D76617660066%7D&file=Infiltration_rate_report_14May2025-Short-Version.docx&action=default&mobileredirect=true
B22: Yousefi, F., Athalye, R., (2025), "Determining Vintage Bins for Prototype Development: An Analysis of California Commercial Buildings," ASHRAE Annual Conference | C22: https://www.thefreelibrary.com/Determining+Vintage+Bins+for+Prototype+Development%3a+An+Analysis+of...-a0879271125
B23: Design Guide: Advanced Water Heating for Foodservice (20232) (by GTI and Frontier funded by SoCalGas and Pacific Gas and Electric Company | C23: https://caenergywise.com/design-guides/hot-water/Technical_Design_Guide.pdf
B24: Design Guide 1 : Improving Commercial Kitchen Ventilation System Performance : Selecting & Sizing Exhaust Hoods referred as CKV (2004) (by SCE) | C24: https://www.streivor.com/wp-content/uploads/2020/11/CKV-Design-Guide-1-Selecting-and-Sizing-Exhaust-Hoods.pdf
B25: Proposed Updates to Equipment Power Densities and Building Schedules for the 2028 Energy Code, referred to as "Plug load and schedules project with CEC, 2025" (Docket Number =25-BSTD-03 & TN=265693) | C25: https://efiling.energy.ca.gov/GetDocument.aspx?tn=265693&DocumentContentId=102545
B26: ENERGY STAR certified commercial water heaters | C26: https://www.energystar.gov/productfinder/product/certified-commercial-water-heaters/results?fuel_filter=Gas&markets_filter=United+States
B27: Grainger gas tank water heaters (sizes below commercial, e.g. 30–75 kBtu/h) | C27: https://www.grainger.com/category/plumbing/water-heaters/gas-tank-water-heaters
B28: Grainger electric tank water heaters | C28: https://www.grainger.com/category/plumbing/water-heaters/electric-tank-water-heaters
A45: Notes
A46: RestaurantFastFood | B46: Is a subcategory of food service building used for prepared-food sales. These places are often quick-service operations (e.g., drive-throughs, counter-service eateries,...).
A49: EIS, 2018: | B49: U.S. Energy Information Administration - EIA - Independent Statistics and Analysis
B80: RestaurantFastFood (STC:3)
A81: Year | B81: Total floor area (k ft2) | C81: Count
A82: 1967 | B82: 5361.9 | C82: 152
A83: 1968 | B83: 8271 | C83: 452
A84: 1969 | B84: 13593.6 | C84: 655
A85: 1970 | B85: 14323.7 | C85: 601
A86: 1971 | B86: 13719.8 | C86: 592
A87: 1972 | B87: 16513.9 | C87: 687
A88: 1973 | B88: 27619.6 | C88: 920
A89: 1974 | B89: 26732 | C89: 804
A90: 1975 | B90: 13654.6 | C90: 710
...

Sheet Prototype
A1: NORESCO, Updated September 2026
A2: RestaurantFastFood
A3: Characteristic | B3: Value | C3: Data Sources
A4: Building Type | B4: Fast Food Restaurant
A5: Building Category | B5: Nonresidential
A6: Version | B6: v2-0
A7: Vintages | B7: 4 Vintages: Pre-1978 , 1978-1997 ,1998-2007 , 2008-2018 New Construction (2019+) | C7: Based on the vintage bin analysis. A summary of the findings is presented in the following paper: Yousefi, F., Athalye, R. (2025). “Determining Vintage Bins for Prototype Development: An Analysis of California Commercial Buildings.” ASHRAE Annual Conference. | D7: https://www.thefreelibrary.com/Determining+Vintage+Bins+for+Prototype+Development%3a+An+Analysis+of...-a0879271125 | E7: NonRes-Vintage bins-Draft Report-30Nov2023-Final.docx
A8: Shape | C8: Assumption; same as CEC Prototype 2022
A9: Total Floor Area (ft²) | B9: 2501 (50 ft * 50 ft) | C9: Assumption; same as CEC Prototype 2022
A10: Aspect Ratio | B10: 1 | C10: Assumption; same as CEC Prototype 2022
A11: Number of Floors | B11: 1 | C11: Assumption; same as CEC Prototype 2022
A12: Roof type | B12: Attic (17°) | C12: Assumption; same as CEC Prototype 2022
A13: WWR | B13: Average 14% (South: 28% , East: 14% ,North: 0% ,West: 14% | C13: Assumption; same as CEC Prototype 2022
A14: Shading Geometry | B14: No shades | C14: Assumption; same as CEC Prototype 2022
A15: Floor to floor height (ft) | B15: N/A | C15: Assumption; same as CEC Prototype 2022
A16: Floor to ceiling height (ft) | B16: 10 | C16: Assumption; same as CEC Prototype 2022
A17: Glazing sill height (ft) | B17: 3.5 (top of the window is 6.5 ft high with 3 ft high glass) | C17: Assumption; same as CEC Prototype 2022
A27: Existing public prototypes
C31: PNNL (Fast Food) | D31: CEC (Small Restaurant) | E31: CPUC (Fast Food)
A32: Geometry | B32: Whole building
A33: Floor area (ft²) | B33: Total | C33: 2500 | D33: 2500 | E33: 1998
A34: Height (ft) | B34: All | C34: 10 | D34: 10 | E34: 10
A35: Zones | C35: Dining 50%, Kitchen 50%, Attic (NOT conditioned) | D35: Dining 50% , Kitchen 50%, Attic (NOT conditioned) | E35: Dining 40% , Kitchen 40% , Waiting Area 15% , Restroom 5% (100 sf)
A36: Internal Load
A37: People (person/ft²) | B37: Dining | C37: 0.07 | D37: 0.033 | E37: 0.033
B38: Kitchen | C38: 0.005 (6.3 people) | D38: 0.0025 | E38: 0.0025
B39: Other zones (if any) | C39: - | D39: - | E39: 0.033 Lobby & 0.005 Restroom
A40: Lights (W/ft²) | B40: Dining | C40: 0.38 | D40: 0.45 | E40: 0.45
B41: Kitchen | C41: 0.89 | D41: 0.95 | E41: 0.95
B42: Other zones (if any) | E42: 0.7 Lobby, 0.65 Restroom
A43: Ext lights (W) | B43: Whole building | C43: 952 (209 and 743) | D43: - | E43: -
A44: Gas Equipment (Btu/h-ft2) | B44: Kitchen | C44: 237.4 (296,748 Btu/h) | D44: 32.4 | E44: 17.5
A45: Electric Equipment (W/ft²) | B45: Dining | C45: 10.3 (12,835 W) | D45: 0.75 (0.5 receptacle & 0.25 refrigerator ) | E45: 0.75 (0.5 & 0.25)
B46: Kitchen | C46: 24.29 (29,769 W receptacle & 313 W ReachIn Refrigerator & 277 W ReachInFreezer) | D46: 2.62 (1.5 receptacle & 1.12 refrigerator) | E46: 2.62 (1.5 & 1.12)
B47: Other zones (if any) | C47: - | D47: - | E47: 0.5 Lobby
A48: Refrigerator | B48: Kitchen | C48: In addition to the Reachin freezer and refrigerator load defined as electric load, it has : 2 Case refrigerator : 716 and 763 Btu/hr-ft for 8 and 10 ft cases 2.5 COP for design compressor rack 1126 Btu/h for fan power of design compressor | D48: Two refrigerator loads is defined as electric equipment load for dining and kitchen | E48: expected to simulate the Refrigerator loads as electric equipment load ( like CEC)
A49: HVAC System
A50: Heating Sizing Factor | B50: All | C50: H&C: 1.2 | D50: H&C:1 | E50: H: 2.5 , C: 2.3
A51: HVAC | B51: Dining | C51: PSZ AC: CAV no reheat, DX cooling coil: multi speed, Gas heating coil | D51: (BAseAirSys 13): VAV no Reheat +DX cooling coil:two speed, Gas Heating coil | E51: Single Zone VAV no Reheat , DX cooling coil:multi speed, Gas heating coil
B52: Kitchen | C52: PSZ AC : CAV no reheat, DX cooling coil: multi speed, Gas heating coil | D52: (sys7or3a): CAV no Reheat+DX cooling coil: single speed+ Gas Heating coil | E52: Single Zone VAV no Reheat , DX cooling coil:single speed, Gas heating coil
...

Sheet Zones
A1: ="Proposed Layout - "&Prototype!A2 -> Proposed Layout - RestaurantFastFood
A2: Building | B2: Space/Thermal Zone | C2: Space Type Primarily from [T24, 2022 Appendix 5.4A] - See Notes column | D2: HVAC zone | E2: Schedule Category | F2: Conditioned (Y/N) | G2: Area Fraction | H2: Area (ft²) | I2: Volume (ft³) | J2: Multipliers | K2: Number of People | L2: People (Persons/1,000 ft²) [T24, 2025,Table 120.1-A] | M2: Notes
A3: RestaurantFastFood | B3: Dining | C3: Dining Area (Cafeteria/Fast Food) | D3: AHU_1 | E3: Restaurant | F3: Y | G3: =H3/$H$6 -> 0.5 | H3: 1250.46 | I3: =H3*Prototype!$B$16 -> 12504.6 | J3: 1 | K3: =L3*H3/1000 -> 41.26518 | L3: 33
A4: RestaurantFastFood | B4: Kitchen | C4: Kitchen/Food Preparation Area | D4: AHU_2 | E4: Kitchen | F4: Y | G4: =H4/$H$6 -> 0.5 | H4: 1250.46 | I4: =H4*Prototype!$B$16 -> 12504.6 | J4: 1 | K4: =L4*H4/1000 -> 3.75138 | L4: 3
A5: RestaurantFastFood | B5: Attic | C5: Attic | D5: n/a | F5: N | H5: 2500 | I5: =H5*Prototype!$B$16 -> 25000 | J5: 1 | K5: =L5*H5/1000 -> 0
A6: Total (1 Building) | B6: Total (3 Space) | C6: Total (3 space type) | D6: Total ( 2 HVAC Zones) | E6: Total (2 category) | F6: Total (2 Conditioned zones) | G6: =SUM(G3:G4) -> 1 | H6: =SUM(H3:H4) -> 2500.92 | I6: =SUM(I3:I4) -> 25009.2
A17: Background Data [To be deleted prior to publication]

Sheet Envelope
A1: ="Envelope - "&Prototype!A2 -> Envelope - RestaurantFastFood
A2: Element | B2: Prototype | C2: Assembly Type | D2: Construction | E2: Thermal properties | F2: Vintage | G2: Selected T24 | H2: Notes | I2: CZ1 | J2: CZ2 | K2: CZ3 | L2: CZ4 | M2: CZ5 | N2: CZ6 | O2: CZ7 | P2: CZ8 | Q2: CZ9 | R2: CZ10 | S2: CZ11 | T2: CZ12 | U2: CZ13 | V2: CZ14 | W2: CZ15 | X2: CZ16
A3: External Wall | B3: RestaurantFastFood | C3: ExtWall_WoodFramed_NonRes | D3: Stucco + insulation + wood framing + gypsum board | E3: U-factor IP | F3: Pre 1978 | G3: N/A | H3: ASHRAE 90.1, 2022 Table A3.4.3.1, 3.5", R-0 | I3: 0.292 | J3: 0.292 | K3: 0.292 | L3: 0.292 | M3: 0.292 | N3: 0.292 | O3: 0.292 | P3: 0.292 | Q3: 0.292 | R3: 0.292 | S3: 0.292 | T3: 0.292 | U3: 0.292 | V3: 0.292 | W3: 0.292 | X3: 0.292
F4: 1978-1997 | G4: 1986 | H4: Copied from low-rise office alternative table: Package A with heat capacity of 0.0-3.99 (Btu/F-ft²) | I4: =1/7.52 -> 0.13297872 | J4: =1/7.52 -> 0.13297872 | K4: =1/7.52 -> 0.13297872 | L4: =1/7.52 -> 0.13297872 | M4: =1/7.52 -> 0.13297872 | N4: =1/7.52 -> 0.13297872 | O4: =1/7.52 -> 0.13297872 | P4: =1/7.52 -> 0.13297872 | ... X4: =1/7.52 -> 0.13297872
F5: 1998-2007 | G5: 2001 | H5: Table 1-H | I5: 0.084 | J5: 0.084 | K5: 0.092 | L5: 0.092 | M5: 0.092 | N5: 0.092 | O5: 0.092 | P5: 0.092 | Q5: 0.092 | R5: 0.084 | S5: 0.084 | T5: 0.084 | U5: 0.084 | V5: 0.084 | W5: 0.084 | X5: 0.084
F6: 2008-2018 | G6: 2013 | H6: Table 140.3-B | I6: 0.102 | J6: 0.059 | K6: 0.11 | L6: 0.059 | M6: 0.102 | N6: 0.11 | O6: 0.11 | P6: 0.102 | Q6: 0.059 | R6: 0.059 | S6: 0.059 | T6: 0.059 | U6: 0.059 | V6: 0.059 | W6: 0.042 | X6: 0.059
F7: 2019+ | G7: 2025 | H7: Table 140.3-C | I7: 0.078 | J7: 0.053 | K7: 0.102 | L7: 0.053 | M7: 0.095 | N7: 0.102 | O7: 0.102 | P7: 0.095 | Q7: 0.053 | R7: 0.053 | S7: 0.042 | T7: 0.053 | U7: 0.053 | V7: 0.053 | W7: 0.038 | X7: 0.053
A8: Ceiling/Roof | B8: RestaurantFastFood | C8: AtticFloor Reversed | D8: Attic roof (no insulation): asphalt shingles + gypsum board Ceiling (wood-joist): insulation + gypsum board | E8: U-factor IP | F8: Pre 1978 | G8: N/A | H8: Considering 30 years for roof/ insulation replacement. | I8: =I9 -> 0.057 | J8: =J9 -> 0.057 | K8: =K9 -> 0.057 | L8: =L9 -> 0.057 | M8: =M9 -> 0.057 | N8: =N9 -> 0.078 | O8: =O9 -> 0.078 | P8: =P9 -> 0.078 | ... X8: =X9 -> 0.057
F9: 1978-1997 | G9: 1992 | I9: 0.057 | J9: 0.057 | K9: 0.057 | L9: 0.057 | M9: 0.057 | N9: 0.078 | O9: 0.078 | P9: 0.078 | Q9: 0.078 | R9: 0.078 | S9: 0.057 | T9: 0.057 | U9: 0.057 | V9: 0.057 | W9: 0.057 | X9: 0.057
F10: 1998-2007 | G10: 2001 | H10: Table 1-H | I10: 0.057 | J10: 0.057 | K10: 0.057 | L10: 0.057 | M10: 0.057 | N10: 0.078 | O10: 0.078 | P10: 0.078 | Q10: 0.078 | R10: 0.057 | S10: 0.057 | T10: 0.057 | U10: 0.057 | V10: 0.057 | W10: 0.057 | X10: 0.057
F11: 2008-2018 | G11: 2013 | H11: Table 140.3-B (Wood Framed and Other) | I11: 0.049 | J11: 0.039 | K11: 0.039 | L11: 0.039 | M11: 0.049 | N11: 0.075 | O11: 0.067 | P11: 0.067 | Q11: 0.039 | R11: 0.039 | S11: 0.039 | T11: 0.039 | U11: 0.039 | V11: 0.039 | W11: 0.039 | X11: 0.039
F12: 2019+ | G12: 2025 | H12: Table 140.3-B (Wood Framed and Other) | I12: 0.028 | J12: 0.028 | K12: 0.028 | L12: 0.028 | M12: 0.028 | N12: 0.047 | O12: 0.047 | P12: 0.047 | Q12: 0.028 | R12: 0.028 | S12: 0.028 | T12: 0.028 | U12: 0.028 | V12: 0.028 | W12: 0.028 | X12: 0.028
A13: Windows | B13: RestaurantFastFood | C13: FixedWindow_NonRes | D13: Single Pane (CBECS 2018, ~ 30 % of windows of Restaurant built before 2000 are single pane) | E13: U-factor IP | F13: Pre 1978 | G13: N/A | H13: 2021 ASHRAE Handbook of Fundamentals - Section 15.9 Table 4 for single pane & T24 2013 Table 140.3-B for double pane (30%-70%) | I13: =0.3*1.12+0.7*I16 -> 0.588 | J13: =0.3*1.12+0.7*J16 -> 0.588 | K13: =0.3*1.12+0.7*K16 -> 0.588 | L13: =0.3*1.12+0.7*L16 -> 0.588 | M13: =0.3*1.12+0.7*M16 -> 0.588 | N13: =0.3*1.12+0.7*N16 -> 0.588 | O13: =0.3*1.12+0.7*O16 -> 0.588 | P13: =0.3*1.12+0.7*P16 -> 0.588 | ... X13: =0.3*1.12+0.7*X16 -> 0.588
F14: 1978-1997 | G14: N/A | I14: =I13 -> 0.588 | J14: =J13 -> 0.588 | K14: =K13 -> 0.588 | L14: =L13 -> 0.588 | M14: =M13 -> 0.588 | N14: =N13 -> 0.588 | O14: =O13 -> 0.588 | P14: =P13 -> 0.588 | ... X14: =X13 -> 0.588 | Y14: These vintages have better performance because of partial retrofit
D15: Double pane | F15: 1998-2007 | G15: 2001 | H15: Table 1-H | I15: 0.49 | J15: 0.49 | K15: 0.81 | L15: 0.81 | M15: 0.81 | N15: 0.81 | O15: 0.81 | P15: 0.81 | Q15: 0.81 | R15: 0.49 | S15: 0.49 | T15: 0.49 | U15: 0.49 | V15: 0.49 | W15: 0.49 | X15: 0.49
F16: 2008-2018 | G16: 2013 | H16: Table 140.3-B | I16: 0.36 | J16: 0.36 | K16: 0.36 | L16: 0.36 | M16: 0.36 | N16: 0.36 | O16: 0.36 | P16: 0.36 | Q16: 0.36 | R16: 0.36 | S16: 0.36 | T16: 0.36 | U16: 0.36 | V16: 0.36 | W16: 0.36 | X16: 0.36
F17: 2019+ | G17: 2025 | H17: Table 140.3-B | I17: 0.36 | J17: 0.36 | K17: 0.36 | L17: 0.36 | M17: 0.36 | N17: 0.36 | O17: 0.36 | P17: 0.36 | Q17: 0.34 | R17: 0.36 | S17: 0.34 | T17: 0.34 | U17: 0.34 | V17: 0.34 | W17: 0.34 | X17: 0.36
D18: Single Pane (CBECS 2018, ~ 30 % of windows of Restaurant built before 2000 are single pane) | E18: SHGC | F18: Pre 1978 | G18: N/A | H18: 2021 ASHRAE Handbook of Fundamentals - Section 15.22 Table 10 for single pane & T24, 2013 Table 140.3-B for double pane (30%-70%) | I18: =0.79*0.3+I21*0.7 -> 0.412 | J18: =0.79*0.3+J21*0.7 -> 0.412 | K18: =0.79*0.3+K21*0.7 -> 0.412 | L18: =0.79*0.3+L21*0.7 -> 0.412 | M18: =0.79*0.3+M21*0.7 -> 0.412 | N18: =0.79*0.3+N21*0.7 -> 0.412 | O18: =0.79*0.3+O21*0.7 -> 0.412 | P18: =0.79*0.3+P21*0.7 -> 0.412 | ... X18: =0.79*0.3+X21*0.7 -> 0.412
F19: 1978-1997 | G19: N/A | I19: =I18 -> 0.412 | J19: =J18 -> 0.412 | K19: =K18 -> 0.412 | L19: =L18 -> 0.412 | M19: =M18 -> 0.412 | N19: =N18 -> 0.412 | O19: =O18 -> 0.412 | P19: =P18 -> 0.412 | ... X19: =X18 -> 0.412 | Y19: These vintages have better performance because of partial retrofit
D20: Double pane | F20: 1998-2007 | G20: 2001 | H20: Table 1-H (Non North, 10-20% total WWR) | I20: 0.43 | J20: 0.36 | K20: 0.55 | L20: 0.55 | M20: 0.55 | N20: 0.61 | O20: 0.61 | P20: 0.61 | Q20: 0.61 | R20: 0.36 | S20: 0.36 | T20: 0.36 | U20: 0.36 | V20: 0.36 | W20: 0.36 | X20: 0.43
F21: 2008-2018 | G21: 2013 | H21: Table 140.3-B | I21: 0.25 | J21: 0.25 | K21: 0.25 | L21: 0.25 | M21: 0.25 | N21: 0.25 | O21: 0.25 | P21: 0.25 | Q21: 0.25 | R21: 0.25 | S21: 0.25 | T21: 0.25 | U21: 0.25 | V21: 0.25 | W21: 0.25 | X21: 0.25
F22: 2019+ | G22: 2025 | H22: Table 140.3-B | I22: 0.25 | J22: 0.25 | K22: 0.25 | L22: 0.25 | M22: 0.25 | N22: 0.25 | O22: 0.25 | P22: 0.25 | Q22: 0.22 | R22: 0.25 | S22: 0.22 | T22: 0.22 | U22: 0.22 | V22: 0.22 | W22: 0.22 | X22: 0.25
C24: Infiltration
D25: Building | E25: Zones | F25: Vintage | G25: I_75 (cfm/ft2) 6-sdied Infiltration rate @ 75 pa | H25: Source | I25: I-design (cfm/ft²) (4-sided Infiltration rate at normal pressure) (Design flow rate approach and Flow/Exterior Wall Area calculation method)
C26: Infiltration | D26: RestaurantFastFood | F26: Pre 1978 | G26: 1.1 | H26: 2022 CASE report (Table 38) | I26: =0.112*G26*$AA$30 -> 0.4312616 | Z26: Floor or roof area | AA26: =50.01^2 -> 2501.0001
F27: 1978-1997 | G27: 1.1 | H27: 2022 CASE report (Table 38) | I27: =0.112*G27*$AA$30 -> 0.4312616 | Z27: Walls area | AA27: =(50.01+50.01)*2*10 -> 2000.4
F28: 1998-2007 | G28: 1.1 | H28: 2022 CASE report (Table 38) | I28: =0.112*G28*$AA$30 -> 0.4312616 | Z28: Building 4 sided area= | AA28: =AA27 -> 2000.4
F29: 2008-2018 | G29: 1 | H29: 2022 CASE report (Table 38) & T24, 2008-2016 (Table 140.3-B) | I29: =0.112*G29*$AA$30 -> 0.392056 | Z29: Building 6 sided area= | AA29: =AA27+(2*AA26) -> 7002.4002
F30: 2019+ | G30: 0.6 | H30: 2022 CASE report (Table 38) & T24, 2025 (Table 140.3-B) | I30: =0.112*G30*$AA$30 -> 0.2352336 | Z30: 6 sided /4 sided factor= | AA30: =AA29/AA28 -> 3.5005
E31: Source: T24 air barrier requirements (all editions) , the standardized infiltration rate reported in the 2022 CASE report, and Dodge 2023 data
E32: Infiltration_rate_report_14May2025-Short-Version.docx

Sheet HVAC System
A1: ="HVAC system - "&Prototype!A2 -> HVAC system - RestaurantFastFood
A2: Vintage | B2: Space/Thermal Zone | C2: Heating | D2: Cooling | E2: Air Distribution | F2: Other Systems | G2: Source
A3: Existing | B3: Dining | C3: Gas Furnace (PSZAC) | D3: DX Coil (PSZAC) | E3: CAV (PSZAC) | F3: Economizer for after 2008 | G3: CEUS 2022 + Engineering Judgement
B4: Kitchen | C4: Gas Furnace (PSZAC) | D4: DX Coil (PSZAC) | E4: CAV (PSZAC) | F4: Makeup Air Unit (Combo with RTU) to supply make-up air exceeding transfer air from dining space (can be included in system13b)
A5: New Construction | B5: Dining | C5: Gas Furnace (PSZAC) | D5: DX Coil (PSZAC) | E5: CAV (PSZAC) | F5: Economizer | G5: T24, 2025 | H5: Demand control ventilation
B6: Kitchen | C6: Gas Furnace (PSZAC) | D6: DX Coil (PSZAC) | E6: CAV (PSZAC) | F6: HR-Makeup Air Unit (systems that integrate make-up air and heat recovery functions) (can be included in system13b)
A12: Efficiency of HVAC System (Efficiency is capacity-dependent. The following table provides a general estimate of system efficiency based on preliminary simulations in one climate zone, or assuming cooling load based on rule of thumb)
A13: Vintage | B13: Upgrade/Installed year | C13: Gas Furnace | D13: Dining DX cooling (<65,000 Btu/h) | E13: Kitchen DX cooling (>=65,000 and < 135,000 Btu/h ) | F13: Source | G13: Note
A14: Pre 1978 | B14: 2008 | C14: Efficiency 80% | D14: SEER 13 | E14: EER 10.3 | F14: System <65,000: 10 CFR, 2009 (Vol. 74, No. 54 , page 12074) system >65,000: T24, 2008, Table 112-A | G14: Econ Max Position=0.9. *Econ Max Position is set to below 1 to approximate effects of not having fault detection and diagnostics (FDD) requirements, which began in 2013. it can be modeled in E+ either by: - Reducing Maximum Outdoor Air Flow Rate in Controller:OutdoorAir. - Or using FaultModel objects to simulate pre-2013 “no FDD” conditions
A15: 1978-1997
A16: 1998-2007
A17: 2008-2018 | B17: 2013 | C17: Efficiency 80% | D17: SEER 13 | E17: EER 11.2 | F17: System <65,000: 10 CFR, 2013, Table 1 TO § 431.97 System >65,000: T24, 2013, Table 110.2-A | G17: Econ Max Position=0.9
A18: New Construction | B18: 2025 | C18: Efficiency 80% | D18: SEER2 13.4 | E18: EER 11.2 | F18: System <65,000: 10 CFR, 2024 ,Table 19 TO § 431.97(h) System >65,000: T24, 2025, Table 110.2-A | G18: - Econ Max Position=1 - Deduct 0.2 from the required EERs and IEERs for units with a heating section other than electric resistance heat.
A22: Fan Power
A23: Vintage | B23: Approach | C23: System | D23: Total Static Pressure (TSP) (in w.c.) | E23: Fan Efficiency [ACM 2025] | F23: Motor Efficiency | G23: Fan Power Index (W/cfm) | H23: Data Source
A24: Existing | B24: PNNL 90.1-2011, TSP | C24: CAV Kitchen (system <7,437 cfm) | D24: 2.5 | E24: 0.65 | F24: ASHRAE 90.1, 2004, Table 10.8 * | H24: Fan power formula: PNNL 20405, 2010, section 5.2.2.5 TSP and fan efficiecncy: PNNL 20405, 2010, Table 5.11, 90.1-04ac values Motor and drive efficiency: ASHRAE 90.1, 2004, Table 10.8
C25: CAV Dining (system <7,437 cfm) | D25: 2.5
A26: Brake horsepower (bhp) = (Supply cfm × TSP in w.c.) / (6356 × fan efficiency)
A27: Fan power (w/cfm) = (bhp × 746) / ( supply cfm × motor efficiency )
A28: New Construction | B28: ACM 2025 | C28: PSZAC (System 3a), CAV kitchen, ≤5,000 cfm | D28: TSP = fan power × motor efficiency × fan efficiency × 6356 / 746 | E28: 0.65 | F28: 2025 ACM Table 12 ** | G28: 0.802 | H28: Fan power index: [ACM 2025, Table 13] Motor efficiency: [ACM 2025, Table 12]
C29: PSZAC (System 3a), CAV dining, ≤5,000 cfm | D29: TSP = fan power × motor efficiency × fan efficiency × 6356 / 746 | G29: 0.802
A31: * According to PNNL 20405 section 5.2.2.5, the full-load efficiency of the motor serving the fan is taken from ASHRAE 90.1, 2004, Table 10.8, based on motor nameplate and assuming enclosed motors operating at 1,800 rotations per minute (rpm) Motor nameplate size (bhp) = brake horsepower (bhp) × 1.1 ( using a 10% oversizing factor)
A32: ** The full‑load efficiency of the motor serving the fan is taken from ACM 2025 Table 12 based on the cfm of the fan. Brake horsepower (bhp) = (Supply cfm from sizing run × fan power in W/cfm) / 746. Note: PSZAC with gas furnace (System 3a SZAC) ≤5,000 cfm. Same index as Restaurant Sit-Down kitchen. Note: PSZAC with gas furnace (System 3a SZAC) ≤5,000 cfm. Same index as Restaurant Sit-Down kitchen.

Sheet Thermostat
A1: ="Thermostat Setpoints - "&Prototype!A2 -> Thermostat Setpoints - RestaurantFastFood
A2: Space/Thermal Zone | B2: Setpoint | C2: CZ1 | D2: CZ2 | E2: CZ3 | F2: CZ4 | G2: CZ5 | H2: CZ6 | I2: CZ7 | J2: CZ8 | K2: CZ9 | L2: CZ10 | M2: CZ11 | N2: CZ12 | O2: CZ13 | P2: CZ14 | Q2: CZ15 | R2: CZ16 | S2: Source
A3: Dining | B3: Heating Setpoint (F) | C3: 70 | D3: 70 | E3: 70 | F3: 70 | G3: 70 | H3: 70 | I3: 70 | J3: 70 | K3: 70 | L3: 70 | M3: 70 | N3: 70 | O3: 70 | P3: 70 | Q3: 70 | R3: 70 | S3: T24 2022 - Appendix 5.4B
B4: Heating Setback (F) | C4: 60 | D4: 60 | E4: 60 | F4: 60 | G4: 60 | H4: 60 | I4: 60 | J4: 60 | K4: 60 | L4: 60 | M4: 60 | N4: 60 | O4: 60 | P4: 60 | Q4: 60 | R4: 60
B5: Cooling Setpoint (F) | C5: 75 | D5: 75 | E5: 75 | F5: 75 | G5: 75 | H5: 75 | I5: 75 | J5: 75 | K5: 75 | L5: 75 | M5: 75 | N5: 75 | O5: 75 | P5: 75 | Q5: 75 | R5: 75
B6: Cooling Setback (F) | C6: 85 | D6: 85 | E6: 85 | F6: 85 | G6: 85 | H6: 85 | I6: 85 | J6: 85 | K6: 85 | L6: 85 | M6: 85 | N6: 85 | O6: 85 | P6: 85 | Q6: 85 | R6: 85
A7: Kitchen | B7: Heating Setpoint (F) | C7: 66 | D7: 66 | E7: 66 | F7: 66 | G7: 66 | H7: 66 | I7: 66 | J7: 66 | K7: 66 | L7: 66 | M7: 66 | N7: 66 | O7: 66 | P7: 66 | Q7: 66 | R7: 66 | S7: PNNL 09.1, 2022 Restaurant prototype
B8: Heating Setback (F) | C8: 60 | D8: 60 | E8: 60 | F8: 60 | G8: 60 | H8: 60 | I8: 60 | J8: 60 | K8: 60 | L8: 60 | M8: 60 | N8: 60 | O8: 60 | P8: 60 | Q8: 60 | R8: 60
B9: Cooling Setpoint (F) | C9: 79 | D9: 79 | E9: 79 | F9: 79 | G9: 79 | H9: 79 | I9: 79 | J9: 79 | K9: 79 | L9: 79 | M9: 79 | N9: 79 | O9: 79 | P9: 79 | Q9: 79 | R9: 79
B10: Cooling Setback (F) | C10: 86 | D10: 86 | E10: 86 | F10: 86 | G10: 86 | H10: 86 | I10: 86 | J10: 86 | K10: 86 | L10: 86 | M10: 86 | N10: 86 | O10: 86 | P10: 86 | Q10: 86 | R10: 86
A12: PNNL's comfort range in kitchen is 4 F wider : 66 -79 F (with Heating setback of 60 F and Cooling setback of 86 F)
A13: CPUC has the same setpoint and setback as CEC

Sheet Ventilation
A1: ="Outdoor Airflow Rate - "&Prototype!A2 -> Outdoor Airflow Rate - RestaurantFastFood
A2: Space/Thermal Zone | B2: Number of People | C2: Floor Area (ft²) | D2: cfm/person [T24, 2025, Equation 120.1-F and Table 120.1-A] | E2: cfm/ft² [T24, 2025, Equation 120.1-F and Table 120.1-A] | F2: Required Exhaust Rate [T24, 2025, Table 120.1-B – minimum exhaust rates] | G2: Total cfm Driven by People | H2: Total cfm Driven by Area | I2: Total cfm Driven by Exhaust | J2: Total cfm | K2: Notes
A3: =Zones!B3 -> Dining | B3: =Zones!K3 -> 41.26518 | C3: =Zones!H3 -> 1250.46 | D3: 15 | E3: 0.15 | F3: 2 restroom, each 25/50 cfm pr unit | G3: =B3*D3 -> 618.9777 | H3: =C3*E3 -> 187.569 | I3: =2*50 -> 100 | J3: =MAX(G3:I3) -> 618.9777
A4: =Zones!B4 -> Kitchen | B4: =Zones!K4 -> 3.75138 | C4: =Zones!H4 -> 1250.46 | D4: 15 | E4: 0.15 | F4: 0.7 cfm/ft2 | G4: =B4*D4 -> 56.2707 | H4: =C4*E4 -> 187.569 | I4: =0.7*C4 -> 875.322 | J4: =MAX(G4:I4) -> 875.322
A5: =Zones!B5 -> Attic
A7: Fine storage is defined for normal inventory that doesn't require an extra exhaust rate based on the space functions in T24, Part6, 2025, Table 120.1 B.
A10: Exhaust hood
A11: Type of Hood | C11: Max Exhaust Flow Rate (cfm/ft) [T24, 2025, Table 140.9-C] | D11: Hood Length (ft) * [CKV, 2004] & | E11: Hood Exhaust Rate (cfm) | F11: Note
A12: Type I , wall-mounted canopy, medium duty hood | C12: 210 | D12: =B24 -> 15.25 | E12: =D12*C12 -> 3202.5
A14: Efficiency of exhaust fan is 50% (according to ACM, 2025,section 5.7.3)
A16: Quick Service Restaurant Hood Appliance
A17: Appliance | B17: Count | C17: Length (ft) | D17: Source
A18: Two Fryers side | B18: 2 | C18: 2.5 | D18: CKV Design Guide, 2004
A19: Fryer drip station (doesn't generate heat or grease but still need to be covered) | B19: 1 | C19: 1.25
A20: Griddle | B20: 1 | C20: 4
A21: Convection oven | B21: 1 | C21: 2.5
A22: Charbroiler | B22: 1 | C22: 4 | D22: Charbroiler is common in fast food with burgers in the menu (e.g., KFC). So, we've decide to add this appliance to the above mentioned ones
A23: Total cooking line length (ft) | B23: =SUM(C18:C22) -> 14.25
A24: Hood length (ft) (+1 ft buffer) | B24: =B23+1 -> 15.25

Sheet Water Heater
A1: ="Water Heater Summary - "&Prototype!A2 -> Water Heater Summary - RestaurantFastFood
A2: Vintage | B2: WH Type | C2: Efficiency | D2: Number of WH | E2: Tank Volume (gal) | F2: Tank Loss | G2: Source
A3: Existing | B3: Gas | C3: 0.8 | D3: 1 | E3: See table below for CZ-specific values: Climate Zone Water Heater Sizing and Loss Coefficients, Storage Volume column (col F) | F3: See table below: Climate Zone Water Heater Sizing and Loss Coefficients, Standby Loss column (col G) | G3: See table below for sources: Climate Zone Water Heater Sizing and Loss Coefficients
A4: New Construction | B4: Gas | C4: 0.8 | D4: 1 | E4: =E3 -> See table below for CZ-specific values: Climate Zone Water Heater Sizing and Loss Coefficients, Storage Volume column (col F) | F4: =F3 -> See table below: Climate Zone Water Heater Sizing and Loss Coefficients, Standby Loss column (col G) | G4: =G3 -> See table below for sources: Climate Zone Water Heater Sizing and Loss Coefficients
A7: Peak Hot Water Consumption
A8: Space Name | B8: Baseline WH Type [T24, 2022, Appendix 5.4A , sheet: "2022 SpaceFuncData-Input"] | C8: Total Area (ft²) | D8: Number of People | E8: Hot Water Usage Specification (gal/hr per person) [T24, 2022, Appendix 5.4A , sheet: "2022 SpaceFuncData-Input"] | F8: Peak Hot Water Usage (gal/hr) | G8: Peak Hot Water Usage (gal/min) | H8: Note
A9: =Zones!B3 -> Dining | B9: Gas | C9: =Zones!H3 -> 1250.46 | D9: =Zones!K3 -> 41.26518 | E9: =0.58*0.2 -> 0.116 | F9: =E9*D9 -> 4.7867609 | G9: =F9/60 -> 0.079779348 | H9: Assumption: HW usage rate for the restaurant dining space was calculated at 20% of the hot water usage rate specified in the 2025 Nonres ACM 2024, Appendix 5.4A (equivalent to applying the full rate to 20% of the dining floor area)
A10: =Zones!B4 -> Kitchen | B10: Gas | C10: =Zones!H4 -> 1250.46 | D10: =Zones!K4 -> 3.75138 | E10: N/A | F10: =D24 -> 53.6 | G10: =F10/60 -> 0.89333333 | H10: Peak HW Usage is based on the fixture calulcation from the table below.
A11: Total | B11: Gas storage | F11: =_xlfn.LET( _xlpm.g,SUMIF($B$9:$B$10,"Gas*",$F$9:$F$10), _xlpm.e,SUMIF($B$9:$B$10,"Electric*",$F$9:$F$10), IF(AND(_xlpm.g>0,_xlpm.e>0),_xlpm.g,IF(_xlpm.g>0,MAX(75,_xlpm.g),0))) -> 75 | H11: Minimum peak hot water usage is 75 gal according to ACM 2025
A12: Total | B12: Electric resistance | F12: =_xlfn.LET( _xlpm.g,SUMIF($B$9:$B$10,"Gas*",$F$9:$F$10), _xlpm.e,SUMIF($B$9:$B$10,"Electric*",$F$9:$F$10), IF(AND(_xlpm.g>0,_xlpm.e>0),_xlpm.e,IF(_xlpm.e>0,MAX(75,_xlpm.e),0))) -> 0
G14: Design Guide: Advanced Water Heating for Foodservice, 2022, Table 8] | J14: Design Guide: Advanced Water Heating for Foodservice, 2023, Table 11]
J15: Technical_Design_Guide.pdf
A17: Peak Water Heater Capacity, Tank Capacity, and Tank Loss
A18: Fixture | B18: Tank Recovery Rate (gal/h) | C18: Fixture Count | D18: Storage Heater Min Recovery Rate (gal/hr) | E18: Source
A19: Room sinks | B19: 5 | C19: 1 | D19: 5 | E19: Design Guide: Advanced Water Heating for Foodservice (2022) , Table 6,7: Small Quick Restaurant Kitchen Design Guide: Advanced Water Heating for Foodservice (2023) , Table11: Small Quick Restaurant Kitchen
A20: Hand sinks | B20: 5 | C20: 1 | D20: 5
A21: 3-Compartment sinks | B21: 42 | C21: 1 | D21: 42
A22: Mop sink | B22: 15 | C22: 1 | D22: 15
A23: Utility or pre-soak sinks | B23: 5
A24: Minimum Recovery Rate (gal/h) | D24: =SUM(D19:D22)*0.8 -> 53.6 | E24: Design Guide: Advanced Water Heating for Foodservice, 2023, Table 11] *Minimum recovery rate discount factor of 20% for using single service utensils
A25: Input Rate (Btu/h) | D25: 56000 | E25: .Design Guide: Advanced Water Heating for Foodservice, 2023, Table 12]
A26: Tank volume (gal) | D26: 75 | E26: .Design Guide: Advanced Water Heating for Foodservice, 2023, Table 12]
A27: Standby Loss (Btu/hr) | D27: =(D25/800)+110*SQRT(D24) -> 875.33223 | E27: Title 20, §1605.1 Table F-4 (Standby loss equation: )
A28: Off/On Cycle Loss Coefficient to Ambient Temperature (Btu/h-F) | D28: =D27/70 -> 12.504746 | E28: Title 20 / 10 CFR 431.102: UA = SL / 70 °F rating ΔT (same as climate-zone col I). Not ambient T.
A31: For Gas Water Heater: UA (Btu/h-°F) = Q_SL (Btu/h) / 70 °F. 70 is the Title 20 / 10 CFR 431.102 rating ΔT (stored water minus ambient), not ambient T.
A32: Rating ΔT (°F) | B32: 70 | C32: 10 CFR 431.102: gas standby loss is Btu/h based on a 70 °F temperature differential between stored water and ambient. Not ACM indoor temperature.
A34: ** For Electric Water Heater: UA(Btu/h-°F)​= 0.0834 *SL​ (%/hr)*V gal
A43: Design supply temperature (°F) | B43: 135 | C43: CEC-400-2022-009-CMF-REV2-AP5.4B
A44: WH system factor | B44: 0.6 | C44: 2025 ACM §5.9.2 Rated Capacity
A45: Water mass conversion (lb/gal) | B45: 8.2877 | C45: 2025 ACM §5.9.2 Rated Capacity
A46: Reheat multiplier | B46: 0.4 | C46: 2025 ACM §5.9.2 Storage Volume
A47: Climate Zone Water Heater Sizing and Loss Coefficients
A48: Climate Zone | B48: Minimum Monthly Mains Temp (°F) [T24 2022 - Appendix 5.4B] | C48: Heat Output (Btu/hr) [ACM, 2025, 5.9.2: Rated capacity section] | D48: WH Capacity (Btu/hr) [ACM, 2025, 5.9.2: Rated capacity section] | E48: Required Energy Input (Btu/hr) | F48: Storage Volume (gal) | G48: Standby Loss [Title 20, §1605.1 Table F-4; Appendix B: Water Heating Calculation Method] | I48: Off/On Cycle Loss Coefficient to Ambient Temp | K48: Source/Note
A49: CZ01 | B49: 47.9 | C49: =$F$11*($B$43-B49)*$B$45 -> 54139.4 | D49: =C49*$B$44 -> 32483.64 | E49: =_xlfn.LET(_xlpm.x,_xlfn.XLOOKUP(D49/$C$3,$A$70:$A$100,$A$70:$A$100,"",1),IF(_xlpm.x="",ROUNDUP(D49/$C$3,0),_xlpm.x)) -> 60000 | F49: =_xlfn.LET(_xlpm.v,MAX(30,$F$11*$B$46),_xlpm.x,_xlfn.XLOOKUP(_xlpm.v,$E$70:$E$88,$E$70:$E$88,"",1),IF(_xlpm.x="",ROUNDUP(_xlpm.v,0),_xlpm.x)) -> 34 | G49: =(E49/800)+110*SQRT(F49) -> 716.40471 | H49: Btu/hr | I49: =G49/70 -> 10.234353 | J49: Btu/h·°F | K49: Required Energy Input: vendor/available catalog size (Market data table). Storage Volume: standard/available catalog tank size (Market data table). Off/On-cycle UA (col I): gas SL / 70 °F rating ΔT (10 CFR 431.102 / Title 20), not ambient T.
A50: CZ02 | B50: 50.8 | C50: =$F$11*($B$43-B50)*$B$45 -> 52336.825 | D50: =C50*$B$44 -> 31402.095 | E50: =_xlfn.LET(_xlpm.x,_xlfn.XLOOKUP(D50/$C$3,$A$70:$A$100,$A$70:$A$100,"",1),IF(_xlpm.x="",ROUNDUP(D50/$C$3,0),_xlpm.x)) -> 60000 | F50: =_xlfn.LET(_xlpm.v,MAX(30,$F$11*$B$46),_xlpm.x,_xlfn.XLOOKUP(_xlpm.v,$E$70:$E$88,$E$70:$E$88,"",1),IF(_xlpm.x="",ROUNDUP(_xlpm.v,0),_xlpm.x)) -> 34 | G50: =(E50/800)+110*SQRT(F50) -> 716.40471 | H50: Btu/hr | I50: =G50/70 -> 10.234353 | J50: Btu/h·°F
A51: CZ03 | B51: 52.2 | C51: =$F$11*($B$43-B51)*$B$45 -> 51466.617 | D51: =C51*$B$44 -> 30879.97 | E51: =_xlfn.LET(_xlpm.x,_xlfn.XLOOKUP(D51/$C$3,$A$70:$A$100,$A$70:$A$100,"",1),IF(_xlpm.x="",ROUNDUP(D51/$C$3,0),_xlpm.x)) -> 60000 | F51: =_xlfn.LET(_xlpm.v,MAX(30,$F$11*$B$46),_xlpm.x,_xlfn.XLOOKUP(_xlpm.v,$E$70:$E$88,$E$70:$E$88,"",1),IF(_xlpm.x="",ROUNDUP(_xlpm.v,0),_xlpm.x)) -> 34 | G51: =(E51/800)+110*SQRT(F51) -> 716.40471 | H51: Btu/hr | I51: =G51/70 -> 10.234353 | J51: Btu/h·°F
A52: CZ04 | B52: 52.7 | C52: =$F$11*($B$43-B52)*$B$45 -> 51155.828 | D52: =C52*$B$44 -> 30693.497 | E52: =_xlfn.LET(_xlpm.x,_xlfn.XLOOKUP(D52/$C$3,$A$70:$A$100,$A$70:$A$100,"",1),IF(_xlpm.x="",ROUNDUP(D52/$C$3,0),_xlpm.x)) -> 60000 | F52: =_xlfn.LET(_xlpm.v,MAX(30,$F$11*$B$46),_xlpm.x,_xlfn.XLOOKUP(_xlpm.v,$E$70:$E$88,$E$70:$E$88,"",1),IF(_xlpm.x="",ROUNDUP(_xlpm.v,0),_xlpm.x)) -> 34 | G52: =(E52/800)+110*SQRT(F52) -> 716.40471 | H52: Btu/hr | I52: =G52/70 -> 10.234353 | J52: Btu/h·°F
A53: CZ05 | B53: 51.6 | C53: =$F$11*($B$43-B53)*$B$45 -> 51839.563 | D53: =C53*$B$44 -> 31103.738 | E53: =_xlfn.LET(_xlpm.x,_xlfn.XLOOKUP(D53/$C$3,$A$70:$A$100,$A$70:$A$100,"",1),IF(_xlpm.x="",ROUNDUP(D53/$C$3,0),_xlpm.x)) -> 60000 | F53: =_xlfn.LET(_xlpm.v,MAX(30,$F$11*$B$46),_xlpm.x,_xlfn.XLOOKUP(_xlpm.v,$E$70:$E$88,$E$70:$E$88,"",1),IF(_xlpm.x="",ROUNDUP(_xlpm.v,0),_xlpm.x)) -> 34 | G53: =(E53/800)+110*SQRT(F53) -> 716.40471 | H53: Btu/hr | I53: =G53/70 -> 10.234353 | J53: Btu/h·°F
A54: CZ06 | B54: 56.8 | C54: =$F$11*($B$43-B54)*$B$45 -> 48607.36 | D54: =C54*$B$44 -> 29164.416 | E54: =_xlfn.LET(_xlpm.x,_xlfn.XLOOKUP(D54/$C$3,$A$70:$A$100,$A$70:$A$100,"",1),IF(_xlpm.x="",ROUNDUP(D54/$C$3,0),_xlpm.x)) -> 60000 | F54: =_xlfn.LET(_xlpm.v,MAX(30,$F$11*$B$46),_xlpm.x,_xlfn.XLOOKUP(_xlpm.v,$E$70:$E$88,$E$70:$E$88,"",1),IF(_xlpm.x="",ROUNDUP(_xlpm.v,0),_xlpm.x)) -> 34 | G54: =(E54/800)+110*SQRT(F54) -> 716.40471 | H54: Btu/hr | I54: =G54/70 -> 10.234353 | J54: Btu/h·°F
A55: CZ07 | B55: 58.4 | C55: =$F$11*($B$43-B55)*$B$45 -> 47612.836 | D55: =C55*$B$44 -> 28567.702 | E55: =_xlfn.LET(_xlpm.x,_xlfn.XLOOKUP(D55/$C$3,$A$70:$A$100,$A$70:$A$100,"",1),IF(_xlpm.x="",ROUNDUP(D55/$C$3,0),_xlpm.x)) -> 60000 | F55: =_xlfn.LET(_xlpm.v,MAX(30,$F$11*$B$46),_xlpm.x,_xlfn.XLOOKUP(_xlpm.v,$E$70:$E$88,$E$70:$E$88,"",1),IF(_xlpm.x="",ROUNDUP(_xlpm.v,0),_xlpm.x)) -> 34 | G55: =(E55/800)+110*SQRT(F55) -> 716.40471 | H55: Btu/hr | I55: =G55/70 -> 10.234353 | J55: Btu/h·°F
...

Sheet Interior Lights
A1: ="Interior Lighting - "&Prototype!A2 -> Interior Lighting - RestaurantFastFood
A2: Space Type | B2: New Construction | E2: Existing
B3: LPD (W/ft²) | C3: Additional LPD for Portable Lighting (W/ft²) | D3: Source | E3: LPD (W/ft²) | F3: Additional LPD for Portable Lighting (W/ft²) | G3: Source
A4: =Zones!C3 -> Dining Area (Cafeteria/Fast Food) | B4: 0.45 | C4: 0.25 | D4: T24, 2025, Table 140.6-C (Area category method) | E4: 1 | G4: T24, 2016, Table 140.6-C (Area category method) LPD of "All other spaces" is considered for storage space
A5: =Zones!C4 -> Kitchen/Food Preparation Area | B5: 0.95 | E5: 1.2
A6: =Zones!C5 -> Attic
A20: Background Data [To be deleted prior to publication]
A24: Existing | B24: Whole Building | C24: All other building | D24: 0.4 | F24: T24, 2019, Table 140.6 B
B25: Area Category | C25: =Zones!B29 -> 0 | D25: 0.65 | F25: T24, 2019, Table 140.6-C
C26: =Zones!B30 -> 0 | D26: 0.4
C27: =Zones!B31 -> 0 | D27: 0.4
A29: Existing | B29: Whole Building | C29: All other building | D29: 0.5 | F29: T24, 2016, Table 140.6 B
B30: Area Category | C30: ZONE1 OFFICE | D30: 0.75 | F30: T24, 2016, Table 140.6-C
C31: ZONE2 FINE STORAGE | D31: 0.5
C32: ZONE3 BULK STORAGE | D32: 0.5
A34: Existing | B34: Whole Building | C34: All other building | D34: 0.6 | F34: T24, 2013, Table 140.6 B
B35: Area Category | C35: ZONE1 OFFICE | D35: 0.75 | F35: T24, 2013, Table 140.6-C
C36: ZONE2 FINE STORAGE | D36: 0.6
C37: ZONE3 BULK STORAGE | D37: 0.6

Sheet Ext Lighting
A1: ="Exterior Lighting - "&Prototype!A2 -> Exterior Lighting - RestaurantFastFood
A2: Motion Controlled Luminaires (W) | B2: Non-motion Controlled Luminaires (W) | C2: Total (W) | D2: Source
A3: =G17 -> 351.02797 | B3: =G18 -> 116.75616 | C3: =B3+A3 -> 467.78413 | D3: T24, 2022
A8: Exterior Lighting
A9: Items (Assume LZ2) | B9: Assumptions [2019 Outdoor Lighting CASE Report & PNNL 90.1-2010 TSD] | D9: Unit | E9: Lighting Power Allowance [T24, 2025, Table 140.7-A & 140.7-B] | F9: Unit | G9: Exterior Lighting Power (W)
A10: IWA (Initial Wattage Allowance) | E10: 200 | F10: (W) | G10: =$E10 -> 200
A11: Parking area | B11: 400 ft² for every parking space [2019 Lighting CASE report, Appendix H] 1 parking space per 250 ft² of gross building area [2019 Lighting CASE report,Table 38] | C11: =B24/250*400 -> 4001.472 | D11: (ft²) | E11: 0.019 | F11: (W/ft²) | G11: =$E11*C11 -> 76.027968
A12: Building Entrance | B12: 2 building entrance (1 per 10,000 ft² footprint) | C12: 1 | D12: (count) | E12: 15 | F12: (W/ea) | G12: =E12*C12 -> 15
A13: Hardscape Ornamental Light | B13: 0.1 ft² per 1 ft² of gross building area [2019 Lighting CASE report,Table 36] | C13: =B24*0.1 -> 250.092 | D13: (ft²) | E13: 0.007 | F13: (W/ft²) | G13: =E13*C13 -> 1.750644
A14: Building façade | B14: 0.1 W per 1 ft² of facade area Façade Area = Perimeter × 0.5 × 10 ft (10 ft is the building height ) * The 0.5 factor assumes that only half of the perimeter walls are lit. -Formula ia developed based on the 2019 Outdoor Lighting CASE report | C14: =B23*0.5*B26 -> 1000 | D14: (ft²) | E14: 0.1 | F14: (W/ft²) | G14: =E14*C14 -> 100
A15: Drive up windows | B15: 1 per 1500 ft² of gross building area [2019 Lighting CASE report,Table 36] | C15: =ROUND(B24/1500,0) -> 2 | D15: (count) | E15: 30 | F15: (W/ea) | G15: =E15*C15 -> 60
A16: Outdoor dining | B16: 1 ft² per 5 ft² of gross building area [2019 Lighting CASE report,Table 36] | C16: =1/5*B24 -> 500.184 | D16: (ft²) | E16: 0.03 | F16: (W/ft²) | G16: =E16*C16 -> 15.00552
A17: Motion controlled Luminaires | G17: =G11+G10+G12+G15 -> 351.02797
A18: Non-motion-controlled Luminaires | G18: =G13+G14+G16 -> 116.75616
A19: TOTAL | G19: =G17+G18 -> 467.78413
A23: Perimeter (ft) | B23: =(50+50)*2 -> 200
A24: Total floor area (ft²) | B24: =Zones!H6 -> 2500.92
A25: Floors | B25: 1
A26: Height (ft) | B26: 10

Sheet Equipment
A1: ="Equipment - "&Prototype!A2 -> Equipment - RestaurantFastFood
A2: Space Type | B2: Plug Load Power Density (W/ft²) | C2: ReachIn Refrigerator and ReachInFreezer Power (W) - 24/7 | D2: Refrigerator Power Density (W/ft²) | E2: Gas Power Density (Btu/hr-ft²) | F2: Source
A3: =Zones!C3 -> Dining Area (Cafeteria/Fast Food) | B3: 0.5 | D3: 0.25 | F3: Others inputs: T24 2025 - Appendix 5.4A: "2022 SpaceFuncData-Input"
A4: =Zones!C4 -> Kitchen/Food Preparation Area | B4: 1.5 | C4: 590 | D4: 1.12 | E4: =17.54*2500/1250 -> 35.08 | F4: - ReachIn Refrigerator and ReachInFreezer load : [PNNL ASHRAE 90.1 2022 Fast Food prototype] - Other inputs: T24 2025 - Appendix 5.4A: "2022 SpaceFuncData-Input" Plug load density is confirmed by the findings Plug load and schedules project with CEC, 2025
A5: =Zones!C5 -> Attic
A6: *ReachIn Refrigerator and ReachInFreezer Power is based on PNNL model. It doesn’t exist in the CEC prototype model.
A7: * Gas load is very low compared to PNNL model (237.4 Btu/hr-ft2 for Kitchen)
A8: Refrigerator load will be simulated as equipment load

Sheet Schedules
A1: ="Schedules - "&Prototype!A2 -> Schedules - RestaurantFastFood
A2: Zone | B2: Schedule Category | C2: Schedule | D2: Source | E2: Type | F2: Hour
F3: 1 | G3: 2 | H3: 3 | I3: 4 | J3: 5 | K3: 6 | L3: 7 | M3: 8 | N3: 9 | O3: 10 | P3: 11 | Q3: 12 | R3: 13 | S3: 14 | T3: 15 | U3: 16 | V3: 17 | W3: 18 | X3: 19 | Y3: 20 | Z3: 21 | AA3: 22 | AB3: 23 | AC3: 24
A4: Dining | B4: Restaurant | C4: Occupancy | D4: PNNL,ASHRAE 90.1, 2022 Fast Food Restaurant prototype (It has higher occupancy rate during morning compared to T24 2022 - Appendix 5.4B) | E4: Weekday | F4: 0.05 | G4: 0 | H4: 0 | I4: 0 | J4: 0 | K4: 0.05 | L4: 0.1 | M4: 0.4 | N4: 0.4 | O4: 0.4 | P4: 0.2 | Q4: 0.5 | R4: 0.8 | S4: 0.7 | T4: 0.4 | U4: 0.2 | V4: 0.25 | W4: 0.5 | X4: 0.8 | Y4: 0.8 | Z4: 0.8 | AA4: 0.5 | AB4: 0.35 | AC4: 0.2
E5: Saturday | F5: 0.05 | G5: 0 | H5: 0 | I5: 0 | J5: 0 | K5: 0 | L5: 0.05 | M5: 0.5 | N5: 0.5 | O5: 0.4 | P5: 0.2 | Q5: 0.45 | R5: 0.5 | S5: 0.5 | T5: 0.35 | U5: 0.3 | V5: 0.3 | W5: 0.3 | X5: 0.7 | Y5: 0.9 | Z5: 0.7 | AA5: 0.65 | AB5: 0.55 | AC5: 0.35
E6: Sunday | F6: 0.05 | G6: 0 | H6: 0 | I6: 0 | J6: 0 | K6: 0 | L6: 0.05 | M6: 0.5 | N6: 0.5 | O6: 0.2 | P6: 0.2 | Q6: 0.3 | R6: 0.5 | S6: 0.5 | T6: 0.3 | U6: 0.2 | V6: 0.25 | W6: 0.35 | X6: 0.55 | Y6: 0.65 | Z6: 0.7 | AA6: 0.35 | AB6: 0.2 | AC6: 0.2
A7: =A4 -> Dining | B7: Restaurant | C7: Lights | D7: T24 2022 - Appendix 5.4B, [Restaurant] Updated based on the equipment schedule from the plug load and schedule project with CEC | E7: Weekday | F7: 0.15 | G7: 0.15 | H7: 0.15 | I7: 0.15 | J7: 0.15 | K7: 0.2 | L7: 0.3 | M7: =M10-5% -> 0.67 | N7: =N10-5% -> 0.73 | O7: =O10-5% -> 0.75 | P7: =P10-5% -> 0.85 | Q7: =Q10-5% -> 0.85 | R7: =R10-5% -> 0.85 | S7: =S10-5% -> 0.83 | T7: =T10-5% -> 0.72 | ... AB7: =AB10-5% -> 0.57 | AC7: 0.3
E8: Saturday | F8: =F11 -> 0.15 | G8: 0.15 | H8: 0.15 | I8: 0.15 | J8: 0.15 | K8: =K11 -> 0.2 | L8: 0.3 | M8: =M11-5% -> 0.67 | N8: =N11-5% -> 0.73 | O8: =O11-5% -> 0.75 | P8: =P11-5% -> 0.85 | Q8: =Q11-5% -> 0.85 | R8: =R11-5% -> 0.85 | S8: =S11-5% -> 0.83 | T8: =T11-5% -> 0.72 | ... AB8: =AB11-5% -> 0.57 | AC8: 0.3
E9: Sunday | F9: 0.2 | G9: 0.15 | H9: 0.15 | I9: 0.15 | J9: 0.15 | K9: 0.15 | L9: 0.3 | M9: =M12-5% -> 0.67 | N9: =N12-5% -> 0.73 | O9: =O12-5% -> 0.75 | P9: =P12-5% -> 0.85 | Q9: =Q12-5% -> 0.85 | R9: =R12-5% -> 0.85 | S9: =S12-5% -> 0.83 | T9: =T12-5% -> 0.72 | ... AB9: =AB12-5% -> 0.57 | AC9: 0.3
A10: =A4 -> Dining | B10: Restaurant | C10: ElecEquipment | D10: Plug load and schedules project with CEC, 2025 | E10: Weekday | F10: 0.15 | G10: 0.15 | H10: 0.15 | I10: 0.15 | J10: 0.15 | K10: 0.2 | L10: 0.3 | M10: 0.72 | N10: 0.78 | O10: 0.8 | P10: 0.9 | Q10: 0.9 | R10: 0.9 | S10: 0.88 | T10: 0.77 | U10: 0.7 | V10: 0.72 | W10: 0.8 | X10: 0.9 | Y10: 0.9 | Z10: 0.9 | AA10: 0.8 | AB10: 0.62 | AC10: 0.3
E11: Saturday | F11: 0.15 | G11: 0.15 | H11: 0.15 | I11: 0.15 | J11: 0.15 | K11: 0.2 | L11: 0.3 | M11: 0.72 | N11: 0.78 | O11: 0.8 | P11: 0.9 | Q11: 0.9 | R11: 0.9 | S11: 0.88 | T11: 0.77 | U11: 0.7 | V11: 0.72 | W11: 0.8 | X11: 0.9 | Y11: 0.9 | Z11: 0.9 | AA11: 0.8 | AB11: 0.62 | AC11: 0.3
E12: Sunday | F12: 0.2 | G12: 0.15 | H12: 0.15 | I12: 0.15 | J12: 0.15 | K12: 0.15 | L12: 0.3 | M12: 0.72 | N12: 0.78 | O12: 0.8 | P12: 0.9 | Q12: 0.9 | R12: 0.9 | S12: 0.88 | T12: 0.77 | U12: 0.7 | V12: 0.72 | W12: 0.8 | X12: 0.9 | Y12: 0.9 | Z12: 0.9 | AA12: 0.8 | AB12: 0.62 | AC12: 0.3
A13: =A4 -> Dining | B13: Restaurant | C13: HVACAvail | D13: T24 2022 - Appendix 5.4B , [Restaurant] Updated based on the adopted PNNL occupancy | E13: Weekday | F13: 1 | G13: 0 | H13: 0 | I13: 0 | J13: 1 | K13: 1 | L13: 1 | M13: 1 | N13: 1 | O13: 1 | P13: 1 | Q13: 1 | R13: 1 | S13: 1 | T13: 1 | U13: 1 | V13: 1 | W13: 1 | X13: 1 | Y13: 1 | Z13: 1 | AA13: 1 | AB13: 1 | AC13: 1
E14: Saturday | F14: 1 | G14: 0 | H14: 0 | I14: 0 | J14: 0 | K14: 1 | L14: 1 | M14: 1 | N14: 1 | O14: 1 | P14: 1 | Q14: 1 | R14: 1 | S14: 1 | T14: 1 | U14: 1 | V14: 1 | W14: 1 | X14: 1 | Y14: 1 | Z14: 1 | AA14: 1 | AB14: 1 | AC14: 1
E15: Sunday | F15: 1 | G15: 0 | H15: 0 | I15: 0 | J15: 0 | K15: 1 | L15: 1 | M15: 1 | N15: 1 | O15: 1 | P15: 1 | Q15: 1 | R15: 1 | S15: 1 | T15: 1 | U15: 1 | V15: 1 | W15: 1 | X15: 1 | Y15: 1 | Z15: 1 | AA15: 1 | AB15: 1 | AC15: 1
A16: =A7 -> Dining | B16: Restaurant | C16: ServiceHotWater | D16: T24 2022 - Appendix 5.4B, [Restaurant] Updated based on the adopted PNNL occupancy | E16: Weekday | F16: 0.2 | G16: 0 | H16: 0 | I16: 0 | J16: 0 | K16: 0.6 | L16: 0.6 | M16: 0.6 | N16: 0.55 | O16: 0.45 | P16: 0.4 | Q16: 0.45 | R16: 0.4 | S16: 0.35 | T16: 0.3 | U16: 0.3 | V16: 0.3 | W16: 0.4 | X16: 0.55 | Y16: 0.6 | Z16: 0.5 | AA16: 0.55 | AB16: 0.45 | AC16: 0.25
E17: Saturday | F17: 0.2 | G17: 0 | H17: 0 | I17: 0 | J17: 0 | K17: 0 | L17: 0.5 | M17: 0.5 | N17: 0.5 | O17: 0.5 | P17: 0.45 | Q17: 0.5 | R17: 0.5 | S17: 0.45 | T17: 0.4 | U17: 0.4 | V17: 0.35 | W17: 0.4 | X17: 0.55 | Y17: 0.55 | Z17: 0.5 | AA17: 0.55 | AB17: 0.4 | AC17: 0.3
E18: Sunday | F18: 0.25 | G18: 0 | H18: 0 | I18: 0 | J18: 0 | K18: 0 | L18: 0.5 | M18: 0.5 | N18: 0.5 | O18: 0.5 | P18: 0.5 | Q18: 0.5 | R18: 0.4 | S18: 0.4 | T18: 0.3 | U18: 0.3 | V18: 0.3 | W18: 0.4 | X18: 0.5 | Y18: 0.5 | Z18: 0.4 | AA18: 0.5 | AB18: 0.4 | AC18: 0.2
A19: =A4 -> Dining | B19: Restaurant | C19: Infiltration | D19: T24 2022 - Appendix 5.4B, [Restaurant] Updated based on the adopted PNNL occupancy | E19: Weekday | F19: 0.25 | G19: 0 | H19: 0 | I19: 1 | J19: 0.25 | K19: 0.25 | L19: 0.25 | M19: 0.25 | N19: 0.25 | O19: 0.25 | P19: 0.25 | Q19: 0.25 | R19: 0.25 | S19: 0.25 | T19: 0.25 | U19: 0.25 | V19: 0.25 | W19: 0.25 | X19: 0.25 | Y19: 0.25 | Z19: 0.25 | AA19: 0.25 | AB19: 0.25 | AC19: 0.25
E20: Saturday | F20: 0.25 | G20: 0 | H20: 0 | I20: 1 | J20: 1 | K20: 0.25 | L20: 0.25 | M20: 0.25 | N20: 0.25 | O20: 0.25 | P20: 0.25 | Q20: 0.25 | R20: 0.25 | S20: 0.25 | T20: 0.25 | U20: 0.25 | V20: 0.25 | W20: 0.25 | X20: 0.25 | Y20: 0.25 | Z20: 0.25 | AA20: 0.25 | AB20: 0.25 | AC20: 0.25
E21: Sunday | F21: 0.25 | G21: 0 | H21: 0 | I21: 1 | J21: 1 | K21: 0.25 | L21: 0.25 | M21: 0.25 | N21: 0.25 | O21: 0.25 | P21: 0.25 | Q21: 0.25 | R21: 0.25 | S21: 0.25 | T21: 0.25 | U21: 0.25 | V21: 0.25 | W21: 0.25 | X21: 0.25 | Y21: 0.25 | Z21: 0.25 | AA21: 0.25 | AB21: 0.25 | AC21: 0.25
A22: =A7 -> Dining | B22: Restaurant | C22: Refrigeration | D22: T24 2022 - Appendix 5.4B, [Restaurant] | E22: Weekday | F22: 0.9 | G22: 0.9 | H22: 0.9 | I22: 0.9 | J22: 0.9 | K22: 0.9 | L22: 0.9 | M22: 0.9 | N22: 0.9 | O22: 0.9 | P22: 0.9 | Q22: 0.9 | R22: 0.9 | S22: 0.9 | T22: 0.9 | U22: 0.9 | V22: 0.9 | W22: 0.9 | X22: 0.9 | Y22: 0.9 | Z22: 0.9 | AA22: 0.9 | AB22: 0.9 | AC22: 0.9
E23: Saturday | F23: 0.9 | G23: 0.9 | H23: 0.9 | I23: 0.9 | J23: 0.9 | K23: 0.9 | L23: 0.9 | M23: 0.9 | N23: 0.9 | O23: 0.9 | P23: 0.9 | Q23: 0.9 | R23: 0.9 | S23: 0.9 | T23: 0.9 | U23: 0.9 | V23: 0.9 | W23: 0.9 | X23: 0.9 | Y23: 0.9 | Z23: 0.9 | AA23: 0.9 | AB23: 0.9 | AC23: 0.9
E24: Sunday | F24: 0.9 | G24: 0.9 | H24: 0.9 | I24: 0.9 | J24: 0.9 | K24: 0.9 | L24: 0.9 | M24: 0.9 | N24: 0.9 | O24: 0.9 | P24: 0.9 | Q24: 0.9 | R24: 0.9 | S24: 0.9 | T24: 0.9 | U24: 0.9 | V24: 0.9 | W24: 0.9 | X24: 0.9 | Y24: 0.9 | Z24: 0.9 | AA24: 0.9 | AB24: 0.9 | AC24: 0.9
A25: =A4 -> Dining | B25: =B16 -> Restaurant | C25: HtgSetpt | D25: T24 2022 - Appendix 5.4B, [Restaurant] | E25: Weekday | F25: =IF(F13=1,Thermostat!$C$3,Thermostat!$C$4) -> 70 | G25: =IF(G13=1,Thermostat!$C$3,Thermostat!$C$4) -> 60 | H25: =IF(H13=1,Thermostat!$C$3,Thermostat!$C$4) -> 60 | I25: =IF(I13=1,Thermostat!$C$3,Thermostat!$C$4) -> 60 | J25: =IF(J13=1,Thermostat!$C$3,Thermostat!$C$4) -> 70 | K25: =IF(K13=1,Thermostat!$C$3,Thermostat!$C$4) -> 70 | L25: =IF(L13=1,Thermostat!$C$3,Thermostat!$C$4) -> 70 | M25: =IF(M13=1,Thermostat!$C$3,Thermostat!$C$4) -> 70 | ... AC25: =IF(AC13=1,Thermostat!$C$3,Thermostat!$C$4) -> 70
E26: Saturday | F26: =IF(F14=1,Thermostat!$C$3,Thermostat!$C$4) -> 70 | G26: =IF(G14=1,Thermostat!$C$3,Thermostat!$C$4) -> 60 | H26: =IF(H14=1,Thermostat!$C$3,Thermostat!$C$4) -> 60 | I26: =IF(I14=1,Thermostat!$C$3,Thermostat!$C$4) -> 60 | J26: =IF(J14=1,Thermostat!$C$3,Thermostat!$C$4) -> 60 | K26: =IF(K14=1,Thermostat!$C$3,Thermostat!$C$4) -> 70 | L26: =IF(L14=1,Thermostat!$C$3,Thermostat!$C$4) -> 70 | M26: =IF(M14=1,Thermostat!$C$3,Thermostat!$C$4) -> 70 | ... AC26: =IF(AC14=1,Thermostat!$C$3,Thermostat!$C$4) -> 70
E27: Sunday | F27: =IF(F15=1,Thermostat!$C$3,Thermostat!$C$4) -> 70 | G27: =IF(G15=1,Thermostat!$C$3,Thermostat!$C$4) -> 60 | H27: =IF(H15=1,Thermostat!$C$3,Thermostat!$C$4) -> 60 | I27: =IF(I15=1,Thermostat!$C$3,Thermostat!$C$4) -> 60 | J27: =IF(J15=1,Thermostat!$C$3,Thermostat!$C$4) -> 60 | K27: =IF(K15=1,Thermostat!$C$3,Thermostat!$C$4) -> 70 | L27: =IF(L15=1,Thermostat!$C$3,Thermostat!$C$4) -> 70 | M27: =IF(M15=1,Thermostat!$C$3,Thermostat!$C$4) -> 70 | ... AC27: =IF(AC15=1,Thermostat!$C$3,Thermostat!$C$4) -> 70
A28: =A4 -> Dining | B28: =B19 -> Restaurant | C28: ClgSetpt | D28: T24 2022 - Appendix 5.4B, [Restaurant] | E28: Weekday | F28: =IF(F13=1,Thermostat!$C$5,Thermostat!$C$6) -> 75 | G28: =IF(G13=1,Thermostat!$C$5,Thermostat!$C$6) -> 85 | H28: =IF(H13=1,Thermostat!$C$5,Thermostat!$C$6) -> 85 | I28: =IF(I13=1,Thermostat!$C$5,Thermostat!$C$6) -> 85 | J28: =IF(J13=1,Thermostat!$C$5,Thermostat!$C$6) -> 75 | K28: =IF(K13=1,Thermostat!$C$5,Thermostat!$C$6) -> 75 | L28: =IF(L13=1,Thermostat!$C$5,Thermostat!$C$6) -> 75 | M28: =IF(M13=1,Thermostat!$C$5,Thermostat!$C$6) -> 75 | ... AC28: =IF(AC13=1,Thermostat!$C$5,Thermostat!$C$6) -> 75
E29: Saturday | F29: =IF(F14=1,Thermostat!$C$5,Thermostat!$C$6) -> 75 | G29: =IF(G14=1,Thermostat!$C$5,Thermostat!$C$6) -> 85 | H29: =IF(H14=1,Thermostat!$C$5,Thermostat!$C$6) -> 85 | I29: =IF(I14=1,Thermostat!$C$5,Thermostat!$C$6) -> 85 | J29: =IF(J14=1,Thermostat!$C$5,Thermostat!$C$6) -> 85 | K29: =IF(K14=1,Thermostat!$C$5,Thermostat!$C$6) -> 75 | L29: =IF(L14=1,Thermostat!$C$5,Thermostat!$C$6) -> 75 | M29: =IF(M14=1,Thermostat!$C$5,Thermostat!$C$6) -> 75 | ... AC29: =IF(AC14=1,Thermostat!$C$5,Thermostat!$C$6) -> 75
E30: Sunday | F30: =IF(F15=1,Thermostat!$C$5,Thermostat!$C$6) -> 75 | G30: =IF(G15=1,Thermostat!$C$5,Thermostat!$C$6) -> 85 | H30: =IF(H15=1,Thermostat!$C$5,Thermostat!$C$6) -> 85 | I30: =IF(I15=1,Thermostat!$C$5,Thermostat!$C$6) -> 85 | J30: =IF(J15=1,Thermostat!$C$5,Thermostat!$C$6) -> 85 | K30: =IF(K15=1,Thermostat!$C$5,Thermostat!$C$6) -> 75 | L30: =IF(L15=1,Thermostat!$C$5,Thermostat!$C$6) -> 75 | M30: =IF(M15=1,Thermostat!$C$5,Thermostat!$C$6) -> 75 | ... AC30: =IF(AC15=1,Thermostat!$C$5,Thermostat!$C$6) -> 75
A31: Kitchen
A32: Kitchen | B32: Kitchen | C32: occupancy | D32: PNNL,ASHRAE 90.1, 2022 Fast Food Restaurant prototype (It has higher occupancy rate during morning compared to T24 2022 - Appendix 5.4B) | E32: Weekday | F32: 0.05 | G32: 0 | H32: 0 | I32: 0 | J32: 0 | K32: 0.05 | L32: 0.1 | M32: 0.4 | N32: 0.4 | O32: 0.4 | P32: 0.2 | Q32: 0.5 | R32: 0.8 | S32: 0.7 | T32: 0.4 | U32: 0.2 | V32: 0.25 | W32: 0.5 | X32: 0.8 | Y32: 0.8 | Z32: 0.8 | AA32: 0.5 | AB32: 0.35 | AC32: 0.2
E33: Saturday | F33: 0.05 | G33: 0 | H33: 0 | I33: 0 | J33: 0 | K33: 0 | L33: 0.05 | M33: 0.5 | N33: 0.5 | O33: 0.4 | P33: 0.2 | Q33: 0.45 | R33: 0.5 | S33: 0.5 | T33: 0.35 | U33: 0.3 | V33: 0.3 | W33: 0.3 | X33: 0.7 | Y33: 0.9 | Z33: 0.7 | AA33: 0.65 | AB33: 0.55 | AC33: 0.35
E34: Sunday | F34: 0.05 | G34: 0 | H34: 0 | I34: 0 | J34: 0 | K34: 0 | L34: 0.05 | M34: 0.5 | N34: 0.5 | O34: 0.2 | P34: 0.2 | Q34: 0.3 | R34: 0.5 | S34: 0.5 | T34: 0.3 | U34: 0.2 | V34: 0.25 | W34: 0.35 | X34: 0.55 | Y34: 0.65 | Z34: 0.7 | AA34: 0.35 | AB34: 0.2 | AC34: 0.2
A35: Kitchen | B35: Kitchen | C35: Lights | D35: T24 2022 - Appendix 5.4B, [Restaurant] Updated based on the equipment schedule from the plug load and schedule project with CEC | E35: Weekday | F35: 0.15 | G35: 0.15 | H35: 0.15 | I35: 0.15 | J35: 0.15 | K35: 0.2 | L35: 0.3 | M35: =M38-5% -> 0.67 | N35: =N38-5% -> 0.73 | O35: =O38-5% -> 0.75 | P35: =P38-5% -> 0.85 | Q35: =Q38-5% -> 0.85 | R35: =R38-5% -> 0.85 | S35: =S38-5% -> 0.83 | T35: =T38-5% -> 0.72 | ... AB35: =AB38-5% -> 0.57 | AC35: 0.3
E36: Saturday | F36: =F39 -> 0.15 | G36: 0.15 | H36: 0.15 | I36: 0.15 | J36: 0.15 | K36: =K39 -> 0.2 | L36: 0.3 | M36: =M39-5% -> 0.67 | N36: =N39-5% -> 0.73 | O36: =O39-5% -> 0.75 | P36: =P39-5% -> 0.85 | Q36: =Q39-5% -> 0.85 | R36: =R39-5% -> 0.85 | S36: =S39-5% -> 0.83 | T36: =T39-5% -> 0.72 | ... AB36: =AB39-5% -> 0.57 | AC36: 0.3
E37: Sunday | F37: 0.2 | G37: 0.15 | H37: 0.15 | I37: 0.15 | J37: 0.15 | K37: 0.15 | L37: 0.3 | M37: =M40-5% -> 0.67 | N37: =N40-5% -> 0.73 | O37: =O40-5% -> 0.75 | P37: =P40-5% -> 0.85 | Q37: =Q40-5% -> 0.85 | R37: =R40-5% -> 0.85 | S37: =S40-5% -> 0.83 | T37: =T40-5% -> 0.72 | ... AB37: =AB40-5% -> 0.57 | AC37: 0.3
A38: Kitchen | B38: Kitchen | C38: ElecEquipment | D38: Plug load and schedules project with CEC, 2025 | E38: Weekday | F38: 0.15 | G38: 0.15 | H38: 0.15 | I38: 0.15 | J38: 0.15 | K38: 0.2 | L38: 0.3 | M38: 0.72 | N38: 0.78 | O38: 0.8 | P38: 0.9 | Q38: 0.9 | R38: 0.9 | S38: 0.88 | T38: 0.77 | U38: 0.7 | V38: 0.72 | W38: 0.8 | X38: 0.9 | Y38: 0.9 | Z38: 0.9 | AA38: 0.8 | AB38: 0.62 | AC38: 0.3
E39: Saturday | F39: 0.15 | G39: 0.15 | H39: 0.15 | I39: 0.15 | J39: 0.15 | K39: 0.2 | L39: 0.3 | M39: 0.72 | N39: 0.78 | O39: 0.8 | P39: 0.9 | Q39: 0.9 | R39: 0.9 | S39: 0.88 | T39: 0.77 | U39: 0.7 | V39: 0.72 | W39: 0.8 | X39: 0.9 | Y39: 0.9 | Z39: 0.9 | AA39: 0.8 | AB39: 0.62 | AC39: 0.3
E40: Sunday | F40: 0.2 | G40: 0.15 | H40: 0.15 | I40: 0.15 | J40: 0.15 | K40: 0.15 | L40: 0.3 | M40: 0.72 | N40: 0.78 | O40: 0.8 | P40: 0.9 | Q40: 0.9 | R40: 0.9 | S40: 0.88 | T40: 0.77 | U40: 0.7 | V40: 0.72 | W40: 0.8 | X40: 0.9 | Y40: 0.9 | Z40: 0.9 | AA40: 0.8 | AB40: 0.62 | AC40: 0.3
...

Sheet Energy Usage
A1: ="CalBEM Energy Consumption - "&Prototype!A2 -> CalBEM Energy Consumption - RestaurantFastFood | I1: National Average (EnergyStar Portfolio Manager) | N1: CEUS Energy Consumption - Restaurant
A2: Prototype | B2: CZ | C2: CalBEM Electricity EUI (KBTU/ft²) | D2: CalBEM Gas EUI (KBTU/ft²) | E2: CalBEM Total EUI (KBTU/ft²) | F2: New Construction Electricity EUI (KBTU/ft²) | G2: New Construction Gas EUI (KBTU/ft²) | H2: New Construction Total EUI (KBTU/ft²) | I2: National Average | J2: Acceptable Range (25% Higher) | K2: Acceptable Range (25% Lower) | L2: National Average Acceptable EUI Range | N2: Prototype | O2: CZ | P2: Total Floorspace (Thousand of ft²) | Q2: CEUS 2022 Electricity EUI (kBtu/ft²) | R2: CEUS 2022 Gas EUI (kBtu/ft²) | S2: CEUS 2022 Total EUI (kBtu/ft²) | T2: Acceptable Range (25% Higher) | U2: Acceptable Range (25% Lower) | V2: CEUS 2022 Acceptable EUI Range
A3: RetailStripMall | B3: 1 | I3: 442.6 | J3: =I3*1.25 -> 553.25 | K3: =0.75*I3 -> 331.95 | L3: =J3-K3 -> 221.3 | N3: Restaurant | O3: 1 | P3: 2670.248 | Q3: 140.21338 | R3: 188.39676 | S3: =Q3+R3 -> 328.61014 | T3: =S3*1.25 -> 410.76268 | U3: =S3*0.75 -> 246.45761 | V3: =T3-U3 -> 164.30507
B4: 2 | I4: 442.6 | J4: =I4*1.25 -> 553.25 | K4: =0.75*I4 -> 331.95 | L4: =J4-K4 -> 221.3 | O4: 2 | P4: 4962.8202 | Q4: 115.43442 | R4: 178.59594 | S4: =Q4+R4 -> 294.03035 | T4: =S4*1.25 -> 367.53794 | U4: =S4*0.75 -> 220.52276 | V4: =T4-U4 -> 147.01518
B5: 3 | I5: 442.6 | J5: =I5*1.25 -> 553.25 | K5: =0.75*I5 -> 331.95 | L5: =J5-K5 -> 221.3 | O5: 3 | P5: 23016.189 | Q5: 121.68255 | R5: 177.66532 | S5: =Q5+R5 -> 299.34786 | T5: =S5*1.25 -> 374.18483 | U5: =S5*0.75 -> 224.5109 | V5: =T5-U5 -> 149.67393
B6: 4 | I6: 442.6 | J6: =I6*1.25 -> 553.25 | K6: =0.75*I6 -> 331.95 | L6: =J6-K6 -> 221.3 | O6: 4 | P6: 11906.95 | Q6: 121.67947 | R6: 177.2298 | S6: =Q6+R6 -> 298.90927 | T6: =S6*1.25 -> 373.63658 | U6: =S6*0.75 -> 224.18195 | V6: =T6-U6 -> 149.45463
B7: 5 | I7: 442.6 | J7: =I7*1.25 -> 553.25 | K7: =0.75*I7 -> 331.95 | L7: =J7-K7 -> 221.3 | O7: 5 | P7: 2232.1752 | Q7: 116.89707 | R7: 182.67998 | S7: =Q7+R7 -> 299.57705 | T7: =S7*1.25 -> 374.47131 | U7: =S7*0.75 -> 224.68278 | V7: =T7-U7 -> 149.78852
B8: 6 | I8: 442.6 | J8: =I8*1.25 -> 553.25 | K8: =0.75*I8 -> 331.95 | L8: =J8-K8 -> 221.3 | O8: 6 | P8: 19264.558 | Q8: 114.30761 | R8: 210.86262 | S8: =Q8+R8 -> 325.17023 | T8: =S8*1.25 -> 406.46278 | U8: =S8*0.75 -> 243.87767 | V8: =T8-U8 -> 162.58511
B9: 7 | I9: 442.6 | J9: =I9*1.25 -> 553.25 | K9: =0.75*I9 -> 331.95 | L9: =J9-K9 -> 221.3 | O9: 7 | P9: 11474.844 | Q9: 139.92699 | R9: 228.2706 | S9: =Q9+R9 -> 368.19759 | T9: =S9*1.25 -> 460.24699 | U9: =S9*0.75 -> 276.14819 | V9: =T9-U9 -> 184.0988
B10: 8 | I10: 442.6 | J10: =I10*1.25 -> 553.25 | K10: =0.75*I10 -> 331.95 | L10: =J10-K10 -> 221.3 | O10: 8 | P10: 29165.647 | Q10: 124.09734 | R10: 226.014 | S10: =Q10+R10 -> 350.11135 | T10: =S10*1.25 -> 437.63918 | U10: =S10*0.75 -> 262.58351 | V10: =T10-U10 -> 175.05567
B11: 9 | I11: 442.6 | J11: =I11*1.25 -> 553.25 | K11: =0.75*I11 -> 331.95 | L11: =J11-K11 -> 221.3 | O11: 9 | P11: 44906.607 | Q11: 111.94889 | R11: 217.89529 | S11: =Q11+R11 -> 329.84417 | T11: =S11*1.25 -> 412.30522 | U11: =S11*0.75 -> 247.38313 | V11: =T11-U11 -> 164.92209
B12: 10 | I12: 442.6 | J12: =I12*1.25 -> 553.25 | K12: =0.75*I12 -> 331.95 | L12: =J12-K12 -> 221.3 | O12: 10 | P12: 24025.703 | Q12: 129.08381 | R12: 231.92373 | S12: =Q12+R12 -> 361.00755 | T12: =S12*1.25 -> 451.25944 | U12: =S12*0.75 -> 270.75566 | V12: =T12-U12 -> 180.50377
B13: 11 | I13: 442.6 | J13: =I13*1.25 -> 553.25 | K13: =0.75*I13 -> 331.95 | L13: =J13-K13 -> 221.3 | O13: 11 | P13: 8514.5666 | Q13: 141.13317 | R13: 172.39688 | S13: =Q13+R13 -> 313.53005 | T13: =S13*1.25 -> 391.91256 | U13: =S13*0.75 -> 235.14753 | V13: =T13-U13 -> 156.76502
B14: 12 | I14: 442.6 | J14: =I14*1.25 -> 553.25 | K14: =0.75*I14 -> 331.95 | L14: =J14-K14 -> 221.3 | O14: 12 | P14: 37639.22 | Q14: 145.52445 | R14: 191.73774 | S14: =Q14+R14 -> 337.26219 | T14: =S14*1.25 -> 421.57774 | U14: =S14*0.75 -> 252.94665 | V14: =T14-U14 -> 168.6311
B15: 13 | I15: 442.6 | J15: =I15*1.25 -> 553.25 | K15: =0.75*I15 -> 331.95 | L15: =J15-K15 -> 221.3 | O15: 13 | P15: 12120.121 | Q15: 147.93232 | R15: 194.18501 | S15: =Q15+R15 -> 342.11732 | T15: =S15*1.25 -> 427.64665 | U15: =S15*0.75 -> 256.58799 | V15: =T15-U15 -> 171.05866
... B18: 16 | I18: 442.6 | J18: =I18*1.25 -> 553.25 | K18: =0.75*I18 -> 331.95 | L18: =J18-K18 -> 221.3 | O18: 16 | P18: 23693.285 | Q18: 127.46412 | R18: 198.83728 | S18: =Q18+R18 -> 326.3014 | T18: =S18*1.25 -> 407.87675 | U18: =S18*0.75 -> 244.72605 | V18: =T18-U18 -> 163.1507
N20: Ref: CEUS 2022 Report
N21: And converted FZ level data to CZ level
N22: Restaurants have only one category in CEUS data.
N50: Background Data [To be deleted prior to publication]
B52: Screenshot of assumption for the national average in the EnergyStar Portfolio Manager website | N52: EIA 2018: | O52: U.S. Energy Information Administration - EIA - Independent Statistics and Analysis
B53: ENERGY STAR Portfolio Manager Upgrade

Sheet Weights
A1: ="% of Floor Area per CZ and Vintage Bin - Restaurant" -> % of Floor Area per CZ and Vintage Bin - Restaurant | J1: ="% of Floor Area per CZ and Vintage Bin - Restaurant" -> % of Floor Area per CZ and Vintage Bin - Restaurant
A2: Prototype | B2: CZ | C2: Vintage Bin | J2: Prototype | K2: Vintage Bin | L2: CZ
C3: Pre-1978 | D3: 1978-1997 | E3: 1998-2007 | F3: 2008-2018 | G3: Not available | L3: 1 | M3: 2 | N3: 3 | O3: 4 | P3: 5 | Q3: 6 | R3: 7 | S3: 8 | T3: 9 | U3: 10 | V3: 11 | W3: 12 | X3: 13 | Y3: 14 | Z3: 15 | AA3: 16
