Workbook
Name nonparticipating_forecastzone_scale_factor: #REF!
Name nonparticipating_forecastzone_scale_factor: #REF!
Name nonparticipating_forecastzone_scale_factor: #REF!
Name nonparticipating_forecastzone_scale_factor: 'Energy Usage'!#REF!
Name Space_Function: Data!$A$2:$A$76

Sheet Notes
A1: Data Sources
A2: Dataset | B2: Dodge 2023
B3: Commercial End-Use Survey (CEUS) 2022 | C3: https://www.energy.ca.gov/publications/2023/2022-california-commercial-end-use-survey-ceus-final-report
B4: Commercial Buildings Energy Consumption Survey (CBECS) 2018 | C4: https://www.eia.gov/consumption/commercial/data/2018/index.php?view=microdata
B5: Comstock 2023 | C5: https://data.openei.org/s3_viewer?bucket=oedi-data-lake&prefix=nrel-pds-building-stock%2Fend-use-load-profiles-for-us-building-stock%2F2023%2Fcomstock_amy2018_release_2%2Fmetadata_and_annual_results%2Fby_state%2Fstate%3DCA%2F
A6: Prototypes | B6: California Energy Commission (CEC) Medium Retail prototype (CBECC 2022.3.1) | C6: https://bees.noresco.com/software2022.html
B7: Pacific Northwest National Laboratory (PNNL) Strip Mall Retail prototypes (90.1-2022) | C7: https://www.energycodes.gov/prototype-building-models#Commercial
B8: Database for Energy Efficient Resources (DEER) Retail prototypes (June 2023) | C8: https://github.com/sound-data/DEER-Prototypes-EnergyPlus
A10: Codes | B10: Title 24, part 6, referred to as T24 (1984, 1992,1998, 2001, 2005, 2008, 2013, 2016,2019, 2022, 2025) | C10: https://www.energy.ca.gov/publications/2025/2025-building-energy-efficiency-standards-residential-and-nonresidential | D10: 2025
C11: https://codes.iccsafe.org/codes/united-states/california | D11: 2010+
B12: American Society of Heating, Refrigerating and Air-Conditioning Engineers (ASHRAE) 90.1 (2022) | C12: https://www.ashrae.org/technical-resources/standards-and-guidelines/read-only-versions-of-ashrae-standards
B13: Code of Federal Regulations (CFR) Title 10 ( 2010) | C13: https://www.govinfo.gov/content/pkg/FR-2009-03-23/pdf/FR-2009-03-23.pdf
B14: CFR Title 10 ( 2024) | C14: https://www.govinfo.gov/content/pkg/CFR-2024-title10-vol3/pdf/CFR-2024-title10-vol3-part431-subpartF.pdf
A15: Others | B15: Alternative Calculation Method (ACM) (2022) | C15: https://www.energy.ca.gov/publications/2022/2022-nonresidential-and-multifamily-alternative-calculation-method-reference
B16: ACM (2025) | C16: https://www.energy.ca.gov/publications/2025/2025-nonresidential-and-multifamily-alternative-calculation-method-reference
B17: Nonres ACM 2022, Appendix 5.4A and Appendix 5.4B | C17: https://www.energy.ca.gov/publications/2022/2022-nonresidential-and-multifamily-alternative-calculation-method-reference
B18: 2022 Reduced infiltration Codes and Standards Enhancement (CASE) report | C18: https://title24stakeholders.com/wp-content/uploads/2020/10/2022-T24-Final-CASE-Report_Reduce-Infiltration.pdf
B19: 2019 Outdoor Lighting CASE Report | C19: https://title24stakeholders.com/wp-content/uploads/2016/10/T24-2019-CASE-Study-Results-Report-Outdoor-Sources_Final_with-Attachments.pdf
B20: PNNL 20405, 2011 | C20: https://www.pnnl.gov/main/publications/external/technical_reports/PNNL-20405.pdf
B21: Air leakage Memo, NORESCO, 2025 | C21: Infiltration_rate_report_14May2025-Short-Version.docx
B22: Yousefi, F., Athalye, R., (2025), "Determining Vintage Bins for Prototype Development: An Analysis of California Commercial Buildings," ASHRAE Annual Conference | C22: https://www.thefreelibrary.com/Determining+Vintage+Bins+for+Prototype+Development%3a+An+Analysis+of...-a0879271125
B23: Proposed Updates to Equipment Power Densities and Building Schedules for the 2028 Energy Code, referred to as "Plug load and schedules project with CEC, 2025" (Docket Number =25-BSTD-03 & TN=265693) | C23: https://efiling.energy.ca.gov/GetDocument.aspx?tn=265693&DocumentContentId=102545
B24: ENERGY STAR certified commercial water heaters | C24: https://www.energystar.gov/productfinder/product/certified-commercial-water-heaters/results?fuel_filter=Gas&markets_filter=United+States
B25: Grainger gas tank water heaters (sizes below commercial, e.g. 30–75 kBtu/h) | C25: https://www.grainger.com/category/plumbing/water-heaters/gas-tank-water-heaters
B26: Grainger electric tank water heaters | C26: https://www.grainger.com/category/plumbing/water-heaters/electric-tank-water-heaters
A29: Notes
A30: This prototype represents a partitioned strip mall typology for retail up to approximately 100,000 ft².

Sheet Prototype
A1: NORESCO, Updated September 2026
A2: RetailStripMall
A3: Characteristic | B3: Value | C3: Data Sources
A4: Building Type | B4: Small Retail
A5: Building Category | B5: Nonresidential
A6: Version | B6: v2-0
A7: Vintages | B7: 4 Vintages: Pre-1978 , 1978-1997 ,1998-2007 , 2008-2018 New Construction (2019+) | C7: Based on the vintage bin analysis. A summary of the findings is presented in the following paper, with a link provided in the Notes tab: Yousefi, F., Athalye, R. (2025). “Determining Vintage Bins for Prototype Development: An Analysis of California Commercial Buildings.” ASHRAE Annual Conference.
A8: Shape | C8: Geometry of CBECC Retail Strip Mall prototype was adapted
A9: Total Floor Area (ft²) | B9: 9,375 (125 ft x 75 ft) | C9: Geometry of CBECC Retail Strip Mall prototype was adapted
A10: Aspect Ratio | B10: 1.67 overall (0.33 for small store & 0.67 for large store) | C10: Geometry of CBECC Retail Strip Mall prototype was adapted
A11: Number of Floors | B11: 1
A12: Roof type | B12: Roof membrane+Roof insulation+metal decking
A13: WWR | B13: 0.0824 | C13: Geometry of CBECC Retail Strip Mall prototype was adapted
A14: Shading Geometry | B14: none
A15: Floor to floor height (feet) | B15: N/A
A16: Floor to ceiling height (feet) | B16: 17 | C16: Geometry of CBECC Retail Strip Mall prototype was adapted
A17: Glazing sill height (feet) | B17: 3.0 ft (top of the window is 8 ft high) | C17: Geometry of CBECC Retail Strip Mall prototype was adapted
A27: Existing Retail Prototypes
B33: CEC: Retail_Large | C33: CPUC: Retail_Multistory Large (Rt3) | D33: CPUC: Retail_Single-Story Large (RtL)
A34: Large size prototype
A35: Total floor area (ft²) | B35: 240000 | C35: =3*40000 -> 120000 | D35: 130502
B38: CEC: Retail_Medium | C38: PNNL : Retail_Stand alone | D38: PNNL: Retail_Stripmall | F38: CPUC: Retail_Grocery
A39: Medium size prototype | B39: zoning same as PNNL Stand alone with more skylight
A40: Total floor area (ft²) | B40: 24692 | C40: 24692 | D40: 22500 | F40: 49997
B43: CEC: Retail_Stripmall (Mixed use) | C43: CPUC: Retail_Small (RtS)
A44: Small size prototype
A45: Total floor area (ft²) | B45: 9375 | C45: 8001

Sheet Zones
A1: ="Proposed Layout - "&Prototype!A2 -> Proposed Layout - RetailStripMall
A2: Building | B2: Space/Thermal Zone | C2: Space Type [Primarily from: T24, 2022 Appendix 5.4A] - See Notes column | D2: Building | E2: HVAC System Name (NC) | F2: HVAC System Name (Existing) | G2: Schedule Category | H2: Conditioned (Y/N) | I2: Area Fraction | J2: Area (ft²) | K2: Volume (ft³) | L2: Multipliers | M2: Number of People | N2: People (Persons/1,000 ft²) [T24, 2025,Table 120.1-A] | O2: Notes | Q2: Spaces and Zoning layout
A3: RetailStripMall | B3: LG_Store_1 | C3: Retail Sales Area (Retail Merchandise Sales) | D3: RetailStripMall | E3: SZVAVHP_LG_Store | F3: SZAC_LG_Store | G3: Retail | H3: Y | I3: =J3/$J$7 -> 0.40000689 | J3: 3750.0386 | K3: 63750.042 | L3: 1 | M3: =N3*J3/1000 -> 63.750656 | N3: 17
A4: RetailStripMall | B4: SM_Store_1 | C4: Retail Sales Area (Retail Merchandise Sales) | D4: RetailStripMall | E4: SZVAVHP_SM_Store1 | F4: SZAC_SM_Store1 | G4: Retail | H4: Y | I4: =J4/$J$7 -> 0.1999977 | J4: 1874.9655 | K4: 31875.021 | L4: 1 | M4: =N4*J4/1000 -> 31.874413 | N4: 17
A5: RetailStripMall | B5: SM_Store_2 | C5: Retail Sales Area (Retail Merchandise Sales) | D5: RetailStripMall | E5: SZVAVHP_SM_Store2 | F5: SZAC_SM_Store2 | G5: Retail | H5: Y | I5: =J5/$J$7 -> 0.1999977 | J5: 1874.9655 | K5: 31875.021 | L5: 1 | M5: =N5*J5/1000 -> 31.874413 | N5: 17
A6: RetailStripMall | B6: SM_Store_3 | C6: Retail Sales Area (Retail Merchandise Sales) | D6: RetailStripMall | E6: SZVAVHP_SM_Store3 | F6: SZAC_SM_Store3 | G6: Retail | H6: Y | I6: =J6/$J$7 -> 0.1999977 | J6: 1874.9655 | K6: 31875.021 | L6: 1 | M6: =N6*J6/1000 -> 31.874413 | N6: 17
A7: Total (1 Building) | B7: Total (4 Space)s | C7: Total (1 Space type) | D7: Total (1 Building) | E7: Total (4 HVAC systems) | F7: Total (4 HVAC systems) | G7: Total (1 Schedule category) | H7: Total (4 Conditioned zones) | I7: =SUM(I3:I6) -> 1 | J7: =SUM(J3:J6) -> 9374.9351 | K7: =SUM(K3:K6) -> 159375.11 | M7: =SUM(M3:M6) -> 159.3739
B9: Plan from CBECC 2022, Retail_Stripmall prototype
B19: Background Data [To be deleted prior to publication]
B21: Floorspace-Types-30Oct2024
B22: Retail (CEUS 2022, statewide %)
B23: Conditioned | C23: Unconditioned | F23: Ventilated
B24: 0.8262 | C24: 0.1737 | F24: 0.8344
C25: Likely storage in larger Retail (see Medium/Standalone)

Sheet Envelope
A1: ="Envelope - "&Prototype!A2 -> Envelope - RetailStripMall
A2: Element | B2: Prototype | C2: Assembly Type | D2: Construction | E2: Thermal Properties | F2: Vintage | G2: Selected T24 | H2: Note | I2: CZ1 | J2: CZ2 | K2: CZ3 | L2: CZ4 | M2: CZ5 | N2: CZ6 | O2: CZ7 | P2: CZ8 | Q2: CZ9 | R2: CZ10 | S2: CZ11 | T2: CZ12 | U2: CZ13 | V2: CZ14 | W2: CZ15 | X2: CZ16
A3: External Wall | B3: RetailStripmall | C3: ExtWall_MetalFramed_NonRes | D3: Metal framed wall: Metal-frame walls + insulation + Gypsum board | E3: U-factor IP | F3: Pre 1978 | G3: N/A | H3: ASHRAE 90.1, 2022, Table A3.3.3.1, 3.5", R-0 | I3: 0.352 | J3: 0.352 | K3: 0.352 | L3: 0.352 | M3: 0.352 | N3: 0.352 | O3: 0.352 | P3: 0.352 | Q3: 0.352 | R3: 0.352 | S3: 0.352 | T3: 0.352 | U3: 0.352 | V3: 0.352 | W3: 0.352 | X3: 0.352
F4: 1978-1997 | G4: 1986 | H4: Heat Capacity was considered 10.0-14.99 (Btu/F-ft²) | I4: 0.15082956 | J4: 0.15748031 | K4: 0.15748031 | L4: 0.14367816 | M4: 0.14367816 | N4: 0.21645022 | O4: 0.21645022 | P4: 0.21645022 | Q4: 0.21645022 | R4: 0.21645022 | S4: 0.18621974 | T4: 0.18621974 | U4: 0.18621974 | V4: 0.15873016 | W4: 0.15873016 | X4: 0.15082956
F5: 1998-2007 | G5: 2001 | H5: TABLE 1-H-NonRes Bldgs | I5: 0.182 | J5: 0.182 | K5: 0.189 | L5: 0.189 | M5: 0.189 | N5: 0.189 | O5: 0.189 | P5: 0.189 | Q5: 0.189 | R5: 0.182 | S5: 0.182 | T5: 0.182 | U5: 0.182 | V5: 0.182 | W5: 0.182 | X5: 0.182
F6: 2008-2018 | G6: 2013 | H6: TABLE 140.3-B-NonRes Bldgs | I6: 0.098 | J6: 0.062 | K6: 0.082 | L6: 0.062 | M6: 0.062 | N6: 0.098 | O6: 0.098 | P6: 0.062 | Q6: 0.062 | R6: 0.062 | S6: 0.062 | T6: 0.062 | U6: 0.062 | V6: 0.062 | W6: 0.062 | X6: 0.062
F7: 2019+ | G7: 2025 | H7: TABLE 140.3-B-NonRes Bldgs | I7: 0.06 | J7: 0.055 | K7: 0.071 | L7: 0.055 | M7: 0.055 | N7: 0.06 | O7: 0.06 | P7: 0.055 | Q7: 0.055 | R7: 0.055 | S7: 0.055 | T7: 0.055 | U7: 0.055 | V7: 0.055 | W7: 0.055 | X7: 0.055
A8: Roof | B8: RetailStripmall | C8: FlatRoof_WoodFramedAndOther_NonRes | D8: Metal deck roof: Roof membrane+roof insulation+metal decking | E8: U-factor IP | F8: Pre 1978 | G8: N/A | H8: Considering 30 years for roof/ insulation replacement. | I8: 0.057 | J8: 0.057 | K8: 0.057 | L8: 0.057 | M8: 0.057 | N8: 0.078 | O8: 0.078 | P8: 0.078 | Q8: 0.078 | R8: 0.078 | S8: 0.057 | T8: 0.057 | U8: 0.057 | V8: 0.057 | W8: 0.057 | X8: 0.057
F9: 1978-1997 | G9: 1992 | I9: 0.057 | J9: 0.057 | K9: 0.057 | L9: 0.057 | M9: 0.057 | N9: 0.078 | O9: 0.078 | P9: 0.078 | Q9: 0.078 | R9: 0.078 | S9: 0.057 | T9: 0.057 | U9: 0.057 | V9: 0.057 | W9: 0.057 | X9: 0.057
F10: 1998-2007 | G10: 2001 | H10: Table 1-H | I10: 0.057 | J10: 0.057 | K10: 0.057 | L10: 0.057 | M10: 0.057 | N10: 0.078 | O10: 0.078 | P10: 0.078 | Q10: 0.078 | R10: 0.057 | S10: 0.057 | T10: 0.057 | U10: 0.057 | V10: 0.057 | W10: 0.057 | X10: 0.057
F11: 2008-2018 | G11: 2013 | H11: Table 140.3-B | I11: 0.049 | J11: 0.039 | K11: 0.039 | L11: 0.039 | M11: 0.049 | N11: 0.075 | O11: 0.067 | P11: 0.067 | Q11: 0.039 | R11: 0.039 | S11: 0.039 | T11: 0.039 | U11: 0.039 | V11: 0.039 | W11: 0.039 | X11: 0.039
F12: 2019+ | G12: 2025 | H12: Table 140.3-B | I12: 0.028 | J12: 0.028 | K12: 0.028 | L12: 0.028 | M12: 0.028 | N12: 0.047 | O12: 0.047 | P12: 0.047 | Q12: 0.028 | R12: 0.028 | S12: 0.028 | T12: 0.028 | U12: 0.028 | V12: 0.028 | W12: 0.028 | X12: 0.028
A13: Windows | B13: RetailStripmall | C13: FixedWindow_NonRes | D13: CBECS 2018 shows that ~ 50 % of retail that were built before 2000 are single pane | E13: U-factor IP | F13: Pre 1978 | G13: N/A | H13: 2021 ASHRAE Handbook of Fundamentals - Section 15.9 Table 4 for single pane & T24, 2013 Table 140.3-B for double pane (50%-50%) | I13: =0.5*1.12+0.5*I16 -> 0.74 | J13: =0.5*1.12+0.5*J16 -> 0.74 | K13: =0.5*1.12+0.5*K16 -> 0.74 | L13: =0.5*1.12+0.5*L16 -> 0.74 | M13: =0.5*1.12+0.5*M16 -> 0.74 | N13: =0.5*1.12+0.5*N16 -> 0.74 | O13: =0.5*1.12+0.5*O16 -> 0.74 | P13: =0.5*1.12+0.5*P16 -> 0.74 | ... X13: =0.5*1.12+0.5*X16 -> 0.74
F14: 1978-1997 | G14: N/A | I14: =I13 -> 0.74 | J14: =J13 -> 0.74 | K14: =K13 -> 0.74 | L14: =L13 -> 0.74 | M14: =M13 -> 0.74 | N14: =N13 -> 0.74 | O14: =O13 -> 0.74 | P14: =P13 -> 0.74 | ... X14: =X13 -> 0.74
D15: Double pane | F15: 1998-2007 | G15: 2001 | H15: Table 1-H | I15: 0.49 | J15: 0.49 | K15: 0.81 | L15: 0.81 | M15: 0.81 | N15: 0.81 | O15: 0.81 | P15: 0.81 | Q15: 0.81 | R15: 0.49 | S15: 0.49 | T15: 0.49 | U15: 0.49 | V15: 0.49 | W15: 0.49 | X15: 0.49
F16: 2008-2018 | G16: 2013 | H16: Table 140.3-B | I16: 0.36 | J16: 0.36 | K16: 0.36 | L16: 0.36 | M16: 0.36 | N16: 0.36 | O16: 0.36 | P16: 0.36 | Q16: 0.36 | R16: 0.36 | S16: 0.36 | T16: 0.36 | U16: 0.36 | V16: 0.36 | W16: 0.36 | X16: 0.36
F17: 2019+ | G17: 2025 | H17: Table 140.3-B | I17: 0.36 | J17: 0.36 | K17: 0.36 | L17: 0.36 | M17: 0.36 | N17: 0.36 | O17: 0.36 | P17: 0.36 | Q17: 0.34 | R17: 0.36 | S17: 0.34 | T17: 0.34 | U17: 0.34 | V17: 0.34 | W17: 0.34 | X17: 0.36
B18: RetailStripmall | C18: FixedWindow_NonRes | D18: CBECS 2018 shows that ~ 50 % of retail that were built before 2000 are single pane | E18: SHGC | F18: Pre 1978 | G18: N/A | H18: 2021 ASHRAE Handbook of Fundamentals - Section 15.22 Table 10 for single pane & T24, 2013 Table 140.3-B for double pane (50%-50%) | I18: =0.79*0.5+I21*0.5 -> 0.52 | J18: =0.79*0.5+J21*0.5 -> 0.52 | K18: =0.79*0.5+K21*0.5 -> 0.52 | L18: =0.79*0.5+L21*0.5 -> 0.52 | M18: =0.79*0.5+M21*0.5 -> 0.52 | N18: =0.79*0.5+N21*0.5 -> 0.52 | O18: =0.79*0.5+O21*0.5 -> 0.52 | P18: =0.79*0.5+P21*0.5 -> 0.52 | ... X18: =0.79*0.5+X21*0.5 -> 0.52
F19: 1978-1997 | G19: N/A | I19: =I18 -> 0.52 | J19: =J18 -> 0.52 | K19: =K18 -> 0.52 | L19: =L18 -> 0.52 | M19: =M18 -> 0.52 | N19: =N18 -> 0.52 | O19: =O18 -> 0.52 | P19: =P18 -> 0.52 | ... X19: =X18 -> 0.52
D20: Double pane | F20: 1998-2007 | G20: 2001 | H20: Table 1-H (Non north 0-10%) | I20: 0.49 | J20: 0.47 | K20: 0.61 | L20: 0.61 | M20: 0.61 | N20: 0.61 | O20: 0.61 | P20: 0.61 | Q20: 0.61 | R20: 0.47 | S20: 0.47 | T20: 0.47 | U20: 0.47 | V20: 0.46 | W20: 0.46 | X20: 0.49
F21: 2008-2018 | G21: 2013 | H21: Table 140.3-B | I21: 0.25 | J21: 0.25 | K21: 0.25 | L21: 0.25 | M21: 0.25 | N21: 0.25 | O21: 0.25 | P21: 0.25 | Q21: 0.25 | R21: 0.25 | S21: 0.25 | T21: 0.25 | U21: 0.25 | V21: 0.25 | W21: 0.25 | X21: 0.25
F22: 2019+ | G22: 2025 | H22: Table 140.3-B | I22: 0.25 | J22: 0.25 | K22: 0.25 | L22: 0.25 | M22: 0.25 | N22: 0.25 | O22: 0.25 | P22: 0.25 | Q22: 0.22 | R22: 0.25 | S22: 0.22 | T22: 0.22 | U22: 0.22 | V22: 0.22 | W22: 0.22 | X22: 0.25
C24: Infiltration
D25: Building | E25: Zones | F25: Vintage | G25: I_75 (cfm/ft²) 6-sdied Infiltration rate @ 75 pa | H25: Note | I25: I-design (cfm/ft²) (4-sided Infiltration rate at normal pressure) (Design flow rate approach and Flow/Exterior Wall Area calculation method)
C26: Infiltration | D26: RetailStripMall | F26: Pre 1978 | G26: 1.1 | H26: 2022 CASE report (Table 38) | I26: =(G26*0.112)*#REF! -> #REF! | Z26: Floor or roof area (ft2) | AA26: =Zones!J7 -> 9374.9351
F27: 1978-1997 | G27: 1.1 | H27: 2022 CASE report (Table 38) | I27: =(G27*0.112)*#REF! -> #REF! | Z27: Walls area (ft2) | AA27: =(125+75)*2*17 -> 6800
F28: 1998-2007 | G28: 1.1 | H28: 2022 CASE report (Table 38) | I28: =(G28*0.112)*#REF! -> #REF! | Z28: Building 4 sided area (ft2) | AA28: =AA27 -> 6800
F29: 2008-2018 | G29: 1 | H29: 2022 CASE report (Table 38) & T24, 2008-2016 (TABLE 140.3-B) | I29: =(G29*0.112)*#REF! -> #REF! | Z29: Building 6 sided area (ft2) | AA29: =AA27+2*AA26 -> 25549.87
F30: 2019+ | G30: 0.6 (barrier in all CZ) | H30: 2022 CASE report (Table 38) & T24, 2025 (TABLE 140.3-B) | I30: =(0.6*0.112)*#REF! -> #REF!
E31: Source: Title 24 air barrier requirements (all editions) and the standardized infiltration rate reported in the 2022 CASE report and Dodge 2023 data
E32: Air Leakage Memo: | G32: Infiltration_rate_report_14May2025-Short-Version.docx

Sheet HVAC System
A1: ="HVAC system - "&Prototype!A2 -> HVAC system - RetailStripMall
A2: Vintage | B2: Heating | C2: Cooling | D2: Air Distribution | E2: Other systems | F2: Source
A3: Existing | B3: PSZAC (furnace) | C3: PSZAC (DX cooling) | D3: PSZAC | E3: OA mixing Economizer for Vintage 3 and 4 | F3: CEUS 2022
A4: New Construction | B4: SZVAVHP | C4: SZVAVHP | D4: PSZVAVHP | E4: OA mixing Economizer | F4: Title 24, 2025, Engineering judgement
A8: Efficiency of HVAC System (Efficiency is capacity-dependent. The following table provides a general estimate of system efficiency based on preliminary simulations in one climate zone, or assuming cooling load based on rule of thumb)
A9: Vintage | B9: Upgrade year | C9: Heating | D9: Cooling | E9: Source
A10: Pre 1978 | B10: 2008 | C10: Thermal Efficiency of 80% | D10: SEER=13.0 for <65 kBtu/h EER 10.1 for 65-135 kBtu/h EER 9.5 for 135-240 kBtu/h EER 9.3 for 240-760 kBtu/h | E10: T24, Table 112-A (2008) 10 CFR § 431.97, Table 1 (2008) California Title 20 Appliance Efficiency Regulations, Table E-4, Standards for Gas- and Oil-Fired Central Furnaces (2008)
A11: 1978-1997
A12: 1998-2007
A13: 2008-2018 | B13: 2013 | C13: Thermal Efficiency of 80%; | D13: SEER 13 for <65 kBtu/h EER 11.0 for 65-135 kBtu/h EER 10.8 for 135-240 kBtu/h EER 9.8 for 240-760 kBtu/h | E13: T24 Tables 110.2-A, 110.2-J (2013) 10 CFR, § 431.97, Table 1 (2013)
A14: New Construction | B14: 2025 | C14: HSPF 8.0 for <65 kBtu/h COP 3.4 for 65-135 kBtu/h COP 3.3 for 135-240 kBtu/h COP 3.2 for >240 kBtu/h | D14: SEER 14 for <65 kBtu/h EER 10.8, IEER 13.9 for 65-135 kBtu/h EER 10.4, IEER = 13.3 135-240 kBtu/h EER 9.3, IEER=12.3 for >240 kBtu/h | E14: 10 CFR § 431.97(b) Table 1 (2025) Title 20 Appliance Efficiency Regulations, Section 1605.1, Table C-5 (2025) T24, Table 110.2-B (2025)
A18: Fan Power
A19: Vintage | B19: Approach | C19: System | D19: Total Static Pressure (TSP) (in w.c.) | E19: Fan Efficiency [ACM 2025] | F19: Motor Efficiency | G19: Fan Power Index (W/cfm) | H19: Data Source | I19: Note
A20: Existing | B20: PNNL 90.1-2011, TSP | C20: CAV < 7,437 cfm | D20: 2.5 | E20: 0.65 | F20: ASHRAE 90.1, 2004, Table 10.8 * | H20: Fan power formula: PNNL 20405, 2010, section 5.2.2.5 TSP and fan efficiecncy: PNNL 20405, 2010, Table 5.11, 90.1-04ac values Motor and drive efficiency: ASHRAE 90.1, 2004, Table 10.8
C21: CAV >= 7,437 cfm | D21: 4.09
A22: Brake horsepower (bhp) = (Supply cfm × TSP in w.c.) / (6356 × fan efficiency)
A23: Fan power (w/cfm) = (bhp × 746) / ( supply cfm × motor efficiency )
A24: New Construction | B24: ACM 2025 | C24: SZVAVHP (System 7b), tenant unit ≤5,000 cfm | D24: TSP = fan power × motor efficiency × fan efficiency × 6356 / 746 | E24: 0.65 | F24: 2025 ACM Table 12 ** | G24: 0.744 | H24: Fan power index: [ACM 2025, Table 13] Motor efficiency: [ACM 2025, Table 12]
C25: SZVAVHP (System 7b), >5,000 and ≤10,000 cfm | D25: TSP = fan power × motor efficiency × fan efficiency × 6356 / 746 | G25: 0.72
A27: * According to PNNL 20405 section 5.2.2.5, the full-load efficiency of the motor serving the fan is taken from ASHRAE 90.1, 2004, Table 10.8, based on motor nameplate and assuming enclosed motors operating at 1,800 rotations per minute (rpm) Motor nameplate size (bhp) = brake horsepower (bhp) × 1.1 ( using a 10% oversizing factor)
A28: ** The full‑load efficiency of the motor serving the fan is taken from ACM 2025 Table 12 based on the cfm of the fan. Brake horsepower (bhp) = (Supply cfm from sizing run × fan power in W/cfm) / 746. Note: Strip-mall packaged SZVAVHP. ACM System 7b ≤5,000 cfm. Note: ACM System 7b mid bin, if a tenant unit is above 5,000 cfm.
A42: Background Data [To be deleted prior to publication]

Sheet Ventilation
A1: ="Outdoor Airflow Rate - "&Prototype!A2 -> Outdoor Airflow Rate - RetailStripMall
A2: Space/Thermal Zone | B2: Number of People | C2: Floor Area (ft²) | D2: cfm/person [T24, 2025, Equation 120.1-F and Table 120.1-A] | E2: cfm/ft² [T24, 2025, Equation 120.1-F and Table 120.1-A] | F2: Required Exhaust Rate [T24, 2025, Table 120.1-B – minimum exhaust rates] | G2: Total cfm Driven by People | H2: Total cfm Driven by Area | I2: Total cfm Driven by Exhaust | J2: Total cfm | K2: Notes
A3: =Zones!B3 -> LG_Store_1 | B3: =Zones!M3 -> 63.750656 | C3: =Zones!J3 -> 3750.0386 | D3: 15 | E3: 0.2 | F3: 2* 25/50 per unit | G3: =D3*B3 -> 956.25984 | H3: =E3*C3 -> 750.00772 | I3: =2*25 -> 50 | J3: =MAX(G3:I3) -> 956.25984 | K3: Although the restroom is not simulated as a separate zone, its exhaust rate and fan load are included in the model.
A4: =Zones!B4 -> SM_Store_1 | B4: =Zones!M4 -> 31.874413 | C4: =Zones!J4 -> 1874.9655 | D4: 15 | E4: 0.2 | G4: =D4*B4 -> 478.1162 | H4: =E4*C4 -> 374.9931 | I4: =F4*C4 -> 0 | J4: =MAX(G4:I4) -> 478.1162
A5: =Zones!B5 -> SM_Store_2 | B5: =Zones!M5 -> 31.874413 | C5: =Zones!J5 -> 1874.9655 | D5: 15 | E5: 0.2 | G5: =D5*B5 -> 478.1162 | H5: =E5*C5 -> 374.9931 | I5: =F5*C5 -> 0 | J5: =MAX(G5:I5) -> 478.1162
A6: =Zones!B6 -> SM_Store_3 | B6: =Zones!M6 -> 31.874413 | C6: =Zones!J6 -> 1874.9655 | D6: 15 | E6: 0.2 | G6: =D6*B6 -> 478.1162 | H6: =E6*C6 -> 374.9931 | I6: =F6*C6 -> 0 | J6: =MAX(G6:I6) -> 478.1162
J7: =SUM(J3:J6) -> 2390.6084
A12: Background Data [To be deleted prior to publication]

Sheet Thermostat
A1: ="Thermostat Setpoints - "&Prototype!A2 -> Thermostat Setpoints - RetailStripMall
A2: Setpoint | B2: CZ1 | C2: CZ2 | D2: CZ3 | E2: CZ4 | F2: CZ5 | G2: CZ6 | H2: CZ7 | I2: CZ8 | J2: CZ9 | K2: CZ10 | L2: CZ11 | M2: CZ12 | N2: CZ13 | O2: CZ14 | P2: CZ15 | Q2: CZ16 | R2: Source
A3: Heating Setpoint (F) | B3: 70 | C3: 70 | D3: 70 | E3: 70 | F3: 70 | G3: 70 | H3: 70 | I3: 70 | J3: 70 | K3: 70 | L3: 70 | M3: 70 | N3: 70 | O3: 70 | P3: 70 | Q3: 70 | R3: T24 2022 - Appendix 5.4B
A4: Heating Setback (F) | B4: 60 | C4: 60 | D4: 60 | E4: 60 | F4: 60 | G4: 60 | H4: 60 | I4: 60 | J4: 60 | K4: 60 | L4: 60 | M4: 60 | N4: 60 | O4: 60 | P4: 60 | Q4: 60
A5: Cooling Setpoint (F) | B5: 75 | C5: 75 | D5: 75 | E5: 75 | F5: 75 | G5: 75 | H5: 75 | I5: 75 | J5: 75 | K5: 75 | L5: 75 | M5: 75 | N5: 75 | O5: 75 | P5: 75 | Q5: 75
A6: Cooling Setback (F) | B6: 85 | C6: 85 | D6: 85 | E6: 85 | F6: 85 | G6: 85 | H6: 85 | I6: 85 | J6: 85 | K6: 85 | L6: 85 | M6: 85 | N6: 85 | O6: 85 | P6: 85 | Q6: 85

Sheet Water Heater
A1: ="Water Heater - "&Prototype!A2 -> Water Heater - RetailStripMall
A2: Vintage | B2: WH Type | C2: Efficiency | D2: Number of WH | E2: Tank Volume (gal) | F2: Tank Loss | G2: Source
A3: Existing | B3: Electric | C3: 1 | D3: 1 | E3: See table below for CZ-specific values: Climate Zone Water Heater Sizing and Loss Coefficients, Storage Volume column (col F) | F3: See table below: Climate Zone Water Heater Sizing and Loss Coefficients, Standby Loss column (col G) | G3: See table below for sources: Climate Zone Water Heater Sizing and Loss Coefficients
A4: New Construction | B4: Electric | C4: 1 | D4: 1 | E4: See table below for CZ-specific values: Climate Zone Water Heater Sizing and Loss Coefficients, Storage Volume column (col F) | F4: See table below: Climate Zone Water Heater Sizing and Loss Coefficients, Standby Loss column (col G) | G4: See table below for sources: Climate Zone Water Heater Sizing and Loss Coefficients
A6: Peak Hot Water Consumption
A7: Space Name | B7: Baseline WH Type [CEUS 2022] | C7: Total Area (ft²) | D7: Number of People | E7: Hot Water Usage Specification (gal/hr per person) [T24, 2022, Appendix 5.4A , sheet: "2022 SpaceFuncData-Input"] | F7: Peak Hot Water Usage (gal/hr) | G7: Peak Hot Water Usage (gal/min) | H7: Note
A8: =Zones!B3 -> LG_Store_1 | B8: Electric | C8: =Zones!J3 -> 3750.0386 | D8: =Zones!M3 -> 63.750656 | E8: 0.18 | F8: =E8*D8 -> 11.475118 | G8: =F8/60 -> 0.19125197 | H8: For space types marked with an asterisk (the ‘*’ symbol), the water‑heater type is listed as electric in Appendix 5.4A, sheet ‘2022 SpaceFuncData‑Input.’ However, we modified the value based on CEUS data, which indicates that gas is the primary fuel type.
A9: =Zones!B4 -> SM_Store_1 | B9: Electric | C9: =Zones!J4 -> 1874.9655 | D9: =Zones!M4 -> 31.874413 | E9: 0.18 | F9: =E9*D9 -> 5.7373944 | G9: =F9/60 -> 0.09562324
A10: =Zones!B5 -> SM_Store_2 | B10: Electric | C10: =Zones!J5 -> 1874.9655 | D10: =Zones!M5 -> 31.874413 | E10: 0.18 | F10: =E10*D10 -> 5.7373944 | G10: =F10/60 -> 0.09562324
A11: =Zones!B6 -> SM_Store_3 | B11: Electric | C11: =Zones!J6 -> 1874.9655 | D11: =Zones!M6 -> 31.874413 | E11: 0.18 | F11: =E11*D11 -> 5.7373944 | G11: =F11/60 -> 0.09562324
A12: Total | B12: Gas storage | F12: =_xlfn.LET( _xlpm.g,SUMIF($B$8:$B$11,"Gas*",$F$8:$F$11), _xlpm.e,SUMIF($B$8:$B$11,"Electric*",$F$8:$F$11), IF(AND(_xlpm.g>0,_xlpm.e>0),_xlpm.g,IF(_xlpm.g>0,MAX(75,_xlpm.g),0))) -> 0 | H12: Minimum peak hot water usage is 75 gal according to ACM 2025
A13: Total | B13: Electric resistance | F13: =_xlfn.LET( _xlpm.g,SUMIF($B$8:$B$11,"Gas*",$F$8:$F$11), _xlpm.e,SUMIF($B$8:$B$11,"Electric*",$F$8:$F$11), IF(AND(_xlpm.g>0,_xlpm.e>0),_xlpm.e,IF(_xlpm.e>0,MAX(75,_xlpm.e),0))) -> 75
A17: Design supply temperature (°F) | B17: 135 | C17: CEC-400-2022-009-CMF-REV2-AP5.4B
A18: WH system factor | B18: 0.6 | C18: 2025 ACM §5.9.2 Rated Capacity
A19: Water mass conversion (lb/gal) | B19: 8.2877 | C19: 2025 ACM §5.9.2 Rated Capacity
A20: Reheat multiplier | B20: 0.4 | C20: 2025 ACM §5.9.2 Storage Volume
A21: Climate Zone Water Heater Sizing and Loss Coefficients (Individual WH)
A22: Climate Zone | B22: Minimum Monthly Mains Temp (°F) [T24 2022 - Appendix 5.4B] | C22: Heat Output (Btu/hr) [ACM, 2025, 5.9.2: Rated capacity section] | D22: WH Capacity (Btu/hr) [ACM, 2025, 5.9.2: Rated capacity section] | E22: Required Energy Input (Btu/hr) | F22: Storage Volume (gal) | G22: Standby Loss [Title 20, §1605.1 Table F-4; Appendix B: Water Heating Calculation Method] | I22: Off/On Cycle Loss Coefficient to Ambient Temp | K22: Source/Note
A23: CZ01 | B23: 47.9 | C23: =$F$13*($B$17-B23)*$B$19 -> 54139.4 | D23: =C23*$B$18 -> 32483.64 | E23: =_xlfn.LET(_xlpm.x,_xlfn.XLOOKUP(D23,$D$44:$D$58,$D$44:$D$58,"",1),IF(_xlpm.x="",ROUNDUP(D23,0),_xlpm.x)) -> 34121 | F23: =_xlfn.LET(_xlpm.v,MAX(30,$F$13*$B$20),_xlpm.x,_xlfn.XLOOKUP(_xlpm.v,$G$44:$G$58,$G$44:$G$58,"",1),IF(_xlpm.x="",ROUNDUP(_xlpm.v,0),_xlpm.x)) -> 30 | G23: =0.3+27/F23 -> 1.2 | H23: =IF($F$13>0,"%/hr","Btu/hr") -> %/hr | I23: =0.0834*G23*F23 -> 3.0024 | J23: Btu/h·°F | K23: Required Energy Input: vendor/available catalog size (Market data table). Storage Volume: standard/available catalog tank size (Market data table).
A24: CZ02 | B24: 50.8 | C24: =$F$13*($B$17-B24)*$B$19 -> 52336.825 | D24: =C24*$B$18 -> 31402.095 | E24: =_xlfn.LET(_xlpm.x,_xlfn.XLOOKUP(D24,$D$44:$D$58,$D$44:$D$58,"",1),IF(_xlpm.x="",ROUNDUP(D24,0),_xlpm.x)) -> 34121 | F24: =_xlfn.LET(_xlpm.v,MAX(30,$F$13*$B$20),_xlpm.x,_xlfn.XLOOKUP(_xlpm.v,$G$44:$G$58,$G$44:$G$58,"",1),IF(_xlpm.x="",ROUNDUP(_xlpm.v,0),_xlpm.x)) -> 30 | G24: =0.3+27/F24 -> 1.2 | H24: =IF($F$13>0,"%/hr","Btu/hr") -> %/hr | I24: =0.0834*G24*F24 -> 3.0024 | J24: Btu/h·°F
A25: CZ03 | B25: 52.2 | C25: =$F$13*($B$17-B25)*$B$19 -> 51466.617 | D25: =C25*$B$18 -> 30879.97 | E25: =_xlfn.LET(_xlpm.x,_xlfn.XLOOKUP(D25,$D$44:$D$58,$D$44:$D$58,"",1),IF(_xlpm.x="",ROUNDUP(D25,0),_xlpm.x)) -> 34121 | F25: =_xlfn.LET(_xlpm.v,MAX(30,$F$13*$B$20),_xlpm.x,_xlfn.XLOOKUP(_xlpm.v,$G$44:$G$58,$G$44:$G$58,"",1),IF(_xlpm.x="",ROUNDUP(_xlpm.v,0),_xlpm.x)) -> 30 | G25: =0.3+27/F25 -> 1.2 | H25: =IF($F$13>0,"%/hr","Btu/hr") -> %/hr | I25: =0.0834*G25*F25 -> 3.0024 | J25: Btu/h·°F
A26: CZ04 | B26: 52.7 | C26: =$F$13*($B$17-B26)*$B$19 -> 51155.828 | D26: =C26*$B$18 -> 30693.497 | E26: =_xlfn.LET(_xlpm.x,_xlfn.XLOOKUP(D26,$D$44:$D$58,$D$44:$D$58,"",1),IF(_xlpm.x="",ROUNDUP(D26,0),_xlpm.x)) -> 30709 | F26: =_xlfn.LET(_xlpm.v,MAX(30,$F$13*$B$20),_xlpm.x,_xlfn.XLOOKUP(_xlpm.v,$G$44:$G$58,$G$44:$G$58,"",1),IF(_xlpm.x="",ROUNDUP(_xlpm.v,0),_xlpm.x)) -> 30 | G26: =0.3+27/F26 -> 1.2 | H26: =IF($F$13>0,"%/hr","Btu/hr") -> %/hr | I26: =0.0834*G26*F26 -> 3.0024 | J26: Btu/h·°F
A27: CZ05 | B27: 51.6 | C27: =$F$13*($B$17-B27)*$B$19 -> 51839.563 | D27: =C27*$B$18 -> 31103.738 | E27: =_xlfn.LET(_xlpm.x,_xlfn.XLOOKUP(D27,$D$44:$D$58,$D$44:$D$58,"",1),IF(_xlpm.x="",ROUNDUP(D27,0),_xlpm.x)) -> 34121 | F27: =_xlfn.LET(_xlpm.v,MAX(30,$F$13*$B$20),_xlpm.x,_xlfn.XLOOKUP(_xlpm.v,$G$44:$G$58,$G$44:$G$58,"",1),IF(_xlpm.x="",ROUNDUP(_xlpm.v,0),_xlpm.x)) -> 30 | G27: =0.3+27/F27 -> 1.2 | H27: =IF($F$13>0,"%/hr","Btu/hr") -> %/hr | I27: =0.0834*G27*F27 -> 3.0024 | J27: Btu/h·°F
A28: CZ06 | B28: 56.8 | C28: =$F$13*($B$17-B28)*$B$19 -> 48607.36 | D28: =C28*$B$18 -> 29164.416 | E28: =_xlfn.LET(_xlpm.x,_xlfn.XLOOKUP(D28,$D$44:$D$58,$D$44:$D$58,"",1),IF(_xlpm.x="",ROUNDUP(D28,0),_xlpm.x)) -> 30709 | F28: =_xlfn.LET(_xlpm.v,MAX(30,$F$13*$B$20),_xlpm.x,_xlfn.XLOOKUP(_xlpm.v,$G$44:$G$58,$G$44:$G$58,"",1),IF(_xlpm.x="",ROUNDUP(_xlpm.v,0),_xlpm.x)) -> 30 | G28: =0.3+27/F28 -> 1.2 | H28: =IF($F$13>0,"%/hr","Btu/hr") -> %/hr | I28: =0.0834*G28*F28 -> 3.0024 | J28: Btu/h·°F
A29: CZ07 | B29: 58.4 | C29: =$F$13*($B$17-B29)*$B$19 -> 47612.836 | D29: =C29*$B$18 -> 28567.702 | E29: =_xlfn.LET(_xlpm.x,_xlfn.XLOOKUP(D29,$D$44:$D$58,$D$44:$D$58,"",1),IF(_xlpm.x="",ROUNDUP(D29,0),_xlpm.x)) -> 30709 | F29: =_xlfn.LET(_xlpm.v,MAX(30,$F$13*$B$20),_xlpm.x,_xlfn.XLOOKUP(_xlpm.v,$G$44:$G$58,$G$44:$G$58,"",1),IF(_xlpm.x="",ROUNDUP(_xlpm.v,0),_xlpm.x)) -> 30 | G29: =0.3+27/F29 -> 1.2 | H29: =IF($F$13>0,"%/hr","Btu/hr") -> %/hr | I29: =0.0834*G29*F29 -> 3.0024 | J29: Btu/h·°F
A30: CZ08 | B30: 58.4 | C30: =$F$13*($B$17-B30)*$B$19 -> 47612.836 | D30: =C30*$B$18 -> 28567.702 | E30: =_xlfn.LET(_xlpm.x,_xlfn.XLOOKUP(D30,$D$44:$D$58,$D$44:$D$58,"",1),IF(_xlpm.x="",ROUNDUP(D30,0),_xlpm.x)) -> 30709 | F30: =_xlfn.LET(_xlpm.v,MAX(30,$F$13*$B$20),_xlpm.x,_xlfn.XLOOKUP(_xlpm.v,$G$44:$G$58,$G$44:$G$58,"",1),IF(_xlpm.x="",ROUNDUP(_xlpm.v,0),_xlpm.x)) -> 30 | G30: =0.3+27/F30 -> 1.2 | H30: =IF($F$13>0,"%/hr","Btu/hr") -> %/hr | I30: =0.0834*G30*F30 -> 3.0024 | J30: Btu/h·°F
A31: CZ09 | B31: 57.6 | C31: =$F$13*($B$17-B31)*$B$19 -> 48110.098 | D31: =C31*$B$18 -> 28866.059 | E31: =_xlfn.LET(_xlpm.x,_xlfn.XLOOKUP(D31,$D$44:$D$58,$D$44:$D$58,"",1),IF(_xlpm.x="",ROUNDUP(D31,0),_xlpm.x)) -> 30709 | F31: =_xlfn.LET(_xlpm.v,MAX(30,$F$13*$B$20),_xlpm.x,_xlfn.XLOOKUP(_xlpm.v,$G$44:$G$58,$G$44:$G$58,"",1),IF(_xlpm.x="",ROUNDUP(_xlpm.v,0),_xlpm.x)) -> 30 | G31: =0.3+27/F31 -> 1.2 | H31: =IF($F$13>0,"%/hr","Btu/hr") -> %/hr | I31: =0.0834*G31*F31 -> 3.0024 | J31: Btu/h·°F
A32: CZ10 | B32: 57.1 | C32: =$F$13*($B$17-B32)*$B$19 -> 48420.887 | D32: =C32*$B$18 -> 29052.532 | E32: =_xlfn.LET(_xlpm.x,_xlfn.XLOOKUP(D32,$D$44:$D$58,$D$44:$D$58,"",1),IF(_xlpm.x="",ROUNDUP(D32,0),_xlpm.x)) -> 30709 | F32: =_xlfn.LET(_xlpm.v,MAX(30,$F$13*$B$20),_xlpm.x,_xlfn.XLOOKUP(_xlpm.v,$G$44:$G$58,$G$44:$G$58,"",1),IF(_xlpm.x="",ROUNDUP(_xlpm.v,0),_xlpm.x)) -> 30 | G32: =0.3+27/F32 -> 1.2 | H32: =IF($F$13>0,"%/hr","Btu/hr") -> %/hr | I32: =0.0834*G32*F32 -> 3.0024 | J32: Btu/h·°F
A33: CZ11 | B33: 50.5 | C33: =$F$13*($B$17-B33)*$B$19 -> 52523.299 | D33: =C33*$B$18 -> 31513.979 | E33: =_xlfn.LET(_xlpm.x,_xlfn.XLOOKUP(D33,$D$44:$D$58,$D$44:$D$58,"",1),IF(_xlpm.x="",ROUNDUP(D33,0),_xlpm.x)) -> 34121 | F33: =_xlfn.LET(_xlpm.v,MAX(30,$F$13*$B$20),_xlpm.x,_xlfn.XLOOKUP(_xlpm.v,$G$44:$G$58,$G$44:$G$58,"",1),IF(_xlpm.x="",ROUNDUP(_xlpm.v,0),_xlpm.x)) -> 30 | G33: =0.3+27/F33 -> 1.2 | H33: =IF($F$13>0,"%/hr","Btu/hr") -> %/hr | I33: =0.0834*G33*F33 -> 3.0024 | J33: Btu/h·°F
A34: CZ12 | B34: 51.4 | C34: =$F$13*($B$17-B34)*$B$19 -> 51963.879 | D34: =C34*$B$18 -> 31178.327 | E34: =_xlfn.LET(_xlpm.x,_xlfn.XLOOKUP(D34,$D$44:$D$58,$D$44:$D$58,"",1),IF(_xlpm.x="",ROUNDUP(D34,0),_xlpm.x)) -> 34121 | F34: =_xlfn.LET(_xlpm.v,MAX(30,$F$13*$B$20),_xlpm.x,_xlfn.XLOOKUP(_xlpm.v,$G$44:$G$58,$G$44:$G$58,"",1),IF(_xlpm.x="",ROUNDUP(_xlpm.v,0),_xlpm.x)) -> 30 | G34: =0.3+27/F34 -> 1.2 | H34: =IF($F$13>0,"%/hr","Btu/hr") -> %/hr | I34: =0.0834*G34*F34 -> 3.0024 | J34: Btu/h·°F
A35: CZ13 | B35: 51.7 | C35: =$F$13*($B$17-B35)*$B$19 -> 51777.406 | D35: =C35*$B$18 -> 31066.443 | E35: =_xlfn.LET(_xlpm.x,_xlfn.XLOOKUP(D35,$D$44:$D$58,$D$44:$D$58,"",1),IF(_xlpm.x="",ROUNDUP(D35,0),_xlpm.x)) -> 34121 | F35: =_xlfn.LET(_xlpm.v,MAX(30,$F$13*$B$20),_xlpm.x,_xlfn.XLOOKUP(_xlpm.v,$G$44:$G$58,$G$44:$G$58,"",1),IF(_xlpm.x="",ROUNDUP(_xlpm.v,0),_xlpm.x)) -> 30 | G35: =0.3+27/F35 -> 1.2 | H35: =IF($F$13>0,"%/hr","Btu/hr") -> %/hr | I35: =0.0834*G35*F35 -> 3.0024 | J35: Btu/h·°F
... A38: CZ16 | B38: 41.4 | C38: =$F$13*($B$17-B38)*$B$19 -> 58179.654 | D38: =C38*$B$18 -> 34907.792 | E38: =_xlfn.LET(_xlpm.x,_xlfn.XLOOKUP(D38,$D$44:$D$58,$D$44:$D$58,"",1),IF(_xlpm.x="",ROUNDUP(D38,0),_xlpm.x)) -> 40946 | F38: =_xlfn.LET(_xlpm.v,MAX(30,$F$13*$B$20),_xlpm.x,_xlfn.XLOOKUP(_xlpm.v,$G$44:$G$58,$G$44:$G$58,"",1),IF(_xlpm.x="",ROUNDUP(_xlpm.v,0),_xlpm.x)) -> 30 | G38: =0.3+27/F38 -> 1.2 | H38: =IF($F$13>0,"%/hr","Btu/hr") -> %/hr | I38: =0.0834*G38*F38 -> 3.0024 | J38: Btu/h·°F
A42: Market data
A43: Catalog gas input (Btu/h) | B43: Input source | C43: Elec resistance tank (kW) | D43: Elec resistance (Btu/h) | E43: Catalog gas tank (gal) | F43: Tank source | G43: Elec tank (gal) | H43: Elec tank source | I43: =HYPERLINK("#'Note'!A1","Sources and links → Note tab") -> Sources and links → Note tab
A44: 60000 | B44: Grainger | C44: 1.5 | D44: 5118 | E44: 34 | F44: ENERGY STAR | G44: 6 | H44: Grainger
A45: 75100 | B45: Grainger | C45: 2 | D45: 6824 | E45: 35 | F45: Grainger | G45: 10 | H45: Grainger
A46: 76000 | B46: Both | C46: 3 | D46: 10236 | E46: 48 | F46: Grainger | G46: 15 | H46: Grainger
A47: 80000 | B47: Grainger | C47: 4.5 | D47: 15355 | E47: 50 | F47: Both | G47: 20 | H47: Grainger
A48: 99900 | B48: ENERGY STAR | C48: 6 | D48: 20473 | E48: 55 | F48: ENERGY STAR | G48: 28 | H48: Grainger
A49: 100000 | B49: Both | C49: 8 | D49: 27297 | E49: 60 | F49: ENERGY STAR | G49: 30 | H49: Grainger
...

Sheet Interior Lights
A1: ="Interior Lighting - "&Prototype!A2 -> Interior Lighting - RetailStripMall
A2: Space Type | B2: New Construction | E2: Existing | H2: Note
B3: LPD (W/ft²) | C3: Additional LPD for Portable Lighting (W/ft²) | D3: Source | E3: LPD (W/ft²) | F3: Additional LPD for Portable Lighting (W/ft²) | G3: Source
A4: =Zones!C3 -> Retail Sales Area (Retail Merchandise Sales) | B4: 0.95 | C4: =0.45*0.2 -> 0.09 | D4: T24, part 6, 2025, Table 140.6-C | E4: 1.2 | F4: =0.3*0.2 -> 0.06 | G4: T24, part 6, 2016, Table 140.6-C | H4: The percentage of additional lighting depends heavily on the specific store type. As a general assumption, additional lighting is calculated for 20% of the Retail Sales Area.
A13: Background Data [To be deleted prior to publication]

Sheet Ext Lighting
A1: ="Exterior Lighting - "&Prototype!A2 -> Exterior Lighting - RetailStripMall
A2: Motion Controlled Luminaires (W) | B2: Non-motion Controlled Luminaires (W) | C2: Total (W) | D2: Source
A3: =G14 -> 472.9153 | B3: =G15 -> 346.56245 | C3: =SUM(A3:B3) -> 819.47775 | D3: T24, 2022
A6: Exterior Lighting
A7: Items (Assume LZ2) | B7: Assumptions [2019 Outdoor Lighting CASE Report & PNNL 90.1-2010 TSD] | D7: Unit | E7: Lighting Power Allowance [T24, 2025, Table 140.7-A & 140.7-B] | F7: Unit | G7: Exterior lighting power (w)
A8: IWA (Initial Wattage Allowance) | E8: 200 | F8: W | G8: =$E8 -> 200
A9: Parking area | B9: 400 ft² for every parking space [2019 Lighting CASE report, Appendix H] 1 parking space per 360 ft² of gross building area [2019 Lighting CASE report, Table 38] | C9: =B21/360*400 -> 10416.595 | D9: (ft²) | E9: 0.019 | F9: (W/ft²) | G9: =$E9*C9 -> 197.9153
A10: Building Entrance | B10: 5 building entrance | C10: 5 | D10: (count) | E10: 15 | F10: (W/ea) | G10: =E10*C10 -> 75
A11: Hardscape Ornamental Light | B11: 0.1 ft² per 1 ft² of gross bldg area [2019 Lighting CASE report, Table 36] *The 0.5 multiplier has not been applied, as it is assumed it will be incorporated later during the measure analysis study. | C11: =B21*0.1 -> 937.49351 | D11: (ft²) | E11: 0.007 | F11: (W/ft²) | G11: =E11*C11 -> 6.5624545
A12: Building façade | B12: 0.1 W per 1 ft² of facade area Façade Area = Perimeter × 0.5 × 17' The 0.5 factor assumes that only half of the perimeter walls are lit. -Formula ia developed based on the 2019 Outdoor Lighting CASE report | C12: =B20*0.5*Prototype!B16 -> 3400 | D12: (ft²) | E12: 0.1 | F12: (W/ft²) | G12: =E12*C12 -> 340
A13: Sales canopy | B13: 0.1 ft² per ft² of gross bldg area | C13: =(B21/B22)*0.1*0 -> 0 | D13: (ft²) | E13: 0.47 | F13: (W/ft²) | G13: =E13*C13 -> 0
A14: Motion controlled Luminaires | G14: =SUM(G8:G13)-G15 -> 472.9153
A15: Non-motion-controlled Luminaires | G15: =G11+G12 -> 346.56245
A16: Total | G16: =G14+G15 -> 819.47775
A18: *Developed based on 2019 Outdoor Lighting CASE Report
A20: Perimeter | B20: =125*2+75*2 -> 400
A21: Total floor area | B21: =Zones!J7 -> 9374.9351
A22: Floors | B22: 1
A26: Background Data [To be deleted prior to publication]

Sheet Equipment
A1: ="Equipment - "&Prototype!A2 -> Equipment - RetailStripMall
A2: Space Type | B2: Plug Load Power Density (W/ft²) | C2: Refrigerator Power Density (W/ft²) | D2: Gas Power Density (Btu/hr-ft²) | E2: Source
A3: =Zones!C3 -> Retail Sales Area (Retail Merchandise Sales) | B3: 0.3 | E3: Mix of sources including "High-Efficiency Retrofit Lessons for Retail from a SuperTarget" (2013) & ASHRAE 90.1 Prototype
A9: Background Data [To be deleted prior to publication]

Sheet Schedules
A1: ="Schedules - "&Prototype!A2 -> Schedules - RetailStripMall
A2: Zone | B2: Schedule Category | C2: Schedule | D2: Source | E2: Type | F2: Hour
F3: 1 | G3: 2 | H3: 3 | I3: 4 | J3: 5 | K3: 6 | L3: 7 | M3: 8 | N3: 9 | O3: 10 | P3: 11 | Q3: 12 | R3: 13 | S3: 14 | T3: 15 | U3: 16 | V3: 17 | W3: 18 | X3: 19 | Y3: 20 | Z3: 21 | AA3: 22 | AB3: 23 | AC3: 24
A4: All Zones | B4: Retail | C4: Occupancy | D4: NLR Study "Final Optimization Report: Empowering Energy Efficiency in Existing Big-Box Retail/Grocery Stores", (2020) | E4: Weekday | F4: 0 | G4: 0 | H4: 0 | I4: 0 | J4: 0 | K4: 0 | L4: 0 | M4: 0.2 | N4: 0.3 | O4: 0.4 | P4: 0.5 | Q4: 0.6 | R4: 0.6 | S4: 0.6 | T4: 0.6 | U4: 0.6 | V4: 0.7 | W4: 0.8 | X4: 0.8 | Y4: 0.6 | Z4: 0.3 | AA4: 0 | AB4: 0 | AC4: 0
E5: Saturday | F5: 0 | G5: 0 | H5: 0 | I5: 0 | J5: 0 | K5: 0 | L5: 0 | M5: 0.3 | N5: 0.4 | O5: 0.6 | P5: 0.8 | Q5: 0.9 | R5: 0.9 | S5: 0.9 | T5: 0.9 | U5: 0.8 | V5: 0.8 | W5: 0.7 | X5: 0.6 | Y5: 0.5 | Z5: 0.3 | AA5: 0 | AB5: 0 | AC5: 0
E6: Sunday | F6: 0 | G6: 0 | H6: 0 | I6: 0 | J6: 0 | K6: 0 | L6: 0 | M6: 0.2 | N6: 0.3 | O6: 0.5 | P6: 0.7 | Q6: 0.8 | R6: 0.8 | S6: 0.8 | T6: 0.8 | U6: 0.7 | V6: 0.7 | W6: 0.6 | X6: 0.5 | Y6: 0.4 | Z6: 0.2 | AA6: 0 | AB6: 0 | AC6: 0
A7: =A4 -> All Zones | B7: =B4 -> Retail | C7: Lights | D7: T24 2022 - Appendix 5.4B, [Retail] | E7: Weekday | F7: 0.05 | G7: 0.05 | H7: 0.05 | I7: 0.05 | J7: 0.05 | K7: 0.05 | L7: 0.7 | M7: 1 | N7: 1 | O7: 1 | P7: 1 | Q7: 1 | R7: 1 | S7: 1 | T7: 1 | U7: 1 | V7: 1 | W7: 1 | X7: 1 | Y7: 1 | Z7: 1 | AA7: 0.7 | AB7: 0.05 | AC7: 0.05
E8: Saturday | F8: 0.05 | G8: 0.05 | H8: 0.05 | I8: 0.05 | J8: 0.05 | K8: 0.05 | L8: 0.7 | M8: 1 | N8: 1 | O8: 1 | P8: 1 | Q8: 1 | R8: 1 | S8: 1 | T8: 1 | U8: 1 | V8: 1 | W8: 1 | X8: 1 | Y8: 1 | Z8: 1 | AA8: 0.7 | AB8: 0.05 | AC8: 0.05
E9: Sunday | F9: 0.05 | G9: 0.05 | H9: 0.05 | I9: 0.05 | J9: 0.05 | K9: 0.05 | L9: 0.7 | M9: 1 | N9: 1 | O9: 1 | P9: 1 | Q9: 1 | R9: 1 | S9: 1 | T9: 1 | U9: 1 | V9: 1 | W9: 1 | X9: 1 | Y9: 1 | Z9: 1 | AA9: 0.7 | AB9: 0.05 | AC9: 0.05
A10: =A4 -> All Zones | B10: =B4 -> Retail | C10: ElecEquipment | D10: Plug load and schedules project with CEC, 2025 | E10: Weekday | F10: 0.4 | G10: 0.4 | H10: 0.4 | I10: 0.4 | J10: 0.4 | K10: 0.4 | L10: 0.4 | M10: 0.9 | N10: 0.9 | O10: 0.9 | P10: 0.9 | Q10: 0.9 | R10: 0.9 | S10: 0.9 | T10: 0.9 | U10: 0.9 | V10: 0.9 | W10: 0.9 | X10: 0.9 | Y10: 0.9 | Z10: 0.9 | AA10: 0.4 | AB10: 0.4 | AC10: 0.4
E11: Saturday | F11: 0.4 | G11: 0.4 | H11: 0.4 | I11: 0.4 | J11: 0.4 | K11: 0.4 | L11: 0.4 | M11: 0.9 | N11: 0.9 | O11: 0.9 | P11: 0.9 | Q11: 0.9 | R11: 0.9 | S11: 0.9 | T11: 0.9 | U11: 0.9 | V11: 0.9 | W11: 0.9 | X11: 0.9 | Y11: 0.9 | Z11: 0.9 | AA11: 0.4 | AB11: 0.4 | AC11: 0.4
E12: Sunday | F12: 0.4 | G12: 0.4 | H12: 0.4 | I12: 0.4 | J12: 0.4 | K12: 0.4 | L12: 0.4 | M12: 0.9 | N12: 0.9 | O12: 0.9 | P12: 0.9 | Q12: 0.9 | R12: 0.9 | S12: 0.9 | T12: 0.9 | U12: 0.9 | V12: 0.9 | W12: 0.9 | X12: 0.9 | Y12: 0.9 | Z12: 0.9 | AA12: 0.4 | AB12: 0.4 | AC12: 0.4
A13: =A7 -> All Zones | B13: =B7 -> Retail | C13: HVACAvail | D13: T24 2022 - Appendix 5.4B, [Retail] | E13: Weekday | F13: 0 | G13: 0 | H13: 0 | I13: 0 | J13: 0 | K13: 0 | L13: 1 | M13: 1 | N13: 1 | O13: 1 | P13: 1 | Q13: 1 | R13: 1 | S13: 1 | T13: 1 | U13: 1 | V13: 1 | W13: 1 | X13: 1 | Y13: 1 | Z13: 1 | AA13: 0 | AB13: 0 | AC13: 0
E14: Saturday | F14: 0 | G14: 0 | H14: 0 | I14: 0 | J14: 0 | K14: 0 | L14: 1 | M14: 1 | N14: 1 | O14: 1 | P14: 1 | Q14: 1 | R14: 1 | S14: 1 | T14: 1 | U14: 1 | V14: 1 | W14: 1 | X14: 1 | Y14: 1 | Z14: 1 | AA14: 1 | AB14: 0 | AC14: 0
E15: Sunday | F15: 0 | G15: 0 | H15: 0 | I15: 0 | J15: 0 | K15: 0 | L15: 0 | M15: 0 | N15: 1 | O15: 1 | P15: 1 | Q15: 1 | R15: 1 | S15: 1 | T15: 1 | U15: 1 | V15: 1 | W15: 1 | X15: 1 | Y15: 0 | Z15: 0 | AA15: 0 | AB15: 0 | AC15: 0
A16: =A10 -> All Zones | B16: =B10 -> Retail | C16: ServiceHotWater | D16: T24 2022 - Appendix 5.4B, [Retail] | E16: Weekday | F16: 0.04 | G16: 0.05 | H16: 0.05 | I16: 0.04 | J16: 0.04 | K16: 0.04 | L16: 0.04 | M16: 0.15 | N16: 0.23 | O16: 0.32 | P16: 0.41 | Q16: 0.57 | R16: 0.62 | S16: 0.61 | T16: 0.5 | U16: 0.45 | V16: 0.46 | W16: 0.47 | X16: 0.42 | Y16: 0.34 | Z16: 0.33 | AA16: 0.23 | AB16: 0.13 | AC16: 0.08
E17: Saturday | F17: 0.11 | G17: 0.1 | H17: 0.08 | I17: 0.06 | J17: 0.06 | K17: 0.06 | L17: 0.07 | M17: 0.2 | N17: 0.24 | O17: 0.27 | P17: 0.42 | Q17: 0.54 | R17: 0.59 | S17: 0.6 | T17: 0.49 | U17: 0.48 | V17: 0.47 | W17: 0.46 | X17: 0.44 | Y17: 0.36 | Z17: 0.29 | AA17: 0.22 | AB17: 0.16 | AC17: 0.13
E18: Sunday | F18: 0.07 | G18: 0.07 | H18: 0.07 | I18: 0.06 | J18: 0.06 | K18: 0.06 | L18: 0.07 | M18: 0.1 | N18: 0.12 | O18: 0.14 | P18: 0.29 | Q18: 0.31 | R18: 0.36 | S18: 0.36 | T18: 0.34 | U18: 0.35 | V18: 0.37 | W18: 0.34 | X18: 0.25 | Y18: 0.27 | Z18: 0.21 | AA18: 0.16 | AB18: 0.1 | AC18: 0.06
A19: =A13 -> All Zones | B19: =B13 -> Retail | C19: Infiltration | D19: T24 2022 - Appendix 5.4B, [Retail] | E19: Weekday | F19: 1 | G19: 1 | H19: 1 | I19: 1 | J19: 1 | K19: 1 | L19: 0.25 | M19: 0.25 | N19: 0.25 | O19: 0.25 | P19: 0.25 | Q19: 0.25 | R19: 0.25 | S19: 0.25 | T19: 0.25 | U19: 0.25 | V19: 0.25 | W19: 0.25 | X19: 0.25 | Y19: 0.25 | Z19: 0.25 | AA19: 1 | AB19: 1 | AC19: 1
E20: Saturday | F20: 1 | G20: 1 | H20: 1 | I20: 1 | J20: 1 | K20: 1 | L20: 0.25 | M20: 0.25 | N20: 0.25 | O20: 0.25 | P20: 0.25 | Q20: 0.25 | R20: 0.25 | S20: 0.25 | T20: 0.25 | U20: 0.25 | V20: 0.25 | W20: 0.25 | X20: 0.25 | Y20: 0.25 | Z20: 0.25 | AA20: 0.25 | AB20: 1 | AC20: 1
E21: Sunday | F21: 1 | G21: 1 | H21: 1 | I21: 1 | J21: 1 | K21: 1 | L21: 1 | M21: 1 | N21: 0.25 | O21: 0.25 | P21: 0.25 | Q21: 0.25 | R21: 0.25 | S21: 0.25 | T21: 0.25 | U21: 0.25 | V21: 0.25 | W21: 0.25 | X21: 0.25 | Y21: 1 | Z21: 1 | AA21: 1 | AB21: 1 | AC21: 1
A22: =A16 -> All Zones | B22: =B16 -> Retail | C22: Refrigeration | D22: T24 2022 - Appendix 5.4B, [Retail] | E22: Weekday | F22: 0.9 | G22: 0.9 | H22: 0.9 | I22: 0.9 | J22: 0.9 | K22: 0.9 | L22: 0.9 | M22: 0.9 | N22: 0.9 | O22: 0.9 | P22: 0.9 | Q22: 0.9 | R22: 0.9 | S22: 0.9 | T22: 0.9 | U22: 0.9 | V22: 0.9 | W22: 0.9 | X22: 0.9 | Y22: 0.9 | Z22: 0.9 | AA22: 0.9 | AB22: 0.9 | AC22: 0.9
E23: Saturday | F23: 0.9 | G23: 0.9 | H23: 0.9 | I23: 0.9 | J23: 0.9 | K23: 0.9 | L23: 0.9 | M23: 0.9 | N23: 0.9 | O23: 0.9 | P23: 0.9 | Q23: 0.9 | R23: 0.9 | S23: 0.9 | T23: 0.9 | U23: 0.9 | V23: 0.9 | W23: 0.9 | X23: 0.9 | Y23: 0.9 | Z23: 0.9 | AA23: 0.9 | AB23: 0.9 | AC23: 0.9
E24: Sunday | F24: 0.9 | G24: 0.9 | H24: 0.9 | I24: 0.9 | J24: 0.9 | K24: 0.9 | L24: 0.9 | M24: 0.9 | N24: 0.9 | O24: 0.9 | P24: 0.9 | Q24: 0.9 | R24: 0.9 | S24: 0.9 | T24: 0.9 | U24: 0.9 | V24: 0.9 | W24: 0.9 | X24: 0.9 | Y24: 0.9 | Z24: 0.9 | AA24: 0.9 | AB24: 0.9 | AC24: 0.9
A25: =A16 -> All Zones | B25: =B16 -> Retail | C25: HtgSetpt | D25: T24 2022 - Appendix 5.4B, [Retail] | E25: Weekday | F25: =IF(F13=1,Thermostat!$B$3,Thermostat!$B$4) -> 60 | G25: =IF(G13=1,Thermostat!$B$3,Thermostat!$B$4) -> 60 | H25: =IF(H13=1,Thermostat!$B$3,Thermostat!$B$4) -> 60 | I25: =IF(I13=1,Thermostat!$B$3,Thermostat!$B$4) -> 60 | J25: =IF(J13=1,Thermostat!$B$3,Thermostat!$B$4) -> 60 | K25: =IF(K13=1,Thermostat!$B$3,Thermostat!$B$4) -> 60 | L25: =IF(L13=1,Thermostat!$B$3,Thermostat!$B$4) -> 70 | M25: =IF(M13=1,Thermostat!$B$3,Thermostat!$B$4) -> 70 | ... AC25: =IF(AC13=1,Thermostat!$B$3,Thermostat!$B$4) -> 60
E26: Saturday | F26: =IF(F14=1,Thermostat!$B$3,Thermostat!$B$4) -> 60 | G26: =IF(G14=1,Thermostat!$B$3,Thermostat!$B$4) -> 60 | H26: =IF(H14=1,Thermostat!$B$3,Thermostat!$B$4) -> 60 | I26: =IF(I14=1,Thermostat!$B$3,Thermostat!$B$4) -> 60 | J26: =IF(J14=1,Thermostat!$B$3,Thermostat!$B$4) -> 60 | K26: =IF(K14=1,Thermostat!$B$3,Thermostat!$B$4) -> 60 | L26: =IF(L14=1,Thermostat!$B$3,Thermostat!$B$4) -> 70 | M26: =IF(M14=1,Thermostat!$B$3,Thermostat!$B$4) -> 70 | ... AC26: =IF(AC14=1,Thermostat!$B$3,Thermostat!$B$4) -> 60
E27: Sunday | F27: =IF(F15=1,Thermostat!$B$3,Thermostat!$B$4) -> 60 | G27: =IF(G15=1,Thermostat!$B$3,Thermostat!$B$4) -> 60 | H27: =IF(H15=1,Thermostat!$B$3,Thermostat!$B$4) -> 60 | I27: =IF(I15=1,Thermostat!$B$3,Thermostat!$B$4) -> 60 | J27: =IF(J15=1,Thermostat!$B$3,Thermostat!$B$4) -> 60 | K27: =IF(K15=1,Thermostat!$B$3,Thermostat!$B$4) -> 60 | L27: =IF(L15=1,Thermostat!$B$3,Thermostat!$B$4) -> 60 | M27: =IF(M15=1,Thermostat!$B$3,Thermostat!$B$4) -> 60 | ... AC27: =IF(AC15=1,Thermostat!$B$3,Thermostat!$B$4) -> 60
A28: =A19 -> All Zones | B28: =B19 -> Retail | C28: ClgSetpt | D28: T24 2022 - Appendix 5.4B, [Retail] | E28: Weekday | F28: =IF(F13=1,Thermostat!$B$5,Thermostat!$B$6) -> 85 | G28: =IF(G13=1,Thermostat!$B$5,Thermostat!$B$6) -> 85 | H28: =IF(H13=1,Thermostat!$B$5,Thermostat!$B$6) -> 85 | I28: =IF(I13=1,Thermostat!$B$5,Thermostat!$B$6) -> 85 | J28: =IF(J13=1,Thermostat!$B$5,Thermostat!$B$6) -> 85 | K28: =IF(K13=1,Thermostat!$B$5,Thermostat!$B$6) -> 85 | L28: =IF(L13=1,Thermostat!$B$5,Thermostat!$B$6) -> 75 | M28: =IF(M13=1,Thermostat!$B$5,Thermostat!$B$6) -> 75 | ... AC28: =IF(AC13=1,Thermostat!$B$5,Thermostat!$B$6) -> 85
E29: Saturday | F29: =IF(F14=1,Thermostat!$B$5,Thermostat!$B$6) -> 85 | G29: =IF(G14=1,Thermostat!$B$5,Thermostat!$B$6) -> 85 | H29: =IF(H14=1,Thermostat!$B$5,Thermostat!$B$6) -> 85 | I29: =IF(I14=1,Thermostat!$B$5,Thermostat!$B$6) -> 85 | J29: =IF(J14=1,Thermostat!$B$5,Thermostat!$B$6) -> 85 | K29: =IF(K14=1,Thermostat!$B$5,Thermostat!$B$6) -> 85 | L29: =IF(L14=1,Thermostat!$B$5,Thermostat!$B$6) -> 75 | M29: =IF(M14=1,Thermostat!$B$5,Thermostat!$B$6) -> 75 | ... AC29: =IF(AC14=1,Thermostat!$B$5,Thermostat!$B$6) -> 85
E30: Sunday | F30: =IF(F15=1,Thermostat!$B$5,Thermostat!$B$6) -> 85 | G30: =IF(G15=1,Thermostat!$B$5,Thermostat!$B$6) -> 85 | H30: =IF(H15=1,Thermostat!$B$5,Thermostat!$B$6) -> 85 | I30: =IF(I15=1,Thermostat!$B$5,Thermostat!$B$6) -> 85 | J30: =IF(J15=1,Thermostat!$B$5,Thermostat!$B$6) -> 85 | K30: =IF(K15=1,Thermostat!$B$5,Thermostat!$B$6) -> 85 | L30: =IF(L15=1,Thermostat!$B$5,Thermostat!$B$6) -> 85 | M30: =IF(M15=1,Thermostat!$B$5,Thermostat!$B$6) -> 85 | ... AC30: =IF(AC15=1,Thermostat!$B$5,Thermostat!$B$6) -> 85
A31: Other
B32: Building | C32: ExtLightingNonMotionCtrl | E32: Weekday | F32: 1 | G32: 1 | H32: 1 | I32: 1 | J32: 1 | K32: 1 | L32: 1 | M32: 1 | N32: 1 | O32: 1 | P32: 1 | Q32: 1 | R32: 1 | S32: 1 | T32: 1 | U32: 1 | V32: 1 | W32: 1 | X32: 1 | Y32: 1 | Z32: 1 | AA32: 1 | AB32: 1 | AC32: 1
E33: Saturday | F33: 1 | G33: 1 | H33: 1 | I33: 1 | J33: 1 | K33: 1 | L33: 1 | M33: 1 | N33: 1 | O33: 1 | P33: 1 | Q33: 1 | R33: 1 | S33: 1 | T33: 1 | U33: 1 | V33: 1 | W33: 1 | X33: 1 | Y33: 1 | Z33: 1 | AA33: 1 | AB33: 1 | AC33: 1
E34: Sunday | F34: 1 | G34: 1 | H34: 1 | I34: 1 | J34: 1 | K34: 1 | L34: 1 | M34: 1 | N34: 1 | O34: 1 | P34: 1 | Q34: 1 | R34: 1 | S34: 1 | T34: 1 | U34: 1 | V34: 1 | W34: 1 | X34: 1 | Y34: 1 | Z34: 1 | AA34: 1 | AB34: 1 | AC34: 1
B35: Building | C35: ExtLightingMotionCtrl | E35: Weekday | F35: 0 | G35: 0 | H35: 0 | I35: 0 | J35: 0 | K35: 1 | L35: 1 | M35: 1 | N35: 1 | O35: 1 | P35: 1 | Q35: 1 | R35: 1 | S35: 1 | T35: 1 | U35: 1 | V35: 1 | W35: 1 | X35: 1 | Y35: 1 | Z35: 1 | AA35: 1 | AB35: 0 | AC35: 0
E36: Saturday | F36: 0 | G36: 0 | H36: 0 | I36: 0 | J36: 0 | K36: 1 | L36: 1 | M36: 1 | N36: 1 | O36: 1 | P36: 1 | Q36: 1 | R36: 1 | S36: 1 | T36: 1 | U36: 1 | V36: 1 | W36: 1 | X36: 1 | Y36: 1 | Z36: 1 | AA36: 1 | AB36: 1 | AC36: 1
E37: Sunday | F37: 0 | G37: 0 | H37: 0 | I37: 0 | J37: 0 | K37: 1 | L37: 1 | M37: 1 | N37: 1 | O37: 1 | P37: 1 | Q37: 1 | R37: 1 | S37: 1 | T37: 1 | U37: 1 | V37: 1 | W37: 1 | X37: 1 | Y37: 1 | Z37: 1 | AA37: 1 | AB37: 1 | AC37: 1
A38: Retails | B38: Building | C38: RetailSalePeopleActivityLevel | D38: Based on Activity level schedules in CEC Prototypes | E38: Weekday | F38: 131.9 | G38: 131.9 | H38: 131.9 | I38: 131.9 | J38: 131.9 | K38: 131.9 | L38: 131.9 | M38: 131.9 | N38: 131.9 | O38: 131.9 | P38: 131.9 | Q38: 131.9 | R38: 131.9 | S38: 131.9 | T38: 131.9 | U38: 131.9 | V38: 131.9 | W38: 131.9 | X38: 131.9 | Y38: 131.9 | Z38: 131.9 | AA38: 131.9 | AB38: 131.9 | AC38: 131.9
E39: Saturday | F39: 131.9 | G39: 131.9 | H39: 131.9 | I39: 131.9 | J39: 131.9 | K39: 131.9 | L39: 131.9 | M39: 131.9 | N39: 131.9 | O39: 131.9 | P39: 131.9 | Q39: 131.9 | R39: 131.9 | S39: 131.9 | T39: 131.9 | U39: 131.9 | V39: 131.9 | W39: 131.9 | X39: 131.9 | Y39: 131.9 | Z39: 131.9 | AA39: 131.9 | AB39: 131.9 | AC39: 131.9
E40: Sunday | F40: 131.9 | G40: 131.9 | H40: 131.9 | I40: 131.9 | J40: 131.9 | K40: 131.9 | L40: 131.9 | M40: 131.9 | N40: 131.9 | O40: 131.9 | P40: 131.9 | Q40: 131.9 | R40: 131.9 | S40: 131.9 | T40: 131.9 | U40: 131.9 | V40: 131.9 | W40: 131.9 | X40: 131.9 | Y40: 131.9 | Z40: 131.9 | AA40: 131.9 | AB40: 131.9 | AC40: 131.9
...

Sheet Energy Usage
A1: ="CalBEM Energy Consumption - "&Prototype!A2 -> CalBEM Energy Consumption - RetailStripMall | I1: National Average (EnergyStar Portfolio Manager) | N1: CEUS Energy Consumption : Retail | Y1: PNNL RetailStripMall 2007 (with floor area of 22,500 ft2) for San Diego shows 62 KBTU/ft2 | AI1: PNNL results are close to RetailMedium
A2: Prototype | B2: CZ | C2: CalBEM Electricity EUI (KBTU/ft²) | D2: CalBEM Gas EUI (KBTU/ft²) | E2: CalBEM Total EUI (KBTU/ft²) | F2: New Construction Electricity EUI (KBTU/ft²) | G2: New Construction Gas EUI (KBTU/ft²) | H2: New Construction Total EUI (KBTU/ft²) | I2: National Average | J2: Acceptable Range (25% Higher) | K2: Acceptable Range (25% Lower) | L2: National Average Acceptable EUI Range | N2: Prototype | O2: CZ | P2: Total Floorspace (Thousand of ft²) | Q2: CEUS 2023 Electricity EUI (kBtu/ft²) | R2: CEUS 2023 Gas EUI (kBtu/ft²) | S2: CEUS 2023 Total EUI (kBtu/ft²) | T2: Acceptable Range (25% Higher) | U2: Acceptable Range (25% Lower) | V2: CEUS 2022 Acceptable EUI Range | Y2: PNNL RetailStripMall 2022 (with floor area of 22,500 ft2) for San Diego shows 29 KBTU/ft2
A3: RetailStripMall | B3: 1 | I3: 46.8 | J3: =I3*1.25 -> 58.5 | K3: =0.75*I3 -> 35.1 | L3: =J3-K3 -> 23.4 | N3: Retail | O3: 1 | P3: 13814 | Q3: 37.9 | R3: 10.4 | S3: =Q3+R3 -> 48.3 | T3: =S3*1.25 -> 60.375 | U3: =S3*0.75 -> 36.225 | V3: =T3-U3 -> 24.15
B4: 2 | I4: 58.4 | J4: =I4*1.25 -> 73 | K4: =0.75*I4 -> 43.8 | L4: =J4-K4 -> 29.2 | O4: 2 | P4: 25239 | Q4: 26.6 | R4: 14.8 | S4: =Q4+R4 -> 41.4 | T4: =S4*1.25 -> 51.75 | U4: =S4*0.75 -> 31.05 | V4: =T4-U4 -> 20.7
B5: 3 | I5: 52.3 | J5: =I5*1.25 -> 65.375 | K5: =0.75*I5 -> 39.225 | L5: =J5-K5 -> 26.15 | O5: 3 | P5: 88648 | Q5: 34.8 | R5: 11.9 | S5: =Q5+R5 -> 46.7 | T5: =S5*1.25 -> 58.375 | U5: =S5*0.75 -> 35.025 | V5: =T5-U5 -> 23.35
B6: 4 | I6: 60.9 | J6: =I6*1.25 -> 76.125 | K6: =0.75*I6 -> 45.675 | L6: =J6-K6 -> 30.45 | O6: 4 | P6: 44551 | Q6: 35.5 | R6: 11.5 | S6: =Q6+R6 -> 47 | T6: =S6*1.25 -> 58.75 | U6: =S6*0.75 -> 35.25 | V6: =T6-U6 -> 23.5
B7: 5 | I7: 50.4 | J7: =I7*1.25 -> 63 | K7: =0.75*I7 -> 37.8 | L7: =J7-K7 -> 25.2 | O7: 5 | P7: 9847 | Q7: 31.7 | R7: 14.6 | S7: =Q7+R7 -> 46.3 | T7: =S7*1.25 -> 57.875 | U7: =S7*0.75 -> 34.725 | V7: =T7-U7 -> 23.15
B8: 6 | I8: 57.8 | J8: =I8*1.25 -> 72.25 | K8: =0.75*I8 -> 43.35 | L8: =J8-K8 -> 28.9 | O8: 6 | P8: 92562 | Q8: 29.3 | R8: 4.6 | S8: =Q8+R8 -> 33.9 | T8: =S8*1.25 -> 42.375 | U8: =S8*0.75 -> 25.425 | V8: =T8-U8 -> 16.95
B9: 7 | I9: 57.8 | J9: =I9*1.25 -> 72.25 | K9: =0.75*I9 -> 43.35 | L9: =J9-K9 -> 28.9 | O9: 7 | P9: 63471 | Q9: 35.1 | R9: 3.2 | S9: =Q9+R9 -> 38.3 | T9: =S9*1.25 -> 47.875 | U9: =S9*0.75 -> 28.725 | V9: =T9-U9 -> 19.15
B10: 8 | I10: 58.9 | J10: =I10*1.25 -> 73.625 | K10: =0.75*I10 -> 44.175 | L10: =J10-K10 -> 29.45 | O10: 8 | P10: 147354 | Q10: 29 | R10: 4.5 | S10: =Q10+R10 -> 33.5 | T10: =S10*1.25 -> 41.875 | U10: =S10*0.75 -> 25.125 | V10: =T10-U10 -> 16.75
B11: 9 | I11: 59.6 | J11: =I11*1.25 -> 74.5 | K11: =0.75*I11 -> 44.7 | L11: =J11-K11 -> 29.8 | O11: 9 | P11: 212697 | Q11: 32.1 | R11: 4.8 | S11: =Q11+R11 -> 36.9 | T11: =S11*1.25 -> 46.125 | U11: =S11*0.75 -> 27.675 | V11: =T11-U11 -> 18.45
B12: 10 | I12: 60.2 | J12: =I12*1.25 -> 75.25 | K12: =0.75*I12 -> 45.15 | L12: =J12-K12 -> 30.1 | O12: 10 | P12: 149832 | Q12: 31.7 | R12: 5.3 | S12: =Q12+R12 -> 37 | T12: =S12*1.25 -> 46.25 | U12: =S12*0.75 -> 27.75 | V12: =T12-U12 -> 18.5
B13: 11 | I13: 62.3 | J13: =I13*1.25 -> 77.875 | K13: =0.75*I13 -> 46.725 | L13: =J13-K13 -> 31.15 | O13: 11 | P13: 45934 | Q13: 36.2 | R13: 9.3 | S13: =Q13+R13 -> 45.5 | T13: =S13*1.25 -> 56.875 | U13: =S13*0.75 -> 34.125 | V13: =T13-U13 -> 22.75
B14: 12 | I14: 61.3 | J14: =I14*1.25 -> 76.625 | K14: =0.75*I14 -> 45.975 | L14: =J14-K14 -> 30.65 | O14: 12 | P14: 195816 | Q14: 37.5 | R14: 9.8 | S14: =Q14+R14 -> 47.3 | T14: =S14*1.25 -> 59.125 | U14: =S14*0.75 -> 35.475 | V14: =T14-U14 -> 23.65
B15: 13 | I15: 62.3 | J15: =I15*1.25 -> 77.875 | K15: =0.75*I15 -> 46.725 | L15: =J15-K15 -> 31.15 | O15: 13 | P15: 67122 | Q15: 42.3 | R15: 8.9 | S15: =Q15+R15 -> 51.2 | T15: =S15*1.25 -> 64 | U15: =S15*0.75 -> 38.4 | V15: =T15-U15 -> 25.6
... B18: 16 | I18: 61.2 | J18: =I18*1.25 -> 76.5 | K18: =0.75*I18 -> 45.9 | L18: =J18-K18 -> 30.6 | O18: 16 | P18: 149464 | Q18: 32.8 | R18: 5.3 | S18: =Q18+R18 -> 38.1 | T18: =S18*1.25 -> 47.625 | U18: =S18*0.75 -> 28.575 | V18: =T18-U18 -> 19.05
N20: Ref: CEUS 2022 Report
N21: And converted FZ level data to CZ level
N22: CEUS has only one category for Retail
N25: Background Data [To be deleted prior to publication]

Sheet Weights
A1: ="% of Floor Area per CZ and Vintage Bin - Retail" -> % of Floor Area per CZ and Vintage Bin - Retail | J1: ="% of Floor Area per CZ and Vintage Bin - Retail" -> % of Floor Area per CZ and Vintage Bin - Retail
A2: Prototype | B2: CZ | C2: Vintage Bin | J2: Prototype | K2: Vintage Bin | L2: CZ
C3: Pre-1978 | D3: 1978-1997 | E3: 1998-2007 | F3: 2008-2018 | L3: 1 | M3: 2 | N3: 3 | O3: 4 | P3: 5 | Q3: 6 | R3: 7 | S3: 8 | T3: 9 | U3: 10 | V3: 11 | W3: 12 | X3: 13 | Y3: 14 | Z3: 15 | AA3: 16
A4: Retail | B4: 1 | H4: =SUM(C4:F4) -> 0 | J4: Retail | K4: Pre-1978 | AB4: =SUM(L4:AA4) -> 0
B5: 2 | H5: =SUM(C5:F5) -> 0 | K5: 1978-1997 | AB5: =SUM(L5:AA5) -> 0
B6: 3 | H6: =SUM(C6:F6) -> 0 | K6: 1998-2007 | AB6: =SUM(L6:AA6) -> 0
B7: 4 | H7: =SUM(C7:F7) -> 0 | K7: 2008-2018 | AB7: =SUM(L7:AA7) -> 0
B8: 5 | H8: =SUM(C8:F8) -> 0 | K8: Not available | AB8: =SUM(L8:AA8) -> 0
B9: 6 | H9: =SUM(C9:F9) -> 0 | K9: Total | AB9: =SUM(L9:AA9) -> 0
B10: 7 | H10: =SUM(C10:F10) -> 0
B11: 8 | H11: =SUM(C11:F11) -> 0
B12: 9 | H12: =SUM(C12:F12) -> 0
B13: 10 | H13: =SUM(C13:F13) -> 0
B14: 11 | H14: =SUM(C14:F14) -> 0
B15: 12 | H15: =SUM(C15:F15) -> 0
B16: 13 | H16: =SUM(C16:F16) -> 0
B17: 14 | H17: =SUM(C17:F17) -> 0
B18: 15 | H18: =SUM(C18:F18) -> 0
B19: 16 | H19: =SUM(C19:F19) -> 0
B20: Statewide | H20: =SUM(C20:F20) -> 0
A22: Ref: CEUS 2022 dataset
A23: And converted FZ level data to CZ level
A24: CEUS has only one category for Retail

Sheet PV
A1: ="PV - "&Prototype!A2 -> PV - RetailStripMall
A2: TBD

Sheet EV Charger
A1: ="EV Charger - "&Prototype!A2 -> EV Charger - RetailStripMall
A2: TBD
A11: Background Data [To be deleted prior to publication]

Sheet Data
A1: Space Function | B1: Electric Equipment Load Intensity | C1: Electric Equipment Load Intensity | D1: LPD
A2: Aging Eye/Low-vision (Corridor Area) | D2: 2013 | E2: 2016 | F2: 2019 | G2: 2025
A3: Aging Eye/Low-vision (Dining)
A4: Aging Eye/Low-vision (Lobby, Main Entry)
A5: Aging Eye/Low-vision (Lounge/Waiting Area)
A6: Aging Eye/Low-vision (Multipurpose Room)
A7: Aging Eye/Low-vision (Religious Worship Area)
A8: Aging Eye/Low-vision (Restroom)
A9: Aging Eye/Low-vision (Stairwell)
A10: Audience Seating Area
A11: Auditorium Area
A12: Auto Repair / Maintenance Area
A13: Barber, Beauty Salon, Spa Area
A14: Civic Meeting Place Area
... A83: Server Room (EPD 45)
