Workbook
Name nonparticipating_forecastzone_scale_factor: #REF!
Name nonparticipating_forecastzone_scale_factor: 'Energy Usage'!#REF!

Sheet Notes
A1: Data Sources
A2: Dataset | C2: DSA Drawings for relocatable schools
B3: Berkeley Lab article | C3: https://www2.lbl.gov/Science-Articles/Archive/EETD-portable-classrooms.html
B4: California Portable Classroom Study | C4: https://ww2.arb.ca.gov/sites/default/files/classic/research/apr/reports/l3006.pdf
B5: California Legislature Environmental Health Condions in California's Portable Classrooms | C5: https://ww2.arb.ca.gov/sites/default/files/2020-05/pcs_v3_es_03-23-04.pdf
A6: Codes | B6: Title 24, part 6, referred to as T24 (1984, 2001, 2007, 2013, 2016, 2022, 2025)
B7: ASHRAE 90.1 (2022)
B8: CFR Title 10 (2008, 2010, 2025)
B9: ACM 2022
B10: T24 2022 - Appendix 5.4A and Appendix 5.4B | C10: https://www.energy.ca.gov/publications/2022/2022-nonresidential-and-multifamily-alternative-calculation-method-reference
B12: 2022 Reduced infiltration CASE report | C12: https://title24stakeholders.com/wp-content/uploads/2020/10/2022-T24-Final-CASE-Report_Reduce-Infiltration.pdf
B13: 2019 Outdoor Lighting CASE Report | C13: https://title24stakeholders.com/wp-content/uploads/2016/10/T24-2019-CASE-Study-Results-Report-Outdoor-Sources_Final_with-Attachments.pdf
B14: 2019 High Efficiency Fume Hoods in Laboratory Spaces CASE Report | C14: https://title24stakeholders.com/wp-content/uploads/2017/09/2019-T24-CASE-Report_Fume-Hoods_Final_September-2017.pdf?
B15: PNNL 20405, 2010 | C15: file:///N:/Prj_SUS/2023/S23668%20SCE%20CA%20Prototypes%20Development/Technical/NR/0_Input%20data/Lighting/PNNL-20405.pdf
A16: Other | B16: Air leakage Memo, NORESCO, 2025 | C16: Infiltration_rate_report_14May2025-Short-Version.docx
B17: BARD Engineering Specification Guide for SPVHP | C17: BARD Engineering Specification Guide for SPVHP
A18: Construction Rate
A31: Notes

Sheet Prototype
A1: NORESCO, Updated November 2025
A2: SchoolRelocatable
A3: Characteristic | B3: Value | C3: Data Sources
A4: Building Type | B4: Relocatable School
A5: Building Category | B5: Nonresidential
A6: Vintages | B6: 4 Vintages: Pre-1978, 1978-1997,1998-2007, 2008-2018 New Construction (2019+) | C6: Based on the vintage bin analysis | D6: NonRes-Vintage bins-Draft Report-30Nov2023-Final.docx
A7: Shape | C7: The analysis uses prototype geometry originally developed by CEC.
A8: Total Floor Area (ft²) | B8: 1920.19 | C8: Same as CEC
A9: Aspect Ratio | B9: =40/24 -> 1.6666667 | C9: Same as CEC
A10: Number of Floors | B10: 1 | C10: Same as CEC
A11: Roof type | B11: Flat | C11: Same as CEC
A12: WWR | B12: 0.0515 | C12: Same as CEC
A13: Shading Geometry | B13: No Shades | C13: Same as CEC
A14: Floor to floor height (feet) | B14: 12 ft | C14: Same as CEC
A15: Floor to ceiling height (feet) | B15: 12 ft | C15: Same as CEC
A16: Glazing sill height (feet) | B16: 2.9 ft | C16: Same as CEC
A20: Above grade wall area (ft²) | B20: 1536.15
A21: Gross wall area (ft²) | B21: =B20+B23 -> 1920.15
A22: Roof area (ft²) | B22: 960.09
A23: Underground Gross Wall Area (ft²) | B23: =(72+120)*2 -> 384

Sheet Zones
A1: ="Proposed Layout - "&Prototype!A2 -> Proposed Layout - SchoolRelocatable
A2: Space Type | B2: Space/Thermal Zone | C2: HVAC System Name/AHU Name | D2: Schedule Category | E2: Conditioned (Y/N) | F2: Area Fraction | G2: Area (ft²) | H2: Volume (ft³) | I2: Multipliers | J2: Number of People | K2: People (Persons/1,000 ft²) [T24, 2025,Table 120.1-A]
A3: Classroom, Lecture, Training, Vocational Areas | B3: Classroom | C3: BaseAirSys5 | D3: Classroom | E3: Y | F3: =G3/$G$5 -> 0.5 | G3: 960 | H3: 11521.69 | I3: 1 | J3: =K3*G3/1000 -> 48 | K3: 50
A4: Unoccupied-Exclude from Gross Floor Area | B4: Crawlspace | E4: N | F4: =G4/$G$5 -> 0.5 | G4: 960 | H4: 2884 | I4: 1
A5: Total (2 Space types) | B5: Total (2 spaces) | C5: Total ( 1 HVAC zone) | D5: Total (1 Schedule categories) | E5: Total (1 Conditioned zones) | F5: =G5/$G$5 -> 1 | G5: =SUM(G3:G4) -> 1920 | H5: =SUM(H3:H4) -> 14405.69 | J5: =SUM(J3:J4) -> 48 | K5: =K3 -> 50

Sheet HVAC System
A1: ="HVAC system - "&Prototype!A2 -> HVAC system - SchoolRelocatable
A2: Vintage | B2: Zones | C2: Heating | D2: Cooling | E2: Air Distribution | F2: Other System | G2: Source | H2: Note
A3: Existing | B3: Classroom, Lecture, Training, Vocational Areas | C3: SPVHP | D3: DX Coil | E3: CAV | F3: Economizer* Fix Dry bulb; integrated; High DB Temperature Lockout: 75 °F | G3: ACM 2025 | H3: System 3b
A4: New Construction | B4: Classroom, Lecture, Training, Vocational Areas | C4: SPVHP | D4: DX Coil | E4: CAV | F4: Economizer* Fix Dry bulb; integrated; High DB Temperature Lockout: 75 °F | G4: ACM 2025 | H4: System 3b
A9: Efficiency of HVAC system
A10: Vintage | B10: Upgrade/Installed year | C10: Heating DX | D10: Supplumentary Heating Coil | E10: Cooling DX | F10: Source | H10: Note
A11: Pre 1978 | B11: 2008 | C11: COP = 3 | D11: Efficiency: 100% (Electric) | E11: EER = 9.0 | F11: 10 CFR 431.97, Table 10 to paragraph (e)(2): SPVHP <65,000 Btu/h → EER 9.0, COP 3.0 (federal standard effective Jan 1, 2010; used here for legacy/vintage modeling consistency) | H11: System 3b
A12: 1978-1997
A13: 1998-2007
A14: 2008-2018 | B14: 2013 | C14: COP = 3 | D14: Efficiency: 100% (Electric) | E14: EER = 9.0 | F14: 10 CFR 431.97, Table 10 to paragraph (e)(2): SPVHP <65,000 Btu/h → EER 9.0, COP 3.0 (still governing in 2013; later update came in 2019)
A15: New Construction | B15: 2025 | C15: COP = 3.3 | D15: Efficiency: 100% (Electric) | E15: EER = 11.0 | F15: CEC 2025 Space-Conditioning Efficiency Tables, Table 5 (row: SPVHP <65,000 Btu/h → EER 11.0, COP 3.3, test AHRI 390). The table cites 10 CFR 431 Subpart F as the federal basis | H15: System 3b
A18: Fan power
A19: Vintage | B19: Approach | C19: System | D19: Total Static Pressure (TSP) | E19: Fan Efficiency | F19: Fan Motor and Drive Efficiency | G19: W/cfm | H19: Note
A20: Existing | B20: ACM 2025 | C20: CAV | D20: =G20*$F$20*$E$20/746*6356 -> 1.744492 | E20: 0.65 | F20: 0.9 | G20: 0.35 | H20: Engineering Judgment
A21: Brake horse power (bhp)=(Supply cfm*TSP in w.c.)/(6356*Fan efficiency)
A22: Fan power (w/cfm) = bhp/motor and drive efficiency *746
A23: New Construction | B23: ACM 2025 | C23: CAV | D23: =G23*$F$23*$E$23/746*6356 -> 1.744492 | E23: 0.65 | F23: 0.9 | G23: 0.35 | H23: Engineering Judgment
F24: * 0.9 is an average fan efficiency according to ACM 2025, Table 14
A25: Fan total eff (E+ input) = 0.65 x Motor_eff
A26: TSP (E+ input) in w.c. = Motor_eff/746 x (6356 x Fan_eff) x W/cfm
A27: Fan_eff=0.65
A31: Background Data [To be deleted prior to publication]

Sheet Envelope
A1: ="Envelope - "&Prototype!A2 -> Envelope - SchoolRelocatable
A2: Element | B2: Prototype | C2: Assembly Type | D2: Construction | E2: Thermal Properties | F2: Vintage | G2: Selected T24 | H2: Note | I2: CZ1 | J2: CZ2 | K2: CZ3 | L2: CZ4 | M2: CZ5 | N2: CZ6 | O2: CZ7 | P2: CZ8 | Q2: CZ9 | R2: CZ10 | S2: CZ11 | T2: CZ12 | U2: CZ13 | V2: CZ14 | W2: CZ15 | X2: CZ16
A3: External Wall | B3: =Prototype!$A$2 -> SchoolRelocatable | C3: ExtWall_MetalFramed_NonRes | D3: Metal-framed walls + insulation + Gypsum board | E3: U-factor IP | F3: Pre 1978 | G3: N/A | H3: ASHRAE 90.1, 2022, Table A3.3.3.1, 3.5", R-0 | I3: 0.292 | J3: 0.292 | K3: 0.292 | L3: 0.292 | M3: 0.292 | N3: 0.292 | O3: 0.292 | P3: 0.292 | Q3: 0.292 | R3: 0.292 | S3: 0.292 | T3: 0.292 | U3: 0.292 | V3: 0.292 | W3: 0.292 | X3: 0.292
F4: 1978-1997 | G4: 1986 | H4: Heat Capacity was considered 10.0-14.99 (Btu/F-ft²) | I4: 0.15082956 | J4: 0.15748031 | K4: 0.15748031 | L4: 0.14367816 | M4: 0.14367816 | N4: 0.21645022 | O4: 0.21645022 | P4: 0.21645022 | Q4: 0.21645022 | R4: 0.21645022 | S4: 0.18621974 | T4: 0.18621974 | U4: 0.18621974 | V4: 0.15873016 | W4: 0.15873016 | X4: 0.15082956
F5: 1998-2007 | G5: 2001 | H5: TABLE 1-H-NonRes Bldgs | I5: 0.182 | J5: 0.182 | K5: 0.189 | L5: 0.189 | M5: 0.189 | N5: 0.189 | O5: 0.189 | P5: 0.189 | Q5: 0.189 | R5: 0.182 | S5: 0.182 | T5: 0.182 | U5: 0.182 | V5: 0.182 | W5: 0.182 | X5: 0.182
F6: 2008-2018 | G6: 2013 | H6: TABLE 140.3-B-NonRes Bldgs | I6: 0.098 | J6: 0.062 | K6: 0.082 | L6: 0.062 | M6: 0.062 | N6: 0.098 | O6: 0.098 | P6: 0.062 | Q6: 0.062 | R6: 0.062 | S6: 0.062 | T6: 0.062 | U6: 0.062 | V6: 0.062 | W6: 0.062 | X6: 0.062
F7: 2019+ | G7: 2025 | H7: TABLE 140.3-B-NonRes Bldgs | I7: 0.06 | J7: 0.055 | K7: 0.071 | L7: 0.055 | M7: 0.055 | N7: 0.06 | O7: 0.06 | P7: 0.055 | Q7: 0.055 | R7: 0.055 | S7: 0.055 | T7: 0.055 | U7: 0.055 | V7: 0.055 | W7: 0.055 | X7: 0.055
A8: Roof | B8: =Prototype!$A$2 -> SchoolRelocatable | C8: FlatRoof_WoodFramedAndOther_NonRes | D8: Built-up Roof steel truss + cavity insulation + plywood deck + above deck insulation + membrane + coverboard | E8: U-value IP | F8: Pre 1978 | G8: N/A | H8: Considering 30 years for roof/ insulation replacement. | I8: 0.057 | J8: 0.057 | K8: 0.057 | L8: 0.057 | M8: 0.057 | N8: 0.078 | O8: 0.078 | P8: 0.078 | Q8: 0.078 | R8: 0.078 | S8: 0.057 | T8: 0.057 | U8: 0.057 | V8: 0.057 | W8: 0.057 | X8: 0.057
F9: 1978-1997 | G9: 1986 | I9: 0.057 | J9: 0.057 | K9: 0.057 | L9: 0.057 | M9: 0.057 | N9: 0.078 | O9: 0.078 | P9: 0.078 | Q9: 0.078 | R9: 0.078 | S9: 0.057 | T9: 0.057 | U9: 0.057 | V9: 0.057 | W9: 0.057 | X9: 0.057
F10: 1998-2007 | G10: 2001 | H10: Table 1-H | I10: 0.057 | J10: 0.057 | K10: 0.057 | L10: 0.057 | M10: 0.057 | N10: 0.078 | O10: 0.078 | P10: 0.078 | Q10: 0.078 | R10: 0.057 | S10: 0.057 | T10: 0.057 | U10: 0.057 | V10: 0.057 | W10: 0.057 | X10: 0.057
F11: 2008-2018 | G11: 2013 | H11: Table 140.3-B | I11: 0.049 | J11: 0.039 | K11: 0.039 | L11: 0.039 | M11: 0.049 | N11: 0.075 | O11: 0.067 | P11: 0.067 | Q11: 0.039 | R11: 0.039 | S11: 0.039 | T11: 0.039 | U11: 0.039 | V11: 0.039 | W11: 0.039 | X11: 0.039
F12: 2019+ | G12: 2025 | H12: Table 140.3-B | I12: 0.028 | J12: 0.028 | K12: 0.028 | L12: 0.028 | M12: 0.028 | N12: 0.047 | O12: 0.047 | P12: 0.047 | Q12: 0.028 | R12: 0.028 | S12: 0.028 | T12: 0.028 | U12: 0.028 | V12: 0.028 | W12: 0.028 | X12: 0.028
A13: Windows_Nonrs | B13: =Prototype!$A$2 -> SchoolRelocatable | C13: OperableWindow_NonRes | D13: CBECS 2018 shows that ~58% of Large Hotels that were built before 2000 are single pane | E13: U-factor IP | F13: Pre 1978 | G13: N/A | H13: ASHRAE Handbook of Fundamentals for single pane & T24, 2013 for double pane (58%-42%) | I13: =I$15*0.42+0.78*0.58 -> 0.6582 | J13: =J$15*0.42+0.78*0.58 -> 0.6582 | K13: =K$15*0.42+0.78*0.58 -> 0.7926 | L13: =L$15*0.42+0.78*0.58 -> 0.7926 | M13: =M$15*0.42+0.78*0.58 -> 0.7926 | N13: =N$15*0.42+0.78*0.58 -> 0.7926 | O13: =O$15*0.42+0.78*0.58 -> 0.7926 | P13: =P$15*0.42+0.78*0.58 -> 0.7926 | ... X13: =X$15*0.42+0.78*0.58 -> 0.6582
F14: 1978-1997 | G14: N/A | I14: =I$15*0.42+0.78*0.58 -> 0.6582 | J14: =J$15*0.42+0.78*0.58 -> 0.6582 | K14: =K$15*0.42+0.78*0.58 -> 0.7926 | L14: =L$15*0.42+0.78*0.58 -> 0.7926 | M14: =M$15*0.42+0.78*0.58 -> 0.7926 | N14: =N$15*0.42+0.78*0.58 -> 0.7926 | O14: =O$15*0.42+0.78*0.58 -> 0.7926 | P14: =P$15*0.42+0.78*0.58 -> 0.7926 | ... X14: =X$15*0.42+0.78*0.58 -> 0.6582
D15: Double pane | F15: 1998-2007 | G15: 2001 | H15: Table1-H | I15: 0.49 | J15: 0.49 | K15: 0.81 | L15: 0.81 | M15: 0.81 | N15: 0.81 | O15: 0.81 | P15: 0.81 | Q15: 0.81 | R15: 0.49 | S15: 0.49 | T15: 0.49 | U15: 0.49 | V15: 0.49 | W15: 0.49 | X15: 0.49
F16: 2008-2018 | G16: 2013 | H16: Table 140.3-B | I16: 0.46 | J16: 0.46 | K16: 0.46 | L16: 0.46 | M16: 0.46 | N16: 0.46 | O16: 0.46 | P16: 0.46 | Q16: 0.46 | R16: 0.46 | S16: 0.46 | T16: 0.46 | U16: 0.46 | V16: 0.46 | W16: 0.46 | X16: 0.46
F17: 2019+ | G17: 2025 | H17: Table 140.3-B | I17: 0.46 | J17: 0.46 | K17: 0.46 | L17: 0.46 | M17: 0.46 | N17: 0.46 | O17: 0.46 | P17: 0.46 | Q17: 0.46 | R17: 0.46 | S17: 0.46 | T17: 0.46 | U17: 0.46 | V17: 0.46 | W17: 0.46 | X17: 0.46
B18: =Prototype!$A$2 -> SchoolRelocatable | D18: CBECS 2018 shows that ~58% of Large Hotels that were built before 2000 are single pane | E18: SHGC | F18: Pre 1978 | G18: N/A | H18: ASHRAE Handbook of Fundamentals for single pane & T24, 2013 for double pane (58%-42%) | I18: =I$15*0.42+1.23*0.58 -> 0.9192 | J18: =J$15*0.42+1.23*0.58 -> 0.9192 | K18: =K$15*0.42+1.23*0.58 -> 1.0536 | L18: =L$15*0.42+1.23*0.58 -> 1.0536 | M18: =M$15*0.42+1.23*0.58 -> 1.0536 | N18: =N$15*0.42+1.23*0.58 -> 1.0536 | O18: =O$15*0.42+1.23*0.58 -> 1.0536 | P18: =P$15*0.42+1.23*0.58 -> 1.0536 | ... X18: =X$15*0.42+1.23*0.58 -> 0.9192
F19: 1978-1997 | G19: N/A | I19: =I$15*0.42+1.23*0.58 -> 0.9192 | J19: =J$15*0.42+1.23*0.58 -> 0.9192 | K19: =K$15*0.42+1.23*0.58 -> 1.0536 | L19: =L$15*0.42+1.23*0.58 -> 1.0536 | M19: =M$15*0.42+1.23*0.58 -> 1.0536 | N19: =N$15*0.42+1.23*0.58 -> 1.0536 | O19: =O$15*0.42+1.23*0.58 -> 1.0536 | P19: =P$15*0.42+1.23*0.58 -> 1.0536 | ... X19: =X$15*0.42+1.23*0.58 -> 0.9192
D20: Double pane | F20: 1998-2007 | G20: 2001 | H20: Table 1-H (based on non north with WWR 30-40% ) | I20: 0.45 | J20: 0.39 | K20: 0.51 | L20: 0.51 | M20: 0.51 | N20: 0.475 | O20: 0.475 | P20: 0.475 | Q20: 0.475 | R20: 0.39 | S20: 0.39 | T20: 0.39 | U20: 0.39 | V20: 0.39 | W20: 0.39 | X20: 0.45
F21: 2008-2018 | G21: 2013 | H21: Table 140.3-B (100% fixed, 0% operable) | I21: 0.22 | J21: 0.22 | K21: 0.22 | L21: 0.22 | M21: 0.22 | N21: 0.22 | O21: 0.22 | P21: 0.22 | Q21: 0.22 | R21: 0.22 | S21: 0.22 | T21: 0.22 | U21: 0.22 | V21: 0.22 | W21: 0.22 | X21: 0.22
F22: 2019+ | G22: 2025 | H22: Table 140.3-B (100% fixed, 0% operable) | I22: 0.22 | J22: 0.22 | K22: 0.22 | L22: 0.22 | M22: 0.22 | N22: 0.22 | O22: 0.22 | P22: 0.22 | Q22: 0.22 | R22: 0.22 | S22: 0.22 | T22: 0.22 | U22: 0.22 | V22: 0.22 | W22: 0.22 | X22: 0.22
A23: * California Legislature Environmental Health Condions in California's Portable Classrooms
E25: Infiltration
F26: Vintage | G26: I_75 6-Sided Inifltration rate @ 75 pa | H26: Note | I26: I-design (cfm/ft²) (4-sided Infiltration rate at normal presure) (Design flow rate approach and Flow/Exterior Wall Area calulation method) | AU26: 0.028 | AW26: 0.028
E27: Infiltration | F27: Pre 1978 | G27: 1.1 | H27: 2022 CASE report (Table 38) | I27: 0.308
F28: 1978-1997 | G28: 1.1 | H28: 2022 CASE report (Table 38) | I28: 0.308
F29: 1998-2007 | G29: 1.1 | H29: 2022 CASE report (Table 38) | I29: 0.308
F30: 2008-2018 | G30: 1 | H30: 2022 CASE report (Table 38) & T24, 2008-2016 (Table 140.3-B)--Air barrier is required in CZ 10-16 | I30: 0.2818
F31: 2019+ | G31: 0.6 | H31: 2022 CASE report (Table 38) & T24, 2025 (Table 140.3-B)--Air barrier is required in all CZs | I31: 0.168
E32: Source: T24 air barrier requirements (all editions) and the standardized infiltration rate reported in the 2022 CASE report and Dodge 2023 data
E33: Air Lekage Memo: | G33: Infiltration_rate_report_14May2025-Short-Version.docx

Sheet Thermostat
A1: ="Thermostat Setpoints - "&Prototype!A2 -> Thermostat Setpoints - SchoolRelocatable
A2: Setpoint | B2: CZ1 | C2: CZ2 | D2: CZ3 | E2: CZ4 | F2: CZ5 | G2: CZ6 | H2: CZ7 | I2: CZ8 | J2: CZ9 | K2: CZ10 | L2: CZ11 | M2: CZ12 | N2: CZ13 | O2: CZ14 | P2: CZ15 | Q2: CZ16 | R2: Source
A3: School Heating Setpoint (F) | B3: 70 | C3: 70 | D3: 70 | E3: 70 | F3: 70 | G3: 70 | H3: 70 | I3: 70 | J3: 70 | K3: 70 | L3: 70 | M3: 70 | N3: 70 | O3: 70 | P3: 70 | Q3: 70 | R3: T24 2022 - Appendix 5.4B
A4: School Heating Setback (F) | B4: 60 | C4: 60 | D4: 60 | E4: 60 | F4: 60 | G4: 60 | H4: 60 | I4: 60 | J4: 60 | K4: 60 | L4: 60 | M4: 60 | N4: 60 | O4: 60 | P4: 60 | Q4: 60
A5: School Cooling Setpoint (F) | B5: 75 | C5: 75 | D5: 75 | E5: 75 | F5: 75 | G5: 75 | H5: 75 | I5: 75 | J5: 75 | K5: 75 | L5: 75 | M5: 75 | N5: 75 | O5: 75 | P5: 75 | Q5: 75 | R5: T24 2022 - Appendix 5.4B
A6: School Cooling Setback (F) | B6: 85 | C6: 85 | D6: 85 | E6: 85 | F6: 85 | G6: 85 | H6: 85 | I6: 85 | J6: 85 | K6: 85 | L6: 85 | M6: 85 | N6: 85 | O6: 85 | P6: 85 | Q6: 85

Sheet Ventilation
A1: ="Outdoor Airflow Rate - "&Prototype!A2 -> Outdoor Airflow Rate - SchoolRelocatable
A2: Space Type | B2: Space/Thermal Zone | C2: Number of People | D2: Floor Area (ft²) | E2: cfm/person [T24, 2025, Equation 120.1-F and Table 120.1-A] | F2: cfm/ft² [T24, 2025, Equation 120.1-F and Table 120.1-A] | G2: Required exhaust rate-CFM/ft²- [T24, 2025, Table 120.1-B – minimum exhaust rates] | H2: Total cfm driven by people | I2: Total cfm driven by area | J2: Total cfm driven by exhaust | K2: Total cfm | L2: Notes
A3: =Zones!A3 -> Classroom, Lecture, Training, Vocational Areas | B3: =Zones!B3 -> Classroom | C3: =Zones!J3 -> 48 | D3: =Zones!G3 -> 960 | E3: 15 | F3: 0.15 | H3: =C3*E3 -> 720 | I3: =D3*F3 -> 144 | J3: =G3*D3 -> 0 | K3: =MAX(H3,I3,J3) -> 720
A4: =Zones!A4 -> Unoccupied-Exclude from Gross Floor Area | B4: =Zones!B4 -> Crawlspace | C4: =Zones!J4 -> 0 | D4: =Zones!G4 -> 960 | H4: =C4*E4 -> 0 | I4: =D4*F4 -> 0 | J4: =G4*D4 -> 0 | K4: =MAX(H4,I4,J4) -> 0
A5: =Zones!A5 -> Total (2 Space types) | B5: =Zones!B5 -> Total (2 spaces) | C5: =Zones!J5 -> 48 | D5: =Zones!G5 -> 1920 | H5: =SUM(H3:H4) -> 720 | I5: =SUM(I3:I4) -> 144 | J5: =SUM(J3:J4) -> 0 | K5: =SUM(K3:K4) -> 720

Sheet Water Heater
A1: ="Water Heater -"&Prototype!A2 -> Water Heater -SchoolRelocatable
A2: Vintage | B2: WH Type | C2: Efficiency | D2: Tank Volume (gal) | E2: Tank Loss | G2: Note
A3: Existing | B3: Electric | C3: 1 | D3: =F17 -> 2 | E3: =G20 -> 0 | F3: (Btu/hr)
A4: New Construction | B4: Electric | C4: 1 | D4: =F15 -> 2 | E4: =G15 -> 0 | F4: (%/hr) | G4: Section 1605.1. Federal and State Standards for Federally-Regulated Appliances.
A6: Peak Hot Water Consumption
A7: Space Name | B7: Baseline WH Type [T24, 2022, Appendix 5.4A , sheet: "2022 SpaceFuncData-Input"] | C7: New Construction: Baseline WH Type ACM 2025 | D7: Total Area (ft²) | E7: Number of People | F7: Hot Water Usage Specification (gal/hr per person) [T24, 2022, Appendix 5.4A , sheet: "2022 SpaceFuncData-Input"] | G7: Peak Hot Water Usage (gal/hr) | H7: Peak Hot Water Usage (gal/min)
A8: =Zones!B3 -> Classroom | B8: Electric | D8: =Zones!G3 -> 960 | E8: =Zones!J3 -> 48 | F8: 0.18 | G8: =F8*E8 -> 8.64 | H8: =G8/60 -> 0.144
A9: Total | D9: =SUM(D8:D8) -> 960 | E9: =SUM(E8:E8) -> 48 | F9: =F8 -> 0.18 | G9: =SUM(G8:G8) -> 8.64 | H9: =G9/60 -> 0.144
A13: Water Heater Capacity, Tank Capacity, and Tank Loss
A14: WH Type | B14: Peak Hot Water Usage (gal/hr) | C14: Heat Output (Btu/hr) [ACM, 2025, 5.9.2: Rated capacity section] | D14: WH Capacity (Btu/hr) [ACM, 2025, 5.9.2: Rated capacity section] | E14: Required Energy Input (Btu/hr) | F14: Storage Volume (gal) | G14: Standby Loss | H14: Unit | I14: Off/On Cycle Loss Coefficient to Ambient Temp (Btu/h-F) | J14: Source
A15: Electric WH | B15: =B22*60 -> 30 | C15: =B15*(B23-B24)*8.2877*1 -> 19890.48 | D15: =C15 -> 19890.48 | E15: =D15/0.98 -> 20296.408 | F15: 2 | G15: 0 | H15: %hr | I15: =0.0834*G15*F15 -> 0 | J15: Standby loss equation: Title 20, §1605.1 Table F-4 WH capacity equation: ACM, 2025, 5.9.2: Rated capacity section)
A16: -
A17: Total | B17: =B15 -> 30 | C17: =B17*(135-55)*8.2877*1 -> 19890.48 | D17: =C17 -> 19890.48 | E17: =SUM(E15:E15) -> 20296.408 | F17: 2 | G17: 0 | H17: %hr | I17: 0
F20: Standby Loss for Existing | G20: =G17 -> 0 | H20: Btu/hr
A22: Maximum flow rate (GPM) | B22: 0.5 | C22: CALGreen §5.303.3.4.1 (Title 24, Part 11, 2025)
A23: Design supply temperature (F) | B23: 135 | C23: Ref: T24 2022 - Appendix 5.4B
A24: Cold Water supply temperature (F) | B24: 55 | C24: Ref: ACM, 2025, 5.9.2: Rated capacity section
A25: WH system factor | B25: 0.6 | C25: Ref: ACM, 2025, 5.9.2: Rated capacity section
A26: Reheat multiplier | B26: 0.4
A27: * The 0.40 multiplier is a storage sizing factor used to account for the fact that the water heater doesn't need to store the full peak hour demand—it can reheat water during that time. This factor assumes that the heater will recover part of the hot water used during the peak hour, so only 40% of the peak hour demand needs to be stored at any given moment.
A28: **For Gas Water Heater: UA(Btu/h-°F)​=Q˙​SL​ (Btu/h)/ΔT (∘F)​
A29: Ambient temp | B29: 68
A30: Delta T | B30: =B23-B29 -> 67
A31: ** For Electric Water Heater: UA(Btu/h-°F)​= 0.0834 *SL​ (%/hr)*V gal
A33: Background Data [To be deleted prior to publication]

Sheet Interior Lights
A1: ="Interior Lighting - "&Prototype!A2 -> Interior Lighting - SchoolRelocatable
A2: Space Type | B2: New Construction | E2: Existing
B3: Lighting density (W/ft²) | C3: Additional lighting power for porTable lighting (W/ft²) | D3: Source | E3: LPD (W/ft²) | F3: Additional LPD for PorTable Lighting (W/ft²) | G3: Source
A4: =Zones!A3 -> Classroom, Lecture, Training, Vocational Areas | B4: 0.6 | D4: T24, 2025, Table 140.6 C (Area category method) | E4: 1.2 | G4: T24, 2016, Table 140.6 C (Area category method)
A5: =Zones!A4 -> Unoccupied-Exclude from Gross Floor Area | B5: 0 | E5: 0

Sheet Ext Lighting
A1: ="Exterior Lighting - "&Prototype!A2 -> Exterior Lighting - SchoolRelocatable
A2: Motion Controlled Luminaires (W) | B2: Non-motion Controlled Luminaires (W) | C2: Total (W) | D2: Source
A3: =G14 -> 200 | B3: =G15 -> 307.87207 | C3: =A3+B3 -> 507.87207 | D3: T24, 2022 & 2025 2019 Outdoor Lighting CASE report PNNL 90.1-2010 TSD
A7: ="Exterior Lighting" -> Exterior Lighting
A8: Items (Assume LZ2) | B8: Assumptions [2019 Outdoor Lighting CASE Report & PNNL 90.1-2010 TS] | D8: Unit | E8: Lighting Power Allowance [T24, 2025, Table 140.7-A & 140.7-B] | F8: Unit | G8: Exterior Lighting Power (W)
A9: IWA (Initial Wattage Allowance) | E9: 200 | F9: (W) | G9: =$E9 -> 200
A10: Parking area | B10: 400 ft² for every parking space 1 parking space per 830 ft² of gross building area | C10: 0 | D10: (ft²) | E10: 0.019 | F10: (W/ft²) | G10: =E10*C10 -> 0
A11: Building Entrance | B11: 5 building entrance per PNNL Model (1 per 10,000 ft² footprint) | C11: 0 | D11: (count) | E11: 15 | F11: (W/ea) | G11: =E11*C11 -> 0
A12: Hardscape Ornamental Light | B12: 0.1 ft² per 1 ft² of gross building area for hardscape ornamental light | C12: =B25*0.1 -> 96.0095 | D12: (ft²) | E12: 0.007 | F12: (W/ft²) | G12: =E12*C12 -> 0.6720665
A13: Building façade | B13: 0.1 W per 1 ft² of facade area Façade Area = Perimeter × 0.5 × max ( height and 30) (30 ft is the max height that is lit) * The 0.5 factor assumes that only half of the perimeter walls are lit. -Formula ia developed based on the 2019 Outdoor Lighting CASE report | C13: =0.5*4*(B23*B20) -> 3072 | D13: (ft²) | E13: 0.1 | F13: (W/ft²) | G13: =E13*C13 -> 307.2
A14: Motion Controlled Luminaires (W) | G14: =G10+G9+G11 -> 200
A15: Non-motion-controlled Luminaires | G15: =G12+G13 -> 307.87207
A16: Total | G16: =G14+G15 -> 507.87207
A20: Max Height (ft) | B20: 12
A21: Building footprint | B21: =B25/2 -> 480.0475
A22: Floors | B22: 1
A23: Perimeter(ft) | B23: =(24+40)*2 -> 128
A24: Background Data [To be deleted prior to publication]
A25: Total floor area (ft²) | B25: =Prototype!B8/2 -> 960.095

Sheet Equipment
A1: ="Equipment - "&Prototype!A2 -> Equipment - SchoolRelocatable
A2: Space Type | B2: Plug load Power Density (W/ft²) | C2: Gas Power Density (Btu/hr-ft²) | D2: Refrigeration Power Density (W/ft²) | E2: Source
A3: =Zones!A3 -> Classroom, Lecture, Training, Vocational Areas | B3: 0.8 | C3: 0 | D3: 0 | E3: T24 2022 - Appendix 5.4A
A4: =Zones!A4 -> Unoccupied-Exclude from Gross Floor Area | B4: 0 | C4: 0 | D4: 0

Sheet Schedules
A1: ="Schedules - "&Prototype!A2 -> Schedules - SchoolRelocatable
A2: Zone | B2: Schedule Category | C2: Schedule | D2: Source | E2: Type | F2: Hour
F3: 1 | G3: 2 | H3: 3 | I3: 4 | J3: 5 | K3: 6 | L3: 7 | M3: 8 | N3: 9 | O3: 10 | P3: 11 | Q3: 12 | R3: 13 | S3: 14 | T3: 15 | U3: 16 | V3: 17 | W3: 18 | X3: 19 | Y3: 20 | Z3: 21 | AA3: 22 | AB3: 23 | AC3: 24
A4: School Zones | B4: Classroom | C4: Occupancy | D4: T24 2022 - Appendix 5.4B [School] | E4: Weekday | F4: 0 | G4: 0 | H4: 0 | I4: 0 | J4: 0 | K4: 0 | L4: 0 | M4: 0.05 | N4: 0.75 | O4: 0.9 | P4: 0.9 | Q4: 0.8 | R4: 0.8 | S4: 0.8 | T4: 0.8 | U4: 0.45 | V4: 0.15 | W4: 0.05 | X4: 0.15 | Y4: 0.2 | Z4: 0.2 | AA4: 0.1 | AB4: 0 | AC4: 0
E5: Saturday | F5: 0 | G5: 0 | H5: 0 | I5: 0 | J5: 0 | K5: 0 | L5: 0 | M5: 0 | N5: 0.1 | O5: 0.1 | P5: 0.1 | Q5: 0.1 | R5: 0.1 | S5: 0 | T5: 0 | U5: 0 | V5: 0 | W5: 0 | X5: 0 | Y5: 0 | Z5: 0 | AA5: 0 | AB5: 0 | AC5: 0
E6: Sunday | F6: 0 | G6: 0 | H6: 0 | I6: 0 | J6: 0 | K6: 0 | L6: 0 | M6: 0 | N6: 0 | O6: 0 | P6: 0 | Q6: 0 | R6: 0 | S6: 0 | T6: 0 | U6: 0 | V6: 0 | W6: 0 | X6: 0 | Y6: 0 | Z6: 0 | AA6: 0 | AB6: 0 | AC6: 0
A7: School Zones | B7: Classroom | C7: Lights | D7: T24 2022 - Appendix 5.4B [School] | E7: Weekday | F7: 0.05 | G7: 0.05 | H7: 0.05 | I7: 0.05 | J7: 0.05 | K7: 0.05 | L7: 0.05 | M7: 0.3 | N7: 0.6 | O7: 0.65 | P7: 0.65 | Q7: 0.65 | R7: 0.55 | S7: 0.55 | T7: 0.55 | U7: 0.5 | V7: 0.35 | W7: 0.35 | X7: 0.35 | Y7: 0.35 | Z7: 0.35 | AA7: 0.3 | AB7: 0.05 | AC7: 0.05
E8: Saturday | F8: 0.05 | G8: 0.05 | H8: 0.05 | I8: 0.05 | J8: 0.05 | K8: 0.05 | L8: 0.05 | M8: 0.05 | N8: 0.15 | O8: 0.15 | P8: 0.15 | Q8: 0.15 | R8: 0.15 | S8: 0.05 | T8: 0.05 | U8: 0.05 | V8: 0.05 | W8: 0.05 | X8: 0.05 | Y8: 0.05 | Z8: 0.05 | AA8: 0.05 | AB8: 0.05 | AC8: 0.05
E9: Sunday | F9: 0.05 | G9: 0.05 | H9: 0.05 | I9: 0.05 | J9: 0.05 | K9: 0.05 | L9: 0.05 | M9: 0.05 | N9: 0.05 | O9: 0.05 | P9: 0.05 | Q9: 0.05 | R9: 0.05 | S9: 0.05 | T9: 0.05 | U9: 0.05 | V9: 0.05 | W9: 0.05 | X9: 0.05 | Y9: 0.05 | Z9: 0.05 | AA9: 0.05 | AB9: 0.05 | AC9: 0.05
A10: School Zones | B10: Classroom | C10: ElecEquipment | D10: T24 2022 - Appendix 5.4B [School] | E10: Weekday | F10: 0.05 | G10: 0.05 | H10: 0.05 | I10: 0.05 | J10: 0.05 | K10: 0.05 | L10: 0.05 | M10: 0.3 | N10: 0.85 | O10: 0.95 | P10: 0.95 | Q10: 0.95 | R10: 0.8 | S10: 0.8 | T10: 0.8 | U10: 0.7 | V10: 0.5 | W10: 0.5 | X10: 0.35 | Y10: 0.35 | Z10: 0.35 | AA10: 0.3 | AB10: 0.05 | AC10: 0.05
E11: Saturday | F11: 0.05 | G11: 0.05 | H11: 0.05 | I11: 0.05 | J11: 0.05 | K11: 0.05 | L11: 0.05 | M11: 0.05 | N11: 0.15 | O11: 0.15 | P11: 0.15 | Q11: 0.15 | R11: 0.15 | S11: 0.05 | T11: 0.05 | U11: 0.05 | V11: 0.05 | W11: 0.05 | X11: 0.05 | Y11: 0.05 | Z11: 0.05 | AA11: 0.05 | AB11: 0.05 | AC11: 0.05
E12: Sunday | F12: 0.05 | G12: 0.05 | H12: 0.05 | I12: 0.05 | J12: 0.05 | K12: 0.05 | L12: 0.05 | M12: 0.05 | N12: 0.05 | O12: 0.05 | P12: 0.05 | Q12: 0.05 | R12: 0.05 | S12: 0.05 | T12: 0.05 | U12: 0.05 | V12: 0.05 | W12: 0.05 | X12: 0.05 | Y12: 0.05 | Z12: 0.05 | AA12: 0.05 | AB12: 0.05 | AC12: 0.05
A13: School Zones | B13: Classroom | C13: ServiceHotWater | D13: T24 2022 - Appendix 5.4B [School] | E13: Weekday | F13: 0.05 | G13: 0.05 | H13: 0.05 | I13: 0.05 | J13: 0.05 | K13: 0.05 | L13: 0.05 | M13: 0.1 | N13: 0.34 | O13: 0.6 | P13: 0.63 | Q13: 0.72 | R13: 0.79 | S13: 0.83 | T13: 0.61 | U13: 0.65 | V13: 0.1 | W13: 0.1 | X13: 0.19 | Y13: 0.25 | Z13: 0.22 | AA13: 0.22 | AB13: 0.12 | AC13: 0.09
E14: Saturday | F14: 0.03 | G14: 0.03 | H14: 0.03 | I14: 0.03 | J14: 0.03 | K14: 0.03 | L14: 0.03 | M14: 0.03 | N14: 0.03 | O14: 0.05 | P14: 0.05 | Q14: 0.05 | R14: 0.05 | S14: 0.03 | T14: 0.03 | U14: 0.03 | V14: 0.03 | W14: 0.03 | X14: 0.03 | Y14: 0.03 | Z14: 0.03 | AA14: 0.03 | AB14: 0.03 | AC14: 0.03
E15: Sunday | F15: 0.03 | G15: 0.03 | H15: 0.03 | I15: 0.03 | J15: 0.03 | K15: 0.03 | L15: 0.03 | M15: 0.03 | N15: 0.05 | O15: 0.05 | P15: 0.05 | Q15: 0.05 | R15: 0.05 | S15: 0.05 | T15: 0.03 | U15: 0.03 | V15: 0.03 | W15: 0.03 | X15: 0.03 | Y15: 0.03 | Z15: 0.03 | AA15: 0.03 | AB15: 0.03 | AC15: 0.03
A16: School Zones | B16: Classroom | C16: GasEquipment | D16: T24 2022 - Appendix 5.4B [School] | E16: Weekday | F16: 0 | G16: 0 | H16: 0 | I16: 0 | J16: 0 | K16: 0 | L16: 0 | M16: 0.5 | N16: 0.5 | O16: 0.75 | P16: 0.9 | Q16: 0.9 | R16: 0.9 | S16: 0 | T16: 0 | U16: 0 | V16: 0 | W16: 0 | X16: 0 | Y16: 0 | Z16: 0 | AA16: 0 | AB16: 0 | AC16: 0
E17: Saturday | F17: 0 | G17: 0 | H17: 0 | I17: 0 | J17: 0 | K17: 0 | L17: 0 | M17: 0 | N17: 0 | O17: 0 | P17: 0 | Q17: 0 | R17: 0 | S17: 0 | T17: 0 | U17: 0 | V17: 0 | W17: 0 | X17: 0 | Y17: 0 | Z17: 0 | AA17: 0 | AB17: 0 | AC17: 0
E18: Sunday | F18: 0 | G18: 0 | H18: 0 | I18: 0 | J18: 0 | K18: 0 | L18: 0 | M18: 0 | N18: 0 | O18: 0 | P18: 0 | Q18: 0 | R18: 0 | S18: 0 | T18: 0 | U18: 0 | V18: 0 | W18: 0 | X18: 0 | Y18: 0 | Z18: 0 | AA18: 0 | AB18: 0 | AC18: 0
A19: School Zones | B19: Classroom | C19: Refrigeration | D19: T24 2022 - Appendix 5.4B [School] | E19: Weekday | F19: 0.9 | G19: 0.9 | H19: 0.9 | I19: 0.9 | J19: 0.9 | K19: 0.9 | L19: 0.9 | M19: 0.9 | N19: 0.9 | O19: 0.9 | P19: 0.9 | Q19: 0.9 | R19: 0.9 | S19: 0.9 | T19: 0.9 | U19: 0.9 | V19: 0.9 | W19: 0.9 | X19: 0.9 | Y19: 0.9 | Z19: 0.9 | AA19: 0.9 | AB19: 0.9 | AC19: 0.9
E20: Saturday | F20: 0.9 | G20: 0.9 | H20: 0.9 | I20: 0.9 | J20: 0.9 | K20: 0.9 | L20: 0.9 | M20: 0.9 | N20: 0.9 | O20: 0.9 | P20: 0.9 | Q20: 0.9 | R20: 0.9 | S20: 0.9 | T20: 0.9 | U20: 0.9 | V20: 0.9 | W20: 0.9 | X20: 0.9 | Y20: 0.9 | Z20: 0.9 | AA20: 0.9 | AB20: 0.9 | AC20: 0.9
E21: Sunday | F21: 0.9 | G21: 0.9 | H21: 0.9 | I21: 0.9 | J21: 0.9 | K21: 0.9 | L21: 0.9 | M21: 0.9 | N21: 0.9 | O21: 0.9 | P21: 0.9 | Q21: 0.9 | R21: 0.9 | S21: 0.9 | T21: 0.9 | U21: 0.9 | V21: 0.9 | W21: 0.9 | X21: 0.9 | Y21: 0.9 | Z21: 0.9 | AA21: 0.9 | AB21: 0.9 | AC21: 0.9
A22: School Zones | B22: Classroom | C22: HVACAvail | D22: T24 2022 - Appendix 5.4B [School] | E22: Weekday | F22: 0 | G22: 0 | H22: 0 | I22: 0 | J22: 0 | K22: 0 | L22: 1 | M22: 1 | N22: 1 | O22: 1 | P22: 1 | Q22: 1 | R22: 1 | S22: 1 | T22: 1 | U22: 1 | V22: 1 | W22: 1 | X22: 1 | Y22: 1 | Z22: 1 | AA22: 1 | AB22: 0 | AC22: 0
E23: Saturday | F23: 0 | G23: 0 | H23: 0 | I23: 0 | J23: 0 | K23: 0 | L23: 0 | M23: 1 | N23: 1 | O23: 1 | P23: 1 | Q23: 1 | R23: 1 | S23: 0 | T23: 0 | U23: 0 | V23: 0 | W23: 0 | X23: 0 | Y23: 0 | Z23: 0 | AA23: 0 | AB23: 0 | AC23: 0
E24: Sunday | F24: 0 | G24: 0 | H24: 0 | I24: 0 | J24: 0 | K24: 0 | L24: 0 | M24: 0 | N24: 0 | O24: 0 | P24: 0 | Q24: 0 | R24: 0 | S24: 0 | T24: 0 | U24: 0 | V24: 0 | W24: 0 | X24: 0 | Y24: 0 | Z24: 0 | AA24: 0 | AB24: 0 | AC24: 0
A25: School Zones | B25: Classroom | C25: HtgSetpt | D25: T24 2022 - Appendix 5.4B | E25: Weekday | F25: =IF(F22=0,Thermostat!$B$4,Thermostat!$B$3) -> 60 | G25: =IF(G22=0,Thermostat!$B$4,Thermostat!$B$3) -> 60 | H25: =IF(H22=0,Thermostat!$B$4,Thermostat!$B$3) -> 60 | I25: =IF(I22=0,Thermostat!$B$4,Thermostat!$B$3) -> 60 | J25: =IF(J22=0,Thermostat!$B$4,Thermostat!$B$3) -> 60 | K25: =IF(K22=0,Thermostat!$B$4,Thermostat!$B$3) -> 60 | L25: =IF(L22=0,Thermostat!$B$4,Thermostat!$B$3) -> 70 | M25: =IF(M22=0,Thermostat!$B$4,Thermostat!$B$3) -> 70 | ... AC25: =IF(AC22=0,Thermostat!$B$4,Thermostat!$B$3) -> 60
E26: Saturday | F26: =IF(F23=0,Thermostat!$B$4,Thermostat!$B$3) -> 60 | G26: =IF(G23=0,Thermostat!$B$4,Thermostat!$B$3) -> 60 | H26: =IF(H23=0,Thermostat!$B$4,Thermostat!$B$3) -> 60 | I26: =IF(I23=0,Thermostat!$B$4,Thermostat!$B$3) -> 60 | J26: =IF(J23=0,Thermostat!$B$4,Thermostat!$B$3) -> 60 | K26: =IF(K23=0,Thermostat!$B$4,Thermostat!$B$3) -> 60 | L26: =IF(L23=0,Thermostat!$B$4,Thermostat!$B$3) -> 60 | M26: =IF(M23=0,Thermostat!$B$4,Thermostat!$B$3) -> 70 | ... AC26: =IF(AC23=0,Thermostat!$B$4,Thermostat!$B$3) -> 60
E27: Sunday | F27: =IF(F24=0,Thermostat!$B$4,Thermostat!$B$3) -> 60 | G27: =IF(G24=0,Thermostat!$B$4,Thermostat!$B$3) -> 60 | H27: =IF(H24=0,Thermostat!$B$4,Thermostat!$B$3) -> 60 | I27: =IF(I24=0,Thermostat!$B$4,Thermostat!$B$3) -> 60 | J27: =IF(J24=0,Thermostat!$B$4,Thermostat!$B$3) -> 60 | K27: =IF(K24=0,Thermostat!$B$4,Thermostat!$B$3) -> 60 | L27: =IF(L24=0,Thermostat!$B$4,Thermostat!$B$3) -> 60 | M27: =IF(M24=0,Thermostat!$B$4,Thermostat!$B$3) -> 60 | ... AC27: =IF(AC24=0,Thermostat!$B$4,Thermostat!$B$3) -> 60
A28: School Zones | B28: Classroom | C28: ClgSetpt | D28: T24 2022 - Appendix 5.4B | E28: Weekday | F28: =IF(F22=0,Thermostat!$B$6,Thermostat!$B$5) -> 85 | G28: =IF(G22=0,Thermostat!$B$6,Thermostat!$B$5) -> 85 | H28: =IF(H22=0,Thermostat!$B$6,Thermostat!$B$5) -> 85 | I28: =IF(I22=0,Thermostat!$B$6,Thermostat!$B$5) -> 85 | J28: =IF(J22=0,Thermostat!$B$6,Thermostat!$B$5) -> 85 | K28: =IF(K22=0,Thermostat!$B$6,Thermostat!$B$5) -> 85 | L28: =IF(L22=0,Thermostat!$B$6,Thermostat!$B$5) -> 75 | M28: =IF(M22=0,Thermostat!$B$6,Thermostat!$B$5) -> 75 | ... AC28: =IF(AC22=0,Thermostat!$B$6,Thermostat!$B$5) -> 85
E29: Saturday | F29: =IF(F23=0,Thermostat!$B$6,Thermostat!$B$5) -> 85 | G29: =IF(G23=0,Thermostat!$B$6,Thermostat!$B$5) -> 85 | H29: =IF(H23=0,Thermostat!$B$6,Thermostat!$B$5) -> 85 | I29: =IF(I23=0,Thermostat!$B$6,Thermostat!$B$5) -> 85 | J29: =IF(J23=0,Thermostat!$B$6,Thermostat!$B$5) -> 85 | K29: =IF(K23=0,Thermostat!$B$6,Thermostat!$B$5) -> 85 | L29: =IF(L23=0,Thermostat!$B$6,Thermostat!$B$5) -> 85 | M29: =IF(M23=0,Thermostat!$B$6,Thermostat!$B$5) -> 75 | ... AC29: =IF(AC23=0,Thermostat!$B$6,Thermostat!$B$5) -> 85
E30: Sunday | F30: =IF(F24=0,Thermostat!$B$6,Thermostat!$B$5) -> 85 | G30: =IF(G24=0,Thermostat!$B$6,Thermostat!$B$5) -> 85 | H30: =IF(H24=0,Thermostat!$B$6,Thermostat!$B$5) -> 85 | I30: =IF(I24=0,Thermostat!$B$6,Thermostat!$B$5) -> 85 | J30: =IF(J24=0,Thermostat!$B$6,Thermostat!$B$5) -> 85 | K30: =IF(K24=0,Thermostat!$B$6,Thermostat!$B$5) -> 85 | L30: =IF(L24=0,Thermostat!$B$6,Thermostat!$B$5) -> 85 | M30: =IF(M24=0,Thermostat!$B$6,Thermostat!$B$5) -> 85 | ... AC30: =IF(AC24=0,Thermostat!$B$6,Thermostat!$B$5) -> 85
A31: School Zones | B31: Classroom | C31: Infiltration | D31: T24 2022 - Appendix 5.4B | E31: Weekday | F31: 1 | G31: 1 | H31: 1 | I31: 1 | J31: 1 | K31: 1 | L31: 1 | M31: 0.25 | N31: 0.25 | O31: 0.25 | P31: 0.25 | Q31: 0.25 | R31: 0.25 | S31: 0.25 | T31: 0.25 | U31: 0.25 | V31: 1 | W31: 1 | X31: 1 | Y31: 1 | Z31: 1 | AA31: 1 | AB31: 1 | AC31: 1
E32: Saturday | F32: 1 | G32: 1 | H32: 1 | I32: 1 | J32: 1 | K32: 1 | L32: 1 | M32: 1 | N32: 1 | O32: 1 | P32: 1 | Q32: 1 | R32: 1 | S32: 1 | T32: 1 | U32: 1 | V32: 1 | W32: 1 | X32: 1 | Y32: 1 | Z32: 1 | AA32: 1 | AB32: 1 | AC32: 1
E33: Sunday | F33: 1 | G33: 1 | H33: 1 | I33: 1 | J33: 1 | K33: 1 | L33: 1 | M33: 1 | N33: 1 | O33: 1 | P33: 1 | Q33: 1 | R33: 1 | S33: 1 | T33: 1 | U33: 1 | V33: 1 | W33: 1 | X33: 1 | Y33: 1 | Z33: 1 | AA33: 1 | AB33: 1 | AC33: 1
A34: Other
B35: Building | C35: ExtLightingNonMotionCtrl | E35: Weekday | F35: 1 | G35: 1 | H35: 1 | I35: 1 | J35: 1 | K35: 1 | L35: 1 | M35: 1 | N35: 1 | O35: 1 | P35: 1 | Q35: 1 | R35: 1 | S35: 1 | T35: 1 | U35: 1 | V35: 1 | W35: 1 | X35: 1 | Y35: 1 | Z35: 1 | AA35: 1 | AB35: 1 | AC35: 1
E36: Saturday | F36: 1 | G36: 1 | H36: 1 | I36: 1 | J36: 1 | K36: 1 | L36: 1 | M36: 1 | N36: 1 | O36: 1 | P36: 1 | Q36: 1 | R36: 1 | S36: 1 | T36: 1 | U36: 1 | V36: 1 | W36: 1 | X36: 1 | Y36: 1 | Z36: 1 | AA36: 1 | AB36: 1 | AC36: 1
E37: Sunday | F37: 1 | G37: 1 | H37: 1 | I37: 1 | J37: 1 | K37: 1 | L37: 1 | M37: 1 | N37: 1 | O37: 1 | P37: 1 | Q37: 1 | R37: 1 | S37: 1 | T37: 1 | U37: 1 | V37: 1 | W37: 1 | X37: 1 | Y37: 1 | Z37: 1 | AA37: 1 | AB37: 1 | AC37: 1
B38: Building | C38: ExtLightingMotionCtrl | E38: Weekday | F38: 0 | G38: 0 | H38: 0 | I38: 0 | J38: 0 | K38: 1 | L38: 1 | M38: 1 | N38: 1 | O38: 1 | P38: 1 | Q38: 1 | R38: 1 | S38: 1 | T38: 1 | U38: 1 | V38: 1 | W38: 1 | X38: 1 | Y38: 1 | Z38: 1 | AA38: 1 | AB38: 0 | AC38: 0
E39: Saturday | F39: 0 | G39: 0 | H39: 0 | I39: 0 | J39: 0 | K39: 1 | L39: 1 | M39: 1 | N39: 1 | O39: 1 | P39: 1 | Q39: 1 | R39: 1 | S39: 1 | T39: 1 | U39: 1 | V39: 1 | W39: 1 | X39: 1 | Y39: 1 | Z39: 1 | AA39: 1 | AB39: 1 | AC39: 1
E40: Sunday | F40: 0 | G40: 0 | H40: 0 | I40: 0 | J40: 0 | K40: 1 | L40: 1 | M40: 1 | N40: 1 | O40: 1 | P40: 1 | Q40: 1 | R40: 1 | S40: 1 | T40: 1 | U40: 1 | V40: 1 | W40: 1 | X40: 1 | Y40: 1 | Z40: 1 | AA40: 1 | AB40: 1 | AC40: 1
...

Sheet Energy Usage
A1: ="CalBEM Energy Consumption - "&Prototype!B4 -> CalBEM Energy Consumption - Relocatable School | N1: ="Energy Consumption - "&Prototype!A2 -> Energy Consumption - SchoolRelocatable
A2: Prototype | B2: CZ | C2: CalBEM Electricity EUI (KBTU/ft²) | D2: CalBEM Gas EUI (KBTU/ft²) | E2: CalBEM Total EUI (KBTU/ft²) | F2: New Construction Electricity EUI (KBTU/ft²) | G2: New Construction Gas EUI (KBTU/ft²) | H2: New Construction Total EUI (KBTU/ft²) | I2: National Average | J2: Acceptable Range (25% Higher) | K2: Acceptable Range (25% Lower) | L2: National Average Acceptable EUI Range | N2: Prototype | O2: CZ | P2: Total Floorspace (Thousand of ft²) | Q2: CEUS 2023 Electricity EUI (kBtu/ft²) | R2: CEUS 2023 Gas EUI (kBtu/ft²) | S2: CEUS 2023 Total EUI (kBtu/ft²) | T2: Acceptable Range (25% Higher) | U2: Acceptable Range (25% Lower) | V2: CEUS 2022 Acceptable EUI Range
A3: =Prototype!B4 -> Relocatable School | B3: 1 | C3: 175.83664 | D3: 0 | E3: 175.83664 | F3: 118.81 | G3: 0 | H3: 118.81 | I3: 51.3 | J3: =I3*1.25 -> 64.125 | K3: =I3*0.75 -> 38.475 | L3: =J3-K3 -> 25.65 | N3: =Prototype!B4 -> Relocatable School | O3: 1 | P3: 7618.5337 | Q3: 32.349176 | R3: 12.848137 | S3: =Q3+R3 -> 45.197312 | T3: =S3*1.25 -> 56.49664 | U3: =S3*0.75 -> 33.897984 | V3: =T3-U3 -> 22.598656
B4: 2 | C4: 141.9838 | D4: 0 | E4: 141.9838 | F4: 98.83 | G4: 0 | H4: 98.83 | I4: 51.3 | J4: =I4*1.25 -> 64.125 | K4: =I4*0.75 -> 38.475 | L4: =J4-K4 -> 25.65 | O4: 2 | P4: 11477.671 | Q4: 15.421598 | R4: 12.913999 | S4: =Q4+R4 -> 28.335597 | T4: =S4*1.25 -> 35.419497 | U4: =S4*0.75 -> 21.251698 | V4: =T4-U4 -> 14.167799
B5: 3 | C5: 107.35581 | D5: 0 | E5: 107.35581 | F5: 78.09 | G5: 0 | H5: 78.09 | I5: 51.3 | J5: =I5*1.25 -> 64.125 | K5: =I5*0.75 -> 38.475 | L5: =J5-K5 -> 25.65 | O5: 3 | P5: 46411.86 | Q5: 20.479595 | R5: 12.799248 | S5: =Q5+R5 -> 33.278843 | T5: =S5*1.25 -> 41.598554 | U5: =S5*0.75 -> 24.959132 | V5: =T5-U5 -> 16.639421
B6: 4 | C6: 148.81858 | D6: 0 | E6: 148.81858 | F6: 102.27 | G6: 0 | H6: 102.27 | I6: 51.3 | J6: =I6*1.25 -> 64.125 | K6: =I6*0.75 -> 38.475 | L6: =J6-K6 -> 25.65 | O6: 4 | P6: 23032.968 | Q6: 21.49373 | R6: 13.019767 | S6: =Q6+R6 -> 34.513497 | T6: =S6*1.25 -> 43.141871 | U6: =S6*0.75 -> 25.885123 | V6: =T6-U6 -> 17.256749
B7: 5 | C7: 107.81653 | D7: 0 | E7: 107.81653 | F7: 77.29 | G7: 0 | H7: 77.29 | I7: 51.3 | J7: =I7*1.25 -> 64.125 | K7: =I7*0.75 -> 38.475 | L7: =J7-K7 -> 25.65 | O7: 5 | P7: 5978.4428 | Q7: 11.998072 | R7: 11.585185 | S7: =Q7+R7 -> 23.583257 | T7: =S7*1.25 -> 29.479072 | U7: =S7*0.75 -> 17.687443 | V7: =T7-U7 -> 11.791629
B8: 6 | C8: 73.331891 | D8: 0 | E8: 73.331891 | F8: 54.61 | G8: 0 | H8: 54.61 | I8: 51.3 | J8: =I8*1.25 -> 64.125 | K8: =I8*0.75 -> 38.475 | L8: =J8-K8 -> 25.65 | O8: 6 | P8: 57755.959 | Q8: 22.607349 | R8: 9.9467421 | S8: =Q8+R8 -> 32.554091 | T8: =S8*1.25 -> 40.692614 | U8: =S8*0.75 -> 24.415568 | V8: =T8-U8 -> 16.277046
B9: 7 | C9: 71.257495 | D9: 0 | E9: 71.257495 | F9: 52.11 | G9: 0 | H9: 52.11 | I9: 51.3 | J9: =I9*1.25 -> 64.125 | K9: =I9*0.75 -> 38.475 | L9: =J9-K9 -> 25.65 | O9: 7 | P9: 35149.993 | Q9: 24.848388 | R9: 6.9700357 | S9: =Q9+R9 -> 31.818424 | T9: =S9*1.25 -> 39.77303 | U9: =S9*0.75 -> 23.863818 | V9: =T9-U9 -> 15.909212
B10: 8 | C10: 87.29357 | D10: 0 | E10: 87.29357 | F10: 64.68 | G10: 0 | H10: 64.68 | I10: 51.3 | J10: =I10*1.25 -> 64.125 | K10: =I10*0.75 -> 38.475 | L10: =J10-K10 -> 25.65 | O10: 8 | P10: 92353.411 | Q10: 22.935329 | R10: 8.842203 | S10: =Q10+R10 -> 31.777532 | T10: =S10*1.25 -> 39.721915 | U10: =S10*0.75 -> 23.833149 | V10: =T10-U10 -> 15.888766
B11: 9 | C11: 94.236014 | D11: 0 | E11: 94.236014 | F11: 69.05 | G11: 0 | H11: 69.05 | I11: 51.3 | J11: =I11*1.25 -> 64.125 | K11: =I11*0.75 -> 38.475 | L11: =J11-K11 -> 25.65 | O11: 9 | P11: 141795.45 | Q11: 26.797343 | R11: 10.089067 | S11: =Q11+R11 -> 36.88641 | T11: =S11*1.25 -> 46.108013 | U11: =S11*0.75 -> 27.664808 | V11: =T11-U11 -> 18.443205
B12: 10 | C12: 100.0645 | D12: 0 | E12: 100.0645 | F12: 74.25 | G12: 0 | H12: 74.25 | I12: 51.3 | J12: =I12*1.25 -> 64.125 | K12: =I12*0.75 -> 38.475 | L12: =J12-K12 -> 25.65 | O12: 10 | P12: 92589.867 | Q12: 22.490401 | R12: 10.108975 | S12: =Q12+R12 -> 32.599376 | T12: =S12*1.25 -> 40.74922 | U12: =S12*0.75 -> 24.449532 | V12: =T12-U12 -> 16.299688
B13: 11 | C13: 157.40738 | D13: 0 | E13: 157.40738 | F13: 111.19 | G13: 0 | H13: 111.19 | I13: 51.3 | J13: =I13*1.25 -> 64.125 | K13: =I13*0.75 -> 38.475 | L13: =J13-K13 -> 25.65 | O13: 11 | P13: 33810.488 | Q13: 26.928661 | R13: 8.760437 | S13: =Q13+R13 -> 35.689098 | T13: =S13*1.25 -> 44.611373 | U13: =S13*0.75 -> 26.766824 | V13: =T13-U13 -> 17.844549
B14: 12 | C14: 136.21838 | D14: 0 | E14: 136.21838 | F14: 97.98 | G14: 0 | H14: 97.98 | I14: 51.3 | J14: =I14*1.25 -> 64.125 | K14: =I14*0.75 -> 38.475 | L14: =J14-K14 -> 25.65 | O14: 12 | P14: 108342.43 | Q14: 31.799594 | R14: 12.230299 | S14: =Q14+R14 -> 44.029893 | T14: =S14*1.25 -> 55.037366 | U14: =S14*0.75 -> 33.02242 | V14: =T14-U14 -> 22.014946
B15: 13 | C15: 133.02286 | D15: 0 | E15: 133.02286 | F15: 97.21 | G15: 0 | H15: 97.21 | I15: 51.3 | J15: =I15*1.25 -> 64.125 | K15: =I15*0.75 -> 38.475 | L15: =J15-K15 -> 25.65 | O15: 13 | P15: 46676.808 | Q15: 32.656044 | R15: 15.473534 | S15: =Q15+R15 -> 48.129578 | T15: =S15*1.25 -> 60.161972 | U15: =S15*0.75 -> 36.097183 | V15: =T15-U15 -> 24.064789
... B18: 16 | C18: 237.78295 | D18: 0 | E18: 237.78295 | F18: 167.29 | G18: 0 | H18: 167.29 | I18: 51.3 | J18: =I18*1.25 -> 64.125 | K18: =I18*0.75 -> 38.475 | L18: =J18-K18 -> 25.65 | O18: 16 | P18: 85267.89 | Q18: 27.026911 | R18: 11.652927 | S18: =Q18+R18 -> 38.679837 | T18: =S18*1.25 -> 48.349796 | U18: =S18*0.75 -> 29.009878 | V18: =T18-U18 -> 19.339919
Q20: Ref: CEUS 2022 Report
Q21: And by applying FZ-CZ multipliers for converting FZ data to CZ data

Sheet Weights
A1: ="% of Floor Area per CZ and Vintage Bin - Schools" -> % of Floor Area per CZ and Vintage Bin - Schools
A2: Prototype | B2: CZ | C2: Vintage Bin
C3: Pre-1978 | D3: 1978-1997 | E3: 1998-2007 | F3: 2008-2018 | G3: Not available
A4: =Prototype!B4 -> Relocatable School | B4: 1 | C4: 0.485 | D4: 0.274 | E4: 0.076 | F4: 0.029 | G4: 0.136 | H4: =SUM(C4:G4) -> 1
B5: 2 | C5: 0.858 | D5: 0.07 | E5: 0.038 | F5: 0.014 | G5: 0.02 | H5: =SUM(C5:G5) -> 1
B6: 3 | C6: 0.661 | D6: 0.209 | E6: 0.015 | F6: 0.006 | G6: 0.109 | H6: =SUM(C6:G6) -> 1
B7: 4 | C7: 0.682 | D7: 0.179 | E7: 0.009 | F7: 0.006 | G7: 0.124 | H7: =SUM(C7:G7) -> 1
B8: 5 | C8: 0.536 | D8: 0.421 | E8: 0.024 | F8: 0.008 | G8: 0.012 | H8: =SUM(C8:G8) -> 1.001
B9: 6 | C9: 0.657 | D9: 0.139 | E9: 0.103 | F9: 0.044 | G9: 0.058 | H9: =SUM(C9:G9) -> 1.001
B10: 7 | C10: 0.288 | D10: 0.247 | E10: 0.188 | F10: 0.235 | G10: 0.042 | H10: =SUM(C10:G10) -> 1
B11: 8 | C11: 0.666 | D11: 0.125 | E11: 0.103 | F11: 0.036 | G11: 0.07 | H11: =SUM(C11:G11) -> 1
B12: 9 | C12: 0.602 | D12: 0.152 | E12: 0.074 | F12: 0.02 | G12: 0.152 | H12: =SUM(C12:G12) -> 1
B13: 10 | C13: 0.327 | D13: 0.201 | E13: 0.317 | F13: 0.111 | G13: 0.044 | H13: =SUM(C13:G13) -> 1
B14: 11 | C14: 0.475 | D14: 0.305 | E14: 0.073 | F14: 0.017 | G14: 0.131 | H14: =SUM(C14:G14) -> 1.001
B15: 12 | C15: 0.447 | D15: 0.31 | E15: 0.096 | F15: 0.028 | G15: 0.118 | H15: =SUM(C15:G15) -> 0.999
B16: 13 | C16: 0.323 | D16: 0.347 | E16: 0.137 | F16: 0.061 | G16: 0.132 | H16: =SUM(C16:G16) -> 1
... B19: 16 | C19: 0.447 | D19: 0.235 | E19: 0.127 | F19: 0.094 | G19: 0.098 | H19: =SUM(C19:G19) -> 1.001
B20: Statewide
A22: Ref: CEUS 2022 dataset
A25: Background Data [To be deleted prior to publication]

Sheet PV
A1: ="PV - "&Prototype!A2 -> PV - SchoolRelocatable
A2: TBD

Sheet EV Charger
A1: ="EV Charger - "&Prototype!A2 -> EV Charger - SchoolRelocatable
A2: TBD
A11: Background Data [To be deleted prior to publication]

Sheet Data
A1: Space Function
A2: Aging Eye/Low-vision (Corridor Area)
A3: Aging Eye/Low-vision (Dining)
A4: Aging Eye/Low-vision (Lobby, Main Entry)
A5: Aging Eye/Low-vision (Lounge/Waiting Area)
A6: Aging Eye/Low-vision (Multipurpose Room)
A7: Aging Eye/Low-vision (Religious Worship Area)
A8: Aging Eye/Low-vision (Restroom)
A9: Aging Eye/Low-vision (Stairwell)
A10: Audience Seating Area
A11: Auditorium Area
A12: Auto Repair / Maintenance Area
... A80: Unoccupied-Exclude from Gross Floor Area
