Workbook
Name nonparticipating_forecastzone_scale_factor: #REF!
Name nonparticipating_forecastzone_scale_factor: #REF!
Name nonparticipating_forecastzone_scale_factor: 'Energy Usage'!#REF!
Name Space_Function: Data!$A$2:$A$76

Sheet Notes
A1: Data Sources
A2: Dataset | B2: Dodge 2023
B3: CEUS 2022
B4: ComStock 2023
A6: Prototype | B6: CEC School prototype (CBECC 2022.3.1) | C6: https://bees.noresco.com/software2022.html
A9: Codes | B9: Title 24, part 6, referred to as T24 (1984, 2001, 2007, 2013, 2016, 2022, 2025)
B10: ASHRAE 90.1 (2022)
B11: CFR Title 10 (2008, 2010, 2025)
B12: ACM 2022
B13: T24 2022 - Appendix 5.4A and Appendix 5.4B | C13: https://www.energy.ca.gov/publications/2022/2022-nonresidential-and-multifamily-alternative-calculation-method-reference
A15: Other | B15: 2022 Reduced infiltration CASE report | C15: https://title24stakeholders.com/wp-content/uploads/2020/10/2022-T24-Final-CASE-Report_Reduce-Infiltration.pdf
B16: 2019 Outdoor Lighting CASE Report | C16: https://title24stakeholders.com/wp-content/uploads/2016/10/T24-2019-CASE-Study-Results-Report-Outdoor-Sources_Final_with-Attachments.pdf
B17: 2019 High Efficiency Fume Hoods in Laboratory Spaces CASE Report | C17: https://title24stakeholders.com/wp-content/uploads/2017/09/2019-T24-CASE-Report_Fume-Hoods_Final_September-2017.pdf?
B18: PNNL 20405, 2010 | C18: file:///N:/Prj_SUS/2023/S23668%20SCE%20CA%20Prototypes%20Development/Technical/NR/0_Input%20data/Lighting/PNNL-20405.pdf
B19: Air leakage Memo, NORESCO, 2025 | C19: Infiltration_rate_report_14May2025-Short-Version.docx
A20: Construction Rate
A33: Notes
A34: 2025 T24 | B34: School Building includes four individual buildings, including north classroom, westclassroom, kindergarten, and MPR/Admin.

Sheet Prototype
A1: NORESCO, Updated September 2025
A2: SchoolK-8
A3: Characteristic | B3: Value | C3: Data Sources
A4: Building Type | B4: K-8 School
A5: Building Category | B5: Nonresidential
A6: Vintages | B6: 4 Vintages: Pre-1978, 1978-1997,1998-2007, 2008-2018 New Construction (2019+) | C6: Based on the vintage bin analysis | D6: NonRes-Vintage bins-Draft Report-30Nov2023-Final.docx
A7: Shape | C7: The analysis uses prototype geometry originally developed by CEC.
A8: Total Floor Area (ft²) | B8: 49979.36 | C8: Same as CEC
A9: Aspect Ratio | B9: It varies for different buildings. | C9: Same as CEC
A10: Number of Floors | B10: It varies for different buildings. | C10: Same as CEC
A11: Roof type | B11: Flat | C11: Same as CEC
A12: WWR | B12: 0.0708 | C12: Same as CEC
A13: Shading Geometry | B13: No Shades | C13: Same as CEC
A14: Floor to floor height (feet) | B14: It varies for different buildings: MPR/Admin: 14-25 Other buildings: 14 ft | C14: Same as CEC
A15: Floor to ceiling height (feet) | B15: It varies for different buildings: MPR/Admin: 14-25 Other buildings: 14 ft | C15: Same as CEC
A16: Glazing sill height (feet) | B16: It varies for different buildings. | C16: Same as CEC
A20: Above grade wall area (ft²) | B20: 42450.09
A21: Gross wall area (ft²) | B21: 42450.09
A22: Roof area (ft²) | B22: 37687.78
A23: Underground Gross Wall Area (ft²) | B23: 0

Sheet Zones
A1: ="Proposed Layout - "&Prototype!B4 -> Proposed Layout - K-8 School
A2: Space Type | B2: Space/Thermal Zone | C2: HVAC System Name/AHU Name | D2: Schedule Category | E2: Conditioned (Y/N) | F2: Area Fraction | G2: Area (ft²) | H2: Volume (ft³) | I2: Multipliers | J2: Number of People | K2: People (Persons/1,000 ft²) [T24, 2025,Table 120.1-A]
A3: Lounge, Breakroom, or Waiting Area | B3: Admin/MPR_Breakroom_Zn | C3: AHU-1 | D3: MPR | E3: Y | F3: =G3/$G$41 -> 0.011508749 | G3: 575.2 | H3: 353.2 | I3: 1 | J3: =K3*G3/1000 -> 37.9632 | K3: 66
A4: Convention, Conference, Multipurpose and Meeting Area | B4: Admin/MPR_Conference Room Zns 3_Zn | C4: AHU-2 | D4: MPR | E4: Y | F4: =G4/$G$41 -> 0.033508626 | G4: 1674.74 | H4: 353.2 | I4: 1 | J4: =K4*G4/1000 -> 110.53284 | K4: 66
A5: Corridor Area | B5: Admin/MPR_Corridor_Zn | C5: AHU-3 | D5: MPR | E5: Y | F5: =G5/$G$41 -> 0.023239989 | G5: 1161.52 | H5: 353.2 | I5: 1 | J5: =K5*G5/1000 -> 11.6152 | K5: 10
A6: Electrical, Mechanical, Telephone Rooms | B6: Admin/MPR_EMT_Zn | C6: AHU-4 | D6: MPR | E6: Y | F6: =G6/$G$41 -> 0.0055664967 | G6: 278.21 | H6: 353.2 | I6: 1 | J6: =K6*G6/1000 -> 2.7821 | K6: 10
A7: Electrical, Mechanical, Telephone Rooms | B7: Admin/MPR_IDF Room_Zn | C7: AHU-5 | D7: MPR | E7: Y | F7: =G7/$G$41 -> 0.0068074087 | G7: 340.23 | H7: 353.2 | I7: 1 | J7: =K7*G7/1000 -> 3.4023 | K7: 10
A8: Kitchen/Food Preparation Area | B8: Admin/MPR_Kitchen_Zn | C8: AHU-6 | D8: Kitchen | E8: Y | F8: =G8/$G$41 -> 0.02915703 | G8: 1457.25 | H8: 353.2 | I8: 1 | J8: =K8*G8/1000 -> 8.7435 | K8: 6
A9: Lobby, Main Entry | B9: Admin/MPR_Lobby_Zn | C9: AHU-7 | D9: MPR | E9: Y | F9: =G9/$G$41 -> 0.024839649 | G9: 1241.47 | H9: 353.2 | I9: 1 | J9: =K9*G9/1000 -> 81.93702 | K9: 66
A10: Convention, Conference, Multipurpose and Meeting Area | B10: Admin/MPR_Multipurpose Room Zns 3_Zn | C10: AHU-8 | D10: MPR | E10: Y | F10: =G10/$G$41 -> 0.11028931 | G10: 5512.19 | H10: 137811.47 | I10: 1 | J10: =K10*G10/1000 -> 363.80454 | K10: 66
A11: Office Area (<250 square feet) | B11: Admin/MPR_Office - LT 250 sf Zns 6_Zn | C11: AHU-9 | D11: MPR | E11: Y | F11: =G11/$G$41 -> 0.020975655 | G11: 1048.35 | H11: 353.2 | I11: 1 | J11: =K11*G11/1000 -> 10.4835 | K11: 10
A12: Restrooms | B12: Admin/MPR_Restroom Zns 3_Zn | C12: AHU-10 | D12: MPR | E12: Y | F12: =G12/$G$41 -> 0.01803084 | G12: 901.17 | H12: 12617.05 | I12: 1 | J12: =K12*G12/1000 -> 9.0117 | K12: 10
A13: Storage (General) | B13: Admin/MPR_Storage - General_Zn | C13: AHU-11 | D13: MPR | E13: Y | F13: =G13/$G$41 -> 0.024964901 | G13: 1247.73 | H13: 353.2 | I13: 1 | J13: =K13*G13/1000 -> 12.4773 | K13: 10
A14: Storage, Commercial/Industrial (Refrigerated) | B14: Admin/MPR_Storage - Refrigerated_Zn | C14: AHU-12 | D14: MPR | E14: Y | F14: =G14/$G$41 -> 0.0050364781 | G14: 251.72 | H14: 353.2 | I14: 1 | J14: =K14*G14/1000 -> 0 | K14: 0
... A40: Storage (General) | B40: Kindergarten_Storage - General_Zn | C40: AHU-38 | D40: Classroom | E40: Y | F40: =G40/$G$41 -> 0.023685773 | G40: 1183.8 | H40: 353.2 | I40: 1 | J40: =K40*G40/1000 -> 11.838 | K40: 10
A41: Total (15 Space types) | B41: Total (38 spaces) | C41: Total ( 5 HVAC zones) | D41: Total (4 Schedule categories)) | E41: Total (38 Conditioned zones) | F41: =G41/$G$41 -> 1 | G41: =SUM(G3:G40) -> 49979.37 | H41: =SUM(H3:H40) -> 191561.04 | J41: =SUM(J3:J40) -> 2136.655
A58: Background Data [To be deleted prior to publication]
O68: Fraction Convected | P68: Sensible Fraction Calculation | Q68: Activity level | R68: ASHRAE 55 Warnings | S68: Carbon Dioxide Generation Rate | T68: Nominal Minimum Number of People | U68: Nominal Maximum Number of People
O69: 0.7 | P69: 0.5 | Q69: ADMIN/MPR_BREAKROOM PEOPLE ACTIVITY LEVEL | R69: No | S69: 3.82e-08 | T69: 0 | U69: 19
O70: 0.7 | P70: 0.613 | Q70: ADMIN/MPR_CONFERENCE ROOM ZNS 3 PEOPLE ACTIVITY LEVEL | R70: No | S70: 3.82e-08 | T70: 0 | U70: 55
O71: 0.7 | P71: 0.5 | Q71: ADMIN/MPR_CORRIDOR PEOPLE ACTIVITY LEVEL | R71: No | S71: 3.82e-08 | T71: 0 | U71: 6
O72: 0.7 | P72: 0.5 | Q72: ADMIN/MPR_EMT PEOPLE ACTIVITY LEVEL | R72: No | S72: 3.82e-08 | T72: 0 | U72: 1
O73: 0.7 | P73: 0.5 | Q73: ADMIN/MPR_IDF ROOM PEOPLE ACTIVITY LEVEL | R73: No | S73: 3.82e-08 | T73: 0 | U73: 2
O74: 0.7 | P74: 0.367 | Q74: ADMIN/MPR_KITCHEN PEOPLE ACTIVITY LEVEL | R74: No | S74: 3.82e-08 | T74: 0 | U74: 4
O75: 0.7 | P75: 0.5 | Q75: ADMIN/MPR_LOBBY PEOPLE ACTIVITY LEVEL | R75: No | S75: 3.82e-08 | T75: 0 | U75: 41
O76: 0.7 | P76: 0.613 | Q76: ADMIN/MPR_MULTIPURPOSE ROOM ZNS 3 PEOPLE ACTIVITY LEVEL | R76: No | S76: 3.82e-08 | T76: 0 | U76: 182
O77: 0.7 | P77: 0.556 | Q77: ADMIN/MPR_OFFICE - LT 250 SF ZNS 6 PEOPLE ACTIVITY LEVEL | R77: No | S77: 3.82e-08 | T77: 0 | U77: 5
O78: 0.7 | P78: 0.5 | Q78: ADMIN/MPR_RESTROOM ZNS 3 PEOPLE ACTIVITY LEVEL | R78: No | S78: 3.82e-08 | T78: 0 | U78: 5
O79: 0.7 | P79: 0.556 | Q79: ADMIN/MPR_STORAGE - GENERAL PEOPLE ACTIVITY LEVEL | R79: No | S79: 3.82e-08 | T79: 0 | U79: 6
O80: 0.7 | P80: 0.7 | Q80: ADMIN/MPR_THEATER - PERFORMANCE PEOPLE ACTIVITY LEVEL | R80: No | S80: 3.82e-08 | T80: 0 | U80: 35
... O105: 0.7 | P105: 0.556 | Q105: KINDERGARTEN_STORAGE - GENERAL PEOPLE ACTIVITY LEVEL | R105: No | S105: 3.82e-08 | T105: 0 | U105: 6

Sheet Envelope
A1: ="Envelope - "&Prototype!A2 -> Envelope - SchoolK-8
A2: Element | B2: Prototype | C2: Assembly Type | D2: Construction | E2: Thermal properties | F2: Vintage | G2: Selected T24 | H2: Note | I2: CZ1 | J2: CZ2 | K2: CZ3 | L2: CZ4 | M2: CZ5 | N2: CZ6 | O2: CZ7 | P2: CZ8 | Q2: CZ9 | R2: CZ10 | S2: CZ11 | T2: CZ12 | U2: CZ13 | V2: CZ14 | W2: CZ15 | X2: CZ16
A3: External Wall | B3: =Prototype!A2 -> SchoolK-8 | C3: ExtWall_MetalFramed_NonRes | D3: Metal frame + insulation + Gypsum board | E3: U-value IP | F3: Pre 1978 | G3: N/A | H3: ASHRAE 90.1, 2022, Table A3.4.3.1, 3.5", R-0 | I3: 0.292 | J3: 0.292 | K3: 0.292 | L3: 0.292 | M3: 0.292 | N3: 0.292 | O3: 0.292 | P3: 0.292 | Q3: 0.292 | R3: 0.292 | S3: 0.292 | T3: 0.292 | U3: 0.292 | V3: 0.292 | W3: 0.292 | X3: 0.292
F4: 1978-1997 | G4: 1986 | H4: Table 2-53V-16: Package A/ Heat Capacity was considered 10.0-14.99 (BTU/F/ft²) | I4: 0.15082956 | J4: 0.15748031 | K4: 0.15748031 | L4: 0.14367816 | M4: 0.14367816 | N4: 0.21645022 | O4: 0.21645022 | P4: 0.21645022 | Q4: 0.21645022 | R4: 0.21645022 | S4: 0.18621974 | T4: 0.18621974 | U4: 0.18621974 | V4: 0.15873016 | W4: 0.15873016 | X4: 0.15082956
F5: 1998-2007 | G5: 2001 | H5: Table 1-H | I5: 0.084 | J5: 0.084 | K5: 0.092 | L5: 0.092 | M5: 0.092 | N5: 0.092 | O5: 0.092 | P5: 0.092 | Q5: 0.092 | R5: 0.084 | S5: 0.084 | T5: 0.084 | U5: 0.084 | V5: 0.084 | W5: 0.084 | X5: 0.084
F6: 2008-2018 | G6: 2013 | H6: Table 140.3-B | I6: 0.102 | J6: 0.059 | K6: 0.11 | L6: 0.059 | M6: 0.102 | N6: 0.11 | O6: 0.11 | P6: 0.102 | Q6: 0.059 | R6: 0.059 | S6: 0.059 | T6: 0.059 | U6: 0.059 | V6: 0.059 | W6: 0.042 | X6: 0.059
F7: 2019+ | G7: 2025 | H7: Table 140.3-B | I7: 0.078 | J7: 0.053 | K7: 0.102 | L7: 0.053 | M7: 0.095 | N7: 0.102 | O7: 0.102 | P7: 0.095 | Q7: 0.053 | R7: 0.053 | S7: 0.042 | T7: 0.053 | U7: 0.053 | V7: 0.053 | W7: 0.038 | X7: 0.053
A8: Roof | B8: =$B$3 -> SchoolK-8 | C8: FlatRoof_WoodFramedAndOther_NonRes | D8: Built-up Roof roof membrane+roof insulation+metal decking | E8: U-value IP | F8: Pre 1978 | G8: N/A | H8: Table 2-53V-16: Considering 30 years for roof/ insulation replacement. | I8: 0.057 | J8: 0.057 | K8: 0.057 | L8: 0.057 | M8: 0.057 | N8: 0.078 | O8: 0.078 | P8: 0.078 | Q8: 0.078 | R8: 0.078 | S8: 0.057 | T8: 0.057 | U8: 0.057 | V8: 0.057 | W8: 0.057 | X8: 0.057
F9: 1978-1997 | G9: 1992 | I9: 0.057 | J9: 0.057 | K9: 0.057 | L9: 0.057 | M9: 0.057 | N9: 0.078 | O9: 0.078 | P9: 0.078 | Q9: 0.078 | R9: 0.078 | S9: 0.057 | T9: 0.057 | U9: 0.057 | V9: 0.057 | W9: 0.057 | X9: 0.057
F10: 1998-2007 | G10: 2001 | H10: Table 1-H | I10: 0.057 | J10: 0.057 | K10: 0.057 | L10: 0.057 | M10: 0.057 | N10: 0.078 | O10: 0.078 | P10: 0.078 | Q10: 0.078 | R10: 0.057 | S10: 0.057 | T10: 0.057 | U10: 0.057 | V10: 0.057 | W10: 0.057 | X10: 0.057
F11: 2008-2018 | G11: 2013 | H11: Table 140.3-B | I11: 0.049 | J11: 0.039 | K11: 0.039 | L11: 0.039 | M11: 0.049 | N11: 0.075 | O11: 0.067 | P11: 0.067 | Q11: 0.039 | R11: 0.039 | S11: 0.039 | T11: 0.039 | U11: 0.039 | V11: 0.039 | W11: 0.039 | X11: 0.039
F12: 2019+ | G12: 2025 | H12: Table 140.3-B | I12: 0.028 | J12: 0.028 | K12: 0.028 | L12: 0.028 | M12: 0.028 | N12: 0.047 | O12: 0.047 | P12: 0.047 | Q12: 0.028 | R12: 0.028 | S12: 0.028 | T12: 0.028 | U12: 0.028 | V12: 0.028 | W12: 0.028 | X12: 0.028
A13: Windows | B13: =$B$3 -> SchoolK-8 | C13: FixedWindow_NonRes | D13: Single pane | E13: U-value IP | F13: Pre 1978 | G13: N/A | H13: ASHRAE Handbook of Fundamentals (Table 4-Ch15) for single pane & T24, 2013 for double pane (33%-67%)* | I13: =0.33*1.12+0.67*0.36 -> 0.6108 | J13: =0.33*1.12+0.67*0.36 -> 0.6108 | K13: =0.33*1.12+0.67*0.36 -> 0.6108 | L13: =0.33*1.12+0.67*0.36 -> 0.6108 | M13: =0.33*1.12+0.67*0.36 -> 0.6108 | N13: =0.33*1.12+0.67*0.36 -> 0.6108 | O13: =0.33*1.12+0.67*0.36 -> 0.6108 | P13: =0.33*1.12+0.67*0.36 -> 0.6108 | ... X13: =0.33*1.12+0.67*0.36 -> 0.6108
F14: 1978-1997 | G14: N/A | I14: =0.33*1.12+0.67*0.36 -> 0.6108 | J14: =0.33*1.12+0.67*0.36 -> 0.6108 | K14: =0.33*1.12+0.67*0.36 -> 0.6108 | L14: =0.33*1.12+0.67*0.36 -> 0.6108 | M14: =0.33*1.12+0.67*0.36 -> 0.6108 | N14: =0.33*1.12+0.67*0.36 -> 0.6108 | O14: =0.33*1.12+0.67*0.36 -> 0.6108 | P14: =0.33*1.12+0.67*0.36 -> 0.6108 | ... X14: =0.33*1.12+0.67*0.36 -> 0.6108
D15: Double pane | F15: 1998-2007 | G15: 2001 | H15: Table 1-H | I15: 0.49 | J15: 0.49 | K15: 0.81 | L15: 0.81 | M15: 0.81 | N15: 0.81 | O15: 0.81 | P15: 0.81 | Q15: 0.81 | R15: 0.49 | S15: 0.49 | T15: 0.49 | U15: 0.49 | V15: 0.49 | W15: 0.49 | X15: 0.49
F16: 2008-2018 | G16: 2013 | H16: Table 140.3-B | I16: 0.36 | J16: 0.36 | K16: 0.36 | L16: 0.36 | M16: 0.36 | N16: 0.36 | O16: 0.36 | P16: 0.36 | Q16: 0.36 | R16: 0.36 | S16: 0.36 | T16: 0.36 | U16: 0.36 | V16: 0.36 | W16: 0.36 | X16: 0.36
F17: 2019+ | G17: 2025 | H17: Table 140.3-B | I17: 0.36 | J17: 0.36 | K17: 0.36 | L17: 0.36 | M17: 0.36 | N17: 0.36 | O17: 0.36 | P17: 0.36 | Q17: 0.34 | R17: 0.36 | S17: 0.34 | T17: 0.34 | U17: 0.34 | V17: 0.34 | W17: 0.34 | X17: 0.36
B18: =$B$3 -> SchoolK-8 | C18: FixedWindow_NonRes | D18: Single pane | E18: SHGC | F18: Pre 1978 | G18: N/A | H18: ASHRAE Handbook of Fundamentals (Table 10-Ch15) for single pane & T24, 2013 for double pane (33%-67%)* | I18: =0.79*0.33+0.67*I21 -> 0.4282 | J18: =0.79*0.33+0.67*J21 -> 0.4282 | K18: =0.79*0.33+0.67*K21 -> 0.4282 | L18: =0.79*0.33+0.67*L21 -> 0.4282 | M18: =0.79*0.33+0.67*M21 -> 0.4282 | N18: =0.79*0.33+0.67*N21 -> 0.4282 | O18: =0.79*0.33+0.67*O21 -> 0.4282 | P18: =0.79*0.33+0.67*P21 -> 0.4282 | ... X18: =0.79*0.33+0.67*X21 -> 0.4282
F19: 1978-1997 | G19: N/A | I19: =0.79*0.33+0.67*I21 -> 0.4282 | J19: =0.79*0.33+0.67*J21 -> 0.4282 | K19: =0.79*0.33+0.67*K21 -> 0.4282 | L19: =0.79*0.33+0.67*L21 -> 0.4282 | M19: =0.79*0.33+0.67*M21 -> 0.4282 | N19: =0.79*0.33+0.67*N21 -> 0.4282 | O19: =0.79*0.33+0.67*O21 -> 0.4282 | P19: =0.79*0.33+0.67*P21 -> 0.4282 | ... X19: =0.79*0.33+0.67*X21 -> 0.4282
D20: Double pane | F20: 1998-2007 | G20: 2001 | H20: Table 1-H - WWR:31-40% / SHGC non-north | I20: 0.43 | J20: 0.36 | K20: 0.41 | L20: 0.41 | M20: 0.41 | N20: 0.34 | O20: 0.34 | P20: 0.34 | Q20: 0.34 | R20: 0.31 | S20: 0.31 | T20: 0.31 | U20: 0.31 | V20: 0.31 | W20: 0.31 | X20: 0.43
F21: 2008-2018 | G21: 2013 | H21: Table 140.3-B | I21: 0.25 | J21: 0.25 | K21: 0.25 | L21: 0.25 | M21: 0.25 | N21: 0.25 | O21: 0.25 | P21: 0.25 | Q21: 0.25 | R21: 0.25 | S21: 0.25 | T21: 0.25 | U21: 0.25 | V21: 0.25 | W21: 0.25 | X21: 0.25
F22: 2019+ | G22: 2025 | H22: Table 140.3-B | I22: 0.25 | J22: 0.25 | K22: 0.25 | L22: 0.25 | M22: 0.25 | N22: 0.25 | O22: 0.25 | P22: 0.25 | Q22: 0.22 | R22: 0.25 | S22: 0.22 | T22: 0.22 | U22: 0.22 | V22: 0.22 | W22: 0.22 | X22: 0.25
E25: Infiltration
F26: Vintage | G26: I_75 6-Sided Inifltration rate @ 75 pa | H26: Note | I26: I-design (cfm/ft²) (4-sided Infiltration rate at normal presure) (Design flow rate approach and Flow/Exterior Wall Area calulation method)
E27: Infiltration | F27: Pre 1978 | G27: 1.1 | H27: 2022 CASE report (Table 38) | I27: 0.342
F28: 1978-1997 | G28: 1.1 | H28: 2022 CASE report (Table 38) | I28: 0.342
F29: 1998-2007 | G29: 1.1 | H29: 2022 CASE report (Table 38) | I29: 0.342
F30: 2008-2018 | G30: 1 | H30: 2022 CASE report (Table 38) & T24, 2008-2016 (Table 140.3-B)--Air barrier is required in CZ 10-16 | I30: 0.3129
F31: 2019+ | G31: 0.6 | H31: 2022 CASE report (Table 38) & T24, 2025 (Table 140.3-B)--Air barrier is required in all CZs | I31: 0.1865
E32: Source: T24 air barrier requirements (all editions) and the standardized infiltration rate reported in the 2022 CASE report and Dodge 2023 data
E33: Air Lekage Memo: | G33: Infiltration_rate_report_14May2025-Short-Version.docx

Sheet HVAC System
A1: ="HVAC system - "&Prototype!A2 -> HVAC system - SchoolK-8
A2: Vintage | B2: Zones | C2: Heating | D2: Cooling | E2: Air Distribution | F2: Source | G2: Note
A3: Exisiting | B3: All Space Types | C3: Gas Furnace | D3: PSZAC (DX cooling) | E3: CAV | F3: Engineering Judgement | G3: System 3a
A4: New Construction | B4: All Space Types | C4: SZHP | D4: SZHP | E4: CAV | F4: ACM 2025 | G4: System 3b
A9: Efficiency of HVAC system
A10: Vintage | B10: Upgrade/Installed year | C10: Gas Furnace | D10: Heating DX | E10: Cooling DX | F10: Sources | G10: Note
A11: Pre 1978 | B11: 2008 | C11: Thermal Efficiency of 80% | D11: n/a | E11: EER 11.2 for <65 kBtu/h EER 10.3 for 65-135 kBtu/h | F11: 2005 Title 20 Appliance Efficiency Regulations, 2005 T24 Standards, Tables 112-A, 112-B
A12: 1978-1997
A13: 1998-2007
A14: 2008-2018 | B14: 2013 | C14: Thermal Efficiency of 80% | D14: n/a | E14: EER 11.2 for <65 kBtu/h EER 10.3 for 65-135 kBtu/h | F14: 2013 Title 20 Appliance Efficiency Regulations, 2013 T24 Tables 112-A, 112-B
A15: New Construction | B15: 2025 | C15: n/a | D15: Heating @ 47 °F : COP = Federal Minimum COP : 3.3 Heating @ 17 °F : COP = Title 24 Table 110.2-B: COP : 2.25 | E15: EER 11.2 for <65 kBtu/h EER 11, COP fed min for 65-135 kBtu/h | F15: Title 20 Appliance Efficiency Regulations, T24, 2025, Tables 110.2-A, 110.2-B
C17: * Et = Combustion efficiency | D17: * Et = Thermal efficiency
A19: Fan power
A20: Vintage | B20: Approach | C20: System | D20: Total Static Pressure (TSP) in w.c. [PNNL 20405, 2010, Table 5.11] | E20: Fan Efficiency [ACM, 2025] | F20: Fan Motor and Drive Efficiency [ACM 2025, Table 14] | G20: W/cfm [ACM 2025, Table 15] | H20: Data Source | I20: Note
A21: Existing | B21: PNNL TSP | C21: CAV | D21: 2.5 for CAV <7,437 cfm 4.09 for CAV >=7,437 cfm | E21: 0.65 | F21: 0.9 | H21: PNNL 2010 TSD
A22: Brake horse power (bhp)=(Supply cfm*TSP in w.c.)/(6356*Fan efficiency)
A23: Fan power (w/cfm) = bhp/motor and drive efficiency *746
A24: New Construction | B24: ACM 2025 | C24: SZHP>10,000 | D24: =F24*E24*G24/746*6356 -> 3.3693616 | E24: 0.65 | F24: 0.9 | G24: 0.676 | H24: 2025 ACM
F25: * 0.9 is an average fan efficiency according to ACM 2025, Table 14
A26: Fan total eff (E+ input) = 0.65 x Motor_eff
A27: TSP (E+ input) in w.c. = Motor_eff/746 x (6356 x Fan_eff) x W/cfm
A28: Fan_eff=0.65
A32: Background Data [To be deleted prior to publication]

Sheet Thermostat
A1: ="Thermostat Setpoints - "&Prototype!A2 -> Thermostat Setpoints - SchoolK-8
A2: Setpoint | B2: CZ1 | C2: CZ2 | D2: CZ3 | E2: CZ4 | F2: CZ5 | G2: CZ6 | H2: CZ7 | I2: CZ8 | J2: CZ9 | K2: CZ10 | L2: CZ11 | M2: CZ12 | N2: CZ13 | O2: CZ14 | P2: CZ15 | Q2: CZ16 | R2: Source
A3: School Heating Setpoint (F) | B3: 70 | C3: 70 | D3: 70 | E3: 70 | F3: 70 | G3: 70 | H3: 70 | I3: 70 | J3: 70 | K3: 70 | L3: 70 | M3: 70 | N3: 70 | O3: 70 | P3: 70 | Q3: 70 | R3: T24 2022 - Appendix 5.4B
A4: School Heating Setback (F) | B4: 60 | C4: 60 | D4: 60 | E4: 60 | F4: 60 | G4: 60 | H4: 60 | I4: 60 | J4: 60 | K4: 60 | L4: 60 | M4: 60 | N4: 60 | O4: 60 | P4: 60 | Q4: 60
A5: School Cooling Setpoint (F) | B5: 75 | C5: 75 | D5: 75 | E5: 75 | F5: 75 | G5: 75 | H5: 75 | I5: 75 | J5: 75 | K5: 75 | L5: 75 | M5: 75 | N5: 75 | O5: 75 | P5: 75 | Q5: 75 | R5: T24 2022 - Appendix 5.4B
A6: School Cooling Setback (F) | B6: 85 | C6: 85 | D6: 85 | E6: 85 | F6: 85 | G6: 85 | H6: 85 | I6: 85 | J6: 85 | K6: 85 | L6: 85 | M6: 85 | N6: 85 | O6: 85 | P6: 85 | Q6: 85

Sheet Ventilation
A1: ="Outdoor Airflow Rate - "&Prototype!A2 -> Outdoor Airflow Rate - SchoolK-8
A2: Space Type | B2: Space/Thermal Zone | C2: Number of People | D2: Floor Area (ft²) | E2: cfm/person [T24, 2025, Equation 120.1-F and Table 120.1-A] | F2: cfm/ft² [T24, 2025, Equation 120.1-F and Table 120.1-A] | G2: Required exhaust rate-CFM/ft²- [T24, 2025, Table 120.1-B – minimum exhaust rates] | H2: Total cfm driven by people | I2: Total cfm driven by area | J2: Total cfm driven by exhaust | K2: Total cfm | L2: Notes
A3: =Zones!A3 -> Lounge, Breakroom, or Waiting Area | B3: =Zones!B3 -> Admin/MPR_Breakroom_Zn | C3: =Zones!J3 -> 37.9632 | D3: =Zones!G3 -> 575.2 | E3: 15 | F3: 0.15 | H3: =C3*E3 -> 569.448 | I3: =D3*F3 -> 86.28 | J3: =G3*D3 -> 0 | K3: =MAX(H3,I3,J3) -> 569.448
A4: =Zones!A4 -> Convention, Conference, Multipurpose and Meeting Area | B4: =Zones!B4 -> Admin/MPR_Conference Room Zns 3_Zn | C4: =Zones!J4 -> 110.53284 | D4: =Zones!G4 -> 1674.74 | E4: 15 | F4: 0.15 | H4: =C4*E4 -> 1657.9926 | I4: =D4*F4 -> 251.211 | J4: =G4*D4 -> 0 | K4: =MAX(H4,I4,J4) -> 1657.9926
A5: =Zones!A5 -> Corridor Area | B5: =Zones!B5 -> Admin/MPR_Corridor_Zn | C5: =Zones!J5 -> 11.6152 | D5: =Zones!G5 -> 1161.52 | E5: 30 | F5: 0.15 | H5: =C5*E5 -> 348.456 | I5: =D5*F5 -> 174.228 | J5: =G5*D5 -> 0 | K5: =MAX(H5,I5,J5) -> 348.456
A6: =Zones!A6 -> Electrical, Mechanical, Telephone Rooms | B6: =Zones!B6 -> Admin/MPR_EMT_Zn | C6: =Zones!J6 -> 2.7821 | D6: =Zones!G6 -> 278.21 | E6: 30 | F6: 0.15 | H6: =C6*E6 -> 83.463 | I6: =D6*F6 -> 41.7315 | J6: =G6*D6 -> 0 | K6: =MAX(H6,I6,J6) -> 83.463
A7: =Zones!A7 -> Electrical, Mechanical, Telephone Rooms | B7: =Zones!B7 -> Admin/MPR_IDF Room_Zn | C7: =Zones!J7 -> 3.4023 | D7: =Zones!G7 -> 340.23 | E7: 30 | F7: 0.15 | H7: =C7*E7 -> 102.069 | I7: =D7*F7 -> 51.0345 | J7: =G7*D7 -> 0 | K7: =MAX(H7,I7,J7) -> 102.069
A8: =Zones!A8 -> Kitchen/Food Preparation Area | B8: =Zones!B8 -> Admin/MPR_Kitchen_Zn | C8: =Zones!J8 -> 8.7435 | D8: =Zones!G8 -> 1457.25 | E8: 50 | F8: 0.15 | H8: =C8*E8 -> 437.175 | I8: =D8*F8 -> 218.5875 | J8: =G8*D8 -> 0 | K8: =MAX(H8,I8,J8) -> 437.175
A9: =Zones!A9 -> Lobby, Main Entry | B9: =Zones!B9 -> Admin/MPR_Lobby_Zn | C9: =Zones!J9 -> 81.93702 | D9: =Zones!G9 -> 1241.47 | E9: 15 | F9: 0.15 | H9: =C9*E9 -> 1229.0553 | I9: =D9*F9 -> 186.2205 | J9: =G9*D9 -> 0 | K9: =MAX(H9,I9,J9) -> 1229.0553
A10: =Zones!A10 -> Convention, Conference, Multipurpose and Meeting Area | B10: =Zones!B10 -> Admin/MPR_Multipurpose Room Zns 3_Zn | C10: =Zones!J10 -> 363.80454 | D10: =Zones!G10 -> 5512.19 | E10: 15 | F10: 0.15 | H10: =C10*E10 -> 5457.0681 | I10: =D10*F10 -> 826.8285 | J10: =G10*D10 -> 0 | K10: =MAX(H10,I10,J10) -> 5457.0681
A11: =Zones!A11 -> Office Area (<250 square feet) | B11: =Zones!B11 -> Admin/MPR_Office - LT 250 sf Zns 6_Zn | C11: =Zones!J11 -> 10.4835 | D11: =Zones!G11 -> 1048.35 | E11: 30 | F11: 0.15 | H11: =C11*E11 -> 314.505 | I11: =D11*F11 -> 157.2525 | J11: =G11*D11 -> 0 | K11: =MAX(H11,I11,J11) -> 314.505
A12: =Zones!A12 -> Restrooms | B12: =Zones!B12 -> Admin/MPR_Restroom Zns 3_Zn | C12: =Zones!J12 -> 9.0117 | D12: =Zones!G12 -> 901.17 | E12: 15 | F12: 0.15 | H12: =C12*E12 -> 135.1755 | I12: =D12*F12 -> 135.1755 | J12: =G12*D12 -> 0 | K12: =MAX(H12,I12,J12) -> 135.1755
A13: =Zones!A13 -> Storage (General) | B13: =Zones!B13 -> Admin/MPR_Storage - General_Zn | C13: =Zones!J13 -> 12.4773 | D13: =Zones!G13 -> 1247.73 | E13: 30 | F13: 0.15 | H13: =C13*E13 -> 374.319 | I13: =D13*F13 -> 187.1595 | J13: =G13*D13 -> 0 | K13: =MAX(H13,I13,J13) -> 374.319
A14: =Zones!A14 -> Storage, Commercial/Industrial (Refrigerated) | B14: =Zones!B14 -> Admin/MPR_Storage - Refrigerated_Zn | C14: =Zones!J14 -> 0 | D14: =Zones!G14 -> 251.72 | E14: 0 | F14: 0.15 | H14: =C14*E14 -> 0 | I14: =D14*F14 -> 37.758 | J14: =G14*D14 -> 0 | K14: =MAX(H14,I14,J14) -> 37.758
... A40: =Zones!A40 -> Storage (General) | B40: =Zones!B40 -> Kindergarten_Storage - General_Zn | C40: =Zones!J40 -> 11.838 | D40: =Zones!G40 -> 1183.8 | E40: 30 | F40: 0.15 | H40: =C40*E40 -> 355.14 | I40: =D40*F40 -> 177.57 | J40: =G40*D40 -> 0 | K40: =MAX(H40,I40,J40) -> 355.14
A41: =Zones!A41 -> Total (15 Space types) | B41: =Zones!B41 -> Total (38 spaces) | C41: =Zones!J41 -> 2136.655 | D41: =Zones!G41 -> 49979.37 | H41: =SUM(H3:H40) -> 33392.546 | I41: =SUM(I3:I40) -> 7496.9055 | J41: =SUM(J3:J40) -> 0 | K41: =SUM(K3:K40) -> 33430.304

Sheet Water Heater
A1: ="Water Heater -"&Prototype!A2 -> Water Heater -SchoolK-8
A2: Vintage | B2: WH Type | C2: Efficiency | D2: Tank Volume (gal) | E2: Tank Loss | G2: Note
A3: Existing | B3: Electric | C3: 0.98 | D3: =F50 -> 141.21652 | E3: =G50 -> 0.49119576 | F3: %hr
A4: New Construction | B4: HPWH | C4: =B71 -> 1.7562732 | D4: =F55 -> 141.21652 | E4: =G55 -> 0.49119576 | F4: %hr | G4: - Section 1605.1. Federal and State Standards for Federally-Regulated Appliances. - HPWH is required in climate zones 2-15, with UEF of 2.25.
A6: Peak Hot Water Consumption
A7: Space Name | B7: Baseline WH Type [T24, 2022, Appendix 5.4A , sheet: "2022 SpaceFuncData-Input"] | C7: Total Area (ft²) | D7: Number of People | E7: Hot Water Usage Specification (gal/hr per person) [T24, 2022, Appendix 5.4A , sheet: "2022 SpaceFuncData-Input"] | F7: Peak Hot Water Usage (gal/hr) | G7: Peak Hot Water Usage (gal/min)
A8: =Zones!B3 -> Admin/MPR_Breakroom_Zn | B8: HPWH | C8: =Zones!G3 -> 575.2 | D8: =Zones!J3 -> 37.9632 | E8: 0.09 | F8: =E8*D8 -> 3.416688 | G8: =F8/60 -> 0.0569448
A9: =Zones!B4 -> Admin/MPR_Conference Room Zns 3_Zn | B9: HPWH | C9: =Zones!G4 -> 1674.74 | D9: =Zones!J4 -> 110.53284 | E9: 0.09 | F9: =E9*D9 -> 9.9479556 | G9: =F9/60 -> 0.16579926
A10: =Zones!B5 -> Admin/MPR_Corridor_Zn | B10: HPWH | C10: =Zones!G5 -> 1161.52 | D10: =Zones!J5 -> 11.6152 | E10: 0 | F10: =E10*D10 -> 0 | G10: =F10/60 -> 0
A11: =Zones!B6 -> Admin/MPR_EMT_Zn | B11: HPWH | C11: =Zones!G6 -> 278.21 | D11: =Zones!J6 -> 2.7821 | E11: 0.18 | F11: =E11*D11 -> 0.500778 | G11: =F11/60 -> 0.0083463
A12: =Zones!B7 -> Admin/MPR_IDF Room_Zn | B12: HPWH | C12: =Zones!G7 -> 340.23 | D12: =Zones!J7 -> 3.4023 | E12: 0.18 | F12: =E12*D12 -> 0.612414 | G12: =F12/60 -> 0.0102069
A13: =Zones!B8 -> Admin/MPR_Kitchen_Zn | B13: HPWH | C13: =Zones!G8 -> 1457.25 | D13: =Zones!J8 -> 8.7435 | E13: 0.578 | F13: =E13*D13 -> 5.053743 | G13: =F13/60 -> 0.08422905
A14: =Zones!B9 -> Admin/MPR_Lobby_Zn | B14: HPWH | C14: =Zones!G9 -> 1241.47 | D14: =Zones!J9 -> 81.93702 | E14: 0.09 | F14: =E14*D14 -> 7.3743318 | G14: =F14/60 -> 0.12290553
A15: =Zones!B10 -> Admin/MPR_Multipurpose Room Zns 3_Zn | B15: HPWH | C15: =Zones!G10 -> 5512.19 | D15: =Zones!J10 -> 363.80454 | E15: 0.09 | F15: =E15*D15 -> 32.742409 | G15: =F15/60 -> 0.54570681
A16: =Zones!B11 -> Admin/MPR_Office - LT 250 sf Zns 6_Zn | B16: HPWH | C16: =Zones!G11 -> 1048.35 | D16: =Zones!J11 -> 10.4835 | E16: 0.18 | F16: =E16*D16 -> 1.88703 | G16: =F16/60 -> 0.0314505
A17: =Zones!B12 -> Admin/MPR_Restroom Zns 3_Zn | B17: HPWH | C17: =Zones!G12 -> 901.17 | D17: =Zones!J12 -> 9.0117 | E17: 0 | F17: =E17*D17 -> 0 | G17: =F17/60 -> 0
A18: =Zones!B13 -> Admin/MPR_Storage - General_Zn | B18: HPWH | C18: =Zones!G13 -> 1247.73 | D18: =Zones!J13 -> 12.4773 | E18: 0 | F18: =E18*D18 -> 0 | G18: =F18/60 -> 0
A19: =Zones!B14 -> Admin/MPR_Storage - Refrigerated_Zn | B19: HPWH | C19: =Zones!G14 -> 251.72 | D19: =Zones!J14 -> 0 | E19: 0.18 | F19: =E19*D19 -> 0 | G19: =F19/60 -> 0
... A45: =Zones!B40 -> Kindergarten_Storage - General_Zn | B45: HPWH | C45: =Zones!G40 -> 1183.8 | D45: =Zones!J40 -> 11.838 | E45: 0 | F45: =E45*D45 -> 0 | G45: =F45/60 -> 0
A46: Total | C46: =SUM(C8:C45) -> 49979.37 | D46: =SUM(D8:D45) -> 2136.655 | F46: =SUM(F8:F45) -> 314.89192 | G46: =F46/60 -> 5.2481986
A48: Water Heater Capacity, Tank Capacity, and Tank Loss
A49: WH Type | B49: Peak Hot Water Usage (gal/hr) | C49: Heat Output (Btu/hr) [ACM, 2025, 5.9.2: Rated capacity section] | D49: WH Capacity (Btu/hr) [ACM, 2025, 5.9.2: Rated capacity section] | E49: Required Energy Input (Btu/hr) | F49: Storage Volume (gal) | G49: Standby Loss | H49: Unit | I49: Off/On Cycle Loss Coefficient to Ambient Temp (Btu/h-F) | J49: Source
A50: Electric | B50: =SUM(B51:B54) -> 353.04131 | C50: =B50*(135-55)*8.345*1 -> 235690.38 | D50: =C50*0.6 -> 141414.23 | E50: =D50/0.98 -> 144300.23 | F50: =B50*1*0.4 -> 141.21652 | G50: =IFERROR(0.3+(27/F50),0) -> 0.49119576 | H50: %hr | I50: =0.0825*G50*F50 -> 5.7226089 | J50: - Tank size equation: 2022/2025 Nonres & MF ACM, §5.9.2 ‘Storage Volume - Heat output equation: Nonres/MF ACM 2019/2022/2025, §5.9.2 ‘Rated Capacity - Input capacity / efficiency source: ACM §5.9.2 ‘Rated Capacity’ + Title 20 CCR §1605.1(f), Tables F-2/F-4 (Appliance Efficiency Regulations) - Standby loss equation (STBY in Btu/h): ACM §5.9.2 ‘Tank Standby Loss’; test method parameters from Title 20 Appliance Efficiency Regs, Section 1604(f). - Standby-loss limit Sₘₐₓ (%/h): 42 U.S.C. §6313(a)(5)(A); DOE 10 CFR Part 431 Subpart G; adopted in California Title 20 CCR §1605.1(f), Table F-4.
A51: HPWH - Admin | B51: =MAX(SUMIF(B8:B20, "*HPWH*",F8:F20),75) -> 75 | C51: =B51*(135-55)*8.345*1 -> 50070 | D51: =C51*0.6 -> 30042 | E51: =D51/B71 -> 17105.539 | F51: =(B51*F55)/B55 -> 30 | G51: =IFERROR(0.3+(27/F51),0) -> 1.2 | H51: %hr | I51: =0.0825*G51*F51 -> 2.97
A52: HPWH - North Classroom | B52: =MAX(SUMIF(B21:B28, "*HPWH*",F21:F28),75) -> 128.04131 | C52: =B52*(135-55)*8.345*1 -> 85480.377 | D52: =C52*0.6 -> 51288.226 | E52: =D52/B71 -> 29202.875 | F52: =(B52*F55)/B55 -> 51.216523 | G52: =IFERROR(0.3+(27/F52),0) -> 0.82717362 | H52: %hr | I52: =0.0825*G52*F52 -> 3.4951089
A53: HPWH - West Classroom | B53: =MAX(SUMIF(B29:B39, "*HPWH*",F29:F39),75) -> 75 | C53: =B53*(135-55)*8.345*1 -> 50070 | D53: =C53*0.6 -> 30042 | E53: =D53/B71 -> 17105.539 | F53: =(B53*F55)/B55 -> 30 | G53: =IFERROR(0.3+(27/F53),0) -> 1.2 | H53: %hr | I53: =0.0825*G53*F53 -> 2.97
A54: HPWH - Kindergarten | B54: =MAX(SUMIF(B40:B45, "*HPWH*",F40:F45),75) -> 75 | C54: =B54*(135-55)*8.345*1 -> 50070 | D54: =C54*0.6 -> 30042 | E54: =D54/B71 -> 17105.539 | F54: =(B54*F55)/B55 -> 30 | G54: =IFERROR(0.3+(27/F54),0) -> 1.2 | H54: %hr | I54: =0.0825*G54*F54 -> 2.97
A55: HPWH - Total | B55: =SUM(B51:B54) -> 353.04131 | C55: =B55*(135-55)*8.345*1 -> 235690.38 | D55: =C55*0.6 -> 141414.23 | E55: =D55/B71 -> 80519.494 | F55: =B55*1*0.4 -> 141.21652 | G55: =IFERROR(0.3+(27/F55),0) -> 0.49119576 | H55: %hr | I55: =0.0825*G55*F55 -> 5.7226089
A56: -
A58: Design supply temperature (F) | B58: 135 | C58: Ref: T24 2022 - Appendix 5.4B
A59: Cold Water supply temperature (F) | B59: 55 | C59: Ref: ACM, 2025, 5.9.2: Rated capacity section
A60: WH system factor | B60: 0.6 | C60: Ref: ACM, 2025, 5.9.2: Rated capacity section
A61: Reheat multiplier | B61: 0.4
A62: * The 0.40 multiplier is a storage sizing factor used to account for the fact that the water heater doesn't need to store the full peak hour demand—it can reheat water during that time. This factor assumes that the heater will recover part of the hot water used during the peak hour, so only 40% of the peak hour demand needs to be stored at any given moment.
A63: **For Gas Water Heater: UA(Btu/h-°F)​=Q˙​SL​ (Btu/h)/ΔT (∘F)​
A64: Ambient temp | B64: 68
A65: Delta T | B65: =B58-B64 -> 67
A66: ** For Electric Water Heater: UA(Btu/h-°F)​= 0.0834 *SL​ (%/hr)*V gal
A68: DV (daily hot water Volume in gallons, DOE UEF tests) | B68: 38 | C68: Note: 10 (very small draw), 38 (low draw), 55 (Medium draw), or 84 (high draw)
A69: UEF = 0.1513 + 0.8407 * EF + 0.0043 * DV | B69: 2.15 | C69: Source: https://energy.gov/sites/prod/files/2016/12/f34/WH_Conversion_Final%20Rule.pdf
...

Sheet Interior Lights
A1: ="Interior Lighting - "&Prototype!A2 -> Interior Lighting - SchoolK-8
A2: Space Type | B2: New Construction | E2: Existing
B3: Lighting density (W/ft²) | C3: Additional lighting power for porTable lighting (W/ft²) | D3: Source | E3: LPD (W/ft²) | F3: Additional LPD for PorTable Lighting (W/ft²) | G3: Source
A4: =Zones!A3 -> Lounge, Breakroom, or Waiting Area | B4: 0.55 | D4: T24, 2025, Table 140.6 C (Area category method) | E4: 0.9 | G4: T24, 2016, Table 140.6 C (Area category method)
A5: =Zones!A4 -> Convention, Conference, Multipurpose and Meeting Area | B5: 0.75 | E5: 1.2
A6: =Zones!A5 -> Corridor Area | B6: 0.4 | E6: 0.6
A7: =Zones!A6 -> Electrical, Mechanical, Telephone Rooms | B7: 0.4 | E7: 0.55
A8: =Zones!A8 -> Kitchen/Food Preparation Area | B8: 0.95 | E8: 1.2
A9: =Zones!A9 -> Lobby, Main Entry | B9: 0.7 | E9: 0.95
A10: =Zones!A12 -> Restrooms | B10: 0.65 | E10: 0.6
A11: =Zones!A13 -> Storage (General) | B11: 0.4 | E11: 0.6
A12: =Zones!A14 -> Storage, Commercial/Industrial (Refrigerated) | B12: 0.4 | E12: 0.7
A13: =Zones!A15 -> Theater Area (Performance) | B13: 0.8 | E13: 1.4
A14: =Zones!A16 -> Classroom, Lecture, Training, Vocational Areas | B14: 0.6 | E14: 1.2
A15: =Zones!A22 -> Office Area (<250 square feet) | B15: 0.65 | E15: 1
A16: =Zones!A27 -> Library (Reading Area) | B16: 0.8 | E16: 1.1

Sheet Equipment
A1: ="Equipment - "&Prototype!A2 -> Equipment - SchoolK-8
A2: Space Type | B2: Plug load Power Density (W/ft²) | C2: Gas Power Density (Btu/hr-ft²) | D2: Refrigeration Power Density (W/ft²) | E2: Source
A3: =Zones!A3 -> Lounge, Breakroom, or Waiting Area | B3: 1 | C3: 0 | D3: 0 | E3: T24 2022 - Appendix 5.4A
A4: =Zones!A4 -> Convention, Conference, Multipurpose and Meeting Area | B4: 1 | C4: 0 | D4: 0
A5: =Zones!A5 -> Corridor Area | B5: 0 | C5: 0 | D5: 0
A6: =Zones!A6 -> Electrical, Mechanical, Telephone Rooms | B6: 3 | C6: 0 | D6: 0
A7: =Zones!A8 -> Kitchen/Food Preparation Area | B7: 1.5 | C7: 17.53768 | D7: 1.12 | E7: Plug load and schedules project with CEC, 2025
A8: =Zones!A9 -> Lobby, Main Entry | B8: 0.5 | C8: 0 | D8: 0 | E8: T24 2022 - Appendix 5.4A
A9: =Zones!A11 -> Office Area (<250 square feet) | B9: 0.7 | C9: 0 | D9: 0 | E9: Plug load and schedules project with CEC, 2025
A10: =Zones!A12 -> Restrooms | B10: 0 | C10: 0 | D10: 0 | E10: T24 2022 - Appendix 5.4A
A11: =Zones!A13 -> Storage (General) | B11: 0.2 | C11: 0 | D11: 0
A12: =Zones!A14 -> Storage, Commercial/Industrial (Refrigerated) | B12: 0.2 | C12: 0 | D12: 10
A13: =Zones!A15 -> Theater Area (Performance) | B13: 0.5 | C13: 0 | D13: 0
A14: =Zones!A16 -> Classroom, Lecture, Training, Vocational Areas | B14: 0.8 | C14: 0 | D14: 0 | E14: Plug load and schedules project with CEC, 2025
A15: =Zones!A27 -> Library (Reading Area) | B15: 1.5 | C15: 0 | D15: 0
A17: Elevator
A18: Vintages | B18: No of Elevator | C18: Design Load (W) | D18: Source
A19: New Construction and Existing | B19: =ROUND((7876*0.7/50000)+ROUND(2/2,0),0) -> 1 | C19: =C24*1000 -> 60000 | D19: ACM with assumptions listed below | F19: https://buildingandinteriors.com/find-the-magic-number-elevators-per-building/
A21: For every two floors or two and a half floors, one more elevator was added.
A22: An in-use rate of 70% for the floor area was assumed, based on engineering judgment.
A23: Calculated number of Elevators: | C23: =ROUND((7876*0.7/50000)+ROUND(2/2,0),0) -> 1
A24: Calculate Elevator load (kw)based on ACM 2022: | C24: =6*C25 -> 60
A25: ACM 2022 suggestion for elevator load (kw): | C25: 10
A26: Elevator load will be defined as exterior load not equipment load

Sheet Ext Lighting
A1: ="Exterior Lighting - "&Prototype!A2 -> Exterior Lighting - SchoolK-8
A2: Motion Controlled Luminaires (W) | B2: Non-motion Controlled Luminaires (W) | C2: Total (W) | D2: Source
A3: =G14 -> 717.64233 | B3: =G15 -> 9012.8416 | C3: =A3+B3 -> 9730.4839 | D3: T24, 2022 & 2025 2019 Outdoor Lighting CASE report PNNL 90.1-2010 TSD
A7: ="Exterior Lighting" -> Exterior Lighting
A8: Items (Assume LZ2) | B8: Assumptions [2019 Outdoor Lighting CASE Report & PNNL 90.1-2010 TS] | D8: Unit | E8: Lighting Power Allowance [T24, 2025, Table 140.7-A & 140.7-B] | F8: Unit | G8: Exterior Lighting Power (W)
A9: IWA (Initial Wattage Allowance) | E9: 200 | F9: (W) | G9: =$E9 -> 200
A10: Parking area | B10: 400 ft² for every parking space 1 parking space per 830 ft² of gross building area | C10: =B25/830*400 -> 24086.439 | D10: (ft²) | E10: 0.019 | F10: (W/ft²) | G10: =E10*C10 -> 457.64233
A11: Building Entrance | B11: 5 building entrance per PNNL Model (1 per 10,000 ft² footprint) | C11: 4 | D11: (count) | E11: 15 | F11: (W/ea) | G11: =E11*C11 -> 60
A12: Hardscape Ornamental Light | B12: 0.1 ft² per 1 ft² of gross building area for hardscape ornamental light | C12: =B25*0.1 -> 4997.936 | D12: (ft²) | E12: 0.007 | F12: (W/ft²) | G12: =E12*C12 -> 34.985552
A13: Building façade | B13: 0.1 W per 1 ft² of facade area Façade Area = Perimeter × 0.5 × max ( height and 30) (30 ft is the max height that is lit) * The 0.5 factor assumes that only half of the perimeter walls are lit. -Formula ia developed based on the 2019 Outdoor Lighting CASE report | C13: =0.5*4*(B20*B21+C20*C21+D20*D21+E20*E21) -> 89778.56 | D13: (ft²) | E13: 0.1 | F13: (W/ft²) | G13: =E13*C13 -> 8977.856
A14: Motion Controlled Luminaires (W) | G14: =G10+G9+G11 -> 717.64233
A15: Non-motion-controlled Luminaires | G15: =G12+G13 -> 9012.8416
A16: Total | G16: =G14+G15 -> 9730.4839
B19: North Classroom | C19: West Classroom | D19: Kindergarten | E19: MPR/Admin
A20: Perimeter of each buildings (ft) | B20: =(235.1+33.5)*2 -> 537.2 | C20: =(129.08+34.2)*2 -> 326.56 | D20: =(192+45)*2 -> 474 | E20: =(195.8+85.56)*2 -> 562.72
A21: Max Height that is lit for each buildings (ft) | B21: 28 | C21: 28 | D21: 14 | E21: 25
A22: Each building footprint | B22: 7876 | C22: 4415 | D22: 8640 | E22: 16754
A23: Floors | B23: 2 | C23: 2 | D23: 1 | E23: 1
A24: Total Perimeter (ft) | B24: =SUM(B20:E20) -> 1900.48
A25: Total floor area (ft²) | B25: =Prototype!B8 -> 49979.36
A26: Background Data [To be deleted prior to publication]

Sheet Schedules
A1: Schedules - SchoolLarge
A2: Zone | B2: Schedule Category | C2: Schedule | D2: Source | E2: Type | F2: Hour
F3: 1 | G3: 2 | H3: 3 | I3: 4 | J3: 5 | K3: 6 | L3: 7 | M3: 8 | N3: 9 | O3: 10 | P3: 11 | Q3: 12 | R3: 13 | S3: 14 | T3: 15 | U3: 16 | V3: 17 | W3: 18 | X3: 19 | Y3: 20 | Z3: 21 | AA3: 22 | AB3: 23 | AC3: 24
A4: School Zones | B4: Classroom | C4: Occupancy | D4: T24 2022 - Appendix 5.4B [School] | E4: Weekday | F4: 0 | G4: 0 | H4: 0 | I4: 0 | J4: 0 | K4: 0 | L4: 0 | M4: 0.05 | N4: 0.75 | O4: 0.9 | P4: 0.9 | Q4: 0.8 | R4: 0.8 | S4: 0.8 | T4: 0.8 | U4: 0.45 | V4: 0.15 | W4: 0.05 | X4: 0.15 | Y4: 0.2 | Z4: 0.2 | AA4: 0.1 | AB4: 0 | AC4: 0
E5: Saturday | F5: 0 | G5: 0 | H5: 0 | I5: 0 | J5: 0 | K5: 0 | L5: 0 | M5: 0 | N5: 0.1 | O5: 0.1 | P5: 0.1 | Q5: 0.1 | R5: 0.1 | S5: 0 | T5: 0 | U5: 0 | V5: 0 | W5: 0 | X5: 0 | Y5: 0 | Z5: 0 | AA5: 0 | AB5: 0 | AC5: 0
E6: Sunday | F6: 0 | G6: 0 | H6: 0 | I6: 0 | J6: 0 | K6: 0 | L6: 0 | M6: 0 | N6: 0 | O6: 0 | P6: 0 | Q6: 0 | R6: 0 | S6: 0 | T6: 0 | U6: 0 | V6: 0 | W6: 0 | X6: 0 | Y6: 0 | Z6: 0 | AA6: 0 | AB6: 0 | AC6: 0
A7: School Zones | B7: Classroom | C7: Lights | D7: T24 2022 - Appendix 5.4B [School] | E7: Weekday | F7: 0.05 | G7: 0.05 | H7: 0.05 | I7: 0.05 | J7: 0.05 | K7: 0.05 | L7: 0.05 | M7: 0.3 | N7: 0.6 | O7: 0.65 | P7: 0.65 | Q7: 0.65 | R7: 0.55 | S7: 0.55 | T7: 0.55 | U7: 0.5 | V7: 0.35 | W7: 0.35 | X7: 0.35 | Y7: 0.35 | Z7: 0.35 | AA7: 0.3 | AB7: 0.05 | AC7: 0.05
E8: Saturday | F8: 0.05 | G8: 0.05 | H8: 0.05 | I8: 0.05 | J8: 0.05 | K8: 0.05 | L8: 0.05 | M8: 0.05 | N8: 0.15 | O8: 0.15 | P8: 0.15 | Q8: 0.15 | R8: 0.15 | S8: 0.05 | T8: 0.05 | U8: 0.05 | V8: 0.05 | W8: 0.05 | X8: 0.05 | Y8: 0.05 | Z8: 0.05 | AA8: 0.05 | AB8: 0.05 | AC8: 0.05
E9: Sunday | F9: 0.05 | G9: 0.05 | H9: 0.05 | I9: 0.05 | J9: 0.05 | K9: 0.05 | L9: 0.05 | M9: 0.05 | N9: 0.05 | O9: 0.05 | P9: 0.05 | Q9: 0.05 | R9: 0.05 | S9: 0.05 | T9: 0.05 | U9: 0.05 | V9: 0.05 | W9: 0.05 | X9: 0.05 | Y9: 0.05 | Z9: 0.05 | AA9: 0.05 | AB9: 0.05 | AC9: 0.05
A10: School Zones | B10: Classroom | C10: ElecEquipment | D10: T24 2022 - Appendix 5.4B [School] | E10: Weekday | F10: 0.05 | G10: 0.05 | H10: 0.05 | I10: 0.05 | J10: 0.05 | K10: 0.05 | L10: 0.05 | M10: 0.3 | N10: 0.85 | O10: 0.95 | P10: 0.95 | Q10: 0.95 | R10: 0.8 | S10: 0.8 | T10: 0.8 | U10: 0.7 | V10: 0.5 | W10: 0.5 | X10: 0.35 | Y10: 0.35 | Z10: 0.35 | AA10: 0.3 | AB10: 0.05 | AC10: 0.05
E11: Saturday | F11: 0.05 | G11: 0.05 | H11: 0.05 | I11: 0.05 | J11: 0.05 | K11: 0.05 | L11: 0.05 | M11: 0.05 | N11: 0.15 | O11: 0.15 | P11: 0.15 | Q11: 0.15 | R11: 0.15 | S11: 0.05 | T11: 0.05 | U11: 0.05 | V11: 0.05 | W11: 0.05 | X11: 0.05 | Y11: 0.05 | Z11: 0.05 | AA11: 0.05 | AB11: 0.05 | AC11: 0.05
E12: Sunday | F12: 0.05 | G12: 0.05 | H12: 0.05 | I12: 0.05 | J12: 0.05 | K12: 0.05 | L12: 0.05 | M12: 0.05 | N12: 0.05 | O12: 0.05 | P12: 0.05 | Q12: 0.05 | R12: 0.05 | S12: 0.05 | T12: 0.05 | U12: 0.05 | V12: 0.05 | W12: 0.05 | X12: 0.05 | Y12: 0.05 | Z12: 0.05 | AA12: 0.05 | AB12: 0.05 | AC12: 0.05
A13: School Zones | B13: Classroom | C13: ServiceHotWater | D13: T24 2022 - Appendix 5.4B [School] | E13: Weekday | F13: 0.05 | G13: 0.05 | H13: 0.05 | I13: 0.05 | J13: 0.05 | K13: 0.05 | L13: 0.05 | M13: 0.1 | N13: 0.34 | O13: 0.6 | P13: 0.63 | Q13: 0.72 | R13: 0.79 | S13: 0.83 | T13: 0.61 | U13: 0.65 | V13: 0.1 | W13: 0.1 | X13: 0.19 | Y13: 0.25 | Z13: 0.22 | AA13: 0.22 | AB13: 0.12 | AC13: 0.09
E14: Saturday | F14: 0.03 | G14: 0.03 | H14: 0.03 | I14: 0.03 | J14: 0.03 | K14: 0.03 | L14: 0.03 | M14: 0.03 | N14: 0.03 | O14: 0.05 | P14: 0.05 | Q14: 0.05 | R14: 0.05 | S14: 0.03 | T14: 0.03 | U14: 0.03 | V14: 0.03 | W14: 0.03 | X14: 0.03 | Y14: 0.03 | Z14: 0.03 | AA14: 0.03 | AB14: 0.03 | AC14: 0.03
E15: Sunday | F15: 0.03 | G15: 0.03 | H15: 0.03 | I15: 0.03 | J15: 0.03 | K15: 0.03 | L15: 0.03 | M15: 0.03 | N15: 0.05 | O15: 0.05 | P15: 0.05 | Q15: 0.05 | R15: 0.05 | S15: 0.05 | T15: 0.03 | U15: 0.03 | V15: 0.03 | W15: 0.03 | X15: 0.03 | Y15: 0.03 | Z15: 0.03 | AA15: 0.03 | AB15: 0.03 | AC15: 0.03
A16: School Zones | B16: Classroom | C16: GasEquipment | D16: T24 2022 - Appendix 5.4B [School] | E16: Weekday | F16: 0 | G16: 0 | H16: 0 | I16: 0 | J16: 0 | K16: 0 | L16: 0 | M16: 0.5 | N16: 0.5 | O16: 0.75 | P16: 0.9 | Q16: 0.9 | R16: 0.9 | S16: 0 | T16: 0 | U16: 0 | V16: 0 | W16: 0 | X16: 0 | Y16: 0 | Z16: 0 | AA16: 0 | AB16: 0 | AC16: 0
E17: Saturday | F17: 0 | G17: 0 | H17: 0 | I17: 0 | J17: 0 | K17: 0 | L17: 0 | M17: 0 | N17: 0 | O17: 0 | P17: 0 | Q17: 0 | R17: 0 | S17: 0 | T17: 0 | U17: 0 | V17: 0 | W17: 0 | X17: 0 | Y17: 0 | Z17: 0 | AA17: 0 | AB17: 0 | AC17: 0
E18: Sunday | F18: 0 | G18: 0 | H18: 0 | I18: 0 | J18: 0 | K18: 0 | L18: 0 | M18: 0 | N18: 0 | O18: 0 | P18: 0 | Q18: 0 | R18: 0 | S18: 0 | T18: 0 | U18: 0 | V18: 0 | W18: 0 | X18: 0 | Y18: 0 | Z18: 0 | AA18: 0 | AB18: 0 | AC18: 0
A19: School Zones | B19: Classroom | C19: Refrigeration | D19: T24 2022 - Appendix 5.4B [School] | E19: Weekday | F19: 0.9 | G19: 0.9 | H19: 0.9 | I19: 0.9 | J19: 0.9 | K19: 0.9 | L19: 0.9 | M19: 0.9 | N19: 0.9 | O19: 0.9 | P19: 0.9 | Q19: 0.9 | R19: 0.9 | S19: 0.9 | T19: 0.9 | U19: 0.9 | V19: 0.9 | W19: 0.9 | X19: 0.9 | Y19: 0.9 | Z19: 0.9 | AA19: 0.9 | AB19: 0.9 | AC19: 0.9
E20: Saturday | F20: 0.9 | G20: 0.9 | H20: 0.9 | I20: 0.9 | J20: 0.9 | K20: 0.9 | L20: 0.9 | M20: 0.9 | N20: 0.9 | O20: 0.9 | P20: 0.9 | Q20: 0.9 | R20: 0.9 | S20: 0.9 | T20: 0.9 | U20: 0.9 | V20: 0.9 | W20: 0.9 | X20: 0.9 | Y20: 0.9 | Z20: 0.9 | AA20: 0.9 | AB20: 0.9 | AC20: 0.9
E21: Sunday | F21: 0.9 | G21: 0.9 | H21: 0.9 | I21: 0.9 | J21: 0.9 | K21: 0.9 | L21: 0.9 | M21: 0.9 | N21: 0.9 | O21: 0.9 | P21: 0.9 | Q21: 0.9 | R21: 0.9 | S21: 0.9 | T21: 0.9 | U21: 0.9 | V21: 0.9 | W21: 0.9 | X21: 0.9 | Y21: 0.9 | Z21: 0.9 | AA21: 0.9 | AB21: 0.9 | AC21: 0.9
A22: School Zones | B22: Classroom | C22: HVACAvail | D22: T24 2022 - Appendix 5.4B [School] | E22: Weekday | F22: 0 | G22: 0 | H22: 0 | I22: 0 | J22: 0 | K22: 0 | L22: 1 | M22: 1 | N22: 1 | O22: 1 | P22: 1 | Q22: 1 | R22: 1 | S22: 1 | T22: 1 | U22: 1 | V22: 1 | W22: 1 | X22: 1 | Y22: 1 | Z22: 1 | AA22: 1 | AB22: 0 | AC22: 0
E23: Saturday | F23: 0 | G23: 0 | H23: 0 | I23: 0 | J23: 0 | K23: 0 | L23: 0 | M23: 1 | N23: 1 | O23: 1 | P23: 1 | Q23: 1 | R23: 1 | S23: 0 | T23: 0 | U23: 0 | V23: 0 | W23: 0 | X23: 0 | Y23: 0 | Z23: 0 | AA23: 0 | AB23: 0 | AC23: 0
E24: Sunday | F24: 0 | G24: 0 | H24: 0 | I24: 0 | J24: 0 | K24: 0 | L24: 0 | M24: 0 | N24: 0 | O24: 0 | P24: 0 | Q24: 0 | R24: 0 | S24: 0 | T24: 0 | U24: 0 | V24: 0 | W24: 0 | X24: 0 | Y24: 0 | Z24: 0 | AA24: 0 | AB24: 0 | AC24: 0
A25: School Zones | B25: Classroom | C25: HtgSetpt | D25: T24 2022 - Appendix 5.4B Updated based on the Plug Loads project | E25: Weekday | F25: =IF(F22=0,Thermostat!$B$4,Thermostat!$B$3) -> 60 | G25: =IF(G22=0,Thermostat!$B$4,Thermostat!$B$3) -> 60 | H25: =IF(H22=0,Thermostat!$B$4,Thermostat!$B$3) -> 60 | I25: =IF(I22=0,Thermostat!$B$4,Thermostat!$B$3) -> 60 | J25: =IF(J22=0,Thermostat!$B$4,Thermostat!$B$3) -> 60 | K25: =IF(K22=0,Thermostat!$B$4,Thermostat!$B$3) -> 60 | L25: =IF(L22=0,Thermostat!$B$4,Thermostat!$B$3) -> 70 | M25: =IF(M22=0,Thermostat!$B$4,Thermostat!$B$3) -> 70 | ... AC25: =IF(AC22=0,Thermostat!$B$4,Thermostat!$B$3) -> 60
E26: Saturday | F26: =IF(F23=0,Thermostat!$B$4,Thermostat!$B$3) -> 60 | G26: =IF(G23=0,Thermostat!$B$4,Thermostat!$B$3) -> 60 | H26: =IF(H23=0,Thermostat!$B$4,Thermostat!$B$3) -> 60 | I26: =IF(I23=0,Thermostat!$B$4,Thermostat!$B$3) -> 60 | J26: =IF(J23=0,Thermostat!$B$4,Thermostat!$B$3) -> 60 | K26: =IF(K23=0,Thermostat!$B$4,Thermostat!$B$3) -> 60 | L26: =IF(L23=0,Thermostat!$B$4,Thermostat!$B$3) -> 60 | M26: =IF(M23=0,Thermostat!$B$4,Thermostat!$B$3) -> 70 | ... AC26: =IF(AC23=0,Thermostat!$B$4,Thermostat!$B$3) -> 60
E27: Sunday | F27: =IF(F24=0,Thermostat!$B$4,Thermostat!$B$3) -> 60 | G27: =IF(G24=0,Thermostat!$B$4,Thermostat!$B$3) -> 60 | H27: =IF(H24=0,Thermostat!$B$4,Thermostat!$B$3) -> 60 | I27: =IF(I24=0,Thermostat!$B$4,Thermostat!$B$3) -> 60 | J27: =IF(J24=0,Thermostat!$B$4,Thermostat!$B$3) -> 60 | K27: =IF(K24=0,Thermostat!$B$4,Thermostat!$B$3) -> 60 | L27: =IF(L24=0,Thermostat!$B$4,Thermostat!$B$3) -> 60 | M27: =IF(M24=0,Thermostat!$B$4,Thermostat!$B$3) -> 60 | ... AC27: =IF(AC24=0,Thermostat!$B$4,Thermostat!$B$3) -> 60
A28: School Zones | B28: Classroom | C28: ClgSetpt | D28: T24 2022 - Appendix 5.4B Updated based on the Plug Loads project | E28: Weekday | F28: =IF(F22=0,Thermostat!$B$6,Thermostat!$B$5) -> 85 | G28: =IF(G22=0,Thermostat!$B$6,Thermostat!$B$5) -> 85 | H28: =IF(H22=0,Thermostat!$B$6,Thermostat!$B$5) -> 85 | I28: =IF(I22=0,Thermostat!$B$6,Thermostat!$B$5) -> 85 | J28: =IF(J22=0,Thermostat!$B$6,Thermostat!$B$5) -> 85 | K28: =IF(K22=0,Thermostat!$B$6,Thermostat!$B$5) -> 85 | L28: =IF(L22=0,Thermostat!$B$6,Thermostat!$B$5) -> 75 | M28: =IF(M22=0,Thermostat!$B$6,Thermostat!$B$5) -> 75 | ... AC28: =IF(AC22=0,Thermostat!$B$6,Thermostat!$B$5) -> 85
E29: Saturday | F29: =IF(F23=0,Thermostat!$B$6,Thermostat!$B$5) -> 85 | G29: =IF(G23=0,Thermostat!$B$6,Thermostat!$B$5) -> 85 | H29: =IF(H23=0,Thermostat!$B$6,Thermostat!$B$5) -> 85 | I29: =IF(I23=0,Thermostat!$B$6,Thermostat!$B$5) -> 85 | J29: =IF(J23=0,Thermostat!$B$6,Thermostat!$B$5) -> 85 | K29: =IF(K23=0,Thermostat!$B$6,Thermostat!$B$5) -> 85 | L29: =IF(L23=0,Thermostat!$B$6,Thermostat!$B$5) -> 85 | M29: =IF(M23=0,Thermostat!$B$6,Thermostat!$B$5) -> 75 | ... AC29: =IF(AC23=0,Thermostat!$B$6,Thermostat!$B$5) -> 85
E30: Sunday | F30: =IF(F24=0,Thermostat!$B$6,Thermostat!$B$5) -> 85 | G30: =IF(G24=0,Thermostat!$B$6,Thermostat!$B$5) -> 85 | H30: =IF(H24=0,Thermostat!$B$6,Thermostat!$B$5) -> 85 | I30: =IF(I24=0,Thermostat!$B$6,Thermostat!$B$5) -> 85 | J30: =IF(J24=0,Thermostat!$B$6,Thermostat!$B$5) -> 85 | K30: =IF(K24=0,Thermostat!$B$6,Thermostat!$B$5) -> 85 | L30: =IF(L24=0,Thermostat!$B$6,Thermostat!$B$5) -> 85 | M30: =IF(M24=0,Thermostat!$B$6,Thermostat!$B$5) -> 85 | ... AC30: =IF(AC24=0,Thermostat!$B$6,Thermostat!$B$5) -> 85
A31: School Zones | B31: Classroom | C31: Infiltration | D31: T24 2022 - Appendix 5.4B Updated based on the Plug Loads project | E31: Weekday | F31: 1 | G31: 1 | H31: 1 | I31: 1 | J31: 1 | K31: 1 | L31: 1 | M31: 0.25 | N31: 0.25 | O31: 0.25 | P31: 0.25 | Q31: 0.25 | R31: 0.25 | S31: 0.25 | T31: 0.25 | U31: 0.25 | V31: 1 | W31: 1 | X31: 1 | Y31: 1 | Z31: 1 | AA31: 1 | AB31: 1 | AC31: 1
E32: Saturday | F32: 1 | G32: 1 | H32: 1 | I32: 1 | J32: 1 | K32: 1 | L32: 1 | M32: 1 | N32: 1 | O32: 1 | P32: 1 | Q32: 1 | R32: 1 | S32: 1 | T32: 1 | U32: 1 | V32: 1 | W32: 1 | X32: 1 | Y32: 1 | Z32: 1 | AA32: 1 | AB32: 1 | AC32: 1
E33: Sunday | F33: 1 | G33: 1 | H33: 1 | I33: 1 | J33: 1 | K33: 1 | L33: 1 | M33: 1 | N33: 1 | O33: 1 | P33: 1 | Q33: 1 | R33: 1 | S33: 1 | T33: 1 | U33: 1 | V33: 1 | W33: 1 | X33: 1 | Y33: 1 | Z33: 1 | AA33: 1 | AB33: 1 | AC33: 1
A34: Kitchen | C34: Other
A35: Kitchen Zone | B35: Kitchen | C35: Occupancy | D35: T24 2022 - Appendix 5.4B Updated based on the Plug Loads project | E35: Weekday | F35: 0 | G35: 0 | H35: 0 | I35: 0 | J35: 0 | K35: 0.1 | L35: 0.5 | M35: 0.95 | N35: 0.95 | O35: 0.95 | P35: 0.95 | Q35: 0.95 | R35: 0.95 | S35: 0.95 | T35: 0.5 | U35: 0 | V35: 0 | W35: 0 | X35: 0 | Y35: 0 | Z35: 0 | AA35: 0 | AB35: 0 | AC35: 0
E36: Saturday | F36: 0 | G36: 0 | H36: 0 | I36: 0 | J36: 0 | K36: 0 | L36: 0 | M36: 0 | N36: 0 | O36: 0 | P36: 0 | Q36: 0 | R36: 0 | S36: 0 | T36: 0 | U36: 0 | V36: 0 | W36: 0 | X36: 0 | Y36: 0 | Z36: 0 | AA36: 0 | AB36: 0 | AC36: 0
E37: Sunday | F37: 0 | G37: 0 | H37: 0 | I37: 0 | J37: 0 | K37: 0 | L37: 0 | M37: 0 | N37: 0 | O37: 0 | P37: 0 | Q37: 0 | R37: 0 | S37: 0 | T37: 0 | U37: 0 | V37: 0 | W37: 0 | X37: 0 | Y37: 0 | Z37: 0 | AA37: 0 | AB37: 0 | AC37: 0
A38: Kitchen Zone | B38: Kitchen | C38: HVACAvail | D38: T24 2022 - Appendix 5.4B Updated based on the Plug Loads project | E38: Weekday | F38: 0 | G38: 0 | H38: 0 | I38: 0 | J38: 0 | K38: 1 | L38: 1 | M38: 1 | N38: 1 | O38: 1 | P38: 1 | Q38: 1 | R38: 1 | S38: 1 | T38: 1 | U38: 0 | V38: 0 | W38: 0 | X38: 0 | Y38: 0 | Z38: 0 | AA38: 0 | AB38: 0 | AC38: 0
E39: Saturday | F39: 0 | G39: 0 | H39: 0 | I39: 0 | J39: 0 | K39: 0 | L39: 0 | M39: 0 | N39: 0 | O39: 0 | P39: 0 | Q39: 0 | R39: 0 | S39: 0 | T39: 0 | U39: 0 | V39: 0 | W39: 0 | X39: 0 | Y39: 0 | Z39: 0 | AA39: 0 | AB39: 0 | AC39: 0
E40: Sunday | F40: 0 | G40: 0 | H40: 0 | I40: 0 | J40: 0 | K40: 0 | L40: 0 | M40: 0 | N40: 0 | O40: 0 | P40: 0 | Q40: 0 | R40: 0 | S40: 0 | T40: 0 | U40: 0 | V40: 0 | W40: 0 | X40: 0 | Y40: 0 | Z40: 0 | AA40: 0 | AB40: 0 | AC40: 0
...

Sheet Energy Usage
A1: ="CalBEM Energy Consumption - "&Prototype!B4 -> CalBEM Energy Consumption - K-8 School | N1: ="Energy Consumption - "&Prototype!A2 -> Energy Consumption - SchoolK-8
A2: Prototype | B2: CZ | C2: CalBEM Electricity EUI (KBTU/ft²) | D2: CalBEM Gas EUI (KBTU/ft²) | E2: CalBEM Total EUI (KBTU/ft²) | F2: New Construction Electricity EUI (KBTU/ft²) | G2: New Construction Gas EUI (KBTU/ft²) | H2: New Construction Total EUI (KBTU/ft²) | I2: National Average | J2: Acceptable Range (25% Higher) | K2: Acceptable Range (25% Lower) | L2: National Average Acceptable EUI Range | N2: Prototype | O2: CZ | P2: Total Floorspace (Thousand of ft²) | Q2: CEUS 2023 Electricity EUI (kBtu/ft²) | R2: CEUS 2023 Gas EUI (kBtu/ft²) | S2: CEUS 2023 Total EUI (kBtu/ft²) | T2: Acceptable Range (25% Higher) | U2: Acceptable Range (25% Lower) | V2: CEUS 2022 Acceptable EUI Range
A3: =Prototype!B4 -> K-8 School | B3: 1 | C3: 61.099352 | D3: 56.586389 | E3: 117.68574 | F3: 56.85 | G3: 0.57 | H3: 57.42 | I3: 38.7 | J3: =I3*1.25 -> 48.375 | K3: =I3*0.75 -> 29.025 | L3: =J3-K3 -> 19.35 | N3: =Prototype!B4 -> K-8 School | O3: 1 | P3: 7618.5337 | Q3: 32.349176 | R3: 12.848137 | S3: 55.364804 | T3: =S3*1.25 -> 69.206005 | U3: =S3*0.75 -> 41.523603 | V3: =T3-U3 -> 27.682402
B4: 2 | C4: 63.195265 | D4: 38.953898 | E4: 102.14916 | F4: 56.44 | G4: 0.57 | H4: 57.01 | I4: 34.3 | J4: =I4*1.25 -> 42.875 | K4: =I4*0.75 -> 25.725 | L4: =J4-K4 -> 17.15 | O4: 2 | P4: 11477.671 | Q4: 15.421598 | R4: 12.913999 | S4: 47.893283 | T4: =S4*1.25 -> 59.866604 | U4: =S4*0.75 -> 35.919962 | V4: =T4-U4 -> 23.946642
B5: 3 | C5: 55.873704 | D5: 31.340449 | E5: 87.214153 | F5: 49.61 | G5: 0.57 | H5: 50.18 | I5: 30.8 | J5: =I5*1.25 -> 38.5 | K5: =I5*0.75 -> 23.1 | L5: =J5-K5 -> 15.4 | O5: 3 | P5: 46411.86 | Q5: 20.479595 | R5: 12.799248 | S5: 100.09497 | T5: =S5*1.25 -> 125.11872 | U5: =S5*0.75 -> 75.071231 | V5: =T5-U5 -> 50.047487
B6: 4 | C6: 68.723253 | D6: 30.775936 | E6: 99.499189 | F6: 58.5 | G6: 0.57 | H6: 59.07 | I6: 39.5 | J6: =I6*1.25 -> 49.375 | K6: =I6*0.75 -> 29.625 | L6: =J6-K6 -> 19.75 | O6: 4 | P6: 23032.968 | Q6: 21.49373 | R6: 13.019767 | S6: 106.62133 | T6: =S6*1.25 -> 133.27666 | U6: =S6*0.75 -> 79.965995 | V6: =T6-U6 -> 53.310663
B7: 5 | C7: 57.552864 | D7: 22.817243 | E7: 80.370108 | F7: 49.6 | G7: 0.57 | H7: 50.17 | I7: 29.7 | J7: =I7*1.25 -> 37.125 | K7: =I7*0.75 -> 22.275 | L7: =J7-K7 -> 14.85 | O7: 5 | P7: 5978.4428 | Q7: 11.998072 | R7: 11.585185 | S7: 59.149271 | T7: =S7*1.25 -> 73.936588 | U7: =S7*0.75 -> 44.361953 | V7: =T7-U7 -> 29.574635
B8: 6 | C8: 51.983979 | D8: 9.7623082 | E8: 61.746287 | F8: 44.94 | G8: 0.57 | H8: 45.51 | I8: 31.8 | J8: =I8*1.25 -> 39.75 | K8: =I8*0.75 -> 23.85 | L8: =J8-K8 -> 15.9 | O8: 6 | P8: 57755.959 | Q8: 22.607349 | R8: 9.9467421 | S8: 82.347488 | T8: =S8*1.25 -> 102.93436 | U8: =S8*0.75 -> 61.760616 | V8: =T8-U8 -> 41.173744
B9: 7 | C9: 51.244802 | D9: 7.0378914 | E9: 58.282693 | F9: 45.09 | G9: 0.57 | H9: 45.66 | I9: 32.8 | J9: =I9*1.25 -> 41 | K9: =I9*0.75 -> 24.6 | L9: =J9-K9 -> 16.4 | O9: 7 | P9: 35149.993 | Q9: 24.848388 | R9: 6.9700357 | S9: 88.553476 | T9: =S9*1.25 -> 110.69184 | U9: =S9*0.75 -> 66.415107 | V9: =T9-U9 -> 44.276738
B10: 8 | C10: 60.194978 | D10: 10.111204 | E10: 70.306183 | F10: 51.71 | G10: 0.57 | H10: 52.28 | I10: 38.6 | J10: =I10*1.25 -> 48.25 | K10: =I10*0.75 -> 28.95 | L10: =J10-K10 -> 19.3 | O10: 8 | P10: 92353.411 | Q10: 22.935329 | R10: 8.842203 | S10: 103.44181 | T10: =S10*1.25 -> 129.30226 | U10: =S10*0.75 -> 77.581354 | V10: =T10-U10 -> 51.720903
B11: 9 | C11: 61.006675 | D11: 13.214906 | E11: 74.22158 | F11: 51.66 | G11: 0.57 | H11: 52.23 | I11: 38.5 | J11: =I11*1.25 -> 48.125 | K11: =I11*0.75 -> 28.875 | L11: =J11-K11 -> 19.25 | O11: 9 | P11: 141795.45 | Q11: 26.797343 | R11: 10.089067 | S11: 119.15132 | T11: =S11*1.25 -> 148.93914 | U11: =S11*0.75 -> 89.363487 | V11: =T11-U11 -> 59.575658
B12: 10 | C12: 63.364278 | D12: 12.265126 | E12: 75.629404 | F12: 54.75 | G12: 0.57 | H12: 55.32 | I12: 42.2 | J12: =I12*1.25 -> 52.75 | K12: =I12*0.75 -> 31.65 | L12: =J12-K12 -> 21.1 | O12: 10 | P12: 92589.867 | Q12: 22.490401 | R12: 10.108975 | S12: 67.419104 | T12: =S12*1.25 -> 84.27388 | U12: =S12*0.75 -> 50.564328 | V12: =T12-U12 -> 33.709552
B13: 11 | C13: 72.929638 | D13: 43.35293 | E13: 116.28257 | F13: 64.9 | G13: 0.57 | H13: 65.47 | I13: 47.7 | J13: =I13*1.25 -> 59.625 | K13: =I13*0.75 -> 35.775 | L13: =J13-K13 -> 23.85 | O13: 11 | P13: 33810.488 | Q13: 26.928661 | R13: 8.760437 | S13: 68.839253 | T13: =S13*1.25 -> 86.049066 | U13: =S13*0.75 -> 51.62944 | V13: =T13-U13 -> 34.419626
B14: 12 | C14: 65.315856 | D14: 35.186628 | E14: 100.50248 | F14: 58.31 | G14: 0.57 | H14: 58.88 | I14: 41.6 | J14: =I14*1.25 -> 52 | K14: =I14*0.75 -> 31.2 | L14: =J14-K14 -> 20.8 | O14: 12 | P14: 108342.43 | Q14: 31.799594 | R14: 12.230299 | S14: 85.587371 | T14: =S14*1.25 -> 106.98421 | U14: =S14*0.75 -> 64.190528 | V14: =T14-U14 -> 42.793686
B15: 13 | C15: 71.486037 | D15: 27.064136 | E15: 98.550173 | F15: 62.85 | G15: 0.57 | H15: 63.42 | I15: 49.6 | J15: =I15*1.25 -> 62 | K15: =I15*0.75 -> 37.2 | L15: =J15-K15 -> 24.8 | O15: 13 | P15: 46676.808 | Q15: 32.656044 | R15: 15.473534 | S15: 57.73569 | T15: =S15*1.25 -> 72.169613 | U15: =S15*0.75 -> 43.301768 | V15: =T15-U15 -> 28.867845
... B18: 16 | C18: 69.381948 | D18: 80.028886 | E18: 149.41083 | F18: 71.33 | G18: 0.57 | H18: 71.9 | I18: 44 | J18: =I18*1.25 -> 55 | K18: =I18*0.75 -> 33 | L18: =J18-K18 -> 22 | O18: 16 | P18: 85267.89 | Q18: 27.026911 | R18: 11.652927 | S18: 67.576478 | T18: =S18*1.25 -> 84.470598 | U18: =S18*0.75 -> 50.682359 | V18: =T18-U18 -> 33.788239
Q20: Ref: CEUS 2022 Report
Q21: And by applying FZ-CZ multipliers for converting FZ data to CZ data

Sheet Weights
A1: ="% of Floor Area per CZ and Vintage Bin - Schools" -> % of Floor Area per CZ and Vintage Bin - Schools
A2: Prototype | B2: CZ | C2: Vintage Bin
C3: Pre-1978 | D3: 1978-1997 | E3: 1998-2007 | F3: 2008-2018 | G3: Not available
A4: =Prototype!B4 -> K-8 School | B4: 1 | C4: 0.485 | D4: 0.274 | E4: 0.076 | F4: 0.029 | G4: 0.136 | H4: =SUM(C4:G4) -> 1
B5: 2 | C5: 0.858 | D5: 0.07 | E5: 0.038 | F5: 0.014 | G5: 0.02 | H5: =SUM(C5:G5) -> 1
B6: 3 | C6: 0.661 | D6: 0.209 | E6: 0.015 | F6: 0.006 | G6: 0.109 | H6: =SUM(C6:G6) -> 1
B7: 4 | C7: 0.682 | D7: 0.179 | E7: 0.009 | F7: 0.006 | G7: 0.124 | H7: =SUM(C7:G7) -> 1
B8: 5 | C8: 0.536 | D8: 0.421 | E8: 0.024 | F8: 0.008 | G8: 0.012 | H8: =SUM(C8:G8) -> 1.001
B9: 6 | C9: 0.657 | D9: 0.139 | E9: 0.103 | F9: 0.044 | G9: 0.058 | H9: =SUM(C9:G9) -> 1.001
B10: 7 | C10: 0.288 | D10: 0.247 | E10: 0.188 | F10: 0.235 | G10: 0.042 | H10: =SUM(C10:G10) -> 1
B11: 8 | C11: 0.666 | D11: 0.125 | E11: 0.103 | F11: 0.036 | G11: 0.07 | H11: =SUM(C11:G11) -> 1
B12: 9 | C12: 0.602 | D12: 0.152 | E12: 0.074 | F12: 0.02 | G12: 0.152 | H12: =SUM(C12:G12) -> 1
B13: 10 | C13: 0.327 | D13: 0.201 | E13: 0.317 | F13: 0.111 | G13: 0.044 | H13: =SUM(C13:G13) -> 1
B14: 11 | C14: 0.475 | D14: 0.305 | E14: 0.073 | F14: 0.017 | G14: 0.131 | H14: =SUM(C14:G14) -> 1.001
B15: 12 | C15: 0.447 | D15: 0.31 | E15: 0.096 | F15: 0.028 | G15: 0.118 | H15: =SUM(C15:G15) -> 0.999
B16: 13 | C16: 0.323 | D16: 0.347 | E16: 0.137 | F16: 0.061 | G16: 0.132 | H16: =SUM(C16:G16) -> 1
... B19: 16 | C19: 0.447 | D19: 0.235 | E19: 0.127 | F19: 0.094 | G19: 0.098 | H19: =SUM(C19:G19) -> 1.001
B20: Statewide
A22: Ref: CEUS 2022 dataset
A25: Background Data [To be deleted prior to publication]

Sheet PV
A1: ="PV - "&Prototype!A2 -> PV - SchoolK-8
A2: TBD

Sheet EV Charger
A1: ="EV Charger - "&Prototype!A2 -> EV Charger - SchoolK-8
A2: TBD
A11: Background Data [To be deleted prior to publication]

Sheet Data
A1: Space Function | B1: Electric Equipment Load Intensity | C1: Electric Equipment Load Intensity | D1: LPD
A2: Aging Eye/Low-vision (Corridor Area) | D2: 2013 | E2: 2016 | F2: 2019 | G2: 2025
A3: Aging Eye/Low-vision (Dining)
A4: Aging Eye/Low-vision (Lobby, Main Entry)
A5: Aging Eye/Low-vision (Lounge/Waiting Area)
A6: Aging Eye/Low-vision (Multipurpose Room)
A7: Aging Eye/Low-vision (Religious Worship Area)
A8: Aging Eye/Low-vision (Restroom)
A9: Aging Eye/Low-vision (Stairwell)
A10: Audience Seating Area
A11: Auditorium Area
A12: Auto Repair / Maintenance Area
A13: Barber, Beauty Salon, Spa Area
A14: Civic Meeting Place Area
... A82: Server Room
