Workbook
Name nonparticipating_forecastzone_scale_factor: #REF!
Name nonparticipating_forecastzone_scale_factor: 'Energy Usage'!#REF!
Name nonparticipating_forecastzone_scale_factor: 'Energy Usage'!#REF!

Sheet Notes
A1: Data Sources
A2: Dataset | B2: Dodge 2023
B3: CEUS 2022
B4: ComStock 2023
A6: Prototype | B6: CEC School prototype (CBECC 2022.3.1) | C6: https://bees.noresco.com/software2022.html
A9: Codes | B9: Title 24, part 6, referred to as T24 (1984, 2001, 2007, 2013, 2016, 2022, 2025)
B10: ASHRAE 90.1 (2022)
B11: CFR Title 10 (2008, 2010, 2025)
B12: ACM 2022
B13: T24 2022 - Appendix 5.4A and Appendix 5.4B | C13: https://www.energy.ca.gov/publications/2022/2022-nonresidential-and-multifamily-alternative-calculation-method-reference
A15: Other | B15: 2022 Reduced infiltration CASE report | C15: https://title24stakeholders.com/wp-content/uploads/2020/10/2022-T24-Final-CASE-Report_Reduce-Infiltration.pdf
B16: 2019 Outdoor Lighting CASE Report | C16: https://title24stakeholders.com/wp-content/uploads/2016/10/T24-2019-CASE-Study-Results-Report-Outdoor-Sources_Final_with-Attachments.pdf
B17: 2019 High Efficiency Fume Hoods in Laboratory Spaces CASE Report | C17: https://title24stakeholders.com/wp-content/uploads/2017/09/2019-T24-CASE-Report_Fume-Hoods_Final_September-2017.pdf?
B18: PNNL 20405, 2010 | C18: file:///N:/Prj_SUS/2023/S23668%20SCE%20CA%20Prototypes%20Development/Technical/NR/0_Input%20data/Lighting/PNNL-20405.pdf
B19: Air leakage Memo, NORESCO, 2025 | C19: Infiltration_rate_report_14May2025-Short-Version.docx
A20: Construction Rate
A33: Notes

Sheet Prototype
A1: NORESCO, Updated September 2025
A2: SchoolLarge
A3: Characteristic | B3: Value | C3: Data Sources
A4: Building Type | B4: Large School
A5: Building Category | B5: Nonresidential
A6: Vintages | B6: 4 Vintages: Pre-1978, 1978-1997,1998-2007, 2008-2018 New Construction (2019+) | C6: Based on the vintage bin analysis | D6: NonRes-Vintage bins-Draft Report-30Nov2023-Final.docx
A7: Shape | C7: The analysis uses prototype geometry originally developed by CEC.
A8: Total Floor Area (ft²) | B8: 210906.62 | C8: Same as CEC
A9: Aspect Ratio | B9: =(203.412+259.186)/(9.842+285.433+45.931) -> 1.3557733 | C9: Same as CEC
A10: Number of Floors | B10: 2 | C10: Same as CEC
A11: Roof type | B11: Flat | C11: Same as CEC
A12: WWR | B12: 0.345 | C12: Same as CEC
A13: Shading Geometry | B13: No Shades | C13: Same as CEC
A14: Floor to floor height (feet) | B14: 13.2 ft | C14: Same as CEC
A15: Floor to ceiling height (feet) | B15: 13.2 ft | C15: Same as CEC
A16: Glazing sill height (feet) | B16: 3.6 ft | C16: Same as CEC
A20: Above grade wall area (ft²) | B20: 64245.23
A21: Gross wall area (ft²) | B21: 64245.23
A22: Roof area (ft²) | B22: 128124.28
A23: Underground Gross Wall Area (ft²) | B23: 0

Sheet Zones
A1: ="Proposed Layout - "&Prototype!A2 -> Proposed Layout - SchoolLarge
A2: Space Type | B2: Space/Thermal Zone | C2: HVAC System Name/AHU Name | D2: Schedule Category | E2: Conditioned (Y/N) | F2: Area Fraction | G2: Area (ft²) | H2: Volume (ft³) | I2: Multipliers | J2: Number of People | K2: People (Persons/1,000 ft²) [T24, 2025,Table 120.1-A]
A3: Auditorium Area | B3: Auditorium_FF_Zn | C3: BaseAirSys5 | D3: Classroom | E3: Y | F3: =G3/$G$49 -> 0.050428996 | G3: 10635.81 | H3: 279168.51 | I3: 1 | J3: =K3*G3/1000 -> 1510.285 | K3: 142
A4: Exercise/Fitness Center and Gymnasium Areas | B4: Aux_Gym_FF_Zn | C4: BaseAirSys5 | D4: Classroom | E4: Y | F4: =G4/$G$49 -> 0.063699322 | G4: 13434.61 | H4: 352631.31 | I4: 1 | J4: =K4*G4/1000 -> 268.6922 | K4: 20
A5: Restrooms | B5: Bathrooms_FF_Zn | C5: BaseAirSys5 | D5: Classroom | E5: Y | F5: =G5/$G$49 -> 0.010718392 | G5: 2260.58 | H5: 29667.9 | I5: 1 | J5: =K5*G5/1000 -> 22.6058 | K5: 10
A6: Restrooms | B6: Bathrooms_SF_Zn | C6: BaseAirSys5-2 | D6: Classroom | E6: Y | F6: =G6/$G$49 -> 0.010718392 | G6: 2260.58 | H6: 29667.68 | I6: 1 | J6: =K6*G6/1000 -> 22.6058 | K6: 10
A7: Dining Area (Cafeteria/Fast Food) | B7: Cafeteria_FF_Zn | C7: BaseAirSys5 | D7: Classroom | E7: Y | F7: =G7/$G$49 -> 0.031849827 | G7: 6717.34 | H7: 88158.58 | I7: 1 | J7: =K7*G7/1000 -> 447.82267 | K7: 66.666667
A8: Classroom, Lecture, Training, Vocational Areas | B8: Corner_Class_1_Pod_1_FF_Zn | C8: BaseAirSys5 | D8: Classroom | E8: Y | F8: =G8/$G$49 -> 0.0050530889 | G8: 1065.73 | H8: 13986.7 | I8: 1 | J8: =K8*G8/1000 -> 53.2865 | K8: 50
A9: Classroom, Lecture, Training, Vocational Areas | B9: Corner_Class_1_Pod_1_SF_Zn | C9: BaseAirSys5-2 | D9: Classroom | E9: Y | F9: =G9/$G$49 -> 0.0050530889 | G9: 1065.73 | H9: 13986.6 | I9: 1 | J9: =K9*G9/1000 -> 53.2865 | K9: 50
A10: Classroom, Lecture, Training, Vocational Areas | B10: Corner_Class_1_Pod_2_FF_Zn | C10: BaseAirSys5 | D10: Classroom | E10: Y | F10: =G10/$G$49 -> 0.0050529941 | G10: 1065.71 | H10: 13986.42 | I10: 1 | J10: =K10*G10/1000 -> 53.2855 | K10: 50
A11: Classroom, Lecture, Training, Vocational Areas | B11: Corner_Class_1_Pod_2_SF_Zn | C11: BaseAirSys5-2 | D11: Classroom | E11: Y | F11: =G11/$G$49 -> 0.0050529941 | G11: 1065.71 | H11: 13986.31 | I11: 1 | J11: =K11*G11/1000 -> 53.2855 | K11: 50
A12: Classroom, Lecture, Training, Vocational Areas | B12: Corner_Class_1_Pod_3_FF_Zn | C12: BaseAirSys5 | D12: Classroom | E12: Y | F12: =G12/$G$49 -> 0.0050531837 | G12: 1065.75 | H12: 13986.89 | I12: 1 | J12: =K12*G12/1000 -> 53.2875 | K12: 50
A13: Classroom, Lecture, Training, Vocational Areas | B13: Corner_Class_1_Pod_3_SF_Zn | C13: BaseAirSys5-2 | D13: Classroom | E13: Y | F13: =G13/$G$49 -> 0.0050531837 | G13: 1065.75 | H13: 13986.79 | I13: 1 | J13: =K13*G13/1000 -> 53.2875 | K13: 50
A14: Classroom, Lecture, Training, Vocational Areas | B14: Corner_Class_2_Pod_1_FF_Zn | C14: BaseAirSys5 | D14: Classroom | E14: Y | F14: =G14/$G$49 -> 0.0050530889 | G14: 1065.73 | H14: 13986.66 | I14: 1 | J14: =K14*G14/1000 -> 53.2865 | K14: 50
... A48: Office Area (>250 square feet) | B48: Offices_SF_Zn | C48: BaseAirSys5-2 | D48: Classroom | E48: Y | F48: =G48/$G$49 -> 0.027154053 | G48: 5726.97 | H48: 75160.39 | I48: 1 | J48: =K48*G48/1000 -> 57.2697 | K48: 10
A49: Total (11 Space types) | B49: Total (46 spaces) | C49: Total ( 5 HVAC zones) | D49: Total (3 Schedule categories) | E49: Total (46 Conditioned zones) | F49: =G49/$G$49 -> 1 | G49: =SUM(G3:G48) -> 210906.64 | H49: =SUM(H3:H48) -> 3363003.6 | J49: =SUM(J3:J48) -> 7500.4598
A66: Background Data [To be deleted prior to publication]

Sheet Envelope
A1: ="Envelope - "&Prototype!A2 -> Envelope - SchoolLarge
A2: Element | B2: Prototype | C2: Assembly Type | D2: Construction | E2: Thermal properties | F2: Vintage | G2: Selected T24 | H2: Note | I2: CZ1 | J2: CZ2 | K2: CZ3 | L2: CZ4 | M2: CZ5 | N2: CZ6 | O2: CZ7 | P2: CZ8 | Q2: CZ9 | R2: CZ10 | S2: CZ11 | T2: CZ12 | U2: CZ13 | V2: CZ14 | W2: CZ15 | X2: CZ16
A3: External Wall | B3: =Prototype!A2 -> SchoolLarge | C3: ExtWall_MetalFramed_NonRes | D3: Metal frame + insulation + Gypsum board | E3: U-value IP | F3: Pre 1978 | G3: N/A | H3: ASHRAE 90.1, 2022, Table A3.4.3.1, 3.5", R-0 | I3: 0.292 | J3: 0.292 | K3: 0.292 | L3: 0.292 | M3: 0.292 | N3: 0.292 | O3: 0.292 | P3: 0.292 | Q3: 0.292 | R3: 0.292 | S3: 0.292 | T3: 0.292 | U3: 0.292 | V3: 0.292 | W3: 0.292 | X3: 0.292
F4: 1978-1997 | G4: 1986 | H4: Table 2-53V-16: Package A/ Heat Capacity was considered 10.0-14.99 (BTU/F/ft²) | I4: 0.15082956 | J4: 0.15748031 | K4: 0.15748031 | L4: 0.14367816 | M4: 0.14367816 | N4: 0.21645022 | O4: 0.21645022 | P4: 0.21645022 | Q4: 0.21645022 | R4: 0.21645022 | S4: 0.18621974 | T4: 0.18621974 | U4: 0.18621974 | V4: 0.15873016 | W4: 0.15873016 | X4: 0.15082956
F5: 1998-2007 | G5: 2001 | H5: Table 1-H | I5: 0.084 | J5: 0.084 | K5: 0.092 | L5: 0.092 | M5: 0.092 | N5: 0.092 | O5: 0.092 | P5: 0.092 | Q5: 0.092 | R5: 0.084 | S5: 0.084 | T5: 0.084 | U5: 0.084 | V5: 0.084 | W5: 0.084 | X5: 0.084
F6: 2008-2018 | G6: 2013 | H6: Table 140.3-B | I6: 0.102 | J6: 0.059 | K6: 0.11 | L6: 0.059 | M6: 0.102 | N6: 0.11 | O6: 0.11 | P6: 0.102 | Q6: 0.059 | R6: 0.059 | S6: 0.059 | T6: 0.059 | U6: 0.059 | V6: 0.059 | W6: 0.042 | X6: 0.059
F7: 2019+ | G7: 2025 | H7: Table 140.3-B | I7: 0.078 | J7: 0.053 | K7: 0.102 | L7: 0.053 | M7: 0.095 | N7: 0.102 | O7: 0.102 | P7: 0.095 | Q7: 0.053 | R7: 0.053 | S7: 0.042 | T7: 0.053 | U7: 0.053 | V7: 0.053 | W7: 0.038 | X7: 0.053
A8: Roof | B8: =$B$3 -> SchoolLarge | C8: FlatRoof_WoodFramedAndOther_NonRes | D8: Built-up Roof roof membrane+roof insulation+metal decking | E8: U-value IP | F8: Pre 1978 | G8: N/A | H8: Table 2-53V-16: Considering 30 years for roof/ insulation replacement. | I8: 0.057 | J8: 0.057 | K8: 0.057 | L8: 0.057 | M8: 0.057 | N8: 0.078 | O8: 0.078 | P8: 0.078 | Q8: 0.078 | R8: 0.078 | S8: 0.057 | T8: 0.057 | U8: 0.057 | V8: 0.057 | W8: 0.057 | X8: 0.057
F9: 1978-1997 | G9: 1992 | I9: 0.057 | J9: 0.057 | K9: 0.057 | L9: 0.057 | M9: 0.057 | N9: 0.078 | O9: 0.078 | P9: 0.078 | Q9: 0.078 | R9: 0.078 | S9: 0.057 | T9: 0.057 | U9: 0.057 | V9: 0.057 | W9: 0.057 | X9: 0.057
F10: 1998-2007 | G10: 2001 | H10: Table 1-H | I10: 0.057 | J10: 0.057 | K10: 0.057 | L10: 0.057 | M10: 0.057 | N10: 0.078 | O10: 0.078 | P10: 0.078 | Q10: 0.078 | R10: 0.057 | S10: 0.057 | T10: 0.057 | U10: 0.057 | V10: 0.057 | W10: 0.057 | X10: 0.057
F11: 2008-2018 | G11: 2013 | H11: Table 140.3-B | I11: 0.049 | J11: 0.039 | K11: 0.039 | L11: 0.039 | M11: 0.049 | N11: 0.075 | O11: 0.067 | P11: 0.067 | Q11: 0.039 | R11: 0.039 | S11: 0.039 | T11: 0.039 | U11: 0.039 | V11: 0.039 | W11: 0.039 | X11: 0.039
F12: 2019+ | G12: 2025 | H12: Table 140.3-B | I12: 0.028 | J12: 0.028 | K12: 0.028 | L12: 0.028 | M12: 0.028 | N12: 0.047 | O12: 0.047 | P12: 0.047 | Q12: 0.028 | R12: 0.028 | S12: 0.028 | T12: 0.028 | U12: 0.028 | V12: 0.028 | W12: 0.028 | X12: 0.028
A13: Windows | B13: =$B$3 -> SchoolLarge | C13: FixedWindow_NonRes | D13: Single pane | E13: U-value IP | F13: Pre 1978 | G13: N/A | H13: ASHRAE Handbook of Fundamentals (Table 4-Ch15) for single pane & T24, 2013 for double pane (33%-67%)* | I13: =0.33*1.12+0.67*0.36 -> 0.6108 | J13: =0.33*1.12+0.67*0.36 -> 0.6108 | K13: =0.33*1.12+0.67*0.36 -> 0.6108 | L13: =0.33*1.12+0.67*0.36 -> 0.6108 | M13: =0.33*1.12+0.67*0.36 -> 0.6108 | N13: =0.33*1.12+0.67*0.36 -> 0.6108 | O13: =0.33*1.12+0.67*0.36 -> 0.6108 | P13: =0.33*1.12+0.67*0.36 -> 0.6108 | ... X13: =0.33*1.12+0.67*0.36 -> 0.6108
F14: 1978-1997 | G14: N/A | I14: =0.33*1.12+0.67*0.36 -> 0.6108 | J14: =0.33*1.12+0.67*0.36 -> 0.6108 | K14: =0.33*1.12+0.67*0.36 -> 0.6108 | L14: =0.33*1.12+0.67*0.36 -> 0.6108 | M14: =0.33*1.12+0.67*0.36 -> 0.6108 | N14: =0.33*1.12+0.67*0.36 -> 0.6108 | O14: =0.33*1.12+0.67*0.36 -> 0.6108 | P14: =0.33*1.12+0.67*0.36 -> 0.6108 | ... X14: =0.33*1.12+0.67*0.36 -> 0.6108
D15: Double pane | F15: 1998-2007 | G15: 2001 | H15: Table 1-H | I15: 0.49 | J15: 0.49 | K15: 0.81 | L15: 0.81 | M15: 0.81 | N15: 0.81 | O15: 0.81 | P15: 0.81 | Q15: 0.81 | R15: 0.49 | S15: 0.49 | T15: 0.49 | U15: 0.49 | V15: 0.49 | W15: 0.49 | X15: 0.49
F16: 2008-2018 | G16: 2013 | H16: Table 140.3-B | I16: 0.36 | J16: 0.36 | K16: 0.36 | L16: 0.36 | M16: 0.36 | N16: 0.36 | O16: 0.36 | P16: 0.36 | Q16: 0.36 | R16: 0.36 | S16: 0.36 | T16: 0.36 | U16: 0.36 | V16: 0.36 | W16: 0.36 | X16: 0.36
F17: 2019+ | G17: 2025 | H17: Table 140.3-B | I17: 0.36 | J17: 0.36 | K17: 0.36 | L17: 0.36 | M17: 0.36 | N17: 0.36 | O17: 0.36 | P17: 0.36 | Q17: 0.34 | R17: 0.36 | S17: 0.34 | T17: 0.34 | U17: 0.34 | V17: 0.34 | W17: 0.34 | X17: 0.36
B18: =$B$3 -> SchoolLarge | C18: FixedWindow_NonRes | D18: Single pane | E18: SHGC | F18: Pre 1978 | G18: N/A | H18: ASHRAE Handbook of Fundamentals (Table 10-Ch15) for single pane & T24, 2013 for double pane (33%-67%)* | I18: =0.79*0.33+0.67*I21 -> 0.4282 | J18: =0.79*0.33+0.67*J21 -> 0.4282 | K18: =0.79*0.33+0.67*K21 -> 0.4282 | L18: =0.79*0.33+0.67*L21 -> 0.4282 | M18: =0.79*0.33+0.67*M21 -> 0.4282 | N18: =0.79*0.33+0.67*N21 -> 0.4282 | O18: =0.79*0.33+0.67*O21 -> 0.4282 | P18: =0.79*0.33+0.67*P21 -> 0.4282 | ... X18: =0.79*0.33+0.67*X21 -> 0.4282
F19: 1978-1997 | G19: N/A | I19: =0.79*0.33+0.67*I21 -> 0.4282 | J19: =0.79*0.33+0.67*J21 -> 0.4282 | K19: =0.79*0.33+0.67*K21 -> 0.4282 | L19: =0.79*0.33+0.67*L21 -> 0.4282 | M19: =0.79*0.33+0.67*M21 -> 0.4282 | N19: =0.79*0.33+0.67*N21 -> 0.4282 | O19: =0.79*0.33+0.67*O21 -> 0.4282 | P19: =0.79*0.33+0.67*P21 -> 0.4282 | ... X19: =0.79*0.33+0.67*X21 -> 0.4282
D20: Double pane | F20: 1998-2007 | G20: 2001 | H20: Table 1-H - WWR:31-40% / SHGC non-north | I20: 0.43 | J20: 0.36 | K20: 0.41 | L20: 0.41 | M20: 0.41 | N20: 0.34 | O20: 0.34 | P20: 0.34 | Q20: 0.34 | R20: 0.31 | S20: 0.31 | T20: 0.31 | U20: 0.31 | V20: 0.31 | W20: 0.31 | X20: 0.43
F21: 2008-2018 | G21: 2013 | H21: Table 140.3-B | I21: 0.25 | J21: 0.25 | K21: 0.25 | L21: 0.25 | M21: 0.25 | N21: 0.25 | O21: 0.25 | P21: 0.25 | Q21: 0.25 | R21: 0.25 | S21: 0.25 | T21: 0.25 | U21: 0.25 | V21: 0.25 | W21: 0.25 | X21: 0.25
F22: 2019+ | G22: 2025 | H22: Table 140.3-B | I22: 0.25 | J22: 0.25 | K22: 0.25 | L22: 0.25 | M22: 0.25 | N22: 0.25 | O22: 0.25 | P22: 0.25 | Q22: 0.22 | R22: 0.25 | S22: 0.22 | T22: 0.22 | U22: 0.22 | V22: 0.22 | W22: 0.22 | X22: 0.25
E25: Infiltration
F26: Vintage | G26: I_75 6-Sided Inifltration rate @ 75 pa | H26: Note | I26: I-design (cfm/ft²) (4-sided Infiltration rate at normal presure) (Design flow rate approach and Flow/Exterior Wall Area calulation method)
E27: Infiltration | F27: Pre 1978 | G27: 1.1 | H27: 2022 CASE report (Table 38) | I27: 0.6146
F28: 1978-1997 | G28: 1.1 | H28: 2022 CASE report (Table 38) | I28: 0.6146
F29: 1998-2007 | G29: 1.1 | H29: 2022 CASE report (Table 38) | I29: 0.6146
F30: 2008-2018 | G30: 1 | H30: 2022 CASE report (Table 38) & T24, 2008-2016 (Table 140.3-B)--Air barrier is required in CZ 10-16 | I30: 0.5624
F31: 2019+ | G31: 0.6 | H31: 2022 CASE report (Table 38) & T24, 2025 (Table 140.3-B)--Air barrier is required in all CZs | I31: 0.3352
E32: Source: T24 air barrier requirements (all editions) and the standardized infiltration rate reported in the 2022 CASE report and Dodge 2023 data
E33: Air Lekage Memo: | G33: Infiltration_rate_report_14May2025-Short-Version.docx

Sheet HVAC System
A1: ="HVAC system - "&Prototype!A2 -> HVAC system - SchoolLarge
A2: Vintage | B2: Zones | C2: Heating | D2: Cooling | E2: Air Distribution | F2: Source | G2: Note
A3: Exisiting | B3: All Space Types | C3: Gas Boiler | D3: Air-cooled Chiller | E3: VAV + Hydronic reheat | F3: Engineering Judgement | G3: System 6
A4: New Construction | B4: All Space Types | C4: Gas Boiler | D4: Air-cooled Chiller | E4: VAV + Hydronic reheat | F4: Engineering Judgement | G4: System 6
A7: Efficiency of HVAC system
A8: Vintage | B8: Upgrade/Installed year | C8: Gas-Fired Boiler | D8: Heating DX | E8: Water Cooled Chiller | F8: Heat Rejection (Cooling Tower) | G8: Source | H8: Note
A9: Pre 1978 | B9: 2008 | C9: If 300,000 Btu/h ≤ input < 2.5 MMBtu/h: Et ≥ 75% | D9: n/a | E9: Centrifugal ≥ 300: COP_FL ≥ 6.10 IPLV COP ≥ 6.40 (ARI 550/590) | F9: Axial fan Open-circuit cooling tower--95°F entering water 85°F leaving water 75°F entering air wb--≥ 38.2 gpm/hp | G9: T24, 2008, Table 112-D (for chiller COP) – Table 112-G (for boiler thermal efficiency)
A10: 1978-1997
A11: 1998-2007
A12: 2008-2018 | B12: 2013 | C12: 300k–2.5 MMBtu/h: Et ≥ 80% > 2.5 MMBtu/h: Ec ≥ 82% | D12: n/a | E12: Positive-displacement (Screw) ≥ 300 and < 600 tons: Path B ≤ 0.639 kW/ton ≤ 0.490 kW/ton IPLV (AHRI 550/590) | F12: Axial fan Open-circuit cooling tower--95°F entering water 85°F leaving water 75°F entering air wb--≥ 42.1 gpm/hp | G12: T24, 2013 Table 110.2-D ( for air cooled chiller) T24, 2013 Table 110.2-K (for boiler efficiency with capacity between 300,000-2,500,000 Btu/hr)
A13: New Construction | B13: 2025 | C13: Boiler (hot-water, gas, > 2.5 MMBtu/h): Ec ≥ 85% | D13: n/a | E13: Positive-displacement (Screw) ≥ 300 and < 600 tons: Path B ≤ 0.625 kW/ton ≤ 0.410 kW/ton IPLV | F13: Axial fan Open-circuit cooling tower--95°F entering water 85°F leaving water 75°F entering air wb--≥ 42.1 gpm/hp | G13: T24, 2025 , Table 110.2-D (for chiller COP) Table 110.2-J (for Boiler thermal efficiency)
C15: * Et = Combustion efficiency | D15: * Et = Thermal efficiency
A17: Fan power
A18: Vintage | B18: Approach | C18: System | D18: Total Static Pressure (TSP) in w.c. [PNNL 20405, 2010, Table 5.11] | E18: Fan Efficiency [ACM, 2025] | F18: Fan Motor and Drive Efficiency [ACM 2025, Table 14] | G18: W/cfm [ACM 2025, Table 15] | H18: Data Source | I18: Note
A19: Existing | B19: PNNL TSP | C19: VAV | D19: 5.58 for VAV >=20,000 cfm | E19: 0.65 | F19: 0.9 | H19: PNNL 2010 TSD
A20: Brake horse power (bhp)=(Supply cfm*TSP in w.c.)/(6356*Fan efficiency)
A21: Fan power (w/cfm) = bhp/motor and drive efficiency *746
A22: New Construction | B22: ACM 2025 | C22: VAV | D22: =G22*$F$22*$E$22/746*6356 -> 4.7200968 | E22: 0.65 | F22: 0.9 | G22: 0.947 | H22: 2025 ACM
F23: * 0.9 is an average fan efficiency according to ACM 2025, Table 14
A24: Fan total eff (E+ input) = 0.65 x Motor_eff
A25: TSP (E+ input) in w.c. = Motor_eff/746 x (6356 x Fan_eff) x W/cfm
A26: Fan_eff=0.65
A30: Background Data [To be deleted prior to publication]

Sheet Thermostat
A1: ="Thermostat Setpoints - "&Prototype!A2 -> Thermostat Setpoints - SchoolLarge
A2: Setpoint | B2: CZ1 | C2: CZ2 | D2: CZ3 | E2: CZ4 | F2: CZ5 | G2: CZ6 | H2: CZ7 | I2: CZ8 | J2: CZ9 | K2: CZ10 | L2: CZ11 | M2: CZ12 | N2: CZ13 | O2: CZ14 | P2: CZ15 | Q2: CZ16 | R2: Source
A3: School Heating Setpoint (F) | B3: 70 | C3: 70 | D3: 70 | E3: 70 | F3: 70 | G3: 70 | H3: 70 | I3: 70 | J3: 70 | K3: 70 | L3: 70 | M3: 70 | N3: 70 | O3: 70 | P3: 70 | Q3: 70 | R3: T24 2022 - Appendix 5.4B
A4: School Heating Setback (F) | B4: 60 | C4: 60 | D4: 60 | E4: 60 | F4: 60 | G4: 60 | H4: 60 | I4: 60 | J4: 60 | K4: 60 | L4: 60 | M4: 60 | N4: 60 | O4: 60 | P4: 60 | Q4: 60
A5: School Cooling Setpoint (F) | B5: 75 | C5: 75 | D5: 75 | E5: 75 | F5: 75 | G5: 75 | H5: 75 | I5: 75 | J5: 75 | K5: 75 | L5: 75 | M5: 75 | N5: 75 | O5: 75 | P5: 75 | Q5: 75 | R5: T24 2022 - Appendix 5.4B
A6: School Cooling Setback (F) | B6: 85 | C6: 85 | D6: 85 | E6: 85 | F6: 85 | G6: 85 | H6: 85 | I6: 85 | J6: 85 | K6: 85 | L6: 85 | M6: 85 | N6: 85 | O6: 85 | P6: 85 | Q6: 85

Sheet Ventilation
A1: ="Outdoor Airflow Rate - "&Prototype!A2 -> Outdoor Airflow Rate - SchoolLarge
A2: Space Type | B2: Space/Thermal Zone | C2: Number of People | D2: Floor Area (ft²) | E2: cfm/person [T24, 2025, Equation 120.1-F and Table 120.1-A] | F2: cfm/ft² [T24, 2025, Equation 120.1-F and Table 120.1-A] | G2: Required exhaust rate-CFM/ft²- [T24, 2025, Table 120.1-B – minimum exhaust rates] | H2: Total cfm driven by people | I2: Total cfm driven by area | J2: Total cfm driven by exhaust | K2: Total cfm | L2: Notes
A3: =Zones!A3 -> Auditorium Area | B3: =Zones!B3 -> Auditorium_FF_Zn | C3: =Zones!J3 -> 1510.285 | D3: =Zones!G3 -> 10635.81 | E3: 15 | F3: 1.065 | H3: =C3*E3 -> 22654.275 | I3: =D3*F3 -> 11327.138 | J3: =G3*D3 -> 0 | K3: =MAX(H3,I3,J3) -> 22654.275
A4: =Zones!A4 -> Exercise/Fitness Center and Gymnasium Areas | B4: =Zones!B4 -> Aux_Gym_FF_Zn | C4: =Zones!J4 -> 268.6922 | D4: =Zones!G4 -> 13434.61 | E4: 15 | F4: 0.15 | H4: =C4*E4 -> 4030.383 | I4: =D4*F4 -> 2015.1915 | J4: =G4*D4 -> 0 | K4: =MAX(H4,I4,J4) -> 4030.383
A5: =Zones!A5 -> Restrooms | B5: =Zones!B5 -> Bathrooms_FF_Zn | C5: =Zones!J5 -> 22.6058 | D5: =Zones!G5 -> 2260.58 | E5: 15 | F5: 0.075 | H5: =C5*E5 -> 339.087 | I5: =D5*F5 -> 169.5435 | J5: =G5*D5 -> 0 | K5: =MAX(H5,I5,J5) -> 339.087
A6: =Zones!A6 -> Restrooms | B6: =Zones!B6 -> Bathrooms_SF_Zn | C6: =Zones!J6 -> 22.6058 | D6: =Zones!G6 -> 2260.58 | E6: 15 | F6: 0.075 | H6: =C6*E6 -> 339.087 | I6: =D6*F6 -> 169.5435 | J6: =G6*D6 -> 0 | K6: =MAX(H6,I6,J6) -> 339.087
A7: =Zones!A7 -> Dining Area (Cafeteria/Fast Food) | B7: =Zones!B7 -> Cafeteria_FF_Zn | C7: =Zones!J7 -> 447.82267 | D7: =Zones!G7 -> 6717.34 | E7: 15 | F7: 0.495 | H7: =C7*E7 -> 6717.34 | I7: =D7*F7 -> 3325.0833 | J7: =G7*D7 -> 0 | K7: =MAX(H7,I7,J7) -> 6717.34
A8: =Zones!A8 -> Classroom, Lecture, Training, Vocational Areas | B8: =Zones!B8 -> Corner_Class_1_Pod_1_FF_Zn | C8: =Zones!J8 -> 53.2865 | D8: =Zones!G8 -> 1065.73 | E8: 15 | F8: 0.375 | H8: =C8*E8 -> 799.2975 | I8: =D8*F8 -> 399.64875 | J8: =G8*D8 -> 0 | K8: =MAX(H8,I8,J8) -> 799.2975
A9: =Zones!A9 -> Classroom, Lecture, Training, Vocational Areas | B9: =Zones!B9 -> Corner_Class_1_Pod_1_SF_Zn | C9: =Zones!J9 -> 53.2865 | D9: =Zones!G9 -> 1065.73 | E9: 15 | F9: 0.375 | H9: =C9*E9 -> 799.2975 | I9: =D9*F9 -> 399.64875 | J9: =G9*D9 -> 0 | K9: =MAX(H9,I9,J9) -> 799.2975
A10: =Zones!A10 -> Classroom, Lecture, Training, Vocational Areas | B10: =Zones!B10 -> Corner_Class_1_Pod_2_FF_Zn | C10: =Zones!J10 -> 53.2855 | D10: =Zones!G10 -> 1065.71 | E10: 15 | F10: 0.375 | H10: =C10*E10 -> 799.2825 | I10: =D10*F10 -> 399.64125 | J10: =G10*D10 -> 0 | K10: =MAX(H10,I10,J10) -> 799.2825
A11: =Zones!A11 -> Classroom, Lecture, Training, Vocational Areas | B11: =Zones!B11 -> Corner_Class_1_Pod_2_SF_Zn | C11: =Zones!J11 -> 53.2855 | D11: =Zones!G11 -> 1065.71 | E11: 15 | F11: 0.375 | H11: =C11*E11 -> 799.2825 | I11: =D11*F11 -> 399.64125 | J11: =G11*D11 -> 0 | K11: =MAX(H11,I11,J11) -> 799.2825
A12: =Zones!A12 -> Classroom, Lecture, Training, Vocational Areas | B12: =Zones!B12 -> Corner_Class_1_Pod_3_FF_Zn | C12: =Zones!J12 -> 53.2875 | D12: =Zones!G12 -> 1065.75 | E12: 15 | F12: 0.375 | H12: =C12*E12 -> 799.3125 | I12: =D12*F12 -> 399.65625 | J12: =G12*D12 -> 0 | K12: =MAX(H12,I12,J12) -> 799.3125
A13: =Zones!A13 -> Classroom, Lecture, Training, Vocational Areas | B13: =Zones!B13 -> Corner_Class_1_Pod_3_SF_Zn | C13: =Zones!J13 -> 53.2875 | D13: =Zones!G13 -> 1065.75 | E13: 15 | F13: 0.375 | H13: =C13*E13 -> 799.3125 | I13: =D13*F13 -> 399.65625 | J13: =G13*D13 -> 0 | K13: =MAX(H13,I13,J13) -> 799.3125
A14: =Zones!A14 -> Classroom, Lecture, Training, Vocational Areas | B14: =Zones!B14 -> Corner_Class_2_Pod_1_FF_Zn | C14: =Zones!J14 -> 53.2865 | D14: =Zones!G14 -> 1065.73 | E14: 15 | F14: 0.375 | H14: =C14*E14 -> 799.2975 | I14: =D14*F14 -> 399.64875 | J14: =G14*D14 -> 0 | K14: =MAX(H14,I14,J14) -> 799.2975
... A25: =Zones!A25 -> Corridor Area | B25: =Zones!B25 -> Corridor_Pod_3_SF_Zn | C25: =Zones!J25 -> 34.4475 | D25: =Zones!G25 -> 3444.75 | E25: 30 | F25: 0.15 | H25: =C25*E25 -> 1033.425 | I25: =D25*F25 -> 516.7125 | J25: =G25*D25 -> 0 | K25: =MAX(H25,I25,J25) -> 1033.425
A26: =Zones!A26 -> Exercise/Fitness Center and Gymnasium Areas | B26: =Zones!B26 -> Gym_FF_Zn | C26: =Zones!J39 -> 256.7485 | D26: =Zones!G39 -> 5134.97 | E26: 15 | F26: 0.15 | H26: =C26*E26 -> 3851.2275 | I26: =D26*F26 -> 770.2455 | J26: =G26*D26 -> 0 | K26: =MAX(H26,I26,J26) -> 3851.2275
A27: =Zones!A27 -> Kitchen/Food Preparation Area | B27: =Zones!B27 -> Kitchen_FF_Zn | C27: =Zones!J40 -> 256.7485 | D27: =Zones!G40 -> 5134.97 | E27: 50 | F27: 0.15 | H27: =C27*E27 -> 12837.425 | I27: =D27*F27 -> 770.2455 | J27: =G27*D27 -> 0 | K27: =MAX(H27,I27,J27) -> 12837.425
A28: =Zones!A28 -> Library (Reading Area) | B28: =Zones!B28 -> Library_Media_Center_SF_Zn | C28: =Zones!J41 -> 256.744 | D28: =Zones!G41 -> 5134.88 | E28: 15 | F28: 0.15 | H28: =C28*E28 -> 3851.16 | I28: =D28*F28 -> 770.232 | J28: =G28*D28 -> 0 | K28: =MAX(H28,I28,J28) -> 3851.16
A29: =Zones!A29 -> Lobby, Main Entry | B29: =Zones!B29 -> Lobby_FF_Zn | C29: =Zones!J42 -> 256.744 | D29: =Zones!G42 -> 5134.88 | E29: 30 | F29: 0.15 | H29: =C29*E29 -> 7702.32 | I29: =D29*F29 -> 770.232 | J29: =G29*D29 -> 0 | K29: =MAX(H29,I29,J29) -> 7702.32
A30: =Zones!A30 -> Lobby, Main Entry | B30: =Zones!B30 -> Lobby_SF_Zn | C30: =Zones!J30 -> 150.708 | D30: =Zones!G30 -> 2260.62 | E30: 30 | F30: 0.15 | H30: =C30*E30 -> 4521.24 | I30: =D30*F30 -> 339.093 | J30: =G30*D30 -> 0 | K30: =MAX(H30,I30,J30) -> 4521.24
A31: =Zones!A31 -> Corridor Area | B31: =Zones!B31 -> Main_Corridor_FF_Zn | C31: =Zones!J31 -> 122.7192 | D31: =Zones!G31 -> 12271.92 | E31: 30 | F31: 0.15 | H31: =C31*E31 -> 3681.576 | I31: =D31*F31 -> 1840.788 | J31: =G31*D31 -> 0 | K31: =MAX(H31,I31,J31) -> 3681.576
A32: =Zones!A32 -> Corridor Area | B32: =Zones!B32 -> Main_Corridor_SF_Zn | C32: =Zones!J32 -> 122.7192 | D32: =Zones!G32 -> 12271.92 | E32: 30 | F32: 0.15 | H32: =C32*E32 -> 3681.576 | I32: =D32*F32 -> 1840.788 | J32: =G32*D32 -> 0 | K32: =MAX(H32,I32,J32) -> 3681.576
A33: =Zones!A33 -> Electrical, Mechanical, Telephone Rooms | B33: =Zones!B33 -> Mech_FF_Zn | C33: =Zones!J33 -> 11.04501 | D33: =Zones!G33 -> 3681.67 | E33: 30 | F33: 0.15 | H33: =C33*E33 -> 331.3503 | I33: =D33*F33 -> 552.2505 | J33: =G33*D33 -> 0 | K33: =MAX(H33,I33,J33) -> 552.2505
A34: =Zones!A34 -> Electrical, Mechanical, Telephone Rooms | B34: =Zones!B34 -> Mech_SF_Zn | C34: =Zones!J34 -> 11.04501 | D34: =Zones!G34 -> 3681.67 | E34: 30 | F34: 0.15 | H34: =C34*E34 -> 331.3503 | I34: =D34*F34 -> 552.2505 | J34: =G34*D34 -> 0 | K34: =MAX(H34,I34,J34) -> 552.2505
A35: =Zones!A35 -> Classroom, Lecture, Training, Vocational Areas | B35: =Zones!B35 -> Mult_Class_1_Pod_1_FF_Zn | C35: =Zones!J35 -> 256.745 | D35: =Zones!G35 -> 5134.9 | E35: 15 | F35: 0.375 | H35: =C35*E35 -> 3851.175 | I35: =D35*F35 -> 1925.5875 | J35: =G35*D35 -> 0 | K35: =MAX(H35,I35,J35) -> 3851.175
A36: =Zones!A36 -> Classroom, Lecture, Training, Vocational Areas | B36: =Zones!B36 -> Mult_Class_1_Pod_1_SF_Zn | C36: =Zones!J36 -> 256.745 | D36: =Zones!G36 -> 5134.9 | E36: 15 | F36: 0.375 | H36: =C36*E36 -> 3851.175 | I36: =D36*F36 -> 1925.5875 | J36: =G36*D36 -> 0 | K36: =MAX(H36,I36,J36) -> 3851.175
A37: =Zones!A37 -> Classroom, Lecture, Training, Vocational Areas | B37: =Zones!B37 -> Mult_Class_1_Pod_2_FF_Zn | C37: =Zones!J37 -> 256.74 | D37: =Zones!G37 -> 5134.8 | E37: 15 | F37: 0.375 | H37: =C37*E37 -> 3851.1 | I37: =D37*F37 -> 1925.55 | J37: =G37*D37 -> 0 | K37: =MAX(H37,I37,J37) -> 3851.1
A38: =Zones!A38 -> Classroom, Lecture, Training, Vocational Areas | B38: =Zones!B38 -> Mult_Class_1_Pod_2_SF_Zn | C38: =Zones!J51 -> 0 | D38: =Zones!G51 -> 0 | E38: 15 | F38: 0.375 | H38: =C38*E38 -> 0 | I38: =D38*F38 -> 0 | J38: =G38*D38 -> 0 | K38: =MAX(H38,I38,J38) -> 0
A39: =Zones!A39 -> Classroom, Lecture, Training, Vocational Areas | B39: =Zones!B39 -> Mult_Class_1_Pod_3_FF_Zn | C39: =Zones!J52 -> 0 | D39: =Zones!G52 -> 0 | E39: 15 | F39: 0.375 | H39: =C39*E39 -> 0 | I39: =D39*F39 -> 0 | J39: =G39*D39 -> 0 | K39: =MAX(H39,I39,J39) -> 0
A40: =Zones!A40 -> Classroom, Lecture, Training, Vocational Areas | B40: =Zones!B40 -> Mult_Class_1_Pod_3_SF_Zn | C40: =Zones!J53 -> 0 | D40: =Zones!G53 -> 0 | E40: 15 | F40: 0.375 | H40: =C40*E40 -> 0 | I40: =D40*F40 -> 0 | J40: =G40*D40 -> 0 | K40: =MAX(H40,I40,J40) -> 0
A41: =Zones!A41 -> Classroom, Lecture, Training, Vocational Areas | B41: =Zones!B41 -> Mult_Class_2_Pod_1_FF_Zn | C41: =Zones!J54 -> 0 | D41: =Zones!G54 -> 0 | E41: 15 | F41: 0.375 | H41: =C41*E41 -> 0 | I41: =D41*F41 -> 0 | J41: =G41*D41 -> 0 | K41: =MAX(H41,I41,J41) -> 0
A42: =Zones!A42 -> Classroom, Lecture, Training, Vocational Areas | B42: =Zones!B42 -> Mult_Class_2_Pod_1_SF_Zn | C42: =Zones!J30 -> 150.708 | D42: =Zones!G30 -> 2260.62 | E42: 15 | F42: 0.375 | H42: =C42*E42 -> 2260.62 | I42: =D42*F42 -> 847.7325 | J42: =G42*D42 -> 0 | K42: =MAX(H42,I42,J42) -> 2260.62
A43: =Zones!A43 -> Classroom, Lecture, Training, Vocational Areas | B43: =Zones!B43 -> Mult_Class_2_Pod_2_FF_Zn | C43: =Zones!J31 -> 122.7192 | D43: =Zones!G31 -> 12271.92 | E43: 15 | F43: 0.375 | H43: =C43*E43 -> 1840.788 | I43: =D43*F43 -> 4601.97 | J43: =G43*D43 -> 0 | K43: =MAX(H43,I43,J43) -> 4601.97
A44: =Zones!A44 -> Classroom, Lecture, Training, Vocational Areas | B44: =Zones!B44 -> Mult_Class_2_Pod_2_SF_Zn | C44: =Zones!J32 -> 122.7192 | D44: =Zones!G32 -> 12271.92 | E44: 15 | F44: 0.375 | H44: =C44*E44 -> 1840.788 | I44: =D44*F44 -> 4601.97 | J44: =G44*D44 -> 0 | K44: =MAX(H44,I44,J44) -> 4601.97
A45: =Zones!A45 -> Classroom, Lecture, Training, Vocational Areas | B45: =Zones!B45 -> Mult_Class_2_Pod_3_FF_Zn | C45: =Zones!J33 -> 11.04501 | D45: =Zones!G33 -> 3681.67 | E45: 15 | F45: 0.375 | H45: =C45*E45 -> 165.67515 | I45: =D45*F45 -> 1380.6263 | J45: =G45*D45 -> 0 | K45: =MAX(H45,I45,J45) -> 1380.6263
A46: =Zones!A46 -> Classroom, Lecture, Training, Vocational Areas | B46: =Zones!B46 -> Mult_Class_2_Pod_3_SF_Zn | C46: =Zones!J34 -> 11.04501 | D46: =Zones!G34 -> 3681.67 | E46: 15 | F46: 0.375 | H46: =C46*E46 -> 165.67515 | I46: =D46*F46 -> 1380.6263 | J46: =G46*D46 -> 0 | K46: =MAX(H46,I46,J46) -> 1380.6263
A47: =Zones!A47 -> Office Area (>250 square feet) | B47: =Zones!B47 -> Offices_FF_Zn | C47: =Zones!J35 -> 256.745 | D47: =Zones!G35 -> 5134.9 | E47: 30 | F47: 0.15 | H47: =C47*E47 -> 7702.35 | I47: =D47*F47 -> 770.235 | J47: =G47*D47 -> 0 | K47: =MAX(H47,I47,J47) -> 7702.35
A48: =Zones!A48 -> Office Area (>250 square feet) | B48: =Zones!B48 -> Offices_SF_Zn | C48: =Zones!J35 -> 256.745 | D48: =Zones!G35 -> 5134.9 | E48: 30 | F48: 0.15 | H48: =C48*E48 -> 7702.35 | I48: =D48*F48 -> 770.235 | J48: =G48*D48 -> 0 | K48: =MAX(H48,I48,J48) -> 7702.35
A49: =Zones!A49 -> Total (11 Space types) | B49: =Zones!B49 -> Total (46 spaces) | C49: =Zones!J49 -> 7500.4598 | D49: =Zones!G49 -> 210906.64 | H49: =SUM(H3:H48) -> 123893.24 | I49: =SUM(I3:I48) -> 53238.816 | J49: =SUM(J3:J48) -> 0 | K49: =SUM(K3:K48) -> 132287.3

Sheet Water Heater
A1: ="Water Heater -"&Prototype!A2 -> Water Heater -SchoolLarge
A2: Vintage | B2: WH Type | C2: Efficiency | D2: Tank Volume (gal) | E2: Tank Loss | G2: Note
A3: Existing | B3: Gas | C3: 0.8 | D3: =F60 -> 526.51044 | E3: =G64 -> 3342.2073 | F3: (Btu/hr)
A4: New Construction | B4: Gas | C4: 0.8 | D4: =F60 -> 526.51044 | E4: =G60 -> 3342.2073 | F4: (Btu/hr) | G4: Section 1605.1. Federal and State Standards for Federally-Regulated Appliances.
A6: Peak Hot Water Consumption
A7: Space Name | B7: Baseline WH Type [T24, 2022, Appendix 5.4A , sheet: "2022 SpaceFuncData-Input"] | C7: New Construction: Baseline WH Type ACM 2025 | D7: Total Area (ft²) | E7: Number of People | F7: Hot Water Usage Specification (gal/hr per person) [T24, 2022, Appendix 5.4A , sheet: "2022 SpaceFuncData-Input"] | G7: Peak Hot Water Usage (gal/hr) | H7: Peak Hot Water Usage (gal/min)
A8: =Zones!B3 -> Auditorium_FF_Zn | B8: Gas | D8: =Zones!G3 -> 10635.81 | E8: =Zones!J3 -> 1510.285 | F8: 0.09 | G8: =F8*E8 -> 135.92565 | H8: =G8/60 -> 2.2654275
A9: =Zones!B4 -> Aux_Gym_FF_Zn | B9: Gas | D9: =Zones!G4 -> 13434.61 | E9: =Zones!J4 -> 268.6922 | F9: 0.18 | G9: =F9*E9 -> 48.364596 | H9: =G9/60 -> 0.8060766
A10: =Zones!B5 -> Bathrooms_FF_Zn | B10: Gas | D10: =Zones!G5 -> 2260.58 | E10: =Zones!J5 -> 22.6058 | F10: 0 | G10: =F10*E10 -> 0 | H10: =G10/60 -> 0
A11: =Zones!B6 -> Bathrooms_SF_Zn | B11: Gas | D11: =Zones!G6 -> 2260.58 | E11: =Zones!J6 -> 22.6058 | F11: 0 | G11: =F11*E11 -> 0 | H11: =G11/60 -> 0
A12: =Zones!B7 -> Cafeteria_FF_Zn | B12: Gas | D12: =Zones!G7 -> 6717.34 | E12: =Zones!J7 -> 447.82267 | F12: 0.578 | G12: =F12*E12 -> 258.8415 | H12: =G12/60 -> 4.314025
A13: =Zones!B8 -> Corner_Class_1_Pod_1_FF_Zn | B13: Gas | D13: =Zones!G8 -> 1065.73 | E13: =Zones!J8 -> 53.2865 | F13: 0.18 | G13: =F13*E13 -> 9.59157 | H13: =G13/60 -> 0.1598595
A14: =Zones!B9 -> Corner_Class_1_Pod_1_SF_Zn | B14: Gas | D14: =Zones!G9 -> 1065.73 | E14: =Zones!J9 -> 53.2865 | F14: 0.18 | G14: =F14*E14 -> 9.59157 | H14: =G14/60 -> 0.1598595
A15: =Zones!B10 -> Corner_Class_1_Pod_2_FF_Zn | B15: Gas | D15: =Zones!G10 -> 1065.71 | E15: =Zones!J10 -> 53.2855 | F15: 0.18 | G15: =F15*E15 -> 9.59139 | H15: =G15/60 -> 0.1598565
A16: =Zones!B11 -> Corner_Class_1_Pod_2_SF_Zn | B16: Gas | D16: =Zones!G11 -> 1065.71 | E16: =Zones!J11 -> 53.2855 | F16: 0.18 | G16: =F16*E16 -> 9.59139 | H16: =G16/60 -> 0.1598565
A17: =Zones!B12 -> Corner_Class_1_Pod_3_FF_Zn | B17: Gas | D17: =Zones!G12 -> 1065.75 | E17: =Zones!J12 -> 53.2875 | F17: 0.18 | G17: =F17*E17 -> 9.59175 | H17: =G17/60 -> 0.1598625
A18: =Zones!B13 -> Corner_Class_1_Pod_3_SF_Zn | B18: Gas | D18: =Zones!G13 -> 1065.75 | E18: =Zones!J13 -> 53.2875 | F18: 0.18 | G18: =F18*E18 -> 9.59175 | H18: =G18/60 -> 0.1598625
A19: =Zones!B14 -> Corner_Class_2_Pod_1_FF_Zn | B19: Gas | D19: =Zones!G14 -> 1065.73 | E19: =Zones!J14 -> 53.2865 | F19: 0.18 | G19: =F19*E19 -> 9.59157 | H19: =G19/60 -> 0.1598595
... A44: =Zones!B39 -> Mult_Class_1_Pod_3_FF_Zn | B44: Gas | D44: =Zones!G39 -> 5134.97 | E44: =Zones!J39 -> 256.7485 | F44: 0.18 | G44: =F44*E44 -> 46.21473 | H44: =G44/60 -> 0.7702455
A45: =Zones!B40 -> Mult_Class_1_Pod_3_SF_Zn | B45: Gas | D45: =Zones!G39 -> 5134.97 | E45: =Zones!J39 -> 256.7485 | F45: 0.18 | G45: =F45*E45 -> 46.21473 | H45: =G45/60 -> 0.7702455
A46: =Zones!B41 -> Mult_Class_2_Pod_1_FF_Zn | B46: Gas | D46: =Zones!G40 -> 5134.97 | E46: =Zones!J40 -> 256.7485 | F46: 0.18 | G46: =F46*E46 -> 46.21473 | H46: =G46/60 -> 0.7702455
A47: =Zones!B42 -> Mult_Class_2_Pod_1_SF_Zn | B47: Gas | D47: =Zones!G41 -> 5134.88 | E47: =Zones!J41 -> 256.744 | F47: 0.18 | G47: =F47*E47 -> 46.21392 | H47: =G47/60 -> 0.770232
A48: =Zones!B43 -> Mult_Class_2_Pod_2_FF_Zn | B48: Gas | D48: =Zones!G42 -> 5134.88 | E48: =Zones!J42 -> 256.744 | F48: 0.18 | G48: =F48*E48 -> 46.21392 | H48: =G48/60 -> 0.770232
A49: =Zones!B44 -> Mult_Class_2_Pod_2_SF_Zn | B49: Gas | D49: =Zones!G43 -> 5134.97 | E49: =Zones!J43 -> 256.7485 | F49: 0.18 | G49: =F49*E49 -> 46.21473 | H49: =G49/60 -> 0.7702455
A50: =Zones!B45 -> Mult_Class_2_Pod_3_FF_Zn | B50: Gas | D50: =Zones!G44 -> 5134.97 | E50: =Zones!J44 -> 256.7485 | F50: 0.18 | G50: =F50*E50 -> 46.21473 | H50: =G50/60 -> 0.7702455
A51: =Zones!B46 -> Mult_Class_2_Pod_3_SF_Zn | B51: Gas | D51: =Zones!G45 -> 5134.8 | E51: =Zones!J45 -> 256.74 | F51: 0.18 | G51: =F51*E51 -> 46.2132 | H51: =G51/60 -> 0.77022
A52: =Zones!B47 -> Offices_FF_Zn | B52: Gas | D52: =Zones!G46 -> 5134.8 | E52: =Zones!J46 -> 256.74 | F52: 0.18 | G52: =F52*E52 -> 46.2132 | H52: =G52/60 -> 0.77022
A53: =Zones!B48 -> Offices_SF_Zn | B53: Gas | D53: =Zones!G47 -> 5726.97 | E53: =Zones!J47 -> 57.2697 | F53: 0.18 | G53: =F53*E53 -> 10.308546 | H53: =G53/60 -> 0.1718091
A54: Total | D54: =SUM(D8:D53) -> 210314.64 | E54: =SUM(E8:E53) -> 7699.9386 | G54: =SUM(G8:G53) -> 1316.2761 | H54: =G54/60 -> 21.937935
A58: Water Heater Capacity, Tank Capacity, and Tank Loss
A59: WH Type | B59: Peak Hot Water Usage (gal/hr) | C59: Heat Output (Btu/hr) [ACM, 2025, 5.9.2: Rated capacity section] | D59: WH Capacity (Btu/hr) [ACM, 2025, 5.9.2: Rated capacity section] | E59: Required Energy Input (Btu/hr) | F59: Storage Volume (gal) | G59: Standby Loss | H59: Unit | I59: Off/On Cycle Loss Coefficient to Ambient Temp (Btu/h-F) | J59: Source
A60: Gas Storage WH | B60: =SUMIF(B8:B53, "*Gas*", G8:G53) -> 1316.2761 | C60: =B60*(135-55)*8.2877*1 -> 872712.12 | D60: =C60*0.6 -> 523627.27 | E60: =D60/0.8 -> 654534.09 | F60: =(B60*F62)/B62 -> 526.51044 | G60: =(E60/800)+110*SQRT(F60) -> 3342.2073 | H60: Btu/hr | I60: =G60/B71 -> 49.883691 | J60: Standby loss equation: Title 20, §1605.1 Table F-4 WH capacity equation: ACM, 2025, 5.9.2: Rated capacity section)
A61: Electric resistance WH | B61: =SUMIF(B8:B53, "*Electric*",G8:G53) -> 0 | C61: =B61*(135-55)*8.2877*1 -> 0 | D61: =C61*0.6 -> 0 | E61: =D61/1 -> 0 | F61: =(B61*F62)/B62 -> 0 | G61: =IFERROR(0.3+(27/F61),0) -> 0 | H61: %hr | I61: =0.0834*G61*F61 -> 0
A62: Total | B62: =B60+B61 -> 1316.2761 | C62: =B62*(135-55)*8.2877*1 -> 872712.12 | D62: =C62*0.6 -> 523627.27 | E62: =D62/0.8 -> 654534.09 | F62: =B62*1*0.4 -> 526.51044
A64: Design supply temperature (F) | B64: 135 | C64: Ref: T24 2022 - Appendix 5.4B | F64: Standby Loss for Existing | G64: =(E62/800)+110*SQRT(F62) -> 3342.2073 | H64: Btu/hr | I64: =G64/B71 -> 49.883691
A65: Cold Water supply temperature (F) | B65: 55 | C65: Ref: ACM, 2025, 5.9.2: Rated capacity section
A66: WH system factor | B66: 0.6 | C66: Ref: ACM, 2025, 5.9.2: Rated capacity section
A67: Reheat multiplier | B67: 0.4
A68: * The 0.40 multiplier is a storage sizing factor used to account for the fact that the water heater doesn't need to store the full peak hour demand—it can reheat water during that time. This factor assumes that the heater will recover part of the hot water used during the peak hour, so only 40% of the peak hour demand needs to be stored at any given moment.
A69: **For Gas Water Heater: UA(Btu/h-°F)​=Q˙​SL​ (Btu/h)/ΔT (∘F)​
...

Sheet Interior Lights
A1: ="Interior Lighting - "&Prototype!A2 -> Interior Lighting - SchoolLarge
A2: Space Type | B2: New Construction | E2: Existing
B3: Lighting density (W/ft²) | C3: Additional lighting power for porTable lighting (W/ft²) | D3: Source | E3: LPD (W/ft²) | F3: Additional LPD for PorTable Lighting (W/ft²) | G3: Source
A4: =Zones!A3 -> Auditorium Area | B4: 0.7 | D4: T24, 2025, Table 140.6 C (Area category method) | E4: 1.4 | G4: T24, 2016, Table 140.6 C (Area category method)
A5: =Zones!A4 -> Exercise/Fitness Center and Gymnasium Areas | B5: 0.5 | E5: 1
A6: =Zones!A5 -> Restrooms | B6: 0.65 | E6: 0.6
A7: =Zones!A7 -> Dining Area (Cafeteria/Fast Food) | B7: 0.6 | E7: 1
A8: =Zones!A8 -> Classroom, Lecture, Training, Vocational Areas | B8: 0.6 | E8: 1.2
A9: =Zones!A20 -> Corridor Area | B9: 0.4 | E9: 0.6
A10: =Zones!A27 -> Kitchen/Food Preparation Area | B10: 0.6 | E10: 1.2
A11: =Zones!A28 -> Library (Reading Area) | B11: 0.65 | E11: 1.1
A12: =Zones!A29 -> Lobby, Main Entry | B12: 0.6 | E12: 0.95
A13: =Zones!A33 -> Electrical, Mechanical, Telephone Rooms | B13: 0.6 | E13: 0.55
A14: =Zones!A47 -> Office Area (>250 square feet) | B14: 0.6 | E14: 0.75

Sheet Ext Lighting
A1: ="Exterior Lighting - "&Prototype!A2 -> Exterior Lighting - SchoolLarge
A2: Motion Controlled Luminaires (W) | B2: Non-motion Controlled Luminaires (W) | C2: Total (W) | D2: Source
A3: =G14 -> 2296.1931 | B3: =G15 -> 8911.3994 | C3: =A3+B3 -> 11207.593 | D3: T24, 2022 & 2025 2019 Outdoor Lighting CASE report PNNL 90.1-2010 TSD
A7: ="Exterior Lighting" -> Exterior Lighting
A8: Items (Assume LZ2) | B8: Assumptions [2019 Outdoor Lighting CASE Report & PNNL 90.1-2010 TS] | D8: Unit | E8: Lighting Power Allowance [T24, 2025, Table 140.7-A & 140.7-B] | F8: Unit | G8: Exterior Lighting Power (W)
A9: IWA (Initial Wattage Allowance) | E9: 200 | F9: (W) | G9: =$E9 -> 200
A10: Parking area | B10: 400 ft² for every parking space 1 parking space per 830 ft² of gross building area | C10: =B25/830*400 -> 101641.74 | D10: (ft²) | E10: 0.019 | F10: (W/ft²) | G10: =E10*C10 -> 1931.1931
A11: Building Entrance | B11: 5 building entrance per PNNL Model (1 per 10,000 ft² footprint) | C11: 11 | D11: (count) | E11: 15 | F11: (W/ea) | G11: =E11*C11 -> 165
A12: Hardscape Ornamental Light | B12: 0.1 ft² per 1 ft² of gross building area for hardscape ornamental light | C12: =B25*0.1 -> 21090.662 | D12: (ft²) | E12: 0.007 | F12: (W/ft²) | G12: =E12*C12 -> 147.63463
A13: Building façade | B13: 0.1 W per 1 ft² of facade area Façade Area = Perimeter × 0.5 × max ( height and 30) (30 ft is the max height that is lit) * The 0.5 factor assumes that only half of the perimeter walls are lit. -Formula ia developed based on the 2019 Outdoor Lighting CASE report | C13: =0.5*4*(B23*B20) -> 87637.648 | D13: (ft²) | E13: 0.1 | F13: (W/ft²) | G13: =E13*C13 -> 8763.7648
A14: Motion Controlled Luminaires (W) | G14: =G10+G9+G11 -> 2296.1931
A15: Non-motion-controlled Luminaires | G15: =G12+G13 -> 8911.3994
A16: Total | G16: =G14+G15 -> 11207.593
A20: Max Height (ft) | B20: 28
A21: Building footprint | B21: =B25/2 -> 105453.31
A22: Floors | B22: 2
A23: Perimeter(ft) | B23: =285.433+203.412+259.186+9.842+78.74+383.858+(75.459*3)+(59.055*2) -> 1564.958
A24: Background Data [To be deleted prior to publication]
A25: Total floor area (ft²) | B25: =Prototype!B8 -> 210906.62

Sheet Equipment
A1: ="Equipment - "&Prototype!A2 -> Equipment - SchoolLarge
A2: Space Type | B2: Plug load Power Density (W/ft²) | C2: Gas Power Density (Btu/hr-ft²) | D2: Refrigeration Power Density (W/ft²) | E2: Source
A3: =Zones!A3 -> Auditorium Area | B3: 1 | C3: 0 | D3: 0 | E3: T24 2022 - Appendix 5.4A
A4: =Zones!A4 -> Exercise/Fitness Center and Gymnasium Areas | B4: 0.5 | C4: 0 | D4: 0
A5: =Zones!A5 -> Restrooms | B5: 0 | C5: 0 | D5: 0
A6: =Zones!A7 -> Dining Area (Cafeteria/Fast Food) | B6: 0.5 | C6: 0 | D6: 0.25
A7: =Zones!A20 -> Corridor Area | B7: 0 | C7: 0 | D7: 0 | E7: T24 2022 - Appendix 5.4A
A8: =Zones!A27 -> Kitchen/Food Preparation Area | B8: 1.5 | C8: 17.53768 | D8: 1.12 | E8: Plug load and schedules project with CEC, 2025
A9: =Zones!A28 -> Library (Reading Area) | B9: 1.5 | C9: 0 | D9: 0 | E9: T24 2022 - Appendix 5.4A
A10: =Zones!A29 -> Lobby, Main Entry | B10: 0.5 | C10: 0 | D10: 0
A11: =Zones!A33 -> Electrical, Mechanical, Telephone Rooms | B11: 3 | C11: 0 | D11: 0
A12: =Zones!A46 -> Classroom, Lecture, Training, Vocational Areas | B12: 0.8 | C12: 0 | D12: 0
A13: =Zones!A47 -> Office Area (>250 square feet) | B13: 0.7 | C13: 0 | D13: 0
A15: Elevator
A16: Vintages | B16: No of Elevator | C16: Design Load (W) | D16: Source
A17: New Construction and Existing | B17: =ROUND(('Ext Lighting'!B21*0.7/50000)+ROUND(2/2,0),0) -> 2 | C17: =F24*1000 -> 11793.11 | D17: PNNL ASHRAE 90.1 2019 Large School prototype
A19: Assumptions for elevators:
A20: One elevator for approximately 50,000 ft² in use. | F20: https://buildingandinteriors.com/find-the-magic-number-elevators-per-building/
A21: For every two floors or two and a half floors, one more elevator was added.
A22: An in-use rate of 70% for the floor area was assumed, based on engineering judgment.
A23: Calculated number of Elevators: | C23: =ROUND(('Ext Lighting'!B21*0.7/50000)+ROUND(2/2,0),0) -> 2
A24: Calculate Elevator load (kw)based on ACM 2022: | C24: =C23*C25 -> 20 | D24: 12 kW is PNNL ASHRE 90.1 2019 elevator load | F24: 11.79311
A25: ACM 2022 suggestion for elevator load (kw): | C25: 10
A45: Elevator load will be defined as exterior load not equipment load.

Sheet Schedules
A1: ="Schedules - "&Prototype!A2 -> Schedules - SchoolLarge
A2: Zone | B2: Schedule Category | C2: Schedule | D2: Source | E2: Type | F2: Hour
F3: 1 | G3: 2 | H3: 3 | I3: 4 | J3: 5 | K3: 6 | L3: 7 | M3: 8 | N3: 9 | O3: 10 | P3: 11 | Q3: 12 | R3: 13 | S3: 14 | T3: 15 | U3: 16 | V3: 17 | W3: 18 | X3: 19 | Y3: 20 | Z3: 21 | AA3: 22 | AB3: 23 | AC3: 24
A4: School Zones | B4: Classroom | C4: Occupancy | D4: T24 2022 - Appendix 5.4B [School] | E4: Weekday | F4: 0 | G4: 0 | H4: 0 | I4: 0 | J4: 0 | K4: 0 | L4: 0 | M4: 0.05 | N4: 0.75 | O4: 0.9 | P4: 0.9 | Q4: 0.8 | R4: 0.8 | S4: 0.8 | T4: 0.8 | U4: 0.45 | V4: 0.15 | W4: 0.05 | X4: 0.15 | Y4: 0.2 | Z4: 0.2 | AA4: 0.1 | AB4: 0 | AC4: 0
E5: Saturday | F5: 0 | G5: 0 | H5: 0 | I5: 0 | J5: 0 | K5: 0 | L5: 0 | M5: 0 | N5: 0.1 | O5: 0.1 | P5: 0.1 | Q5: 0.1 | R5: 0.1 | S5: 0 | T5: 0 | U5: 0 | V5: 0 | W5: 0 | X5: 0 | Y5: 0 | Z5: 0 | AA5: 0 | AB5: 0 | AC5: 0
E6: Sunday | F6: 0 | G6: 0 | H6: 0 | I6: 0 | J6: 0 | K6: 0 | L6: 0 | M6: 0 | N6: 0 | O6: 0 | P6: 0 | Q6: 0 | R6: 0 | S6: 0 | T6: 0 | U6: 0 | V6: 0 | W6: 0 | X6: 0 | Y6: 0 | Z6: 0 | AA6: 0 | AB6: 0 | AC6: 0
A7: School Zones | B7: =B4 -> Classroom | C7: Lights | D7: T24 2022 - Appendix 5.4B [School] | E7: Weekday | F7: 0.05 | G7: 0.05 | H7: 0.05 | I7: 0.05 | J7: 0.05 | K7: 0.05 | L7: 0.05 | M7: 0.3 | N7: 0.6 | O7: 0.65 | P7: 0.65 | Q7: 0.65 | R7: 0.55 | S7: 0.55 | T7: 0.55 | U7: 0.5 | V7: 0.35 | W7: 0.35 | X7: 0.35 | Y7: 0.35 | Z7: 0.35 | AA7: 0.3 | AB7: 0.05 | AC7: 0.05
E8: Saturday | F8: 0.05 | G8: 0.05 | H8: 0.05 | I8: 0.05 | J8: 0.05 | K8: 0.05 | L8: 0.05 | M8: 0.05 | N8: 0.15 | O8: 0.15 | P8: 0.15 | Q8: 0.15 | R8: 0.15 | S8: 0.05 | T8: 0.05 | U8: 0.05 | V8: 0.05 | W8: 0.05 | X8: 0.05 | Y8: 0.05 | Z8: 0.05 | AA8: 0.05 | AB8: 0.05 | AC8: 0.05
E9: Sunday | F9: 0.05 | G9: 0.05 | H9: 0.05 | I9: 0.05 | J9: 0.05 | K9: 0.05 | L9: 0.05 | M9: 0.05 | N9: 0.05 | O9: 0.05 | P9: 0.05 | Q9: 0.05 | R9: 0.05 | S9: 0.05 | T9: 0.05 | U9: 0.05 | V9: 0.05 | W9: 0.05 | X9: 0.05 | Y9: 0.05 | Z9: 0.05 | AA9: 0.05 | AB9: 0.05 | AC9: 0.05
A10: School Zones | B10: =B4 -> Classroom | C10: ElecEquipment | D10: T24 2022 - Appendix 5.4B [School] | E10: Weekday | F10: 0.05 | G10: 0.05 | H10: 0.05 | I10: 0.05 | J10: 0.05 | K10: 0.05 | L10: 0.05 | M10: 0.3 | N10: 0.85 | O10: 0.95 | P10: 0.95 | Q10: 0.95 | R10: 0.8 | S10: 0.8 | T10: 0.8 | U10: 0.7 | V10: 0.5 | W10: 0.5 | X10: 0.35 | Y10: 0.35 | Z10: 0.35 | AA10: 0.3 | AB10: 0.05 | AC10: 0.05
E11: Saturday | F11: 0.05 | G11: 0.05 | H11: 0.05 | I11: 0.05 | J11: 0.05 | K11: 0.05 | L11: 0.05 | M11: 0.05 | N11: 0.15 | O11: 0.15 | P11: 0.15 | Q11: 0.15 | R11: 0.15 | S11: 0.05 | T11: 0.05 | U11: 0.05 | V11: 0.05 | W11: 0.05 | X11: 0.05 | Y11: 0.05 | Z11: 0.05 | AA11: 0.05 | AB11: 0.05 | AC11: 0.05
E12: Sunday | F12: 0.05 | G12: 0.05 | H12: 0.05 | I12: 0.05 | J12: 0.05 | K12: 0.05 | L12: 0.05 | M12: 0.05 | N12: 0.05 | O12: 0.05 | P12: 0.05 | Q12: 0.05 | R12: 0.05 | S12: 0.05 | T12: 0.05 | U12: 0.05 | V12: 0.05 | W12: 0.05 | X12: 0.05 | Y12: 0.05 | Z12: 0.05 | AA12: 0.05 | AB12: 0.05 | AC12: 0.05
A13: School Zones | B13: =B4 -> Classroom | C13: ServiceHotWater | D13: T24 2022 - Appendix 5.4B [School] | E13: Weekday | F13: 0.05 | G13: 0.05 | H13: 0.05 | I13: 0.05 | J13: 0.05 | K13: 0.05 | L13: 0.05 | M13: 0.1 | N13: 0.34 | O13: 0.6 | P13: 0.63 | Q13: 0.72 | R13: 0.79 | S13: 0.83 | T13: 0.61 | U13: 0.65 | V13: 0.1 | W13: 0.1 | X13: 0.19 | Y13: 0.25 | Z13: 0.22 | AA13: 0.22 | AB13: 0.12 | AC13: 0.09
E14: Saturday | F14: 0.03 | G14: 0.03 | H14: 0.03 | I14: 0.03 | J14: 0.03 | K14: 0.03 | L14: 0.03 | M14: 0.03 | N14: 0.03 | O14: 0.05 | P14: 0.05 | Q14: 0.05 | R14: 0.05 | S14: 0.03 | T14: 0.03 | U14: 0.03 | V14: 0.03 | W14: 0.03 | X14: 0.03 | Y14: 0.03 | Z14: 0.03 | AA14: 0.03 | AB14: 0.03 | AC14: 0.03
E15: Sunday | F15: 0.03 | G15: 0.03 | H15: 0.03 | I15: 0.03 | J15: 0.03 | K15: 0.03 | L15: 0.03 | M15: 0.03 | N15: 0.05 | O15: 0.05 | P15: 0.05 | Q15: 0.05 | R15: 0.05 | S15: 0.05 | T15: 0.03 | U15: 0.03 | V15: 0.03 | W15: 0.03 | X15: 0.03 | Y15: 0.03 | Z15: 0.03 | AA15: 0.03 | AB15: 0.03 | AC15: 0.03
A16: School Zones | B16: =B4 -> Classroom | C16: GasEquipment | D16: T24 2022 - Appendix 5.4B [School] | E16: Weekday | F16: 0 | G16: 0 | H16: 0 | I16: 0 | J16: 0 | K16: 0 | L16: 0 | M16: 0.5 | N16: 0.5 | O16: 0.75 | P16: 0.9 | Q16: 0.9 | R16: 0.9 | S16: 0 | T16: 0 | U16: 0 | V16: 0 | W16: 0 | X16: 0 | Y16: 0 | Z16: 0 | AA16: 0 | AB16: 0 | AC16: 0
E17: Saturday | F17: 0 | G17: 0 | H17: 0 | I17: 0 | J17: 0 | K17: 0 | L17: 0 | M17: 0 | N17: 0 | O17: 0 | P17: 0 | Q17: 0 | R17: 0 | S17: 0 | T17: 0 | U17: 0 | V17: 0 | W17: 0 | X17: 0 | Y17: 0 | Z17: 0 | AA17: 0 | AB17: 0 | AC17: 0
E18: Sunday | F18: 0 | G18: 0 | H18: 0 | I18: 0 | J18: 0 | K18: 0 | L18: 0 | M18: 0 | N18: 0 | O18: 0 | P18: 0 | Q18: 0 | R18: 0 | S18: 0 | T18: 0 | U18: 0 | V18: 0 | W18: 0 | X18: 0 | Y18: 0 | Z18: 0 | AA18: 0 | AB18: 0 | AC18: 0
A19: School Zones | B19: =B4 -> Classroom | C19: Refrigeration | D19: T24 2022 - Appendix 5.4B [School] | E19: Weekday | F19: 0.9 | G19: 0.9 | H19: 0.9 | I19: 0.9 | J19: 0.9 | K19: 0.9 | L19: 0.9 | M19: 0.9 | N19: 0.9 | O19: 0.9 | P19: 0.9 | Q19: 0.9 | R19: 0.9 | S19: 0.9 | T19: 0.9 | U19: 0.9 | V19: 0.9 | W19: 0.9 | X19: 0.9 | Y19: 0.9 | Z19: 0.9 | AA19: 0.9 | AB19: 0.9 | AC19: 0.9
E20: Saturday | F20: 0.9 | G20: 0.9 | H20: 0.9 | I20: 0.9 | J20: 0.9 | K20: 0.9 | L20: 0.9 | M20: 0.9 | N20: 0.9 | O20: 0.9 | P20: 0.9 | Q20: 0.9 | R20: 0.9 | S20: 0.9 | T20: 0.9 | U20: 0.9 | V20: 0.9 | W20: 0.9 | X20: 0.9 | Y20: 0.9 | Z20: 0.9 | AA20: 0.9 | AB20: 0.9 | AC20: 0.9
E21: Sunday | F21: 0.9 | G21: 0.9 | H21: 0.9 | I21: 0.9 | J21: 0.9 | K21: 0.9 | L21: 0.9 | M21: 0.9 | N21: 0.9 | O21: 0.9 | P21: 0.9 | Q21: 0.9 | R21: 0.9 | S21: 0.9 | T21: 0.9 | U21: 0.9 | V21: 0.9 | W21: 0.9 | X21: 0.9 | Y21: 0.9 | Z21: 0.9 | AA21: 0.9 | AB21: 0.9 | AC21: 0.9
A22: School Zones | B22: =B4 -> Classroom | C22: HVACAvail | D22: T24 2022 - Appendix 5.4B [School] | E22: Weekday | F22: 0 | G22: 0 | H22: 0 | I22: 0 | J22: 0 | K22: 0 | L22: 1 | M22: 1 | N22: 1 | O22: 1 | P22: 1 | Q22: 1 | R22: 1 | S22: 1 | T22: 1 | U22: 1 | V22: 1 | W22: 1 | X22: 1 | Y22: 1 | Z22: 1 | AA22: 1 | AB22: 0 | AC22: 0
E23: Saturday | F23: 0 | G23: 0 | H23: 0 | I23: 0 | J23: 0 | K23: 0 | L23: 0 | M23: 1 | N23: 1 | O23: 1 | P23: 1 | Q23: 1 | R23: 1 | S23: 0 | T23: 0 | U23: 0 | V23: 0 | W23: 0 | X23: 0 | Y23: 0 | Z23: 0 | AA23: 0 | AB23: 0 | AC23: 0
E24: Sunday | F24: 0 | G24: 0 | H24: 0 | I24: 0 | J24: 0 | K24: 0 | L24: 0 | M24: 0 | N24: 0 | O24: 0 | P24: 0 | Q24: 0 | R24: 0 | S24: 0 | T24: 0 | U24: 0 | V24: 0 | W24: 0 | X24: 0 | Y24: 0 | Z24: 0 | AA24: 0 | AB24: 0 | AC24: 0
A25: School Zones | B25: =B4 -> Classroom | C25: Infiltration | D25: T24 2022 - Appendix 5.4B [School] | E25: Weekday | F25: 0 | G25: =IF(G22=1,0.25,1) -> 1 | H25: =IF(H22=1,0.25,1) -> 1 | I25: =IF(I22=1,0.25,1) -> 1 | J25: =IF(J22=1,0.25,1) -> 1 | K25: =IF(K22=1,0.25,1) -> 1 | L25: =IF(L22=1,0.25,1) -> 0.25 | M25: =IF(M22=1,0.25,1) -> 0.25 | N25: =IF(N22=1,0.25,1) -> 0.25 | ... AC25: =IF(AC22=1,0.25,1) -> 1
E26: Saturday | F26: 0 | G26: =IF(G23=1,0.25,1) -> 1 | H26: =IF(H23=1,0.25,1) -> 1 | I26: =IF(I23=1,0.25,1) -> 1 | J26: =IF(J23=1,0.25,1) -> 1 | K26: =IF(K23=1,0.25,1) -> 1 | L26: =IF(L23=1,0.25,1) -> 1 | M26: =IF(M23=1,0.25,1) -> 0.25 | N26: =IF(N23=1,0.25,1) -> 0.25 | ... AC26: =IF(AC23=1,0.25,1) -> 1
E27: Sunday | F27: 0 | G27: =IF(G24=1,0.25,1) -> 1 | H27: =IF(H24=1,0.25,1) -> 1 | I27: =IF(I24=1,0.25,1) -> 1 | J27: =IF(J24=1,0.25,1) -> 1 | K27: =IF(K24=1,0.25,1) -> 1 | L27: =IF(L24=1,0.25,1) -> 1 | M27: =IF(M24=1,0.25,1) -> 1 | N27: =IF(N24=1,0.25,1) -> 1 | ... AC27: =IF(AC24=1,0.25,1) -> 1
A28: School Zones | B28: =B4 -> Classroom | C28: HtgSetpt | D28: T24 2022 - Appendix 5.4B [School] | E28: Weekday | F28: =IF(F22=0,Thermostat!$B$4,Thermostat!$B$3) -> 60 | G28: =IF(G22=0,Thermostat!$B$4,Thermostat!$B$3) -> 60 | H28: =IF(H22=0,Thermostat!$B$4,Thermostat!$B$3) -> 60 | I28: =IF(I22=0,Thermostat!$B$4,Thermostat!$B$3) -> 60 | J28: =IF(J22=0,Thermostat!$B$4,Thermostat!$B$3) -> 60 | K28: =IF(K22=0,Thermostat!$B$4,Thermostat!$B$3) -> 60 | L28: =IF(L22=0,Thermostat!$B$4,Thermostat!$B$3) -> 70 | M28: =IF(M22=0,Thermostat!$B$4,Thermostat!$B$3) -> 70 | ... AC28: =IF(AC22=0,Thermostat!$B$4,Thermostat!$B$3) -> 60
E29: Saturday | F29: =IF(F23=0,Thermostat!$B$4,Thermostat!$B$3) -> 60 | G29: =IF(G23=0,Thermostat!$B$4,Thermostat!$B$3) -> 60 | H29: =IF(H23=0,Thermostat!$B$4,Thermostat!$B$3) -> 60 | I29: =IF(I23=0,Thermostat!$B$4,Thermostat!$B$3) -> 60 | J29: =IF(J23=0,Thermostat!$B$4,Thermostat!$B$3) -> 60 | K29: =IF(K23=0,Thermostat!$B$4,Thermostat!$B$3) -> 60 | L29: =IF(L23=0,Thermostat!$B$4,Thermostat!$B$3) -> 60 | M29: =IF(M23=0,Thermostat!$B$4,Thermostat!$B$3) -> 70 | ... AC29: =IF(AC23=0,Thermostat!$B$4,Thermostat!$B$3) -> 60
E30: Sunday | F30: =IF(F24=0,Thermostat!$B$4,Thermostat!$B$3) -> 60 | G30: =IF(G24=0,Thermostat!$B$4,Thermostat!$B$3) -> 60 | H30: =IF(H24=0,Thermostat!$B$4,Thermostat!$B$3) -> 60 | I30: =IF(I24=0,Thermostat!$B$4,Thermostat!$B$3) -> 60 | J30: =IF(J24=0,Thermostat!$B$4,Thermostat!$B$3) -> 60 | K30: =IF(K24=0,Thermostat!$B$4,Thermostat!$B$3) -> 60 | L30: =IF(L24=0,Thermostat!$B$4,Thermostat!$B$3) -> 60 | M30: =IF(M24=0,Thermostat!$B$4,Thermostat!$B$3) -> 60 | ... AC30: =IF(AC24=0,Thermostat!$B$4,Thermostat!$B$3) -> 60
A31: School Zones | B31: =B4 -> Classroom | C31: ClgSetpt | D31: T24 2022 - Appendix 5.4B [School] | E31: Weekday | F31: =IF(F22=0,Thermostat!$B$6,Thermostat!$B$3) -> 85 | G31: =IF(G22=0,Thermostat!$B$6,Thermostat!$B$3) -> 85 | H31: =IF(H22=0,Thermostat!$B$6,Thermostat!$B$3) -> 85 | I31: =IF(I22=0,Thermostat!$B$6,Thermostat!$B$3) -> 85 | J31: =IF(J22=0,Thermostat!$B$6,Thermostat!$B$3) -> 85 | K31: =IF(K22=0,Thermostat!$B$6,Thermostat!$B$3) -> 85 | L31: =IF(L22=0,Thermostat!$B$6,Thermostat!$B$3) -> 70 | M31: =IF(M22=0,Thermostat!$B$6,Thermostat!$B$3) -> 70 | ... AC31: =IF(AC22=0,Thermostat!$B$6,Thermostat!$B$3) -> 85
E32: Saturday | F32: =IF(F23=0,Thermostat!$B$6,Thermostat!$B$3) -> 85 | G32: =IF(G23=0,Thermostat!$B$6,Thermostat!$B$3) -> 85 | H32: =IF(H23=0,Thermostat!$B$6,Thermostat!$B$3) -> 85 | I32: =IF(I23=0,Thermostat!$B$6,Thermostat!$B$3) -> 85 | J32: =IF(J23=0,Thermostat!$B$6,Thermostat!$B$3) -> 85 | K32: =IF(K23=0,Thermostat!$B$6,Thermostat!$B$3) -> 85 | L32: =IF(L23=0,Thermostat!$B$6,Thermostat!$B$3) -> 85 | M32: =IF(M23=0,Thermostat!$B$6,Thermostat!$B$3) -> 70 | ... AC32: =IF(AC23=0,Thermostat!$B$6,Thermostat!$B$3) -> 85
E33: Sunday | F33: =IF(F24=0,Thermostat!$B$6,Thermostat!$B$3) -> 85 | G33: =IF(G24=0,Thermostat!$B$6,Thermostat!$B$3) -> 85 | H33: =IF(H24=0,Thermostat!$B$6,Thermostat!$B$3) -> 85 | I33: =IF(I24=0,Thermostat!$B$6,Thermostat!$B$3) -> 85 | J33: =IF(J24=0,Thermostat!$B$6,Thermostat!$B$3) -> 85 | K33: =IF(K24=0,Thermostat!$B$6,Thermostat!$B$3) -> 85 | L33: =IF(L24=0,Thermostat!$B$6,Thermostat!$B$3) -> 85 | M33: =IF(M24=0,Thermostat!$B$6,Thermostat!$B$3) -> 85 | ... AC33: =IF(AC24=0,Thermostat!$B$6,Thermostat!$B$3) -> 85
A34: School Zones | B34: Classroom | C34: Infiltration | D34: T24 2022 - Appendix 5.4B Updated based on the Plug Loads project | E34: Weekday | F34: 1 | G34: 1 | H34: 1 | I34: 1 | J34: 1 | K34: 1 | L34: 1 | M34: 0.25 | N34: 0.25 | O34: 0.25 | P34: 0.25 | Q34: 0.25 | R34: 0.25 | S34: 0.25 | T34: 0.25 | U34: 0.25 | V34: 1 | W34: 1 | X34: 1 | Y34: 1 | Z34: 1 | AA34: 1 | AB34: 1 | AC34: 1
E35: Saturday | F35: 1 | G35: 1 | H35: 1 | I35: 1 | J35: 1 | K35: 1 | L35: 1 | M35: 1 | N35: 1 | O35: 1 | P35: 1 | Q35: 1 | R35: 1 | S35: 1 | T35: 1 | U35: 1 | V35: 1 | W35: 1 | X35: 1 | Y35: 1 | Z35: 1 | AA35: 1 | AB35: 1 | AC35: 1
E36: Sunday | F36: 1 | G36: 1 | H36: 1 | I36: 1 | J36: 1 | K36: 1 | L36: 1 | M36: 1 | N36: 1 | O36: 1 | P36: 1 | Q36: 1 | R36: 1 | S36: 1 | T36: 1 | U36: 1 | V36: 1 | W36: 1 | X36: 1 | Y36: 1 | Z36: 1 | AA36: 1 | AB36: 1 | AC36: 1
A37: Kitchen | C37: Other
A38: Kitchen Zone | B38: Kitchen | C38: Occupancy | D38: T24 2022 - Appendix 5.4B Updated based on the Plug Loads project | E38: Weekday | F38: 0 | G38: 0 | H38: 0 | I38: 0 | J38: 0 | K38: 0.1 | L38: 0.5 | M38: 0.95 | N38: 0.95 | O38: 0.95 | P38: 0.95 | Q38: 0.95 | R38: 0.95 | S38: 0.95 | T38: 0.5 | U38: 0 | V38: 0 | W38: 0 | X38: 0 | Y38: 0 | Z38: 0 | AA38: 0 | AB38: 0 | AC38: 0
E39: Saturday | F39: 0 | G39: 0 | H39: 0 | I39: 0 | J39: 0 | K39: 0 | L39: 0 | M39: 0 | N39: 0 | O39: 0 | P39: 0 | Q39: 0 | R39: 0 | S39: 0 | T39: 0 | U39: 0 | V39: 0 | W39: 0 | X39: 0 | Y39: 0 | Z39: 0 | AA39: 0 | AB39: 0 | AC39: 0
E40: Sunday | F40: 0 | G40: 0 | H40: 0 | I40: 0 | J40: 0 | K40: 0 | L40: 0 | M40: 0 | N40: 0 | O40: 0 | P40: 0 | Q40: 0 | R40: 0 | S40: 0 | T40: 0 | U40: 0 | V40: 0 | W40: 0 | X40: 0 | Y40: 0 | Z40: 0 | AA40: 0 | AB40: 0 | AC40: 0
...

Sheet Energy Usage
A1: ="CalBEM Energy Consumption - "&Prototype!B4 -> CalBEM Energy Consumption - Large School | N1: ="Energy Consumption - "&Prototype!A2 -> Energy Consumption - SchoolLarge
A2: Prototype | B2: CZ | C2: CalBEM Electricity EUI (KBTU/ft²) | D2: CalBEM Gas EUI (KBTU/ft²) | E2: CalBEM Total EUI (KBTU/ft²) | F2: New Construction Electricity EUI (KBTU/ft²) | G2: New Construction Gas EUI (KBTU/ft²) | H2: New Construction Total EUI (KBTU/ft²) | I2: National Average | J2: Acceptable Range (25% Higher) | K2: Acceptable Range (25% Lower) | L2: National Average Acceptable EUI Range | N2: Prototype | O2: CZ | P2: Total Floorspace (Thousand of ft²) | Q2: CEUS 2023 Electricity EUI (kBtu/ft²) | R2: CEUS 2023 Gas EUI (kBtu/ft²) | S2: CEUS 2023 Total EUI (kBtu/ft²) | T2: Acceptable Range (25% Higher) | U2: Acceptable Range (25% Lower) | V2: CEUS 2022 Acceptable EUI Range
A3: =Prototype!B4 -> Large School | B3: 1 | C3: 17.463958 | D3: 51.379838 | E3: 68.843796 | F3: 14.68 | G3: 42.85 | H3: 57.53 | I3: 84 | J3: =I3*1.25 -> 105 | K3: =I3*0.75 -> 63 | L3: =J3-K3 -> 42 | N3: =Prototype!B4 -> Large School | O3: 1 | P3: 7618.5337 | Q3: 32.349176 | R3: 12.848137 | S3: 55.364804 | T3: =S3*1.25 -> 69.206005 | U3: =S3*0.75 -> 41.523603 | V3: =T3-U3 -> 27.682402
B4: 2 | C4: 22.985306 | D4: 40.368286 | E4: 63.353592 | F4: 19.5 | G4: 33.43 | H4: 52.93 | I4: 84 | J4: =I4*1.25 -> 105 | K4: =I4*0.75 -> 63 | L4: =J4-K4 -> 42 | O4: 2 | P4: 11477.671 | Q4: 15.421598 | R4: 12.913999 | S4: 47.893283 | T4: =S4*1.25 -> 59.866604 | U4: =S4*0.75 -> 35.919962 | V4: =T4-U4 -> 23.946642
B5: 3 | C5: 19.637407 | D5: 32.777901 | E5: 52.415309 | F5: 16.64 | G5: 27.84 | H5: 44.48 | I5: 84 | J5: =I5*1.25 -> 105 | K5: =I5*0.75 -> 63 | L5: =J5-K5 -> 42 | O5: 3 | P5: 46411.86 | Q5: 20.479595 | R5: 12.799248 | S5: 100.09497 | T5: =S5*1.25 -> 125.11872 | U5: =S5*0.75 -> 75.071231 | V5: =T5-U5 -> 50.047487
B6: 4 | C6: 25.462717 | D6: 34.981758 | E6: 60.444475 | F6: 21.37 | G6: 28.59 | H6: 49.96 | I6: 84 | J6: =I6*1.25 -> 105 | K6: =I6*0.75 -> 63 | L6: =J6-K6 -> 42 | O6: 4 | P6: 23032.968 | Q6: 21.49373 | R6: 13.019767 | S6: 106.62133 | T6: =S6*1.25 -> 133.27666 | U6: =S6*0.75 -> 79.965995 | V6: =T6-U6 -> 53.310663
B7: 5 | C7: 20.925495 | D7: 27.155005 | E7: 48.0805 | F7: 18.02 | G7: 22.83 | H7: 40.85 | I7: 84 | J7: =I7*1.25 -> 105 | K7: =I7*0.75 -> 63 | L7: =J7-K7 -> 42 | O7: 5 | P7: 5978.4428 | Q7: 11.998072 | R7: 11.585185 | S7: 59.149271 | T7: =S7*1.25 -> 73.936588 | U7: =S7*0.75 -> 44.361953 | V7: =T7-U7 -> 29.574635
B8: 6 | C8: 25.237556 | D8: 17.500389 | E8: 42.737944 | F8: 22.12 | G8: 15.7 | H8: 37.82 | I8: 84 | J8: =I8*1.25 -> 105 | K8: =I8*0.75 -> 63 | L8: =J8-K8 -> 42 | O8: 6 | P8: 57755.959 | Q8: 22.607349 | R8: 9.9467421 | S8: 82.347488 | T8: =S8*1.25 -> 102.93436 | U8: =S8*0.75 -> 61.760616 | V8: =T8-U8 -> 41.173744
B9: 7 | C9: 25.464979 | D9: 16.134092 | E9: 41.599071 | F9: 22.03 | G9: 14.8 | H9: 36.83 | I9: 84 | J9: =I9*1.25 -> 105 | K9: =I9*0.75 -> 63 | L9: =J9-K9 -> 42 | O9: 7 | P9: 35149.993 | Q9: 24.848388 | R9: 6.9700357 | S9: 88.553476 | T9: =S9*1.25 -> 110.69184 | U9: =S9*0.75 -> 66.415107 | V9: =T9-U9 -> 44.276738
B10: 8 | C10: 30.166441 | D10: 20.453699 | E10: 50.62014 | F10: 26.09 | G10: 18.26 | H10: 44.35 | I10: 84 | J10: =I10*1.25 -> 105 | K10: =I10*0.75 -> 63 | L10: =J10-K10 -> 42 | O10: 8 | P10: 92353.411 | Q10: 22.935329 | R10: 8.842203 | S10: 103.44181 | T10: =S10*1.25 -> 129.30226 | U10: =S10*0.75 -> 77.581354 | V10: =T10-U10 -> 51.720903
B11: 9 | C11: 29.241156 | D11: 23.194009 | E11: 52.435165 | F11: 25.33 | G11: 20.09 | H11: 45.42 | I11: 84 | J11: =I11*1.25 -> 105 | K11: =I11*0.75 -> 63 | L11: =J11-K11 -> 42 | O11: 9 | P11: 141795.45 | Q11: 26.797343 | R11: 10.089067 | S11: 119.15132 | T11: =S11*1.25 -> 148.93914 | U11: =S11*0.75 -> 89.363487 | V11: =T11-U11 -> 59.575658
B12: 10 | C12: 30.351287 | D12: 22.234582 | E12: 52.585868 | F12: 26.84 | G12: 19.77 | H12: 46.61 | I12: 84 | J12: =I12*1.25 -> 105 | K12: =I12*0.75 -> 63 | L12: =J12-K12 -> 42 | O12: 10 | P12: 92589.867 | Q12: 22.490401 | R12: 10.108975 | S12: 67.419104 | T12: =S12*1.25 -> 84.27388 | U12: =S12*0.75 -> 50.564328 | V12: =T12-U12 -> 33.709552
B13: 11 | C13: 29.677993 | D13: 45.706569 | E13: 75.384562 | F13: 25.19 | G13: 37.89 | H13: 63.08 | I13: 84 | J13: =I13*1.25 -> 105 | K13: =I13*0.75 -> 63 | L13: =J13-K13 -> 42 | O13: 11 | P13: 33810.488 | Q13: 26.928661 | R13: 8.760437 | S13: 68.839253 | T13: =S13*1.25 -> 86.049066 | U13: =S13*0.75 -> 51.62944 | V13: =T13-U13 -> 34.419626
B14: 12 | C14: 26.297173 | D14: 37.924512 | E14: 64.221685 | F14: 22.48 | G14: 32.29 | H14: 54.77 | I14: 84 | J14: =I14*1.25 -> 105 | K14: =I14*0.75 -> 63 | L14: =J14-K14 -> 42 | O14: 12 | P14: 108342.43 | Q14: 31.799594 | R14: 12.230299 | S14: 85.587371 | T14: =S14*1.25 -> 106.98421 | U14: =S14*0.75 -> 64.190528 | V14: =T14-U14 -> 42.793686
B15: 13 | C15: 31.243721 | D15: 33.280611 | E15: 64.524332 | F15: 26.74 | G15: 28.36 | H15: 55.1 | I15: 84 | J15: =I15*1.25 -> 105 | K15: =I15*0.75 -> 63 | L15: =J15-K15 -> 42 | O15: 13 | P15: 46676.808 | Q15: 32.656044 | R15: 15.473534 | S15: 57.73569 | T15: =S15*1.25 -> 72.169613 | U15: =S15*0.75 -> 43.301768 | V15: =T15-U15 -> 28.867845
... B18: 16 | C18: 22.379323 | D18: 68.098872 | E18: 90.478195 | F18: 18.98 | G18: 57.3 | H18: 76.28 | I18: 84 | J18: =I18*1.25 -> 105 | K18: =I18*0.75 -> 63 | L18: =J18-K18 -> 42 | O18: 16 | P18: 85267.89 | Q18: 27.026911 | R18: 11.652927 | S18: 67.576478 | T18: =S18*1.25 -> 84.470598 | U18: =S18*0.75 -> 50.682359 | V18: =T18-U18 -> 33.788239
