Workbook
Name nonparticipating_forecastzone_scale_factor: #REF!
Name nonparticipating_forecastzone_scale_factor: #REF!
Name nonparticipating_forecastzone_scale_factor: 'Energy Usage'!#REF!
Name Space_Function: Data!$A$2:$A$76

Sheet Notes
A1: Data Sources
A2: Dataset | B2: Dodge 2023
A3: Prototype | B3: CEC prototype (CBECC 2022.3.1) | C3: https://bees.noresco.com/software2022.html
B4: TRC Multifamily Prototypes study (2019) | C4: https://title24stakeholders.com/wp-content/uploads/2019/06/SCE-MFModeling_MultifamilyPrototypesReport_2019-06-07_clean.pdf
A5: Codes | B5: Title 24, part 6 (1986, 2001, 2007, 2013, 2022, 2025)
B6: ASHRAE 90.1 (2022)
B7: ASHRAE Handbook of Fundamentals (Ch. 15 Tables 4 and 10)
B8: CFR Title 10 (2010, 2024)
A9: Others | B9: 2019 Outdoor Lighting CASE Report | C9: https://title24stakeholders.com/wp-content/uploads/2016/10/T24-2019-CASE-Study-Results-Report-Outdoor-Sources_Final_with-Attachments.pdf
B10: PNNL 20405, 2011 | C10: https://www.pnnl.gov/main/publications/external/technical_reports/PNNL-20405.pdf
B11: 2024 CASE Report: A Comprehensive, High Efficiency Solution for Water Heating in Multifamily Buildings | C11: https://www.energy.ca.gov/sites/default/files/2024-06/CEC-500-2024-054.pdf
B12: 2022 CASE Report: Multifamily Domestic Hot Water Distribution | C12: https://title24stakeholders.com/wp-content/uploads/2020/09/2022_T24_Final-CASE-Report-MF-DHW-Dist.pdf
B13: Maguire & Roberts 2020 (NREL/CP-5500-71633): Deriving Simulation Parameters for Storage-Type Water Heaters Using Ratings Data Produced from the Uniform Energy Factor Test Procedure | C13: https://docs.nrel.gov/docs/fy21osti/71633.pdf
A17: Construction Rate
A30: Notes

Sheet Prototype
A1: NORESCO, Updated September 2026
A2: ApartmentMidRise
A3: Characteristic | B3: Value | C3: Data Sources
A4: Building Type | B4: Mid-Rise Apartment
A5: Building Category | B5: Nonresidential
A6: Version | B6: v2-0
A7: Vintages | B7: 4 Vintages: Pre-1978 , 1978-1997 ,1998-2007 , 2008-2018 New Construction (2019+) | C7: Following the vintage‑bin analysis performed for the nonresidential prototypes. A summary of the findings is presented in the following paper, with a link provided in the Notes tab: Yousefi, F., Athalye, R. (2025). “Determining Vintage Bins for Prototype Development: An Analysis of California Commercial Buildings.” ASHRAE Annual Conference.
A8: Shape | C8: CEC Prototype model TRC Multifamily Prototypes study (2019) https://title24stakeholders.com/wp-content/uploads/2019/06/SCE-MFModeling_MultifamilyPrototypesReport_2019-06-07_clean.pdf
A9: Total Floor Area (ft2) | B9: =Zones!K40 -> 141013.76 | C9: CEC Prototype model TRC Multifamily Prototypes study (2019)
A10: Aspect Ratio | B10: =180/155 -> 1.1612903
A11: Number of Floors | B11: 5 above-ground floors including one underground parking garage (180 ft x 155 ft)
A12: Roof type | B12: Flat roof
A13: WWR (above grade) | B13: South: 22.0%, East: 22.0%, North: 22.0%, West: 22.0% Total 22.0%
A14: Window dimensions | B14: 5 * 3
A15: Shading Geometry | B15: -
A16: Floor to floor height (feet) | B16: Residential: 10 Non-residential: 10 Parking: 15
A17: Floor to ceiling height (feet) | B17: Residential: 9 Non-residential: 10 Parking: 14
A18: Glazing sill height (feet) | B18: 3.1 ft (in first floor), 2.95 ft. (in upper floors)
A19: Number of dwelling units | B19: 88 | C19: 22 per residential floor × 4 floors. Mix per floor from TRC/plans: 2 studio, 10 one-bed, 8 two-bed, 2 three-bed.
A22: Above grade wall area (ft²) | B22: 42304.13
A23: Gross wall area (ft²) | B23: 51685.04
A24: Roof area (ft²) | B24: 27902.72
A25: Underground Gross Wall Area (ft²) | B25: =B23-B22 -> 9380.91

Sheet Zones
A1: ="Proposed Layout - "&Prototype!A2 -> Proposed Layout - ApartmentMidRise
A2: Building | B2: Space/Thermal Zone | C2: Space Type [Primarily from: T24, 2022 Appendix 5.4A] - See Notes column | D2: Res/NR | E2: Schedule Category | F2: No. of Dwelling Units | G2: Dwelling Unit Type | H2: Thermal Zone (HVAC Zone) | I2: Conditioned [Y/N] | J2: Area Fraction | K2: Area (ft²) | L2: Volume (ft³) | M2: Multipliers | N2: People | O2: People (persons/1,000 ft²) | P2: Notes | S2: Spaces and Zoning layout
A3: ApartmentMidRise | B3: F1 BUSINESS CENTER | C3: Convention, Conference, Multipurpose and Meeting Area | D3: NR | E3: ResidentialCommon | F3: NA | G3: NA | H3: AHU1 | I3: Y | J3: =K3*M3/$K$40 -> 0.002553226 | K3: 360.04 | L3: 3600.53 | M3: 1 | N3: =O3*K3*M3/1000 -> 24.003867 | O3: 66.67 | P3: Dwellings: occupants/unit — ACM 2025 §6.5.4 Max(Nbr+1, 2) Parking garage: 0 (unoccupied for internal loads; App 5.4A 5/1000 not used) Other nonresidential: persons/1,000 ft² — App 5.4A / Table 120.1-A
A4: ApartmentMidRise | B4: F1 CORRIDOR | C4: Corridor Area | D4: NR | E4: ResidentialCommon | F4: NA | G4: NA | H4: AHU2 | I4: Y | J4: =K4*M4/$K$40 -> 0.01361704 | K4: 1920.19 | L4: 19202.81 | M4: 1 | N4: =O4*K4*M4/1000 -> 19.2019 | O4: 10
A5: ApartmentMidRise | B5: F1 FITNESS CENTER | C5: Exercise/Fitness Center and Gymnasium Areas | D5: NR | E5: ResidentialCommon | F5: NA | G5: NA | H5: AHU3 | I5: Y | J5: =K5*M5/$K$40 -> 0.0063829941 | K5: 900.09 | L5: 9001.32 | M5: 1 | N5: =O5*K5*M5/1000 -> 18.0018 | O5: 20
A6: ApartmentMidRise | B6: F1 LEASING OFFICE | C6: Office Area (>250 square feet) | D6: NR | E6: ResidentialCommon | F6: NA | G6: NA | H6: AHU4 | I6: Y | J6: =K6*M6/$K$40 -> 0.0024467825 | K6: 345.03 | L6: 3450.51 | M6: 1 | N6: =O6*K6*M6/1000 -> 3.4503 | O6: 10
A7: ApartmentMidRise | B7: F1 LOUNGE | C7: Lobby, Main Entry | D7: NR | E7: ResidentialCommon | F7: NA | G7: NA | H7: AHU5 | I7: Y | J7: =K7*M7/$K$40 -> 0.007446791 | K7: 1050.1 | L7: 10501.54 | M7: 1 | N7: =O7*K7*M7/1000 -> 70.04167 | O7: 66.7
A8: ApartmentMidRise | B8: F1 MECHANICAL ROOM | C8: Electrical, Mechanical, Telephone Rooms | D8: NR | E8: Ancillary | F8: NA | G8: NA | H8: AHU6 | I8: Y | J8: =K8*M8/$K$40 -> 0.0030638145 | K8: 432.04 | L8: 4320.63 | M8: 1 | N8: =O8*K8*M8/1000 -> 1.29612 | O8: 3
A9: ApartmentMidRise | B9: F1 RETAIL N-NW | C9: Retail Sales Area (Retail Merchandise Sales) | D9: NR | E9: Retail | F9: NA | G9: NA | H9: AHU7 | I9: Y | J9: =K9*M9/$K$40 -> 0.04244678 | K9: 5985.58 | L9: 59858.76 | M9: 1 | N9: =O9*K9*M9/1000 -> 99.759667 | O9: 16.666667
A10: ApartmentMidRise | B10: F1 RETAIL NE | C10: Retail Sales Area (Retail Merchandise Sales) | D10: NR | E10: Retail | F10: NA | G10: NA | H10: AHU8 | I10: Y | J10: =K10*M10/$K$40 -> 0.030638287 | K10: 4320.42 | L10: 43206.32 | M10: 1 | N10: =O10*K10*M10/1000 -> 72.007 | O10: 16.666667
A11: ApartmentMidRise | B11: F1 RETAIL SE | C11: Retail Sales Area (Retail Merchandise Sales) | D11: NR | E11: Retail | F11: NA | G11: NA | H11: AHU9 | I11: Y | J11: =K11*M11/$K$40 -> 0.020425524 | K11: 2880.28 | L11: 28804.22 | M11: 1 | N11: =O11*K11*M11/1000 -> 48.004667 | O11: 16.666667
A12: ApartmentMidRise | B12: F1 RETAIL SW | C12: Retail Sales Area (Retail Merchandise Sales) | D12: NR | E12: Retail | F12: NA | G12: NA | H12: AHU10 | I12: Y | J12: =K12*M12/$K$40 -> 0.03140424 | K12: 4428.43 | L12: 44286.48 | M12: 1 | N12: =O12*K12*M12/1000 -> 73.807167 | O12: 16.666667
A13: ApartmentMidRise | B13: F2-4 1-BED CORE EAST | C13: Residential Living Spaces | D13: Res | E13: ResidentialLiving | F13: 6 | G13: 1-Bed Type | H13: AHU11 | I13: Y | J13: =K13*M13/$K$40 -> 0.030638287 | K13: 1440.14 | L13: 14402.11 | M13: 3 | N13: =F13*O13 -> 12 | O13: =MAX(2,1+IF(ISNUMBER(SEARCH("Studio",G13)),0,IF(ISNUMBER(SEARCH("3-Bed",G13)),3,IF(ISNUMBER(SEARCH("2-Bed",G13)),2,1)))) -> 2
A14: ApartmentMidRise | B14: F2-4 1-BED CORE N | C14: Residential Living Spaces | D14: Res | E14: ResidentialLiving | F14: 3 | G14: 1-Bed Type | H14: AHU12 | I14: Y | J14: =K14*M14/$K$40 -> 0.015319143 | K14: 720.07 | L14: 7201.05 | M14: 3 | N14: =F14*O14 -> 6 | O14: =MAX(2,1+IF(ISNUMBER(SEARCH("Studio",G14)),0,IF(ISNUMBER(SEARCH("3-Bed",G14)),3,IF(ISNUMBER(SEARCH("2-Bed",G14)),2,1)))) -> 2
A15: ApartmentMidRise | B15: F2-4 1-BED CORE WEST | C15: Residential Living Spaces | D15: Res | E15: ResidentialLiving | F15: 6 | G15: 1-Bed Type | H15: AHU13 | I15: Y | J15: =K15*M15/$K$40 -> 0.030638287 | K15: 1440.14 | L15: 14402.11 | M15: 3 | N15: =F15*O15 -> 12 | O15: =MAX(2,1+IF(ISNUMBER(SEARCH("Studio",G15)),0,IF(ISNUMBER(SEARCH("3-Bed",G15)),3,IF(ISNUMBER(SEARCH("2-Bed",G15)),2,1)))) -> 2
A16: ApartmentMidRise | B16: F2-4 1-BED NORTH | C16: Residential Living Spaces | D16: Res | E16: ResidentialLiving | F16: 15 | G16: 1-Bed Type | H16: AHU14 | I16: Y | J16: =K16*M16/$K$40 -> 0.079148872 | K16: 3720.36 | L16: 37205.45 | M16: 3 | N16: =F16*O16 -> 30 | O16: =MAX(2,1+IF(ISNUMBER(SEARCH("Studio",G16)),0,IF(ISNUMBER(SEARCH("3-Bed",G16)),3,IF(ISNUMBER(SEARCH("2-Bed",G16)),2,1)))) -> 2
A17: ApartmentMidRise | B17: F2-4 2-BED CORE NE-NW | C17: Residential Living Spaces | D17: Res | E17: ResidentialLiving | F17: 6 | G17: 2-Bed Type | H17: AHU15 | I17: Y | J17: =K17*M17/$K$40 -> 0.04595743 | K17: 2160.21 | L17: 21603.16 | M17: 3 | N17: =F17*O17 -> 18 | O17: =MAX(2,1+IF(ISNUMBER(SEARCH("Studio",G17)),0,IF(ISNUMBER(SEARCH("3-Bed",G17)),3,IF(ISNUMBER(SEARCH("2-Bed",G17)),2,1)))) -> 3
A18: ApartmentMidRise | B18: F2-4 2-BED EAST | C18: Residential Living Spaces | D18: Res | E18: ResidentialLiving | F18: 9 | G18: 2-Bed Type | H18: AHU16 | I18: Y | J18: =K18*M18/$K$40 -> 0.068936251 | K18: 3240.32 | L18: 32404.74 | M18: 3 | N18: =F18*O18 -> 27 | O18: =MAX(2,1+IF(ISNUMBER(SEARCH("Studio",G18)),0,IF(ISNUMBER(SEARCH("3-Bed",G18)),3,IF(ISNUMBER(SEARCH("2-Bed",G18)),2,1)))) -> 3
A19: ApartmentMidRise | B19: F2-4 2-BED WEST | C19: Residential Living Spaces | D19: Res | E19: ResidentialLiving | F19: 9 | G19: 2-Bed Type | H19: AHU17 | I19: Y | J19: =K19*M19/$K$40 -> 0.068936251 | K19: 3240.32 | L19: 32404.74 | M19: 3 | N19: =F19*O19 -> 27 | O19: =MAX(2,1+IF(ISNUMBER(SEARCH("Studio",G19)),0,IF(ISNUMBER(SEARCH("3-Bed",G19)),3,IF(ISNUMBER(SEARCH("2-Bed",G19)),2,1)))) -> 3
A20: ApartmentMidRise | B20: F2-4 3-BED NE | C20: Residential Living Spaces | D20: Res | E20: ResidentialLiving | F20: 3 | G20: 3-Bed Type | H20: AHU18 | I20: Y | J20: =K20*M20/$K$40 -> 0.030000051 | K20: 1410.14 | L20: 14102.06 | M20: 3 | N20: =F20*O20 -> 12 | O20: =MAX(2,1+IF(ISNUMBER(SEARCH("Studio",G20)),0,IF(ISNUMBER(SEARCH("3-Bed",G20)),3,IF(ISNUMBER(SEARCH("2-Bed",G20)),2,1)))) -> 4
A21: ApartmentMidRise | B21: F2-4 3-BED NW | C21: Residential Living Spaces | D21: Res | E21: ResidentialLiving | F21: 3 | G21: 3-Bed Type | H21: AHU19 | I21: Y | J21: =K21*M21/$K$40 -> 0.030000051 | K21: 1410.14 | L21: 14102.06 | M21: 3 | N21: =F21*O21 -> 12 | O21: =MAX(2,1+IF(ISNUMBER(SEARCH("Studio",G21)),0,IF(ISNUMBER(SEARCH("3-Bed",G21)),3,IF(ISNUMBER(SEARCH("2-Bed",G21)),2,1)))) -> 4
A22: ApartmentMidRise | B22: F2-4 CORRIDOR | C22: Corridor Area | D22: NR | E22: ResidentialCommon | F22: NA | G22: NA | H22: AHU20 | I22: Y | J22: =K22*M22/$K$40 -> 0.054893579 | K22: 2580.25 | L22: 25803.78 | M22: 3 | N22: =O22*K22*M22/1000 -> 77.4075 | O22: 10
A23: ApartmentMidRise | B23: F2-4 LAUNDRY | C23: Laundry Area | D23: NR | E23: ResidentialCommon | F23: NA | G23: NA | H23: AHU21 | I23: Y | J23: =K23*M23/$K$40 -> 0.003829839 | K23: 180.02 | L23: 1800.26 | M23: 3 | N23: =O23*K23*M23/1000 -> 5.4006 | O23: 10
A24: ApartmentMidRise | B24: F2-4 STUDIO SE | C24: Residential Living Spaces | D24: Res | E24: ResidentialLiving | F24: 3 | G24: Studio Type | H24: AHU22 | I24: Y | J24: =K24*M24/$K$40 -> 0.011489304 | K24: 540.05 | L24: 5400.79 | M24: 3 | N24: =F24*O24 -> 6 | O24: =MAX(2,1+IF(ISNUMBER(SEARCH("Studio",G24)),0,IF(ISNUMBER(SEARCH("3-Bed",G24)),3,IF(ISNUMBER(SEARCH("2-Bed",G24)),2,1)))) -> 2
A25: ApartmentMidRise | B25: F2-4 STUDIO SW | C25: Residential Living Spaces | D25: Res | E25: ResidentialLiving | F25: 3 | G25: Studio Type | H25: AHU23 | I25: Y | J25: =K25*M25/$K$40 -> 0.011489304 | K25: 540.05 | L25: 5400.79 | M25: 3 | N25: =F25*O25 -> 6 | O25: =MAX(2,1+IF(ISNUMBER(SEARCH("Studio",G25)),0,IF(ISNUMBER(SEARCH("3-Bed",G25)),3,IF(ISNUMBER(SEARCH("2-Bed",G25)),2,1)))) -> 2
A26: ApartmentMidRise | B26: F5 1-BED CORE EAST | C26: Residential Living Spaces | D26: Res | E26: ResidentialLiving | F26: 2 | G26: 1-Bed Type | H26: AHU24 | I26: Y | J26: =K26*M26/$K$40 -> 0.010212762 | K26: 1440.14 | L26: 14402.11 | M26: 1 | N26: =F26*O26 -> 4 | O26: =MAX(2,1+IF(ISNUMBER(SEARCH("Studio",G26)),0,IF(ISNUMBER(SEARCH("3-Bed",G26)),3,IF(ISNUMBER(SEARCH("2-Bed",G26)),2,1)))) -> 2
A27: ApartmentMidRise | B27: F5 1-BED CORE N | C27: Residential Living Spaces | D27: Res | E27: ResidentialLiving | F27: 1 | G27: 1-Bed Type | H27: AHU25 | I27: Y | J27: =K27*M27/$K$40 -> 0.0051063811 | K27: 720.07 | L27: 7201.05 | M27: 1 | N27: =F27*O27 -> 2 | O27: =MAX(2,1+IF(ISNUMBER(SEARCH("Studio",G27)),0,IF(ISNUMBER(SEARCH("3-Bed",G27)),3,IF(ISNUMBER(SEARCH("2-Bed",G27)),2,1)))) -> 2
A28: ApartmentMidRise | B28: F5 1-BED CORE WEST | C28: Residential Living Spaces | D28: Res | E28: ResidentialLiving | F28: 2 | G28: 1-Bed Type | H28: AHU26 | I28: Y | J28: =K28*M28/$K$40 -> 0.010212762 | K28: 1440.14 | L28: 14402.11 | M28: 1 | N28: =F28*O28 -> 4 | O28: =MAX(2,1+IF(ISNUMBER(SEARCH("Studio",G28)),0,IF(ISNUMBER(SEARCH("3-Bed",G28)),3,IF(ISNUMBER(SEARCH("2-Bed",G28)),2,1)))) -> 2
A29: ApartmentMidRise | B29: F5 1-BED NORTH | C29: Residential Living Spaces | D29: Res | E29: ResidentialLiving | F29: 5 | G29: 1-Bed Type | H29: AHU27 | I29: Y | J29: =K29*M29/$K$40 -> 0.026382957 | K29: 3720.36 | L29: 37205.45 | M29: 1 | N29: =F29*O29 -> 10 | O29: =MAX(2,1+IF(ISNUMBER(SEARCH("Studio",G29)),0,IF(ISNUMBER(SEARCH("3-Bed",G29)),3,IF(ISNUMBER(SEARCH("2-Bed",G29)),2,1)))) -> 2
A30: ApartmentMidRise | B30: F5 2-BED CORE NE-NW | C30: Residential Living Spaces | D30: Res | E30: ResidentialLiving | F30: 2 | G30: 2-Bed Type | H30: AHU28 | I30: Y | J30: =K30*M30/$K$40 -> 0.015319143 | K30: 2160.21 | L30: 21603.16 | M30: 1 | N30: =F30*O30 -> 6 | O30: =MAX(2,1+IF(ISNUMBER(SEARCH("Studio",G30)),0,IF(ISNUMBER(SEARCH("3-Bed",G30)),3,IF(ISNUMBER(SEARCH("2-Bed",G30)),2,1)))) -> 3
A31: ApartmentMidRise | B31: F5 2-BED EAST | C31: Residential Living Spaces | D31: Res | E31: ResidentialLiving | F31: 3 | G31: 2-Bed Type | H31: AHU29 | I31: Y | J31: =K31*M31/$K$40 -> 0.02297875 | K31: 3240.32 | L31: 32404.74 | M31: 1 | N31: =F31*O31 -> 9 | O31: =MAX(2,1+IF(ISNUMBER(SEARCH("Studio",G31)),0,IF(ISNUMBER(SEARCH("3-Bed",G31)),3,IF(ISNUMBER(SEARCH("2-Bed",G31)),2,1)))) -> 3
A32: ApartmentMidRise | B32: F5 2-BED WEST | C32: Residential Living Spaces | D32: Res | E32: ResidentialLiving | F32: 3 | G32: 2-Bed Type | H32: AHU30 | I32: Y | J32: =K32*M32/$K$40 -> 0.02297875 | K32: 3240.32 | L32: 32404.74 | M32: 1 | N32: =F32*O32 -> 9 | O32: =MAX(2,1+IF(ISNUMBER(SEARCH("Studio",G32)),0,IF(ISNUMBER(SEARCH("3-Bed",G32)),3,IF(ISNUMBER(SEARCH("2-Bed",G32)),2,1)))) -> 3
A33: ApartmentMidRise | B33: F5 3-BED NE | C33: Residential Living Spaces | D33: Res | E33: ResidentialLiving | F33: 1 | G33: 3-Bed Type | H33: AHU31 | I33: Y | J33: =K33*M33/$K$40 -> 0.010000017 | K33: 1410.14 | L33: 14102.06 | M33: 1 | N33: =F33*O33 -> 4 | O33: =MAX(2,1+IF(ISNUMBER(SEARCH("Studio",G33)),0,IF(ISNUMBER(SEARCH("3-Bed",G33)),3,IF(ISNUMBER(SEARCH("2-Bed",G33)),2,1)))) -> 4
A34: ApartmentMidRise | B34: F5 3-BED NW | C34: Residential Living Spaces | D34: Res | E34: ResidentialLiving | F34: 1 | G34: 3-Bed Type | H34: AHU32 | I34: Y | J34: =K34*M34/$K$40 -> 0.010000017 | K34: 1410.14 | L34: 14102.06 | M34: 1 | N34: =F34*O34 -> 4 | O34: =MAX(2,1+IF(ISNUMBER(SEARCH("Studio",G34)),0,IF(ISNUMBER(SEARCH("3-Bed",G34)),3,IF(ISNUMBER(SEARCH("2-Bed",G34)),2,1)))) -> 4
A35: ApartmentMidRise | B35: F5 CORRIDOR | C35: Corridor Area | D35: NR | E35: ResidentialCommon | F35: NA | G35: NA | H35: AHU33 | I35: Y | J35: =K35*M35/$K$40 -> 0.01829786 | K35: 2580.25 | L35: 25803.78 | M35: 1 | N35: =O35*K35*M35/1000 -> 25.8025 | O35: 10
A36: ApartmentMidRise | B36: F5 LAUNDRY | C36: Laundry Area | D36: NR | E36: ResidentialCommon | F36: NA | G36: NA | H36: AHU34 | I36: Y | J36: =K36*M36/$K$40 -> 0.001276613 | K36: 180.02 | L36: 1800.26 | M36: 1 | N36: =O36*K36*M36/1000 -> 1.8002 | O36: 10
A37: ApartmentMidRise | B37: F5 STUDIO SE | C37: Residential Living Spaces | D37: Res | E37: ResidentialLiving | F37: 1 | G37: Studio Type | H37: AHU35 | I37: Y | J37: =K37*M37/$K$40 -> 0.0038297681 | K37: 540.05 | L37: 5400.79 | M37: 1 | N37: =F37*O37 -> 2 | O37: =MAX(2,1+IF(ISNUMBER(SEARCH("Studio",G37)),0,IF(ISNUMBER(SEARCH("3-Bed",G37)),3,IF(ISNUMBER(SEARCH("2-Bed",G37)),2,1)))) -> 2
A38: ApartmentMidRise | B38: F5 STUDIO SW | C38: Residential Living Spaces | D38: Res | E38: ResidentialLiving | F38: 1 | G38: Studio Type | H38: AHU36 | I38: Y | J38: =K38*M38/$K$40 -> 0.0038297681 | K38: 540.05 | L38: 5400.79 | M38: 1 | N38: =F38*O38 -> 2 | O38: =MAX(2,1+IF(ISNUMBER(SEARCH("Studio",G38)),0,IF(ISNUMBER(SEARCH("3-Bed",G38)),3,IF(ISNUMBER(SEARCH("2-Bed",G38)),2,1)))) -> 2
A39: ApartmentMidRise | B39: PARKING GARAGE | C39: Parking Garage Area (Parking Zone and Ramps) | D39: NR | E39: ResidentialCommon | F39: NA | G39: NA | H39: none | I39: N | J39: =K39*M39/$K$40 -> 0.19787232 | K39: 27902.72 | L39: 390657.19 | M39: 1 | N39: =O39*K39*M39/1000 -> 0 | O39: 0
A40: Total (1 Building) | B40: Total (37 Spaces) | C40: Total (11 Space Types) | F40: Total (88 Dwelling Units) | G40: Total (4 Dwelling Unit Types) | H40: Total (37 Thermal Zones) | I40: Total (36 Conditioned Zones, 1 Unconditioned Zones) | J40: =SUM(J3:J39) -> 1 | K40: =SUMPRODUCT(K3:K39,M3:M39) -> 141013.76 | L40: =SUM(L3:L39) -> 1069356.5 | N40: =SUM(N3:N39) -> 763.98496

Sheet Envelope
A1: ="Envelope - "&Prototype!A2 -> Envelope - ApartmentMidRise
A2: Element | B2: Prototype | C2: Assembly Type | D2: Construction | E2: Thermal Properties | F2: Vintage | G2: Selected T24 | H2: Notes | I2: CZ1 | J2: CZ2 | K2: CZ3 | L2: CZ4 | M2: CZ5 | N2: CZ6 | O2: CZ7 | P2: CZ8 | Q2: CZ9 | R2: CZ10 | S2: CZ11 | T2: CZ12 | U2: CZ13 | V2: CZ14 | W2: CZ15 | X2: CZ16
A3: External Wall (Floor 1) | B3: =Prototype!$A$2 -> ApartmentMidRise | C3: ExtWall_MassHeavy_Nonres | D3: Heavy mass wall: 8-in cast-in-place concrete wall + insulation + air/water barrier + exterior cladding + gypsum board Insulation only where the vintage U-factor requires | E3: U-factor IP | F3: Pre 1978 | G3: N/A | H3: Using: 1)ASHRAE 90.1‑2022, Table A3.1‑1: R‑0 wall (U = 0.74 for concrete); using U = 5.523 for stucco, U = 1.746 for gypsum board, and U=1.54 for Air - Metal Wall Framing 2) and a 7.7% cumulative wall renovation rate through 2028, based on the average annual rate from CBECS 2003 and 2012 projected over 48 years. | I3: =I60*(1-$I$62)+I61*$I$62 -> 0.35456895 | J3: =J60*(1-$I$62)+J61*$I$62 -> 0.3630422 | K3: =K60*(1-$I$62)+K61*$I$62 -> 0.3630422 | L3: =L60*(1-$I$62)+L61*$I$62 -> 0.3630422 | M3: =M60*(1-$I$62)+M61*$I$62 -> 0.3630422 | N3: =N60*(1-$I$62)+N61*$I$62 -> 0.3630422 | O3: =O60*(1-$I$62)+O61*$I$62 -> 0.3630422 | P3: =P60*(1-$I$62)+P61*$I$62 -> 0.3630422 | ... X3: =X60*(1-$I$62)+X61*$I$62 -> 0.34740795
F4: 1978-1997 | G4: 1992 | H4: Same as 1992. No direct regulation was found in 1986 for concrete walls. Also, T24, 1986, Table 2-53B and Equation 2-53E presents U-factors more than the previous vintage (for wall density of >81 lb/ft² & Degree day<3000). | I4: =MIN(0.36,I60) -> 0.36 | J4: =MIN(0.65,J60) -> 0.3630422 | K4: =MIN(0.65,K60) -> 0.3630422 | L4: =MIN(0.65,L60) -> 0.3630422 | M4: =MIN(0.65,M60) -> 0.3630422 | N4: =MIN(0.69,N60) -> 0.3630422 | O4: =MIN(0.69,O60) -> 0.3630422 | P4: =MIN(0.69,P60) -> 0.3630422 | Q4: =MIN(0.69,Q60) -> 0.3630422 | R4: =MIN(0.69,R60) -> 0.3630422 | S4: =MIN(0.69,S60) -> 0.3630422 | T4: =MIN(0.65,T60) -> 0.3630422 | U4: =MIN(0.65,U60) -> 0.3630422 | V4: =MIN(0.4,V60) -> 0.3630422 | W4: =MIN(0.4,W60) -> 0.3630422 | X4: =MIN(0.36,X60) -> 0.36
F5: 1998-2007 | G5: 2001 | H5: Table 1-H Mass HC≥15 (2001). CZ groups 1&16 / 3-5 / 6-9 / 2&10-13 / 14-15. | I5: =MIN(0.36,I60) -> 0.36 | J5: =MIN(0.65,J60) -> 0.3630422 | K5: =MIN(0.65,K60) -> 0.3630422 | L5: =MIN(0.65,L60) -> 0.3630422 | M5: =MIN(0.65,M60) -> 0.3630422 | N5: =MIN(0.69,N60) -> 0.3630422 | O5: =MIN(0.69,O60) -> 0.3630422 | P5: =MIN(0.69,P60) -> 0.3630422 | Q5: =MIN(0.69,Q60) -> 0.3630422 | R5: =MIN(0.65,R60) -> 0.3630422 | S5: =MIN(0.65,S60) -> 0.3630422 | T5: =MIN(0.65,T60) -> 0.3630422 | U5: =MIN(0.65,U60) -> 0.3630422 | V5: =MIN(0.4,V60) -> 0.3630422 | W5: =MIN(0.4,W60) -> 0.3630422 | X5: =MIN(0.36,X60) -> 0.36
F6: 2008-2018 | G6: 2013 | H6: Table 140.3-B Walls — Mass, Heavy (2013) | I6: =MIN(0.253,I60) -> 0.253 | J6: =MIN(0.65,J60) -> 0.3630422 | K6: =MIN(0.65,K60) -> 0.3630422 | L6: =MIN(0.65,L60) -> 0.3630422 | M6: =MIN(0.65,M60) -> 0.3630422 | N6: =MIN(0.69,N60) -> 0.3630422 | O6: =MIN(0.69,O60) -> 0.3630422 | P6: =MIN(0.69,P60) -> 0.3630422 | Q6: =MIN(0.69,Q60) -> 0.3630422 | R6: =MIN(0.65,R60) -> 0.3630422 | S6: =MIN(0.18,S60) -> 0.18 | T6: =MIN(0.25,T60) -> 0.25 | U6: =MIN(0.21,U60) -> 0.21 | V6: =MIN(0.18,V60) -> 0.18 | W6: =MIN(0.18,W60) -> 0.18 | X6: =MIN(0.16,X60) -> 0.16
F7: Existing | H7: Weighted average of all 4 vintages | I7: {=_xlfn.BYCOL(TRANSPOSE(Weights!$C$4:$F$19)*I3:X6,_xlfn.LAMBDA(_xlpm.c,SUM(_xlpm.c)))} -> 0 | J7: 0 | K7: 0 | L7: 0 | M7: 0 | N7: 0 | O7: 0 | P7: 0 | Q7: 0 | R7: 0 | S7: 0 | T7: 0 | U7: 0 | V7: 0 | W7: 0 | X7: 0
F8: 2019+ | G8: 2025 | H8: Table 140.3-B Walls - Mass, Heavy (2025) | I8: =MIN(0.211,I60) -> 0.211 | J8: =MIN(0.65,J60) -> 0.3630422 | K8: =MIN(0.65,K60) -> 0.3630422 | L8: =MIN(0.65,L60) -> 0.3630422 | M8: =MIN(0.65,M60) -> 0.3630422 | N8: =MIN(0.69,N60) -> 0.3630422 | O8: =MIN(0.69,O60) -> 0.3630422 | P8: =MIN(0.69,P60) -> 0.3630422 | Q8: =MIN(0.69,Q60) -> 0.3630422 | R8: =MIN(0.65,R60) -> 0.3630422 | S8: =MIN(0.16,S60) -> 0.16 | T8: =MIN(0.21,T60) -> 0.21 | U8: =MIN(0.18,U60) -> 0.18 | V8: =MIN(0.16,V60) -> 0.16 | W8: =MIN(0.16,W60) -> 0.16 | X8: =MIN(0.15,X60) -> 0.15
A9: External Wall (Floors 2-5) | B9: =Prototype!$A$2 -> ApartmentMidRise | C9: ExtWall_WoodFramed_Res | D9: Wood framed walls: Wood frame + insulation + Gypsum board | E9: U-factor IP | F9: Pre 1978 | G9: N/A | H9: Using ASHRAE 90.1, 2022 Table A3.4.3.1, 3.5", R-1.5 and a 7.7% cumulative wall renovation rate through 2028, based on the average annual rate from CBECS 2003 and 2012 projected over 48 years. | I9: =I65*(1-$I$66)+I64*$I$66 -> 0.190989 | J9: =J65*(1-$I$66)+J64*$I$66 -> 0.190989 | K9: =K65*(1-$I$66)+K64*$I$66 -> 0.190989 | L9: =L65*(1-$I$66)+L64*$I$66 -> 0.190989 | M9: =M65*(1-$I$66)+M64*$I$66 -> 0.190989 | N9: =N65*(1-$I$66)+N64*$I$66 -> 0.190989 | O9: =O65*(1-$I$66)+O64*$I$66 -> 0.190989 | P9: =P65*(1-$I$66)+P64*$I$66 -> 0.190989 | ... X9: =X65*(1-$I$66)+X64*$I$66 -> 0.18968
F10: 1978-1997 | G10: 1986 | H10: Title 24 1986 Table 2-53 BB, wall density less than 25 | I10: 0.095 | J10: 0.095 | K10: 0.095 | L10: 0.095 | M10: 0.095 | N10: 0.095 | O10: 0.095 | P10: 0.095 | Q10: 0.095 | R10: 0.095 | S10: 0.095 | T10: 0.095 | U10: 0.095 | V10: 0.095 | W10: 0.095 | X10: 0.095
F11: 1998-2007 | G11: 2001 | H11: TABLE 1-I wood frame (2001 high-rise residential). CZ1 and CZ16 = 0.063. | I11: 0.063 | J11: 0.084 | K11: 0.092 | L11: 0.092 | M11: 0.092 | N11: 0.092 | O11: 0.092 | P11: 0.092 | Q11: 0.092 | R11: 0.084 | S11: 0.084 | T11: 0.084 | U11: 0.084 | V11: 0.084 | W11: 0.084 | X11: 0.063
F12: 2008-2018 | G12: 2013 | H12: TABLE 140.3-C Wood-framed and Other (2013 high-rise residential). Not 140.3-B and not Mass, Heavy (F2-5 construction is wood). | I12: 0.059 | J12: 0.059 | K12: 0.059 | L12: 0.059 | M12: 0.059 | N12: 0.059 | O12: 0.059 | P12: 0.059 | Q12: 0.059 | R12: 0.059 | S12: 0.042 | T12: 0.059 | U12: 0.059 | V12: 0.042 | W12: 0.042 | X12: 0.042
F13: Existing | H13: Weighted average of all 4 vintages | I13: {=_xlfn.BYCOL(TRANSPOSE(Weights!$C$4:$F$19)*I9:X12,_xlfn.LAMBDA(_xlpm.c,SUM(_xlpm.c)))} -> 0 | J13: 0 | K13: 0 | L13: 0 | M13: 0 | N13: 0 | O13: 0 | P13: 0 | Q13: 0 | R13: 0 | S13: 0 | T13: 0 | U13: 0 | V13: 0 | W13: 0 | X13: 0
F14: 2019+ | G14: 2025 | H14: TABLE 170.2-A framed (wood, metal) and other — >1-hr fire rating | I14: 0.059 | J14: 0.059 | K14: 0.059 | L14: 0.059 | M14: 0.059 | N14: 0.065 | O14: 0.065 | P14: 0.059 | Q14: 0.059 | R14: 0.059 | S14: 0.051 | T14: 0.059 | U14: 0.059 | V14: 0.051 | W14: 0.051 | X14: 0.051
A15: Roof | B15: =Prototype!$A$2 -> ApartmentMidRise | C15: FlatRoof_WoodFramedAndOther_Res | D15: wood deck roof: Roof membrane or shingles + roof insulation + wood decking/sheathing + wood framing | E15: U-factor IP | F15: Pre 1978 | G15: N/A | H15: Considering 30 years for roof/ insulation replacement. | I15: 0.037 | J15: 0.051 | K15: 0.051 | L15: 0.051 | M15: 0.051 | N15: 0.051 | O15: 0.051 | P15: 0.051 | Q15: 0.051 | R15: 0.051 | S15: 0.037 | T15: 0.037 | U15: 0.037 | V15: 0.037 | W15: 0.037 | X15: 0.037
F16: 1978-1997 | G16: N/A | I16: 0.037 | J16: 0.051 | K16: 0.051 | L16: 0.051 | M16: 0.051 | N16: 0.051 | O16: 0.051 | P16: 0.051 | Q16: 0.051 | R16: 0.051 | S16: 0.037 | T16: 0.037 | U16: 0.037 | V16: 0.037 | W16: 0.037 | X16: 0.037
F17: 1998-2007 | G17: 2001 | H17: TABLE 1-I | I17: 0.037 | J17: 0.037 | K17: 0.051 | L17: 0.051 | M17: 0.051 | N17: 0.051 | O17: 0.051 | P17: 0.051 | Q17: 0.051 | R17: 0.037 | S17: 0.037 | T17: 0.037 | U17: 0.037 | V17: 0.037 | W17: 0.037 | X17: 0.037
F18: 2008-2018 | G18: 2013 | H18: TABLE 140.3-C | I18: 0.034 | J18: 0.028 | K18: 0.039 | L18: 0.028 | M18: 0.039 | N18: 0.039 | O18: 0.039 | P18: 0.028 | Q18: 0.028 | R18: 0.028 | S18: 0.028 | T18: 0.028 | U18: 0.028 | V18: 0.028 | W18: 0.028 | X18: 0.028
F19: Existing | H19: Weighted average of all 4 vintages | I19: {=_xlfn.BYCOL(TRANSPOSE(Weights!$C$4:$F$19)*I15:X18,_xlfn.LAMBDA(_xlpm.c,SUM(_xlpm.c)))} -> 0 | J19: 0 | K19: 0 | L19: 0 | M19: 0 | N19: 0 | O19: 0 | P19: 0 | Q19: 0 | R19: 0 | S19: 0 | T19: 0 | U19: 0 | V19: 0 | W19: 0 | X19: 0
F20: 2019+ | G20: 2025 | H20: TABLE 170.2-A ENVELOPE COMPONENT PACKAGE – Multifamily Standard Building Design | I20: 0.028 | J20: 0.028 | K20: 0.034 | L20: 0.028 | M20: 0.034 | N20: 0.034 | O20: 0.039 | P20: 0.028 | Q20: 0.028 | R20: 0.028 | S20: 0.028 | T20: 0.028 | U20: 0.028 | V20: 0.028 | W20: 0.028 | X20: 0.028
A21: Windows_Dwelling Units (Floors 2-5) | B21: =Prototype!$A$2 -> ApartmentMidRise | C21: FixedAndOperableWindow_Res | D21: 100% single pane for Pre-1978 and 1978-1997 (as-built). Title 24 fenestration U/SHGC starts at 1998-2007 (2001 Tables 1-H / 1-I). | E21: U factor | F21: Pre 1978 | G21: N/A | H21: ASHRAE Handbook of Fundamentals Ch. 15 Table 4: U 1.12 (fixed metal) / 1.23 (operable). Weighted with Envelope $C$56 operable fraction. No 2013 double-pane blend. | I21: =(1-$C$74)*1.12+$C$74*1.23 -> 1.1475 | J21: =(1-$C$74)*1.12+$C$74*1.23 -> 1.1475 | K21: =(1-$C$74)*1.12+$C$74*1.23 -> 1.1475 | L21: =(1-$C$74)*1.12+$C$74*1.23 -> 1.1475 | M21: =(1-$C$74)*1.12+$C$74*1.23 -> 1.1475 | N21: =(1-$C$74)*1.12+$C$74*1.23 -> 1.1475 | O21: =(1-$C$74)*1.12+$C$74*1.23 -> 1.1475 | P21: =(1-$C$74)*1.12+$C$74*1.23 -> 1.1475 | ... X21: =(1-$C$74)*1.12+$C$74*1.23 -> 1.1475
F22: 1978-1997 | G22: N/A | I22: =(1-$C$74)*1.12+$C$74*1.23 -> 1.1475 | J22: =(1-$C$74)*1.12+$C$74*1.23 -> 1.1475 | K22: =(1-$C$74)*1.12+$C$74*1.23 -> 1.1475 | L22: =(1-$C$74)*1.12+$C$74*1.23 -> 1.1475 | M22: =(1-$C$74)*1.12+$C$74*1.23 -> 1.1475 | N22: =(1-$C$74)*1.12+$C$74*1.23 -> 1.1475 | O22: =(1-$C$74)*1.12+$C$74*1.23 -> 1.1475 | P22: =(1-$C$74)*1.12+$C$74*1.23 -> 1.1475 | ... X22: =(1-$C$74)*1.12+$C$74*1.23 -> 1.1475
D23: Double pane | F23: 1998-2007 | G23: 2001 | H23: Table 1-I | I23: =(1-$C$74)*J93+$C$74*J113 -> 0.49 | J23: =(1-$C$74)*K93+$C$74*K113 -> 0.49 | K23: =(1-$C$74)*L93+$C$74*L113 -> 0.49 | L23: =(1-$C$74)*M93+$C$74*M113 -> 0.49 | M23: =(1-$C$74)*N93+$C$74*N113 -> 0.49 | N23: =(1-$C$74)*O93+$C$74*O113 -> 0.49 | O23: =(1-$C$74)*P93+$C$74*P113 -> 0.49 | P23: =(1-$C$74)*Q93+$C$74*Q113 -> 0.49 | ... X23: =(1-$C$74)*Y93+$C$74*Y113 -> 0.49
F24: 2008-2018 | G24: 2013 | H24: Table 140.3-C | I24: =(1-$C$74)*J94+$C$74*J114 -> 0.385 | J24: =(1-$C$74)*K94+$C$74*K114 -> 0.385 | K24: =(1-$C$74)*L94+$C$74*L114 -> 0.385 | L24: =(1-$C$74)*M94+$C$74*M114 -> 0.385 | M24: =(1-$C$74)*N94+$C$74*N114 -> 0.385 | N24: =(1-$C$74)*O94+$C$74*O114 -> 0.385 | O24: =(1-$C$74)*P94+$C$74*P114 -> 0.385 | P24: =(1-$C$74)*Q94+$C$74*Q114 -> 0.385 | ... X24: =(1-$C$74)*Y94+$C$74*Y114 -> 0.385
F25: Existing | H25: Weighted average of all 4 vintages | I25: {=_xlfn.BYCOL(TRANSPOSE(Weights!$C$4:$F$19)*I21:X24,_xlfn.LAMBDA(_xlpm.c,SUM(_xlpm.c)))} -> 0 | J25: 0 | K25: 0 | L25: 0 | M25: 0 | N25: 0 | O25: 0 | P25: 0 | Q25: 0 | R25: 0 | S25: 0 | T25: 0 | U25: 0 | V25: 0 | W25: 0 | X25: 0
F26: 2019+ | G26: 2025 | H26: TABLE 170.2-A All Other Fenestration (not fixed/operable blend) | I26: 0.28 | J26: 0.3 | K26: 0.28 | L26: 0.28 | M26: 0.28 | N26: 0.34 | O26: 0.34 | P26: 0.3 | Q26: 0.3 | R26: 0.3 | S26: 0.28 | T26: 0.3 | U26: 0.28 | V26: 0.28 | W26: 0.28 | X26: 0.28
D27: 100% single pane for Pre-1978 and 1978-1997 (as-built). Title 24 fenestration U/SHGC starts at 1998-2007 (2001 Tables 1-H / 1-I). | E27: SHGC | F27: Pre 1978 | G27: N/A | H27: ASHRAE Handbook of Fundamentals Ch. 15 Table 10: SHGC 0.79 (fixed) / 0.78 (operable). Weighted with Envelope $C$56. No 2013 double-pane blend. | I27: =(1-$C$74)*0.79+$C$74*0.78 -> 0.7875 | J27: =(1-$C$74)*0.79+$C$74*0.78 -> 0.7875 | K27: =(1-$C$74)*0.79+$C$74*0.78 -> 0.7875 | L27: =(1-$C$74)*0.79+$C$74*0.78 -> 0.7875 | M27: =(1-$C$74)*0.79+$C$74*0.78 -> 0.7875 | N27: =(1-$C$74)*0.79+$C$74*0.78 -> 0.7875 | O27: =(1-$C$74)*0.79+$C$74*0.78 -> 0.7875 | P27: =(1-$C$74)*0.79+$C$74*0.78 -> 0.7875 | ... X27: =(1-$C$74)*0.79+$C$74*0.78 -> 0.7875
F28: 1978-1997 | G28: N/A | I28: =(1-$C$74)*0.79+$C$74*0.78 -> 0.7875 | J28: =(1-$C$74)*0.79+$C$74*0.78 -> 0.7875 | K28: =(1-$C$74)*0.79+$C$74*0.78 -> 0.7875 | L28: =(1-$C$74)*0.79+$C$74*0.78 -> 0.7875 | M28: =(1-$C$74)*0.79+$C$74*0.78 -> 0.7875 | N28: =(1-$C$74)*0.79+$C$74*0.78 -> 0.7875 | O28: =(1-$C$74)*0.79+$C$74*0.78 -> 0.7875 | P28: =(1-$C$74)*0.79+$C$74*0.78 -> 0.7875 | ... X28: =(1-$C$74)*0.79+$C$74*0.78 -> 0.7875
D29: Double pane | F29: 1998-2007 | G29: 2001 | H29: TABLE 1-I 21-30% WWR (prototype 22%). Non-north row 116; CZ1 uses north (row 117) per Table 1-I note. | I29: =J135 -> 0.36 | J29: =K134 -> 0.4 | K29: =L134 -> 0.61 | L29: =M134 -> 0.61 | M29: =N134 -> 0.61 | N29: =O134 -> 0.61 | O29: =P134 -> 0.61 | P29: =Q134 -> 0.61 | Q29: =R134 -> 0.61 | ... X29: =Y134 -> 0.47
F30: 2008-2018 | G30: 2013 | H30: Table 140.3-C | I30: =(1-$C$74)*J99+$C$74*J119 -> 0.2425 | J30: =(1-$C$74)*K99+$C$74*K119 -> 0.2425 | K30: =(1-$C$74)*L99+$C$74*L119 -> 0.2425 | L30: =(1-$C$74)*M99+$C$74*M119 -> 0.2425 | M30: =(1-$C$74)*N99+$C$74*N119 -> 0.2425 | N30: =(1-$C$74)*O99+$C$74*O119 -> 0.2425 | O30: =(1-$C$74)*P99+$C$74*P119 -> 0.2425 | P30: =(1-$C$74)*Q99+$C$74*Q119 -> 0.2425 | ... X30: =(1-$C$74)*Y99+$C$74*Y119 -> 0.2425
F31: Existing | H31: Weighted average of all 4 vintages | I31: {=_xlfn.BYCOL(TRANSPOSE(Weights!$C$4:$F$19)*I27:X30,_xlfn.LAMBDA(_xlpm.c,SUM(_xlpm.c)))} -> 0 | J31: 0 | K31: 0 | L31: 0 | M31: 0 | N31: 0 | O31: 0 | P31: 0 | Q31: 0 | R31: 0 | S31: 0 | T31: 0 | U31: 0 | V31: 0 | W31: 0 | X31: 0
F32: 2019+ | G32: 2025 | H32: TABLE 170.2-A All Other Fenestration RSHGC (NR in CZ1, 3, 5, 16), for those excluded climate zones, an SHGC of 0.6 was assumed (greater than other CZs) | I32: 0.6 | J32: 0.23 | K32: 0.6 | L32: 0.23 | M32: 0.6 | N32: 0.23 | O32: 0.23 | P32: 0.23 | Q32: 0.23 | R32: 0.23 | S32: 0.23 | T32: 0.23 | U32: 0.23 | V32: 0.23 | W32: 0.23 | X32: 0.6
A33: Windows_Nonres (Floor 1) | B33: =Prototype!$A$2 -> ApartmentMidRise | C33: FixedWindow_NonRes | D33: 100% single pane for Pre-1978 and 1978-1997 (as-built). Title 24 fenestration U/SHGC starts at 1998-2007 (2001 Tables 1-H / 1-I). | E33: U factor | F33: Pre 1978 | G33: N/A | H33: ASHRAE Handbook of Fundamentals Ch. 15 Table 4: U-1.12 (100% fixed metal, Nonres). No 2013 double-pane blend. | I33: 1.12 | J33: 1.12 | K33: 1.12 | L33: 1.12 | M33: 1.12 | N33: 1.12 | O33: 1.12 | P33: 1.12 | Q33: 1.12 | R33: 1.12 | S33: 1.12 | T33: 1.12 | U33: 1.12 | V33: 1.12 | W33: 1.12 | X33: 1.12
F34: 1978-1997 | G34: N/A | I34: 1.12 | J34: 1.12 | K34: 1.12 | L34: 1.12 | M34: 1.12 | N34: 1.12 | O34: 1.12 | P34: 1.12 | Q34: 1.12 | R34: 1.12 | S34: 1.12 | T34: 1.12 | U34: 1.12 | V34: 1.12 | W34: 1.12 | X34: 1.12
D35: Double pane | F35: 1998-2007 | G35: 2001 | H35: Table 1-H window U-factor (2001). CZ3-9 = 0.81; other CZs = 0.49. Values from Envelope row 85. | I35: =J103 -> 0.49 | J35: =K103 -> 0.49 | K35: =L103 -> 0.81 | L35: =M103 -> 0.81 | M35: =N103 -> 0.81 | N35: =O103 -> 0.81 | O35: =P103 -> 0.81 | P35: =Q103 -> 0.81 | ... X35: =Y103 -> 0.49
F36: 2008-2018 | G36: 2013 | H36: Table 140.3-B | I36: =J104 -> 0.36 | J36: =K104 -> 0.36 | K36: =L104 -> 0.36 | L36: =M104 -> 0.36 | M36: =N104 -> 0.36 | N36: =O104 -> 0.36 | O36: =P104 -> 0.36 | P36: =Q104 -> 0.36 | ... X36: =Y104 -> 0.36
F37: Existing | H37: Weighted average of all 4 vintages | I37: {=_xlfn.BYCOL(TRANSPOSE(Weights!$C$4:$F$19)*I33:X36,_xlfn.LAMBDA(_xlpm.c,SUM(_xlpm.c)))} -> 0 | J37: 0 | K37: 0 | L37: 0 | M37: 0 | N37: 0 | O37: 0 | P37: 0 | Q37: 0 | R37: 0 | S37: 0 | T37: 0 | U37: 0 | V37: 0 | W37: 0 | X37: 0
F38: 2019+ | G38: 2025 | H38: Table 140.3-B | I38: =J105 -> 0.36 | J38: =K105 -> 0.36 | K38: =L105 -> 0.36 | L38: =M105 -> 0.36 | M38: =N105 -> 0.36 | N38: =O105 -> 0.36 | O38: =P105 -> 0.36 | P38: =Q105 -> 0.36 | ... X38: =Y105 -> 0.36
D39: 100% single pane for Pre-1978 and 1978-1997 (as-built). Title 24 fenestration U/SHGC starts at 1998-2007 (2001 Tables 1-H / 1-I). | E39: SHGC | F39: Pre 1978 | G39: N/A | H39: ASHRAE Handbook of Fundamentals Ch. 15 Table 10: SHGC 0.79 (100% fixed, Nonres). No 2013 double-pane blend. | I39: 0.79 | J39: 0.79 | K39: 0.79 | L39: 0.79 | M39: 0.79 | N39: 0.79 | O39: 0.79 | P39: 0.79 | Q39: 0.79 | R39: 0.79 | S39: 0.79 | T39: 0.79 | U39: 0.79 | V39: 0.79 | W39: 0.79 | X39: 0.79
F40: 1978-1997 | G40: N/A | I40: 0.79 | J40: 0.79 | K40: 0.79 | L40: 0.79 | M40: 0.79 | N40: 0.79 | O40: 0.79 | P40: 0.79 | Q40: 0.79 | R40: 0.79 | S40: 0.79 | T40: 0.79 | U40: 0.79 | V40: 0.79 | W40: 0.79 | X40: 0.79
...

Sheet HVAC System
A1: ="HVAC system - "&Prototype!A2 -> HVAC system - ApartmentMidRise
A2: Vintage | B2: Space Type | C2: Heating | D2: Cooling | E2: Air Distribution | F2: Source
A3: Existing | B3: Residential Tenant and common | C3: SZAC (Furnace) | D3: SZAC (DX) | E3: CAV | F3: ResStock 2022 & T24 (2008, 2013)
B4: Non-Residential Tenant (Retail) | C4: PVAV (Gas Boiler & hot water reheat) | D4: PVAV (DX) | E4: VAV | F4: ResStock 2022 & T24 (2008, 2013)
A5: New Construction | B5: Residential Tenant and common | C5: SZHP (DX) | D5: SZHP (DX) | E5: CAV | F5: T24 2025 | G5: ACM 2025 Table 26: dwelling units (>3 habitable floors) SZHP CAV, no economizer; CZ2-15 electric-resistance supplemental heat; CZ1/16 gas furnace supplemental. Common areas are a separate Table 26 row (economizer language differs). Tenant vs common not split into two HVAC rows this pass.
B6: Non-Residential Tenant (Retail) | C6: PVAV (Gas Boiler & hot water reheat) | D6: PVAV (DX) | E6: VAV
A7: *Based on NR ACM 2025 - Table 26
A10: Efficiency of HVAC system (Efficiency is capacity-dependent. The following table provides a general estimate of system efficiency based on preliminary simulations in one climate zone, or assuming cooling load based on rule of thumb)
A11: Vintage | B11: Upgrade/Installed year | C11: Heating | D11: Cooling | E11: Source
A12: Pre 1978 | B12: 2008 | C12: Efficiency 80% (78% AFUE) | D12: EER=9 (<65,000 Btu/h) RES SEER: 13 | E12: T24, 2008 / 10 CFR Part 430, §430.32(c)(2)
A13: 1978-1997
A14: 1998-2007
A15: 2008-2018 | B15: 2013 | C15: Efficiency 80% (78% AFUE) | D15: EER=9 (<65,000 Btu/h) RES: SEER 13 (<65k) | E15: CFR Energy 2010:Title 10- Table 9
A16: New Construction | B16: 2025 | C16: RES: HSPF2:7.5 For SZHPDF: Furnace efficiency: 80% | D16: SEER2: 14.3 | E16: Title 20, 2023 Table E-6
C17: Non-Res: For ≥65k and <135k Btu/h: 11.0 EER and 14.1 IEER Heating (gas boiler) efficiency is not listed and was not invented. Retail NC system remains PVAV with gas boiler (row 6). | D17: 11.0 EER, 14.1 IEER Dual Fuel: 10.8 EER, 13.9 IEER | E17: Title 24, 2025 able 110.2 footnote a
A20: Fan power
A21: Vintage | B21: Approach | C21: System | D21: Total Static Pressure (TSP) (in w.c.) | E21: Fan Efficiency [ACM 2025] | F21: Motor Efficiency | G21: Fan Power Index (W/cfm) | H21: Data Source
A22: Existing | B22: PNNL 90.1-2011, TSP | C22: SZAC CAV, residential tenant and common | D22: 1.33 | E22: 0.65 | F22: ASHRAE 90.1, 2004, Table 10.8 * | H22: Fan power formula: PNNL 20405, 2010, section 5.2.2.5 TSP and fan efficiency: PNNL 20405, 2010, Table 5.11, 90.1-04ac values Motor and drive efficiency: ASHRAE 90.1, 2004, Table 10.8 | I22: PNNL 20405, 2010, Table 5.11
C23: VAV, retail supply fans | D23: 5.58
A24: Brake horsepower (bhp) = (Supply cfm × TSP in w.c.) / (6356 × fan efficiency)
A25: Fan power (w/cfm) = (bhp × 746) / ( supply cfm × motor efficiency )
A26: New Construction | B26: ACM 2025 | C26: SZHP, residential tenant and common — indoor-unit fan | D26: TSP = fan power × motor efficiency × fan efficiency × 6356 / 746 | E26: 0.65 | F26: 2025 ACM Table 12 ** | G26: 0.35 | H26: w/cfm: [T24, 2025, Section 140.4(a)3 D] Motor efficiency: [ACM 2025, Table 12]
C27: PVAV, retail (System 5), by supply cfm | D27: TSP = fan power × motor efficiency × fan efficiency × 6356 / 746 | G27: 0.978 <=5,000; 1.022 <=10,000; 0.964 >10,000 | H27: Fan power index: [ACM 2025, Table 13] Motor efficiency: [ACM 2025, Table 12]
A29: * According to PNNL 20405 section 5.2.2.5, the full-load efficiency of the motor serving the fan is taken from ASHRAE 90.1, 2004, Table 10.8, based on motor nameplate and assuming enclosed motors operating at 1,800 rotations per minute (rpm) Motor nameplate size (bhp) = brake horsepower (bhp) × 1.1 ( using a 10% oversizing factor)
A30: ** The full‑load efficiency of the motor serving the fan is taken from ACM 2025 Table 12 based on the motor nameplate horsepower. Brake horsepower (bhp) = (Supply cfm from sizing run × fan power in W/cfm) / 746. Note: 0.35 W/cfm is the indoor-unit fan (T24 2025 §140.4(a)3 D), same allowance as OfficeMedium VRF and Hotel Large four-pipe fan coil. Not an ACM Table 13 system index. Note: HVAC system is PVAV, not System 6. ACM System 5 >10,000 cfm = 0.964 (Hotel Small). >5,000–10,000 cfm = 1.022. At or below 5,000 cfm = 0.978.

Sheet Thermostat
A1: ="Thermostat Setpoints - "&Prototype!A2&": ResidentialLiving" -> Thermostat Setpoints - ApartmentMidRise : ResidentialLiving
A2: Setpoint | B2: CZ1 | C2: CZ2 | D2: CZ3 | E2: CZ4 | F2: CZ5 | G2: CZ6 | H2: CZ7 | I2: CZ8 | J2: CZ9 | K2: CZ10 | L2: CZ11 | M2: CZ12 | N2: CZ13 | O2: CZ14 | P2: CZ15 | Q2: CZ16 | R2: Source
A3: Heating Setpoint (F) | B3: 68 | C3: 68 | D3: 68 | E3: 68 | F3: 68 | G3: 68 | H3: 68 | I3: 68 | J3: 68 | K3: 68 | L3: 68 | M3: 68 | N3: 68 | O3: 68 | P3: 68 | Q3: 68 | R3: T24 2025 - Appendix 5.4B
A4: Heating Setback (F) | B4: 60 | C4: 60 | D4: 60 | E4: 60 | F4: 60 | G4: 60 | H4: 60 | I4: 60 | J4: 60 | K4: 60 | L4: 60 | M4: 60 | N4: 60 | O4: 60 | P4: 60 | Q4: 60
A5: Cooling Setpoint (F) | B5: 78 | C5: 78 | D5: 78 | E5: 78 | F5: 78 | G5: 78 | H5: 78 | I5: 78 | J5: 78 | K5: 78 | L5: 78 | M5: 78 | N5: 78 | O5: 78 | P5: 78 | Q5: 78 | R5: T24 2025 - Appendix 5.4B
A6: Cooling Setback (F) | B6: 78 | C6: 78 | D6: 78 | E6: 78 | F6: 78 | G6: 78 | H6: 78 | I6: 78 | J6: 78 | K6: 78 | L6: 78 | M6: 78 | N6: 78 | O6: 78 | P6: 78 | Q6: 78
A8: ="Thermostat Setpoints - "&Prototype!A2 & ":Retail" -> Thermostat Setpoints - ApartmentMidRise :Retail
A9: Setpoint | B9: CZ1 | C9: CZ2 | D9: CZ3 | E9: CZ4 | F9: CZ5 | G9: CZ6 | H9: CZ7 | I9: CZ8 | J9: CZ9 | K9: CZ10 | L9: CZ11 | M9: CZ12 | N9: CZ13 | O9: CZ14 | P9: CZ15 | Q9: CZ16 | R9: Source
A10: Heating Setpoint (F) | B10: 70 | C10: 70 | D10: 70 | E10: 70 | F10: 70 | G10: 70 | H10: 70 | I10: 70 | J10: 70 | K10: 70 | L10: 70 | M10: 70 | N10: 70 | O10: 70 | P10: 70 | Q10: 70 | R10: T24 2022 - Appendix 5.4B
A11: Heating Setback (F) | B11: 60 | C11: 60 | D11: 60 | E11: 60 | F11: 60 | G11: 60 | H11: 60 | I11: 60 | J11: 60 | K11: 60 | L11: 60 | M11: 60 | N11: 60 | O11: 60 | P11: 60 | Q11: 60
A12: Cooling Setpoint (F) | B12: 75 | C12: 75 | D12: 75 | E12: 75 | F12: 75 | G12: 75 | H12: 75 | I12: 75 | J12: 75 | K12: 75 | L12: 75 | M12: 75 | N12: 75 | O12: 75 | P12: 75 | Q12: 75
A13: Cooling Setback (F) | B13: 85 | C13: 85 | D13: 85 | E13: 85 | F13: 85 | G13: 85 | H13: 85 | I13: 85 | J13: 85 | K13: 85 | L13: 85 | M13: 85 | N13: 85 | O13: 85 | P13: 85 | Q13: 85
A14: ="Thermostat Setpoints - "&Prototype!A2&": ResidentialCommon" -> Thermostat Setpoints - ApartmentMidRise : ResidentialCommon
A15: Heating Setpoint (F) | B15: 68 | C15: 68 | D15: 68 | E15: 68 | F15: 68 | G15: 68 | H15: 68 | I15: 68 | J15: 68 | K15: 68 | L15: 68 | M15: 68 | N15: 68 | O15: 68 | P15: 68 | Q15: 68 | R15: T24 2025 Appendix 5.4B ResidentialCommon
A16: Heating Setback (F) | B16: 68 | C16: 68 | D16: 68 | E16: 68 | F16: 68 | G16: 68 | H16: 68 | I16: 68 | J16: 68 | K16: 68 | L16: 68 | M16: 68 | N16: 68 | O16: 68 | P16: 68 | Q16: 68
A17: Cooling Setpoint (F) | B17: 78 | C17: 78 | D17: 78 | E17: 78 | F17: 78 | G17: 78 | H17: 78 | I17: 78 | J17: 78 | K17: 78 | L17: 78 | M17: 78 | N17: 78 | O17: 78 | P17: 78 | Q17: 78
A18: Cooling Setback (F) | B18: 78 | C18: 78 | D18: 78 | E18: 78 | F18: 78 | G18: 78 | H18: 78 | I18: 78 | J18: 78 | K18: 78 | L18: 78 | M18: 78 | N18: 78 | O18: 78 | P18: 78 | Q18: 78
A19: Thermostat Setpoints: Ancillary
A20: Heating Setpoint (F) | B20: 60 | C20: 60 | D20: 60 | E20: 60 | F20: 60 | G20: 60 | H20: 60 | I20: 60 | J20: 60 | K20: 60 | L20: 60 | M20: 60 | N20: 60 | O20: 60 | P20: 60 | Q20: 60
A21: Heating Setback (F) | B21: 60 | C21: 60 | D21: 60 | E21: 60 | F21: 60 | G21: 60 | H21: 60 | I21: 60 | J21: 60 | K21: 60 | L21: 60 | M21: 60 | N21: 60 | O21: 60 | P21: 60 | Q21: 60
A22: Cooling Setpoint (F) | B22: 85 | C22: 85 | D22: 85 | E22: 85 | F22: 85 | G22: 85 | H22: 85 | I22: 85 | J22: 85 | K22: 85 | L22: 85 | M22: 85 | N22: 85 | O22: 85 | P22: 85 | Q22: 85
A23: Cooling Setback (F) | B23: 85 | C23: 85 | D23: 85 | E23: 85 | F23: 85 | G23: 85 | H23: 85 | I23: 85 | J23: 85 | K23: 85 | L23: 85 | M23: 85 | N23: 85 | O23: 85 | P23: 85 | Q23: 85
A26: One App 5.4B ResidentialLiving profile (68°F occupied / 60°F hours 1–6 and 23–24). ACM 2025 does not publish a multi-unit thermostat diversity set for this prototype. Stochastic or deep-setback mixes were not added.

Sheet Ventilation
A1: ="Outdoor Airflow Rate - "&Prototype!A2 -> Outdoor Airflow Rate - ApartmentMidRise
A2: Space Thermal Zone | B2: Number of People | C2: Floor Area (ft2) | D2: cfm/person (T24, 2025, Equation 120.1-F and Table 120.1-A) | E2: cfm (whole-dwelling continuous mechanical ventilation rate) Res: Equation 160.2-B | F2: cfm/ft² (T24, 2025, Equation 120.1-F and Table 120.1-A) | G2: Required Exhaust Rate-CFM/ft²- (T24, 2025, Table 120.1-B – Minimum Exhaust Rates) | H2: Total cfm Driven by People | I2: Total cfm Driven by Area | J2: Total cfm Driven by Exhaust | K2: Total cfm | L2: Note
A3: =Zones!B3 -> F1 BUSINESS CENTER | B3: =Zones!N3 -> 24.003867 | C3: =Zones!K3 -> 360.04 | D3: 15 | F3: 0.15 | H3: =B3*D3 -> 360.058 | I3: =C3*F3 -> 54.006 | K3: =MAX(H3:J3) -> 360.058
A4: =Zones!B4 -> F1 CORRIDOR | B4: =Zones!N4 -> 19.2019 | C4: =Zones!K4 -> 1920.19 | D4: 15 | F4: 0.15 | H4: =B4*D4 -> 288.0285 | I4: =C4*F4 -> 288.0285 | K4: =MAX(H4:J4) -> 288.0285
A5: =Zones!B5 -> F1 FITNESS CENTER | B5: =Zones!N5 -> 18.0018 | C5: =Zones!K5 -> 900.09 | D5: 15 | F5: 0.15 | H5: =B5*D5 -> 270.027 | I5: =C5*F5 -> 135.0135 | K5: =MAX(H5:J5) -> 270.027
A6: =Zones!B6 -> F1 LEASING OFFICE | B6: =Zones!N6 -> 3.4503 | C6: =Zones!K6 -> 345.03 | D6: 15 | F6: 0.15 | H6: =B6*D6 -> 51.7545 | I6: =C6*F6 -> 51.7545 | K6: =MAX(H6:J6) -> 51.7545
A7: =Zones!B7 -> F1 LOUNGE | B7: =Zones!N7 -> 70.04167 | C7: =Zones!K7 -> 1050.1 | D7: 15 | F7: 0.15 | H7: =B7*D7 -> 1050.625 | I7: =C7*F7 -> 157.515 | K7: =MAX(H7:J7) -> 1050.625
A8: =Zones!B8 -> F1 MECHANICAL ROOM | B8: =Zones!N8 -> 1.29612 | C8: =Zones!K8 -> 432.04 | D8: 15 | F8: 0.15 | H8: =B8*D8 -> 19.4418 | I8: =C8*F8 -> 64.806 | K8: =MAX(H8:J8) -> 64.806
A9: =Zones!B9 -> F1 RETAIL N-NW | B9: =Zones!N9 -> 99.759667 | C9: =Zones!K9 -> 5985.58 | D9: 15 | F9: 0.2 | H9: =B9*D9 -> 1496.395 | I9: =C9*F9 -> 1197.116 | K9: =MAX(H9:J9) -> 1496.395 | L9: Retail merchandise: Table 120.1-A / App 5.4C Retail-Sales Ra = 0.20 cfm/ft².
A10: =Zones!B10 -> F1 RETAIL NE | B10: =Zones!N10 -> 72.007 | C10: =Zones!K10 -> 4320.42 | D10: 15 | F10: 0.2 | H10: =B10*D10 -> 1080.105 | I10: =C10*F10 -> 864.084 | K10: =MAX(H10:J10) -> 1080.105
A11: =Zones!B11 -> F1 RETAIL SE | B11: =Zones!N11 -> 48.004667 | C11: =Zones!K11 -> 2880.28 | D11: 15 | F11: 0.2 | H11: =B11*D11 -> 720.07 | I11: =C11*F11 -> 576.056 | K11: =MAX(H11:J11) -> 720.07
A12: =Zones!B12 -> F1 RETAIL SW | B12: =Zones!N12 -> 73.807167 | C12: =Zones!K12 -> 4428.43 | D12: 15 | F12: 0.2 | H12: =B12*D12 -> 1107.1075 | I12: =C12*F12 -> 885.686 | K12: =MAX(H12:J12) -> 1107.1075
A13: =Zones!B13 -> F2-4 1-BED CORE EAST | B13: =Zones!N13 -> 12 | C13: =Zones!K13 -> 1440.14 | D13: NA | E13: =0.03*C13*Zones!M13+7.5*Zones!F13*(1+IF(ISNUMBER(SEARCH("Studio",Zones!G13)),0,IF(ISNUMBER(SEARCH("3-Bed",Zones!G13)),3,IF(ISNUMBER(SEARCH("2-Bed",Zones!G13)),2,1)))) -> 219.6126 | I13: =E13 -> 219.6126 | J13: =I13 -> 219.6126 | K13: =MAX(H13:J13) -> 219.6126 | L13: Eq 160.2-B: 0.03×CFA_total + 7.5×N_units×(N_br+1). Studio N_br=0. CFA_total = zone area × floor multiplier. Natural ventilation is not modeled (operable fraction Envelope C56 is fenestration weighting only).
A14: =Zones!B14 -> F2-4 1-BED CORE N | B14: =Zones!N14 -> 6 | C14: =Zones!K14 -> 720.07 | D14: NA | E14: =0.03*C14*Zones!M14+7.5*Zones!F14*(1+IF(ISNUMBER(SEARCH("Studio",Zones!G14)),0,IF(ISNUMBER(SEARCH("3-Bed",Zones!G14)),3,IF(ISNUMBER(SEARCH("2-Bed",Zones!G14)),2,1)))) -> 109.8063 | I14: =E14 -> 109.8063 | J14: =I14 -> 109.8063 | K14: =MAX(H14:J14) -> 109.8063 | L14: Balanced IAQ fan - only applies to new construction
A15: =Zones!B15 -> F2-4 1-BED CORE WEST | B15: =Zones!N15 -> 12 | C15: =Zones!K15 -> 1440.14 | D15: NA | E15: =0.03*C15*Zones!M15+7.5*Zones!F15*(1+IF(ISNUMBER(SEARCH("Studio",Zones!G15)),0,IF(ISNUMBER(SEARCH("3-Bed",Zones!G15)),3,IF(ISNUMBER(SEARCH("2-Bed",Zones!G15)),2,1)))) -> 219.6126 | I15: =E15 -> 219.6126 | J15: =I15 -> 219.6126 | K15: =MAX(H15:J15) -> 219.6126 | L15: Balanced IAQ fan - only applies to new construction
A16: =Zones!B16 -> F2-4 1-BED NORTH | B16: =Zones!N16 -> 30 | C16: =Zones!K16 -> 3720.36 | D16: NA | E16: =0.03*C16*Zones!M16+7.5*Zones!F16*(1+IF(ISNUMBER(SEARCH("Studio",Zones!G16)),0,IF(ISNUMBER(SEARCH("3-Bed",Zones!G16)),3,IF(ISNUMBER(SEARCH("2-Bed",Zones!G16)),2,1)))) -> 559.8324 | I16: =E16 -> 559.8324 | J16: =I16 -> 559.8324 | K16: =MAX(H16:J16) -> 559.8324 | L16: Balanced IAQ fan - only applies to new construction
A17: =Zones!B17 -> F2-4 2-BED CORE NE-NW | B17: =Zones!N17 -> 18 | C17: =Zones!K17 -> 2160.21 | D17: NA | E17: =0.03*C17*Zones!M17+7.5*Zones!F17*(1+IF(ISNUMBER(SEARCH("Studio",Zones!G17)),0,IF(ISNUMBER(SEARCH("3-Bed",Zones!G17)),3,IF(ISNUMBER(SEARCH("2-Bed",Zones!G17)),2,1)))) -> 329.4189 | I17: =E17 -> 329.4189 | J17: =I17 -> 329.4189 | K17: =MAX(H17:J17) -> 329.4189 | L17: Balanced IAQ fan - only applies to new construction
A18: =Zones!B18 -> F2-4 2-BED EAST | B18: =Zones!N18 -> 27 | C18: =Zones!K18 -> 3240.32 | D18: NA | E18: =0.03*C18*Zones!M18+7.5*Zones!F18*(1+IF(ISNUMBER(SEARCH("Studio",Zones!G18)),0,IF(ISNUMBER(SEARCH("3-Bed",Zones!G18)),3,IF(ISNUMBER(SEARCH("2-Bed",Zones!G18)),2,1)))) -> 494.1288 | I18: =E18 -> 494.1288 | J18: =I18 -> 494.1288 | K18: =MAX(H18:J18) -> 494.1288 | L18: Balanced IAQ fan - only applies to new construction
A19: =Zones!B19 -> F2-4 2-BED WEST | B19: =Zones!N19 -> 27 | C19: =Zones!K19 -> 3240.32 | D19: NA | E19: =0.03*C19*Zones!M19+7.5*Zones!F19*(1+IF(ISNUMBER(SEARCH("Studio",Zones!G19)),0,IF(ISNUMBER(SEARCH("3-Bed",Zones!G19)),3,IF(ISNUMBER(SEARCH("2-Bed",Zones!G19)),2,1)))) -> 494.1288 | I19: =E19 -> 494.1288 | J19: =I19 -> 494.1288 | K19: =MAX(H19:J19) -> 494.1288 | L19: Balanced IAQ fan - only applies to new construction
A20: =Zones!B20 -> F2-4 3-BED NE | B20: =Zones!N20 -> 12 | C20: =Zones!K20 -> 1410.14 | D20: NA | E20: =0.03*C20*Zones!M20+7.5*Zones!F20*(1+IF(ISNUMBER(SEARCH("Studio",Zones!G20)),0,IF(ISNUMBER(SEARCH("3-Bed",Zones!G20)),3,IF(ISNUMBER(SEARCH("2-Bed",Zones!G20)),2,1)))) -> 216.9126 | I20: =E20 -> 216.9126 | J20: =I20 -> 216.9126 | K20: =MAX(H20:J20) -> 216.9126 | L20: Balanced IAQ fan - only applies to new construction
A21: =Zones!B21 -> F2-4 3-BED NW | B21: =Zones!N21 -> 12 | C21: =Zones!K21 -> 1410.14 | D21: NA | E21: =0.03*C21*Zones!M21+7.5*Zones!F21*(1+IF(ISNUMBER(SEARCH("Studio",Zones!G21)),0,IF(ISNUMBER(SEARCH("3-Bed",Zones!G21)),3,IF(ISNUMBER(SEARCH("2-Bed",Zones!G21)),2,1)))) -> 216.9126 | I21: =E21 -> 216.9126 | J21: =I21 -> 216.9126 | K21: =MAX(H21:J21) -> 216.9126 | L21: Balanced IAQ fan - only applies to new construction
A22: =Zones!B22 -> F2-4 CORRIDOR | B22: =Zones!N22 -> 77.4075 | C22: =Zones!K22 -> 2580.25 | D22: 15 | F22: 0.15 | H22: =B22*D22 -> 1161.1125 | I22: =C22*F22 -> 387.0375 | K22: =MAX(H22:J22) -> 1161.1125
A23: =Zones!B23 -> F2-4 LAUNDRY | B23: =Zones!N23 -> 5.4006 | C23: =Zones!K23 -> 180.02 | D23: 15 | F23: 0.15 | H23: =B23*D23 -> 81.009 | I23: =C23*F23 -> 27.003 | K23: =MAX(H23:J23) -> 81.009
A24: =Zones!B24 -> F2-4 STUDIO SE | B24: =Zones!N24 -> 6 | C24: =Zones!K24 -> 540.05 | D24: NA | E24: =0.03*C24*Zones!M24+7.5*Zones!F24*(1+IF(ISNUMBER(SEARCH("Studio",Zones!G24)),0,IF(ISNUMBER(SEARCH("3-Bed",Zones!G24)),3,IF(ISNUMBER(SEARCH("2-Bed",Zones!G24)),2,1)))) -> 71.1045 | I24: =E24 -> 71.1045 | J24: =I24 -> 71.1045 | K24: =MAX(H24:J24) -> 71.1045 | L24: Balanced IAQ fan - only applies to new construction
A25: =Zones!B25 -> F2-4 STUDIO SW | B25: =Zones!N25 -> 6 | C25: =Zones!K25 -> 540.05 | D25: NA | E25: =0.03*C25*Zones!M25+7.5*Zones!F25*(1+IF(ISNUMBER(SEARCH("Studio",Zones!G25)),0,IF(ISNUMBER(SEARCH("3-Bed",Zones!G25)),3,IF(ISNUMBER(SEARCH("2-Bed",Zones!G25)),2,1)))) -> 71.1045 | I25: =E25 -> 71.1045 | J25: =I25 -> 71.1045 | K25: =MAX(H25:J25) -> 71.1045 | L25: Balanced IAQ fan - only applies to new construction
A26: =Zones!B26 -> F5 1-BED CORE EAST | B26: =Zones!N26 -> 4 | C26: =Zones!K26 -> 1440.14 | D26: NA | E26: =0.03*C26*Zones!M26+7.5*Zones!F26*(1+IF(ISNUMBER(SEARCH("Studio",Zones!G26)),0,IF(ISNUMBER(SEARCH("3-Bed",Zones!G26)),3,IF(ISNUMBER(SEARCH("2-Bed",Zones!G26)),2,1)))) -> 73.2042 | I26: =E26 -> 73.2042 | J26: =I26 -> 73.2042 | K26: =MAX(H26:J26) -> 73.2042 | L26: Balanced IAQ fan - only applies to new construction
A27: =Zones!B27 -> F5 1-BED CORE N | B27: =Zones!N27 -> 2 | C27: =Zones!K27 -> 720.07 | D27: NA | E27: =0.03*C27*Zones!M27+7.5*Zones!F27*(1+IF(ISNUMBER(SEARCH("Studio",Zones!G27)),0,IF(ISNUMBER(SEARCH("3-Bed",Zones!G27)),3,IF(ISNUMBER(SEARCH("2-Bed",Zones!G27)),2,1)))) -> 36.6021 | I27: =E27 -> 36.6021 | J27: =I27 -> 36.6021 | K27: =MAX(H27:J27) -> 36.6021 | L27: Balanced IAQ fan - only applies to new construction
A28: =Zones!B28 -> F5 1-BED CORE WEST | B28: =Zones!N28 -> 4 | C28: =Zones!K28 -> 1440.14 | D28: NA | E28: =0.03*C28*Zones!M28+7.5*Zones!F28*(1+IF(ISNUMBER(SEARCH("Studio",Zones!G28)),0,IF(ISNUMBER(SEARCH("3-Bed",Zones!G28)),3,IF(ISNUMBER(SEARCH("2-Bed",Zones!G28)),2,1)))) -> 73.2042 | I28: =E28 -> 73.2042 | J28: =I28 -> 73.2042 | K28: =MAX(H28:J28) -> 73.2042 | L28: Balanced IAQ fan - only applies to new construction
A29: =Zones!B29 -> F5 1-BED NORTH | B29: =Zones!N29 -> 10 | C29: =Zones!K29 -> 3720.36 | D29: NA | E29: =0.03*C29*Zones!M29+7.5*Zones!F29*(1+IF(ISNUMBER(SEARCH("Studio",Zones!G29)),0,IF(ISNUMBER(SEARCH("3-Bed",Zones!G29)),3,IF(ISNUMBER(SEARCH("2-Bed",Zones!G29)),2,1)))) -> 186.6108 | I29: =E29 -> 186.6108 | J29: =I29 -> 186.6108 | K29: =MAX(H29:J29) -> 186.6108 | L29: Balanced IAQ fan - only applies to new construction
A30: =Zones!B30 -> F5 2-BED CORE NE-NW | B30: =Zones!N30 -> 6 | C30: =Zones!K30 -> 2160.21 | D30: NA | E30: =0.03*C30*Zones!M30+7.5*Zones!F30*(1+IF(ISNUMBER(SEARCH("Studio",Zones!G30)),0,IF(ISNUMBER(SEARCH("3-Bed",Zones!G30)),3,IF(ISNUMBER(SEARCH("2-Bed",Zones!G30)),2,1)))) -> 109.8063 | I30: =E30 -> 109.8063 | J30: =I30 -> 109.8063 | K30: =MAX(H30:J30) -> 109.8063 | L30: Balanced IAQ fan - only applies to new construction
A31: =Zones!B31 -> F5 2-BED EAST | B31: =Zones!N31 -> 9 | C31: =Zones!K31 -> 3240.32 | D31: NA | E31: =0.03*C31*Zones!M31+7.5*Zones!F31*(1+IF(ISNUMBER(SEARCH("Studio",Zones!G31)),0,IF(ISNUMBER(SEARCH("3-Bed",Zones!G31)),3,IF(ISNUMBER(SEARCH("2-Bed",Zones!G31)),2,1)))) -> 164.7096 | I31: =E31 -> 164.7096 | J31: =I31 -> 164.7096 | K31: =MAX(H31:J31) -> 164.7096 | L31: Balanced IAQ fan - only applies to new construction
A32: =Zones!B32 -> F5 2-BED WEST | B32: =Zones!N32 -> 9 | C32: =Zones!K32 -> 3240.32 | D32: NA | E32: =0.03*C32*Zones!M32+7.5*Zones!F32*(1+IF(ISNUMBER(SEARCH("Studio",Zones!G32)),0,IF(ISNUMBER(SEARCH("3-Bed",Zones!G32)),3,IF(ISNUMBER(SEARCH("2-Bed",Zones!G32)),2,1)))) -> 164.7096 | I32: =E32 -> 164.7096 | J32: =I32 -> 164.7096 | K32: =MAX(H32:J32) -> 164.7096 | L32: Balanced IAQ fan - only applies to new construction
A33: =Zones!B33 -> F5 3-BED NE | B33: =Zones!N33 -> 4 | C33: =Zones!K33 -> 1410.14 | D33: NA | E33: =0.03*C33*Zones!M33+7.5*Zones!F33*(1+IF(ISNUMBER(SEARCH("Studio",Zones!G33)),0,IF(ISNUMBER(SEARCH("3-Bed",Zones!G33)),3,IF(ISNUMBER(SEARCH("2-Bed",Zones!G33)),2,1)))) -> 72.3042 | I33: =E33 -> 72.3042 | J33: =I33 -> 72.3042 | K33: =MAX(H33:J33) -> 72.3042 | L33: Balanced IAQ fan - only applies to new construction
A34: =Zones!B34 -> F5 3-BED NW | B34: =Zones!N34 -> 4 | C34: =Zones!K34 -> 1410.14 | D34: NA | E34: =0.03*C34*Zones!M34+7.5*Zones!F34*(1+IF(ISNUMBER(SEARCH("Studio",Zones!G34)),0,IF(ISNUMBER(SEARCH("3-Bed",Zones!G34)),3,IF(ISNUMBER(SEARCH("2-Bed",Zones!G34)),2,1)))) -> 72.3042 | I34: =E34 -> 72.3042 | J34: =I34 -> 72.3042 | K34: =MAX(H34:J34) -> 72.3042 | L34: Balanced IAQ fan - only applies to new construction
A35: =Zones!B35 -> F5 CORRIDOR | B35: =Zones!N35 -> 25.8025 | C35: =Zones!K35 -> 2580.25 | D35: 15 | F35: 0.15 | H35: =B35*D35 -> 387.0375 | I35: =C35*F35 -> 387.0375 | K35: =MAX(H35:J35) -> 387.0375
A36: =Zones!B36 -> F5 LAUNDRY | B36: =Zones!N36 -> 1.8002 | C36: =Zones!K36 -> 180.02 | D36: 15 | F36: 0.15 | H36: =B36*D36 -> 27.003 | I36: =C36*F36 -> 27.003 | K36: =MAX(H36:J36) -> 27.003
A37: =Zones!B37 -> F5 STUDIO SE | B37: =Zones!N37 -> 2 | C37: =Zones!K37 -> 540.05 | D37: NA | E37: =0.03*C37*Zones!M37+7.5*Zones!F37*(1+IF(ISNUMBER(SEARCH("Studio",Zones!G37)),0,IF(ISNUMBER(SEARCH("3-Bed",Zones!G37)),3,IF(ISNUMBER(SEARCH("2-Bed",Zones!G37)),2,1)))) -> 23.7015 | I37: =E37 -> 23.7015 | J37: =I37 -> 23.7015 | K37: =MAX(H37:J37) -> 23.7015 | L37: Balanced IAQ fan - only applies to new construction
A38: =Zones!B38 -> F5 STUDIO SW | B38: =Zones!N38 -> 2 | C38: =Zones!K38 -> 540.05 | D38: NA | E38: =0.03*C38*Zones!M38+7.5*Zones!F38*(1+IF(ISNUMBER(SEARCH("Studio",Zones!G38)),0,IF(ISNUMBER(SEARCH("3-Bed",Zones!G38)),3,IF(ISNUMBER(SEARCH("2-Bed",Zones!G38)),2,1)))) -> 23.7015 | I38: =E38 -> 23.7015 | J38: =I38 -> 23.7015 | K38: =MAX(H38:J38) -> 23.7015 | L38: Balanced IAQ fan - only applies to new construction
A39: =Zones!B39 -> PARKING GARAGE | B39: =Zones!N39 -> 0 | C39: =Zones!K39 -> 27902.72 | D39: 0 | F39: 0 | G39: 0.75 | H39: =B39*D39 -> 0 | I39: =C39*F39 -> 0 | J39: =C39*G39 -> 20927.04 | K39: =MAX(H39:J39) -> 20927.04 | L39: Parking garage: Table 120.1-B exhaust 0.75 cfm/ft² only. Person and area OA removed (App 5.4C Exhaust - Parking garages).

Sheet Water Heater
A1: ="Water Heater - "&Prototype!A2 -> Water Heater - ApartmentMidRise
A2: Vintage | B2: WH Type | C2: Efficiency | D2: Number of WH | E2: Tank volume (gal) | F2: Tank loss | G2: Source | H2: Note
A3: Existing | B3: Gas consumer storage (in-unit) | C3: 0.8 | D3: =B51 -> 88 | E3: ="See Existing in-unit CZ table, col F (gal/unit); building = 88 x F" -> See Existing in-unit CZ table, col F (gal/unit); building = 88 x F | F3: =IF(F62<=55,0.692-0.0013*F62,0.8072-0.0003*F62) -> 0.653 | G3: C3 is recovery efficiency (input = capacity / RE). F3 is the 10 CFR 430.32 high-draw UEF for the CZ tank size (col F). CZ columns: G = standby loss %/hr = I / (0.0834 × F); I = tank UA (Btu/h·°F) from the Maguire & Roberts 2020 UEF-to-UA method, used for both off-cycle and on-cycle losses; J is the unit. In SI, UA (W/K) = I × 0.527527 (B140). Not Title 20 Table F-4 and not the DEER commercial HPWH value 4.37. | H3: D3 = 88 in-unit water heaters, one per apartment (dwelling units only, not a central plant). All 88 are the same unit in every CZ: 30 gal / 30,000 Btu/h gas storage (Existing) and 200,000 Btu/h instantaneous (NC), because the smallest catalog size already covers the 3-bed peak. Only the hot water draw differs: 48 studio/1-bed (2 people, 0.36 gal/h), 32 two-bed (3 people, 0.54 gal/h), 8 three-bed (4 people, 0.72 gal/h). The common/retail area adds 1 commercial gas storage heater (Common CZ table), so the building has 89 water heaters.
A4: New Construction | B4: Gas consumer instantaneous (in-unit) | C4: 0.81 | D4: =D3 -> 88 | E4: 0 | F4: n/a
A5: * Individual dwelling-unit water heaters (not central §170.2(d)3 storage + recirculation + solar). 88 units. Existing = consumer storage catalog. NC = ACM §6.11.2 instantaneous. Retail/laundry/amenities = one commercial plant (NR catalog + 75 gal/h minimum).
A8: Peak Hot Water Consumption
A9: Space | B9: Plant (In-unit dwelling vs Common commercial) | C9: Total Area (ft²) | D9: Number of People | E9: Hot Water Usage Specification (gal/hr per person) [T24, 2022, Appendix 5.4A , sheet: "2022 SpaceFuncData-Input"] | F9: Peak Hot Water Usage (gal/hr) | G9: Peak Hot Water Usage (gal/min) | H9: Notes
A10: =Zones!B3 -> F1 BUSINESS CENTER | B10: Common | C10: =Zones!K3*Zones!M3 -> 360.04 | D10: =Zones!N3 -> 24.003867 | E10: 0.18 | F10: =D10*E10 -> 4.320696 | G10: =F10/60 -> 0.0720116 | H10: In-unit = dwelling DHW (consumer heater in each apartment). Common = retail/laundry/amenity DHW on a separate commercial plant. Dwelling gal/h-person is 0.18 throughout. Corridor 0, lounge/office 0.09, laundry 0.578 per Jason APTM58 / school App 5.4A kitchen-locker rate.
A11: =Zones!B4 -> F1 CORRIDOR | B11: Common | C11: =Zones!K4*Zones!M4 -> 1920.19 | D11: =Zones!N4 -> 19.2019 | E11: 0 | F11: =D11*E11 -> 0 | G11: =F11/60 -> 0
A12: =Zones!B5 -> F1 FITNESS CENTER | B12: Common | C12: =Zones!K5*Zones!M5 -> 900.09 | D12: =Zones!N5 -> 18.0018 | E12: 0.18 | F12: =D12*E12 -> 3.240324 | G12: =F12/60 -> 0.0540054
A13: =Zones!B6 -> F1 LEASING OFFICE | B13: Common | C13: =Zones!K6*Zones!M6 -> 345.03 | D13: =Zones!N6 -> 3.4503 | E13: 0.09 | F13: =D13*E13 -> 0.310527 | G13: =F13/60 -> 0.00517545
A14: =Zones!B7 -> F1 LOUNGE | B14: Common | C14: =Zones!K7*Zones!M7 -> 1050.1 | D14: =Zones!N7 -> 70.04167 | E14: 0.09 | F14: =D14*E14 -> 6.3037503 | G14: =F14/60 -> 0.1050625
A15: =Zones!B8 -> F1 MECHANICAL ROOM | B15: Common | C15: =Zones!K8*Zones!M8 -> 432.04 | D15: =Zones!N8 -> 1.29612 | E15: 0 | F15: =D15*E15 -> 0 | G15: =F15/60 -> 0
A16: =Zones!B9 -> F1 RETAIL N-NW | B16: Common | C16: =Zones!K9*Zones!M9 -> 5985.58 | D16: =Zones!N9 -> 99.759667 | E16: 0.18 | F16: =D16*E16 -> 17.95674 | G16: =F16/60 -> 0.299279
A17: =Zones!B10 -> F1 RETAIL NE | B17: Common | C17: =Zones!K10*Zones!M10 -> 4320.42 | D17: =Zones!N10 -> 72.007 | E17: 0.18 | F17: =D17*E17 -> 12.96126 | G17: =F17/60 -> 0.216021
A18: =Zones!B11 -> F1 RETAIL SE | B18: Common | C18: =Zones!K11*Zones!M11 -> 2880.28 | D18: =Zones!N11 -> 48.004667 | E18: 0.18 | F18: =D18*E18 -> 8.64084 | G18: =F18/60 -> 0.144014
A19: =Zones!B12 -> F1 RETAIL SW | B19: Common | C19: =Zones!K12*Zones!M12 -> 4428.43 | D19: =Zones!N12 -> 73.807167 | E19: 0.18 | F19: =D19*E19 -> 13.28529 | G19: =F19/60 -> 0.2214215
A20: =Zones!B13 -> F2-4 1-BED CORE EAST | B20: In-unit | C20: =Zones!K13*Zones!M13 -> 4320.42 | D20: =Zones!N13 -> 12 | E20: 0.18 | F20: =D20*E20 -> 2.16 | G20: =F20/60 -> 0.036
