Workbook
Name nonparticipating_forecastzone_scale_factor: #REF!
Name nonparticipating_forecastzone_scale_factor: 'Energy Usage'!#REF!

Sheet Notes
A1: Data Sources
A2: Dataset | B2: Dodge 2023
B3: CEUS 2022
B4: ComStock 2023
A6: Prototype | B6: CEC Assembly prototype (CBECC 2022.3.1) | C6: https://bees.noresco.com/software2022.html
A9: Codes | B9: Title 24, part 6, referred to as T24 (1984, 2001, 2007, 2013, 2016, 2022, 2025)
B10: ASHRAE 90.1 (2022)
B11: CFR Title 10 (2008, 2010, 2025)
B12: ACM 2022
B13: T24 2022 - Appendix 5.4A and Appendix 5.4B | C13: https://www.energy.ca.gov/publications/2022/2022-nonresidential-and-multifamily-alternative-calculation-method-reference
A15: Other | B15: 2022 Reduced infiltration CASE report | C15: https://title24stakeholders.com/wp-content/uploads/2020/10/2022-T24-Final-CASE-Report_Reduce-Infiltration.pdf
B16: 2019 Outdoor Lighting CASE Report | C16: https://title24stakeholders.com/wp-content/uploads/2016/10/T24-2019-CASE-Study-Results-Report-Outdoor-Sources_Final_with-Attachments.pdf
B17: 2019 High Efficiency Fume Hoods in Laboratory Spaces CASE Report | C17: https://title24stakeholders.com/wp-content/uploads/2017/09/2019-T24-CASE-Report_Fume-Hoods_Final_September-2017.pdf?
B18: PNNL 20405, 2011 | C18: file:///N:/Prj_SUS/2023/S23668%20SCE%20CA%20Prototypes%20Development/Technical/NR/0_Input%20data/Lighting/PNNL-20405.pdf
B19: Air leakage Memo, NORESCO, 2025 | C19: Infiltration_rate_report_14May2025-Short-Version.docx
A20: Water Heater | B20: ENERGY STAR certified commercial water heaters (gas storage input ≥76 kBtu/h; ES tank sizes) | C20: =HYPERLINK("https://www.energystar.gov/productfinder/product/certified-commercial-water-heaters/results?fuel_filter=Gas&markets_filter=United+States","ENERGY STAR product finder — gas") -> ENERGY STAR product finder — gas
B21: ENERGY STAR commercial WH dataset (download) | C21: =HYPERLINK("https://data.energystar.gov/Active-Specifications/ENERGY-STAR-Certified-Commercial-Water-Heaters/xmq6-bm79","ENERGY STAR dataset xmq6-bm79") -> ENERGY STAR dataset xmq6-bm79
B22: ENERGY STAR commercial WH eligibility (gas storage >75 kBtu/h) | C22: =HYPERLINK("https://www.energystar.gov/products/water_heaters/commercial_water_heaters/key_product_criteria","ENERGY STAR key product criteria") -> ENERGY STAR key product criteria
B23: Grainger gas tank water heaters (sizes below ES commercial, e.g. 30–75 kBtu/h) | C23: =HYPERLINK("https://www.grainger.com/category/plumbing/water-heaters/gas-tank-water-heaters","Grainger — gas tank WH") -> Grainger — gas tank WH
B24: Grainger electric tank water heaters (kW ladder, tank gallons) | C24: =HYPERLINK("https://www.grainger.com/category/plumbing/water-heaters/electric-tank-water-heaters","Grainger — electric tank WH") -> Grainger — electric tank WH
B25: ES commercial electric = heat pumps only; not used for resistance tank list | C25: =HYPERLINK("https://www.energystar.gov/productfinder/product/certified-commercial-water-heaters/results?fuel_filter=Electric&markets_filter=United+States","ENERGY STAR — electric (HPWH)") -> ENERGY STAR — electric (HPWH)
A26: Construction Rate
A39: Notes
A40: 2025 T24 | B40: Assembly Building is a building with meeting halls in which people gather for civic, social, or recreational activities. These include civic centers, convention centers and auditoriums.

Sheet Prototype
A1: NORESCO, Updated September 2026
A2: Assembly
A3: Characteristic | B3: Value | C3: Data Sources
A4: Building Type | B4: Assembly
A5: Building Category | B5: Nonresidential
A6: Version | B6: v2-0
A7: Vintages | B7: 4 Vintages: Pre-1978, 1978-1997,1998-2007, 2008-2018 New Construction (2019+) | C7: Based on the vintage bin analysis. A summary of the findings is presented in the following paper, with a link provided in the Notes tab: Yousefi, F., Athalye, R. (2025). “Determining Vintage Bins for Prototype Development: An Analysis of California Commercial Buildings.” ASHRAE Annual Conference.
A8: Shape | B8: #VALUE! | C8: The analysis uses prototype geometry originally developed by CEC.
A9: Total Floor Area (ft²) | B9: 315352 | C9: Same as CEC
A10: Aspect Ratio | B10: It varies for different buildings. | C10: Same as CEC
A11: Number of Floors | B11: 1 | C11: Same as CEC
A12: Roof type | B12: Flat | C12: Same as CEC
A13: WWR | B13: 0.145 | C13: Same as CEC
A14: Shading Geometry | B14: No Shades | C14: Same as CEC
A15: Floor to floor height (feet) | B15: Library and Exhibit & Events=13 ft, Religious=50 ft, Sports & Rec and Terminal=25 ft | C15: Same as CEC
A16: Floor to ceiling height (feet) | B16: Library and Exhibit & Events=13 ft, Religious=50 ft, Sports & Rec and Terminal=25 ft | C16: Same as CEC
A17: Glazing sill height (feet) | B17: It varies for different buildings. | C17: Same as CEC
A21: Above grade wall area (ft²) | B21: 415619.76
A22: Gross wall area (ft²) | B22: 415619.76
A23: Roof area (ft²) | B23: 315369.42
A24: Underground Gross Wall Area (ft²) | B24: 0

Sheet Zones
A1: ="Proposed Layout - "&Prototype!B4 -> Proposed Layout - Assembly
A2: Building | B2: Space/Thermal Zone | C2: Space Type [Primarily from: T24, 2022 Appendix 5.4A] - See Notes column | D2: HVAC System Name/AHU Name | E2: Schedule Category | F2: Conditioned (Y/N) | G2: Area Fraction | H2: Area (ft²) W/O Multiplier | I2: Area (ft²) | J2: Volume (ft³) | K2: Multipliers | L2: Number of People W/O Multiplier | M2: Number of People | N2: People (Persons/1,000 ft²) [T24, 2025,Table 120.1-A] | O2: Notes
A3: Exhibits and events | B3: Exhibits and events_Conference Room | C3: Convention, Conference, Multipurpose and Meeting Area | D3: AHU-1 | E3: Assembly | F3: Yes | G3: =I3/$I$20 -> 0.1015627 | H3: =2669 -> 2669 | I3: =2669*K3 -> 32028 | J3: =34693*K3 -> 416316 | K3: 12 | L3: =(N3*H3)/1000 -> 88.077 | M3: =(N3*I3)/1000 -> 1056.924 | N3: 33 | P3: =N3/1000 -> 0.033
A4: Exhibits and events | B4: Exhibits and events_Theater Area | C4: Theater Area (Motion Picture) | D4: AHU-1 | E4: Assembly | F4: Yes | G4: =I4/$I$20 -> 0.084667292 | H4: =2225 -> 2225 | I4: =2225*K4 -> 26700 | J4: =28931*K4 -> 347172 | K4: 12 | L4: =(N4*H4)/1000 -> 157.975 | M4: =(N4*I4)/1000 -> 1895.7 | N4: 71 | P4: =N4/1000 -> 0.071
A5: Exhibits and events | B5: Exhibits and events_Auditorium Area | C5: Auditorium Area | D5: AHU-1 | E5: Assembly | F5: Yes | G5: =I5/$I$20 -> 0.084553134 | H5: =2222 -> 2222 | I5: =2222*K5 -> 26664 | J5: =28883*K5 -> 346596 | K5: 12 | L5: =(N5*H5)/1000 -> 157.762 | M5: =(N5*I5)/1000 -> 1893.144 | N5: 71 | P5: =N5/1000 -> 0.071
A6: Exhibits and events | B6: Exhibits and events_Museum Area Exhibition Display | C6: Museum Area (Exhibition/Display) | D6: AHU-1 | E6: Assembly | F6: Yes | G6: =I6/$I$20 -> 0.067619676 | H6: =1777 -> 1777 | I6: =1777*K6 -> 21324 | J6: =23095*K6 -> 277140 | K6: 12 | L6: =(N6*H6)/1000 -> 30.209 | M6: =(N6*I6)/1000 -> 362.508 | N6: 17 | P6: =N6/1000 -> 0.017
A7: Library | B7: Library_Conference Room | C7: Convention, Conference, Multipurpose and Meeting Area | D7: AHU-2 | E7: Assembly | F7: Yes | G7: =I7/$I$20 -> 0.0041223775 | H7: =650 -> 650 | I7: =650*K7 -> 1300 | J7: =8447*K7 -> 16894 | K7: 2 | L7: =(N7*H7)/1000 -> 21.45 | M7: =(N7*I7)/1000 -> 42.9 | N7: 33 | P7: =N7/1000 -> 0.033
A8: Library | B8: Library_Reading Area | C8: Library (Reading Area) | D8: AHU-2 | E8: Assembly | F8: Yes | G8: =I8/$I$20 -> 0.024727923 | H8: =3899 -> 3899 | I8: =3899*K8 -> 7798 | J8: =50684*K8 -> 101368 | K8: 2 | L8: =(N8*H8)/1000 -> 38.99 | M8: =(N8*I8)/1000 -> 77.98 | N8: 10 | P8: =N8/1000 -> 0.01
A9: Library | B9: Library_Stacks Area | C9: Library (Stacks Area) | D9: AHU-2 | E9: Assembly | F9: Yes | G9: =I9/$I$20 -> 0.049455846 | H9: =7798 -> 7798 | I9: =7798*K9 -> 15596 | J9: =101369*K9 -> 202738 | K9: 2 | L9: =(N9*H9)/1000 -> 77.98 | M9: =(N9*I9)/1000 -> 155.96 | N9: 10 | P9: =N9/1000 -> 0.01
A10: Library | B10: Library_Lobby Main Entry | C10: Lobby, Main Entry | D10: AHU-2 | E10: Assembly | F10: Yes | G10: =I10/$I$20 -> 0.0041223775 | H10: =650 -> 650 | I10: =650*K10 -> 1300 | J10: =8447*K10 -> 16894 | K10: 2 | L10: =(N10*H10)/1000 -> 21.45 | M10: =(N10*I10)/1000 -> 42.9 | N10: 33 | P10: =N10/1000 -> 0.033
A11: Religious | B11: Religious_Conference Room | C11: Convention, Conference, Multipurpose and Meeting Area | D11: AHU-3 | E11: Assembly | F11: Yes | G11: =I11/$I$20 -> 0.019663741 | H11: =689 -> 689 | I11: =689*K11 -> 6201 | J11: =34445*K11 -> 310005 | K11: 9 | L11: =(N11*H11)/1000 -> 22.737 | M11: =(N11*I11)/1000 -> 204.633 | N11: 33 | P11: =N11/1000 -> 0.033
A12: Religious | B12: Religious_General Office | C12: Office Area (>250 square feet) | D12: AHU-3 | E12: Office | F12: Yes | G12: =I12/$I$20 -> 0.019663741 | H12: =689 -> 689 | I12: =689*K12 -> 6201 | J12: =34445*K12 -> 310005 | K12: 9 | L12: =(N12*H12)/1000 -> 3.445 | M12: =(N12*I12)/1000 -> 31.005 | N12: 5 | P12: =N12/1000 -> 0.005
A13: Religious | B13: Religious_Worship Area | C13: Religious Worship Area | D13: AHU-3 | E13: Assembly | F13: Yes | G13: =I13/$I$20 -> 0.15728139 | H13: =5511 -> 5511 | I13: =5511*K13 -> 49599 | J13: =275560*K13 -> 2480040 | K13: 9 | L13: =(N13*H13)/1000 -> 391.281 | M13: =(N13*I13)/1000 -> 3521.529 | N13: 71 | P13: =N13/1000 -> 0.071
A14: Sports | B14: Sports and recreation_GYM | C14: Exercise/Fitness Center and Gymnasium Areas | D14: AHU-4 | E14: Assembly | F14: Yes | G14: =I14/$I$20 -> 0.25703024 | H14: =2795 -> 2795 | I14: =2795*K14 -> 81055 | J14: =69886*K14 -> 2026694 | K14: 29 | L14: =(N14*H14)/1000 -> 27.95 | M14: =(N14*I14)/1000 -> 810.55 | N14: 10 | P14: =N14/1000 -> 0.01
A15: Sports | B15: Sports and recreation_Locker Room | C15: Locker Room | D15: AHU-4 | E15: Assembly | F15: Yes | G15: =I15/$I$20 -> 0.048095462 | H15: =523 -> 523 | I15: =523*K15 -> 15167 | J15: =13069*K15 -> 379001 | K15: 29 | L15: =(N15*H15)/1000 -> 10.46 | M15: =(N15*I15)/1000 -> 303.34 | N15: 20 | P15: =N15/1000 -> 0.02
A16: Sports | B16: Sports and recreation_Restroom | C16: Restrooms | E16: Assembly | F16: Yes | G16: =I16/$I$20 -> 0.016093128 | H16: =175 -> 175 | I16: =175*K16 -> 5075 | J16: =4366*K16 -> 126614 | K16: 29 | L16: =(N16*H16)/1000 -> 1.75 | M16: =(N16*I16)/1000 -> 50.75 | N16: 10 | O16: Indirectly conditioned | P16: =N16/1000 -> 0.01
A17: Terminal | B17: Terminals_Concourse | C17: Concourse and Atria Area | D17: AHU-5 | E17: Assembly | F17: Yes | G17: =I17/$I$20 -> 0.055233517 | H17: =5806 -> 5806 | I17: =5806*K17 -> 17418 | J17: =145142*K17 -> 435426 | K17: 3 | L17: =(N17*H17)/1000 -> 98.702 | M17: =(N17*I17)/1000 -> 296.106 | N17: 17 | O17: Occupancy load is based on T24, 2025, Appendix 5.4A, [For CSV - 2022 SpcFuncData] tab | P17: =N17/1000 -> 0.017
A18: Terminal | B18: Terminals_Baggage | C18: Transportation Function (Baggage Area) | D18: AHU-5 | E18: Assembly | F18: Yes | G18: =I18/$I$20 -> 0.0030537304 | H18: =321 -> 321 | I18: =321*K18 -> 963 | J18: =8030*K18 -> 24090 | K18: 3 | L18: =(N18*H18)/1000 -> 10.593 | M18: =(N18*I18)/1000 -> 31.779 | N18: 33 | P18: =N18/1000 -> 0.033
A19: Terminal | B19: Terminals_Ticket | C19: Transportation Function (Ticketing Area) | D19: AHU-5 | E19: Assembly | F19: Yes | G19: =I19/$I$20 -> 0.0030537304 | H19: =321 -> 321 | I19: =321*K19 -> 963 | J19: =8030*K19 -> 24090 | K19: 3 | L19: =(N19*H19)/1000 -> 10.593 | M19: =(N19*I19)/1000 -> 31.779 | N19: 33 | P19: =N19/1000 -> 0.033
A20: Total (5 Building) | B20: Total (17 spaces) | C20: Total (15 Space types) | D20: Total ( 5 HVAC Zones) | F20: Total (17 Conditioned zones) | H20: =SUM(H3:H19) -> 38720 | I20: =SUM(I3:I19) -> 315352 | L20: =SUM(L3:L19) -> 1171.404 | M20: =SUM(M3:M19) -> 10809.487
C37: Background Data [To be deleted prior to publication]

Sheet Envelope
A1: ="Envelope - "&Prototype!B4 -> Envelope - Assembly
A2: Element | B2: Prototype | C2: Assembly Type | D2: Construction | E2: Thermal properties | F2: Vintage | G2: Selected T24 | H2: Notes | I2: CZ1 | J2: CZ2 | K2: CZ3 | L2: CZ4 | M2: CZ5 | N2: CZ6 | O2: CZ7 | P2: CZ8 | Q2: CZ9 | R2: CZ10 | S2: CZ11 | T2: CZ12 | U2: CZ13 | V2: CZ14 | W2: CZ15 | X2: CZ16
A3: External Wall | B3: =Prototype!A2 -> Assembly | C3: ExtWall_MetalFramed_NonRes | D3: Metal framed wall: Metal frame + insulation + Gypsum board | E3: U-value IP | F3: Pre 1978 | G3: N/A | H3: Using DOE pre-1980 U-values and a 6.1% cumulative wall renovation rate through 2028, based on the average annual rate from CBECS 2003 and 2012 projected over 48 years. | I3: =I69*(1-$I$70)+I68*$I$70 -> 0.219131 | J3: =J69*(1-$I$70)+J68*$I$70 -> 0.216935 | K3: =K69*(1-$I$70)+K68*$I$70 -> 0.218155 | L3: =L69*(1-$I$70)+L68*$I$70 -> 0.216935 | M3: =M69*(1-$I$70)+M68*$I$70 -> 0.216935 | N3: =N69*(1-$I$70)+N68*$I$70 -> 0.219131 | O3: =O69*(1-$I$70)+O68*$I$70 -> 0.219131 | P3: =P69*(1-$I$70)+P68*$I$70 -> 0.216935 | ... X3: =X69*(1-$I$70)+X68*$I$70 -> 0.216935
F4: 1978-1997 | G4: 1986 | H4: Similar to Low-rise office: Package A/ Heat Capacity was considered 0-3.99 (BTU/F/ft²) | I4: =1/7.52 -> 0.13297872 | J4: =1/7.52 -> 0.13297872 | K4: =1/7.52 -> 0.13297872 | L4: =1/7.52 -> 0.13297872 | M4: =1/7.52 -> 0.13297872 | N4: =1/7.52 -> 0.13297872 | O4: =1/7.52 -> 0.13297872 | P4: =1/7.52 -> 0.13297872 | ... X4: =1/7.52 -> 0.13297872 | Y4: These values have better performance than the next vintage
F5: 1998-2007 | G5: 2001 | H5: Table 1-H | I5: 0.182 | J5: 0.182 | K5: 0.189 | L5: 0.189 | M5: 0.189 | N5: 0.189 | O5: 0.189 | P5: 0.189 | Q5: 0.189 | R5: 0.182 | S5: 0.182 | T5: 0.182 | U5: 0.182 | V5: 0.182 | W5: 0.182 | X5: 0.182
F6: 2008-2018 | G6: 2013 | H6: Table 140.3-B | I6: 0.098 | J6: 0.062 | K6: 0.082 | L6: 0.062 | M6: 0.062 | N6: 0.098 | O6: 0.098 | P6: 0.062 | Q6: 0.062 | R6: 0.062 | S6: 0.062 | T6: 0.062 | U6: 0.062 | V6: 0.062 | W6: 0.062 | X6: 0.062
F7: Existing | H7: Weighted average of all 4 vintages | I7: {=_xlfn.BYCOL(TRANSPOSE(Weights!$C$4:$F$19)*I3:X6,_xlfn.LAMBDA(_xlpm.c,SUM(_xlpm.c)))} -> 0.17018743 | J7: 0.16742119 | K7: 0.18101495 | L7: 0.17935105 | M7: 0.17585245 | N7: 0.19087233 | O7: 0.17901138 | P7: 0.19055699 | Q7: 0.19029163 | R7: 0.1662765 | S7: 0.16673888 | T7: 0.16947707 | U7: 0.16682184 | V7: 0.17218403 | W7: 0.16507788 | X7: 0.16343469
F8: 2019+ | G8: 2025 | H8: Table 140.3-B | I8: 0.06 | J8: 0.055 | K8: 0.071 | L8: 0.055 | M8: 0.055 | N8: 0.06 | O8: 0.06 | P8: 0.055 | Q8: 0.055 | R8: 0.055 | S8: 0.055 | T8: 0.055 | U8: 0.055 | V8: 0.055 | W8: 0.055 | X8: 0.055
A9: Roof | B9: =$B$3 -> Assembly | C9: FlatRoof_WoodFramedAndOther_NonRes | D9: Metal deck roof: roof membrane+roof insulation+metal decking | E9: U-value IP | F9: Pre 1978 | G9: N/A | H9: Considering 30 years for roof/ insulation replacement. | I9: 0.057 | J9: 0.057 | K9: 0.057 | L9: 0.057 | M9: 0.057 | N9: 0.078 | O9: 0.078 | P9: 0.078 | Q9: 0.078 | R9: 0.078 | S9: 0.057 | T9: 0.057 | U9: 0.057 | V9: 0.057 | W9: 0.057 | X9: 0.057
F10: 1978-1997 | G10: 1992 | I10: 0.057 | J10: 0.057 | K10: 0.057 | L10: 0.057 | M10: 0.057 | N10: 0.078 | O10: 0.078 | P10: 0.078 | Q10: 0.078 | R10: 0.078 | S10: 0.057 | T10: 0.057 | U10: 0.057 | V10: 0.057 | W10: 0.057 | X10: 0.057
F11: 1998-2007 | G11: 2001 | H11: Table 1-H | I11: 0.057 | J11: 0.057 | K11: 0.057 | L11: 0.057 | M11: 0.057 | N11: 0.078 | O11: 0.078 | P11: 0.078 | Q11: 0.078 | R11: 0.057 | S11: 0.057 | T11: 0.057 | U11: 0.057 | V11: 0.057 | W11: 0.057 | X11: 0.057
F12: 2008-2018 | G12: 2013 | H12: Table 140.3-B | I12: 0.049 | J12: 0.039 | K12: 0.039 | L12: 0.039 | M12: 0.049 | N12: 0.075 | O12: 0.067 | P12: 0.067 | Q12: 0.039 | R12: 0.039 | S12: 0.039 | T12: 0.039 | U12: 0.039 | V12: 0.039 | W12: 0.039 | X12: 0.039
F13: Existing | H13: Weighted average of all 4 vintages | I13: {=_xlfn.BYCOL(TRANSPOSE(Weights!$C$4:$F$19)*I9:X12,_xlfn.LAMBDA(_xlpm.c,SUM(_xlpm.c)))} -> 0.056308073 | J13: 0.056130375 | K13: 0.055643004 | L13: 0.055670281 | M13: 0.056253061 | N13: 0.077901031 | O13: 0.07739056 | P13: 0.077630409 | Q13: 0.076472292 | R13: 0.069995214 | S13: 0.055349218 | T13: 0.055200322 | U13: 0.055239762 | V13: 0.055823286 | W13: 0.055983806 | X13: 0.055287365
F14: 2019+ | G14: 2025 | H14: Table 140.3-B | I14: 0.038 | J14: 0.038 | K14: 0.038 | L14: 0.038 | M14: 0.038 | N14: 0.038 | O14: 0.038 | P14: 0.038 | Q14: 0.038 | R14: 0.038 | S14: 0.038 | T14: 0.038 | U14: 0.038 | V14: 0.038 | W14: 0.038 | X14: 0.038
A15: Windows | B15: =$B$3 -> Assembly | C15: FixedWindow_NonRes | D15: Single pane | E15: U-value IP | F15: Pre 1978 | G15: N/A | H15: ASHRAE Handbook of Fundamentals (Table 4-Ch15) for single pane & T24, 2013 for double pane (33%-67%)* | I15: =0.33*1.12+0.67*0.36 -> 0.6108 | J15: =0.33*1.12+0.67*0.36 -> 0.6108 | K15: =0.33*1.12+0.67*0.36 -> 0.6108 | L15: =0.33*1.12+0.67*0.36 -> 0.6108 | M15: =0.33*1.12+0.67*0.36 -> 0.6108 | N15: =0.33*1.12+0.67*0.36 -> 0.6108 | O15: =0.33*1.12+0.67*0.36 -> 0.6108 | P15: =0.33*1.12+0.67*0.36 -> 0.6108 | ... X15: =0.33*1.12+0.67*0.36 -> 0.6108
F16: 1978-1997 | G16: N/A | I16: =0.33*1.12+0.67*0.36 -> 0.6108 | J16: =0.33*1.12+0.67*0.36 -> 0.6108 | K16: =0.33*1.12+0.67*0.36 -> 0.6108 | L16: =0.33*1.12+0.67*0.36 -> 0.6108 | M16: =0.33*1.12+0.67*0.36 -> 0.6108 | N16: =0.33*1.12+0.67*0.36 -> 0.6108 | O16: =0.33*1.12+0.67*0.36 -> 0.6108 | P16: =0.33*1.12+0.67*0.36 -> 0.6108 | ... X16: =0.33*1.12+0.67*0.36 -> 0.6108
D17: Double pane | F17: 1998-2007 | G17: 2001 | H17: Table 1-H | I17: 0.49 | J17: 0.49 | K17: 0.81 | L17: 0.81 | M17: 0.81 | N17: 0.81 | O17: 0.81 | P17: 0.81 | Q17: 0.81 | R17: 0.49 | S17: 0.49 | T17: 0.49 | U17: 0.49 | V17: 0.49 | W17: 0.49 | X17: 0.49
F18: 2008-2018 | G18: 2013 | H18: Table 140.3-B | I18: 0.36 | J18: 0.36 | K18: 0.36 | L18: 0.36 | M18: 0.36 | N18: 0.36 | O18: 0.36 | P18: 0.36 | Q18: 0.36 | R18: 0.36 | S18: 0.36 | T18: 0.36 | U18: 0.36 | V18: 0.36 | W18: 0.36 | X18: 0.36
F19: Existing | H19: Weighted average of all 4 vintages | I19: {=_xlfn.BYCOL(TRANSPOSE(Weights!$C$4:$F$19)*I15:X18,_xlfn.LAMBDA(_xlpm.c,SUM(_xlpm.c)))} -> 0.57694 | J19: 0.58691521 | K19: 0.61856871 | L19: 0.61888709 | M19: 0.60943161 | N19: 0.62779252 | O19: 0.63153608 | P19: 0.62041374 | Q19: 0.61744802 | R19: 0.56301688 | S19: 0.56954539 | T19: 0.56654296 | U19: 0.57405706 | V19: 0.57538291 | W19: 0.55653637 | X19: 0.56779309
F20: 2019+ | G20: 2025 | H20: Table 140.3-B | I20: 0.36 | J20: 0.36 | K20: 0.36 | L20: 0.36 | M20: 0.36 | N20: 0.36 | O20: 0.36 | P20: 0.36 | Q20: 0.34 | R20: 0.36 | S20: 0.34 | T20: 0.34 | U20: 0.34 | V20: 0.34 | W20: 0.34 | X20: 0.36
B21: =$B$3 -> Assembly | C21: FixedWindow_NonRes | D21: Single pane | E21: SHGC | F21: Pre 1978 | G21: N/A | H21: ASHRAE Handbook of Fundamentals (Table 10-Ch15) for single pane & T24, 2013 for double pane (33%-67%)* | I21: =0.79*0.33+0.67*I24 -> 0.4282 | J21: =0.79*0.33+0.67*J24 -> 0.4282 | K21: =0.79*0.33+0.67*K24 -> 0.4282 | L21: =0.79*0.33+0.67*L24 -> 0.4282 | M21: =0.79*0.33+0.67*M24 -> 0.4282 | N21: =0.79*0.33+0.67*N24 -> 0.4282 | O21: =0.79*0.33+0.67*O24 -> 0.4282 | P21: =0.79*0.33+0.67*P24 -> 0.4282 | ... X21: =0.79*0.33+0.67*X24 -> 0.4282
F22: 1978-1997 | G22: N/A | I22: =0.79*0.33+0.67*I24 -> 0.4282 | J22: =0.79*0.33+0.67*J24 -> 0.4282 | K22: =0.79*0.33+0.67*K24 -> 0.4282 | L22: =0.79*0.33+0.67*L24 -> 0.4282 | M22: =0.79*0.33+0.67*M24 -> 0.4282 | N22: =0.79*0.33+0.67*N24 -> 0.4282 | O22: =0.79*0.33+0.67*O24 -> 0.4282 | P22: =0.79*0.33+0.67*P24 -> 0.4282 | ... X22: =0.79*0.33+0.67*X24 -> 0.4282
D23: Double pane | F23: 1998-2007 | G23: 2001 | H23: Table 1-H - WWR:31-40% / SHGC non-north | I23: 0.43 | J23: 0.36 | K23: 0.41 | L23: 0.41 | M23: 0.41 | N23: 0.34 | O23: 0.34 | P23: 0.34 | Q23: 0.34 | R23: 0.31 | S23: 0.31 | T23: 0.31 | U23: 0.31 | V23: 0.31 | W23: 0.31 | X23: 0.43
F24: 2008-2018 | G24: 2013 | H24: Table 140.3-B | I24: 0.25 | J24: 0.25 | K24: 0.25 | L24: 0.25 | M24: 0.25 | N24: 0.25 | O24: 0.25 | P24: 0.25 | Q24: 0.25 | R24: 0.25 | S24: 0.25 | T24: 0.25 | U24: 0.25 | V24: 0.25 | W24: 0.25 | X24: 0.25
F25: Existing | H25: Weighted average of all 4 vintages | I25: {=_xlfn.BYCOL(TRANSPOSE(Weights!$C$4:$F$19)*I21:X24,_xlfn.LAMBDA(_xlpm.c,SUM(_xlpm.c)))} -> 0.41296872 | J25: 0.41294685 | K25: 0.41232844 | L25: 0.41260413 | M25: 0.40954749 | N25: 0.41113406 | O25: 0.40299334 | P25: 0.41422498 | Q25: 0.41392608 | R25: 0.38585621 | S25: 0.39399642 | T25: 0.39161451 | U25: 0.39881963 | V25: 0.39793839 | W25: 0.37889819 | X25: 0.41153017
F26: 2019+ | G26: 2025 | H26: Table 140.3-B | I26: 0.25 | J26: 0.25 | K26: 0.25 | L26: 0.25 | M26: 0.25 | N26: 0.25 | O26: 0.25 | P26: 0.25 | Q26: 0.22 | R26: 0.25 | S26: 0.22 | T26: 0.22 | U26: 0.22 | V26: 0.22 | W26: 0.22 | X26: 0.25
C29: Infiltration
D30: Building | E30: Zones | F30: Vintage | G30: I_75 6-sdied Infiltration rate @ 75 pa | H30: Note | I30: I-design (cfm/ft²) (4-sided Infiltration rate at normal pressure) (Design flow rate approach and Flow/Exterior Wall Area calculation method)
C31: Infiltration | D31: Exhibits and events | F31: Pre 1978 | G31: 1.1 | H31: 2022 CASE report (Table 38) | I31: =0.112*G31*AA36 -> 0.57003692 | Z31: Floor or roof area (ft2) | AA31: 8892.49
F32: 1978-1997 | G32: 1.1 | H32: 2022 CASE report (Table 38) | I32: =0.112*G32*AA36 -> 0.57003692 | Z32: Walls area (ft2) | AA32: =94.3*4*13 -> 4903.6
F33: 1998-2007 | G33: 1.1 | H33: 2022 CASE report (Table 38) | I33: =0.112*G33*AA36 -> 0.57003692 | Z33: Building 4 sided area (ft2)= | AA33: =AA32 -> 4903.6
F34: 2008-2018 | G34: 1 | H34: 2022 CASE report (Table 38) & T24, 2008-2016 (Table 140.3-B)--Air barrier is required in CZ 10-16 | I34: =0.112*G34*AA36 -> 0.51821538 | Z34: Building 6 sided area (ft2)= | AA34: =AA32+(2*AA31) -> 22688.58
F35: Existing | G35: =G32 -> 1.1 | H35: Same as Pre 2008 because of their higher weights | I35: =0.112*G35*AA36 -> 0.57003692
F36: 2019+ | G36: 0.6 | H36: 2022 CASE report (Table 38) & T24, 2025 (Table 140.3-B)--Air barrier is required in all CZs | I36: =0.112*G36*AA36 -> 0.31092923 | Z36: 6 sided /4 sided factor= | AA36: =AA34/AA33 -> 4.6269231
D37: Library | F37: Pre 1978 | G37: 1.1 | H37: 2022 CASE report (Table 38) | I37: =0.112*G37*AA42 -> 0.66338462 | Z37: Floor or roof area (ft2) | AA37: 12996
F38: 1978-1997 | G38: 1.1 | H38: 2022 CASE report (Table 38) | I38: =0.112*G38*AA42 -> 0.66338462 | Z38: Walls area (ft2) | AA38: =114*4*13 -> 5928
F39: 1998-2007 | G39: 1.1 | H39: 2022 CASE report (Table 38) | I39: =0.112*G39*AA42 -> 0.66338462 | Z39: Building 4 sided area (ft2)= | AA39: =AA38 -> 5928
F40: 2008-2018 | G40: 1 | H40: 2022 CASE report (Table 38) & T24, 2008-2016 (Table 140.3-B)--Air barrier is required in CZ 10-16 | I40: =0.112*G40*AA42 -> 0.60307692 | Z40: Building 6 sided area (ft2)= | AA40: =AA38+(2*AA37) -> 31920
F41: Existing | G41: =G38 -> 1.1 | H41: Same as Pre 2008 because of their higher weights | I41: =0.112*G41*AA42 -> 0.66338462
F42: 2019+ | G42: 0.6 | H42: 2022 CASE report (Table 38) & T24, 2025 (Table 140.3-B)--Air barrier is required in all CZs | I42: =0.112*G42*AA42 -> 0.36184615 | Z42: 6 sided /4 sided factor= | AA42: =AA40/AA39 -> 5.3846154
...

Sheet HVAC System
A1: ="HVAC system - "&Prototype!B4 -> HVAC system - Assembly
A2: Vintage | B2: Zones | C2: Heating | D2: Cooling | E2: Air Distribution | F2: Source | G2: Note
A3: Existing | B3: All Space Types | C3: Hot water heating (Central Gas Boiler) | D3: Chilled water cooling (central Water-Cooled Chiller) | E3: MZ VAV+Hydronic Reheat | F3: Engineering Judgement | G3: System 6 – VAV
A4: New Construction | B4: Library | C4: Hot water heating (AWHP) | D4: Chilled water cooling (central Water-Cooled Chiller) | E4: MZ VAV+Hydronic Reheat | F4: T24 2025 ACM 2025, Table 2 and 3 | G4: System 15 – VAVAWHP
B5: Exhibit/Sport Arena/Religious building/Terminal | C5: Hot water heating (Central Gas Boiler) | D5: Chilled water cooling (central Water-Cooled Chiller) | E5: MZ VAV+Hydronic Reheat | G5: System 6 – VAV
A10: Efficiency of HVAC system (Efficiency is capacity-dependent. The following table provides a general estimate of system efficiency based on preliminary simulations in one climate zone, or assuming cooling load based on rule of thumb)
A11: Vintage | B11: Upgrade/Installed year | C11: Water Cooled Chiller | D11: Gas Boiler | E11: Heat Rejection (Cooling Tower) | F11: Sources | G11: Note
A12: Pre 1978 | B12: 2008 | C12: Water Cooled, Electrically Operated, Centrifugal--≥ 300 tons - 6.10 COP 6.40 IPLV | D12: 80% Ec | E12: Axial fan Open-circuit cooling tower--95°F entering water 85°F leaving water 75°F entering air wb--≥ 38.2 gpm/hp | F12: 2008 Title 20 Appliance Efficiency Regulations, 2005 T24 Standards, Tables 112-A, 112-B
A13: 1978-1997
A14: 1998-2007
A15: 2008-2018 | B15: 2013 | C15: Water Cooled, Electrically Operated, Centrifugal--≥ 600 tons --≤ 0.570 kW/ton (6.2 COP) ≤ 0.539 IPLV (Path A) | D15: 82% Ec | E15: Axial fan Open-circuit cooling tower--95°F entering water 85°F leaving water 75°F entering air wb--≥ 42.1 gpm/hp | F15: 2013 Title 20 Appliance Efficiency Regulations, 2013 T24 Tables 112-A, 112-B
A16: New Construction | B16: 2025 | C16: Water Cooled, Electrically Operated, Centrifugal--≥ 600 tons ≤ 0.560 kW/ton (6.28 COP) ≤ 0.500 IPLV (Path A) | D16: Gas-Fired Boiler > 10,000,000 Btu/h-- 82% Ec | E16: Axial fan Open-circuit cooling tower--95°F entering water 85°F leaving water 75°F entering air wb--≥ 42.1 gpm/hp | F16: Title 20 Appliance Efficiency Regulations, T24, 2025, Tables 110.2-A, 110.2-B
C18: * Et = Combustion efficiency | D18: * Et = Thermal efficiency
A20: Fan power
A21: Vintage | B21: Approach | C21: System | D21: Total Static Pressure (TSP) (in w.c.) | E21: Fan Efficiency [ACM 2025] | F21: Motor Efficiency | G21: Fan Power Index (W/cfm) | H21: Data Source | I21: Note
A22: Existing | B22: PNNL 90.1-2011, TSP | C22: VAV (System 6), > 4,648 cfm | D22: 5.58 | E22: 0.65 | F22: ASHRAE 90.1, 2004, Table 10.8 * | H22: Fan power formula: PNNL 20405, 2010, section 5.2.2.5 TSP and fan efficiency: PNNL 20405, 2010, Table 5.11, 90.1-04ac values Motor efficiency: ASHRAE 90.1, 2004, Table 10.8
A23: Brake horsepower (bhp) = (Supply cfm × TSP in w.c.) / (6356 × fan efficiency)
A24: Fan power (w/cfm) = (bhp × 746) / ( supply cfm × motor efficiency )
A25: New Construction | B25: ACM 2025 | C25: PVAVAWHP (System 15), library, >10,000 cfm | D25: TSP = fan power × motor efficiency × fan efficiency × 6356 / 746 | E25: 0.65 | F25: 2025 ACM Table 12 ** | G25: 0.964 | H25: Fan power index: [ACM 2025, Table 13] Motor efficiency: [ACM 2025, Table 12]
C26: VAV (System 6), all other zones, >10,000 cfm | D26: TSP = fan power × motor efficiency × fan efficiency × 6356 / 746 | G26: 0.947
A28: * According to PNNL 20405 section 5.2.2.5, the full-load efficiency of the motor serving the fan is taken from ASHRAE 90.1, 2004, Table 10.8, based on motor nameplate and assuming enclosed motors operating at 1,800 rotations per minute (rpm) Motor nameplate size (bhp) = brake horsepower (bhp) × 1.1 ( using a 10% oversizing factor)
A29: ** The full‑load efficiency of the motor serving the fan is taken from ACM 2025 Table 12 based on the cfm of the fan. Brake horsepower (bhp) = (Supply cfm from sizing run × fan power in W/cfm) / 746. Note: Library is System 15 PVAVAWHP (ACM Table 13 >10,000 cfm = 0.964; 5,000–10,000 cfm = 1.022). Parallel fan-powered box fans, where used, are a separate 0.3 W/cfm. All other zones are System 6 (0.946, same as Hospital).

Sheet Thermostat
A1: ="Thermostat Setpoints - "&Prototype!A2 -> Thermostat Setpoints - Assembly
A2: Setpoint | B2: CZ1 | C2: CZ2 | D2: CZ3 | E2: CZ4 | F2: CZ5 | G2: CZ6 | H2: CZ7 | I2: CZ8 | J2: CZ9 | K2: CZ10 | L2: CZ11 | M2: CZ12 | N2: CZ13 | O2: CZ14 | P2: CZ15 | Q2: CZ16 | R2: Source
A3: Assembly Heating Setpoint (F) | B3: 70 | C3: 70 | D3: 70 | E3: 70 | F3: 70 | G3: 70 | H3: 70 | I3: 70 | J3: 70 | K3: 70 | L3: 70 | M3: 70 | N3: 70 | O3: 70 | P3: 70 | Q3: 70 | R3: T24 2022 - Appendix 5.4B
A4: Assembly Heating Setback (F) | B4: 60 | C4: 60 | D4: 60 | E4: 60 | F4: 60 | G4: 60 | H4: 60 | I4: 60 | J4: 60 | K4: 60 | L4: 60 | M4: 60 | N4: 60 | O4: 60 | P4: 60 | Q4: 60
A5: Assembly Cooling Setpoint (F) | B5: 75 | C5: 75 | D5: 75 | E5: 75 | F5: 75 | G5: 75 | H5: 75 | I5: 75 | J5: 75 | K5: 75 | L5: 75 | M5: 75 | N5: 75 | O5: 75 | P5: 75 | Q5: 75
A6: Assembly Cooling Setback (F) | B6: 85 | C6: 85 | D6: 85 | E6: 85 | F6: 85 | G6: 85 | H6: 85 | I6: 85 | J6: 85 | K6: 85 | L6: 85 | M6: 85 | N6: 85 | O6: 85 | P6: 85 | Q6: 85

Sheet Ventilation
A1: Outdoor Airflow Rate
A2: Space | B2: Number of People | C2: Floor Area (ft²) | D2: cfm/person [T24, 2025, Equation 120.1-F and Table 120.1-A] | E2: cfm/ft² [T24, 2025, Equation 120.1-F and Table 120.1-A] | F2: Required exhaust rate-CFM/ft²- [T24, 2025, Table 120.1-B – minimum exhaust rates] | G2: Total cfm driven by people | H2: Total cfm driven by area | I2: Total cfm driven by exhaust | J2: Total cfm | K2: Notes
A3: =Zones!B3 -> Exhibits and events_Conference Room | B3: =Zones!M3 -> 1056.924 | C3: =Zones!I3 -> 32028 | D3: 15 | E3: 0.15 | G3: =B3*D3 -> 15853.86 | H3: =C3*E3 -> 4804.2 | I3: =F3*C3 -> 0 | J3: =MAX(G3,H3,I3) -> 15853.86
A4: =Zones!B4 -> Exhibits and events_Theater Area | B4: =Zones!M4 -> 1895.7 | C4: =Zones!I4 -> 26700 | D4: 15 | E4: 0.15 | G4: =B4*D4 -> 28435.5 | H4: =C4*E4 -> 4005 | I4: =F4*C4 -> 0 | J4: =MAX(G4,H4,I4) -> 28435.5
A5: =Zones!B5 -> Exhibits and events_Auditorium Area | B5: =Zones!M5 -> 1893.144 | C5: =Zones!I5 -> 26664 | D5: 15 | E5: 0.15 | G5: =B5*D5 -> 28397.16 | H5: =C5*E5 -> 3999.6 | I5: =F5*C5 -> 0 | J5: =MAX(G5,H5,I5) -> 28397.16
A6: =Zones!B6 -> Exhibits and events_Museum Area Exhibition Display | B6: =Zones!M6 -> 362.508 | C6: =Zones!I6 -> 21324 | D6: 15 | E6: 0.15 | G6: =B6*D6 -> 5437.62 | H6: =C6*E6 -> 3198.6 | I6: =F6*C6 -> 0 | J6: =MAX(G6,H6,I6) -> 5437.62
A7: =Zones!B7 -> Library_Conference Room | B7: =Zones!M7 -> 42.9 | C7: =Zones!I7 -> 1300 | D7: 15 | E7: 0.15 | G7: =B7*D7 -> 643.5 | H7: =C7*E7 -> 195 | I7: =F7*C7 -> 0 | J7: =MAX(G7,H7,I7) -> 643.5
A8: =Zones!B8 -> Library_Reading Area | B8: =Zones!M8 -> 77.98 | C8: =Zones!I8 -> 7798 | D8: 15 | E8: 0.15 | G8: =B8*D8 -> 1169.7 | H8: =C8*E8 -> 1169.7 | I8: =F8*C8 -> 0 | J8: =MAX(G8,H8,I8) -> 1169.7
A9: =Zones!B9 -> Library_Stacks Area | B9: =Zones!M9 -> 155.96 | C9: =Zones!I9 -> 15596 | D9: 15 | E9: 0.15 | G9: =B9*D9 -> 2339.4 | H9: =C9*E9 -> 2339.4 | I9: =F9*C9 -> 0 | J9: =MAX(G9,H9,I9) -> 2339.4
A10: =Zones!B10 -> Library_Lobby Main Entry | B10: =Zones!M10 -> 42.9 | C10: =Zones!I10 -> 1300 | D10: 15 | E10: 0.15 | G10: =B10*D10 -> 643.5 | H10: =C10*E10 -> 195 | I10: =F10*C10 -> 0 | J10: =MAX(G10,H10,I10) -> 643.5
A11: =Zones!B11 -> Religious_Conference Room | B11: =Zones!M11 -> 204.633 | C11: =Zones!I11 -> 6201 | D11: 15 | E11: 0.15 | G11: =B11*D11 -> 3069.495 | H11: =C11*E11 -> 930.15 | I11: =F11*C11 -> 0 | J11: =MAX(G11,H11,I11) -> 3069.495
A12: =Zones!B12 -> Religious_General Office | B12: =Zones!M12 -> 31.005 | C12: =Zones!I12 -> 6201 | D12: 15 | E12: 0.15 | G12: =B12*D12 -> 465.075 | H12: =C12*E12 -> 930.15 | I12: =F12*C12 -> 0 | J12: =MAX(G12,H12,I12) -> 930.15
A13: =Zones!B13 -> Religious_Worship Area | B13: =Zones!M13 -> 3521.529 | C13: =Zones!I13 -> 49599 | D13: 15 | E13: 0.15 | G13: =B13*D13 -> 52822.935 | H13: =C13*E13 -> 7439.85 | I13: =F13*C13 -> 0 | J13: =MAX(G13,H13,I13) -> 52822.935
A14: =Zones!B14 -> Sports and recreation_GYM | B14: =Zones!M14 -> 810.55 | C14: =Zones!I14 -> 81055 | D14: 15 | E14: 0.15 | G14: =B14*D14 -> 12158.25 | H14: =C14*E14 -> 12158.25 | I14: =F14*C14 -> 0 | J14: =MAX(G14,H14,I14) -> 12158.25
A15: =Zones!B15 -> Sports and recreation_Locker Room | B15: =Zones!M15 -> 303.34 | C15: =Zones!I15 -> 15167 | D15: 15 | E15: 0.15 | F15: 0.5 | G15: =B15*D15 -> 4550.1 | H15: =C15*E15 -> 2275.05 | I15: =F15*C15 -> 7583.5 | J15: =MAX(G15,H15,I15) -> 7583.5
A16: =Zones!B16 -> Sports and recreation_Restroom | B16: =Zones!M16 -> 50.75 | C16: =Zones!I16 -> 5075 | D16: 0 | E16: 0 | F16: 50 Per Unit or ~0.5 cfm/ft2 | G16: =B16*D16 -> 0 | H16: =C16*E16 -> 0 | I16: =50*6 -> 300 | J16: =MAX(G16,H16,I16) -> 300 | K16: Restrooms in California per 2025 T24 require mechanical exhaust ventilation, but they do not require additional dedicated outdoor air (OA) beyond that local exhaust. Bathroom exhaust and exhaust fan energy will be captured in the models. We will assume make-up air is drawn from adjacent spaces.
A17: =Zones!B17 -> Terminals_Concourse | B17: =Zones!M17 -> 296.106 | C17: =Zones!I17 -> 17418 | D17: 15 | E17: 0.15 | G17: =B17*D17 -> 4441.59 | H17: =C17*E17 -> 2612.7 | I17: =F17*C17 -> 0 | J17: =MAX(G17,H17,I17) -> 4441.59
A18: =Zones!B18 -> Terminals_Baggage | B18: =Zones!M18 -> 31.779 | C18: =Zones!I18 -> 963 | D18: 15 | E18: 0.15 | G18: =B18*D18 -> 476.685 | H18: =C18*E18 -> 144.45 | I18: =F18*C18 -> 0 | J18: =MAX(G18,H18,I18) -> 476.685
A19: =Zones!B19 -> Terminals_Ticket | B19: =Zones!M19 -> 31.779 | C19: =Zones!I19 -> 963 | D19: 15 | E19: 0.15 | G19: =B19*D19 -> 476.685 | H19: =C19*E19 -> 144.45 | I19: =F19*C19 -> 0 | J19: =MAX(G19,H19,I19) -> 476.685

Sheet Water Heater
A1: Water Heater - Laboratory
A2: Vintage | B2: WH Type | C2: Efficiency | D2: Number of WH | E2: Tank Volume (gal) | F2: Tank Loss | G2: Source
A3: Existing | B3: Gas | C3: 0.8 | D3: 5 | E3: See table below for CZ-specific values: Climate Zone Water Heater Sizing and Loss Coefficients, Storage Volume column (col F) | F3: See table below: Climate Zone Water Heater Sizing and Loss Coefficients, Standby Loss column (col G) | G3: See table below for sources: Climate Zone Water Heater Sizing and Loss Coefficients
A4: New Construction | B4: Gas | C4: 0.8 | D4: 5 | E4: =E3 -> See table below for CZ-specific values: Climate Zone Water Heater Sizing and Loss Coefficients, Storage Volume column (col F) | F4: =F3 -> See table below: Climate Zone Water Heater Sizing and Loss Coefficients, Standby Loss column (col G) | G4: =G3 -> See table below for sources: Climate Zone Water Heater Sizing and Loss Coefficients
A6: Peak Hot Water Consumption
A7: Space Name | B7: Baseline WH Type [CEUS 2022] | C7: Total Area (ft²) | D7: Number of People | E7: Hot Water Usage Specification (gal/hr per person) [T24, 2022, Appendix 5.4A , sheet: "2022 SpaceFuncData-Input"] | F7: Peak Hot Water Usage (gal/hr) | G7: Peak Hot Water Usage (gal/min) | H7: Note
A8: =Zones!B3 -> Exhibits and events_Conference Room | B8: Gas | C8: =Zones!I3 -> 32028 | D8: =Zones!M3 -> 1056.924 | E8: 0.09 | F8: =E8*D8 -> 95.12316 | G8: =F8/60 -> 1.585386 | H8: For space types marked with an asterisk (the ‘*’ symbol), the water‑heater type is listed as electric in Appendix 5.4A, sheet ‘2022 SpaceFuncData‑Input.’ However, we modified the value based on CEUS data, which indicates that gas is the primary fuel type.
A9: =Zones!B4 -> Exhibits and events_Theater Area | B9: Gas | C9: =Zones!I4 -> 26700 | D9: =Zones!M4 -> 1895.7 | E9: 0.09 | F9: =E9*D9 -> 170.613 | G9: =F9/60 -> 2.84355
A10: =Zones!B5 -> Exhibits and events_Auditorium Area | B10: Gas | C10: =Zones!I5 -> 26664 | D10: =Zones!M5 -> 1893.144 | E10: 0.09 | F10: =E10*D10 -> 170.38296 | G10: =F10/60 -> 2.839716
A11: =Zones!B6 -> Exhibits and events_Museum Area Exhibition Display | B11: Gas | C11: =Zones!I6 -> 21324 | D11: =Zones!M6 -> 362.508 | E11: 0.09 | F11: =E11*D11 -> 32.62572 | G11: =F11/60 -> 0.543762
A12: =Zones!B7 -> Library_Conference Room | B12: Gas | C12: =Zones!I7 -> 1300 | D12: =Zones!M7 -> 42.9 | E12: 0.09 | F12: =E12*D12 -> 3.861 | G12: =F12/60 -> 0.06435
A13: =Zones!B8 -> Library_Reading Area | B13: Gas | C13: =Zones!I8 -> 7798 | D13: =Zones!M8 -> 77.98 | E13: 0.18 | F13: =E13*D13 -> 14.0364 | G13: =F13/60 -> 0.23394
A14: =Zones!B9 -> Library_Stacks Area | B14: Gas | C14: =Zones!I9 -> 15596 | D14: =Zones!M9 -> 155.96 | E14: 0.18 | F14: =E14*D14 -> 28.0728 | G14: =F14/60 -> 0.46788
A15: =Zones!B10 -> Library_Lobby Main Entry | B15: Gas | C15: =Zones!I10 -> 1300 | D15: =Zones!M10 -> 42.9 | E15: 0.09 | F15: =E15*D15 -> 3.861 | G15: =F15/60 -> 0.06435
A16: =Zones!B11 -> Religious_Conference Room | B16: Gas | C16: =Zones!I11 -> 6201 | D16: =Zones!M11 -> 204.633 | E16: 0.09 | F16: =E16*D16 -> 18.41697 | G16: =F16/60 -> 0.3069495
A17: =Zones!B12 -> Religious_General Office | B17: Gas | C17: =Zones!I12 -> 6201 | D17: =Zones!M12 -> 31.005 | E17: 0.18 | F17: =E17*D17 -> 5.5809 | G17: =F17/60 -> 0.093015
A18: =Zones!B13 -> Religious_Worship Area | B18: Gas | C18: =Zones!I13 -> 49599 | D18: =Zones!M13 -> 3521.529 | E18: 0.09 | F18: =E18*D18 -> 316.93761 | G18: =F18/60 -> 5.2822935
A19: =Zones!B14 -> Sports and recreation_GYM | B19: Gas | C19: =Zones!I14 -> 81055 | D19: =Zones!M14 -> 810.55 | E19: 0.18 | F19: =E19*D19 -> 145.899 | G19: =F19/60 -> 2.43165
A20: =Zones!B15 -> Sports and recreation_Locker Room | B20: Gas | C20: =Zones!I15 -> 15167 | D20: =Zones!M15 -> 303.34 | E20: 0.578 | F20: =E20*D20 -> 175.33052 | G20: =F20/60 -> 2.9221753
... A24: =Zones!B19 -> Terminals_Ticket | B24: Gas | C24: =Zones!I19 -> 963 | D24: =Zones!M19 -> 31.779 | E24: 0.18 | F24: =E24*D24 -> 5.72022 | G24: =F24/60 -> 0.095337
A25: Total | B25: Gas storage | F25: {=_xlfn.LET( _xlpm.g,SUMIF($B$8:$B$24,"Gas*",$F$8:$F$24), _xlpm.e,SUMIF($B$8:$B$24,"Electric*",$F$8:$F$24), IF(AND(_xlpm.g>0,_xlpm.e>0),_xlpm.g,IF(_xlpm.g>0,MAX(75,_xlpm.g),0)))} -> 1245.4806 | H25: Minimum peak hot water usage is 75 gal according to ACM 2025
A26: Total | B26: Electric resistance | F26: =_xlfn.LET( _xlpm.g,SUMIF($B$8:$B$24,"Gas*",$F$8:$F$24), _xlpm.e,SUMIF($B$8:$B$24,"Electric*",$F$8:$F$24), IF(AND(_xlpm.g>0,_xlpm.e>0),_xlpm.e,IF(_xlpm.e>0,MAX(75,_xlpm.e),0))) -> 0
A28: Plant peak hot water per building (gal/hr)
A29: Water Heater Name | B29: WH type | C29: Peak Hot Water Usage (gal/hr) | D29: Notes
A30: ExhibitBldg_WH | B30: Gas | C30: =SUM(F8:F11) -> 468.74484 | D30: Minimum peak hot water usage is 75 gal/hr according to ACM 2025, §5.9.2
A31: LibraryBldg_WH | B31: Gas | C31: =SUM(F12:F15) -> 49.8312
A32: ReligiousBldg_WH | B32: Gas | C32: =SUM(F16:F18) -> 340.93548
A33: SportsBldg_WH | B33: Gas | C33: =SUM(F19:F21) -> 321.22952
A34: TerminalsBldg_WH | B34: Gas | C34: =SUM(F22:F24) -> 64.73952
A37: Design supply temperature (°F) | B37: 135 | C37: CEC-400-2022-009-CMF-REV2-AP5.4B
A38: WH system factor | B38: 0.6 | C38: 2025 ACM §5.9.2 Rated Capacity
A39: Water mass conversion (lb/gal) | B39: 8.2877 | C39: 2025 ACM §5.9.2 Rated Capacity
A40: Reheat multiplier | B40: 0.4 | C40: 2025 ACM §5.9.2 Storage Volume
A41: Climate Zone Water Heater Sizing and Loss Coefficients
A42: Water Heater name | B42: Climate Zone | C42: Minimum Monthly Mains Temp (°F) [T24 2022 - Appendix 5.4B] | D42: Heat Output (Btu/hr) [ACM, 2025, 5.9.2: Rated capacity section] | E42: WH Capacity (Btu/hr) [ACM, 2025, 5.9.2: Rated capacity section] | F42: Required Energy Input (Btu/hr) | G42: Storage Volume (gal) | H42: Standby Loss [Title 20, §1605.1 Table F-4; Appendix B: Water Heating Calculation Method] | J42: Off/On Cycle Loss Coefficient to Ambient Temp | L42: Source/Note
A43: =$A$30 -> ExhibitBldg_WH | B43: CZ01 | C43: 47.9 | D43: =$C$30*($B$37-C43)*$B$39 -> 338367.53 | E43: =D43*$B$38 -> 203020.52 | F43: =_xlfn.LET(_xlpm.x,_xlfn.XLOOKUP(E43/$C$3,$A$128:$A$158,$A$128:$A$158,"",1),IF(_xlpm.x="",ROUNDUP(E43/$C$3,0),_xlpm.x)) -> 270000 | G43: =_xlfn.LET(_xlpm.v,MAX(30,$C$30*$B$40),_xlpm.x,_xlfn.XLOOKUP(_xlpm.v,$E$128:$E$146,$E$128:$E$146,"",1),IF(_xlpm.x="",ROUNDUP(_xlpm.v,0),_xlpm.x)) -> 188 | H43: =(F43/800)+110*SQRT(G43) -> 1845.744 | I43: Btu/hr | J43: =H43/70 -> 26.367772 | K43: Btu/h·°F | L43: Required Energy Input: vendor/available catalog size (Market data table). Storage Volume: standard/available catalog tank size (Market data table).
A44: =$A$30 -> ExhibitBldg_WH | B44: CZ02 | C44: 50.8 | D44: =$C$30*($B$37-C44)*$B$39 -> 327101.56 | E44: =D44*$B$38 -> 196260.94 | F44: =_xlfn.LET(_xlpm.x,_xlfn.XLOOKUP(E44/$C$3,$A$128:$A$158,$A$128:$A$158,"",1),IF(_xlpm.x="",ROUNDUP(E44/$C$3,0),_xlpm.x)) -> 250000 | G44: =_xlfn.LET(_xlpm.v,MAX(30,$C$30*$B$40),_xlpm.x,_xlfn.XLOOKUP(_xlpm.v,$E$128:$E$146,$E$128:$E$146,"",1),IF(_xlpm.x="",ROUNDUP(_xlpm.v,0),_xlpm.x)) -> 188 | H44: =(F44/800)+110*SQRT(G44) -> 1820.744 | I44: Btu/hr | J44: =H44/70 -> 26.010629 | K44: Btu/h·°F
A45: =$A$30 -> ExhibitBldg_WH | B45: CZ03 | C45: 52.2 | D45: =$C$30*($B$37-C45)*$B$39 -> 321662.82 | E45: =D45*$B$38 -> 192997.69 | F45: =_xlfn.LET(_xlpm.x,_xlfn.XLOOKUP(E45/$C$3,$A$128:$A$158,$A$128:$A$158,"",1),IF(_xlpm.x="",ROUNDUP(E45/$C$3,0),_xlpm.x)) -> 250000 | G45: =_xlfn.LET(_xlpm.v,MAX(30,$C$30*$B$40),_xlpm.x,_xlfn.XLOOKUP(_xlpm.v,$E$128:$E$146,$E$128:$E$146,"",1),IF(_xlpm.x="",ROUNDUP(_xlpm.v,0),_xlpm.x)) -> 188 | H45: =(F45/800)+110*SQRT(G45) -> 1820.744 | I45: Btu/hr | J45: =H45/70 -> 26.010629 | K45: Btu/h·°F
A46: =$A$30 -> ExhibitBldg_WH | B46: CZ04 | C46: 52.7 | D46: =$C$30*($B$37-C46)*$B$39 -> 319720.41 | E46: =D46*$B$38 -> 191832.24 | F46: =_xlfn.LET(_xlpm.x,_xlfn.XLOOKUP(E46/$C$3,$A$128:$A$158,$A$128:$A$158,"",1),IF(_xlpm.x="",ROUNDUP(E46/$C$3,0),_xlpm.x)) -> 250000 | G46: =_xlfn.LET(_xlpm.v,MAX(30,$C$30*$B$40),_xlpm.x,_xlfn.XLOOKUP(_xlpm.v,$E$128:$E$146,$E$128:$E$146,"",1),IF(_xlpm.x="",ROUNDUP(_xlpm.v,0),_xlpm.x)) -> 188 | H46: =(F46/800)+110*SQRT(G46) -> 1820.744 | I46: Btu/hr | J46: =H46/70 -> 26.010629 | K46: Btu/h·°F
A47: =$A$30 -> ExhibitBldg_WH | B47: CZ05 | C47: 51.6 | D47: =$C$30*($B$37-C47)*$B$39 -> 323993.71 | E47: =D47*$B$38 -> 194396.22 | F47: =_xlfn.LET(_xlpm.x,_xlfn.XLOOKUP(E47/$C$3,$A$128:$A$158,$A$128:$A$158,"",1),IF(_xlpm.x="",ROUNDUP(E47/$C$3,0),_xlpm.x)) -> 250000 | G47: =_xlfn.LET(_xlpm.v,MAX(30,$C$30*$B$40),_xlpm.x,_xlfn.XLOOKUP(_xlpm.v,$E$128:$E$146,$E$128:$E$146,"",1),IF(_xlpm.x="",ROUNDUP(_xlpm.v,0),_xlpm.x)) -> 188 | H47: =(F47/800)+110*SQRT(G47) -> 1820.744 | I47: Btu/hr | J47: =H47/70 -> 26.010629 | K47: Btu/h·°F
...

Sheet Interior Lights
A1: ="Interior Lighting - "&Prototype!B4 -> Interior Lighting - Assembly
A2: Space Type | B2: New Construction | E2: Existing | H2: Notes
B3: Lighting density (W/ft²) | C3: Additional lighting power for portable lighting (W/ft²) | D3: Source | E3: LPD (W/ft²) | F3: Additional LPD for Portable Lighting (W/ft²) | G3: Source
A4: Convention, Conference, Multipurpose and Meeting Area | B4: 0.75 | C4: =0.25*0.5 -> 0.125 | D4: T24, 2025, Table 140.6 C (Area category method) | E4: 1.2 | F4: =0.5*0.5 -> 0.25 | G4: T24, 2016, Table 140.6 C (Area category method)
A5: Theater Area (Motion Picture) | B5: 0.5 | E5: 0.9
A6: Auditorium Area | B6: 0.5 | E6: 1.4
A7: Museum Area (Exhibition/Display) | B7: 0.6 | E7: 1.8
A8: Library (Reading Area) | B8: 0.8 | E8: 1.1
A9: Library (Stacks Area) | B9: 1 | E9: 1.5
A10: Lobby, Main Entry | B10: 0.7 | C10: =0.25*0.5 -> 0.125 | E10: 0.95 | F10: =0.5*0.5 -> 0.25 | H10: It is assumed that 50% of the additional allowance lighting is in use.
A11: Office Area (>250 square feet) | B11: 0.6 | C11: 0.1 | E11: 0.75 | H11: It is assumed that 50% of the additional allowance lighting is in use.
A12: Religious Worship Area | B12: 0.95 | E12: 1.5
A13: Exercise/Fitness Center and Gymnasium Areas | B13: 0.5 | E13: 1
A14: Locker Room | B14: 0.45 | E14: 0.7
A15: Restrooms | B15: 0.65 | E15: 0.6
A16: Concourse and Atria Area | B16: 0.6 | E16: 0.95
A17: Transportation Function (Baggage Area) | B17: 0.4 | E17: 0.5
A18: Transportation Function (Ticketing Area) | B18: 0.45 | E18: 1

Sheet Ext Lighting
A1: ="Exterior Lighting - "&Prototype!B4 -> Exterior Lighting - Assembly
A2: Motion Controlled Luminaires (W) | B2: Non-motion Controlled Luminaires (W) | C2: Total (W) | D2: Source
A3: =G14 -> 9861.697 | B3: =G15 -> 1957.325 | C3: =A3+B3 -> 11819.022 | D3: T24, 2022 & 2025 2019 Outdoor Lighting CASE report PNNL 90.1-2010 TSD
A7: ="Exterior Lighting" -> Exterior Lighting
A8: Items (Assume LZ2) | B8: Assumptions [2019 Outdoor Lighting CASE Report & PNNL 90.1-2010 TS] | D8: Unit | E8: Lighting Power Allowance [T24, 2025, Table 140.7-A & 140.7-B] | F8: Unit | G8: Exterior Lighting Power (W)
A9: IWA (Initial Wattage Allowance) | E9: 200 | F9: (W) | G9: =$E9 -> 200
A10: Parking area | B10: 400 ft² for every parking space 1 parking space per 830 ft² of gross building area | C10: 504563 | D10: (ft²) | E10: 0.019 | F10: (W/ft²) | G10: =E10*C10 -> 9586.697
A11: Building Entrance | B11: 5 building entrance per PNNL Model | C11: 5 | D11: (count) | E11: 15 | F11: (W/ea) | G11: =E11*C11 -> 75
A12: Hardscape Ornamental Light | B12: 0.1 ft² per 1 ft² of gross building area for hardscape ornamental light | C12: 31535 | D12: (ft²) | E12: 0.007 | F12: (W/ft²) | G12: =E12*C12 -> 220.745
A13: Building façade | B13: 0.1 W per 1 ft² of facade area Façade Area = Perimeter × 0.5 × max ( height and 30) (30 ft is the max height that is lit) * The 0.5 factor assumes that only half of the perimeter walls are lit. -Formula is developed based on the 2019 Outdoor Lighting CASE report | C13: =0.5*4*(B20*B21+C20*C21+D20*D21+E20*E21+F20*F21) -> 17365.8 | D13: (ft²) | E13: 0.1 | F13: (W/ft²) | G13: =E13*C13 -> 1736.58
A14: Motion Controlled Luminaires (W) | G14: =G10+G9+G11 -> 9861.697
A15: Non-motion-controlled Luminaires | G15: =G12+G13 -> 1957.325
A16: Total | G16: =G14+G15 -> 11819.022
A19: Total floor area | B19: =Prototype!B9 -> 315352
A20: side each buildings (ft) | B20: 114 | C20: 94.3 | D20: 80.3 | E20: 59.1 | F20: 83
A21: max Height that is lit for each buildings (ft) | B21: 13 | C21: 13 | D21: 25 | E21: 25 | F21: 30
A22: Floors
B23: 3

Sheet Equipment
A1: ="Equipment - "&Prototype!B4 -> Equipment - Assembly
A2: Space Type | B2: Plug load Power Density (W/ft²) | C2: Gas Power Density (Btu/hr-ft²) | D2: Refrigeration Power Density (W/ft²) | E2: Source
A3: Convention, Conference, Multipurpose and Meeting Area | B3: 1 | C3: 0 | D3: 0 | E3: T24 2022 - Appendix 5.4A
A4: Theater Area (Motion Picture) | B4: 0.5 | C4: 0 | D4: 0
A5: Auditorium Area | B5: 1 | C5: 0 | D5: 0
A6: Museum Area (Exhibition/Display) | B6: 1.5 | C6: 0 | D6: 0
A7: Library (Reading Area) | B7: 1.5 | C7: 0 | D7: 0
A8: Library (Stacks Area) | B8: 1.5 | C8: 0 | D8: 0
A9: Lobby, Main Entry | B9: 0.5 | C9: 0 | D9: 0
A10: Office Area (>250 square feet) | B10: 0.7 | C10: 0 | D10: 0 | E10: Plug load and schedules project with CEC, 2025
A11: Religious Worship Area | B11: 0.5 | C11: 0 | D11: 0 | E11: T24 2022 - Appendix 5.4A
A12: Exercise/Fitness Center and Gymnasium Areas | B12: 0.5 | C12: 0 | D12: 0
A13: Locker Room | B13: 0.5 | C13: 0 | D13: 0
A14: Restrooms | B14: 0 | C14: 0 | D14: 0
A15: Concourse and Atria Area | B15: 0.5 | C15: 0 | D15: 0
A16: Transportation Function (Baggage Area) | B16: 0.5 | C16: 0 | D16: 0
A17: Transportation Function (Ticketing Area) | B17: 0.5 | C17: 0 | D17: 0

Sheet Schedules
A1: ="Schedules - "&Prototype!B4 -> Schedules - Assembly
A2: Zone | B2: Schedule Category | C2: Schedule | D2: Source | E2: Type | F2: Hour
F3: 1 | G3: 2 | H3: 3 | I3: 4 | J3: 5 | K3: 6 | L3: 7 | M3: 8 | N3: 9 | O3: 10 | P3: 11 | Q3: 12 | R3: 13 | S3: 14 | T3: 15 | U3: 16 | V3: 17 | W3: 18 | X3: 19 | Y3: 20 | Z3: 21 | AA3: 22 | AB3: 23 | AC3: 24
A4: All the Zones except Office | B4: Assembly | C4: Occupancy | D4: T24 2022 - Appendix 5.4B, [Assembly] | E4: Weekday | F4: 0 | G4: 0 | H4: 0 | I4: 0 | J4: 0 | K4: 0 | L4: 0 | M4: 0 | N4: 0.2 | O4: 0.2 | P4: 0.2 | Q4: 0.8 | R4: 0.8 | S4: 0.8 | T4: 0.8 | U4: 0.8 | V4: 0.8 | W4: 0.8 | X4: 0.2 | Y4: 0.2 | Z4: 0.2 | AA4: 0.2 | AB4: 0.1 | AC4: 0
E5: Saturday | F5: 0 | G5: 0 | H5: 0 | I5: 0 | J5: 0 | K5: 0 | L5: 0 | M5: 0 | N5: 0.2 | O5: 0.2 | P5: 0.2 | Q5: 0.6 | R5: 0.6 | S5: 0.6 | T5: 0.6 | U5: 0.6 | V5: 0.6 | W5: 0.6 | X5: 0.6 | Y5: 0.6 | Z5: 0.6 | AA5: 0.8 | AB5: 0.1 | AC5: 0
E6: Sunday | F6: 0 | G6: 0 | H6: 0 | I6: 0 | J6: 0 | K6: 0 | L6: 0 | M6: 0 | N6: 0.1 | O6: 0.1 | P6: 0.1 | Q6: 0.1 | R6: 0.1 | S6: 0.7 | T6: 0.7 | U6: 0.7 | V6: 0.7 | W6: 0.7 | X6: 0.7 | Y6: 0.7 | Z6: 0.7 | AA6: 0.7 | AB6: 0.2 | AC6: 0
A7: All the Zones except Office and Storage | B7: Assembly | C7: Lights | D7: T24 2022 - Appendix 5.4B, [Assembly] | E7: Weekday | F7: 0.05 | G7: 0.05 | H7: 0.05 | I7: 0.05 | J7: 0.05 | K7: 0.05 | L7: 0.35 | M7: 0.35 | N7: 0.35 | O7: 0.65 | P7: 0.65 | Q7: 0.65 | R7: 0.65 | S7: 0.65 | T7: 0.65 | U7: 0.65 | V7: 0.65 | W7: 0.65 | X7: 0.65 | Y7: 0.65 | Z7: 0.65 | AA7: 0.65 | AB7: 0.25 | AC7: 0.05
E8: Saturday | F8: 0.05 | G8: 0.05 | H8: 0.05 | I8: 0.05 | J8: 0.05 | K8: 0.05 | L8: 0.05 | M8: 0.3 | N8: 0.3 | O8: 0.4 | P8: 0.4 | Q8: 0.4 | R8: 0.4 | S8: 0.4 | T8: 0.4 | U8: 0.4 | V8: 0.4 | W8: 0.4 | X8: 0.4 | Y8: 0.4 | Z8: 0.4 | AA8: 0.4 | AB8: 0.4 | AC8: 0.05
E9: Sunday | F9: 0.05 | G9: 0.05 | H9: 0.05 | I9: 0.05 | J9: 0.05 | K9: 0.05 | L9: 0.05 | M9: 0.3 | N9: 0.3 | O9: 0.3 | P9: 0.3 | Q9: 0.3 | R9: 0.55 | S9: 0.55 | T9: 0.55 | U9: 0.55 | V9: 0.55 | W9: 0.55 | X9: 0.55 | Y9: 0.55 | Z9: 0.55 | AA9: 0.55 | AB9: 0.05 | AC9: 0.05
A10: All the Zones except Office | B10: Assembly | C10: ElecEquipment | D10: T24 2022 - Appendix 5.4B, [Assembly] | E10: Weekday | F10: 0.05 | G10: 0.05 | H10: 0.05 | I10: 0.05 | J10: 0.05 | K10: 0.05 | L10: 0.4 | M10: 0.4 | N10: 0.4 | O10: 0.75 | P10: 0.75 | Q10: 0.75 | R10: 0.75 | S10: 0.75 | T10: 0.75 | U10: 0.75 | V10: 0.75 | W10: 0.75 | X10: 0.75 | Y10: 0.75 | Z10: 0.75 | AA10: 0.75 | AB10: 0.25 | AC10: 0.05
E11: Saturday | F11: 0.05 | G11: 0.05 | H11: 0.05 | I11: 0.05 | J11: 0.05 | K11: 0.05 | L11: 0.05 | M11: 0.3 | N11: 0.3 | O11: 0.5 | P11: 0.5 | Q11: 0.5 | R11: 0.5 | S11: 0.5 | T11: 0.5 | U11: 0.5 | V11: 0.5 | W11: 0.5 | X11: 0.5 | Y11: 0.5 | Z11: 0.5 | AA11: 0.5 | AB11: 0.5 | AC11: 0.05
E12: Sunday | F12: 0.05 | G12: 0.05 | H12: 0.05 | I12: 0.05 | J12: 0.05 | K12: 0.05 | L12: 0.05 | M12: 0.3 | N12: 0.3 | O12: 0.3 | P12: 0.3 | Q12: 0.3 | R12: 0.65 | S12: 0.65 | T12: 0.65 | U12: 0.65 | V12: 0.65 | W12: 0.65 | X12: 0.65 | Y12: 0.65 | Z12: 0.65 | AA12: 0.65 | AB12: 0.05 | AC12: 0.05
A13: All the Zones except Office | B13: Assembly | C13: ServiceHotWater | D13: T24 2022 - Appendix 5.4B, [Assembly] | E13: Weekday | F13: 0 | G13: 0 | H13: 0 | I13: 0 | J13: 0 | K13: 0 | L13: 0 | M13: 0 | N13: 0 | O13: 0.05 | P13: 0.05 | Q13: 0.35 | R13: 0.05 | S13: 0.05 | T13: 0.05 | U13: 0.05 | V13: 0.05 | W13: 0 | X13: 0 | Y13: 0 | Z13: 0 | AA13: 0 | AB13: 0 | AC13: 0
E14: Saturday | F14: 0 | G14: 0 | H14: 0 | I14: 0 | J14: 0 | K14: 0 | L14: 0 | M14: 0 | N14: 0 | O14: 0.05 | P14: 0.05 | Q14: 0.2 | R14: 0 | S14: 0 | T14: 0 | U14: 0 | V14: 0 | W14: 0 | X14: 0 | Y14: 0.65 | Z14: 0.3 | AA14: 0 | AB14: 0 | AC14: 0
E15: Sunday | F15: 0 | G15: 0 | H15: 0 | I15: 0 | J15: 0 | K15: 0 | L15: 0 | M15: 0 | N15: 0 | O15: 0.05 | P15: 0.05 | Q15: 0.1 | R15: 0 | S15: 0 | T15: 0 | U15: 0 | V15: 0 | W15: 0 | X15: 0 | Y15: 0.65 | Z15: 0.3 | AA15: 0 | AB15: 0 | AC15: 0
A16: All the Zones except Office | B16: Assembly | C16: GasEquipment | D16: T24 2022 - Appendix 5.4B, [Assembly] | E16: Weekday | F16: 0 | G16: 0 | H16: 0 | I16: 0 | J16: 0 | K16: 0 | L16: 0 | M16: 0 | N16: 0.3 | O16: 0.3 | P16: 0.2 | Q16: 0.9 | R16: 0.9 | S16: 0.9 | T16: 0.2 | U16: 0.2 | V16: 0.2 | W16: 0.5 | X16: 0.5 | Y16: 0.1 | Z16: 0.1 | AA16: 0.1 | AB16: 0 | AC16: 0
E17: Saturday | F17: 0 | G17: 0 | H17: 0 | I17: 0 | J17: 0 | K17: 0 | L17: 0 | M17: 0 | N17: 0.3 | O17: 0.3 | P17: 0.2 | Q17: 0.7 | R17: 0.7 | S17: 0.7 | T17: 0.2 | U17: 0.2 | V17: 0.2 | W17: 0.4 | X17: 0.4 | Y17: 0.1 | Z17: 0.1 | AA17: 0.1 | AB17: 0 | AC17: 0
E18: Sunday | F18: 0 | G18: 0 | H18: 0 | I18: 0 | J18: 0 | K18: 0 | L18: 0 | M18: 0 | N18: 0.2 | O18: 0.2 | P18: 0.1 | Q18: 0.1 | R18: 0.3 | S18: 0.8 | T18: 0.2 | U18: 0.2 | V18: 0.2 | W18: 0.5 | X18: 0.5 | Y18: 0.1 | Z18: 0.1 | AA18: 0.1 | AB18: 0 | AC18: 0
A19: All the Zones except Office | B19: Assembly | C19: Refrigeration | D19: T24 2022 - Appendix 5.4B, [Assembly] | E19: Weekday | F19: 0.9 | G19: 0.9 | H19: 0.9 | I19: 0.9 | J19: 0.9 | K19: 0.9 | L19: 0.9 | M19: 0.9 | N19: 0.9 | O19: 0.9 | P19: 0.9 | Q19: 0.9 | R19: 0.9 | S19: 0.9 | T19: 0.9 | U19: 0.9 | V19: 0.9 | W19: 0.9 | X19: 0.9 | Y19: 0.9 | Z19: 0.9 | AA19: 0.9 | AB19: 0.9 | AC19: 0.9
E20: Saturday | F20: 0.9 | G20: 0.9 | H20: 0.9 | I20: 0.9 | J20: 0.9 | K20: 0.9 | L20: 0.9 | M20: 0.9 | N20: 0.9 | O20: 0.9 | P20: 0.9 | Q20: 0.9 | R20: 0.9 | S20: 0.9 | T20: 0.9 | U20: 0.9 | V20: 0.9 | W20: 0.9 | X20: 0.9 | Y20: 0.9 | Z20: 0.9 | AA20: 0.9 | AB20: 0.9 | AC20: 0.9
E21: Sunday | F21: 0.9 | G21: 0.9 | H21: 0.9 | I21: 0.9 | J21: 0.9 | K21: 0.9 | L21: 0.9 | M21: 0.9 | N21: 0.9 | O21: 0.9 | P21: 0.9 | Q21: 0.9 | R21: 0.9 | S21: 0.9 | T21: 0.9 | U21: 0.9 | V21: 0.9 | W21: 0.9 | X21: 0.9 | Y21: 0.9 | Z21: 0.9 | AA21: 0.9 | AB21: 0.9 | AC21: 0.9
A22: All the Zones except Office | B22: Assembly | C22: HVACAvail | D22: T24 2022 - Appendix 5.4B, [Assembly] | E22: Weekday | F22: 0 | G22: 0 | H22: 0 | I22: 0 | J22: 0 | K22: 0 | L22: 0 | M22: 1 | N22: 1 | O22: 1 | P22: 1 | Q22: 1 | R22: 1 | S22: 1 | T22: 1 | U22: 1 | V22: 1 | W22: 1 | X22: 1 | Y22: 1 | Z22: 1 | AA22: 1 | AB22: 1 | AC22: 0
E23: Saturday | F23: 0 | G23: 0 | H23: 0 | I23: 0 | J23: 0 | K23: 0 | L23: 0 | M23: 1 | N23: 1 | O23: 1 | P23: 1 | Q23: 1 | R23: 1 | S23: 1 | T23: 1 | U23: 1 | V23: 1 | W23: 1 | X23: 1 | Y23: 1 | Z23: 1 | AA23: 1 | AB23: 1 | AC23: 0
E24: Sunday | F24: 0 | G24: 0 | H24: 0 | I24: 0 | J24: 0 | K24: 0 | L24: 0 | M24: 1 | N24: 1 | O24: 1 | P24: 1 | Q24: 1 | R24: 1 | S24: 1 | T24: 1 | U24: 1 | V24: 1 | W24: 1 | X24: 1 | Y24: 1 | Z24: 1 | AA24: 1 | AB24: 1 | AC24: 0
A25: All the Zones except Office | B25: Assembly | C25: Infiltration | D25: T24 2022 - Appendix 5.4B, [Assembly] | E25: Weekday | F25: =IF(F4=0,1,0.25) -> 1 | G25: =IF(G4=0,1,0.25) -> 1 | H25: =IF(H4=0,1,0.25) -> 1 | I25: =IF(I4=0,1,0.25) -> 1 | J25: =IF(J4=0,1,0.25) -> 1 | K25: =IF(K4=0,1,0.25) -> 1 | L25: =IF(L4=0,1,0.25) -> 1 | M25: =IF(M4=0,1,0.25) -> 1 | ... AC25: =IF(AC4=0,1,0.25) -> 1
E26: Saturday | F26: =IF(F5=0,1,0.25) -> 1 | G26: =IF(G5=0,1,0.25) -> 1 | H26: =IF(H5=0,1,0.25) -> 1 | I26: =IF(I5=0,1,0.25) -> 1 | J26: =IF(J5=0,1,0.25) -> 1 | K26: =IF(K5=0,1,0.25) -> 1 | L26: =IF(L5=0,1,0.25) -> 1 | M26: =IF(M5=0,1,0.25) -> 1 | ... AC26: =IF(AC5=0,1,0.25) -> 1
E27: Sunday | F27: =IF(F6=0,1,0.25) -> 1 | G27: =IF(G6=0,1,0.25) -> 1 | H27: =IF(H6=0,1,0.25) -> 1 | I27: =IF(I6=0,1,0.25) -> 1 | J27: =IF(J6=0,1,0.25) -> 1 | K27: =IF(K6=0,1,0.25) -> 1 | L27: =IF(L6=0,1,0.25) -> 1 | M27: =IF(M6=0,1,0.25) -> 1 | ... AC27: =IF(AC6=0,1,0.25) -> 1
A28: All the Zones except Office | B28: Assembly | C28: HtgSetpt | D28: T24 2022 - Appendix 5.4B, [Assembly] | E28: Weekday | F28: =IF(F22=1,Thermostat!$B$3,Thermostat!$B$4) -> 60 | G28: =IF(G22=1,Thermostat!$B$3,Thermostat!$B$4) -> 60 | H28: =IF(H22=1,Thermostat!$B$3,Thermostat!$B$4) -> 60 | I28: =IF(I22=1,Thermostat!$B$3,Thermostat!$B$4) -> 60 | J28: =IF(J22=1,Thermostat!$B$3,Thermostat!$B$4) -> 60 | K28: =IF(K22=1,Thermostat!$B$3,Thermostat!$B$4) -> 60 | L28: =IF(L22=1,Thermostat!$B$3,Thermostat!$B$4) -> 60 | M28: =IF(M22=1,Thermostat!$B$3,Thermostat!$B$4) -> 70 | ... AC28: =IF(AC22=1,Thermostat!$B$3,Thermostat!$B$4) -> 60
E29: Saturday | F29: =IF(F23=1,Thermostat!$B$3,Thermostat!$B$4) -> 60 | G29: =IF(G23=1,Thermostat!$B$3,Thermostat!$B$4) -> 60 | H29: =IF(H23=1,Thermostat!$B$3,Thermostat!$B$4) -> 60 | I29: =IF(I23=1,Thermostat!$B$3,Thermostat!$B$4) -> 60 | J29: =IF(J23=1,Thermostat!$B$3,Thermostat!$B$4) -> 60 | K29: =IF(K23=1,Thermostat!$B$3,Thermostat!$B$4) -> 60 | L29: =IF(L23=1,Thermostat!$B$3,Thermostat!$B$4) -> 60 | M29: =IF(M23=1,Thermostat!$B$3,Thermostat!$B$4) -> 70 | ... AC29: =IF(AC23=1,Thermostat!$B$3,Thermostat!$B$4) -> 60
E30: Sunday | F30: =IF(F24=1,Thermostat!$B$3,Thermostat!$B$4) -> 60 | G30: =IF(G24=1,Thermostat!$B$3,Thermostat!$B$4) -> 60 | H30: =IF(H24=1,Thermostat!$B$3,Thermostat!$B$4) -> 60 | I30: =IF(I24=1,Thermostat!$B$3,Thermostat!$B$4) -> 60 | J30: =IF(J24=1,Thermostat!$B$3,Thermostat!$B$4) -> 60 | K30: =IF(K24=1,Thermostat!$B$3,Thermostat!$B$4) -> 60 | L30: =IF(L24=1,Thermostat!$B$3,Thermostat!$B$4) -> 60 | M30: =IF(M24=1,Thermostat!$B$3,Thermostat!$B$4) -> 70 | ... AC30: =IF(AC24=1,Thermostat!$B$3,Thermostat!$B$4) -> 60
A31: All the Zones except Office | B31: Assembly | C31: ClgSetpt | D31: T24 2022 - Appendix 5.4B, [Assembly] | E31: Weekday | F31: =IF(F22=1,Thermostat!$B$5,Thermostat!$B$6) -> 85 | G31: =IF(G22=1,Thermostat!$B$5,Thermostat!$B$6) -> 85 | H31: =IF(H22=1,Thermostat!$B$5,Thermostat!$B$6) -> 85 | I31: =IF(I22=1,Thermostat!$B$5,Thermostat!$B$6) -> 85 | J31: =IF(J22=1,Thermostat!$B$5,Thermostat!$B$6) -> 85 | K31: =IF(K22=1,Thermostat!$B$5,Thermostat!$B$6) -> 85 | L31: =IF(L22=1,Thermostat!$B$5,Thermostat!$B$6) -> 85 | M31: =IF(M22=1,Thermostat!$B$5,Thermostat!$B$6) -> 75 | ... AC31: =IF(AC22=1,Thermostat!$B$5,Thermostat!$B$6) -> 85
E32: Saturday | F32: =IF(F23=1,Thermostat!$B$5,Thermostat!$B$6) -> 85 | G32: =IF(G23=1,Thermostat!$B$5,Thermostat!$B$6) -> 85 | H32: =IF(H23=1,Thermostat!$B$5,Thermostat!$B$6) -> 85 | I32: =IF(I23=1,Thermostat!$B$5,Thermostat!$B$6) -> 85 | J32: =IF(J23=1,Thermostat!$B$5,Thermostat!$B$6) -> 85 | K32: =IF(K23=1,Thermostat!$B$5,Thermostat!$B$6) -> 85 | L32: =IF(L23=1,Thermostat!$B$5,Thermostat!$B$6) -> 85 | M32: =IF(M23=1,Thermostat!$B$5,Thermostat!$B$6) -> 75 | ... AC32: =IF(AC23=1,Thermostat!$B$5,Thermostat!$B$6) -> 85
E33: Sunday | F33: =IF(F24=1,Thermostat!$B$5,Thermostat!$B$6) -> 85 | G33: =IF(G24=1,Thermostat!$B$5,Thermostat!$B$6) -> 85 | H33: =IF(H24=1,Thermostat!$B$5,Thermostat!$B$6) -> 85 | I33: =IF(I24=1,Thermostat!$B$5,Thermostat!$B$6) -> 85 | J33: =IF(J24=1,Thermostat!$B$5,Thermostat!$B$6) -> 85 | K33: =IF(K24=1,Thermostat!$B$5,Thermostat!$B$6) -> 85 | L33: =IF(L24=1,Thermostat!$B$5,Thermostat!$B$6) -> 85 | M33: =IF(M24=1,Thermostat!$B$5,Thermostat!$B$6) -> 75 | ... AC33: =IF(AC24=1,Thermostat!$B$5,Thermostat!$B$6) -> 85
A34: Office | C34: Other
A35: Office | B35: Office | C35: Occupancy | D35: T24 2022 - Appendix 5.4B, [Office] Updated based on Plug load and schedules project with CEC, 2025 | E35: Weekday | F35: 0 | G35: 0 | H35: 0 | I35: 0 | J35: 0 | K35: 0 | L35: 0.1 | M35: 0.2 | N35: 0.95 | O35: 0.95 | P35: 0.95 | Q35: 0.95 | R35: 0.5 | S35: 0.95 | T35: 0.95 | U35: 0.95 | V35: 0.95 | W35: 0.3 | X35: 0.1 | Y35: 0.1 | Z35: 0.1 | AA35: 0.1 | AB35: 0.05 | AC35: 0.05
E36: Saturday | F36: 0 | G36: 0 | H36: 0 | I36: 0 | J36: 0 | K36: 0 | L36: 0.05 | M36: 0.05 | N36: 0.05 | O36: 0.05 | P36: 0.05 | Q36: 0.05 | R36: 0.05 | S36: 0.05 | T36: 0.05 | U36: 0.05 | V36: 0.05 | W36: 0.05 | X36: 0 | Y36: 0 | Z36: 0 | AA36: 0 | AB36: 0 | AC36: 0
E37: Sunday | F37: 0 | G37: 0 | H37: 0 | I37: 0 | J37: 0 | K37: 0 | L37: 0.05 | M37: 0.05 | N37: 0.05 | O37: 0.05 | P37: 0.05 | Q37: 0.05 | R37: 0.05 | S37: 0.05 | T37: 0.05 | U37: 0.05 | V37: 0.05 | W37: 0.05 | X37: 0 | Y37: 0 | Z37: 0 | AA37: 0 | AB37: 0 | AC37: 0
A38: Office | B38: Office | C38: Lights | D38: T24 2022 - Appendix 5.4B, [Office] | E38: Weekday | F38: 0.05 | G38: 0.05 | H38: 0.05 | I38: 0.05 | J38: 0.05 | K38: 0.1 | L38: 0.1 | M38: 0.3 | N38: 0.65 | O38: 0.65 | P38: 0.65 | Q38: 0.65 | R38: 0.65 | S38: 0.65 | T38: 0.65 | U38: 0.65 | V38: 0.65 | W38: 0.35 | X38: 0.3 | Y38: 0.3 | Z38: 0.2 | AA38: 0.2 | AB38: 0.1 | AC38: 0.05
E39: Saturday | F39: 0.05 | G39: 0.05 | H39: 0.05 | I39: 0.05 | J39: 0.05 | K39: 0.05 | L39: 0.05 | M39: 0.05 | N39: 0.05 | O39: 0.05 | P39: 0.05 | Q39: 0.05 | R39: 0.05 | S39: 0.05 | T39: 0.05 | U39: 0.05 | V39: 0.05 | W39: 0.05 | X39: 0.05 | Y39: 0.05 | Z39: 0.05 | AA39: 0.05 | AB39: 0.05 | AC39: 0.05
E40: Sunday | F40: 0.05 | G40: 0.05 | H40: 0.05 | I40: 0.05 | J40: 0.05 | K40: 0.05 | L40: 0.05 | M40: 0.05 | N40: 0.05 | O40: 0.05 | P40: 0.05 | Q40: 0.05 | R40: 0.05 | S40: 0.05 | T40: 0.05 | U40: 0.05 | V40: 0.05 | W40: 0.05 | X40: 0.05 | Y40: 0.05 | Z40: 0.05 | AA40: 0.05 | AB40: 0.05 | AC40: 0.05
...

Sheet Weights
A1: ="% of Floor Area per CZ and Vintage Bin - "&Prototype!A2 -> % of Floor Area per CZ and Vintage Bin - Assembly | J1: ="% of Floor Area per CZ and Vintage Bin - "&Prototype!A2 -> % of Floor Area per CZ and Vintage Bin - Assembly
A2: Prototype | B2: CZ | C2: Vintage Bin | J2: Prototype | K2: Vintage Bin | L2: CZ
C3: Pre-1978 | D3: 1978-1997 | E3: 1998-2007 | F3: 2008-2018 | G3: Not available | L3: 1 | M3: 2 | N3: 3 | O3: 4 | P3: 5 | Q3: 6 | R3: 7 | S3: 8 | T3: 9 | U3: 10 | V3: 11 | W3: 12 | X3: 13 | Y3: 14 | Z3: 15 | AA3: 16
