Workbook
Name nonparticipating_forecastzone_scale_factor: #REF!
Name nonparticipating_forecastzone_scale_factor: #REF!
Name nonparticipating_forecastzone_scale_factor: 'Energy Usage'!#REF!
Name Space_Function: Data!$A$2:$A$76

Sheet Notes
A1: Data Sources
A2: Dataset | B2: Dodge 2023
B3: Commercial End-Use Survey (CEUS) 2022 | C3: https://www.energy.ca.gov/publications/2023/2022-california-commercial-end-use-survey-ceus-final-report
B4: Commercial Buildings Energy Consumption Survey (CBECS) 2018 | C4: https://www.eia.gov/consumption/commercial/data/2018/
B5: ComStock 2023 | C5: https://comstock.nlr.gov/page/datasets
A7: Prototype | B7: California Energy Commission (CEC) Hospital prototype (CBECC 2022.3.1) | C7: https://bees.noresco.com/software2022.html
B8: Pacific Northwest National Laboratory (PNNL) Hospital prototype (90.1-2022, 2019, 2013) | C8: https://www.energycodes.gov/prototype-building-models#Commercial
B9: Database for Energy Efficient Resources (DEER) Hospital prototype (June 2023) | C9: https://github.com/sound-data/DEER-Prototypes-EnergyPlus
A11: Codes | B11: Title 24, part 6, referred to as T24 (1984, 1992,1998, 2001, 2005, 2008, 2013, 2016,2019, 2022, 2025) | C11: https://www.energy.ca.gov/publications/2025/2025-building-energy-efficiency-standards-residential-and-nonresidential | D11: 2025
C12: https://codes.iccsafe.org/codes/united-states/california | D12: 2010+
B13: American Society of Heating, Refrigerating and Air-Conditioning Engineers (ASHRAE) 90.1 (2022) | C13: https://www.ashrae.org/technical-resources/standards-and-guidelines/read-only-versions-of-ashrae-standards
B14: ASHRAE 62.1 (2022) | C14: https://codes.iccsafe.org/content/ASHRAE6212022P1
B15: Code of Federal Regulations (CFR) Title 10 ( 2010) | C15: https://www.govinfo.gov/content/pkg/FR-2009-03-23/pdf/FR-2009-03-23.pdf
B16: 10 CFR Part 431 (2025) | C16: https://www.ecfr.gov/current/title-10/chapter-II/subchapter-D/part-431/subpart E/subject-group-ECFR0f6eefb37f6d425/section-431.87
B17: ASHRAE 170/OSHPD | C17: https://www.ashrae.org/technical-resources/bookstore/health-care-facilities-resources
B18: California Department of Health Care Access and Information (OSHPD) | C18: https://hcai.ca.gov/
B19: 2022 California Mechanical Code (Title 24, Part 4) | C19: https://up.codes/viewer/california/ca-mechanical-code-2022
A21: Others | B21: Alternative Calculation Method (ACM) (2022) | C21: https://www.energy.ca.gov/publications/2022/2022-nonresidential-and-multifamily-alternative-calculation-method-reference
B22: Nonres ACM 2022, Appendix 5.4A and Appendix 5.4B | C22: https://www.energy.ca.gov/publications/2022/2022-nonresidential-and-multifamily-alternative-calculation-method-reference
B23: 2022 Reduced infiltration CASE report | C23: https://title24stakeholders.com/wp-content/uploads/2020/10/2022-T24-Final-CASE-Report_Reduce-Infiltration.pdf
B24: 2019 Outdoor Lighting CASE Report | C24: https://title24stakeholders.com/wp-content/uploads/2016/10/T24-2019-CASE-Study-Results-Report-Outdoor-Sources_Final_with-Attachments.pdf
B25: PNNL 20405, 2011 | C25: https://www.pnnl.gov/main/publications/external/technical_reports/PNNL-20405.pdf
B26: Air leakage Memo, NORESCO, 2025 | C26: https://2050partners.sharepoint.com/:w:/r/sites/CalBEMCollaborativeEfforts/Shared%20Documents/Working%20Group%201%20-%20Streamlined%20Process/D%20-%20Complexity%20of%20Compliance/Prototype%20Unification/Project%20Development/Phase%202%20(Collect%20Inputs)%20Development/NR/Air%20Leakage%20Memo/Infiltration_rate_report_14May2025-Short-Version.docx?d=w3bef8f747fac44f2a70cd76617660066&csf=1&web=1&e=wh5Dm4
B27: 2019 High Efficiency Fume Hoods in Laboratory Spaces CASE Report | C27: https://title24stakeholders.com/wp-content/uploads/2017/09/2019-T24-CASE-Report_Fume-Hoods_Final_September-2017.pdf?
B28: Targeting 100! Envisioning the High Performance Hospital: Implications for a New, Low Energy, High Performance Prototype | C28: https://idl.be.uw.edu/wp-content/uploads/sites/32/2017/08/Targeting100_FullReport_063010.pdf
B29: ASHRAE's Advanced Energy Design Guide for Large Hospitals-50% (AEDG) | C29: https://www.ashrae.org/technical-resources/aedgs/50-percent-aedg-free-download
B30: American Hospital Association (AHA) Statistics data for Hospital | C30: https://www.ahadata.com/aha-hospital-statistics
B31: Yousefi, F., Athalye, R., (2025), "Determining Vintage Bins for Prototype Development: An Analysis of California Commercial Buildings," ASHRAE Annual Conference | C31: https://www.thefreelibrary.com/Determining+Vintage+Bins+for+Prototype+Development%3a+An+Analysis+of...-a0879271125
B32: ENERGY STAR certified commercial water heaters | C32: https://www.energystar.gov/productfinder/product/certified-commercial-water-heaters/results?fuel_filter=Gas&markets_filter=United+States
B33: Grainger gas tank water heaters (sizes below commercial, e.g. 30–75 kBtu/h) | C33: https://www.grainger.com/category/plumbing/water-heaters/gas-tank-water-heaters
B34: Grainger electric tank water heaters | C34: https://www.grainger.com/category/plumbing/water-heaters/electric-tank-water-heaters
A38: Construction Rate
B51: Source:Dodge Construction Data, 2023 ( NEW hospital built after 1967) (STC refers to building types in Dodge terminology).
A52: Notes
A53: Hospital | B53: A hospital, as defined across CEC, PNNL, and CPUC prototypes, is a large, full-service inpatient healthcare facility that operates 24/7, providing acute medical care, surgical services, and diagnostic treatment. It includes patient rooms, operating suites, labs, and support areas, and is typically served by 100% outdoor air HVAC systems with strict ventilation and pressurization controls.
A54: EIA, 2018 CBECS | B54: On average, hospitals were 264,800 square feet per building, but outpatient health care buildings averaged 13,700 square feet.
A55: Source | B55: https://www.eia.gov/consumption/commercial/

Sheet Prototype
A1: NORESCO, Updated September 2026
A2: Hospital
A3: Characteristic | B3: Value | C3: Data Sources
A4: Building Type | B4: Hospital
A5: Building Category | B5: Nonresidential
A6: Version | B6: v2-0
A7: Vintages | B7: 4 Vintages: Pre-1978 , 1978-1997 ,1998-2007 , 2008-2018 New Construction (2019+) | C7: Based on the vintage bin analysis. A summary of the findings is presented in the following paper, with a link provided in the Notes tab: Yousefi, F., Athalye, R. (2025). “Determining Vintage Bins for Prototype Development: An Analysis of California Commercial Buildings.” ASHRAE Annual Conference.
A8: Shape | C8: The analysis uses prototype geometry originally developed by PNNL. The CEC prototypes also adopt this geometry as a foundation.
A9: Total Floor Area (ft²) | B9: 241,521 (230 ft x 175 ft for each floor) | C9: Assumption: same as CEC and PNNL
A10: Number of Beds | B10: 100 | C10: Assumption: 2,400 ft² per bed ( typical in CA)
A11: Aspect Ratio | B11: 1.31 | C11: Assumption: same as CEC and PNNL
A12: Number of Floors | B12: 6 (5 floors + basement) | C12: Assumption: same as CEC and PNNL
A13: Roof type | B13: Flat roof | C13: Typical for hospitals
A14: WWR | B14: North: 23%, East: 24%, South: 28%, West: 48%. Average Total: 30%. | C14: Assumption: same as CEC and PNNL
A15: Shading Geometry | B15: Fixed entrance/ER canopies (12 ft) + S/E/W window overhangs PF=0.5 (~60% of window area). North unshaded. | C15: Assumption
A16: Floor to floor height (feet) | B16: Basement floor: 8 ft Upper floors: 14 ft | C16: Assumption; typical floor height of hospital buildings.
A17: Floor to ceiling height (feet) | B17: No ceiling; plenum is not modeled
A18: Glazing sill height (feet) | B18: 3 ft (4 ft high windows) | C18: Assumption; typical sill height for windows.
A21: Above grade wall area (ft²) | B21: 56720
A22: Gross wall area (ft²) | B22: 63203
A23: Roof area (ft²) | B23: 40254
A24: Underground Gross Wall Area (ft²) | B24: 6482

Sheet Zones
A1: ="Proposed Layout - "&Prototype!A2 -> Proposed Layout - Hospital
A2: Building | B2: Space/Thermal Zone | C2: Space Type [Primarily from: T24, 2022 Appendix 5.4A] - See Notes column | D2: HVAC System Name / AHU Name | E2: Schedule Category | F2: Conditioned (Y/N) | G2: Area Fraction | H2: Area (ft²) | I2: Volume (ft³) | J2: Multipliers | K2: Total Area (ft²) | L2: Number of People | M2: People (Persons/1,000 ft²) [T24, 2025,Table 120.1-A] | N2: Notes
A3: Hospital | B3: MechElec_Basement | C3: Electrical, Mechanical, Telephone Rooms | D3: VAV Basement | E3: Ancillary | F3: Yes | G3: =K3/$K$62 -> 0.086658962 | H3: 20930 | I3: 167489 | J3: 1 | K3: =J3*H3 -> 20930 | L3: =ROUND(H3*M3/1000,0) -> 0 | M3: 0
A4: Hospital | B4: SoiledUtil_Basement | C4: Laundry Area | D4: VAV Basement | E4: Assembly | F4: Yes | G4: =K4/$K$62 -> 0.029997333 | H4: 7245 | I4: 57977 | J4: 1 | K4: =J4*H4 -> 7245 | L4: =ROUND(H4*M4/1000,0) -> 36 | M4: 5
A5: Hospital | B5: Corridor_Basement | C5: Corridor Area | D5: VAV Basement | E5: Assembly | F5: Yes | G5: =K5/$K$62 -> 0.024999848 | H5: 6038 | I5: 48318 | J5: 1 | K5: =J5*H5 -> 6038 | L5: =ROUND(H5*M5/1000,0) -> 0 | M5: 0 | N5: (transient traffic only)
A6: Hospital | B6: IDF_Basement | C6: Computer Room (EPD 20) | D6: CRAC | E6: Data | F6: Yes | G6: =K6/$K$62 -> 0.013332148 | H6: 3220 | I6: 25768 | J6: 1 | K6: =J6*H6 -> 3220 | L6: =ROUND(H6*M6/1000,0) -> 16 | M6: 5
A7: Hospital | B7: MedSupply_Basement | C7: Healthcare Facility and Hospitals (Medical Supply Room) | D7: VAV Basement | E7: Assembly | F7: Yes | G7: =K7/$K$62 -> 0.0116677 | H7: 2818 | I7: 22551 | J7: 1 | K7: =J7*H7 -> 2818 | L7: =ROUND(H7*M7/1000,0) -> 14 | M7: 5
A8: Hospital | B8: Corridor_flr_1 | C8: Corridor Area | D8: VAV Clinical | E8: Health | F8: Yes | G8: =K8/$K$62 -> 0.025362549 | H8: 6125.6 | I8: 85784.61 | J8: 1 | K8: =J8*H8 -> 6125.6 | L8: =ROUND(H8*M8/1000,0) -> 0 | M8: 0 | N8: (transient traffic only)
A9: Hospital | B9: Corridor_flr_2 | C9: Corridor Area | D9: VAV Clinical | E9: Health | F9: Yes | G9: =K9/$K$62 -> 0.025362549 | H9: 6125.6 | I9: 85784.61 | J9: 1 | K9: =J9*H9 -> 6125.6 | L9: =ROUND(H9*M9/1000,0) -> 0 | M9: 0 | N9: (transient traffic only)
A10: Hospital | B10: Corridor_flr_5 | C10: Corridor Area | D10: VAV Clinical | E10: Health | F10: Yes | G10: =K10/$K$62 -> 0.022360455 | H10: 5400.53 | I10: 75630.51 | J10: 1 | K10: =J10*H10 -> 5400.53 | L10: =ROUND(H10*M10/1000,0) -> 0 | M10: 0 | N10: (transient traffic only)
A11: Hospital | B11: Corridor_nw_flr_3 | C11: Corridor Area | D11: VAV Clinical | E11: Health | F11: Yes | G11: =K11/$K$62 -> 0.025259038 | H11: 6100.6 | I11: 85434.47 | J11: 1 | K11: =J11*H11 -> 6100.6 | L11: =ROUND(H11*M11/1000,0) -> 0 | M11: 0 | N11: (transient traffic only)
A12: Hospital | B12: Corridor_nw_flr_4 | C12: Corridor Area | D12: VAV Clinical | E12: Health | F12: Yes | G12: =K12/$K$62 -> 0.025259038 | H12: 6100.6 | I12: 85434.47 | J12: 1 | K12: =J12*H12 -> 6100.6 | L12: =ROUND(H12*M12/1000,0) -> 0 | M12: 0 | N12: (transient traffic only)
A13: Hospital | B13: Corridor_se_flr_3 | C13: Corridor Area | D13: VAV Clinical | E13: Health | F13: Yes | G13: =K13/$K$62 -> 0.025259038 | H13: 6100.6 | I13: 85434.47 | J13: 1 | K13: =J13*H13 -> 6100.6 | L13: =ROUND(H13*M13/1000,0) -> 0 | M13: 0 | N13: (transient traffic only)
A14: Hospital | B14: Corridor_se_flr_4 | C14: Corridor Area | D14: VAV Clinical | E14: Health | F14: Yes | G14: =K14/$K$62 -> 0.025259038 | H14: 6100.6 | I14: 85434.47 | J14: 1 | K14: =J14*H14 -> 6100.6 | L14: =ROUND(H14*M14/1000,0) -> 0 | M14: 0 | N14: (transient traffic only)
A15: Hospital | B15: Dining_flr_5 | C15: Dining Area (Cafeteria/Fast Food) | D15: VAV Dining | E15: Restaurant | F15: Yes | G15: =K15/$K$62 -> 0.031056162 | H15: 7500.73 | I15: 105042.38 | J15: 1 | K15: =J15*H15 -> 7500.73 | L15: =ROUND(H15*M15/1000,0) -> 248 | M15: 33
A16: Hospital | B16: Er_exam1_mult4_flr_1 | C16: Healthcare Facility and Hospitals (Exam/Treatment Room) | D16: VAV ER | E16: Health24/7 | F16: Yes | G16: =K16/$K$62 -> 0.0049689992 | H16: 300.03 | I16: 4201.7 | J16: 4 | K16: =J16*H16 -> 1200.12 | L16: =ROUND(H16*M16/1000,0) -> 2 | M16: 5 | N16: Table 120.1-A- 2025 T24-Misc-All Other
A17: Hospital | B17: Er_exam3_mult4_flr_1 | C17: Healthcare Facility and Hospitals (Exam/Treatment Room) | D17: VAV ER | E17: Health24/7 | F17: Yes | G17: =K17/$K$62 -> 0.0049689992 | H17: 300.03 | I17: 4201.7 | J17: 4 | K17: =J17*H17 -> 1200.12 | L17: =ROUND(H17*M17/1000,0) -> 2 | M17: 5
A18: Hospital | B18: Er_nursestn_lobby_flr_1 | C18: Healthcare Facility and Hospitals (Nurse's Station) | D18: VAV Clinical | E18: Health24/7 | F18: Yes | G18: =K18/$K$62 -> 0.055072951 | H18: 13301.3 | I18: 186275.15 | J18: 1 | K18: =J18*H18 -> 13301.3 | L18: =ROUND(H18*M18/1000,0) -> 20 | M18: 1.5 | N18: 1 nurse per bed
A19: Hospital | B19: Er_trauma1_flr_1 | C19: Healthcare Facility and Hospitals (Exam/Treatment Room) | D19: VAV ER | E19: Health24/7 | F19: Yes | G19: =K19/$K$62 -> 0.0012422498 | H19: 300.03 | I19: 4201.7 | J19: 1 | K19: =J19*H19 -> 300.03 | L19: =ROUND(H19*M19/1000,0) -> 2 | M19: 5
A20: Hospital | B20: Er_trauma2_flr_1 | C20: Healthcare Facility and Hospitals (Exam/Treatment Room) | D20: VAV ER | E20: Health24/7 | F20: Yes | G20: =K20/$K$62 -> 0.0012422498 | H20: 300.03 | I20: 4201.7 | J20: 1 | K20: =J20*H20 -> 300.03 | L20: =ROUND(H20*M20/1000,0) -> 2 | M20: 5
A21: Hospital | B21: Er_triage_mult4_flr_1 | C21: Healthcare Facility and Hospitals (Exam/Treatment Room) | D21: VAV ER | E21: Health24/7 | F21: Yes | G21: =K21/$K$62 -> 0.0049689992 | H21: 300.03 | I21: 4201.7 | J21: 4 | K21: =J21*H21 -> 1200.12 | L21: =ROUND(H21*M21/1000,0) -> 2 | M21: 5
A22: Hospital | B22: Icu_flr_2 | C22: Healthcare Facility and Hospitals (Recovery Room) | D22: VAV ICU | E22: Health24/7 | F22: Yes | G22: =K22/$K$62 -> 0.027543555 | H22: 6652.36 | I22: 93161.52 | J22: 1 | K22: =J22*H22 -> 6652.36 | L22: =ROUND(H22*M22/1000,0) -> 33 | M22: 5 | N22: Intensive Care Unit, for lighting we can go with the general lighting for the patient room but for other EPD and ventilation refer to the CA mechanical code
A23: Hospital | B23: Icu_nursestn_lobby_flr_2 | C23: Healthcare Facility and Hospitals (Nurse's Station) | D23: VAV Clinical | E23: Health24/7 | F23: Yes | G23: =K23/$K$62 -> 0.02980795 | H23: 7199.26 | I23: 100820.51 | J23: 1 | K23: =J23*H23 -> 7199.26 | L23: =ROUND(H23*M23/1000,0) -> 11 | M23: 1.5 | N23: 1 nurse per bed
A24: Hospital | B24: Ic_patroom1_mult5_flr_2 | C24: Healthcare Facility and Hospitals (Recovery Room) | D24: VAV ICU | E24: Health24/7 | F24: Yes | G24: =K24/$K$62 -> 0.004658385 | H24: 225.02 | I24: 3151.27 | J24: 5 | K24: =J24*H24 -> 1125.1 | L24: =ROUND(H24*M24/1000,0) -> 1 | M24: 5
A25: Hospital | B25: Ic_patroom2_flr_2 | C25: Healthcare Facility and Hospitals (Recovery Room) | D25: VAV ICU | E25: Health24/7 | F25: Yes | G25: =K25/$K$62 -> 0.0012422498 | H25: 300.03 | I25: 4201.7 | J25: 1 | K25: =J25*H25 -> 300.03 | L25: =ROUND(H25*M25/1000,0) -> 2 | M25: 5
A26: Hospital | B26: Ic_patroom3_mult6_flr_2 | C26: Healthcare Facility and Hospitals (Recovery Room) | D26: VAV ICU | E26: Health24/7 | F26: Yes | G26: =K26/$K$62 -> 0.005590062 | H26: 225.02 | I26: 3151.27 | J26: 6 | K26: =J26*H26 -> 1350.12 | L26: =ROUND(H26*M26/1000,0) -> 1 | M26: 5
A27: Hospital | B27: Kitchen_flr_5 | C27: Kitchen/Food Preparation Area | D27: CAV Kitchen | E27: Kitchen | F27: Yes | G27: =K27/$K$62 -> 0.041408244 | H27: 10000.98 | I27: 140056.5 | J27: 1 | K27: =J27*H27 -> 10000.98 | L27: =ROUND(H27*M27/1000,0) -> 30 | M27: 3
A28: Hospital | B28: Lab_flr_3 | C28: Laboratory, Scientific | D28: VAV Laboratory | E28: Health | F28: Yes | G28: =K28/$K$62 -> 0.011801352 | H28: 2850.28 | I28: 39916.1 | J28: 1 | K28: =J28*H28 -> 2850.28 | L28: =ROUND(H28*M28/1000,0) -> 14 | M28: 5 | N28: Change it back to 5 same as CEC and PNNL
A29: Hospital | B29: Lab_flr_4 | C29: Laboratory, Scientific | D29: VAV Laboratory | E29: Health | F29: Yes | G29: =K29/$K$62 -> 0.011801352 | H29: 2850.28 | I29: 39916.1 | J29: 1 | K29: =J29*H29 -> 2850.28 | L29: =ROUND(H29*M29/1000,0) -> 14 | M29: 5
A30: Hospital | B30: Lobby_records_flr_1 | C30: Lobby, Main Entry | D30: VAV Admin | E30: Health | F30: Yes | G30: =K30/$K$62 -> 0.065734446 | H30: 15876.28 | I30: 222335.92 | J30: 1 | K30: =J30*H30 -> 15876.28 | L30: =ROUND(H30*M30/1000,0) -> 79 | M30: 5 | N30: For the hospital lobby,5 persons per 1,000 ft² was used considering the size of the lobby, consistent with T24 assumption for reception areas. ASHRAE 62.1 (Table 6‑1) and T24, specify 10 and 33 persons per 1,000 ft² for main entry lobbies, respectively.
A31: Hospital | B31: Nursestn_lobby_flr_3 | C31: Healthcare Facility and Hospitals (Nurse's Station) | D31: VAV Clinical | E31: Health24/7 | F31: Yes | G31: =K31/$K$62 -> 0.040373015 | H31: 9750.95 | I31: 136555.09 | J31: 1 | K31: =J31*H31 -> 9750.95 | L31: =ROUND(H31*M31/1000,0) -> 15 | M31: 1.5 | N31: 1 nurse per bed
A32: Hospital | B32: Nursestn_lobby_flr_4 | C32: Healthcare Facility and Hospitals (Nurse's Station) | D32: VAV Clinical | E32: Health24/7 | F32: Yes | G32: =K32/$K$62 -> 0.040373015 | H32: 9750.95 | I32: 136555.09 | J32: 1 | K32: =J32*H32 -> 9750.95 | L32: =ROUND(H32*M32/1000,0) -> 15 | M32: 1.5 | N32: 1 nurse per bed
A33: Hospital | B33: Nursestn_lobby_flr_5 | C33: Healthcare Facility and Hospitals (Nurse's Station) | D33: VAV Clinical | E33: Health24/7 | F33: Yes | G33: =K33/$K$62 -> 0.046377202 | H33: 11201.09 | I33: 156863.28 | J33: 1 | K33: =J33*H33 -> 11201.09 | L33: =ROUND(H33*M33/1000,0) -> 17 | M33: 1.5 | N33: 1 nurse per bed
A34: Hospital | B34: Office1_flr_5 | C34: Office Area (>250 square feet) | D34: VAV Admin | E34: Office | F34: Yes | G34: =K34/$K$62 -> 0.0031064319 | H34: 750.27 | I34: 10507.01 | J34: 1 | K34: =J34*H34 -> 750.27 | L34: =ROUND(H34*M34/1000,0) -> 4 | M34: 5
A35: Hospital | B35: Office1_mult5_flr_1 | C35: Office Area (<250 square feet) | D35: VAV Admin | E35: Office | F35: Yes | G35: =K35/$K$62 -> 0.003105521 | H35: 150.01 | I35: 2100.85 | J35: 5 | K35: =J35*H35 -> 750.05 | L35: =ROUND(H35*M35/1000,0) -> 1 | M35: 5
A36: Hospital | B36: Office2_mult5_flr_5 | C36: Office Area (>250 square feet) | D36: VAV Admin | E36: Office | F36: Yes | G36: =K36/$K$62 -> 0.015528019 | H36: 750.07 | I36: 10502.39 | J36: 5 | K36: =J36*H36 -> 3750.35 | L36: =ROUND(H36*M36/1000,0) -> 4 | M36: 5
A37: Hospital | B37: Office3_flr_5 | C37: Office Area (>250 square feet) | D37: VAV Admin | E37: Office | F37: Yes | G37: =K37/$K$62 -> 0.0031056038 | H37: 750.07 | I37: 10504.24 | J37: 1 | K37: =J37*H37 -> 750.07 | L37: =ROUND(H37*M37/1000,0) -> 4 | M37: 5
A38: Hospital | B38: Office4_mult6_flr_5 | C38: Office Area (<250 square feet) | D38: VAV Admin | E38: Office | F38: Yes | G38: =K38/$K$62 -> 0.0037266252 | H38: 150.01 | I38: 2100.85 | J38: 6 | K38: =J38*H38 -> 900.06 | L38: =ROUND(H38*M38/1000,0) -> 1 | M38: 5
A39: Hospital | B39: Or1_flr_2 | C39: Healthcare Facility and Hospitals (Operating Room) | D39: VAV OR | E39: HealthOR | F39: Yes | G39: =K39/$K$62 -> 0.0024844996 | H39: 600.06 | I39: 8403.39 | J39: 1 | K39: =J39*H39 -> 600.06 | L39: =ROUND(H39*M39/1000,0) -> 3 | M39: 5
A40: Hospital | B40: Or2_mult5_flr_2 | C40: Healthcare Facility and Hospitals (Operating Room) | D40: VAV OR | E40: HealthOR | F40: Yes | G40: =K40/$K$62 -> 0.012422498 | H40: 600.06 | I40: 8403.39 | J40: 5 | K40: =J40*H40 -> 3000.3 | L40: =ROUND(H40*M40/1000,0) -> 3 | M40: 5
...

Sheet Envelope
A1: ="Envelope - "&Prototype!A2 -> Envelope - Hospital
A2: Element | B2: Prototype | C2: Assembly Type | D2: Construction | E2: Thermal Properties | F2: Vintage | G2: Selected T24 | H2: Notes | I2: CZ1 | J2: CZ2 | K2: CZ3 | L2: CZ4 | M2: CZ5 | N2: CZ6 | O2: CZ7 | P2: CZ8 | Q2: CZ9 | R2: CZ10 | S2: CZ11 | T2: CZ12 | U2: CZ13 | V2: CZ14 | W2: CZ15 | X2: CZ16
A3: External Wall | B3: Hospital | C3: ExtWall_MetalFramed_NonRes | D3: Metal framed wall: Metal frame + insulation + gypsum board (Same as CEC and DEER. PNNL has Mass wall)) | E3: U-factor IP | F3: Pre 1978 | G3: N/A | H3: Using DOE pre-1980 U-values and a 11.7% cumulative wall renovation rate through 2028, based on the average annual rate from CBECS 2003 and 2012 projected over 48 years. | I3: =I43*$I$45+I44*(1-$I$45) -> 0.211907 | J3: =J43*$I$45+J44*(1-$I$45) -> 0.207695 | K3: =K43*$I$45+K44*(1-$I$45) -> 0.210035 | L3: =L43*$I$45+L44*(1-$I$45) -> 0.207695 | M3: =M43*$I$45+M44*(1-$I$45) -> 0.207695 | N3: =N43*$I$45+N44*(1-$I$45) -> 0.211907 | O3: =O43*$I$45+O44*(1-$I$45) -> 0.211907 | P3: =P43*$I$45+P44*(1-$I$45) -> 0.207695 | ... X3: =X43*$I$45+X44*(1-$I$45) -> 0.207695
F4: 1978-1997 | G4: 1986 | H4: Copied from High-rise office alternative requirements (Table 2-53W): Package A with heat capacity between 0-3.99 (Btu/F-ft²) *T24, 1986, Table 2-53BB presents U-factors less than the next vintage (for wall density of 26-40 lb/ft² & Degree day<3500)! | I4: =1/7.4 -> 0.13513514 | J4: =1/7.4 -> 0.13513514 | K4: =1/7.4 -> 0.13513514 | L4: =1/7.4 -> 0.13513514 | M4: =1/7.4 -> 0.13513514 | N4: =1/7.4 -> 0.13513514 | O4: =1/7.4 -> 0.13513514 | P4: =1/7.4 -> 0.13513514 | ... X4: =1/7.4 -> 0.13513514 | Y4: These values have better performance than the next vintage
F5: 1998-2007 | G5: 2001 | H5: Table 1-H | I5: 0.182 | J5: 0.182 | K5: 0.189 | L5: 0.189 | M5: 0.189 | N5: 0.189 | O5: 0.189 | P5: 0.189 | Q5: 0.189 | R5: 0.182 | S5: 0.182 | T5: 0.182 | U5: 0.182 | V5: 0.182 | W5: 0.182 | X5: 0.182
F6: 2008-2018 | G6: 2013 | H6: Table 140.3-B | I6: 0.098 | J6: 0.062 | K6: 0.082 | L6: 0.062 | M6: 0.062 | N6: 0.098 | O6: 0.098 | P6: 0.062 | Q6: 0.062 | R6: 0.062 | S6: 0.062 | T6: 0.062 | U6: 0.062 | V6: 0.062 | W6: 0.062 | X6: 0.062
F7: Existing | H7: Weighted average of all 4 vintages | I7: {=_xlfn.BYCOL(TRANSPOSE(Weights!$C$4:$F$19)*I3:X6,_xlfn.LAMBDA(_xlpm.c,SUM(_xlpm.c)))} -> 0.16187763 | J7: 0.16310368 | K7: 0.16339285 | L7: 0.16031756 | M7: 0.15637833 | N7: 0.18572548 | O7: 0.16626504 | P7: 0.18598769 | Q7: 0.18241738 | R7: 0.15166686 | S7: 0.15240736 | T7: 0.15385144 | U7: 0.14821958 | V7: 0.16398086 | W7: 0.14229482 | X7: 0.14964586
F8: 2019+ | G8: 2025 | H8: Table 140.3-B | I8: 0.06 | J8: 0.055 | K8: 0.071 | L8: 0.055 | M8: 0.055 | N8: 0.06 | O8: 0.06 | P8: 0.055 | Q8: 0.055 | R8: 0.055 | S8: 0.055 | T8: 0.055 | U8: 0.055 | V8: 0.055 | W8: 0.055 | X8: 0.055
A9: Roof | B9: Hospital | C9: FlatRoof_WoodFramedAndOther_NonRes | D9: Metal deck roof: Roof membrane + roof insulation + metal decking (Same as PNNL and DEER-Metal roof- CEC has wood-framed roof) | E9: U-factor IP | F9: Pre 1978 | G9: N/A | H9: Considering 30 years for roof/ insulation replacement. | I9: 0.057 | J9: 0.057 | K9: 0.057 | L9: 0.057 | M9: 0.057 | N9: 0.078 | O9: 0.078 | P9: 0.078 | Q9: 0.078 | R9: 0.078 | S9: 0.057 | T9: 0.057 | U9: 0.057 | V9: 0.057 | W9: 0.057 | X9: 0.057
F10: 1978-1997 | G10: 1992 | I10: 0.057 | J10: 0.057 | K10: 0.057 | L10: 0.057 | M10: 0.057 | N10: 0.078 | O10: 0.078 | P10: 0.078 | Q10: 0.078 | R10: 0.078 | S10: 0.057 | T10: 0.057 | U10: 0.057 | V10: 0.057 | W10: 0.057 | X10: 0.057
F11: 1998-2007 | G11: 2001 | H11: Table 1-H | I11: 0.057 | J11: 0.057 | K11: 0.057 | L11: 0.057 | M11: 0.057 | N11: 0.078 | O11: 0.078 | P11: 0.078 | Q11: 0.078 | R11: 0.057 | S11: 0.057 | T11: 0.057 | U11: 0.057 | V11: 0.057 | W11: 0.057 | X11: 0.057
F12: 2008-2018 | G12: 2013 | H12: Table 140.3-B | I12: 0.049 | J12: 0.039 | K12: 0.039 | L12: 0.039 | M12: 0.049 | N12: 0.075 | O12: 0.067 | P12: 0.067 | Q12: 0.039 | R12: 0.039 | S12: 0.039 | T12: 0.039 | U12: 0.039 | V12: 0.039 | W12: 0.039 | X12: 0.039
F13: Existing | H13: Weighted average of all 4 vintages | I13: {=_xlfn.BYCOL(TRANSPOSE(Weights!$C$4:$F$19)*I9:X12,_xlfn.LAMBDA(_xlpm.c,SUM(_xlpm.c)))} -> 0.05476 | J13: 0.05376 | K13: 0.0552 | L13: 0.055120291 | M13: 0.056560454 | N13: 0.077907311 | O13: 0.077078645 | P13: 0.077806986 | Q13: 0.075502822 | R13: 0.069452266 | S13: 0.052931788 | T13: 0.053371863 | U13: 0.051703815 | V13: 0.05459971 | W13: 0.052859554 | X13: 0.05258624
F14: 2019+ | G14: 2025 | H14: Table 140.3-B | I14: 0.038 | J14: 0.038 | K14: 0.038 | L14: 0.038 | M14: 0.038 | N14: 0.038 | O14: 0.038 | P14: 0.038 | Q14: 0.038 | R14: 0.038 | S14: 0.038 | T14: 0.038 | U14: 0.038 | V14: 0.038 | W14: 0.038 | X14: 0.038
A15: Windows | B15: Hospital | C15: FixedWindow_NonRes | D15: Single pane | E15: U-factor IP | F15: Pre 1978 | G15: N/A | H15: ASHRAE Handbook of Fundamentals (Table 4-Ch15) for single pane & T24, 2013 for double pane(33%-67%)* | I15: =0.338*1.12+0.67*0.36 -> 0.61976 | J15: =0.338*1.12+0.67*0.36 -> 0.61976 | K15: =0.338*1.12+0.67*0.36 -> 0.61976 | L15: =0.338*1.12+0.67*0.36 -> 0.61976 | M15: =0.338*1.12+0.67*0.36 -> 0.61976 | N15: =0.338*1.12+0.67*0.36 -> 0.61976 | O15: =0.338*1.12+0.67*0.36 -> 0.61976 | P15: =0.338*1.12+0.67*0.36 -> 0.61976 | ... X15: =0.338*1.12+0.67*0.36 -> 0.61976
F16: 1978-1997 | G16: N/A | I16: =0.338*1.12+0.67*0.36 -> 0.61976 | J16: =0.338*1.12+0.67*0.36 -> 0.61976 | K16: =0.338*1.12+0.67*0.36 -> 0.61976 | L16: =0.338*1.12+0.67*0.36 -> 0.61976 | M16: =0.338*1.12+0.67*0.36 -> 0.61976 | N16: =0.338*1.12+0.67*0.36 -> 0.61976 | O16: =0.338*1.12+0.67*0.36 -> 0.61976 | P16: =0.338*1.12+0.67*0.36 -> 0.61976 | ... X16: =0.338*1.12+0.67*0.36 -> 0.61976
D17: Double pane | F17: 1998-2007 | G17: 2001 | H17: Table 1-H | I17: 0.49 | J17: 0.49 | K17: 0.81 | L17: 0.81 | M17: 0.81 | N17: 0.81 | O17: 0.81 | P17: 0.81 | Q17: 0.81 | R17: 0.49 | S17: 0.49 | T17: 0.49 | U17: 0.49 | V17: 0.49 | W17: 0.49 | X17: 0.49
F18: 2008-2018 | G18: 2013 | H18: Table 140.3-B | I18: 0.36 | J18: 0.36 | K18: 0.36 | L18: 0.36 | M18: 0.36 | N18: 0.36 | O18: 0.36 | P18: 0.36 | Q18: 0.36 | R18: 0.36 | S18: 0.36 | T18: 0.36 | U18: 0.36 | V18: 0.36 | W18: 0.36 | X18: 0.36
F19: Existing | H19: Weighted average of all 4 vintages | I19: {=_xlfn.BYCOL(TRANSPOSE(Weights!$C$4:$F$19)*I15:X18,_xlfn.LAMBDA(_xlpm.c,SUM(_xlpm.c)))} -> 0.524968 | J19: 0.5535392 | K19: 0.6356368 | L19: 0.63197128 | M19: 0.66912126 | N19: 0.64101457 | O19: 0.62463207 | P19: 0.64535946 | Q19: 0.62065311 | R19: 0.56363583 | S19: 0.53681852 | T19: 0.54214252 | U19: 0.51730204 | V19: 0.56791165 | W19: 0.55817991 | X19: 0.5391426
F20: 2019+ | G20: 2025 | H20: Table 140.3-B | I20: 0.36 | J20: 0.36 | K20: 0.36 | L20: 0.36 | M20: 0.36 | N20: 0.36 | O20: 0.36 | P20: 0.36 | Q20: 0.34 | R20: 0.36 | S20: 0.34 | T20: 0.34 | U20: 0.34 | V20: 0.34 | W20: 0.34 | X20: 0.36
B21: Hospital | C21: FixedWindow_NonRes | D21: Single pane | E21: SHGC | F21: Pre 1978 | G21: N/A | H21: ASHRAE Handbook of Fundamentals (Table 10-Ch15) for single pane & T24, 2013 for double pane(33%-67%)* | I21: =0.79*0.33+0.67*I24 -> 0.4282 | J21: =0.79*0.33+0.67*J24 -> 0.4282 | K21: =0.79*0.33+0.67*K24 -> 0.4282 | L21: =0.79*0.33+0.67*L24 -> 0.4282 | M21: =0.79*0.33+0.67*M24 -> 0.4282 | N21: =0.79*0.33+0.67*N24 -> 0.4282 | O21: =0.79*0.33+0.67*O24 -> 0.4282 | P21: =0.79*0.33+0.67*P24 -> 0.4282 | ... X21: =0.79*0.33+0.67*X24 -> 0.4282
F22: 1978-1997 | G22: N/A | I22: =0.79*0.33+0.67*I24 -> 0.4282 | J22: =0.79*0.33+0.67*J24 -> 0.4282 | K22: =0.79*0.33+0.67*K24 -> 0.4282 | L22: =0.79*0.33+0.67*L24 -> 0.4282 | M22: =0.79*0.33+0.67*M24 -> 0.4282 | N22: =0.79*0.33+0.67*N24 -> 0.4282 | O22: =0.79*0.33+0.67*O24 -> 0.4282 | P22: =0.79*0.33+0.67*P24 -> 0.4282 | ... X22: =0.79*0.33+0.67*X24 -> 0.4282
D23: Double pane | F23: 1998-2007 | G23: 2001 | H23: Table 1-H (Non North, WWR:11-20% ) | I23: 0.43 | J23: 0.36 | K23: 0.55 | L23: 0.55 | M23: 0.55 | N23: 0.61 | O23: 0.61 | P23: 0.61 | Q23: 0.61 | R23: 0.36 | S23: 0.36 | T23: 0.36 | U23: 0.36 | V23: 0.36 | W23: 0.36 | X23: 0.43
F24: 2008-2018 | G24: 2013 | H24: Table 140.3-B | I24: 0.25 | J24: 0.25 | K24: 0.25 | L24: 0.25 | M24: 0.25 | N24: 0.25 | O24: 0.25 | P24: 0.25 | Q24: 0.25 | R24: 0.25 | S24: 0.25 | T24: 0.25 | U24: 0.25 | V24: 0.25 | W24: 0.25 | X24: 0.25
F25: Existing | H25: Weighted average of all 4 vintages | I25: {=_xlfn.BYCOL(TRANSPOSE(Weights!$C$4:$F$19)*I21:X24,_xlfn.LAMBDA(_xlpm.c,SUM(_xlpm.c)))} -> 0.37861 | J25: 0.385894 | K25: 0.437176 | L25: 0.43477652 | M25: 0.45914996 | N25: 0.4506753 | O25: 0.43872208 | P25: 0.45389267 | Q25: 0.43353789 | R25: 0.39136171 | S25: 0.37518836 | T25: 0.37900544 | U25: 0.36208776 | V25: 0.39539207 | W25: 0.38624836 | X25: 0.38473851
F26: 2019+ | G26: 2025 | H26: Table 140.3-B | I26: 0.25 | J26: 0.25 | K26: 0.25 | L26: 0.25 | M26: 0.25 | N26: 0.25 | O26: 0.25 | P26: 0.25 | Q26: 0.22 | R26: 0.25 | S26: 0.22 | T26: 0.22 | U26: 0.22 | V26: 0.22 | W26: 0.22 | X26: 0.25
C29: Infiltration
D30: Building | E30: Zones | F30: Vintage | G30: I_75 6-sdied Infiltration rate @ 75 pa | H30: Note | I30: I-design (cfm/ft²) (4-sided Infiltration rate at normal pressure) (Design flow rate approach and Flow/Exterior Wall Area calculation method)
C31: Infiltration | D31: Hospital | F31: Pre 1978 | G31: 1.1 | H31: 2022 CASE report (Table 38) | I31: 0.3121
F32: 1978-1997 | G32: 1.1 | H32: 2022 CASE report (Table 38) | I32: 0.3121
F33: 1998-2007 | G33: 1.1 | H33: 2022 CASE report (Table 38) | I33: 0.3121
F34: 2008-2018 | G34: 1 | H34: 2022 CASE report (Table 38) & T24, 2008-2016 (Table 140.3-B)--Air barrier is required in CZ 10-16 | I34: 0.2856
F35: Existing | H35: Same as Pre 2008 because of their higher weights | I35: =I33 -> 0.3121
F36: 2019+ | G36: 0.6 | H36: 2022 CASE report (Table 38) & T24, 2025 (Table 140.3-B)-Air barrier is required in all CZs | I36: 0.1703
E37: Source: Title 24 air barrier requirements (all editions) and the standardized infiltration rate reported in the 2022 CASE report and Dodge 2023 data
E38: Air Leakage Memo: | G38: Infiltration_rate_report_14May2025-Short-Version.docx
A41: Pre-1978 exterior wall U value calculation
A42: External Wall | B42: Hospital | C42: ExtWall_MetalFramed_NonRes | D42: Metal framed wall: Metal frame + insulation + gypsum board (Same as CEC and DEER. PNNL has Mass wall)) | E42: U-factor IP | F42: Pre 1978 | G42: N/A | H42: ASHRAE 90.1, 2022 Table A3.4.3.1, 3.5", R-0 | I42: 0.292 | J42: 0.292 | K42: 0.292 | L42: 0.292 | M42: 0.292 | N42: 0.292 | O42: 0.292 | P42: 0.292 | Q42: 0.292 | R42: 0.292 | S42: 0.292 | T42: 0.292 | U42: 0.292 | V42: 0.292 | W42: 0.292 | X42: 0.292
H43: T24 (2008 U value) | I43: 0.098 | J43: 0.062 | K43: 0.082 | L43: 0.062 | M43: 0.062 | N43: 0.098 | O43: 0.098 | P43: 0.062 | Q43: 0.062 | R43: 0.062 | S43: 0.062 | T43: 0.062 | U43: 0.062 | V43: 0.062 | W43: 0.062 | X43: 0.062
H44: DOE pre 1980 prototype LA (U value) | I44: 0.227 | J44: 0.227 | K44: 0.227 | L44: 0.227 | M44: 0.227 | N44: 0.227 | O44: 0.227 | P44: 0.227 | Q44: 0.227 | R44: 0.227 | S44: 0.227 | T44: 0.227 | U44: 0.227 | V44: 0.227 | W44: 0.227 | X44: 0.227
...

Sheet HVAC System
A1: ="HVAC system - "&Prototype!A2 -> HVAC system - Hospital
A2: Vintage | B2: Zones | C2: Heating | D2: Cooling | E2: Air Distribution | F2: Other Systems | G2: Source | H2: Note
A3: Existing | B3: Kitchen | C3: Gas Boiler | D3: Chiller | E3: CAV | F3: CAV exhaust system with rooftop makeup air units, no energy recovery and no Demand Control | G3: CEUS 2022(Other system based on T24 and Engineering judgement)
B4: All other conditioned zones | C4: Gas Boiler | D4: Chiller | E4: CAV + Hydronic Reheat | G4: CEUS 2022(Other system based on T24 and Engineering judgement)
A5: New Construction | B5: Kitchen | C5: Gas Boiler | D5: Chiller | E5: VAV | F5: A VAV dedicated MAU with tempered outside air, with exhaust hood and demand control ventilation and Heat Recovery | G5: T24 2025 ACM 2025, Table 2 and 3 | H5: System 13 a - Built-up kitchen MAU
B6: All other conditioned zones (ER, ICU, Labs, OR, Patient Rms) | C6: Gas Boiler | D6: Chiller | E6: VAV + Hydronic Reheat | F6: With Heat Recovery | G6: T24 2025 ACM 2025, Table 2 and 3 | H6: System 6 – VAV
A11: Efficiency of HVAC System (Efficiency is capacity-dependent. The following table provides a general estimate of system efficiency based on preliminary simulations in one climate zone, or assuming cooling load based on rule of thumb)
B12: Upgrade/Installed year | C12: Water Cooled Chiller | D12: Gas Boiler | E12: Heat Rejection (Cooling Tower) | F12: Sources | G12: Note
A13: Pre 1978 | B13: 2008 | C13: Water Cooled, Electrically Operated, Centrifugal--≥ 300 tons and < 600 tons - 5.55 COP 5.90 IPLV | D13: 80% Ec | E13: Axial fan Open-circuit cooling tower--95°F entering water 85°F leaving water 75°F entering air wb--≥ 38.2 gpm/hp | F13: T24, 2008, Table 112-D (for chiller COP) , Title 24-2008 §111 / Title 20 Table E-3 (and 10 CFR 431.87 as in effect through March 1, 2012) for Boiler Efficiency. Table 112-G (Performance Requirements for Heat Rejection Equipment)
A14: 1978-1997
A15: 1998-2007
A16: 2008-2018 | B16: 2013 | C16: Water Cooled, Electrically Operated, Centrifugal--≥ 300 tons and < 600 tons --≤ 0.576 kW/ton ≤ 0.549 IPLV (Path A) | D16: Gas-Fired Boiler > 300,000 Btu/h and ≤2,500,000 Btu/h-- 80% Et Gas-Fired Boiler > 2,500,000 Btu/h -- 82% Ec | E16: Axial fan Open-circuit cooling tower--95°F entering water 85°F leaving water 75°F entering air wb--≥ 42.1 gpm/hp | F16: T24, 2013 , Table 110.2-D (for chiller COP) - Table 110.2-K (for Boiler thermal efficiency). Table 110.2-G (Performance Requirements for Heat Rejection Equipment)
A17: New Construction | B17: 2025 | C17: Water Cooled, Electrically Operated, Centrifugal--≥ 300 tons and < 400 tons--≤ 0.560 kW/ton ≤ 0.520 IPLV (Path A) | D17: Gas-Fired Boiler > 300,000 Btu/h and ≤2,500,000 Btu/h-- 80% Et Gas-Fired Boiler > 2,500,000 Btu/h -- 82% Ec | E17: Axial fan Open-circuit cooling tower--95°F entering water 85°F leaving water 75°F entering air wb--≥ 42.1 gpm/hp | F17: T24, 2025 , Table 110.2-D (for chiller COP) - 10 CFR 431.86 , section § 431.87 Table 1 (for Boiler thermal efficiency). Table 110.2-E (Performance Requirements for Heat Rejection Equipment)
C19: * Ec = combustion efficiency
A24: Fan power
A25: Vintage | B25: Approach | C25: System | D25: Total Static Pressure (TSP) in w.c. | E25: Fan Efficiency [ACM, 2025] | F25: Motor Efficiency | G25: Fan Power Index (W/cfm) | H25: Data Source | I25: Note
A26: Existing | B26: PNNL 90.1-2011, TSP | C26: Kitchen System CAVMAU | D26: 4.09 | E26: 0.65 | F26: ASHRAE 90.1, 2004, Table 10.8 * | H26: Fan power formula: PNNL 20405, 2010, section 5.2.2.5 TSP and fan efficiency: PNNL 20405, 2010, Table 5.11, 90.1-04ac values Motor efficiency: ASHRAE 90.1, 2004, Table 10.8
C27: All other zones, CAV + hydronic reheat | D27: 2.5 below 7,437 cfm; 4.09 at or above 7,437 cfm
A28: Brake horsepower (bhp) = (Supply cfm × TSP in w.c.) / (6356 × fan efficiency)
A29: Fan power (w/cfm) = (bhp × 746) / ( supply cfm × motor efficiency )
A30: New Construction | B30: ACM 2025 | C30: Kitchen System 13a, >5,000 and <=10,000 cfm | D30: TSP = fan power × motor efficiency × fan efficiency × 6356 / 746 | E30: 0.65 | F30: 2025 ACM Table 12 ** | G30: 0.586 | H30: Fan power index: [ACM 2025, Table 13] Motor efficiency: [ ACM 2025, Table 12]
C31: All other zones, System 6 VAV, >10,000 cfm | D31: TSP = fan power × motor efficiency × fan efficiency × 6356 / 746 | G31: 0.947
C32: All other zones, System 6 VAV, >5,000 and <=10,000 cfm | D32: TSP = fan power × motor efficiency × fan efficiency × 6356 / 746 | G32: 1.013
A33: * According to PNNL 20405 section 5.2.2.5, the full-load efficiency of the motor serving the fan is taken from ASHRAE 90.1, 2004, Table 10.8, based on motor nameplate and assuming enclosed motors operating at 1,800 rotations per minute (rpm) Motor nameplate size (bhp) = brake horsepower (bhp) × 1.1 ( using a 10% oversizing factor)
A34: ** The full‑load efficiency of the motor serving the fan is taken from ACM 2025 Table 12 based on the motor nameplate horsepower. Brake horsepower (bhp) = (Supply cfm from sizing run × fan power in W/cfm) / 746.

Sheet Ventilation
A1: =O1 -> Outdoor Airflow Rate - Hospital | O1: ="Outdoor Airflow Rate - "&Prototype!A2 -> Outdoor Airflow Rate - Hospital
A2: Space Type | B2: Space/Thermal Zone | C2: Number of People | D2: Floor Area (ft²) | E2: cfm/person [T24, 2025, Equation 120.1-F and Table 120.1-A] | F2: cfm/ft² [T24, 2025, Equation 120.1-F and Table 120.1-A] | G2: Required exhaust rate (cfm/ft) [T24, 2025, Table 120.1-B – minimum exhaust rates] | H2: Min OA Ventilation Requirement (cfm/ft) [Table 4-A, 2022 California Mechanical Code] | I2: Total cfm driven by people | J2: Total cfm driven by area | K2: Total cfm driven by exhaust | L2: Total cfm | M2: Note | N2: ACH | O2: Space Type | P2: Total Area (ft²) | Q2: Min. occupancy load (persons/1000 ft²) | R2: Total Number of Occupants | S2: cfm/ft² (Table 120.1-A – Minimum Ventilation Rates) | T2: Required Exhaust Rate-cfm/ft² (Table 120.1-B – Minimum Exhaust Rates) | U2: Min OA Ventilation Requirement-ACH-(Table 4-A, 2022 California Mechanical Code) | V2: Min OA Ventilation Requirement-cfm/ft²-(Table 4-A, 2022 California Mechanical Code) | W2: cfm
A3: Electrical, Mechanical, Telephone Rooms | B3: =Zones!B3 -> MechElec_Basement | C3: =Zones!L3 -> 0 | D3: =Zones!K3 -> 20930 | E3: 15 | F3: =VLOOKUP(A3,O$2:S$20,5) -> 0.15 | H3: 0 | I3: =E3*C3 -> 0 | J3: =F3*D3 -> 3139.5 | K3: =G3*D3 -> 0 | L3: =MAX(I3:K3) -> 3139.5 | O3: =Zones!C3 -> Electrical, Mechanical, Telephone Rooms | P3: =SUMIF(Zones!C$3:C$61, "*Office Area (>250 square feet)*", Zones!K$3:K$61) -> 5250.69 | Q3: =Zones!M3 -> 0 | R3: =(P3/1000)*Q3 -> 0 | S3: 0.15 | T3: 0 | W3: =MAX(R3*15,P3*S3,P3*T3,P3*V3) -> 787.6035
A4: Laundry Area | B4: =Zones!B4 -> SoiledUtil_Basement | C4: =Zones!L4 -> 36 | D4: =Zones!K4 -> 7245 | E4: 15 | F4: 0.15 | G4: 1 | H4: 0 | I4: =E4*C4 -> 540 | J4: =F4*D4 -> 1086.75 | K4: =G4*D4 -> 7245 | L4: =MAX(I4:K4) -> 7245 | O4: =Zones!C4 -> Laundry Area | P4: =SUMIF(Zones!C$3:C$61, "*Laundry Area *", Zones!K$3:K$61) -> 7245 | Q4: =Zones!M4 -> 5 | R4: =(P4/1000)*Q4 -> 36.225 | S4: 0.15 | T4: 1 | W4: =MAX(R4*15,P4*S4,P4*T4,P4*V4) -> 7245
A5: Corridor Area | B5: =Zones!B5 -> Corridor_Basement | C5: =Zones!L5 -> 0 | D5: =Zones!K5 -> 6038 | E5: 15 | F5: 0.15 | H5: 0 | I5: =E5*C5 -> 0 | J5: =F5*D5 -> 905.7 | K5: =G5*D5 -> 0 | L5: =MAX(I5:K5) -> 905.7 | O5: =Zones!C6 -> Computer Room (EPD 20) | P5: =SUMIF(Zones!C$3:C$61, "*Computer Room (EPD 20)*", Zones!K$3:K$61) -> 3220 | Q5: =Zones!M6 -> 5 | R5: =(P5/1000)*Q5 -> 16.1 | S5: 0.15 | T5: 0 | W5: =MAX(R5*15,P5*S5,P5*T5,P5*V5) -> 483
A6: Computer Room (EPD 20) | B6: =Zones!B6 -> IDF_Basement | C6: =Zones!L6 -> 16 | D6: =Zones!K6 -> 3220 | E6: 15 | F6: 0.15 | H6: 0 | I6: =E6*C6 -> 240 | J6: =F6*D6 -> 483 | K6: =G6*D6 -> 0 | L6: =MAX(I6:K6) -> 483 | O6: =Zones!C7 -> Healthcare Facility and Hospitals (Medical Supply Room) | P6: =SUMIF(Zones!C$3:C$61, "*Healthcare Facility and Hospitals (Medical Supply Room)*", Zones!K$3:K$61) -> 2818 | Q6: =Zones!M7 -> 5 | R6: =(P6/1000)*Q6 -> 14.09 | S6: 0.15 | T6: 0 | W6: =MAX(R6*15,P6*S6,P6*T6,P6*V6) -> 422.7
A7: Healthcare Facility and Hospitals (Medical Supply Room) | B7: =Zones!B7 -> MedSupply_Basement | C7: =Zones!L7 -> 14 | D7: =Zones!K7 -> 2818 | E7: 15 | F7: 0.15 | H7: 0 | I7: =E7*C7 -> 210 | J7: =F7*D7 -> 422.7 | K7: =G7*D7 -> 0 | L7: =MAX(I7:K7) -> 422.7 | O7: =Zones!C34 -> Office Area (>250 square feet) | P7: =SUMIF(Zones!C$3:C$61, "*Office Area (>250 square feet)*", Zones!K$3:K$61) -> 5250.69 | Q7: =Zones!M34 -> 5 | R7: =(P7/1000)*Q7 -> 26.25345 | S7: 0.15 | W7: =MAX(R7*15,P7*S7,P7*T7,P7*V7) -> 787.6035 | X7: *Negative pressure
A8: Corridor Area | B8: Corridor_flr_1 | C8: =Zones!L8 -> 0 | D8: =Zones!K8 -> 6125.6 | E8: 15 | F8: 0.15 | H8: 0 | I8: =E8*C8 -> 0 | J8: =F8*D8 -> 918.84 | K8: =G8*D8 -> 0 | L8: =MAX(I8:K8) -> 918.84 | O8: =Zones!C35 -> Office Area (<250 square feet) | P8: =SUMIF(Zones!C$3:C$61, "*Office Area (<250 square feet)*", Zones!K$3:K$61) -> 1650.11 | Q8: =Zones!M35 -> 5 | R8: =(P8/1000)*Q8 -> 8.25055 | S8: 0.15 | T8: 0 | W8: =MAX(R8*15,P8*S8,P8*T8,P8*V8) -> 247.5165 | X8: *Positive, No recirculation
A9: Corridor Area | B9: Corridor_flr_2 | C9: =Zones!L9 -> 0 | D9: =Zones!K9 -> 6125.6 | E9: 15 | F9: 0.15 | H9: 0 | I9: =E9*C9 -> 0 | J9: =F9*D9 -> 918.84 | K9: =G9*D9 -> 0 | L9: =MAX(I9:K9) -> 918.84 | O9: =Zones!C8 -> Corridor Area | P9: =SUMIF(Zones!C$3:C$61, "*Corridor Area*", Zones!K$3:K$61) -> 48092.13 | Q9: =Zones!M8 -> 0 | R9: =(P9/1000)*Q9 -> 0 | S9: 0.15 | T9: 0 | W9: =MAX(R9*15,P9*S9,P9*T9,P9*V9) -> 7213.8195 | X9: *Negative pressure
A10: Corridor Area | B10: Corridor_flr_5 | C10: =Zones!L10 -> 0 | D10: =Zones!K10 -> 5400.53 | E10: 15 | F10: 0.15 | H10: 0 | I10: =E10*C10 -> 0 | J10: =F10*D10 -> 810.0795 | K10: =G10*D10 -> 0 | L10: =MAX(I10:K10) -> 810.0795 | O10: =Zones!C15 -> Dining Area (Cafeteria/Fast Food) | P10: =SUMIF(Zones!C$3:C$61, "*Dining Area (Cafeteria/Fast Food)*", Zones!K$3:K$61) -> 7500.73 | Q10: =Zones!M15 -> 33 | R10: =(P10/1000)*Q10 -> 247.52409 | S10: 0.15 | T10: 0 | W10: =MAX(R10*15,P10*S10,P10*T10,P10*V10) -> 3712.8614
A11: Corridor Area | B11: Corridor_nw_flr_3 | C11: =Zones!L11 -> 0 | D11: =Zones!K11 -> 6100.6 | E11: 15 | F11: 0.15 | H11: 0 | I11: =E11*C11 -> 0 | J11: =F11*D11 -> 915.09 | K11: =G11*D11 -> 0 | L11: =MAX(I11:K11) -> 915.09 | O11: =Zones!C16 -> Healthcare Facility and Hospitals (Exam/Treatment Room) | P11: =SUMIF(Zones!C$3:C$61, "*Healthcare Facility and Hospitals (Exam/Treatment Room)*", Zones!K$3:K$61) -> 4200.42 | Q11: =Zones!M16 -> 5 | R11: =(P11/1000)*Q11 -> 21.0021 | T11: 0 | U11: 2 | V11: =(U11*14)/60 -> 0.46666667 | W11: =MAX(R11*15,P11*S11,P11*T11,P11*V11) -> 1960.196
A12: Corridor Area | B12: Corridor_nw_flr_4 | C12: =Zones!L12 -> 0 | D12: =Zones!K12 -> 6100.6 | E12: 15 | F12: 0.15 | H12: 0 | I12: =E12*C12 -> 0 | J12: =F12*D12 -> 915.09 | K12: =G12*D12 -> 0 | L12: =MAX(I12:K12) -> 915.09 | O12: =Zones!C18 -> Healthcare Facility and Hospitals (Nurse's Station) | P12: =SUMIF(Zones!C$3:C$61, "*Healthcare Facility and Hospitals (Nurse's Station)*", Zones!K$3:K$61) -> 62104.61 | Q12: =Zones!M18 -> 1.5 | R12: =(P12/1000)*Q12 -> 93.156915 | T12: 0 | U12: 2 | V12: =(U12*14)/60 -> 0.46666667 | W12: =MAX(R12*15,P12*S12,P12*T12,P12*V12)+3137 -> 32119.151
A13: Corridor Area | B13: Corridor_se_flr_3 | C13: =Zones!L13 -> 0 | D13: =Zones!K13 -> 6100.6 | E13: 15 | F13: 0.15 | H13: 0 | I13: =E13*C13 -> 0 | J13: =F13*D13 -> 915.09 | K13: =G13*D13 -> 0 | L13: =MAX(I13:K13) -> 915.09 | O13: =Zones!C22 -> Healthcare Facility and Hospitals (Recovery Room) | P13: =SUMIF(Zones!C$3:C$61, "*Healthcare Facility and Hospitals (Recovery Room)*", Zones!K$3:K$61) -> 9427.61 | Q13: =Zones!M22 -> 5 | R13: =(P13/1000)*Q13 -> 47.13805 | T13: 0 | U13: 2 | V13: =(U13*14)/60 -> 0.46666667 | W13: =MAX(R13*15,P13*S13,P13*T13,P13*V13) -> 4399.5513
A14: Corridor Area | B14: Corridor_se_flr_4 | C14: =Zones!L14 -> 0 | D14: =Zones!K14 -> 6100.6 | E14: 15 | F14: 0.15 | H14: 0 | I14: =E14*C14 -> 0 | J14: =F14*D14 -> 915.09 | K14: =G14*D14 -> 0 | L14: =MAX(I14:K14) -> 915.09 | O14: =Zones!C28 -> Laboratory, Scientific | P14: =SUMIF(Zones!C$3:C$61, "*Laboratory, Scientific*", Zones!K$3:K$61) -> 5700.56 | Q14: =Zones!M28 -> 5 | R14: =(P14/1000)*Q14 -> 28.5028 | T14: 1 | U14: 2 | V14: =(U14*14)/60 -> 0.46666667 | W14: =MAX(R14*15,P14*S14,P14*T14,P14*V14)+E71+E72 -> 8700.56
A15: Dining Area (Cafeteria/Fast Food) | B15: Dining_flr_5 | C15: =Zones!L15 -> 248 | D15: =Zones!K15 -> 7500.73 | E15: 15 | F15: 0.15 | H15: 0 | I15: =E15*C15 -> 3720 | J15: =F15*D15 -> 1125.1095 | K15: =G15*D15 -> 0 | L15: =MAX(I15:K15) -> 3720 | O15: =Zones!C39 -> Healthcare Facility and Hospitals (Operating Room) | P15: =SUMIF(Zones!C$3:C$61, "*Healthcare Facility and Hospitals (Operating Room)*", Zones!K$3:K$61) -> 6600.65 | Q15: =Zones!M39 -> 5 | R15: =(P15/1000)*Q15 -> 33.00325 | U15: 4 | V15: =(U15*14)/60 -> 0.93333333 | W15: =MAX(R15*15,P15*S15,P15*T15,P15*V15) -> 6160.6067
A16: Healthcare Facility and Hospitals (Exam/Treatment Room) | B16: Er_exam1_mult4_flr_1 | C16: =Zones!L16 -> 2 | D16: =Zones!K16 -> 1200.12 | E16: 15 | F16: =VLOOKUP(A16,O$2:S$20,5) -> 0 | H16: 0.46666667 | I16: =E16*C16 -> 30 | J16: =H16*D16 -> 560.056 | K16: =G16*D16 -> 0 | L16: =MAX(I16:K16) -> 560.056 | O16: =Zones!C60 -> Healthcare Facility and Hospitals (Physical Therapy Room) | P16: =SUMIF(Zones!C$3:C$61, "*Healthcare Facility and Hospitals (Physical Therapy Room)*", Zones!K$3:K$61) -> 5250.51 | Q16: =Zones!M60 -> 5 | R16: =(P16/1000)*Q16 -> 26.25255 | U16: 2 | V16: =(U16*14)/60 -> 0.46666667 | W16: =MAX(R16*15,P16*S16,P16*T16,P16*V16) -> 2450.238
A17: Healthcare Facility and Hospitals (Exam/Treatment Room) | B17: Er_exam3_mult4_flr_1 | C17: =Zones!L17 -> 2 | D17: =Zones!K17 -> 1200.12 | E17: 15 | F17: =VLOOKUP(A17,O$2:S$20,5) -> 0 | H17: 0.46666667 | I17: =E17*C17 -> 30 | J17: =H17*D17 -> 560.056 | K17: =G17*D17 -> 0 | L17: =MAX(I17:K17) -> 560.056 | O17: =Zones!C61 -> Healthcare Facility and Hospitals (Imaging Room) | P17: =SUMIF(Zones!C$3:C$61, "*Healthcare Facility and Hospitals (Imaging Room)*", Zones!K$3:K$61) -> 5250.51 | Q17: =Zones!M61 -> 5 | R17: =(P17/1000)*Q17 -> 26.25255 | U17: 2 | V17: =(U17*14)/60 -> 0.46666667 | W17: =MAX(R17*15,P17*S17,P17*T17,P17*V17) -> 2450.238
A18: Healthcare Facility and Hospitals (Nurse's Station) | B18: Er_nursestn_lobby_flr_1 | C18: =Zones!L18 -> 20 | D18: =Zones!K18 -> 13301.3 | E18: 15 | F18: =VLOOKUP(A18,O$2:S$20,5) -> 0 | H18: 0.46666667 | I18: =E18*C18 -> 300 | J18: =H18*D18 -> 6207.2733 | K18: =G18*D18 -> 0 | L18: =MAX(I18:K18) -> 6207.2733 | O18: =Zones!C44 -> Healthcare Facility and Hospitals (Patient Room) | P18: =SUMIF(Zones!C$3:C$61, "*Healthcare Facility and Hospitals (Patient Room)*", Zones!K$3:K$61) -> 20402.68 | Q18: 5 | R18: =(P18/1000)*Q18 -> 102.0134 | U18: 2 | V18: =(U18*14)/60 -> 0.46666667 | W18: =MAX(R18*15,P18*S18,P18*T18,P18*V18) -> 9521.2507
A19: Healthcare Facility and Hospitals (Exam/Treatment Room) | B19: Er_trauma1_flr_1 | C19: =Zones!L19 -> 2 | D19: =Zones!K19 -> 300.03 | E19: 15 | F19: =VLOOKUP(A19,O$2:S$20,5) -> 0 | H19: 0.7 | I19: =E19*C19 -> 30 | J19: =H19*D19 -> 210.021 | K19: =G19*D19 -> 0 | L19: =MAX(I19:K19) -> 210.021 | O19: =Zones!C30 -> Lobby, Main Entry | P19: =SUMIF(Zones!C$3:C$61, "*Lobby, Main Entry*", Zones!K$3:K$61) -> 15876.28 | Q19: =Zones!M30 -> 5 | R19: =(P19/1000)*Q19 -> 79.3814 | S19: 0.15 | W19: =MAX(R19*15,P19*S19,P19*T19,P19*V19) -> 2381.442
A20: Healthcare Facility and Hospitals (Exam/Treatment Room) | B20: Er_trauma2_flr_1 | C20: =Zones!L20 -> 2 | D20: =Zones!K20 -> 300.03 | E20: 15 | F20: =VLOOKUP(A20,O$2:S$20,5) -> 0 | H20: 0.7 | I20: =E20*C20 -> 30 | J20: =H20*D20 -> 210.021 | K20: =G20*D20 -> 0 | L20: =MAX(I20:K20) -> 210.021 | O20: =Zones!C27 -> Kitchen/Food Preparation Area | P20: =SUMIF(Zones!C$3:C$61, "*Kitchen/Food Preparation Area*", Zones!K$3:K$61) -> 10000.98 | Q20: =Zones!M27 -> 3 | R20: =(P20/1000)*Q20 -> 30.00294 | S20: 0.15 | T20: 0.7 | W20: =MAX(R20*15,P20*S20,P20*T20,P20*V20) -> 7000.686
A21: Healthcare Facility and Hospitals (Exam/Treatment Room) | B21: Er_triage_mult4_flr_1 | C21: =Zones!L21 -> 2 | D21: =Zones!K21 -> 1200.12 | E21: 15 | F21: =VLOOKUP(A21,O$2:S$20,5) -> 0 | G21: =3697/D21 -> 3.0805253 | H21: 0.46666667 | I21: =E21*C21 -> 30 | J21: =H21*D21 -> 560.056 | K21: =G21*D21 -> 3697 | L21: =MAX(I21:K21) -> 3697 | M21: According to CEC model, exhaust required | O21: Total | P21: =SUM(P3:P20) -> 225842.16 | R21: =SUM(R3:R20) -> 835.14905 | W21: =SUM(W3:W20) -> 98044.024
A22: Healthcare Facility and Hospitals (Recovery Room) | B22: Icu_flr_2 | C22: =Zones!L22 -> 33 | D22: =Zones!K22 -> 6652.36 | E22: 15 | F22: =VLOOKUP(A22,O$2:S$20,5) -> 0 | H22: 0.46666667 | I22: =E22*C22 -> 495 | J22: =H22*D22 -> 3104.4347 | L22: =MAX(I22:K22) -> 3104.4347
A23: Healthcare Facility and Hospitals (Nurse's Station) | B23: Icu_nursestn_lobby_flr_2 | C23: =Zones!L23 -> 11 | D23: =Zones!K23 -> 7199.26 | E23: 15 | F23: =VLOOKUP(A23,O$2:S$20,5) -> 0 | H23: 0.46666667 | I23: =E23*C23 -> 165 | J23: =H23*D23 -> 3359.6547 | L23: =MAX(I23:K23) -> 3359.6547
A24: Healthcare Facility and Hospitals (Recovery Room) | B24: Ic_patroom1_mult5_flr_2 | C24: =Zones!L24 -> 1 | D24: =Zones!K24 -> 1125.1 | E24: 15 | F24: =VLOOKUP(A24,O$2:S$20,5) -> 0 | H24: 0.46666667 | I24: =E24*C24 -> 15 | J24: =H24*D24 -> 525.04667 | L24: =MAX(I24:K24) -> 525.04667
A25: Healthcare Facility and Hospitals (Recovery Room) | B25: Ic_patroom2_flr_2 | C25: =Zones!L25 -> 2 | D25: =Zones!K25 -> 300.03 | E25: 15 | F25: =VLOOKUP(A25,O$2:S$20,5) -> 0 | H25: 0.46666667 | I25: =E25*C25 -> 30 | J25: =H25*D25 -> 140.014 | L25: =MAX(I25:K25) -> 140.014
A26: Healthcare Facility and Hospitals (Recovery Room) | B26: Ic_patroom3_mult6_flr_2 | C26: =Zones!L26 -> 1 | D26: =Zones!K26 -> 1350.12 | E26: 15 | F26: =VLOOKUP(A26,O$2:S$20,5) -> 0 | H26: 0.46666667 | I26: =E26*C26 -> 15 | J26: =H26*D26 -> 630.056 | L26: =MAX(I26:K26) -> 630.056
A27: Kitchen/Food Preparation Area | B27: Kitchen_flr_5 | C27: =Zones!L27 -> 30 | D27: =Zones!K27 -> 10000.98 | E27: 15 | F27: 0.15 | G27: 0.7 | I27: =E27*C27 -> 450 | J27: =F27*D27 -> 1500.147 | K27: =G27*D27 -> 7000.686 | L27: =MAX(I27:K27) -> 7000.686 | M27: Exhaust required according to Code
A28: Laboratory, Scientific | B28: Lab_flr_3 | C28: =Zones!L28 -> 14 | D28: =Zones!K28 -> 2850.28 | E28: 15 | F28: =VLOOKUP(A28,O$2:S$20,5) -> 0 | G28: 1 | H28: 0.46666667 | I28: =E28*C28 -> 210 | J28: =H28*D28 -> 1330.1307 | K28: =G28*D28 -> 2850.28 | L28: =MAX(I28:K28)+E71 -> 4350.28 | M28: Exhaust required according to Code Per ASHRAE 62.1: Table 6.5-General Lab Exhaust
A29: Laboratory, Scientific | B29: Lab_flr_4 | C29: =Zones!L29 -> 14 | D29: =Zones!K29 -> 2850.28 | E29: 15 | F29: =VLOOKUP(A29,O$2:S$20,5) -> 0 | G29: 1 | H29: 0.46666667 | I29: =E29*C29 -> 210 | J29: =H29*D29 -> 1330.1307 | K29: =G29*D29 -> 2850.28 | L29: =MAX(I29:K29)+E72 -> 4350.28 | M29: Exhaust required according to Code Per ASHRAE 62.1: Table 6.5-General Lab Exhaust
A30: Lobby, Main Entry | B30: Lobby_records_flr_1 | C30: =Zones!L30 -> 79 | D30: =Zones!K30 -> 15876.28 | E30: 15 | F30: =VLOOKUP(A30,O$2:S$20,5) -> 0.15 | H30: =VLOOKUP(A30,O$2:V$20,8) -> 0 | I30: =E30*C30 -> 1185 | J30: =F30*D30 -> 2381.442 | K30: =G30*D30 -> 0 | L30: =MAX(I30:K30) -> 2381.442
A31: Healthcare Facility and Hospitals (Nurse's Station) | B31: Nursestn_lobby_flr_3 | C31: =Zones!L31 -> 15 | D31: =Zones!K31 -> 9750.95 | E31: 15 | F31: =VLOOKUP(A31,O$2:S$20,5) -> 0 | G31: =4551/D31 -> 0.46672376 | H31: 0.46666667 | I31: =E31*C31 -> 225 | J31: =H31*D31 -> 4550.4433 | K31: =G31*D31 -> 4551 | L31: =MAX(I31:K31) -> 4551 | M31: According to CEC Model
A32: Healthcare Facility and Hospitals (Nurse's Station) | B32: Nursestn_lobby_flr_4 | C32: =Zones!L32 -> 15 | D32: =Zones!K32 -> 9750.95 | E32: 15 | F32: =VLOOKUP(A32,O$2:S$20,5) -> 0 | G32: =4551/D32 -> 0.46672376 | H32: 0.46666667 | I32: =E32*C32 -> 225 | J32: =H32*D32 -> 4550.4433 | K32: =G32*D32 -> 4551 | L32: =MAX(I32:K32) -> 4551 | M32: According to CEC Model
A33: Healthcare Facility and Hospitals (Nurse's Station) | B33: Nursestn_lobby_flr_5 | C33: =Zones!L33 -> 17 | D33: =Zones!K33 -> 11201.09 | E33: 15 | F33: =VLOOKUP(A33,O$2:S$20,5) -> 0 | H33: 0.46666667 | I33: =E33*C33 -> 255 | J33: =H33*D33 -> 5227.1753 | K33: =G33*D33 -> 0 | L33: =MAX(I33:K33) -> 5227.1753
A34: Office Area (>250 square feet) | B34: Office1_flr_5 | C34: =Zones!L34 -> 4 | D34: =Zones!K34 -> 750.27 | E34: 15 | F34: =VLOOKUP(A34,O$2:S$20,5) -> 0.15 | H34: =VLOOKUP(A34,O$2:V$20,8) -> 0 | I34: =E34*C34 -> 60 | J34: =F34*D34 -> 112.5405 | K34: =G34*D34 -> 0 | L34: =MAX(I34:K34) -> 112.5405
A35: Office Area (<250 square feet) | B35: Office1_mult5_flr_1 | C35: =Zones!L35 -> 1 | D35: =Zones!K35 -> 750.05 | E35: 15 | F35: =VLOOKUP(A35,O$2:S$20,5) -> 0.15 | H35: =VLOOKUP(A35,O$2:V$20,8) -> 0 | I35: =E35*C35 -> 15 | J35: =F35*D35 -> 112.5075 | K35: =G35*D35 -> 0 | L35: =MAX(I35:K35) -> 112.5075
A36: Office Area (>250 square feet) | B36: Office2_mult5_flr_5 | C36: =Zones!L36 -> 4 | D36: =Zones!K36 -> 3750.35 | E36: 15 | F36: =VLOOKUP(A36,O$2:S$20,5) -> 0.15 | H36: =VLOOKUP(A36,O$2:V$20,8) -> 0 | I36: =E36*C36 -> 60 | J36: =F36*D36 -> 562.5525 | K36: =G36*D36 -> 0 | L36: =MAX(I36:K36) -> 562.5525
A37: Office Area (>250 square feet) | B37: Office3_flr_5 | C37: =Zones!L37 -> 4 | D37: =Zones!K37 -> 750.07 | E37: 15 | F37: =VLOOKUP(A37,O$2:S$20,5) -> 0.15 | H37: =VLOOKUP(A37,O$2:V$20,8) -> 0 | I37: =E37*C37 -> 60 | J37: =F37*D37 -> 112.5105 | K37: =G37*D37 -> 0 | L37: =MAX(I37:K37) -> 112.5105
A38: Office Area (<250 square feet) | B38: Office4_mult6_flr_5 | C38: =Zones!L38 -> 1 | D38: =Zones!K38 -> 900.06 | E38: 15 | F38: =VLOOKUP(A38,O$2:S$20,5) -> 0.15 | H38: =VLOOKUP(A38,O$2:V$20,8) -> 0 | I38: =E38*C38 -> 15 | J38: =F38*D38 -> 135.009 | K38: =G38*D38 -> 0 | L38: =MAX(I38:K38) -> 135.009
A39: Healthcare Facility and Hospitals (Operating Room) | B39: Or1_flr_2 | C39: =Zones!L39 -> 3 | D39: =Zones!K39 -> 600.06 | E39: 15 | F39: =VLOOKUP(A39,O$2:S$20,5) -> 0 | H39: 0.9333333 | I39: =E39*C39 -> 45 | J39: =H39*D39 -> 560.05598 | K39: =G39*D39 -> 0 | L39: =MAX(I39:K39) -> 560.05598
A40: Healthcare Facility and Hospitals (Operating Room) | B40: Or2_mult5_flr_2 | C40: =Zones!L40 -> 3 | D40: =Zones!K40 -> 3000.3 | E40: 15 | F40: =VLOOKUP(A40,O$2:S$20,5) -> 0 | H40: 0.9333333 | I40: =E40*C40 -> 45 | J40: =H40*D40 -> 2800.2799 | K40: =G40*D40 -> 0 | L40: =MAX(I40:K40) -> 2800.2799
...

Sheet Thermostat
A1: ="Thermostat Setpoints - "&Prototype!A2 -> Thermostat Setpoints - Hospital
A2: Setpoint | B2: CZ1 | C2: CZ2 | D2: CZ3 | E2: CZ4 | F2: CZ5 | G2: CZ6 | H2: CZ7 | I2: CZ8 | J2: CZ9 | K2: CZ10 | L2: CZ11 | M2: CZ12 | N2: CZ13 | O2: CZ14 | P2: CZ15 | Q2: CZ16 | R2: Source | S2: Note
A3: Health Heating Setpoint (F) | B3: 70 | C3: 70 | D3: 70 | E3: 70 | F3: 70 | G3: 70 | H3: 70 | I3: 70 | J3: 70 | K3: 70 | L3: 70 | M3: 70 | N3: 70 | O3: 70 | P3: 70 | Q3: 70 | R3: T24 2022 - Appendix 5.4B | S3: CEC and PNNL Healthcare-Hospital prototypes use the same setpoints without setbacks; however, the DEER model applies a 10° F setback from midnight to 5:00 AM.
A4: Health Heating Setback (F) | B4: 70 | C4: 70 | D4: 70 | E4: 70 | F4: 70 | G4: 70 | H4: 70 | I4: 70 | J4: 70 | K4: 70 | L4: 70 | M4: 70 | N4: 70 | O4: 70 | P4: 70 | Q4: 70
A5: Health Cooling Setpoint (F) | B5: 75 | C5: 75 | D5: 75 | E5: 75 | F5: 75 | G5: 75 | H5: 75 | I5: 75 | J5: 75 | K5: 75 | L5: 75 | M5: 75 | N5: 75 | O5: 75 | P5: 75 | Q5: 75
A6: Health Cooling Setback (F) | B6: 75 | C6: 75 | D6: 75 | E6: 75 | F6: 75 | G6: 75 | H6: 75 | I6: 75 | J6: 75 | K6: 75 | L6: 75 | M6: 75 | N6: 75 | O6: 75 | P6: 75 | Q6: 75
A7: Kitchen Heating Setpoint (F) | B7: 66 | C7: 66 | D7: 66 | E7: 66 | F7: 66 | G7: 66 | H7: 66 | I7: 66 | J7: 66 | K7: 66 | L7: 66 | M7: 66 | N7: 66 | O7: 66 | P7: 66 | Q7: 66 | R7: PNNL 09.1, 2022 Restaurant prototype
A8: Kitchen Heating Setback (F) | B8: 60 | C8: 60 | D8: 60 | E8: 60 | F8: 60 | G8: 60 | H8: 60 | I8: 60 | J8: 60 | K8: 60 | L8: 60 | M8: 60 | N8: 60 | O8: 60 | P8: 60 | Q8: 60
A9: Kitchen Cooling Setpoint (F) | B9: 79 | C9: 79 | D9: 79 | E9: 79 | F9: 79 | G9: 79 | H9: 79 | I9: 79 | J9: 79 | K9: 79 | L9: 79 | M9: 79 | N9: 79 | O9: 79 | P9: 79 | Q9: 79
A10: Kitchen Cooling Setback (F) | B10: 86 | C10: 86 | D10: 86 | E10: 86 | F10: 86 | G10: 86 | H10: 86 | I10: 86 | J10: 86 | K10: 86 | L10: 86 | M10: 86 | N10: 86 | O10: 86 | P10: 86 | Q10: 86
A11: UnOccupied Heating Setpoint (F) | B11: =B3-4 -> 66 | C11: =C3-4 -> 66 | D11: =D3-4 -> 66 | E11: =E3-4 -> 66 | F11: =F3-4 -> 66 | G11: =G3-4 -> 66 | H11: =H3-4 -> 66 | I11: =I3-4 -> 66 | ... Q11: =Q3-4 -> 66 | R11: T24 2022 - Appendix 5.4B
A12: UnOccupied Heating Setback (F) | B12: =B4-4 -> 66 | C12: =C4-4 -> 66 | D12: =D4-4 -> 66 | E12: =E4-4 -> 66 | F12: =F4-4 -> 66 | G12: =G4-4 -> 66 | H12: =H4-4 -> 66 | I12: =I4-4 -> 66 | ... Q12: =Q4-4 -> 66
A13: UnOccupied Cooling Setpoint (F) | B13: =B5+4 -> 79 | C13: =C5+4 -> 79 | D13: =D5+4 -> 79 | E13: =E5+4 -> 79 | F13: =F5+4 -> 79 | G13: =G5+4 -> 79 | H13: =H5+4 -> 79 | I13: =I5+4 -> 79 | ... Q13: =Q5+4 -> 79
A14: UnOccupied Cooling Setback (F) | B14: =B6+4 -> 79 | C14: =C6+4 -> 79 | D14: =D6+4 -> 79 | E14: =E6+4 -> 79 | F14: =F6+4 -> 79 | G14: =G6+4 -> 79 | H14: =H6+4 -> 79 | I14: =I6+4 -> 79 | ... Q14: =Q6+4 -> 79
A15: Mechanical Heating Setpoint (F) | B15: 60 | C15: 60 | D15: 60 | E15: 60 | F15: 60 | G15: 60 | H15: 60 | I15: 60 | J15: 60 | K15: 60 | L15: 60 | M15: 60 | N15: 60 | O15: 60 | P15: 60 | Q15: 60 | R15: Engineering Judgment
A16: Mechanical Heating Setback (F) | B16: 60 | C16: 60 | D16: 60 | E16: 60 | F16: 60 | G16: 60 | H16: 60 | I16: 60 | J16: 60 | K16: 60 | L16: 60 | M16: 60 | N16: 60 | O16: 60 | P16: 60 | Q16: 60
A17: Mechanical Cooling Setpoint (F) | B17: 85 | C17: 85 | D17: 85 | E17: 85 | F17: 85 | G17: 85 | H17: 85 | I17: 85 | J17: 85 | K17: 85 | L17: 85 | M17: 85 | N17: 85 | O17: 85 | P17: 85 | Q17: 85
A18: Mechanical Cooling Setback (F) | B18: 85 | C18: 85 | D18: 85 | E18: 85 | F18: 85 | G18: 85 | H18: 85 | I18: 85 | J18: 85 | K18: 85 | L18: 85 | M18: 85 | N18: 85 | O18: 85 | P18: 85 | Q18: 85
A19: Assembly Heating Setpoint (F) | B19: 70 | C19: 70 | D19: 70 | E19: 70 | F19: 70 | G19: 70 | H19: 70 | I19: 70 | J19: 70 | K19: 70 | L19: 70 | M19: 70 | N19: 70 | O19: 70 | P19: 70 | Q19: 70 | R19: T24 2022 - Appendix 5.4B - “Assembly” tab
A20: Assembly Heating Setback (F) | B20: 60 | C20: 60 | D20: 60 | E20: 60 | F20: 60 | G20: 60 | H20: 60 | I20: 60 | J20: 60 | K20: 60 | L20: 60 | M20: 60 | N20: 60 | O20: 60 | P20: 60 | Q20: 60
A21: Assembly Cooling Setpoint (F) | B21: 75 | C21: 75 | D21: 75 | E21: 75 | F21: 75 | G21: 75 | H21: 75 | I21: 75 | J21: 75 | K21: 75 | L21: 75 | M21: 75 | N21: 75 | O21: 75 | P21: 75 | Q21: 75
A22: Assembly Cooling Setback (F) | B22: 85 | C22: 85 | D22: 85 | E22: 85 | F22: 85 | G22: 85 | H22: 85 | I22: 85 | J22: 85 | K22: 85 | L22: 85 | M22: 85 | N22: 85 | O22: 85 | P22: 85 | Q22: 85
A23: Computer Room Cooling Setpoint (F)* | B23: 80 | C23: 80 | D23: 80 | E23: 80 | F23: 80 | G23: 80 | H23: 80 | I23: 80 | J23: 80 | K23: 80 | L23: 80 | M23: 80 | N23: 80 | O23: 80 | P23: 80 | Q23: 80 | R23: Title 24, Part 6, 2025, section 140.9 (a) and PNNL ASHRAE 90.1 2022 Large Office prototype
A24: Computer Room Heating setpoint (F)* | B24: *The computer room with over 12 W/ft2 load doesn't require heating system as the equipment constantly generate enough heat.
A30: Background Data [To be deleted prior to publication]
B31: Heating | E31: Cooling
B32: Weekday | C32: Saturday | D32: Sunday | E32: Weekday | F32: Saturday | G32: Sunday
A33: DEER | B33: 0:00 to 5:00 | C33: 0:00 to 5:00 | D33: 0:00 to 24:00 | E33: 0:00 to 5:00 | F33: 0:00 to 5:00 | G33: 0:00 to 24:00
B34: 15.56 | C34: 15.56 | D34: 15.56 | E34: 29.22 | F34: 29.22 | G34: 29.22
B35: 5:00 to 24:00 | C35: 5:00 to 19:00 | E35: 5:00 to 24:00 | F35: 5:00 to 19:00
B36: 21.11 | C36: 21.11 | E36: 23.88 | F36: 23.88
A39: T24, Appendix JA5-4 : Occupant Controlled Smart Thermostat (OCST)
A56: Kitchen Heating Setpoint (F) | B56: 66 | C56: 66 | D56: 66 | E56: 66 | F56: 66 | G56: 66 | H56: 66 | I56: 66 | J56: 66 | K56: 66 | L56: 66 | M56: 66 | N56: 66 | O56: 66 | P56: 66 | Q56: 66 | R56: PNNL 09.1, 2022 Restaurant prototype
A57: Kitchen Heating Setback (F) | B57: 60 | C57: 60 | D57: 60 | E57: 60 | F57: 60 | G57: 60 | H57: 60 | I57: 60 | J57: 60 | K57: 60 | L57: 60 | M57: 60 | N57: 60 | O57: 60 | P57: 60 | Q57: 60
A58: Kitchen Cooling Setpoint (F) | B58: 79 | C58: 79 | D58: 79 | E58: 79 | F58: 79 | G58: 79 | H58: 79 | I58: 79 | J58: 79 | K58: 79 | L58: 79 | M58: 79 | N58: 79 | O58: 79 | P58: 79 | Q58: 79
A59: Kitchen Cooling Setback (F) | B59: 86 | C59: 86 | D59: 86 | E59: 86 | F59: 86 | G59: 86 | H59: 86 | I59: 86 | J59: 86 | K59: 86 | L59: 86 | M59: 86 | N59: 86 | O59: 86 | P59: 86 | Q59: 86
A64: Space | B64: Heat | C64: Cool | D64: RH min | E64: RH max | F64: Notes
A65: General clinical / patient rooms | B65: 70 | C65: 75 | D65: — | E65: — | F65: Current assumption
A66: Operating rooms | B66: 68 | C66: 68 | D66: 40 | E66: 60 | F66: ASHRAE 170 design band is 68–75°F / 20–60% RH. Use 68°F occupied. AEDG 50% is also 68F
A67: Imaging / radiology | B67: 70 | C67: 75 | D67: — | E67: — | F67: 170-typical; no dedicated RH loop in the model
...

Sheet Water Heater
A1: ="Water Heater - "&Prototype!A2 -> Water Heater - Hospital
A2: Vintage | B2: WH Type | C2: Efficiency | D2: Number of WH | E2: Tank Volume (gal) | F2: Tank Loss | G2: Source
