Workbook
Name nonparticipating_forecastzone_scale_factor: #REF!
Name nonparticipating_forecastzone_scale_factor: 'Energy Usage'!#REF!
Name Space_Function: Data!$A$2:$A$76

Sheet Notes
A1: Data Sources
A2: Dataset | B2: Dodge 2023
B3: Commercial End-Use Survey (CEUS) 2022 | C3: https://www.energy.ca.gov/publications/2023/2022-california-commercial-end-use-survey-ceus-final-report
B4: Commercial Buildings Energy Consumption Survey (CBECS) 2018 | C4: https://www.eia.gov/consumption/commercial/data/2018/index.php?view=microdata
B5: Comstock 2023 | C5: https://data.openei.org/s3_viewer?bucket=oedi-data-lake&prefix=nrel-pds-building-stock%2Fend-use-load-profiles-for-us-building-stock%2F2023%2Fcomstock_amy2018_release_2%2Fmetadata_and_annual_results%2Fby_state%2Fstate%3DCA%2F
A6: Prototype | B6: Pacific Northwest National Laboratory (PNNL) Large Hotel prototype (ASHRAE 90.1-2022) | C6: https://www.energycodes.gov/prototype-building-models#Commercial
B7: Database for Energy Efficient Resources (DEER) Hotel prototype (June 2024) | C7: https://github.com/sound-data/DEER-Prototypes-EnergyPlus
B8: Department of Energy (DOE) Large Hotel 2004 Prototype | C8: https://www.energy.gov/eere/buildings/new-construction-commercial-reference-buildings
B9: California Energy Commission (CEC) Small Hotel prototype (CBECC 2022.3.1) | C9: https://bees.noresco.com/software2022.html
A10: Codes | B10: Title 24, part 6, referred to as T24 (1984, 1992,1998, 2001, 2005, 2008, 2013, 2016,2019, 2022, 2025) | C10: https://www.energy.ca.gov/publications/2025/2025-building-energy-efficiency-standards-residential-and-nonresidential | D10: 2025
C11: https://codes.iccsafe.org/codes/united-states/california | D11: 2010+
B12: American Society of Heating, Refrigerating and Air-Conditioning Engineers (ASHRAE) 90.1 (2022) | C12: https://www.ashrae.org/technical-resources/standards-and-guidelines/read-only-versions-of-ashrae-standards
B13: Title 20 | C13: https://govt.westlaw.com/calregs/Document/I270DCA634B4011EFA8F7F119BAF97AD6?viewType=FullText&originationContext=documenttoc&transitionType=CategoryPageItem&contextData=(sc.Default)
A15: Others | B15: Alternative Calculation Method (ACM) (2022) | C15: https://www.energy.ca.gov/publications/2022/2022-nonresidential-and-multifamily-alternative-calculation-method-reference
B16: ACM (2025) | C16: https://www.energy.ca.gov/publications/2025/2025-nonresidential-and-multifamily-alternative-calculation-method-reference
B17: Nonres ACM 2022, Appendix 5.4A and Appendix 5.4B | C17: https://www.energy.ca.gov/publications/2022/2022-nonresidential-and-multifamily-alternative-calculation-method-reference
B18: 2022 Reduced infiltration Codes and Standards Enhancement (CASE) report | C18: https://title24stakeholders.com/wp-content/uploads/2020/10/2022-T24-Final-CASE-Report_Reduce-Infiltration.pdf
B19: Honeywell, INNCOM e7 Thermostat User Guide, 2017 | C19: https://prod-edam.honeywell.com/content/dam/honeywell-edam/hbt/en-us/documents/manuals-and-guides/installation-guides/inncom/hbt-bms-INNCOM-e7-USER-GUIDE.pdf?download=false
B20: 2019 Outdoor Lighting CASE Report | C20: https://title24stakeholders.com/wp-content/uploads/2016/10/T24-2019-CASE-Study-Results-Report-Outdoor-Sources_Final_with-Attachments.pdf
B21: 2024 California Lodging forecast | C21: https://assets.visitcalifornia.com/media/?mediaId=D0CF4716-DD37-4678-852AB388768DE451&viewType=grid
B22: 2025 State of the Industry Report | C22: https://www.ahla.com/sites/default/files/25_SOTI.pdf
B23: PNNL 20405, 2011 | C23: https://www.pnnl.gov/main/publications/external/technical_reports/PNNL-20405.pdf
B24: Air leakage Memo, NORESCO, 2025 | C24: Infiltration_rate_report_14May2025-Short-Version.docx
B25: Yousefi, F., Athalye, R., (2025), "Determining Vintage Bins for Prototype Development: An Analysis of California Commercial Buildings," ASHRAE Annual Conference | C25: https://www.thefreelibrary.com/Determining+Vintage+Bins+for+Prototype+Development%3a+An+Analysis+of...-a0879271125
B26: Proposed Updates to Equipment Power Densities and Building Schedules for the 2028 Energy Code, referred to as "Plug load and schedules project with CEC, 2025" (Docket Number =25-BSTD-03 & TN=265693) | C26: https://efiling.energy.ca.gov/GetDocument.aspx?tn=265693&DocumentContentId=102545
B27: ENERGY STAR certified commercial water heaters | C27: https://www.energystar.gov/productfinder/product/certified-commercial-water-heaters/results?fuel_filter=Gas&markets_filter=United+States
... B29: Grainger electric tank water heaters | C29: https://www.grainger.com/category/plumbing/water-heaters/electric-tank-water-heaters
A31: Construction Rate
B43: Source:Dodge Construction Data, 2023 ( NEW Hotels above 60,000 sf built after 1967) (STC refers to building types in Dodge terminology).
A44: Notes
A45: HotelLarge Prototype | B45: The HotelLarge prototype was developed to represent California large hotels with floor area above 60,000 ft² , no matter of their number of stories. According to Dodge (2023), the average large hotel in California is described as a 9‑story building with a total floor area of 150,000 sf and a footprint of 16,600 sf. In comparison, the PNNL large hotel prototype is characterized as a 7‑story building with a total floor area of 122,000 sf and a 17,400 sf footprint, placing its footprint within 5% of the California average. Because the prototype is considered well established and has defined zoning, it is selected as the basis for the model and modified through the addition of two floors. With this modification, alignment with the California building stock assessment is achieved, and the percentage of guest rooms is increased.
A72: "NUMPRO=1" refers to Dodge records with only one building per record, while "All extended" includes all the records.
A73: Source:Dodge Construction Data, 2023 ( NEW Hotels above 60,000 sf built after 1967) (STC refers to building types in Dodge terminology).
A75: 1984 is the representative year for the 1984-1997 vintage bin | B75: "Most large hotels in this vintage bin were built after 1984 (more than 53% ) and the CA energy code did not noticeably changed between 1984 to 1992) Also "Heat Capacity" for external wall is considered between 10.0 to 14.99 (Btu/F/ft²) Package A was selected for the thermal properties, and the prescriptive criteria of high-rise office buildings were also applied to the large hotel.
A76: 2001 is the representative year for the 1998-2007 vintage bin | B76: Wall and roof prescriptive criteria from 1998 to 2005 remain unchanged except for CZ2 and 6 in 2001 code (the percentage of change is less than 10%).
B77: Since the construction rate between 1998-2005 is greater than the 2006-2007 period, the envelope properties of 1998 -2005 were chosen for envelope properties. Since the windows requirement considerably changed in the 2001 code, the nominated year for this vintage is 2001.
A78: 2013 is the representative year for the 2008-2018 vintage bin | B78: Wall properties remain unchanged from the 2008 code to the 2016 code but the roof did changed. Although the 2016 code introduced improvement for roof in nearly all CZ and for wall in a few CZ, and construction activity surged between 2017 and 2018, the extended period from 2008 to 2016 resulted in a higher construction rate during that time . As a result, it was decided to select the code that was effective during 2008-2016.
B79: Construction activity from 2014-2018 was higher compared to 2008-2013 period. Therefore, the 2013 code was chosen as the representative code. Additionally, the 2013 code modified the solar reflectance requirement for low-sloped roof products ( by approximately 15%), and enhanced window properties.

Sheet Prototype
A1: NORESCO, Updated September 2026
A2: HotelLarge
A3: Characteristic | B3: Value | C3: Data Sources
A4: Building Type | B4: Large Hotel
A5: Building Category | B5: Nonresidential
A6: Version | B6: v2-0
A7: Vintages | B7: 4 Vintages: Pre-1978 , 1978-1997 ,1998-2007 , 2008-2018 New Construction (2019+) | C7: Based on the vintage bin analysis. A summary of the findings is presented in the following paper, with a link provided in the Notes tab: Yousefi, F., Athalye, R. (2025). “Determining Vintage Bins for Prototype Development: An Analysis of California Commercial Buildings.” ASHRAE Annual Conference.
A8: Shape | C8: PNNL Hotel Large 2022 prototype, modified by adding two additional living floors, based on Dodge 2023 data analysis and update zoning of the basement and ground floor.
A9: Total Floor Area (ft²) | B9: 153,921 (284 ft x 75 ft) | C9: Total floor area : Dodge 2023 data, Footprint :PNNL Hotel Large 2022
A10: Aspect Ratio | B10: Ground floor: 3.79 (284 ft x 75 ft) All other floors: 5.07 (284 ft x 56 ft) | C10: Assumption: PNNL Hotel Large 2022
A11: Number of Floors | B11: 8 above-ground floors plus one basement | C11: Dodge 2023 data,
A12: Surface to Floor Area Ratio
A13: Number of Guestrooms | B13: 263 (accounting for about 48% of the total floor area)
A14: Roof type | B14: Flat roof
A15: WWR | B15: South: 36.7%, East: 24.5%, North: 26.0%, West: 24.5% Total: 30.2% | C15: Assumption: PNNL Hotel Large 2022
A16: Shading Geometry | B16: -
A17: Floor to floor height (ft) | B17: Basement: 13 ft Ground floor: 13 ft 2nd - 6th floors: 10 ft | C17: Assumptions: PNNL Hotel Large 2022 Basement height: assumed based on the average basement height of typical large hotels, considering associated space requirements
A18: Floor to ceiling height (ft) | B18: Basement: 13 ft Ground floor: 13 ft 2nd - 8th floors: 10 ft | C18: Assumptions: PNNL Hotel Large 2022 Basement height: assumed based on the average basement height of typical large hotels, considering associated space requirements
A19: Glazing sill height (ft) | B19: 6 in.(in ground floor), 3.6 ft. (in upper floors) | C19: Assumptions:PNNL Hotel Large 2022
A23: Above grade wall area (ft²) | B23: 43333.6
A24: Gross wall area (ft²) | B24: 49079.02
A25: Roof area (ft²) | B25: 21300.06
A26: Underground Gross Wall Area (ft²) | B26: 5745.5
A35: Background Data
A38: Existing Public Prototypes:
B39: CPUC | C39: PNNL | E39: Zone | F39: CPUC | J39: PNNL
A40: Geometry | F40: Area share (%) | G40: People (ft² per person) | H40: Lighting (W/ft²) | I40: Plug and Process (W/ft²) | J40: Area share | K40: People (ft² per person) | L40: Lighting (W/ft²) | M40: Plug and Process (W/ft²) | N40: Electric Load (W/ft²) | O40: Gas Load (W/ft²)
A41: Stories | B41: 4 stories | C41: 6 Stories + Basement | E41: Small Guest room | F41: 0.1597292 | G41: 399.98691 | H41: 0.50000416 | I41: 0.50000416 | J41: 0.34809077 | K41: 175.98994 | L41: 0.40970241 | M41: 0.97733998 | N41: 0.97733998 | O41: 0
A42: Total floor area (ft²) | B42: =CONVERT(6369.28,"m2","ft2") -> 68558.359 | C42: =CONVERT(11345.29,"m2","ft2") -> 122119.69 | E42: Large Guest room | F42: 0.47920644 | G42: 399.98691 | H42: 0.50000416 | I42: 0.50000416 | J42: 0.061905446 | K42: 279.96931 | L42: 0.40970241 | M42: 0.62709552 | N42: 0.62709552 | O42: 0
A43: Planus (ft²) | B43: Yes: 68,558 | C43: No | E43: Corridor | F43: 0.080467494 | G43: 199.99346 | H43: 0.40000333 | I43: 0 | J43: 0.17360954 | K43: 199.99346 | L43: 0.41806368 | M43: 0 | N43: 0 | O43: 0
A44: Multiplier | B44: No | C44: Yes | E44: Dining | F44: 0.011665369 | G44: 30.03131 | H44: 0.40000333 | I44: 0.50000416 | J44: 0.029232246 | K44: 14.316001 | L44: 0.72185662 | M44: 6.3006842 | N44: 6.3006842 | O44: 0
A45: Number of Guest room | B45: 12 | C45: 179 | E45: Kitchen | F45: 0.014568366 | G45: 399.98691 | H45: 0.94999862 | I45: 7.7591225 | J45: 0.009104779 | K45: 50.052183 | L45: 1.1305371 | M45: 272.34526 | N45: 47.588932 | O45: 224.75661
A46: Above Ground WWR | B46: 0.2228 | C46: 0.3015 | E46: Lobby | F46: 0.11990366 | G46: 30.03131 | H46: 0.69999654 | I46: 0.50000416 | J46: 0.11530282 | K46: 33.368122 | L46: 0.75994687 | M46: 0.74972753 | N46: 0.74972753 | O46: 0
A47: Areas: | E47: Laundry | F47: 0.059948691 | G47: 199.99346 | H47: 0.45000375 | I47: 3.2200008 | J47: 0.0068783829 | K47: 99.996728 | L47: 0.48402484 | M47: 55.512353 | N47: 5.7302595 | O47: 49.782094
A48: Window Opening Area (ft²) | B48: 6744.9892 | C48: 13065.127 | E48: Office | F48: 0.059948691 | G48: 199.99346 | H48: 0.5999957 | I48: 1.5000032
A49: Skylight Area (ft²) | B49: 0 | C49: 0 | E49: Barcasino | F49: 0.014568366 | G49: 30.03131 | H49: 0.40000333 | I49: 0.50000416
A50: Gross Roof Area (ft²) | B50: 239.81992 | C50: 21300.056 | E50: Basement | J50: 0.17441249 | K50: 199.99346 | L50: 0.57599885 | M50: 0.49981836 | N50: 0.49981836 | O50: 0
A51: Gross Wall Area (ft²) | B51: 30277.696 | C51: 49079.018 | E51: Retail | J51: 0.012757267 | K51: 66.628605 | L51: 0.70234698 | M51: 0.99963671 | N51: 0.49981836 | O51: 0
A52: Above Ground Wall Area (ft²) | B52: 30277.696 | C52: 43333.566 | E52: Mech | J52: 0.014475982 | K52: 666.60897 | L52: 0.67447607 | M52: 0.49981836 | N52: 0.49981836 | O52: 0
A53: Loads | E53: Storage | J53: 0.0083520703 | K53: 499.98364 | L53: 0.35117349 | M53: 0.24990918 | N53: 0.24990918 | O53: 0
...

Sheet Zones
A1: ="Proposed Layout - "&Prototype!A2 -> Proposed Layout - HotelLarge | P1: N
A2: Building | B2: Space/ Thermal Zone | C2: Space Type [Primarily from: T24, 2022 Appendix 5.4A] - See Notes column | D2: HVAC System Name/AHU Name | E2: Schedule Category | F2: Conditioned (Y/N) | G2: Area Fraction | H2: Area (ft²) | I2: Volume (ft³) | J2: Multipliers | K2: Number of People | L2: People (Persons/1,000 ft²) [T24, 2025,Table 120.1-A] | M2: Notes
A3: HotelLarge | B3: BasementConference | C3: Convention, Conference, Multipurpose and Meeting Area | E3: Office | F3: Yes | G3: =H3/$H$30 -> 0.048433613 | H3: 7454.9371 | I3: =H3*13 -> 96914.183 | J3: 1 | K3: =L3*H3/1000 -> 246.01293 | L3: 33
A4: HotelLarge | B4: BasementOffice | C4: Office Area (>250 square feet) | E4: Office | F4: Yes | G4: =H4/$H$30 -> 0.010733444 | H4: 1652.0996 | I4: =H4*13 -> 21477.295 | J4: 1 | K4: =L4*H4/1000 -> 8.2604979 | L4: 5
A5: HotelLarge | B5: BasementMechanical | C5: Electrical, Mechanical, Telephone Rooms | E5: Ancillary | F5: Yes | G5: =H5/$H$30 -> 0.011485483 | H5: 1767.854 | I5: =H5*13 -> 22982.102 | J5: 1 | K5: =L5*H5/1000 -> 0 | L5: 0
A6: HotelLarge | B6: BasementLaundry | C6: Laundry Area | E6: Assembly | F6: Yes | G6: =H6/$H$30 -> 0.0054574228 | H6: 840.0105 | I6: =H6*13 -> 10920.137 | J6: 1 | K6: =L6*H6/1000 -> 4.2000525 | L6: 5 | N6: Basement: 6 zones including Storage, service, storage, laundry, mechanical rooms, Office, and conference
A7: HotelLarge | B7: BasementService | C7: Service and back up prep | E7: ServiceAndBackUpPrep | F7: Yes | G7: =H7/$H$30 -> 0.041514526 | H7: 6389.9461 | I7: =H7*13 -> 83069.299 | J7: 1 | K7: =L7*H7/1000 -> 19.169838 | L7: 3
A8: HotelLarge | B8: BasementStorage | C8: Storage (General) | E8: Assembly | F8: Yes | G8: =H8/$H$30 -> 0.020757263 | H8: 3194.9731 | I8: =H8*13 -> 41534.65 | J8: 1 | K8: =L8*H8/1000 -> 0 | L8: 0
A9: HotelLarge | B9: Retail_1_FloorG | C9: Retail Sales Area (Retail Merchandise Sales) | E9: Retail | F9: Yes | G9: =H9/$H$30 -> 0.0046902787 | H9: 721.93112 | I9: =H9*13 -> 9385.1045 | J9: 1 | K9: =L9*H9/1000 -> 12.272829 | L9: 17
A10: HotelLarge | B10: Retail_2_FloorG | C10: Retail Sales Area (Retail Merchandise Sales) | E10: Retail | F10: Yes | G10: =H10/$H$30 -> 0.0054315483 | H10: 836.02788 | I10: =H10*13 -> 10868.362 | J10: 1 | K10: =L10*H10/1000 -> 14.212474 | L10: 17
A11: HotelLarge | B11: Office_FloorG | C11: Office Area (>250 square feet) | E11: Office | F11: Yes | G11: =H11/$H$30 -> 0.011485483 | H11: 1767.854 | I11: =H11*13 -> 22982.102 | J11: 1 | K11: =L11*H11/1000 -> 8.8392699 | L11: 5
A12: HotelLarge | B12: Storage_FloorG | C12: Storage (General) | E12: Assembly | F12: Yes | G12: =H12/$H$30 -> 0.0066266707 | H12: 1019.982 | I12: =H12*13 -> 13259.766 | J12: 1 | K12: =L12*H12/1000 -> 0 | L12: 0
A13: HotelLarge | B13: Kitchen_FloorG | C13: Kitchen/Food Preparation Area | E13: Kitchen | F13: Yes | G13: =H13/$H$30 -> 0.0054574228 | H13: 840.0105 | I13: =H13*13 -> 10920.137 | J13: 1 | K13: =L13*H13/1000 -> 2.5200315 | L13: 3 | N13: FloorG (Ground floor): 7 zones including retails, lobby, cafe, Kitchen, storage and Office;
A14: HotelLarge | B14: Cafe_FloorG | C14: Dining Area (Cafeteria/Fast Food) | E14: =E27 -> Restaurant | F14: Yes | G14: =H14/$H$30 -> 0.013207187 | H14: 2032.8599 | I14: =H14*13 -> 26427.178 | J14: 1 | K14: =L14*H14/1000 -> 67.084375 | L14: 33
A15: HotelLarge | B15: Lobby_FloorG | C15: Lobby, Main Entry | E15: ResidentialCommon | F15: Yes | G15: =H15/$H$30 -> 0.091483162 | H15: 14081.155 | I15: =H15*13 -> 183055.02 | J15: 1 | K15: =L15*H15/1000 -> 140.81155 | L15: 10 | M15: For entrance lobbies, 10 persons per 1,000 ft² are assumed based on ASHRAE 62.1 Table 6‑1 (Office Entrance). The Title 24 assumptions for main entry lobbies result in an unrealistically high total occupant count and therefore was not used. Title 24 specifies 33 persons per 1,000 ft² for main entry lobbies and 5 persons per 1,000 ft² for reception areas.
A16: HotelLarge | B16: GuestRoom_1_FloorM | C16: Hotel/Motel Guest Room | E16: ResidentialLiving | F16: Yes | G16: =H16/$H$30 -> 0.0027287114 | H16: 420.00525 | I16: =H16*10 -> 4200.0525 | J16: 6 | K16: =L16*H16/1000 -> 1.2600158 | L16: 3
A17: HotelLarge | B17: GuestRoom_2_FloorM | C17: Hotel/Motel Guest Room | E17: =E16 -> ResidentialLiving | F17: Yes | G17: =H17/$H$30 -> 0.0027287114 | H17: 420.00525 | I17: =H17*10 -> 4200.0525 | J17: 6 | K17: =L17*H17/1000 -> 1.2600158 | L17: 3
A18: HotelLarge | B18: GuestRoom_3_Multi19_FloorM | C18: Hotel/Motel Guest Room | E18: =E16 -> ResidentialLiving | F18: Yes | G18: =H18/$H$30 -> 0.0017147105 | H18: 263.92949 | I18: =H18*10 -> 2639.2949 | J18: =6*19 -> 114 | K18: =L18*H18/1000 -> 0.79178847 | L18: 3
A19: HotelLarge | B19: GuestRoom_4_Multi19_FloorM | C19: Hotel/Motel Guest Room | E19: =E16 -> ResidentialLiving | F19: Yes | G19: =H19/$H$30 -> 0.0017154098 | H19: 264.03713 | I19: =H19*10 -> 2640.3713 | J19: =6*19 -> 114 | K19: =L19*H19/1000 -> 0.79211139 | L19: 3 | S19: Full view of FloorM
A20: HotelLarge | B20: GuestRoom_5_FloorM | C20: Hotel/Motel Guest Room | E20: =E16 -> ResidentialLiving | F20: Yes | G20: =H20/$H$30 -> 0.0027287114 | H20: 420.00525 | I20: =H20*10 -> 4200.0525 | J20: 6 | K20: =L20*H20/1000 -> 1.2600158 | L20: 3 | N20: FloorM (Middle floors): 2nd to 7th Floor : 7 zones per floor, including guest rooms and corridor. Each floor has 42 guest rooms;
A21: HotelLarge | B21: GuestRoom_6_FloorM | C21: Hotel/Motel Guest Room | E21: =E16 -> ResidentialLiving | F21: Yes | G21: =H21/$H$30 -> 0.0027287114 | H21: 420.00525 | I21: =H21*10 -> 4200.0525 | J21: 6 | K21: =L21*H21/1000 -> 1.2600158 | L21: 3
A22: HotelLarge | B22: Corridor_FloorM | C22: Corridor Area | E22: ResidentialCommon | F22: Yes | G22: =H22/$H$30 -> 0.027231169 | H22: 4191.4414 | I22: =H22*10 -> 41914.414 | J22: 6 | K22: =L22*H22/1000 -> 20.957207 | L22: 5
A23: HotelLarge | B23: GuestRoom_1_FloorT | C23: Hotel/Motel Guest Room | E23: =E16 -> ResidentialLiving | F23: Yes | G23: =H23/$H$30 -> 0.0027287114 | H23: 420.00525 | I23: =H23*10 -> 4200.0525 | J23: 1 | K23: =L23*H23/1000 -> 1.2600158 | L23: 3
A24: HotelLarge | B24: GuestRoom_2_FloorT | C24: Hotel/Motel Guest Room | E24: =E16 -> ResidentialLiving | F24: Yes | G24: =H24/$H$30 -> 0.0027287114 | H24: 420.00525 | I24: =H24*10 -> 4200.0525 | J24: 1 | K24: =L24*H24/1000 -> 1.2600158 | L24: 3
A25: HotelLarge | B25: GuestRoom_3_Multi9_FloorT | C25: Hotel/Motel Guest Room | E25: =E16 -> ResidentialLiving | F25: Yes | G25: =H25/$H$30 -> 0.0017154098 | H25: 264.03713 | I25: =H25*10 -> 2640.3713 | J25: 9 | K25: =L25*H25/1000 -> 0.79211139 | L25: 3
A26: HotelLarge | B26: Banquet_FloorT | C26: Hotel Function Area | E26: Assembly | F26: Yes | G26: =H26/$H$30 -> 0.023193348 | H26: 3569.937 | I26: =H26*10 -> 35699.37 | J26: 1 | K26: =L26*H26/1000 -> 117.80792 | L26: 33 | M26: Occupancy based on "Restaurant Dining Area"
A27: HotelLarge | B27: Dining_FloorT | C27: Dining Area (Bar/Lounge and Fine Dining) | E27: Restaurant | F27: Yes | G27: =H27/$H$30 -> 0.023193348 | H27: 3569.937 | I27: =H27*10 -> 35699.37 | J27: 1 | K27: =L27*H27/1000 -> 117.80792 | L27: 33
A28: HotelLarge | B28: Kitchen_FloorT | C28: Kitchen/Food Preparation Area | E28: Kitchen | F28: Yes | G28: =H28/$H$30 -> 0.0072238823 | H28: 1111.9052 | I28: =H28*10 -> 11119.052 | J28: 1 | K28: =L28*H28/1000 -> 3.3357157 | L28: 3
A29: HotelLarge | B29: Corridor_FloorT | C29: Corridor Area | E29: =E22 -> ResidentialCommon | F29: Yes | G29: =H29/$H$30 -> 0.028820004 | H29: 4435.996 | I29: =H29*10 -> 44359.96 | J29: 1 | K29: =L29*H29/1000 -> 22.17998 | L29: 5 | S29: Full view of FloorT
A30: Total (1 Building) | B30: Total (286 Space/Thermal Zones) | C30: Total (14 Space Types) | E30: Total (9 Schedule categories) | F30: Total (286 Conditioned zones) | G30: =SUMPRODUCT(G3:G29,J3:J29) -> 1 | H30: =SUMPRODUCT(H3:H29,J3:J29) -> 153920.73 | I30: =SUMPRODUCT(I3:I29,J3:J29) -> 1667006.2 | N30: FloorT (Top floor): 9th Floor: 7 zones including guest rooms, banquet room, dining, kitchen and corridor.
B32: Ref for layout and zoning: PNNL Large Hotel prototypes (ASHRAE 90.1 2022)
B35: Occupancy Rate
B36: % of occupied guest rooms | C36: Source
B37: 0.65 | C37: California Lodging Forecast (April 2025)
C38: 2025 State of the industry report
C41: Number of Guest room | D41: =SUM(J16:J21,J23:J25) -> 263
C42: Guest room (ft²) | D42: =SUMPRODUCT(H16:H21,J16:J21)+SUMPRODUCT(H23:H25,J23:J25) -> 73484.666
C43: Guest room % ( all floors except basement) | D43: =D42/(H30-SUM(H3:H8)) -> 0.55409562
C44: Guest room % ( all floors) | D44: =D42/H30 -> 0.4774189

Sheet Envelope
A1: ="Envelope - "&Prototype!A2 -> Envelope - HotelLarge
A2: Element | B2: Prototype | C2: Assembly Type | D2: Construction | E2: Thermal Properties | F2: Vintage | G2: Selected T24 | H2: Notes | I2: CZ1 | J2: CZ2 | K2: CZ3 | L2: CZ4 | M2: CZ5 | N2: CZ6 | O2: CZ7 | P2: CZ8 | Q2: CZ9 | R2: CZ10 | S2: CZ11 | T2: CZ12 | U2: CZ13 | V2: CZ14 | W2: CZ15 | X2: CZ16
A3: External Wall_ Guest Room (FloorM and FloorT) | B3: HotelLarge | C3: ExtWall_MetalFramed_GuestRooms | D3: Metal framed wall: Stucco + Metal frame + insulation + Gypsum board | E3: U-factor IP | F3: Pre 1978 | G3: N/A | H3: ASHRAE 90.1, 2022, Table A3.3.3.1, 3.5", R-0 | I3: 0.352 | J3: 0.352 | K3: 0.352 | L3: 0.352 | M3: 0.352 | N3: 0.352 | O3: 0.352 | P3: 0.352 | Q3: 0.352 | R3: 0.352 | S3: 0.352 | T3: 0.352 | U3: 0.352 | V3: 0.352 | W3: 0.352 | X3: 0.352
F4: 1978-1997 | G4: 1986 | H4: Copied from High-rise office alternative requirements (Table 2-53W): Package A with heat capacity between 10-14.99 (Btu/F-ft²) *T24, 1986, Table 2-53B presents U-factors less than the next vintage (for wall density of 26-40 lb/ft² & Degree day<3500)! | I4: =1/4.7 -> 0.21276596 | J4: =1/4.4 -> 0.22727273 | K4: =1/4.4 -> 0.22727273 | L4: =1/4.6 -> 0.2173913 | M4: =1/4.6 -> 0.2173913 | N4: =1/3.9 -> 0.25641026 | O4: =1/3.9 -> 0.25641026 | P4: =1/3.9 -> 0.25641026 | Q4: =1/3.9 -> 0.25641026 | R4: =1/3.9 -> 0.25641026 | S4: =1/4.2 -> 0.23809524 | T4: =1/4.2 -> 0.23809524 | U4: =1/4.2 -> 0.23809524 | V4: =1/4.8 -> 0.20833333 | W4: =1/4.8 -> 0.20833333 | X4: =1/4.7 -> 0.21276596 | Y4: * Heat capacity might be close to 4-9.99 categories for mix of steel frame and concrete (concrete for fist floor) . However, selecting this category will result in U values lower than the next vintage to both REs and Nonres! (for HC below 4 Btu/F-ft², all CZ is 1/7.4)
F5: 1998-2007 | G5: 2001 | H5: Table 1-I | I5: 0.14 | J5: 0.175 | K5: 0.181 | L5: 0.181 | M5: 0.181 | N5: 0.181 | O5: 0.181 | P5: 0.181 | Q5: 0.181 | R5: 0.175 | S5: 0.175 | T5: 0.175 | U5: 0.175 | V5: 0.175 | W5: 0.175 | X5: 0.14
F6: 2008-2018 | G6: 2013 | H6: Table 140.3-C | I6: 0.105 | J6: 0.105 | K6: 0.105 | L6: 0.105 | M6: 0.105 | N6: 0.105 | O6: 0.105 | P6: 0.105 | Q6: 0.105 | R6: 0.105 | S6: 0.105 | T6: 0.105 | U6: 0.105 | V6: 0.105 | W6: 0.105 | X6: 0.105
F7: 2019+ | G7: 2025 | H7: Table 140.3-C | I7: 0.069 | J7: 0.069 | K7: 0.069 | L7: 0.069 | M7: 0.069 | N7: 0.069 | O7: 0.105 | P7: 0.069 | Q7: 0.069 | R7: 0.069 | S7: 0.069 | T7: 0.069 | U7: 0.069 | V7: 0.069 | W7: 0.048 | X7: 0.069
A8: External Wall_ Nonres (FloorG) | B8: HotelLarge | C8: ExtWall_MassHeavy_NonRes | D8: Heavy mass wall: Stucco + 8 in Concrete + insulation + Gypsum board | E8: U-factor IP | F8: Pre 1978 | G8: N/A | H8: ASHRAE 90.1, 2022, Table A3.1-1, R-0 | I8: 0.74 | J8: 0.74 | K8: 0.74 | L8: 0.74 | M8: 0.74 | N8: 0.74 | O8: 0.74 | P8: 0.74 | Q8: 0.74 | R8: 0.74 | S8: 0.74 | T8: 0.74 | U8: 0.74 | V8: 0.74 | W8: 0.74 | X8: 0.74
F9: 1978-1997 | G9: 1992 | H9: Same as 1992. No direct regulation was found in 1986 for concrete walls. Also, T24, 1986, Table 2-53B and Equation 2-53E presents U-factors more than the previous vintage (for wall density of >81 lb/ft² & Degree day<3000). | I9: 0.36 | J9: 0.65 | K9: 0.65 | L9: 0.65 | M9: 0.65 | N9: 0.69 | O9: 0.69 | P9: 0.69 | Q9: 0.69 | R9: 0.69 | S9: 0.65 | T9: 0.65 | U9: 0.65 | V9: 0.4 | W9: 0.4 | X9: 0.36
F10: 1998-2007 | G10: 2001 | H10: Table 1-H | I10: 0.36 | J10: 0.65 | K10: 0.65 | L10: 0.65 | M10: 0.65 | N10: 0.69 | O10: 0.69 | P10: 0.69 | Q10: 0.69 | R10: 0.65 | S10: 0.65 | T10: 0.65 | U10: 0.65 | V10: 0.4 | W10: 0.4 | X10: 0.36
F11: 2008-2018 | G11: 2013 | H11: Table 140.3-B | I11: 0.253 | J11: 0.65 | K11: 0.65 | L11: 0.65 | M11: 0.65 | N11: 0.69 | O11: 0.69 | P11: 0.69 | Q11: 0.69 | R11: 0.65 | S11: 0.184 | T11: 0.253 | U11: 0.211 | V11: 0.184 | W11: 0.184 | X11: 0.16
F12: 2019+ | G12: 2025 | H12: Table 140.3-B (Nonres) | I12: 0.211 | J12: 0.65 | K12: 0.65 | L12: 0.65 | M12: 0.65 | N12: 0.69 | O12: 0.69 | P12: 0.69 | Q12: 0.69 | R12: 0.65 | S12: 0.16 | T12: 0.211 | U12: 0.184 | V12: 0.16 | W12: 0.16 | X12: 0.153
A13: Roof_Guest Room (FloorT) | B13: HotelLarge | C13: FlatRoof_WoodFramedAndOther_GuestRooms | D13: Metal deck roof: Roof membrane + insulation + Metal Deck | E13: U-factor IP | F13: Pre 1978 | G13: N/A | H13: Considering 30 years for roof/ insulation replacement. ( Guest room requirement) | I13: =I14 -> 0.037 | J13: =J14 -> 0.051 | K13: =K14 -> 0.051 | L13: =L14 -> 0.051 | M13: =M14 -> 0.051 | N13: =N14 -> 0.051 | O13: =O14 -> 0.051 | P13: =P14 -> 0.051 | ... X13: =X14 -> 0.037
F14: 1978-1997 | G14: 1992 | I14: 0.037 | J14: 0.051 | K14: 0.051 | L14: 0.051 | M14: 0.051 | N14: 0.051 | O14: 0.051 | P14: 0.051 | Q14: 0.051 | R14: 0.051 | S14: 0.037 | T14: 0.037 | U14: 0.037 | V14: 0.037 | W14: 0.037 | X14: 0.037
F15: 1998-2007 | G15: 2001 | H15: Table 1-I (the lowest U-factor between Nonres and Guest room was considered) | I15: 0.037 | J15: 0.037 | K15: 0.051 | L15: 0.051 | M15: 0.051 | N15: 0.051 | O15: 0.051 | P15: 0.051 | Q15: 0.051 | R15: 0.037 | S15: 0.037 | T15: 0.037 | U15: 0.037 | V15: 0.037 | W15: 0.037 | X15: 0.037
F16: 2008-2018 | G16: 2013 | H16: Table 140.3-C (the lowest U-factor between Nonres and Guest room was considered) | I16: 0.034 | J16: 0.028 | K16: 0.039 | L16: 0.028 | M16: 0.039 | N16: 0.039 | O16: 0.039 | P16: 0.028 | Q16: 0.028 | R16: 0.028 | S16: 0.028 | T16: 0.028 | U16: 0.028 | V16: 0.028 | W16: 0.028 | X16: 0.028
F17: 2019+ | G17: 2025 | H17: Table 140.3-C (the lowest U-factor between Nonres and Guest room was considered) | I17: 0.028 | J17: 0.028 | K17: 0.028 | L17: 0.028 | M17: 0.034 | N17: 0.034 | O17: 0.039 | P17: 0.028 | Q17: 0.028 | R17: 0.028 | S17: 0.028 | T17: 0.028 | U17: 0.028 | V17: 0.028 | W17: 0.028 | X17: 0.028
A18: Roof_Nonres (FloorG) | B18: HotelLarge | C18: FlatRoof_WoodFramedAndOther_NonRes | D18: Metal deck roof: Roof membrane + insulation + Metal Deck | E18: U-factor IP | F18: Pre 1978 | G18: N/A | H18: Considering 30 years for roof/ insulation replacement. ( Guest room requirement) | I18: 0.057 | J18: 0.057 | K18: 0.057 | L18: 0.057 | M18: 0.057 | N18: 0.078 | O18: 0.078 | P18: 0.078 | Q18: 0.078 | R18: 0.078 | S18: 0.057 | T18: 0.057 | U18: 0.057 | V18: 0.057 | W18: 0.057 | X18: 0.057
F19: 1978-1997 | G19: 1992 | I19: 0.057 | J19: 0.057 | K19: 0.057 | L19: 0.057 | M19: 0.057 | N19: 0.078 | O19: 0.078 | P19: 0.078 | Q19: 0.078 | R19: 0.078 | S19: 0.057 | T19: 0.057 | U19: 0.057 | V19: 0.057 | W19: 0.057 | X19: 0.057
F20: 1998-2007 | G20: 2001 | H20: Table 1-H | I20: 0.057 | J20: 0.057 | K20: 0.057 | L20: 0.057 | M20: 0.057 | N20: 0.078 | O20: 0.078 | P20: 0.078 | Q20: 0.078 | R20: 0.057 | S20: 0.057 | T20: 0.057 | U20: 0.057 | V20: 0.057 | W20: 0.057 | X20: 0.057
F21: 2008-2018 | G21: 2013 | H21: Table 140.3-B | I21: 0.049 | J21: 0.039 | K21: 0.039 | L21: 0.039 | M21: 0.049 | N21: 0.075 | O21: 0.067 | P21: 0.067 | Q21: 0.039 | R21: 0.039 | S21: 0.039 | T21: 0.039 | U21: 0.039 | V21: 0.039 | W21: 0.039 | X21: 0.039
F22: 2019+ | G22: 2025 | H22: Table 140.3-B | I22: 0.028 | J22: 0.028 | K22: 0.028 | L22: 0.028 | M22: 0.028 | N22: 0.047 | O22: 0.047 | P22: 0.047 | Q22: 0.028 | R22: 0.028 | S22: 0.028 | T22: 0.028 | U22: 0.028 | V22: 0.028 | W22: 0.028 | X22: 0.028
A23: Windows_ Guest Room (FloorM and FloorT) | B23: HotelLarge | C23: FixedWindow_GuestRoom | D23: CBECS 2018 shows that ~43% of Large Hotels that were built before 2000 are single pane | E23: U-factor IP | F23: Pre 1978 | G23: N/A | H23: ASHRAE Handbook of Fundamentals for single pane (Table 4-Ch15)& T24, 2013 for double pane (43%-57%) | I23: 0.6868 | J23: 0.6868 | K23: 0.6868 | L23: 0.6868 | M23: 0.6868 | N23: 0.6868 | O23: 0.6868 | P23: 0.6868 | Q23: 0.6868 | R23: 0.6868 | S23: 0.6868 | T23: 0.6868 | U23: 0.6868 | V23: 0.6868 | W23: 0.6868 | X23: 0.6868
F24: 1978-1997 | G24: N/A | I24: 0.6868 | J24: 0.6868 | K24: 0.6868 | L24: 0.6868 | M24: 0.6868 | N24: 0.6868 | O24: 0.6868 | P24: 0.6868 | Q24: 0.6868 | R24: 0.6868 | S24: 0.6868 | T24: 0.6868 | U24: 0.6868 | V24: 0.6868 | W24: 0.6868 | X24: 0.6868
D25: Double pane | F25: 1998-2007 | G25: 2001 | H25: Table 1-I | I25: 0.49 | J25: 0.49 | K25: 0.49 | L25: 0.49 | M25: 0.49 | N25: 0.49 | O25: 0.49 | P25: 0.49 | Q25: 0.49 | R25: 0.49 | S25: 0.49 | T25: 0.49 | U25: 0.49 | V25: 0.49 | W25: 0.49 | X25: 0.49
F26: 2008-2018 | G26: 2013 | H26: Table 140.3-C | I26: 0.36 | J26: 0.36 | K26: 0.36 | L26: 0.36 | M26: 0.36 | N26: 0.36 | O26: 0.36 | P26: 0.36 | Q26: 0.36 | R26: 0.36 | S26: 0.36 | T26: 0.36 | U26: 0.36 | V26: 0.36 | W26: 0.36 | X26: 0.36
F27: 2019+ | G27: 2025 | H27: Table 140.3-C | I27: 0.36 | J27: 0.36 | K27: 0.36 | L27: 0.36 | M27: 0.36 | N27: 0.36 | O27: 0.36 | P27: 0.36 | Q27: 0.36 | R27: 0.36 | S27: 0.36 | T27: 0.36 | U27: 0.36 | V27: 0.36 | W27: 0.36 | X27: 0.36
D28: CBECS 2018 shows that ~43% of Large Hotels that were built before 2000 are single pane | E28: SHGC | F28: Pre 1978 | G28: N/A | H28: ASHRAE Handbook of Fundamentals for single pane (Table 10-Ch15) & T24, 2013 for double pane (43%-57%) | I28: 0.4822 | J28: 0.4822 | K28: 0.4822 | L28: 0.4822 | M28: 0.4822 | N28: 0.4822 | O28: 0.4822 | P28: 0.4822 | Q28: 0.4822 | R28: 0.4822 | S28: 0.4822 | T28: 0.4822 | U28: 0.4822 | V28: 0.4822 | W28: 0.4822 | X28: 0.4822
F29: 1978-1997 | G29: N/A | I29: 0.4822 | J29: 0.4822 | K29: 0.4822 | L29: 0.4822 | M29: 0.4822 | N29: 0.4822 | O29: 0.4822 | P29: 0.4822 | Q29: 0.4822 | R29: 0.4822 | S29: 0.4822 | T29: 0.4822 | U29: 0.4822 | V29: 0.4822 | W29: 0.4822 | X29: 0.4822
D30: Double pane | F30: 1998-2007 | G30: 2001 | H30: TABLE 1-I (based on non north with WWR 30-40%) | I30: 0.3 | J30: 0.26 | K30: 0.26 | L30: 0.26 | M30: 0.26 | N30: 0.31 | O30: 0.31 | P30: 0.31 | Q30: 0.31 | R30: 0.26 | S30: 0.26 | T30: 0.26 | U30: 0.26 | V30: 0.26 | W30: 0.26 | X30: 0.3
F31: 2008-2018 | G31: 2013 | H31: Table 140.3-C | I31: 0.25 | J31: 0.25 | K31: 0.25 | L31: 0.25 | M31: 0.25 | N31: 0.25 | O31: 0.25 | P31: 0.25 | Q31: 0.25 | R31: 0.25 | S31: 0.25 | T31: 0.25 | U31: 0.25 | V31: 0.25 | W31: 0.25 | X31: 0.25
F32: 2019+ | G32: 2025 | H32: Table 140.3-C | I32: 0.25 | J32: 0.25 | K32: 0.25 | L32: 0.25 | M32: 0.25 | N32: 0.25 | O32: 0.25 | P32: 0.25 | Q32: 0.25 | R32: 0.25 | S32: 0.25 | T32: 0.25 | U32: 0.25 | V32: 0.25 | W32: 0.25 | X32: 0.25
A33: Windows_ Nonres (FloorG) | B33: HotelLarge | C33: FixedWindow_NonRes | D33: CBECS 2018 shows that ~43% of Large Hotels that were built before 2000 are single pane | E33: U-factor IP | F33: Pre 1978 | G33: N/A | H33: ASHRAE Handbook of Fundamentals for single pane (Table 4-Ch15)& T24, 2013 for double pane (43%-57%) | I33: 0.6868 | J33: 0.6868 | K33: 0.6868 | L33: 0.6868 | M33: 0.6868 | N33: 0.6868 | O33: 0.6868 | P33: 0.6868 | Q33: 0.6868 | R33: 0.6868 | S33: 0.6868 | T33: 0.6868 | U33: 0.6868 | V33: 0.6868 | W33: 0.6868 | X33: 0.6868
F34: 1978-1997 | G34: N/A | I34: 0.6868 | J34: 0.6868 | K34: 0.6868 | L34: 0.6868 | M34: 0.6868 | N34: 0.6868 | O34: 0.6868 | P34: 0.6868 | Q34: 0.6868 | R34: 0.6868 | S34: 0.6868 | T34: 0.6868 | U34: 0.6868 | V34: 0.6868 | W34: 0.6868 | X34: 0.6868
D35: Double pane | F35: 1998-2007 | G35: 2001 | H35: Table1-H | I35: 0.49 | J35: 0.49 | K35: 0.81 | L35: 0.81 | M35: 0.81 | N35: 0.81 | O35: 0.81 | P35: 0.81 | Q35: 0.81 | R35: 0.49 | S35: 0.49 | T35: 0.49 | U35: 0.49 | V35: 0.49 | W35: 0.49 | X35: 0.49
F36: 2008-2018 | G36: 2013 | H36: Table 140.3-B | I36: 0.36 | J36: 0.36 | K36: 0.36 | L36: 0.36 | M36: 0.36 | N36: 0.36 | O36: 0.36 | P36: 0.36 | Q36: 0.36 | R36: 0.36 | S36: 0.36 | T36: 0.36 | U36: 0.36 | V36: 0.36 | W36: 0.36 | X36: 0.36
F37: 2019+ | G37: 2025 | H37: Table 140.3-B | I37: 0.36 | J37: 0.36 | K37: 0.36 | L37: 0.36 | M37: 0.36 | N37: 0.36 | O37: 0.36 | P37: 0.36 | Q37: 0.34 | R37: 0.36 | S37: 0.34 | T37: 0.34 | U37: 0.34 | V37: 0.34 | W37: 0.34 | X37: 0.36
D38: CBECS 2018 shows that ~43% of Large Hotels that were built before 2000 are single pane | E38: SHGC | F38: Pre 1978 | G38: N/A | H38: ASHRAE Handbook of Fundamentals for single pane (Table 10-Ch15) & T24, 2013 for double pane (43%-57%) | I38: 0.4822 | J38: 0.4822 | K38: 0.4822 | L38: 0.4822 | M38: 0.4822 | N38: 0.4822 | O38: 0.4822 | P38: 0.4822 | Q38: 0.4822 | R38: 0.4822 | S38: 0.4822 | T38: 0.4822 | U38: 0.4822 | V38: 0.4822 | W38: 0.4822 | X38: 0.4822
F39: 1978-1997 | G39: N/A | I39: 0.4822 | J39: 0.4822 | K39: 0.4822 | L39: 0.4822 | M39: 0.4822 | N39: 0.4822 | O39: 0.4822 | P39: 0.4822 | Q39: 0.4822 | R39: 0.4822 | S39: 0.4822 | T39: 0.4822 | U39: 0.4822 | V39: 0.4822 | W39: 0.4822 | X39: 0.4822
D40: Double pane | F40: 1998-2007 | G40: 2001 | H40: Table 1-H (based on non north with WWR 30-40% ) | I40: 0.43 | J40: 0.31 | K40: 0.41 | L40: 0.41 | M40: 0.41 | N40: 0.34 | O40: 0.34 | P40: 0.34 | Q40: 0.34 | R40: 0.31 | S40: 0.31 | T40: 0.31 | U40: 0.31 | V40: 0.31 | W40: 0.31 | X40: 0.43
...

Sheet HVAC System
A1: ="HVAC System - "&Prototype!A2 -> HVAC System - HotelLarge
A2: Vintage | B2: Spaces | C2: Heating | D2: Cooling | E2: Air Distribution | F2: Other Systems | G2: Source | H2: Note
A3: Existing | B3: Common spaces | C3: Gas Boiler | D3: Air-cooled Chiller | E3: VAV + Hydronic reheat | F3: Economizer (only 2008-2018) No DOAS - OA through main VAV air handler | G3: CEUS 2022 (Other system based on T24 and Engineering judgement) | H3: Chiller is air cooled if the chiller capacity if below 300 ton as T24, 2025, section 170.2(c)4H (Page 563) banned having more than 300 ton of cooling provide by air cooled chiller.
B4: Guest rooms | C4: Gas Boiler | D4: Air-cooled Chiller | E4: FPFC (single speed fan) | F4: Exhaust-Only Ventilation | G4: CEUS 2022 (Other system based on Engineering judgement)
A5: New Construction | B5: Common spaces | C5: Gas Boiler | D5: Air-cooled Chiller | E5: VAV + Hydronic reheat | F5: Economizer No DOAS - OA through main VAV air handler | G5: ACM 2025, Table 2 and 3 (Other system based on Engineering judgement)
B6: Guest rooms | C6: Gas Boiler | D6: Air-cooled Chiller | E6: FPFC (multi speed fan) | F6: DOAS | G6: Engineering judgement with considering CEUS data
A11: Efficiency of HVAC System (Efficiency is capacity-dependent. The following table provides a general estimate of system efficiency based on preliminary simulations in one climate zone, or assuming cooling load based on rule of thumb)
A12: Vintage | B12: Upgrade/Installed year | C12: Gas Boiler | D12: Air Cooled Chiller | E12: Source | G12: Note
A13: Pre 1978 | B13: 2008 | C13: Thermal Efficiency of 80% Et | D13: EER=9.56 (COP=2.8) | E13: T24, 2008 Table 112-D (for chiller COP of 2.8 , then converted to EER of 9.56) - T24, 2013 Table 110.2-K (for boiler efficiency with capacity between 300,000-2,500,000 Btu/hr). T24 2008 doesn't has requirement for Et
A14: 1978-1997
A15: 1998-2007
A16: 2008-2018 | B16: 2013 | C16: Thermal Efficiency of 80% Et | D16: EER=9.56 | E16: T24, 2013 Table 110.2-D ( for air cooled chiller) T24, 2013 Table 110.2-K (for boiler efficiency with capacity between 300,000-2,500,000 Btu/hr)
A17: New Construction | B17: 2025 | C17: CZ: 7, 8, 15: Thermal Efficiency of 80% Et ; All other CZ: Thermal Efficiency of 90% Et and return water temp of 120F | D17: EER=9.7 | E17: T24, 2025 Table 110.2-D (path B) (for chiller) ACM, 2025, section (5.8.1) for number of boiler (2 boilers), and section (5.8.1) and 10CFR § 431.87 (for boiler efficiency in CZ 7, 8, 15) and Title 24, 2025 section 140.4(k)8 (for boiler efficiency in other CZs). The boiler capacity is assumed to be over 1 MMBtu based on engineering judgment, considering that the PNNL prototype in San Diego (CZ7, a mild climate) lists a boiler capacity of 0.85 MMBtu. Therefore, it is reasonable to expect a larger capacity—above 1 MMBtu—for CZ12, which has colder winters. | G17: According to T24, 2025 140.4(k)8 and ACM 2025, "Gas-fired boilers in climate zones 1 through 6, 9 through 14 and 16 with rated capacity above 1 MMBtu/h and less than 10 MMBtu/h have a standard design efficiency of 90 percent" For other climate zones, the efficiency of gas fired boiler is 80% following Federal regulation 10CFR § 431.87 *Note: efficiency of gas fired boiler was 84% in T24, 2022, Table 110.2-J for capacity between 300,000-2,500,000 Btu/hr for all CZs. The efficiency will be adjusted based on the results of a sizing simulation run, that shows us what the peak heating capacity requirements are. | O17: COP (2013)= | P17: =9.56/3.412 -> 2.8018757
O18: COP (2025)= | P18: =9.7/3.412 -> 2.8429074
P19: =10/3.412 -> 2.9308324
A22: Fan power
A23: Vintage | B23: Approach | C23: System | D23: Total Static Pressure (TSP) (in w.c.) | E23: Fan Efficiency [ACM 2025] | F23: Motor Efficiency | G23: Fan Power Index (W/cfm) | H23: Data Source | I23: Note
A24: Existing | B24: PNNL 90.1-2011, TSP | C24: VAV System > 4,648 cfm | D24: 5.58 | E24: 0.65 | F24: ASHRAE 90.1, 2004, Table 10.8 * | H24: Fan power formula: PNNL 20405, 2010, section 5.2.2.5 TSP and fan efficiency: PNNL 20405, 2010, Table 5.11, 90.1-04ac values Motor efficiency: ASHRAE 90.1, 2004, Table 10.8
C25: FPFC (on/off) | D25: 1.33 | E25: 0.65
A26: Brake horsepower (bhp) = (Supply cfm × TSP in w.c.) / (6356 × fan efficiency)
A27: Fan power (w/cfm) = (bhp × 746) / ( supply cfm × motor efficiency )
A28: New Construction | B28: ACM 2025 | C28: VAV (System 6), >10,000 cfm | D28: TSP = fan power × motor efficiency × fan efficiency × 6356 / 746 | E28: 0.65 | F28: 2025 ACM Table 12 ** | G28: 0.947 | H28: Fan power index: [ACM 2025, Table 13] Motor efficiency: [ACM 2025, Table 12] | I28: According to ACM, fan power for this cfm is 0.947 W/cfm (VAV >10,000 cfm). FPFC 0.35 and DOAS 0.70 rows are unchanged.
B29: ACM 2025 | C29: FPFC (on/off) | D29: TSP (E+ input) in w.c. = fan power in W/cfm × motor efficiency × fan efficiency × 6356 / 746 | F29: The full‑load efficiency of the motor serving the fan is taken from ACM 2025 Table 12 based on the cfm of the fan. Motor horsepower in hp = (Supply cfm from sizing run × fan power in W/cfm) / 746. | G29: 0.35 | H29: w/cfm: [T24, 2025, Section 140.4(a)3 D] | I29: 0.35 w/cfm for indoor unit fan
C30: DOAS Supply fan | G30: 0.7 | H30: w/cfm: [T24, 2025, Section 140.4(c) and Table 140.4-A] | I30: cfm of DOAS system is already calculated in the Ventilation sheet. Total cfm is more than 10,000 when 10% oversizing factor is applied - Supply 0.7 w/cfm= 0.325 (base allowance, >6 floors)+0.107 (MERV filter upstream of cooling coil) + 0.054 (central hydronic heating coil) + 0.107 (cooling coil) + 0.107 (100% OA allowance) DOAS OA ventilation rate is lower than guestroom's Exhaust fan rate. Therefore only one exhaust fan object will be model to each guestroom and DOAS exhaust fan will be excluded | J30: Total cfm of DOAS | K30: =1.1*Ventilation!J31 -> 14465
A32: * According to PNNL 20405 section 5.2.2.5, the full-load efficiency of the motor serving the fan is taken from ASHRAE 90.1, 2004, Table 10.8, based on motor nameplate and assuming enclosed motors operating at 1,800 rotations per minute (rpm) Motor nameplate size (bhp) = brake horsepower (bhp) × 1.1 ( using a 10% oversizing factor)
A33: ** The full‑load efficiency of the motor serving the fan is taken from ACM 2025 Table 12 based on the cfm of the fan. Brake horsepower (bhp) = (Supply cfm from sizing run × fan power in W/cfm) / 746.

Sheet Thermostat
A1: ="Thermostat Setpoints - "&Prototype!A2 -> Thermostat Setpoints - HotelLarge
A2: Setpoint | B2: CZ1 | C2: CZ2 | D2: CZ3 | E2: CZ4 | F2: CZ5 | G2: CZ6 | H2: CZ7 | I2: CZ8 | J2: CZ9 | K2: CZ10 | L2: CZ11 | M2: CZ12 | N2: CZ13 | O2: CZ14 | P2: CZ15 | Q2: CZ16 | R2: Source
A3: Assembly, Office, Basement, Retail, Dining and Café Heating Setpoint (F) | B3: 70 | C3: 70 | D3: 70 | E3: 70 | F3: 70 | G3: 70 | H3: 70 | I3: 70 | J3: 70 | K3: 70 | L3: 70 | M3: 70 | N3: 70 | O3: 70 | P3: 70 | Q3: 70 | R3: T24 2022 - Appendix 5.4B - “Assembly” tab , "Retail" tab, "Restaurant" Tab * Basement was considered similar to Office area
A4: Assembly, Office, Basement, Retail, Dining and Café Heating Setback (F) | B4: 60 | C4: 60 | D4: 60 | E4: 60 | F4: 60 | G4: 60 | H4: 60 | I4: 60 | J4: 60 | K4: 60 | L4: 60 | M4: 60 | N4: 60 | O4: 60 | P4: 60 | Q4: 60
A5: Assembly, Office, Basement, Retail, Dining and Café Cooling Setpoint (F) | B5: 75 | C5: 75 | D5: 75 | E5: 75 | F5: 75 | G5: 75 | H5: 75 | I5: 75 | J5: 75 | K5: 75 | L5: 75 | M5: 75 | N5: 75 | O5: 75 | P5: 75 | Q5: 75
A6: Assembly, Office, Basement, Retail, Dining and Café Cooling Setback (F) | B6: 85 | C6: 85 | D6: 85 | E6: 85 | F6: 85 | G6: 85 | H6: 85 | I6: 85 | J6: 85 | K6: 85 | L6: 85 | M6: 85 | N6: 85 | O6: 85 | P6: 85 | Q6: 85
A7: ResidentialCommon Heating Setpoint (F) | B7: 68 | C7: 68 | D7: 68 | E7: 68 | F7: 68 | G7: 68 | H7: 68 | I7: 68 | J7: 68 | K7: 68 | L7: 68 | M7: 68 | N7: 68 | O7: 68 | P7: 68 | Q7: 68 | R7: T24 2022 - Appendix 5.4B - “ResidentialCommon” tab
A8: ResidentialCommon Heating Setback (F) | B8: 68 | C8: 68 | D8: 68 | E8: 68 | F8: 68 | G8: 68 | H8: 68 | I8: 68 | J8: 68 | K8: 68 | L8: 68 | M8: 68 | N8: 68 | O8: 68 | P8: 68 | Q8: 68
A9: ResidentialCommon Cooling Setpoint (F) | B9: 78 | C9: 78 | D9: 78 | E9: 78 | F9: 78 | G9: 78 | H9: 68 | I9: 78 | J9: 78 | K9: 78 | L9: 78 | M9: 78 | N9: 78 | O9: 78 | P9: 78 | Q9: 78
A10: ResidentialCommon Cooling Setback (F) | B10: 78 | C10: 78 | D10: 78 | E10: 78 | F10: 78 | G10: 78 | H10: 78 | I10: 78 | J10: 78 | K10: 78 | L10: 78 | M10: 78 | N10: 78 | O10: 78 | P10: 78 | Q10: 78
A11: ResidentialLiving Heating Setpoint (F)* | B11: 70 | C11: 70 | D11: 70 | E11: 70 | F11: 70 | G11: 70 | H11: 70 | I11: 70 | J11: 70 | K11: 70 | L11: 70 | M11: 70 | N11: 70 | O11: 70 | P11: 70 | Q11: 70
A12: ResidentialLiving Heating Setback (F)* | B12: 70 | C12: 70 | D12: 70 | E12: 70 | F12: 70 | G12: 70 | H12: 70 | I12: 70 | J12: 70 | K12: 70 | L12: 70 | M12: 70 | N12: 70 | O12: 70 | P12: 70 | Q12: 70
A13: ResidentialLiving Cooling Setpoint (F)* | B13: 72 | C13: 72 | D13: 72 | E13: 72 | F13: 72 | G13: 72 | H13: 72 | I13: 72 | J13: 72 | K13: 72 | L13: 72 | M13: 72 | N13: 72 | O13: 72 | P13: 72 | Q13: 72 | R13: Honeywell-INNCOM e7 Thermostat User Guide
A14: ResidentialLiving Cooling Setback (F)* | B14: 72 | C14: 72 | D14: 72 | E14: 72 | F14: 72 | G14: 72 | H14: 72 | I14: 72 | J14: 72 | K14: 72 | L14: 72 | M14: 72 | N14: 72 | O14: 72 | P14: 72 | Q14: 72 | R14: & Engineering Judgment
A15: Kitchen Heating Setpoint (F) | B15: 66 | C15: 66 | D15: 66 | E15: 66 | F15: 66 | G15: 66 | H15: 66 | I15: 66 | J15: 66 | K15: 66 | L15: 66 | M15: 66 | N15: 66 | O15: 66 | P15: 66 | Q15: 66 | R15: PNNL 09.1, 2022 Restaurant prototype (Same as Kitchen area in Restaurant scorecards)
A16: Kitchen Heating Setback (F) | B16: 60 | C16: 60 | D16: 60 | E16: 60 | F16: 60 | G16: 60 | H16: 60 | I16: 60 | J16: 60 | K16: 60 | L16: 60 | M16: 60 | N16: 60 | O16: 60 | P16: 60 | Q16: 60
A17: Kitchen Cooling Setpoint (F) | B17: 79 | C17: 79 | D17: 79 | E17: 79 | F17: 79 | G17: 79 | H17: 79 | I17: 79 | J17: 79 | K17: 79 | L17: 79 | M17: 79 | N17: 79 | O17: 79 | P17: 79 | Q17: 79
A18: Kitchen Cooling Setback (F) | B18: 86 | C18: 86 | D18: 86 | E18: 86 | F18: 86 | G18: 86 | H18: 86 | I18: 86 | J18: 86 | K18: 86 | L18: 86 | M18: 86 | N18: 86 | O18: 86 | P18: 86 | Q18: 86
A19: Mechanical Room Heating Setpoint (F) | B19: 60 | C19: 60 | D19: 60 | E19: 60 | F19: 60 | G19: 60 | H19: 60 | I19: 60 | J19: 60 | K19: 60 | L19: 60 | M19: 60 | N19: 60 | O19: 60 | P19: 60 | Q19: 60 | R19: Based on engineering judgment (semi‑conditioned space)
A20: Mechanical Room Heating Setback (F) | B20: 60 | C20: 60 | D20: 60 | E20: 60 | F20: 60 | G20: 60 | H20: 60 | I20: 60 | J20: 60 | K20: 60 | L20: 60 | M20: 60 | N20: 60 | O20: 60 | P20: 60 | Q20: 60
A21: Mechanical Room Cooling Setpoint (F) | B21: 85 | C21: 85 | D21: 85 | E21: 85 | F21: 85 | G21: 85 | H21: 85 | I21: 85 | J21: 85 | K21: 85 | L21: 85 | M21: 85 | N21: 85 | O21: 85 | P21: 85 | Q21: 85
A22: Mechanical Room Cooling Setback (F) | B22: 85 | C22: 85 | D22: 85 | E22: 85 | F22: 85 | G22: 85 | H22: 85 | I22: 85 | J22: 85 | K22: 85 | L22: 85 | M22: 85 | N22: 85 | O22: 85 | P22: 85 | Q22: 85
A24: * 72°F is the default setting for one of the most prominent thermostat (INNCOM) in California hotels. We have chosen to set the heating setpoint close to this value, allowing only a 2°F variance, with no setback applied. Our understanding is that guests rarely change the setpoint when leaving their rooms, as they expect the room to remain conditioned upon their return.
A25: * Another option for the guest rooms would be: set heating and cooling setpoint at 72 F, with +-4F variation for C/H setback. ( based on INNCOM)
A26: ICCCOM has 4F setback temperature variance.
A27: PNNL's comfort range in kitchen is 4 F wider than CEC. CEC uses 70-75 F with setbacks of 60 F and 86 F but PNNL uses 66 -79 F (with setback of 60 F and 86 F)
A29: Existing prototypes:
A30: DEER has 60F for 0-6 am! It's the time that guest room is supposed to be occupied.
A31: PNNL has 70F for both cooling and heating setpoint with +-4 setback.
A43: Background Data [To be deleted prior to publication]
C45: DEER | I45: PNNL
A46: Why DEER had 85 for cooling from 0-5? | C46: Heating: 60 F Cooling: 85 C | E46: Heating: 70 F Cooling: 75 F Setback: +-10 | I46: Heating: 70 F Cooling: 70 F Setback:+-4 | L46: Heating: 60 F Cooling: 80 F | N46: Heating: 70 F Cooling: 75 F
C47: All guest room | E47: Corridors | G47: Lobby, Office, Laundry, Dining, barcasino | I47: Occupied guest room | L47: Vacant guest room | N47: Other space
A48: Heating setpoint | B48: Weekday | C48: 0 -6 ----> 60 6-22 --->68 22-24-->60 | E48: 0 -5 ------> 60 5-24 ----->70 | G48: 0-7----->60 7-23--->70 23-24--->60 | I48: 0:00-7:50 ------> 70 7:50-9:00------->66 9:00-10:50 ----->70 10:50-16:10---->66 16:10-17:50 --->70 17:50-19:00---->66 19:00-24:00---->70 | L48: 0-24 ----> 60 | N48: 0-24 ----> 70
B49: Saturday | E49: 0 -5 ------> 60 5-19------>70 19-24 --->60
B50: Sunday | E50: 60
A51: Cooling Setpoint | B51: Weekday | C51: 78 | E51: 0 -5 -----> 85 5-24 ---->75 | G51: 0-7----->85 7-23--->75 23-24--->85 | I51: 0:00-7:50 ------> 70 7:50-9:00------->74 9:00-10:50 ----->70 10:50-16:10---->74 16:10-17:50 --->70 17:50-19:00---->74 19:00-24:00---->70 | L51: 0-24 ----> 80 | N51: 0-24 ----> 75
B52: Saturday | E52: 0 -5 -----> 85 5-19----->75 19-24 --->85
B53: Sunday | E53: 85
A57: T24, Appendix JA5-4 : Occupant Controlled Smart Thermostat (OCST) | F57: Honeywell-INNCOM e7 Thermostat User Guide
...

Sheet Ventilation
A1: ="Outdoor Airflow Rate - "&Prototype!A2 -> Outdoor Airflow Rate - HotelLarge
A2: Space/Thermal Zone | B2: Number of People | C2: Floor Area (ft²) | D2: cfm/person (T24, 2025, Equation 120.1-F and Table 120.1-A) (ASHRAE 62.1, 2022, Table 6-1) only for guest rooms | E2: cfm/ft² (T24, 2025, Equation 120.1-F and Table 120.1-A) (ASHRAE 62.1, 2022, Table 6-1) only for guest rooms | F2: Required Exhaust Rate (T24, 2025, Table 120.1-B – Minimum Exhaust Rates) | G2: Total cfm Driven by People | H2: Total cfm Driven by Area | I2: Total cfm Driven by Exhaust | J2: Total cfm | K2: Note
A3: =Zones!B3 -> BasementConference | B3: =Zones!K3 -> 246.01293 | C3: =Zones!H3 -> 7454.9371 | D3: 15 | E3: 0.15 | F3: 2*50/70 per unit | G3: =B3*D3 -> 3690.1939 | H3: =C3*E3 -> 1118.2406 | I3: =2*70 -> 140 | J3: =MAX(G3,H3,I3) -> 3690.1939
A4: =Zones!B4 -> BasementOffice | B4: =Zones!K4 -> 8.2604979 | C4: =Zones!H4 -> 1652.0996 | D4: 15 | E4: 0.15 | G4: =B4*D4 -> 123.90747 | H4: =C4*E4 -> 247.81494 | J4: =MAX(G4,H4,I4) -> 247.81494
A5: =Zones!B5 -> BasementMechanical | B5: =Zones!K5 -> 0 | C5: =Zones!H5 -> 1767.854 | D5: 15 | E5: 0.15 | G5: =B5*D5 -> 0 | H5: =C5*E5 -> 265.1781 | J5: =MAX(G5,H5,I5) -> 265.1781
A6: =Zones!B6 -> BasementLaundry | B6: =Zones!K6 -> 4.2000525 | C6: =Zones!H6 -> 840.0105 | D6: 15 | E6: 0.15 | F6: 1 cfm/ft² for Soiled laundry storage rooms | G6: =B6*D6 -> 63.000788 | H6: =C6*E6 -> 126.00158 | I6: =1*0.2*C6 -> 168.0021 | J6: =MAX(G6,H6,I6) -> 168.0021 | K6: Only 20% of the laundry space is assumed as "Solied laundry storage room"
A7: =Zones!B7 -> BasementService | B7: =Zones!K7 -> 19.169838 | C7: =Zones!H7 -> 6389.9461 | D7: 15 | E7: 0.15 | F7: 0.7 cfm/sf | G7: =B7*D7 -> 287.54757 | H7: =C7*E7 -> 958.49192 | I7: =0.7*C7 -> 4472.9623 | J7: =MAX(G7,H7,I7) -> 4472.9623 | K7: Same as kitchen
A8: =Zones!B8 -> BasementStorage | B8: =Zones!K8 -> 0 | C8: =Zones!H8 -> 3194.9731 | D8: 15 | E8: 0.15 | G8: =B8*D8 -> 0 | H8: =C8*E8 -> 479.24596 | J8: =MAX(G8,H8,I8) -> 479.24596
A9: =Zones!B9 -> Retail_1_FloorG | B9: =Zones!K9 -> 12.272829 | C9: =Zones!H9 -> 721.93112 | D9: 15 | E9: 0.2 | G9: =B9*D9 -> 184.09243 | H9: =C9*E9 -> 144.38622 | J9: =MAX(G9,H9,I9) -> 184.09243
A10: =Zones!B10 -> Retail_2_FloorG | B10: =Zones!K10 -> 14.212474 | C10: =Zones!H10 -> 836.02788 | D10: 15 | E10: 0.2 | G10: =B10*D10 -> 213.18711 | H10: =C10*E10 -> 167.20558 | J10: =MAX(G10,H10,I10) -> 213.18711
A11: =Zones!B11 -> Office_FloorG | B11: =Zones!K11 -> 8.8392699 | C11: =Zones!H11 -> 1767.854 | D11: 15 | E11: 0.15 | G11: =B11*D11 -> 132.58905 | H11: =C11*E11 -> 265.1781 | J11: =MAX(G11,H11,I11) -> 265.1781
A12: =Zones!B12 -> Storage_FloorG | B12: =Zones!K12 -> 0 | C12: =Zones!H12 -> 1019.982 | D12: 15 | E12: 0.15 | G12: =B12*D12 -> 0 | H12: =C12*E12 -> 152.9973 | J12: =MAX(G12,H12,I12) -> 152.9973
A13: =Zones!B13 -> Kitchen_FloorG | B13: =Zones!K13 -> 2.5200315 | C13: =Zones!H13 -> 840.0105 | D13: 15 | E13: 0.15 | F13: 0.7 cfm/ft² for kitchen commercial | G13: =B13*D13 -> 37.800473 | H13: =C13*E13 -> 126.00158 | I13: =0.7*C13 -> 588.00735 | J13: =MAX(G13,H13,I13) -> 588.00735 | K13: 588 cm< hood exhaust cfm . It will be covered under hood cfm
A14: =Zones!B14 -> Cafe_FloorG | B14: =Zones!K14 -> 67.084375 | C14: =Zones!H14 -> 2032.8599 | D14: 15 | E14: 0.15 | G14: =B14*D14 -> 1006.2656 | H14: =C14*E14 -> 304.92898 | J14: =MAX(G14,H14,I14) -> 1006.2656
A15: =Zones!B15 -> Lobby_FloorG | B15: =Zones!K15 -> 140.81155 | C15: =Zones!H15 -> 14081.155 | D15: 15 | E15: 0.15 | G15: =B15*D15 -> 2112.1733 | H15: =C15*E15 -> 2112.1733 | J15: =MAX(G15,H15,I15) -> 2112.1733
A16: =Zones!B16 -> GuestRoom_1_FloorM | B16: =Zones!K16 -> 1.2600158 | C16: =Zones!H16 -> 420.00525 | D16: =5*10/3 -> 16.666667 | E16: 0.06 | F16: 20/50 cfm per unit | G16: =B16*D16 -> 21.000263 | H16: =C16*E16 -> 25.200315 | I16: 50 | J16: =MAX(G16+H16,I16) -> 50 | K16: Ventilation for guest rooms is calculated using the ASHRAE 62.1, as T24's occupancy-only baseline does not capture realistic ventilation design. The total outdoor airflow is calculated as: Ventilation = (Occupancy per 1,000 ft² × cfm/person) + (Floor area in ft² × cfm/ft²) To maintain simulation consistency across tabs and of ease of automation, we retained the T24 occupant rate of 3 occupants per 1,000 sq ft rather than adopting ASHRAE's higher rate of 10 occupants per 1,000 sq ft. To compensate for this, we scaled ASHRAE’s per-person airflow requirement (5 cfm/person) by a factor of 10/3. Although the occupant-based portion of the ventilation load remains almost equivalent across both codes, incorporating ASHRAE’s area-based ventilation component represents the key difference in overall outdoor air rates.
A17: =Zones!B17 -> GuestRoom_2_FloorM | B17: =Zones!K17 -> 1.2600158 | C17: =Zones!H17 -> 420.00525 | D17: =5*10/3 -> 16.666667 | E17: 0.06 | F17: 20/50 cfm per unit | G17: =B17*D17 -> 21.000263 | H17: =C17*E17 -> 25.200315 | I17: 50 | J17: =MAX(G17,H17,I17) -> 50
A18: =Zones!B18 -> GuestRoom_3_Multi19_FloorM | B18: =Zones!K18 -> 0.79178847 | C18: =Zones!H18 -> 263.92949 | D18: =5*10/3 -> 16.666667 | E18: 0.06 | F18: 20/50 cfm per unit | G18: =B18*D18 -> 13.196475 | H18: =C18*E18 -> 15.835769 | I18: 50 | J18: =MAX(G18,H18,I18) -> 50
A19: =Zones!B19 -> GuestRoom_4_Multi19_FloorM | B19: =Zones!K19 -> 0.79211139 | C19: =Zones!H19 -> 264.03713 | D19: =5*10/3 -> 16.666667 | E19: 0.06 | F19: 20/50 cfm per unit | G19: =B19*D19 -> 13.201856 | H19: =C19*E19 -> 15.842228 | I19: 50 | J19: =MAX(G19,H19,I19) -> 50
A20: =Zones!B20 -> GuestRoom_5_FloorM | B20: =Zones!K20 -> 1.2600158 | C20: =Zones!H20 -> 420.00525 | D20: =5*10/3 -> 16.666667 | E20: 0.06 | F20: 20/50 cfm per unit | G20: =B20*D20 -> 21.000263 | H20: =C20*E20 -> 25.200315 | I20: 50 | J20: =MAX(G20,H20,I20) -> 50
A21: =Zones!B21 -> GuestRoom_6_FloorM | B21: =Zones!K21 -> 1.2600158 | C21: =Zones!H21 -> 420.00525 | D21: =5*10/3 -> 16.666667 | E21: 0.06 | F21: 20/50 cfm per unit | G21: =B21*D21 -> 21.000263 | H21: =C21*E21 -> 25.200315 | I21: 50 | J21: =MAX(G21,H21,I21) -> 50
A22: =Zones!B22 -> Corridor_FloorM | B22: =Zones!K22 -> 20.957207 | C22: =Zones!H22 -> 4191.4414 | D22: 15 | E22: 0.15 | G22: =B22*D22 -> 314.35811 | H22: =C22*E22 -> 628.71622 | J22: =MAX(G22,H22,I22) -> 628.71622
A23: =Zones!B23 -> GuestRoom_1_FloorT | B23: =Zones!K23 -> 1.2600158 | C23: =Zones!H23 -> 420.00525 | D23: =5*10/3 -> 16.666667 | E23: 0.06 | F23: 20/50 cfm per unit | G23: =B23*D23 -> 21.000263 | H23: =C23*E23 -> 25.200315 | I23: 50 | J23: =MAX(G23,H23,I23) -> 50 | K23: Same explanation as other guestrooms (see the note above).
A24: =Zones!B24 -> GuestRoom_2_FloorT | B24: =Zones!K24 -> 1.2600158 | C24: =Zones!H24 -> 420.00525 | D24: =5*10/3 -> 16.666667 | E24: 0.06 | F24: 20/50 cfm per unit | G24: =B24*D24 -> 21.000263 | H24: =C24*E24 -> 25.200315 | I24: 50 | J24: =MAX(G24,H24,I24) -> 50
A25: =Zones!B25 -> GuestRoom_3_Multi9_FloorT | B25: =Zones!K25 -> 0.79211139 | C25: =Zones!H25 -> 264.03713 | D25: =5*10/3 -> 16.666667 | E25: 0.06 | F25: 20/50 cfm per unit | G25: =B25*D25 -> 13.201856 | H25: =C25*E25 -> 15.842228 | I25: 50 | J25: =MAX(G25,H25,I25) -> 50
A26: =Zones!B26 -> Banquet_FloorT | B26: =Zones!K26 -> 117.80792 | C26: =Zones!H26 -> 3569.937 | D26: 15 | E26: 0.15 | G26: =B26*D26 -> 1767.1188 | H26: =C26*E26 -> 535.49055 | J26: =MAX(G26,H26,I26) -> 1767.1188
A27: =Zones!B27 -> Dining_FloorT | B27: =Zones!K27 -> 117.80792 | C27: =Zones!H27 -> 3569.937 | D27: 15 | E27: 0.15 | G27: =B27*D27 -> 1767.1188 | H27: =C27*E27 -> 535.49055 | J27: =MAX(G27,H27,I27) -> 1767.1188
A28: =Zones!B28 -> Kitchen_FloorT | B28: =Zones!K28 -> 3.3357157 | C28: =Zones!H28 -> 1111.9052 | D28: 15 | E28: 0.15 | F28: 0.7 cfm/ft² for kitchen commercial | G28: =B28*D28 -> 50.035736 | H28: =C28*E28 -> 166.78579 | I28: =0.7*C28 -> 778.33367 | J28: =MAX(G28,H28,I28) -> 778.33367 | K28: 778 cm< hood exhaust cfm . It will be covered under hood cfm
A29: =Zones!B29 -> Corridor_FloorT | B29: =Zones!K29 -> 22.17998 | C29: =Zones!H29 -> 4435.996 | D29: 15 | E29: 0.15 | G29: =B29*D29 -> 332.6997 | H29: =C29*E29 -> 665.3994 | J29: =MAX(G29,H29,I29) -> 665.3994
I31: Total OA of guest rooms (cfm) | J31: =SUMPRODUCT(J16:J21,Zones!J16:J21)+SUMPRODUCT(J23:J25,Zones!J23:J25) -> 13150
A34: Type of Hood | C34: Max Exhaust Flow Rate (cfm/ft) [T24, 2025, Table 140.9-C] | D34: Hood Length (ft) * | E34: Hood Exhaust Rate (cfm) | F34: Note
A35: Kitchen FloorT: Type I , wall-mounted canopy, medium duty hood | C35: 210 | D35: 16 | E35: =C35*D35 -> 3360 | F35: Over fryers, griddles, broilers, or any equipment that produces grease and vapor
A36: Kitchen FloorG: Type I , wall-mounted canopy, medium duty hood | C36: 210 | D36: 11 | E36: =C36*D36 -> 2310 | F36: Over fryers, griddles, broilers, or any equipment that produces grease and vapor
A37: * Assuming a 6 ft long griddle space right next to a 4 ft long fryer space and a 2 ft Charbroiler and 2 ft range , that would be 6 + 4 + 2 + 2 + (0.5 ft x 2) or 15 ft long hood required, where the 0.5 ft is the 6 inches extending on either side of the cooking equipment. 1 extra ft has also been added as a buffer.
A38: ** Assuming a 4 ft griddle, 2 ft of warming/holding equipment, and 3 ft small fryer or oven . With 6‑inch hood overhangs on each end, the total hood length needed is approximately 10 ft. 1 extra ft has also been added as a buffer.
A40: Exhaust hood
A41: Efficiency of exhaust fan is 50% (according to ACM, 2025,section 5.7.3)
B42: A full‑service hotel kitchen serving a 7,000‑ft² restaurant and banquet space typically includes a multi‑appliance cookline: a griddle (3–6 ft), fryers (2–4 ft), Charbroiler (2–3 ft), range (2–3 ft), and a convection oven or holding equipment (2–3 ft). Placed side‑by‑side, these appliances require approximately 14–18 ft of linear hood coverage, including the mandatory 6‑inch overhang on each side. Therefore, a 16‑ft Type I hood represents a realistic and industry‑standard length for a restaurant/banquet cookline in a 1,100‑ft² hotel kitchen.
A44: Background Data [To be deleted prior to publication]
A47: T24, 2025, Table 140.9-C
...

Sheet Water Heater
A1: ="Water Heater - "&Prototype!A2 -> Water Heater - HotelLarge
A2: Vintage | B2: WH Type | C2: Efficiency | D2: Number of WH | E2: Tank Volume (gal) | F2: Tank Loss | G2: Source
A3: Existing | B3: Gas | C3: 0.8 | D3: =B40 -> 5 | E3: See table below for CZ-specific values: Climate Zone Water Heater Sizing and Loss Coefficients, Storage Volume column (col G) | F3: See table below: Climate Zone Water Heater Sizing and Loss Coefficients, Standby Loss column (col H) | G3: See table below for sources: Climate Zone Water Heater Sizing and Loss Coefficients
A4: New Construction | B4: Gas | C4: 0.8 | D4: 5 | E4: See table below for CZ-specific values: Climate Zone Water Heater Sizing and Loss Coefficients, Storage Volume column (col G) | F4: See table below: Climate Zone Water Heater Sizing and Loss Coefficients, Standby Loss column (col H) | G4: See table below for sources: Climate Zone Water Heater Sizing and Loss Coefficients
A8: Peak Hot Water Consumption
A9: Space Name | B9: Baseline WH Type [T24, 2022, Appendix 5.4A , sheet: "2022 SpaceFuncData-Input"] | C9: Total Area (ft²) | D9: Number of People | E9: Hot Water Usage Specification (gal/hr per person) [T24, 2022, Appendix 5.4A , sheet: "2022 SpaceFuncData-Input"] | F9: Peak Hot Water Usage (gal/hr) | G9: Peak Hot Water Usage (gal/min) | H9: Note
A10: =Zones!B3 -> BasementConference | B10: Gas | C10: =Zones!H3*Zones!J3 -> 7454.9371 | D10: =Zones!K3*Zones!J3 -> 246.01293 | E10: =Data!L84 -> 0.2724 | F10: =D10*E10 -> 67.013921 | G10: =F10/60 -> 1.1168987 | H10: For space types marked with an asterisk (the ‘*’ symbol), the water‑heater type is listed as electric in Appendix 5.4A, sheet ‘2022 SpaceFuncData‑Input.’ However, we modified the value based on CEUS data, which indicates that gas is the primary fuel type.
