Workbook
Name nonparticipating_forecastzone_scale_factor: #REF!
Name nonparticipating_forecastzone_scale_factor: 'Energy Usage'!#REF!
Name Space_Function: Data!$A$2:$A$76

Sheet Notes
A1: Data Sources
A2: Dataset | B2: Dodge 2023
B3: Commercial End-Use Survey (CEUS) 2022 | C3: https://www.energy.ca.gov/publications/2023/2022-california-commercial-end-use-survey-ceus-final-report
B4: Commercial Buildings Energy Consumption Survey (CBECS) 2018 | C4: https://www.eia.gov/consumption/commercial/data/2018/index.php?view=microdata
B5: Comstock 2023 | C5: https://data.openei.org/s3_viewer?bucket=oedi-data-lake&prefix=nrel-pds-building-stock%2Fend-use-load-profiles-for-us-building-stock%2F2023%2Fcomstock_amy2018_release_2%2Fmetadata_and_annual_results%2Fby_state%2Fstate%3DCA%2F
A6: Prototype | B6: Pacific Northwest National Laboratory (PNNL) Large Hotel prototype (ASHRAE 90.1-2022) | C6: https://www.energycodes.gov/prototype-building-models#Commercial
B7: Database for Energy Efficient Resources (DEER) Hotel prototype (June 2024) | C7: https://github.com/sound-data/DEER-Prototypes-EnergyPlus
B8: California Energy Commission (CEC) Small Hotel prototype (CBECC 2022.3.1) | C8: https://bees.noresco.com/software2022.html
A10: Codes | B10: Title 24, part 6, referred to as T24 (1984, 1992,1998, 2001, 2005, 2008, 2013, 2016,2019, 2022, 2025) | C10: https://www.energy.ca.gov/publications/2025/2025-building-energy-efficiency-standards-residential-and-nonresidential | D10: 2025
C11: https://codes.iccsafe.org/codes/united-states/california | D11: 2010+
B12: American Society of Heating, Refrigerating and Air-Conditioning Engineers (ASHRAE) 90.1 (2022) | C12: https://www.ashrae.org/technical-resources/standards-and-guidelines/read-only-versions-of-ashrae-standards
B13: Code of Federal Regulations (CFR) Title 10 (2009) | C13: https://www.govinfo.gov/content/pkg/FR-2009-03-23/pdf/FR-2009-03-23.pdf
B14: CFR Title 10 ( 2013) | C14: https://www.govinfo.gov/content/pkg/CFR-2013-title10-vol3/pdf/CFR-2013-title10-vol3-part431.pdf
B15: CFR Title 10 ( 2024) | C15: https://www.govinfo.gov/content/pkg/CFR-2024-title10-vol3/pdf/CFR-2024-title10-vol3-part431-subpartF.pdf
A17: Others | B17: Alternative Calculation Method (ACM) (2022) | C17: https://www.energy.ca.gov/publications/2022/2022-nonresidential-and-multifamily-alternative-calculation-method-reference
B18: ACM (2025) | C18: https://www.energy.ca.gov/publications/2025/2025-nonresidential-and-multifamily-alternative-calculation-method-reference
B19: Nonres ACM 2022, Appendix 5.4A and Appendix 5.4B | C19: https://www.energy.ca.gov/publications/2022/2022-nonresidential-and-multifamily-alternative-calculation-method-reference
B20: 2022 Reduced infiltration Codes and Standards Enhancement (CASE) report | C20: https://title24stakeholders.com/wp-content/uploads/2020/10/2022-T24-Final-CASE-Report_Reduce-Infiltration.pdf
B21: Honeywell, INNCOM e7 Thermostat User Guide, 2017 | C21: https://prod-edam.honeywell.com/content/dam/honeywell-edam/hbt/en-us/documents/manuals-and-guides/installation-guides/inncom/hbt-bms-INNCOM-e7-USER-GUIDE.pdf?download=false
B22: 2019 Outdoor Lighting CASE Report | C22: https://title24stakeholders.com/wp-content/uploads/2016/10/T24-2019-CASE-Study-Results-Report-Outdoor-Sources_Final_with-Attachments.pdf
B23: 2025 State of the Industry Report | C23: https://www.ahla.com/sites/default/files/25_SOTI.pdf
B24: PNNL 20405, 2011 | C24: https://www.pnnl.gov/main/publications/external/technical_reports/PNNL-20405.pdf
B25: Air leakage Memo, NORESCO, 2025 | C25: Infiltration_rate_report_14May2025-Short-Version.docx
B26: Yousefi, F., Athalye, R., (2025), "Determining Vintage Bins for Prototype Development: An Analysis of California Commercial Buildings," ASHRAE Annual Conference | C26: https://www.thefreelibrary.com/Determining+Vintage+Bins+for+Prototype+Development%3a+An+Analysis+of...-a0879271125
B27: Proposed Updates to Equipment Power Densities and Building Schedules for the 2028 Energy Code, referred to as "Plug load and schedules project with CEC, 2025" (Docket Number =25-BSTD-03 & TN=265693) | C27: https://efiling.energy.ca.gov/GetDocument.aspx?tn=265693&DocumentContentId=102545
B28: ENERGY STAR certified commercial water heaters | C28: https://www.energystar.gov/productfinder/product/certified-commercial-water-heaters/results?fuel_filter=Gas&markets_filter=United+States
B29: Grainger gas tank water heaters (sizes below commercial, e.g. 30–75 kBtu/h) | C29: https://www.grainger.com/category/plumbing/water-heaters/gas-tank-water-heaters
B30: Grainger electric tank water heaters | C30: https://www.grainger.com/category/plumbing/water-heaters/electric-tank-water-heaters
A35: Construction Rate
A48: Notes
A49: HotelSmall | B49: The HotelSmall prototype was developed to represent California small hotels with floor areas below 60,000 ft², regardless of the number of stories. According to Dodge (2023), the average small hotel in California is described as a 3‑story building with a total floor area of about 26,000 ft². In comparison, the CEC and PNNL small hotel prototype is characterized as a 4‑story building with a total floor area of 43,200 ft² and a 10,800‑ft² footprint. Because the CEC and PNNL prototype is considered well established and has defined zoning, it is selected as the basis for the model and modified by removing one floor. With this modification, the geometry aligns more closely with findings from the California building stock assessment.
A50: Dodge 2023
A63: "NUMPRO=1" refers to Dodge records with only one building per record, while "All extended" includes all the records.
A64: Source:Dodge Construction Data, 2023 ( NEW Hotels above 60,000 sf built after 1967) (STC refers to building types in Dodge terminology).
A66: EIA, 2018 CBECS | B66: Approximately 42% of lodging buildings were between 1,001 ft² and 10,000 ft². On average, lodging buildings were among the largest commercial building types (33,700 ft² per building). More than one-half (56%) of lodging buildings were on a campus or complex. The majority of lodging buildings were not tall—only 2% of lodging buildings had 10 or more floors. Buildings that had one or two floors accounted for 71% of all lodging buildings.

Sheet Prototype
A1: NORESCO, Updated September 2026
A2: HotelSmall
A3: Characteristic | B3: Value | C3: Data Sources
A4: Building Type | B4: Small Hotel
A5: Building Category | B5: Nonresidential
A6: Version | B6: v2-0
A7: Vintages | B7: 4 Vintages: Pre-1978 , 1978-1997 ,1998-2007 , 2008-2018 New Construction (2019+) | C7: Based on the vintage bin analysis. A summary of the findings is presented in the following paper, with a link provided in the Notes tab: Yousefi, F., Athalye, R. (2025). “Determining Vintage Bins for Prototype Development: An Analysis of California Commercial Buildings.” ASHRAE Annual Conference.
A8: Shape | C8: Same as CEC and PNNL, except CalBEM is three stories whereas CEC and PNNL have four stories. Number of stories, are supported by Dodge 2023 data
A9: Total Floor Area (ft²) | B9: 32,400 (180 ft x 60 ft) | C9: Footprint same as CEC and PNNL, but total floor area was adjusted based on Dodge 2023 data
A10: Aspect Ratio | B10: 3 | C10: Assumption: same as CEC and PNNL
A11: Number of Floors | B11: 3 | C11: Based on Dodge 2023 data (Average number of stories)
A12: Number of Guestrooms | B12: 53 (accounting for about 58% of the total floor area)
A13: Roof type | B13: Flat Wood-Framed Roof for Guest rooms of Hotel/Motel | C13: Based on typical small hotel structure
A14: WWR | B14: South: 15.2%, East: 3.1%, North: 11.4%, West: 4.0% Average Total: 10.9% Size of the guest room windows: 3.7 ft × 4.7 ft
A15: Shading Geometry | B15: No Shades
A16: Floor to floor height (ft) | B16: Ground floor: 11 ft Upper floors: 9 ft | C16: Typical small hotel's height, also same as CEC and PNNL
A17: Floor to ceiling height (ft) | B17: Same as above | C17: Typical small hotel's height, also same as CEC and PNNL
A18: Glazing sill height (ft) | B18: 3 ft in ground floor, 2 ft. in upper floors | C18: Assumption: same as CEC and PNNL

Sheet Zones
A1: Proposed Layout - HotelSmall | Q1: N
A2: Building | B2: Space/Thermal Zone | C2: Space Type Primarily from [T24, 2022 Appendix 5.4A] - See Notes column | D2: HVAC Zone | E2: Schedule Category | F2: Conditioned [Y/N] | G2: Area Fraction | H2: Area (ft²) | I2: Volume [ft³] | J2: Multipliers | K2: People | L2: People (Persons/1,000 ft²) [T24, 2025,Table 120.1-A] | M2: Notes
A3: HotelSmall | B3: Corridor_FloorG | C3: Corridor Area | D3: BaseAirSys5 | E3: ResidentialCommon | F3: Yes | G3: =H3/$H$51 -> 0.054998656 | H3: 1782.21 | I3: 19605.24 | J3: 1 | K3: =(H3/1000)*L3 -> 8.91105 | L3: 5
A4: HotelSmall | B4: Corridor_FloorM | C4: Corridor Area | D4: BaseAirSys5-2 | E4: ResidentialCommon | F4: Yes | G4: =H4/$H$51 -> 0.046664965 | H4: 1512.16 | I4: 13610.11 | J4: 1 | K4: =(H4/1000)*L4 -> 7.5608 | L4: 5
A5: HotelSmall | B5: Corridor_FloorT | C5: Corridor Area | D5: BaseAirSys5-3 | E5: ResidentialCommon | F5: Yes | G5: =H5/$H$51 -> 0.046664965 | H5: 1512.16 | I5: 13610.11 | J5: 1 | K5: =(H5/1000)*L5 -> 7.5608 | L5: 5
A6: HotelSmall | B6: Lounge_FloorG | C6: Lounge, Breakroom, or Waiting Area | D6: BaseAirSys5 | E6: ResidentialCommon | F6: Yes | G6: =H6/$G$51 -> 0 | H6: 351.03 | I6: 3861.57 | J6: 1 | K6: =(H6/1000)*L6 -> 11.58399 | L6: 33
A7: HotelSmall | B7: Gym_FloorG | C7: Exercise/Fitness Center and Gymnasium Areas | D7: BaseAirSys5 | E7: Assembly | F7: Yes | G7: =H7/$H$51 -> 0.010832718 | H7: 351.03 | I7: 3861.57 | J7: 1 | K7: =(H7/1000)*L7 -> 3.5103 | L7: 10
A8: HotelSmall | B8: Front_Lounge_FloorG | C8: Lounge, Breakroom, or Waiting Area | D8: BaseAirSys5 | E8: ResidentialCommon | F8: Yes | G8: =H8/$H$51 -> 0.054168219 | H8: 1755.3 | I8: 19309.26 | J8: 1 | K8: =(H8/1000)*L8 -> 26.3295 | L8: 15 | M8: NonRes ACM 2005, Appendix 5.4A assigns 2.5 occupants to kitchenette spaces, but because this room serves as a combined break/kitchenette area—and break rooms assume 33 occupants—we applied a midpoint value. The lounge overlaps functionally with the break area, so its occupant count (33) was reduced to 15 to keep overall loads balanced.
A9: HotelSmall | B9: Front_Office_FloorG | C9: Office Area (>250 square feet) | D9: BaseAirSys5 | E9: Office | F9: Yes | G9: =H9/$H$51 -> 0.043331489 | H9: 1404.14 | I9: 15446.26 | J9: 1 | K9: =(H9/1000)*L9 -> 7.0207 | L9: 5
A10: HotelSmall | B10: Front_Stair_FloorG | C10: Stairwell | D10: BaseAirSys5 | E10: AncillaryResidentialCommon | F10: Yes | G10: =H10/$H$51 -> 0.0066663354 | H10: 216.02 | I10: 2376.35 | J10: 1 | K10: =(H10/1000)*L10 -> 0 | L10: 0 | P10: Ground floor (FloorG)
A11: HotelSmall | B11: Front_Stair_FloorM | C11: Stairwell | D11: BaseAirSys5-2 | E11: AncillaryResidentialCommon | F11: Yes | G11: =H11/$H$51 -> 0.0066663354 | H11: 216.02 | I11: 1944.29 | J11: 1 | K11: =(H11/1000)*L11 -> 0 | L11: 0
A12: HotelSmall | B12: Front_Stair_FloorT | C12: Stairwell | D12: BaseAirSys5-3 | E12: AncillaryResidentialCommon | F12: Yes | G12: =H12/$H$51 -> 0.0066663354 | H12: 216.02 | I12: 1944.29 | J12: 1 | K12: =(H12/1000)*L12 -> 0 | L12: 0
A13: HotelSmall | B13: Front_Storage_FloorG | C13: Storage (General) | D13: BaseAirSys5 | E13: Assembly | F13: Yes | G13: =H13/$H$51 -> 0.0041663825 | H13: 135.01 | I13: 1485.22 | J13: 1 | K13: =(H13/1000)*L13 -> 0.27002 | L13: 2
A14: HotelSmall | B14: Front_Storage_FloorM | C14: Storage (General) | D14: BaseAirSys5-2 | E14: Assembly | F14: Yes | G14: =H14/$H$51 -> 0.0041663825 | H14: 135.01 | I14: 1215.18 | J14: 1 | K14: =(H14/1000)*L14 -> 0.27002 | L14: 2
A15: HotelSmall | B15: Front_Storage_FloorT | C15: Storage (General) | D15: BaseAirSys5-3 | E15: Assembly | F15: Yes | G15: =H15/$H$51 -> 0.0041663825 | H15: 135.01 | I15: 1215.18 | J15: 1 | K15: =(H15/1000)*L15 -> 0.27002 | L15: 2
A16: HotelSmall | B16: GuestRoom_1_FloorG | C16: Hotel/Motel Guest Room | D16: BaseZnSys1 | E16: ResidentialLiving | F16: Yes | G16: =H16/$H$51 -> 0.010833644 | H16: 351.06 | I16: 3861.85 | J16: 1 | K16: =(H16/1000)*L16 -> 1.05318 | L16: 3
A17: HotelSmall | B17: GuestRoom_2_FloorG | C17: Hotel/Motel Guest Room | D17: BaseZnSys1-2 | E17: ResidentialLiving | F17: Yes | G17: =H17/$H$51 -> 0.010833644 | H17: 351.06 | I17: 3861.85 | J17: 1 | K17: =(H17/1000)*L17 -> 1.05318 | L17: 3
A18: HotelSmall | B18: GuestRoom_3_FloorG | C18: Hotel/Motel Guest Room | D18: BaseZnSys1-3 | E18: ResidentialLiving | F18: Yes | G18: =H18/$H$51 -> 0.010833644 | H18: 351.06 | I18: 3861.85 | J18: 1 | K18: =(H18/1000)*L18 -> 1.05318 | L18: 3
A19: HotelSmall | B19: GuestRoom_4_FloorG | C19: Hotel/Motel Guest Room | D19: BaseZnSys1-4 | E19: ResidentialLiving | F19: Yes | G19: =H19/$H$51 -> 0.010832718 | H19: 351.03 | I19: 3861.57 | J19: 1 | K19: =(H19/1000)*L19 -> 1.05309 | L19: 3
A20: HotelSmall | B20: GuestRoom_5_FloorG | C20: Hotel/Motel Guest Room | D20: BaseZnSys1-5 | E20: ResidentialLiving | F20: Yes | G20: =H20/$H$51 -> 0.010832718 | H20: 351.03 | I20: 3861.57 | J20: 1 | K20: =(H20/1000)*L20 -> 1.05309 | L20: 3
A21: HotelSmall | B21: GuestRoom_1_FloorM | C21: Hotel/Motel Guest Room | D21: BaseZnSys1-6 | E21: ResidentialLiving | F21: Yes | G21: =H21/$H$51 -> 0.010833644 | H21: 351.06 | I21: 3159.7 | J21: 1 | K21: =(H21/1000)*L21 -> 1.05318 | L21: 3
A22: HotelSmall | B22: GuestRoom_2_5_FloorM | C22: Hotel/Motel Guest Room | D22: BaseZnSys1-7 | E22: ResidentialLiving | F22: Yes | G22: =H22/$H$51 -> 0.043334575 | H22: 1404.24 | I22: 12638.78 | J22: 1 | K22: =(H22/1000)*L22 -> 4.21272 | L22: 3
... A24: HotelSmall | B24: GuestRoom_9_12_FloorM | C24: Hotel/Motel Guest Room | D24: BaseZnSys1-9 | E24: ResidentialLiving | F24: Yes | G24: =H24/$H$51 -> 0.043334575 | H24: 1404.24 | I24: 12638.78 | J24: 1 | K24: =(H24/1000)*L24 -> 4.21272 | L24: 3
A25: HotelSmall | B25: GuestRoom_13_FloorM | C25: Hotel/Motel Guest Room | D25: BaseZnSys1-10 | E25: ResidentialLiving | F25: Yes | G25: =H25/$H$51 -> 0.010833644 | H25: 351.06 | I25: 3159.7 | J25: 1 | K25: =(H25/1000)*L25 -> 1.05318 | L25: 3 | P25: Middle floor and top floor (FloorM, FloorT)
A26: HotelSmall | B26: GuestRoom_14_FloorM | C26: Hotel/Motel Guest Room | D26: BaseZnSys1-11 | E26: ResidentialLiving | F26: Yes | G26: =H26/$H$51 -> 0.010832718 | H26: 351.03 | I26: 3159.46 | J26: 1 | K26: =(H26/1000)*L26 -> 1.05309 | L26: 3
A27: HotelSmall | B27: GuestRoom_15_18_FloorM | C27: Hotel/Motel Guest Room | D27: BaseZnSys1-12 | E27: ResidentialLiving | F27: Yes | G27: =H27/$H$51 -> 0.043331489 | H27: 1404.14 | I27: 12637.85 | J27: 1 | K27: =(H27/1000)*L27 -> 4.21242 | L27: 3
A28: HotelSmall | B28: GuestRoom_19_FloorM | C28: Hotel/Motel Guest Room | D28: BaseZnSys1-13 | E28: ResidentialLiving | F28: Yes | G28: =H28/$H$51 -> 0.010833027 | H28: 351.04 | I28: 3159.51 | J28: 1 | K28: =(H28/1000)*L28 -> 1.05312 | L28: 3 | O28: Space | P28: Floor area (ft2) | Q28: Fraction
A29: HotelSmall | B29: GuestRoom_20_23_FloorM | C29: Hotel/Motel Guest Room | D29: BaseZnSys1-14 | E29: ResidentialLiving | F29: Yes | G29: =H29/$H$51 -> 0.043331489 | H29: 1404.14 | I29: 12637.85 | J29: 1 | K29: =(H29/1000)*L29 -> 4.21242 | L29: 3 | O29: Guest Room | P29: =SUMIFS($H$3:$H$50, $C$3:$C$50, "*Guest Room*") -> 18767.6 | Q29: =P29/$H$51 -> 0.57916451
A30: HotelSmall | B30: GuestRoom_24_FloorM | C30: Hotel/Motel Guest Room | D30: BaseZnSys1-15 | E30: ResidentialLiving | F30: Yes | G30: =H30/$H$51 -> 0.010832718 | H30: 351.03 | I30: 3159.46 | J30: 1 | K30: =(H30/1000)*L30 -> 1.05309 | L30: 3 | O30: Lounge | P30: =SUMIFS($H$3:$H$50, $C$3:$C$50, "*Lounge*") -> 2106.33 | Q30: =P30/$H$51 -> 0.065000937
A31: HotelSmall | B31: GuestRoom_1_FloorT | C31: Hotel/Motel Guest Room | D31: BaseZnSys1-16 | E31: ResidentialLiving | F31: Yes | G31: =H31/$H$51 -> 0.010833644 | H31: 351.06 | I31: 3159.7 | J31: 1 | K31: =(H31/1000)*L31 -> 1.05318 | L31: 3 | O31: Corridor | P31: =SUMIFS($H$3:$H$50, $C$3:$C$50, "*Corridor*") -> 4806.53 | Q31: =P31/$H$51 -> 0.14832859
A32: HotelSmall | B32: GuestRoom_2_5_FloorT | C32: Hotel/Motel Guest Room | D32: BaseZnSys1-17 | E32: ResidentialLiving | F32: Yes | G32: =H32/$H$51 -> 0.043334575 | H32: 1404.24 | I32: 12638.78 | J32: 1 | K32: =(H32/1000)*L32 -> 4.21272 | L32: 3 | O32: Office | P32: =SUMIFS($H$3:$H$50, $C$3:$C$50, "*Office*") -> 1404.14 | Q32: =P32/$H$51 -> 0.043331489
A33: HotelSmall | B33: GuestRoom_6_8_FloorT | C33: Hotel/Motel Guest Room | D33: BaseZnSys1-18 | E33: ResidentialLiving | F33: Yes | G33: =H33/$H$51 -> 0.035001193 | H33: 1134.2 | I33: 10208.3 | J33: 1 | K33: =(H33/1000)*L33 -> 3.4026 | L33: 3 | O33: Exercise/Gym | P33: =SUMIFS($H$3:$H$50, $C$3:$C$50, "*Exercise*") -> 351.03 | Q33: =P33/$H$51 -> 0.010832718
A34: HotelSmall | B34: GuestRoom_9_12_FloorT | C34: Hotel/Motel Guest Room | D34: BaseZnSys1-19 | E34: ResidentialLiving | F34: Yes | G34: =H34/$H$51 -> 0.043334575 | H34: 1404.24 | I34: 12638.78 | J34: 1 | K34: =(H34/1000)*L34 -> 4.21272 | L34: 3 | O34: Conference | P34: =SUMIFS($H$3:$H$50, $C$3:$C$50, "*Conference*") -> 864.15 | Q34: =P34/$H$51 -> 0.026667502
A35: HotelSmall | B35: GuestRoom_13_FloorT | C35: Hotel/Motel Guest Room | D35: BaseZnSys1-20 | E35: ResidentialLiving | F35: Yes | G35: =H35/$H$51 -> 0.010833644 | H35: 351.06 | I35: 3159.7 | J35: 1 | K35: =(H35/1000)*L35 -> 1.05318 | L35: 3 | O35: Mechanical | P35: =SUMIFS($H$3:$H$50, $C$3:$C$50, "*Mechanical*") -> 351.06 | Q35: =P35/$H$51 -> 0.010833644
A36: HotelSmall | B36: GuestRoom_14_FloorT | C36: Hotel/Motel Guest Room | D36: BaseZnSys1-21 | E36: ResidentialLiving | F36: Yes | G36: =H36/$H$51 -> 0.010832718 | H36: 351.03 | I36: 3159.46 | J36: 1 | K36: =(H36/1000)*L36 -> 1.05309 | L36: 3 | O36: Laundry | P36: =SUMIFS($H$3:$H$50, $C$3:$C$50, "*Laundry*") -> 1053.11 | Q36: =P36/$H$51 -> 0.032498771
A37: HotelSmall | B37: GuestRoom_15_18_FloorT | C37: Hotel/Motel Guest Room | D37: BaseZnSys1-22 | E37: ResidentialLiving | F37: Yes | G37: =H37/$H$51 -> 0.043331489 | H37: 1404.14 | I37: 12637.85 | J37: 1 | K37: =(H37/1000)*L37 -> 4.21242 | L37: 3 | O37: Storage | P37: =SUMIFS($H$3:$H$50, $C$3:$C$50, "*Storage*") -> 1053.3 | Q37: =P37/$H$51 -> 0.032504634
A38: HotelSmall | B38: GuestRoom_19_FloorT | C38: Hotel/Motel Guest Room | D38: BaseZnSys1-23 | E38: ResidentialLiving | F38: Yes | G38: =H38/$H$51 -> 0.010833027 | H38: 351.04 | I38: 3159.51 | J38: 1 | K38: =(H38/1000)*L38 -> 1.05312 | L38: 3 | O38: Restroom | P38: =SUMIFS($H$3:$H$50, $C$3:$C$50, "*Restroom*") -> 351.06 | Q38: =P38/$H$51 -> 0.010833644
A39: HotelSmall | B39: GuestRoom_20_23_FloorT | C39: Hotel/Motel Guest Room | D39: BaseZnSys1-24 | E39: ResidentialLiving | F39: Yes | G39: =H39/$H$51 -> 0.043331489 | H39: 1404.14 | I39: 12637.85 | J39: 1 | K39: =(H39/1000)*L39 -> 4.21242 | L39: 3 | O39: Stairs | P39: =SUMIFS($H$3:$H$50, $C$3:$C$50, "*Stair*") -> 1296.3 | Q39: =P39/$H$51 -> 0.040003567
A40: HotelSmall | B40: GuestRoom_24_FloorT | C40: Hotel/Motel Guest Room | D40: BaseZnSys1-25 | E40: ResidentialLiving | F40: Yes | G40: =H40/$H$51 -> 0.010832718 | H40: 351.03 | I40: 3159.46 | J40: 1 | K40: =(H40/1000)*L40 -> 1.05309 | L40: 3
A41: HotelSmall | B41: Laundry_FloorG | C41: Laundry Area | D41: BaseAirSys5 | E41: Assembly | F41: Yes | G41: =H41/$H$51 -> 0.032498771 | H41: 1053.11 | I41: 11584.76 | J41: 1 | K41: =(H41/1000)*L41 -> 5.26555 | L41: 5
...

Sheet Envelope
A1: Envelope - HotelSmall
A2: Element | B2: Prototype | C2: Assembly Type | D2: Construction | E2: Thermal Properties | F2: Vintage | G2: Selected T24 | H2: Notes | I2: CZ1 | J2: CZ2 | K2: CZ3 | L2: CZ4 | M2: CZ5 | N2: CZ6 | O2: CZ7 | P2: CZ8 | Q2: CZ9 | R2: CZ10 | S2: CZ11 | T2: CZ12 | U2: CZ13 | V2: CZ14 | W2: CZ15 | X2: CZ16
A3: External Wall_Guest Room | B3: HotelSmall | C3: ExtWall_MetalFramed_GuestRooms | D3: Metal framed wall: Stucco + Metal-frame (2x4 16 in. OC) + insulation + Gypsum board | E3: U-factor IP | F3: Pre 1978 | G3: N/A | H3: ASHRAE 90.1, 2022, Table A3.3.3.1, 3.5", R-0 | I3: 0.352 | J3: 0.352 | K3: 0.352 | L3: 0.352 | M3: 0.352 | N3: 0.352 | O3: 0.352 | P3: 0.352 | Q3: 0.352 | R3: 0.352 | S3: 0.352 | T3: 0.352 | U3: 0.352 | V3: 0.352 | W3: 0.352 | X3: 0.352
F4: 1978-1997 | G4: 1986 | H4: Copied from High-rise office alternative requirements (Table 2-53W): Package A with heat capacity between 10-14.99 (Btu/F-ft²) *T24, 1986, Table 2-53BB presents U-factors less than the next vintage (for wall density of 26-40 lb/ft² & Degree day<3500)! | I4: =1/4.7 -> 0.21276596 | J4: =1/4.4 -> 0.22727273 | K4: =1/4.4 -> 0.22727273 | L4: =1/4.6 -> 0.2173913 | M4: =1/3.9 -> 0.25641026 | N4: =1/3.9 -> 0.25641026 | O4: =1/3.9 -> 0.25641026 | P4: =1/3.9 -> 0.25641026 | Q4: =1/3.9 -> 0.25641026 | R4: =1/3.9 -> 0.25641026 | S4: =1/4.2 -> 0.23809524 | T4: =1/4.2 -> 0.23809524 | U4: =1/4.2 -> 0.23809524 | V4: =1/4.8 -> 0.20833333 | W4: =1/4.8 -> 0.20833333 | X4: =1/4.7 -> 0.21276596
F5: 1998-2007 | G5: 2001 | H5: Table 1-I-Guest rooms of Hotel/Motel | I5: 0.14 | J5: 0.175 | K5: 0.181 | L5: 0.181 | M5: 0.181 | N5: 0.181 | O5: 0.181 | P5: 0.181 | Q5: 0.181 | R5: 0.175 | S5: 0.175 | T5: 0.175 | U5: 0.175 | V5: 0.175 | W5: 0.175 | X5: 0.14
F6: 2008-2018 | G6: 2013 | H6: Table 140.3-C-Guest rooms of Hotel/Motel | I6: 0.105 | J6: 0.105 | K6: 0.105 | L6: 0.105 | M6: 0.105 | N6: 0.105 | O6: 0.105 | P6: 0.105 | Q6: 0.105 | R6: 0.105 | S6: 0.105 | T6: 0.105 | U6: 0.105 | V6: 0.105 | W6: 0.105 | X6: 0.105
F7: 2019+ | G7: 2025 | H7: Table 140.3-C-Guest rooms of Hotel/Motel | I7: 0.069 | J7: 0.069 | K7: 0.069 | L7: 0.069 | M7: 0.069 | N7: 0.069 | O7: 0.105 | P7: 0.069 | Q7: 0.069 | R7: 0.069 | S7: 0.069 | T7: 0.069 | U7: 0.069 | V7: 0.069 | W7: 0.048 | X7: 0.069
A8: External Wall_Nonres | B8: HotelSmall | C8: ExtWall_MetalFramed_NonRes | D8: Metal framed wall : Stucco + Metal frame (2x4 16 in. OC) + insulation + Gypsum board | E8: U-factor IP | F8: Pre 1978 | G8: N/A | H8: ASHRAE 90.1, 2022, Table A3.3.3.1, 3.5", R-0 | I8: 0.352 | J8: 0.352 | K8: 0.352 | L8: 0.352 | M8: 0.352 | N8: 0.352 | O8: 0.352 | P8: 0.352 | Q8: 0.352 | R8: 0.352 | S8: 0.352 | T8: 0.352 | U8: 0.352 | V8: 0.352 | W8: 0.352 | X8: 0.352
F9: 1978-1997 | G9: 1986 | H9: Copied from High-rise office alternative requirements (Table 2-53W): Package A with heat capacity between 10-14.99 (Btu/F-ft²) *T24, 1986, Table 2-53BB presents U-factors less than the next vintage (for wall density of 26-40 lb/ft² & Degree day<3500)! | I9: 0.21276596 | J9: 0.22727273 | K9: 0.22727273 | L9: 0.2173913 | M9: 0.25641026 | N9: 0.25641026 | O9: 0.25641026 | P9: 0.25641026 | Q9: 0.25641026 | R9: 0.25641026 | S9: 0.23809524 | T9: 0.23809524 | U9: 0.23809524 | V9: 0.20833333 | W9: 0.20833333 | X9: 0.21276596
F10: 1998-2007 | G10: 2001 | H10: Table 1-H-NonRes Bldgs | I10: 0.182 | J10: 0.182 | K10: 0.189 | L10: 0.189 | M10: 0.189 | N10: 0.189 | O10: 0.189 | P10: 0.189 | Q10: 0.189 | R10: 0.182 | S10: 0.182 | T10: 0.182 | U10: 0.182 | V10: 0.182 | W10: 0.182 | X10: 0.182
F11: 2008-2018 | G11: 2013 | H11: Table 140.3-B-NonRes Bldgs | I11: 0.098 | J11: 0.062 | K11: 0.082 | L11: 0.062 | M11: 0.062 | N11: 0.098 | O11: 0.098 | P11: 0.062 | Q11: 0.062 | R11: 0.062 | S11: 0.062 | T11: 0.062 | U11: 0.062 | V11: 0.062 | W11: 0.062 | X11: 0.062
F12: 2019+ | G12: 2025 | H12: Table 140.3-B-NonRes Bldgs | I12: 0.06 | J12: 0.055 | K12: 0.071 | L12: 0.055 | M12: 0.055 | N12: 0.06 | O12: 0.06 | P12: 0.055 | Q12: 0.055 | R12: 0.055 | S12: 0.055 | T12: 0.055 | U12: 0.055 | V12: 0.055 | W12: 0.055 | X12: 0.055
A13: Roof_Guest Room | B13: HotelSmall | C13: FlatRoof_WoodFramedAndOther_GuestRooms | D13: Metal deck roof: Roof membrane or shingles + roof insulation + metal decking/sheathing + framing | E13: U-factor IP | F13: Pre 1978 | G13: N/A | H13: Considering 30 years for roof/ insulation replacement. | I13: 0.037 | J13: 0.051 | K13: 0.051 | L13: 0.051 | M13: 0.051 | N13: 0.051 | O13: 0.051 | P13: 0.051 | Q13: 0.051 | R13: 0.051 | S13: 0.037 | T13: 0.037 | U13: 0.037 | V13: 0.037 | W13: 0.037 | X13: 0.037
F14: 1978-1997 | G14: N/A | I14: 0.037 | J14: 0.051 | K14: 0.051 | L14: 0.051 | M14: 0.051 | N14: 0.051 | O14: 0.051 | P14: 0.051 | Q14: 0.051 | R14: 0.051 | S14: 0.037 | T14: 0.037 | U14: 0.037 | V14: 0.037 | W14: 0.037 | X14: 0.037
F15: 1998-2007 | G15: 2001 | H15: Table 1-I-Guest rooms of Hotel/Motel | I15: 0.037 | J15: 0.037 | K15: 0.051 | L15: 0.051 | M15: 0.051 | N15: 0.051 | O15: 0.051 | P15: 0.051 | Q15: 0.051 | R15: 0.037 | S15: 0.037 | T15: 0.037 | U15: 0.037 | V15: 0.037 | W15: 0.037 | X15: 0.037
F16: 2008-2018 | G16: 2013 | H16: Table 140.3-C-Guest rooms of Hotel/Motel | I16: 0.034 | J16: 0.028 | K16: 0.039 | L16: 0.028 | M16: 0.039 | N16: 0.039 | O16: 0.039 | P16: 0.028 | Q16: 0.028 | R16: 0.028 | S16: 0.028 | T16: 0.028 | U16: 0.028 | V16: 0.028 | W16: 0.028 | X16: 0.028
F17: 2019+ | G17: 2025 | H17: Table 140.3-C-Guest rooms of Hotel/Motel | I17: 0.028 | J17: 0.028 | K17: 0.034 | L17: 0.028 | M17: 0.034 | N17: 0.034 | O17: 0.039 | P17: 0.028 | Q17: 0.028 | R17: 0.028 | S17: 0.028 | T17: 0.028 | U17: 0.028 | V17: 0.028 | W17: 0.028 | X17: 0.028
A18: Windows_ Guest Room | B18: HotelSmall | C18: FixedWindow_GuestRoom | D18: Single pane | E18: U-factor IP | F18: Pre 1978 | G18: N/A | H18: ASHRAE Handbook of Fundamentals (Table 4-Ch15) for single pane & T24, 2013 for double pane(33%-67%)* | I18: =0.33*1.12+0.67*0.36 -> 0.6108 | J18: =0.33*1.12+0.67*0.36 -> 0.6108 | K18: =0.33*1.12+0.67*0.36 -> 0.6108 | L18: =0.33*1.12+0.67*0.36 -> 0.6108 | M18: =0.33*1.12+0.67*0.36 -> 0.6108 | N18: =0.33*1.12+0.67*0.36 -> 0.6108 | O18: =0.33*1.12+0.67*0.36 -> 0.6108 | P18: =0.33*1.12+0.67*0.36 -> 0.6108 | ... X18: =0.33*1.12+0.67*0.36 -> 0.6108
F19: 1978-1997 | G19: N/A | I19: =0.33*1.12+0.67*0.36 -> 0.6108 | J19: =0.33*1.12+0.67*0.36 -> 0.6108 | K19: =0.33*1.12+0.67*0.36 -> 0.6108 | L19: =0.33*1.12+0.67*0.36 -> 0.6108 | M19: =0.33*1.12+0.67*0.36 -> 0.6108 | N19: =0.33*1.12+0.67*0.36 -> 0.6108 | O19: =0.33*1.12+0.67*0.36 -> 0.6108 | P19: =0.33*1.12+0.67*0.36 -> 0.6108 | ... X19: =0.33*1.12+0.67*0.36 -> 0.6108
D20: Double pane | F20: 1998-2007 | G20: 2001 | H20: Table 1-I-Guest rooms of Hotel/Motel | I20: 0.49 | J20: 0.49 | K20: 0.49 | L20: 0.49 | M20: 0.49 | N20: 0.49 | O20: 0.49 | P20: 0.49 | Q20: 0.49 | R20: 0.49 | S20: 0.49 | T20: 0.49 | U20: 0.49 | V20: 0.49 | W20: 0.49 | X20: 0.49
F21: 2008-2018 | G21: 2013 | H21: Table 140.3-C-Guest rooms of Hotel/Motel | I21: 0.36 | J21: 0.36 | K21: 0.36 | L21: 0.36 | M21: 0.36 | N21: 0.36 | O21: 0.36 | P21: 0.36 | Q21: 0.36 | R21: 0.36 | S21: 0.36 | T21: 0.36 | U21: 0.36 | V21: 0.36 | W21: 0.36 | X21: 0.36
F22: 2019+ | G22: 2025 | H22: Table 140.3-C-Guest rooms of Hotel/Motel | I22: 0.36 | J22: 0.36 | K22: 0.36 | L22: 0.36 | M22: 0.36 | N22: 0.36 | O22: 0.36 | P22: 0.36 | Q22: 0.36 | R22: 0.36 | S22: 0.36 | T22: 0.36 | U22: 0.36 | V22: 0.36 | W22: 0.36 | X22: 0.36
D23: Single pane | E23: SHGC | F23: Pre 1978 | G23: N/A | H23: ASHRAE Handbook of Fundamentals (Table 10-Ch15) for single pane & T24, 2013 for double pane(33%-67%)* | I23: =0.79*0.33+0.67*I36 -> 0.4282 | J23: =0.79*0.33+0.67*J36 -> 0.4282 | K23: =0.79*0.33+0.67*K36 -> 0.4282 | L23: =0.79*0.33+0.67*L36 -> 0.4282 | M23: =0.79*0.33+0.67*M36 -> 0.4282 | N23: =0.79*0.33+0.67*N36 -> 0.4282 | O23: =0.79*0.33+0.67*O36 -> 0.4282 | P23: =0.79*0.33+0.67*P36 -> 0.4282 | ... X23: =0.79*0.33+0.67*X36 -> 0.4282
F24: 1978-1997 | G24: N/A | I24: =0.79*0.33+0.67*I26 -> 0.4282 | J24: =0.79*0.33+0.67*J26 -> 0.4282 | K24: =0.79*0.33+0.67*K26 -> 0.4282 | L24: =0.79*0.33+0.67*L26 -> 0.4282 | M24: =0.79*0.33+0.67*M26 -> 0.4282 | N24: =0.79*0.33+0.67*N26 -> 0.4282 | O24: =0.79*0.33+0.67*O26 -> 0.4282 | P24: =0.79*0.33+0.67*P26 -> 0.4282 | ... X24: =0.79*0.33+0.67*X26 -> 0.4282
D25: Double pane | F25: 1998-2007 | G25: 2001 | H25: Table 1-I-Guest rooms of Hotel/Motel (WWR:10-20% / SHGC Non-north) | I25: 0.46 | J25: 0.36 | K25: 0.4 | L25: 0.4 | M25: 0.4 | N25: 0.4 | O25: 0.4 | P25: 0.4 | Q25: 0.4 | R25: 0.36 | S25: 0.36 | T25: 0.36 | U25: 0.36 | V25: 0.31 | W25: 0.31 | X25: 0.46
F26: 2008-2018 | G26: 2013 | H26: Table 140.3-C-Guest rooms of Hotel/Motel | I26: 0.25 | J26: 0.25 | K26: 0.25 | L26: 0.25 | M26: 0.25 | N26: 0.25 | O26: 0.25 | P26: 0.25 | Q26: 0.25 | R26: 0.25 | S26: 0.25 | T26: 0.25 | U26: 0.25 | V26: 0.25 | W26: 0.25 | X26: 0.25
F27: 2019+ | G27: 2025 | H27: Table 140.3-C-Guest rooms of Hotel/Motel | I27: 0.25 | J27: 0.25 | K27: 0.25 | L27: 0.25 | M27: 0.25 | N27: 0.25 | O27: 0.25 | P27: 0.25 | Q27: 0.25 | R27: 0.25 | S27: 0.25 | T27: 0.25 | U27: 0.25 | V27: 0.25 | W27: 0.25 | X27: 0.25
A28: Windows_ Nonres | B28: HotelSmall | C28: FixedWindow_NonRes | D28: Single pane | E28: U-factor IP | F28: Pre 1978 | G28: N/A | H28: ASHRAE Handbook of Fundamentals (Table 4-Ch15) for single pane & T24, 2013 for double pane(33%-67%)* | I28: =0.338*1.12+0.67*0.36 -> 0.61976 | J28: =0.338*1.12+0.67*0.36 -> 0.61976 | K28: =0.338*1.12+0.67*0.36 -> 0.61976 | L28: =0.338*1.12+0.67*0.36 -> 0.61976 | M28: =0.338*1.12+0.67*0.36 -> 0.61976 | N28: =0.338*1.12+0.67*0.36 -> 0.61976 | O28: =0.338*1.12+0.67*0.36 -> 0.61976 | P28: =0.338*1.12+0.67*0.36 -> 0.61976 | ... X28: =0.338*1.12+0.67*0.36 -> 0.61976
F29: 1978-1997 | G29: N/A | I29: =0.338*1.12+0.67*0.36 -> 0.61976 | J29: =0.338*1.12+0.67*0.36 -> 0.61976 | K29: =0.338*1.12+0.67*0.36 -> 0.61976 | L29: =0.338*1.12+0.67*0.36 -> 0.61976 | M29: =0.338*1.12+0.67*0.36 -> 0.61976 | N29: =0.338*1.12+0.67*0.36 -> 0.61976 | O29: =0.338*1.12+0.67*0.36 -> 0.61976 | P29: =0.338*1.12+0.67*0.36 -> 0.61976 | ... X29: =0.338*1.12+0.67*0.36 -> 0.61976
D30: Double pane | F30: 1998-2007 | G30: 2001 | H30: Table 1-H-NonRes Bldgs | I30: 0.49 | J30: 0.49 | K30: 0.81 | L30: 0.81 | M30: 0.81 | N30: 0.81 | O30: 0.81 | P30: 0.81 | Q30: 0.81 | R30: 0.49 | S30: 0.49 | T30: 0.49 | U30: 0.49 | V30: 0.49 | W30: 0.49 | X30: 0.49
F31: 2008-2018 | G31: 2013 | H31: Table 140.3-B-NonRes Bldgs | I31: 0.36 | J31: 0.36 | K31: 0.36 | L31: 0.36 | M31: 0.36 | N31: 0.36 | O31: 0.36 | P31: 0.36 | Q31: 0.36 | R31: 0.36 | S31: 0.36 | T31: 0.36 | U31: 0.36 | V31: 0.36 | W31: 0.36 | X31: 0.36
F32: 2019+ | G32: 2025 | H32: Table 140.3-B-NonRes Bldgs | I32: 0.36 | J32: 0.36 | K32: 0.36 | L32: 0.36 | M32: 0.36 | N32: 0.36 | O32: 0.36 | P32: 0.36 | Q32: 0.34 | R32: 0.36 | S32: 0.34 | T32: 0.34 | U32: 0.34 | V32: 0.34 | W32: 0.34 | X32: 0.36
D33: Single pane | E33: SHGC | F33: Pre 1978 | G33: N/A | H33: ASHRAE Handbook of Fundamentals (Table 10-Ch15) for single pane & T24, 2013 for double pane(33%-67%)* | I33: =0.79*0.33+0.67*I36 -> 0.4282 | J33: =0.79*0.33+0.67*J36 -> 0.4282 | K33: =0.79*0.33+0.67*K36 -> 0.4282 | L33: =0.79*0.33+0.67*L36 -> 0.4282 | M33: =0.79*0.33+0.67*M36 -> 0.4282 | N33: =0.79*0.33+0.67*N36 -> 0.4282 | O33: =0.79*0.33+0.67*O36 -> 0.4282 | P33: =0.79*0.33+0.67*P36 -> 0.4282 | ... X33: =0.79*0.33+0.67*X36 -> 0.4282
F34: 1978-1997 | G34: N/A | I34: =0.79*0.33+0.67*I36 -> 0.4282 | J34: =0.79*0.33+0.67*J36 -> 0.4282 | K34: =0.79*0.33+0.67*K36 -> 0.4282 | L34: =0.79*0.33+0.67*L36 -> 0.4282 | M34: =0.79*0.33+0.67*M36 -> 0.4282 | N34: =0.79*0.33+0.67*N36 -> 0.4282 | O34: =0.79*0.33+0.67*O36 -> 0.4282 | P34: =0.79*0.33+0.67*P36 -> 0.4282 | ... X34: =0.79*0.33+0.67*X36 -> 0.4282
D35: Double pane | F35: 1998-2007 | G35: 2001 | H35: Table 1-H-NonRes Bldgs (WWR:10-20% / SHGC Non-north) | I35: 0.43 | J35: 0.36 | K35: 0.55 | L35: 0.55 | M35: 0.55 | N35: 0.61 | O35: 0.61 | P35: 0.61 | Q35: 0.61 | R35: 0.36 | S35: 0.36 | T35: 0.36 | U35: 0.36 | V35: 0.36 | W35: 0.36 | X35: 0.43
F36: 2008-2018 | G36: 2013 | H36: Table 140.3-B-NonRes Bldgs | I36: 0.25 | J36: 0.25 | K36: 0.25 | L36: 0.25 | M36: 0.25 | N36: 0.25 | O36: 0.25 | P36: 0.25 | Q36: 0.25 | R36: 0.25 | S36: 0.25 | T36: 0.25 | U36: 0.25 | V36: 0.25 | W36: 0.25 | X36: 0.25
F37: 2019+ | G37: 2025 | H37: Table 140.3-B-NonRes Bldgs | I37: 0.25 | J37: 0.25 | K37: 0.25 | L37: 0.25 | M37: 0.25 | N37: 0.25 | O37: 0.25 | P37: 0.25 | Q37: 0.22 | R37: 0.25 | S37: 0.22 | T37: 0.22 | U37: 0.22 | V37: 0.22 | W37: 0.22 | X37: 0.25
C39: Infiltration
D40: Building | E40: Zones | F40: Vintage | G40: I_75 (cfm/ft²) 6-sdied Infiltration rate @ 75 pa | H40: Source | I40: I-design (cfm/ft²) (4-sided Infiltration rate at normal pressure) (Design flow rate approach and Flow/Exterior Wall Area calculation method)
C41: Infiltration | D41: HotelSmall | F41: Pre 1978 | G41: 1.1 | H41: 2022 CASE report (Table 38) | I41: 0.3144
...

Sheet HVAC System
A1: ="HVAC system - "&Prototype!A2 -> HVAC system - HotelSmall
A2: Vintage | B2: Zones | C2: Heating | D2: Cooling | E2: Air Distribution | F2: Source | G2: Note
A3: Existing | B3: Guest Rooms | C3: Electric resistance | D3: PTAC | F3: CEUS 2022 + engineering judgement
B4: All other conditioned zones | C4: Electric resistance | D4: PTAC | F4: CEUS 2022 + engineering judgement
A6: New Construction | B6: Guest Rooms | C6: PTHP | D6: PTHP | F6: Engineering Judgement | G6: The guestroom system was originally System 1 (RAC) based on Title 24 Tables 2 and 3. However, after several discussions and consultations with experts and engineers, we realized that for new buildings, each room should instead use a PTHP system. We updated the HVAC accordingly.
B7: All other conditioned zones | C7: Gas Boiler | D7: PVAV | E7: VAV + Hydronic Reheat | F7: T24 2025 ACM 2025, Table 2 and 3 | G7: Packaged VAV-System5
A11: Efficiency of HVAC System (Efficiency is capacity-dependent. The following table provides a general estimate of system efficiency based on preliminary simulations in one climate zone, or assuming cooling load based on rule of thumb)
A12: Vintage | B12: Upgrade/Installed year | C12: DX Cooling-Guest Rooms | D12: DX Cooling-All Other Conditioned Zones | E12: Gas Boiler- Guest rooms and All Other Conditioned Zones | F12: Sources | G12: Note
A13: Pre 1978 | B13: 2008 | C13: EER=9 (<65,000 Btu/h) | D13: - | E13: - | F13: CFR Energy 2008 (for DX Cooling)
A14: 1978-1997
A15: 1998-2007
A16: 2008-2018 | B16: 2013 | C16: EER=9 (<65,000 Btu/h) | D16: - | E16: - | F16: CFR Energy 2010:Title 10- Table 9 (for DX Cooling)
A17: New Construction | B17: 2025 | C17: EER=9 (<65,000 Btu/h) | D17: EER=10 (≥ 240,000 Btu/h and < 760,000 Btu/h) and EER=9 (<65,000 Btu/h) | E17: Thermal Efficiency (Et) of 84% | F17: CFR Energy 2025, Table 12 (for DX Coils) T24, 2022 ,Table 110.2-J (for Boiler thermal efficiency) | G17: Deduct 0.2 from the required EERs and IEERs for units with a heating section other than electric resistance heat.
A21: Fan power
A22: Vintage | B22: Approach | C22: System | D22: Total Static Pressure (TSP) | E22: Fan Efficiency [ACM 2025] | F22: Motor Efficiency | G22: Fan Power Index (W/cfm) | H22: Data Source
A23: Existing | B23: PNNL 90.1-2011, TSP | C23: PTAC, PTHP | D23: 1.33 | E23: 0.65 | F23: ASHRAE 90.1, 2004, Table 10.8 * | H23: Fan power formula: PNNL 20405, 2010, section 5.2.2.5 TSP and fan efficiency: PNNL 20405, 2010, Table 5.11, 90.1-04ac values Motor efficiency: ASHRAE 90.1, 2004, Table 10.8
A24: Brake horse power (bhp)=(Supply cfm*TSP in w.c.)/(6356*Fan efficiency)
A25: Fan power (w/cfm) = bhp/motor and drive efficiency *746
A26: cfm = supply fan airflow as determined by EnergyPlus sizing runs
A27: Nameplate horsepower = brake horsepower × (1+10% oversizing factor)
A28: Motor nameplate horsepower will be determined based of NEMA standards
A29: New Construction | B29: ACM 2025 | C29: System 3b-SZHP, <5000 | D29: TSP = fan power × motor efficiency × fan efficiency × 6356 / 746 | E29: 0.65 | F29: 2025 ACM Table 12 ** | G29: 0.744 | H29: Fan power index: [ACM 2025, Table 13] Motor efficiency: [ACM 2025, Table 12]
C30: PVAV System >10,000 cfm | D30: TSP = fan power × motor efficiency × fan efficiency × 6356 / 746 | G30: 0.964
A32: * According to PNNL 20405 section 5.2.2.5, the full-load efficiency of the motor serving the fan is taken from ASHRAE 90.1, 2004, Table 10.8, based on motor nameplate and assuming enclosed motors operating at 1,800 rotations per minute (rpm) Motor nameplate size (bhp) = brake horsepower (bhp) × 1.1 ( using a 10% oversizing factor)
A33: ** The full‑load efficiency of the motor serving the fan is taken from ACM 2025 Table 12 based on the cfm of the fan. Brake horsepower (bhp) = (Supply cfm from sizing run × fan power in W/cfm) / 746.

Sheet Ventilation
A1: Outdoor Airflow Rate - HotelSmall
A2: Space Name | B2: Number of People | C2: Floor Area (ft²) | D2: cfm/person (T24, 2025, Equation 120.1-F and Table 120.1-A) (ASHRAE 62.1, 2022, Table 6-1) for guest rooms | E2: cfm/ft² (T24, 2025, Equation 120.1-F and Table 120.1-A) (ASHRAE 62.1, 2022, Table 6-1) for guest rooms | F2: Required Exhaust Rate (T24, 2025, Table 120.1-B – Minimum Exhaust Rates) | G2: Total cfm Driven by People | H2: Total cfm Driven by Area | I2: Total cfm Driven by Exhaust | J2: Total cfm | K2: Notes
A3: =Zones!B3 -> Corridor_FloorG | B3: =Zones!K3 -> 8.91105 | C3: =Zones!H3 -> 1782.21 | D3: 15 | E3: 0.15 | G3: =B3*D3 -> 133.66575 | H3: =C3*E3 -> 267.3315 | J3: =MAX(G3:I3) -> 267.3315
A4: =Zones!B4 -> Corridor_FloorM | B4: =Zones!K4 -> 7.5608 | C4: =Zones!H4 -> 1512.16 | D4: 15 | E4: 0.15 | G4: =B4*D4 -> 113.412 | H4: =C4*E4 -> 226.824 | J4: =MAX(G4:I4) -> 226.824
A5: =Zones!B5 -> Corridor_FloorT | B5: =Zones!K5 -> 7.5608 | C5: =Zones!H5 -> 1512.16 | D5: 15 | E5: 0.15 | G5: =B5*D5 -> 113.412 | H5: =C5*E5 -> 226.824 | J5: =MAX(G5:I5) -> 226.824
A6: =Zones!B6 -> Lounge_FloorG | B6: =Zones!K6 -> 11.58399 | C6: =Zones!H6 -> 351.03 | D6: 15 | E6: 0.15 | G6: =B6*D6 -> 173.75985 | H6: =C6*E6 -> 52.6545 | J6: =MAX(G6:I6) -> 173.75985
A7: =Zones!B7 -> Gym_FloorG | B7: =Zones!K7 -> 3.5103 | C7: =Zones!H7 -> 351.03 | D7: 15 | E7: 0.15 | G7: =B7*D7 -> 52.6545 | H7: =C7*E7 -> 52.6545 | J7: =MAX(G7:I7) -> 52.6545
A8: =Zones!B8 -> Front_Lounge_FloorG | B8: =Zones!K8 -> 26.3295 | C8: =Zones!H8 -> 1755.3 | D8: 15 | E8: 0.15 | G8: =B8*D8 -> 394.9425 | H8: =C8*E8 -> 263.295 | J8: =MAX(G8:I8) -> 394.9425
A9: =Zones!B9 -> Front_Office_FloorG | B9: =Zones!K9 -> 7.0207 | C9: =Zones!H9 -> 1404.14 | D9: 15 | E9: 0.15 | G9: =B9*D9 -> 105.3105 | H9: =C9*E9 -> 210.621 | J9: =MAX(G9:I9) -> 210.621
A10: =Zones!B10 -> Front_Stair_FloorG | B10: =Zones!K10 -> 0 | C10: =Zones!H10 -> 216.02 | D10: 15 | E10: 0.15 | G10: =B10*D10 -> 0 | H10: =C10*E10 -> 32.403 | J10: =MAX(G10:I10) -> 32.403
A11: =Zones!B11 -> Front_Stair_FloorM | B11: =Zones!K11 -> 0 | C11: =Zones!H11 -> 216.02 | D11: 15 | E11: 0.15 | G11: =B11*D11 -> 0 | H11: =C11*E11 -> 32.403 | J11: =MAX(G11:I11) -> 32.403
A12: =Zones!B12 -> Front_Stair_FloorT | B12: =Zones!K12 -> 0 | C12: =Zones!H12 -> 216.02 | D12: 15 | E12: 0.15 | G12: =B12*D12 -> 0 | H12: =C12*E12 -> 32.403 | J12: =MAX(G12:I12) -> 32.403
A13: =Zones!B13 -> Front_Storage_FloorG | B13: =Zones!K13 -> 0.27002 | C13: =Zones!H13 -> 135.01 | D13: 15 | E13: 0.15 | G13: =B13*D13 -> 4.0503 | H13: =C13*E13 -> 20.2515 | J13: =MAX(G13:I13) -> 20.2515
A14: =Zones!B14 -> Front_Storage_FloorM | B14: =Zones!K14 -> 0.27002 | C14: =Zones!H14 -> 135.01 | D14: 15 | E14: 0.15 | G14: =B14*D14 -> 4.0503 | H14: =C14*E14 -> 20.2515 | J14: =MAX(G14:I14) -> 20.2515
A15: =Zones!B15 -> Front_Storage_FloorT | B15: =Zones!K15 -> 0.27002 | C15: =Zones!H15 -> 135.01 | D15: 15 | E15: 0.15 | G15: =B15*D15 -> 4.0503 | H15: =C15*E15 -> 20.2515 | J15: =MAX(G15:I15) -> 20.2515
A16: =Zones!B16 -> GuestRoom_1_FloorG | B16: =Zones!K16 -> 1.05318 | C16: =Zones!H16 -> 351.06 | D16: =5*10/3 -> 16.666667 | E16: 0.06 | F16: 20/50 cfm/unit per shower head | G16: =B16*D16 -> 17.553 | H16: =C16*E16 -> 21.0636 | I16: =50 -> 50 | J16: =MAX(G16+H16,I16) -> 50 | K16: Several guestrooms are bundled together. for those, it's assumed for each person, there is one shower, that's why the exhaust rate are multiplied by people. Ventilation for guest rooms is calculated using the ASHRAE 62.1, as T24's occupancy-only baseline does not capture realistic ventilation design. The total outdoor airflow is calculated as: Ventilation = (Occupancy per 1,000 ft² × cfm/person) + (Floor area in ft² × cfm/ft²) To maintain simulation consistency across tabs and fo ease of automation, we retained the T24 occupant rate of 3 occupants per 1,000 sq ft rather than adopting ASHRAE's higher rate of 10 occupants per 1,000 sq ft. To compensate for this, we scaled ASHRAE’s per-person airflow requirement (5 cfm/person) by a factor of 10/3. Although the occupant-based portion of the ventilation load remains almost equivalent across both codes, incorporating ASHRAE’s area-based ventilation component represents the key difference in overall outdoor air rates. Ventilation air for this occupancy category shall be permitted to be reduced to zero when the space is in occupied-standby mode
A17: =Zones!B17 -> GuestRoom_2_FloorG | B17: =Zones!K17 -> 1.05318 | C17: =Zones!H17 -> 351.06 | D17: =5*10/3 -> 16.666667 | E17: 0.06 | F17: 20/50 cfm/unit per shower head | G17: =B17*D17 -> 17.553 | H17: =C17*E17 -> 21.0636 | I17: =50 -> 50 | J17: =MAX(G17+H17,I17) -> 50
A18: =Zones!B18 -> GuestRoom_3_FloorG | B18: =Zones!K18 -> 1.05318 | C18: =Zones!H18 -> 351.06 | D18: =5*10/3 -> 16.666667 | E18: 0.06 | F18: 20/50 cfm/unit per shower head | G18: =B18*D18 -> 17.553 | H18: =C18*E18 -> 21.0636 | I18: =50 -> 50 | J18: =MAX(G18+H18,I18) -> 50
A19: =Zones!B19 -> GuestRoom_4_FloorG | B19: =Zones!K19 -> 1.05309 | C19: =Zones!H19 -> 351.03 | D19: =5*10/3 -> 16.666667 | E19: 0.06 | F19: 20/50 cfm/unit per shower head | G19: =B19*D19 -> 17.5515 | H19: =C19*E19 -> 21.0618 | I19: =50 -> 50 | J19: =MAX(G19+H19,I19) -> 50
A20: =Zones!B20 -> GuestRoom_5_FloorG | B20: =Zones!K20 -> 1.05309 | C20: =Zones!H20 -> 351.03 | D20: =5*10/3 -> 16.666667 | E20: 0.06 | F20: 20/50 cfm/unit per shower head | G20: =B20*D20 -> 17.5515 | H20: =C20*E20 -> 21.0618 | I20: =50 -> 50 | J20: =MAX(G20+H20,I20) -> 50
A21: =Zones!B21 -> GuestRoom_1_FloorM | B21: =Zones!K21 -> 1.05318 | C21: =Zones!H21 -> 351.06 | D21: =5*10/3 -> 16.666667 | E21: 0.06 | F21: 20/50 cfm/unit per shower head | G21: =B21*D21 -> 17.553 | H21: =C21*E21 -> 21.0636 | I21: =50 -> 50 | J21: =MAX(G21+H21,I21) -> 50
A22: =Zones!B22 -> GuestRoom_2_5_FloorM | B22: =Zones!K22 -> 4.21272 | C22: =Zones!H22 -> 1404.24 | D22: =5*10/3 -> 16.666667 | E22: 0.06 | F22: 20/50 cfm/unit per shower head | G22: =B22*D22 -> 70.212 | H22: =C22*E22 -> 84.2544 | I22: =50*B22 -> 210.636 | J22: =MAX(G22+H22,I22) -> 210.636
A23: =Zones!B23 -> GuestRoom_6_8_FloorM | B23: =Zones!K23 -> 3.4026 | C23: =Zones!H23 -> 1134.2 | D23: =5*10/3 -> 16.666667 | E23: 0.06 | F23: 20/50 cfm/unit per shower head | G23: =B23*D23 -> 56.71 | H23: =C23*E23 -> 68.052 | I23: =50*B23 -> 170.13 | J23: =MAX(G23+H23,I23) -> 170.13
A24: =Zones!B24 -> GuestRoom_9_12_FloorM | B24: =Zones!K24 -> 4.21272 | C24: =Zones!H24 -> 1404.24 | D24: =5*10/3 -> 16.666667 | E24: 0.06 | F24: 20/50 cfm/unit per shower head | G24: =B24*D24 -> 70.212 | H24: =C24*E24 -> 84.2544 | I24: =50*B24 -> 210.636 | J24: =MAX(G24+H24,I24) -> 210.636
A25: =Zones!B25 -> GuestRoom_13_FloorM | B25: =Zones!K25 -> 1.05318 | C25: =Zones!H25 -> 351.06 | D25: =5*10/3 -> 16.666667 | E25: 0.06 | F25: 20/50 cfm/unit per shower head | G25: =B25*D25 -> 17.553 | H25: =C25*E25 -> 21.0636 | I25: =50*B25 -> 52.659 | J25: =MAX(G25+H25,I25) -> 52.659
A26: =Zones!B26 -> GuestRoom_14_FloorM | B26: =Zones!K26 -> 1.05309 | C26: =Zones!H26 -> 351.03 | D26: =5*10/3 -> 16.666667 | E26: 0.06 | F26: 20/50 cfm/unit per shower head | G26: =B26*D26 -> 17.5515 | H26: =C26*E26 -> 21.0618 | I26: =50*B26 -> 52.6545 | J26: =MAX(G26+H26,I26) -> 52.6545
A27: =Zones!B27 -> GuestRoom_15_18_FloorM | B27: =Zones!K27 -> 4.21242 | C27: =Zones!H27 -> 1404.14 | D27: =5*10/3 -> 16.666667 | E27: 0.06 | F27: 20/50 cfm/unit per shower head | G27: =B27*D27 -> 70.207 | H27: =C27*E27 -> 84.2484 | I27: =50*B27 -> 210.621 | J27: =MAX(G27+H27,I27) -> 210.621
A28: =Zones!B28 -> GuestRoom_19_FloorM | B28: =Zones!K28 -> 1.05312 | C28: =Zones!H28 -> 351.04 | D28: =5*10/3 -> 16.666667 | E28: 0.06 | F28: 20/50 cfm/unit per shower head | G28: =B28*D28 -> 17.552 | H28: =C28*E28 -> 21.0624 | I28: =50*B28 -> 52.656 | J28: =MAX(G28+H28,I28) -> 52.656
A29: =Zones!B29 -> GuestRoom_20_23_FloorM | B29: =Zones!K29 -> 4.21242 | C29: =Zones!H29 -> 1404.14 | D29: =5*10/3 -> 16.666667 | E29: 0.06 | F29: 20/50 cfm/unit per shower head | G29: =B29*D29 -> 70.207 | H29: =C29*E29 -> 84.2484 | I29: =50*B29 -> 210.621 | J29: =MAX(G29+H29,I29) -> 210.621
A30: =Zones!B30 -> GuestRoom_24_FloorM | B30: =Zones!K30 -> 1.05309 | C30: =Zones!H30 -> 351.03 | D30: =5*10/3 -> 16.666667 | E30: 0.06 | F30: 20/50 cfm/unit per shower head | G30: =B30*D30 -> 17.5515 | H30: =C30*E30 -> 21.0618 | I30: =50*B30 -> 52.6545 | J30: =MAX(G30+H30,I30) -> 52.6545
A31: =Zones!B31 -> GuestRoom_1_FloorT | B31: =Zones!K31 -> 1.05318 | C31: =Zones!H31 -> 351.06 | D31: =5*10/3 -> 16.666667 | E31: 0.06 | F31: 20/50 cfm/unit per shower head | G31: =B31*D31 -> 17.553 | H31: =C31*E31 -> 21.0636 | I31: =50*B31 -> 52.659 | J31: =MAX(G31+H31,I31) -> 52.659
A32: =Zones!B32 -> GuestRoom_2_5_FloorT | B32: =Zones!K32 -> 4.21272 | C32: =Zones!H32 -> 1404.24 | D32: =5*10/3 -> 16.666667 | E32: 0.06 | F32: 20/50 cfm/unit per shower head | G32: =B32*D32 -> 70.212 | H32: =C32*E32 -> 84.2544 | I32: =50*B32 -> 210.636 | J32: =MAX(G32+H32,I32) -> 210.636
A33: =Zones!B33 -> GuestRoom_6_8_FloorT | B33: =Zones!K33 -> 3.4026 | C33: =Zones!H33 -> 1134.2 | D33: =5*10/3 -> 16.666667 | E33: 0.06 | F33: 20/50 cfm/unit per shower head | G33: =B33*D33 -> 56.71 | H33: =C33*E33 -> 68.052 | I33: =50*B33 -> 170.13 | J33: =MAX(G33+H33,I33) -> 170.13
... A40: =Zones!B40 -> GuestRoom_24_FloorT | B40: =Zones!K40 -> 1.05309 | C40: =Zones!H40 -> 351.03 | D40: =5*10/3 -> 16.666667 | E40: 0.06 | F40: 20/50 cfm/unit per shower head | G40: =B40*D40 -> 17.5515 | H40: =C40*E40 -> 21.0618 | I40: =50*B40 -> 52.6545 | J40: =MAX(G40+H40,I40) -> 52.6545
A41: =Zones!B41 -> Laundry_FloorG | B41: =Zones!K41 -> 5.26555 | C41: =Zones!H41 -> 1053.11 | D41: 15 | E41: 0.15 | F41: 1 cfm/ft2 for Soiled laundry storage rooms | G41: =B41*D41 -> 78.98325 | H41: =C41*E41 -> 157.9665 | I41: =1*0.2*C41 -> 210.622 | J41: =MAX(G41:I41) -> 210.622 | K41: Only 20% of the laundry space is assumed as "Solied laundry storage room"
A42: =Zones!B42 -> Mech_FloorG | B42: =Zones!K42 -> 0 | C42: =Zones!H42 -> 351.06 | D42: 15 | E42: 0.15 | G42: =B42*D42 -> 0 | H42: =C42*E42 -> 52.659 | J42: =MAX(G42:I42) -> 52.659
A43: =Zones!B43 -> Conference_FloorG | B43: =Zones!K43 -> 28.51695 | C43: =Zones!H43 -> 864.15 | D43: 15 | E43: 0.15 | G43: =B43*D43 -> 427.75425 | H43: =C43*E43 -> 129.6225 | J43: =MAX(G43:I43) -> 427.75425
A44: =Zones!B44 -> Rear_Stair_FloorG | B44: =Zones!K44 -> 1.0804 | C44: =Zones!H44 -> 216.08 | D44: 15 | E44: 0.15 | G44: =B44*D44 -> 16.206 | H44: =C44*E44 -> 32.412 | J44: =MAX(G44:I44) -> 32.412
A45: =Zones!B45 -> Rear_Stair_FloorT | B45: =Zones!K45 -> 1.0804 | C45: =Zones!H45 -> 216.08 | D45: 15 | E45: 0.15 | G45: =B45*D45 -> 16.206 | H45: =C45*E45 -> 32.412 | J45: =MAX(G45:I45) -> 32.412
A46: =Zones!B46 -> Rear_Stair_FloorM | B46: =Zones!K46 -> 1.0804 | C46: =Zones!H46 -> 216.08 | D46: 15 | E46: 0.15 | G46: =B46*D46 -> 16.206 | H46: =C46*E46 -> 32.412 | J46: =MAX(G46:I46) -> 32.412
...

Sheet Thermostat
A1: Thermostat Setpoints - HotelSmall
A2: Setpoint | B2: CZ1 | C2: CZ2 | D2: CZ3 | E2: CZ4 | F2: CZ5 | G2: CZ6 | H2: CZ7 | I2: CZ8 | J2: CZ9 | K2: CZ10 | L2: CZ11 | M2: CZ12 | N2: CZ13 | O2: CZ14 | P2: CZ15 | Q2: CZ16 | R2: Source
A3: Assembly and Office Heating Setpoint (F) | B3: 70 | C3: 70 | D3: 70 | E3: 70 | F3: 70 | G3: 70 | H3: 70 | I3: 70 | J3: 70 | K3: 70 | L3: 70 | M3: 70 | N3: 70 | O3: 70 | P3: 70 | Q3: 70 | R3: T24 2022 - Appendix 5.4B, [Assembly]
A4: Assembly and Office Heating Setback (F) | B4: 60 | C4: 60 | D4: 60 | E4: 60 | F4: 60 | G4: 60 | H4: 60 | I4: 60 | J4: 60 | K4: 60 | L4: 60 | M4: 60 | N4: 60 | O4: 60 | P4: 60 | Q4: 60
A5: Assembly and Office Cooling Setpoint (F) | B5: 75 | C5: 75 | D5: 75 | E5: 75 | F5: 75 | G5: 75 | H5: 75 | I5: 75 | J5: 75 | K5: 75 | L5: 75 | M5: 75 | N5: 75 | O5: 75 | P5: 75 | Q5: 75
A6: Assembly and Office Cooling Setback (F) | B6: 85 | C6: 85 | D6: 85 | E6: 85 | F6: 85 | G6: 85 | H6: 85 | I6: 85 | J6: 85 | K6: 85 | L6: 85 | M6: 85 | N6: 85 | O6: 85 | P6: 85 | Q6: 85
A7: ResidentialCommon Heating Setpoint (F) | B7: 68 | C7: 68 | D7: 68 | E7: 68 | F7: 68 | G7: 68 | H7: 68 | I7: 68 | J7: 68 | K7: 68 | L7: 68 | M7: 68 | N7: 68 | O7: 68 | P7: 68 | Q7: 68 | R7: T24 2022 - Appendix 5.4B, [ResidentialCommon]
A8: ResidentialCommon Heating Setback (F) | B8: 68 | C8: 68 | D8: 68 | E8: 68 | F8: 68 | G8: 68 | H8: 68 | I8: 68 | J8: 68 | K8: 68 | L8: 68 | M8: 68 | N8: 68 | O8: 68 | P8: 68 | Q8: 68
A9: ResidentialCommon Cooling Setpoint (F) | B9: 78 | C9: 78 | D9: 78 | E9: 78 | F9: 78 | G9: 78 | H9: 78 | I9: 78 | J9: 78 | K9: 78 | L9: 78 | M9: 78 | N9: 78 | O9: 78 | P9: 78 | Q9: 78
A10: ResidentialCommon Cooling Setback (F) | B10: 78 | C10: 78 | D10: 78 | E10: 78 | F10: 78 | G10: 78 | H10: 78 | I10: 78 | J10: 78 | K10: 78 | L10: 78 | M10: 78 | N10: 78 | O10: 78 | P10: 78 | Q10: 78
A11: ResidentialLiving Heating Setpoint (F) | B11: 70 | C11: 70 | D11: 70 | E11: 70 | F11: 70 | G11: 70 | H11: 70 | I11: 70 | J11: 70 | K11: 70 | L11: 70 | M11: 70 | N11: 70 | O11: 70 | P11: 70 | Q11: 70
A12: ResidentialLiving Heating Setback (F) | B12: 70 | C12: 70 | D12: 70 | E12: 70 | F12: 70 | G12: 70 | H12: 70 | I12: 70 | J12: 70 | K12: 70 | L12: 70 | M12: 70 | N12: 70 | O12: 70 | P12: 70 | Q12: 70
A13: ResidentialLiving Cooling Setpoint (F) | B13: 72 | C13: 72 | D13: 72 | E13: 72 | F13: 72 | G13: 72 | H13: 72 | I13: 72 | J13: 72 | K13: 72 | L13: 72 | M13: 72 | N13: 72 | O13: 72 | P13: 72 | Q13: 72 | R13: Honeywell-INNCOM e7 Thermostat User Guide
A14: ResidentialLiving Cooling Setback (F) | B14: 72 | C14: 72 | D14: 72 | E14: 72 | F14: 72 | G14: 72 | H14: 72 | I14: 72 | J14: 72 | K14: 72 | L14: 72 | M14: 72 | N14: 72 | O14: 72 | P14: 72 | Q14: 72 | R14: & Engineering Judgment
A15: Ancillary Heating Setpoint (F) | B15: 60 | C15: 60 | D15: 60 | E15: 60 | F15: 60 | G15: 60 | H15: 60 | I15: 60 | J15: 60 | K15: 60 | L15: 60 | M15: 60 | N15: 60 | O15: 60 | P15: 60 | Q15: 60 | R15: Based on engineering judgment (semi‑conditioned space)
A16: Ancillary Heating Setback (F) | B16: 60 | C16: 60 | D16: 60 | E16: 60 | F16: 60 | G16: 60 | H16: 60 | I16: 60 | J16: 60 | K16: 60 | L16: 60 | M16: 60 | N16: 60 | O16: 60 | P16: 60 | Q16: 60
A17: Ancillary Cooling Setpoint (F) | B17: 85 | C17: 85 | D17: 85 | E17: 85 | F17: 85 | G17: 85 | H17: 85 | I17: 85 | J17: 85 | K17: 85 | L17: 85 | M17: 85 | N17: 85 | O17: 85 | P17: 85 | Q17: 85
A18: Ancillary Cooling Setback (F) | B18: 85 | C18: 85 | D18: 85 | E18: 85 | F18: 85 | G18: 85 | H18: 85 | I18: 85 | J18: 85 | K18: 85 | L18: 85 | M18: 85 | N18: 85 | O18: 85 | P18: 85 | Q18: 85
A21: PNNL had 70F for both cooling and heating setpoint without setback.
A22: 72F is the default setting for one of the most prominent thermostats (Inncom) in California hotels.
A23: It has a limit by which a hotel guest can override the default setting. For instance: if the default cooling setpoint is 72, the coolest that a user can set the cooling setpoint is 72-5 = 67F.
A24: Ref: https://prod-edam.honeywell.com/content/dam/honeywell-edam/hbt/en-us/documents/manuals-and-guides/installation-guides/inncom/hbt-bms-INNCOM-e7-USER-GUIDE.pdf

Sheet Water Heater
A1: Water Heater - HotelSmall
A2: Vintage | B2: WH Type | C2: Efficiency | D2: Number of WH | E2: Tank Volume (gal) | F2: Tank Loss | G2: Source
A3: Existing | B3: Gas | C3: 0.8 | D3: 1 | E3: See table below for CZ-specific values: Climate Zone Water Heater Sizing and Loss Coefficients, Storage Volume column (col G) | F3: See table below: Climate Zone Water Heater Sizing and Loss Coefficients, Standby Loss column (col H) | G3: See table below for sources: Climate Zone Water Heater Sizing and Loss Coefficients
A4: New Construction | B4: Gas | C4: 0.8 | D4: 1 | E4: See table below for CZ-specific values: Climate Zone Water Heater Sizing and Loss Coefficients, Storage Volume column (col G) | F4: See table below: Climate Zone Water Heater Sizing and Loss Coefficients, Standby Loss column (col H) | G4: See table below for sources: Climate Zone Water Heater Sizing and Loss Coefficients
A6: Peak Hot Water Consumption
A7: Space Name | B7: Baseline WH Type [CEUS 2022] | C7: Total Area (ft²) | D7: Number of People | E7: Hot Water Usage Specification (gal/hr per person) [T24, 2022, Appendix 5.4A , sheet: "2022 SpaceFuncData-Input"] | F7: Peak Hot Water Usage (gal/hr) | G7: Peak Hot Water Usage (gal/min) | H7: Note
A8: =Zones!B3 -> Corridor_FloorG | B8: Gas | C8: =Zones!H3 -> 1782.21 | D8: =Zones!K3 -> 8.91105 | E8: 0 | F8: =E8*D8 -> 0 | G8: =F8/60 -> 0 | H8: For space types marked with an asterisk (the ‘*’ symbol), the water‑heater type is listed as electric in Appendix 5.4A, sheet ‘2022 SpaceFuncData‑Input.’ However, we modified the value based on CEUS data, which indicates that gas is the primary fuel type.
A9: =Zones!B4 -> Corridor_FloorM | B9: Gas | C9: =Zones!H4 -> 1512.16 | D9: =Zones!K4 -> 7.5608 | E9: 0 | F9: =E9*D9 -> 0 | G9: =F9/60 -> 0
A10: =Zones!B5 -> Corridor_FloorT | B10: Gas | C10: =Zones!H5 -> 1512.16 | D10: =Zones!K5 -> 7.5608 | E10: 0 | F10: =E10*D10 -> 0 | G10: =F10/60 -> 0
A11: =Zones!B6 -> Lounge_FloorG | B11: Gas | C11: =Zones!H6 -> 351.03 | D11: =Zones!K6 -> 11.58399 | E11: 0.09 | F11: =E11*D11 -> 1.0425591 | G11: =F11/60 -> 0.017375985
A12: =Zones!B7 -> Gym_FloorG | B12: Gas | C12: 351.03 | D12: 3.5103 | E12: 0.18 | F12: =E12*D12 -> 0.631854 | G12: =F12/60 -> 0.0105309
A13: =Zones!B8 -> Front_Lounge_FloorG | B13: Gas | C13: 1755.3 | D13: 57.9249 | E13: 0.09 | F13: =E13*D13 -> 5.213241 | G13: =F13/60 -> 0.08688735
A14: =Zones!B9 -> Front_Office_FloorG | B14: Gas | C14: 1404.14 | D14: 7.0207 | E14: 0.18 | F14: =E14*D14 -> 1.263726 | G14: =F14/60 -> 0.0210621
A15: =Zones!B10 -> Front_Stair_FloorG | B15: Gas | C15: =Zones!H10 -> 216.02 | D15: =Zones!K10 -> 0 | E15: 0 | F15: =E15*D15 -> 0 | G15: =F15/60 -> 0
A16: =Zones!B11 -> Front_Stair_FloorM | B16: Gas | C16: =Zones!H11 -> 216.02 | D16: =Zones!K11 -> 0 | E16: 0 | F16: =E16*D16 -> 0 | G16: =F16/60 -> 0
A17: =Zones!B12 -> Front_Stair_FloorT | B17: Gas | C17: =Zones!H12 -> 216.02 | D17: =Zones!K12 -> 0 | E17: 0 | F17: =E17*D17 -> 0 | G17: =F17/60 -> 0
A18: =Zones!B13 -> Front_Storage_FloorG | B18: Gas | C18: =Zones!H13 -> 135.01 | D18: =Zones!K13 -> 0.27002 | E18: 0 | F18: =E18*D18 -> 0 | G18: =F18/60 -> 0
A19: =Zones!B14 -> Front_Storage_FloorM | B19: Gas | C19: =Zones!H14 -> 135.01 | D19: =Zones!K14 -> 0.27002 | E19: 0 | F19: =E19*D19 -> 0 | G19: =F19/60 -> 0
A20: =Zones!B15 -> Front_Storage_FloorT | B20: Gas | C20: =Zones!H15 -> 135.01 | D20: =Zones!K15 -> 0.27002 | E20: 0 | F20: =E20*D20 -> 0 | G20: =F20/60 -> 0
A21: =Zones!B16 -> GuestRoom_1_FloorG | B21: Gas | C21: 351.06 | D21: 1.05318 | E21: 4.48 | F21: =E21*D21 -> 4.7182464 | G21: =F21/60 -> 0.07863744
A22: =Zones!B17 -> GuestRoom_2_FloorG | B22: Gas | C22: 351.06 | D22: 1.05318 | E22: 4.48 | F22: =E22*D22 -> 4.7182464 | G22: =F22/60 -> 0.07863744
A23: =Zones!B18 -> GuestRoom_3_FloorG | B23: Gas | C23: 351.06 | D23: 1.05318 | E23: 4.48 | F23: =E23*D23 -> 4.7182464 | G23: =F23/60 -> 0.07863744
A24: =Zones!B19 -> GuestRoom_4_FloorG | B24: Gas | C24: 351.03 | D24: 1.05309 | E24: 4.48 | F24: =E24*D24 -> 4.7178432 | G24: =F24/60 -> 0.07863072
A25: =Zones!B20 -> GuestRoom_5_FloorG | B25: Gas | C25: 351.03 | D25: 1.05309 | E25: 4.48 | F25: =E25*D25 -> 4.7178432 | G25: =F25/60 -> 0.07863072
A26: =Zones!B21 -> GuestRoom_1_FloorM | B26: Gas | C26: 351.06 | D26: 1.05318 | E26: 4.48 | F26: =E26*D26 -> 4.7182464 | G26: =F26/60 -> 0.07863744
A27: =Zones!B22 -> GuestRoom_2_5_FloorM | B27: Gas | C27: 1404.24 | D27: 4.21272 | E27: 4.48 | F27: =E27*D27 -> 18.872986 | G27: =F27/60 -> 0.31454976
A28: =Zones!B23 -> GuestRoom_6_8_FloorM | B28: Gas | C28: 1134.2 | D28: 3.4026 | E28: 4.48 | F28: =E28*D28 -> 15.243648 | G28: =F28/60 -> 0.2540608
A29: =Zones!B24 -> GuestRoom_9_12_FloorM | B29: Gas | C29: 1404.24 | D29: 4.21272 | E29: 4.48 | F29: =E29*D29 -> 18.872986 | G29: =F29/60 -> 0.31454976
A30: =Zones!B25 -> GuestRoom_13_FloorM | B30: Gas | C30: 351.06 | D30: 1.05318 | E30: 4.48 | F30: =E30*D30 -> 4.7182464 | G30: =F30/60 -> 0.07863744
A31: =Zones!B26 -> GuestRoom_14_FloorM | B31: Gas | C31: 351.03 | D31: 1.05309 | E31: 4.48 | F31: =E31*D31 -> 4.7178432 | G31: =F31/60 -> 0.07863072
A32: =Zones!B27 -> GuestRoom_15_18_FloorM | B32: Gas | C32: 1404.14 | D32: 4.21242 | E32: 4.48 | F32: =E32*D32 -> 18.871642 | G32: =F32/60 -> 0.31452736
... A46: =Zones!B41 -> Laundry_FloorG | B46: Gas | C46: 1053.11 | D46: 5.26555 | E46: 0.578 | F46: =E46*D46 -> 3.0434879 | G46: =F46/60 -> 0.050724798
A47: =Zones!B42 -> Mech_FloorG | B47: Gas | C47: =Zones!H42 -> 351.06 | D47: =Zones!K42 -> 0 | E47: 0.18 | F47: =E47*D47 -> 0 | G47: =F47/60 -> 0
A48: =Zones!B43 -> Conference_FloorG | B48: Gas | C48: 864.15 | D48: 28.51695 | E48: 0.09 | F48: =E48*D48 -> 2.5665255 | G48: =F48/60 -> 0.042775425
A49: =Zones!B44 -> Rear_Stair_FloorG | B49: Gas | C49: =Zones!H44 -> 216.08 | D49: =Zones!K44 -> 1.0804 | E49: 0 | F49: =E49*D49 -> 0 | G49: =F49/60 -> 0
A50: =Zones!B45 -> Rear_Stair_FloorT | B50: Gas | C50: =Zones!H45 -> 216.08 | D50: =Zones!K45 -> 1.0804 | E50: 0 | F50: =E50*D50 -> 0 | G50: =F50/60 -> 0
A51: =Zones!B46 -> Rear_Stair_FloorM | B51: Gas | C51: =Zones!H46 -> 216.08 | D51: =Zones!K46 -> 1.0804 | E51: 0 | F51: =E51*D51 -> 0 | G51: =F51/60 -> 0
A52: =Zones!B47 -> Rear_Storage_FloorG | B52: Gas | C52: =Zones!H47 -> 216.09 | D52: =Zones!K47 -> 0.43218 | E52: 0 | F52: =E52*D52 -> 0 | G52: =F52/60 -> 0
A53: =Zones!B48 -> Rear_Storage_FloorM | B53: Gas | C53: =Zones!H48 -> 216.09 | D53: =Zones!K48 -> 0.43218 | E53: 0 | F53: =E53*D53 -> 0 | G53: =F53/60 -> 0
A54: =Zones!B49 -> Rear_Storage_FloorT | B54: Gas | C54: =Zones!H49 -> 216.09 | D54: =Zones!K49 -> 0.43218 | E54: 0 | F54: =E54*D54 -> 0 | G54: =F54/60 -> 0
...

Sheet Interior Lights
A1: Interior Lighting - HotelSmall
A2: Space Type | B2: New Construction | E2: Existing | H2: Note
B3: LPD (W/ft²) | C3: Additional LPD for Portable Lighting (W/ft²) | D3: Source | E3: LPD (W/ft²) | F3: Additional LPD for Portable Lighting (W/ft²) | G3: Source
A4: Corridor Area | B4: 0.4 | D4: T24, 2025, Table 140.6-C PNNL ASHRAE 90.1 2022 for Guest Room, same as ASHRAE 90.1 2025 (Area category method) | E4: 0.6 | G4: T24, 2019*, Table 140.6-C (Area category method) Guest rooms: ASHRAE 90.1 2016, Table 9.6.1 (It's been assumed that guest rooms have a longer lighting replacement cycle compared to other space types)
A5: Lounge, Breakroom, or Waiting Area | B5: 0.55 | C5: =0.25*0.5 -> 0.125 | E5: 0.85 | F5: 0.25
A6: Exercise/Fitness Center and Gymnasium Areas | B6: 0.5 | E6: 0.5
A7: Office Area (>250 square feet) | B7: 0.6 | C7: 0.1 | E7: 0.7
A8: Stairwell | B8: 0.6 | E8: 0.5
A9: Storage (General) | B9: 0.4 | E9: 0.4
A10: Hotel/Motel Guest Room | B10: 0.41 | E10: 0.77
A11: Laundry Area | B11: 0.45 | E11: 0.45
A12: Electrical, Mechanical, Telephone Rooms | B12: 0.4 | E12: 0.4
A13: Convention, Conference, Multipurpose and Meeting Area | B13: 0.75 | C13: =0.25*0.5 -> 0.125 | E13: 0.85 | F13: 0.25
A14: Restrooms | B14: 0.65 | E14: 0.65
A16: Comply with 130.1(c)8: Hotel/motel guest rooms shall be controlled with one of the following controls such that, no longer than 20 minutes after the guest room has been vacated, lighting power is switched off: i. Captive card key controls; or ii. Occupant sensing controls; or iii. Other automatic controls.
A22: Background Data [To be deleted prior to publication]

Sheet Ext Lighting
A1: Exterior Lighting - HotelSmall
A2: Motion Controlled Luminaires (W) | B2: Non-motion Controlled Luminaires (W) | C2: Total (W) | D2: Source
A3: =G16 -> 979.85732 | B3: =G17 -> 742.68323 | C3: =A3+B3 -> 1722.5405 | D3: T24, 2025
A8: Exterior Lighting
A9: Items (Assume LZ2) | B9: Assumptions [2019 Outdoor Lighting CASE Report & PNNL 90.1-2010 TSD] | D9: Unit | E9: Lighting Power Allowance [T24, 2025, Table 140.7-A & 140.7-B] | F9: Unit | G9: Exterior Lighting Power (W)
A10: IWA (Initial Wage Allowance) | E10: 200 | F10: (W) | G10: =$E10 -> 200
