Workbook
Name nonparticipating_forecastzone_scale_factor: 'Energy Usage'!#REF!
Name Space_Function: Data!$A$2:$A$76

Sheet Notes
A1: Data Sources
A2: Dataset | B2: Dodge 2023
B3: Commercial End-Use Survey (CEUS) 2022 | C3: https://www.energy.ca.gov/publications/2023/2022-california-commercial-end-use-survey-ceus-final-report
B4: Commercial Buildings Energy Consumption Survey (CBECS) 2018 | C4: https://www.eia.gov/consumption/commercial/data/2018/index.php?view=microdata
B5: Comstock 2023 | C5: https://data.openei.org/s3_viewer?bucket=oedi-data-lake&prefix=nrel-pds-building-stock%2Fend-use-load-profiles-for-us-building-stock%2F2023%2Fcomstock_amy2018_release_2%2Fmetadata_and_annual_results%2Fby_state%2Fstate%3DCA%2F
A6: Prototype | B6: California Energy Commission (CEC) Medium Office prototype (CBECC 2022.3.1) | C6: https://bees.noresco.com/software2022.html
B7: Pacific Northwest National Laboratory (PNNL) Medium Office prototype (90.1-2022) | C7: https://www.energycodes.gov/prototype-building-models#Commercial
B8: Database for Energy Efficient Resources (DEER) Large Office prototype (June 2023) | C8: https://github.com/sound-data/DEER-Prototypes-EnergyPlus
B9: Oak Ridge National Laboratory (ORNL) 2019 Medium Office prototype zoning | C9: https://web.eecs.utk.edu/~jnew1/publications/2019_IBPSA_OpenStudioOffice.pdf
A10: Codes | B10: Title 24, part 6, referred to as T24 (1984, 1992,1998, 2001, 2005, 2008, 2013, 2016,2019, 2022, 2025) | C10: https://www.energy.ca.gov/publications/2025/2025-building-energy-efficiency-standards-residential-and-nonresidential | D10: 2025
C11: https://codes.iccsafe.org/codes/united-states/california | D11: 2010+
B12: Title 20 | C12: https://govt.westlaw.com/calregs/Document/I270DCA634B4011EFA8F7F119BAF97AD6?viewType=FullText&originationContext=documenttoc&transitionType=CategoryPageItem&contextData=(sc.Default)
B13: American Society of Heating, Refrigerating and Air-Conditioning Engineers (ASHRAE) 90.1 (2022) | C13: https://www.ashrae.org/technical-resources/standards-and-guidelines/read-only-versions-of-ashrae-standards
B14: Code of Federal Regulations (CFR) Title 10 ( 2024) | C14: https://www.govinfo.gov/content/pkg/CFR-2024-title10-vol3/pdf/CFR-2024-title10-vol3-part431-subpartF.pdf
B15: Alternative Calculation Method (ACM) (2022) | C15: https://www.energy.ca.gov/publications/2022/2022-nonresidential-and-multifamily-alternative-calculation-method-reference
B16: ACM (2025) | C16: https://www.energy.ca.gov/publications/2025/2025-nonresidential-and-multifamily-alternative-calculation-method-reference
B17: Nonres ACM 2022, Appendix 5.4A and Appendix 5.4B | C17: https://www.energy.ca.gov/publications/2022/2022-nonresidential-and-multifamily-alternative-calculation-method-reference
B18: 2022 Reduced infiltration Codes and Standards Enhancement (CASE) report | C18: https://title24stakeholders.com/wp-content/uploads/2020/10/2022-T24-Final-CASE-Report_Reduce-Infiltration.pdf
B19: 2019 Outdoor Lighting CASE Report | C19: https://title24stakeholders.com/wp-content/uploads/2016/10/T24-2019-CASE-Study-Results-Report-Outdoor-Sources_Final_with-Attachments.pdf
B20: PNNL 20405, 2011 | C20: https://www.pnnl.gov/main/publications/external/technical_reports/PNNL-20405.pdf
B21: Air leakage Memo, NORESCO, 2025 | C21: Infiltration_rate_report_14May2025-Short-Version.docx
B22: Yousefi, F., Athalye, R., (2025), "Determining Vintage Bins for Prototype Development: An Analysis of California Commercial Buildings," ASHRAE Annual Conference | C22: https://www.thefreelibrary.com/Determining+Vintage+Bins+for+Prototype+Development%3a+An+Analysis+of...-a0879271125
B23: Proposed Updates to Equipment Power Densities and Building Schedules for the 2028 Energy Code, referred to as "Plug load and schedules project with CEC, 2025" (Docket Number =25-BSTD-03 & TN=265693) | C23: https://efiling.energy.ca.gov/GetDocument.aspx?tn=265693&DocumentContentId=102545
... B27: Grainger electric tank water heaters | C27: https://www.grainger.com/category/plumbing/water-heaters/electric-tank-water-heaters
A31: Construction Rate
F35: 1978-84 | G35: 1985-97 | H35: 1992-1997
E37: Construction rate (Dodge 2023 data for new medium offices) | F37: 0.46189629 | G37: 0.53810371 | H37: 0.12391054
B41: Source:Dodge Construction Data, 2023 ( NEW medium office built after 1967) (STC refers to building types in Dodge terminology).
A42: Notes
A43: OfficeMedium Prototype | B43: The Medium Office prototype was developed to represent California office buildings between 25,000 and 150,000 ft². Based on California construction data, the existing CEC/PNNL Medium Office geometry was retained because it aligned well with observed building stock characteristics. The prototype is modeled as a three-story building with a total floor area of 53,628 ft². Its zoning layout was updated using ORNL-based layouts, with modifications to better reflect current design practice and simplify the model. These changes included consolidating spaces, reducing the total number of thermal zones, and incorporating elevator space into the vertical circulation area. The resulting Medium Office prototype includes approximately 61.8% office space, 6.2% conference space, 5.5% storage, 9% corridor, 5.9% lobby, 3.6% restroom, 3.7% stair/elevator area, and for other 4.3% (server room, mechanical room, breakroom). The same geometry and zoning layout are applied across vintages and California climate zones. Information about the geometry and underlying logic of the office prototypes can be found in this paper: Yousefi, F., Athalye, R. (2026). ‘Developing a New Set of Prototypical Models for Office Buildings in California.’ IBPSA-USA Conference. The link is provided above in the Data Source section. The floor area was slightly modified in some spaces during the geometry‑drawing phase.
A44: 1986 is the representative year for the 1984-1997 vintage bin | B44: Most medium offices in this vintage bin were built after 1984 (more than 54% ) and the CA energy code did not noticeably changed between 1984 to 1992) . Edition 1986 included 6 prescriptive packages per CZ for office buildings compared to 1984 with 3 packages per CZ. Also "Heat Capacity" for external wall is considered between 10.0 to 14.99 (BTU/F/ft2) Package A was selected for the thermal properties Medium office was considered as low rise office
A45: 2001 is the representative year for the 1998-2007 vintage bin | B45: Wall and roof prescriptive criteria from 1998 to 2005 remain unchanged except for CZ2 and 6 in 2001 version (the percentage of change is less than 10%). Since the construction rate between 1998-2005 is greater than the 2006-2007 period, the envelope properties of 1998 -2005 were chosen for envelope properties. The windows requirement considerably changed in the 2001 code and makes this year (2001) as the nominated year for this vintage. It should be noticed that, only one Title 24 should be chosen within each vintage bin for building envelope properties since the entire envelope is built at once. We can't choose 1998 for walls and 2001 for windows. Wall and roof prescriptive criteria from 1998 to 2005 remain unchanged except for CZ2 and 6 in 2001 version (the percentage of change is less than 10%).
A46: 2013 is the representative year for the 2008-2018 vintage bin | B46: Wall properties remain unchanged from the 2008 code to the 2016 code but the roof did changed. Although the 2016 code introduced improvement for roof in nearly all CZ and for wall in a few CZ, and construction activity surged between 2017 and 2018, the extende period from 2008 to 2016 resulted in a higher construction rate during that time . As a result, it was decided to select the code that was effective during 2008-2016. The 2013 code modified the solar reflectance requirement for low-sloped roof products ( by approximately 15%), and enhanced window properties. Therefore, the 2013 code was chosen as the representative code. Additionally, construction activity from 2014-2018 was higher compared to 2008-2013 period.

Sheet Prototype
A1: NORESCO, Updated September 2026
A2: OfficeMedium
A3: Characteristic | B3: Value | C3: Data Sources
A4: Building Type | B4: Medium Office
A5: Building Category | B5: Nonresidential
A6: Version | B6: v2-0
A7: Vintages | B7: 4 Vintages: Pre-1978 , 1978-1997 ,1998-2007 , 2008-2018 New Construction (2019+) | C7: Based on the vintage bin analysis. A summary of the findings is presented in the following paper, with a link provided in the Notes tab: Yousefi, F., Athalye, R. (2025). “Determining Vintage Bins for Prototype Development: An Analysis of California Commercial Buildings.” ASHRAE Annual Conference.
A8: Shape | C8: Assume rectangular shape; supported by CBECS, CEC, and PNNL. The windows have been updated from ribbon style to punched openings. The logic behind the geometry of the CalBEM Office prototypes' shell is described in the following paper, with a link provided in the Notes tab: Yousefi, F., & Athalye, R. (2026). "Developing a New Set of Prototypical Models for Office Buildings in California", IBPSA-USA Conference.
A9: Total Floor Area (ft2) | B9: 53,628 (163.7 ft x 109.2 ft) | C9: Supported by Dodge 2023 data (Same as CEC and PNNL)
A10: Aspect Ratio | B10: 1.5 | C10: Assumption; same as CEC and PNNL Medium Office prototype
A11: Number of Floors | B11: 3 | C11: Supported by Dodge 2023 data (Same as CEC and PNNL) DEER doesn't offer medium office prototype
A12: Roof type | B12: Flat | C12: Supported by CBECS 2018 data (Same as CEC and PNNL)
A13: Window dimensions | B13: 33% | C13: Assumed based on CBECS data; same as CEC and PNNL Medium Office prototype. CBECS: 26-50% Comstock: 26% CEC prototype: 33% same as PNNL DEER: 33% for Large Office prototype | D13: 3 ft from ground, 6*3 feet, 1 ft from ceiling, 2ft from each other.
A14: Shading Geometry | B14: No Shades | C14: Assumption; same as CEC and PNNL Medium Office prototype
A15: Floor to floor height (feet) | B15: 13 | C15: Assumption, standard ceiling height in office buildings; same as CEC and PNNL Medium Office prototype.
A16: Floor to ceiling height (feet) | B16: 9 (4 ft above-ceiling plenum) | C16: Assumption; same as CEC and PNNL Medium Office prototype
A17: Glazing sill height (feet) | B17: 3.35 ft (top of the window is 7.64 ft high with 4.29 ft high glass) | C17: Assumption; same as CEC and PNNL Medium Office prototype

Sheet Zones
A1: Proposed OfficeMedium | Q1: Layout of Spcase (each space has its own thermal zone)
A2: Building | B2: Space/Thermal Zone | C2: Space Type Primarily from [T24, 2022 Appendix 5.4A] - See Notes column | D2: HVAC System Name Vintage 1&2 | E2: HVAC System Name Vintage 3&4 | F2: HVAC System Name New Construction | G2: Schedule Category | H2: Conditioned (Y/N) | I2: Area Fraction | J2: Area (ft²) | K2: Volume (ft³) | L2: Multipliers | M2: Number of People | N2: People (Persons/1,000 ft²) [T24, 2025,Table 120.1-A] | O2: Notes
A3: OfficeMedium | B3: Open_Office_Core_FloorG | C3: Office Area (>250 square feet) | D3: CAV with Reheat_Core | E3: PVAV_FloorG | F3: VRF System_FloorG + DOAS | G3: Office | H3: Yes | I3: =J3/$J$57 -> 0.079864791 | J3: 4283 | K3: =J3*9 -> 38547 | L3: 1 | M3: =IFERROR(N3*J3/1000,0) -> 21.415 | N3: 5
A4: OfficeMedium | B4: Open_Office_N_FloorG | C4: Office Area (>250 square feet) | D4: CAV with Reheat_North | E4: PVAV_FloorG | F4: VRF System_FloorG + DOAS | G4: Office | H4: Yes | I4: =J4/$J$57 -> 0.042850403 | J4: 2297.9873 | K4: =J4*9 -> 20681.886 | L4: 1 | M4: =IFERROR(N4*J4/1000,0) -> 11.489937 | N4: 5
A5: OfficeMedium | B5: Enclosed_Office_W_FloorG | C5: Office Area (>250 square feet) | D5: CAV with Reheat_West | E5: PVAV_FloorG | F5: VRF System_FloorG + DOAS | G5: Office | H5: Yes | I5: =J5/$J$57 -> 0.030541079 | J5: 1637.8612 | K5: =J5*9 -> 14740.75 | L5: 1 | M5: =IFERROR(N5*J5/1000,0) -> 8.1893058 | N5: 5
A6: OfficeMedium | B6: Enclosed_Office_E_FloorG | C6: Office Area (>250 square feet) | D6: CAV with Reheat_East | E6: PVAV_FloorG | F6: VRF System_FloorG + DOAS | G6: Office | H6: Yes | I6: =J6/$J$57 -> 0.030541079 | J6: 1637.8612 | K6: =J6*9 -> 14740.75 | L6: 1 | M6: =IFERROR(N6*J6/1000,0) -> 8.1893058 | N6: 5
A7: OfficeMedium | B7: Open_Office_S_FloorG | C7: Office Area (>250 square feet) | D7: CAV with Reheat_South | E7: PVAV_FloorG | F7: VRF System_FloorG + DOAS | G7: Office | H7: Yes | I7: =J7/$J$57 -> 0.022119126 | J7: 1186.2075 | K7: =J7*9 -> 10675.868 | L7: 1 | M7: =IFERROR(N7*J7/1000,0) -> 5.9310376 | N7: 5
A8: OfficeMedium | B8: Conference_FloorG | C8: Convention, Conference, Multipurpose and Meeting Area | D8: CAV with Reheat_South | E8: PVAV_FloorG | F8: VRF System_FloorG + DOAS | G8: Office | H8: Yes | I8: =J8/$J$57 -> 0.020731278 | J8: 1111.7798 | K8: =J8*9 -> 10006.018 | L8: 1 | M8: =IFERROR(N8*J8/1000,0) -> 36.688734 | N8: 33 | O8: Persons/1,000 ft²: ORNL: 54, T24:33
A9: OfficeMedium | B9: Lobby_FloorG | C9: Lobby, Main Entry | D9: CAV with Reheat_Core_Service | E9: PVAV_FloorG | F9: VRF System_FloorG + DOAS | G9: Office | H9: Yes | I9: =J9/$J$57 -> 0.019750368 | J9: 1059.1755 | K9: =J9*9 -> 9532.5792 | L9: 1 | M9: =IFERROR(N9*J9/1000,0) -> 10.591755 | N9: 10 | O9: For entrance lobbies, assumed 10 persons/1000 ft² based on ASHRAE 62.1 Table 6-1 T24 assumed 33 persons/1,000 ft² for main Entry lobbies & 5 persons/1000 ft² for reception area
A10: OfficeMedium | B10: Storage_FloorG | C10: Storage (General) | D10: CAV with Reheat_Core_Service | E10: PVAV_FloorG | F10: VRF System_FloorG + DOAS | G10: Office | H10: Yes | I10: =J10/$J$57 -> 0.018332841 | J10: 983.15611 | K10: =J10*9 -> 8848.405 | L10: 1 | M10: =IFERROR(N10*J10/1000,0) -> 0 | N10: - | O10: Occupant load density for storage is based on T24, 2025, Appendix 5.4A. Conditioned but with higher cooling setpoint
A11: OfficeMedium | B11: Mechanical/Electrical_FloorG | C11: Electrical, Mechanical, Telephone Rooms | D11: CAV with Reheat_Core_Service | E11: PVAV_FloorG | F11: VRF System_FloorG + DOAS | G11: Ancillary | H11: Yes | I11: =J11/$J$57 -> 0.006663486 | J11: 357.35034 | K11: =J11*9 -> 3216.1531 | L11: 1 | M11: =IFERROR(N11*J11/1000,0) -> 0 | N11: - | O11: Conditioned but with higher cooling setpoint
A12: OfficeMedium | B12: IT-Room_FloorG | C12: IT Room (EPD 12) | D12: CAV with Reheat_Core_Service | E12: PVAV_FloorG | F12: VRF System_FloorG + DOAS | G12: Data | H12: Yes | I12: =J12/$J$57 -> 0.0033366309 | J12: 178.9373 | K12: =J12*9 -> 1610.4357 | L12: 1 | M12: =IFERROR(N12*J12/1000,0) -> 0.26840595 | N12: 1.5 | O12: Nonres ACM 2025, Appendix 5.4A
A13: OfficeMedium | B13: Restroom_FloorG | C13: Restrooms | G13: Office | H13: Yes | I13: =J13/$J$57 -> 0.012000749 | J13: 643.57783 | K13: =J13*9 -> 5792.2004 | L13: 1 | M13: =IFERROR(N13*J13/1000,0) -> 0 | N13: - | O13: Indirectly conditioned
A14: OfficeMedium | B14: BreakRoom/Kitchenette_FloorG | C14: Lounge, Breakroom, or Waiting Area | D14: CAV with Reheat_Core_Service | E14: PVAV_FloorG | F14: VRF System_FloorG + DOAS | G14: Office | H14: Yes | I14: =J14/$J$57 -> 0.0043324823 | J14: 232.34295 | K14: =J14*9 -> 2091.0866 | L14: 1 | M14: =IFERROR(N14*J14/1000,0) -> 7.6673175 | N14: 33 | O14: Number of People: T24: 33 for Breakroom
A15: OfficeMedium | B15: Stairway_FloorG | C15: Stairwell | D15: CAV with Reheat_Core_Service | E15: PVAV_FloorG | F15: VRF System_FloorG + DOAS | G15: Ancillary | H15: Yes | I15: =J15/$J$57 -> 0.012332934 | J15: 661.39226 | K15: =J15*9 -> 5952.5303 | L15: 1 | M15: =IFERROR(N15*J15/1000,0) -> 0 | N15: - | O15: Conditioned but with higher cooling setpoint
A16: OfficeMedium | B16: Corridor_W_FloorG | C16: Corridor Area | D16: CAV with Reheat_West | E16: PVAV_FloorG | F16: VRF System_FloorG + DOAS | G16: Office | H16: Yes | I16: =J16/$J$57 -> 0.0055940783 | J16: 300 | K16: =J16*9 -> 2700 | L16: 1 | M16: =IFERROR(N16*J16/1000,0) -> 1.5 | N16: 5 | R16: First Floor | W16: Second and Third Floor
A17: OfficeMedium | B17: Corridor_N_FloorG | C17: Corridor Area | D17: CAV with Reheat_North | E17: PVAV_FloorG | F17: VRF System_FloorG + DOAS | G17: Office | H17: Yes | I17: =J17/$J$57 -> 0.00937889 | J17: 502.9724 | K17: =J17*9 -> 4526.7516 | L17: 1 | M17: =IFERROR(N17*J17/1000,0) -> 2.514862 | N17: 5
A18: OfficeMedium | B18: Corridor_E_FloorG | C18: Corridor Area | D18: CAV with Reheat_East | E18: PVAV_FloorG | F18: VRF System_FloorG + DOAS | G18: Office | H18: Yes | I18: =J18/$J$57 -> 0.0055793025 | J18: 299.2076 | K18: =J18*9 -> 2692.8684 | L18: 1 | M18: =IFERROR(N18*J18/1000,0) -> 1.496038 | N18: 5
A19: OfficeMedium | B19: Corridor_S_FloorG | C19: Corridor Area | D19: CAV with Reheat_South | E19: PVAV_FloorG | F19: VRF System_FloorG + DOAS | G19: Office | H19: Yes | I19: =J19/$J$57 -> 0.00937889 | J19: 502.9724 | K19: =J19*9 -> 4526.7516 | L19: 1 | M19: =IFERROR(N19*J19/1000,0) -> 2.514862 | N19: 5 | R19: Area Distribution By Space Type
A20: OfficeMedium | B20: Plenum_FloorG | C20: Plenum | D20: - | E20: - | F20: - | G20: Office | H20: No | J20: 17875.932 | K20: =J20*4 -> 71503.73 | L20: 1 | M20: =IFERROR(N20*J20/1000,0) -> 0 | N20: - | R20: Space Type | S20: % Area
A21: OfficeMedium | B21: =LEFT(B3,LEN(B3)-1)&"M" -> Open_Office_Core_FloorM | C21: Office Area (>250 square feet) | D21: CAV with Reheat_Core | E21: PVAV_FloorM | F21: VRF System_FloorM + DOAS | G21: Office | H21: =H3 -> Yes | I21: =J21/$J$57 -> 0.079864791 | J21: 4283 | K21: =K3 -> 38547 | L21: =L3 -> 1 | M21: =IFERROR(N21*J21/1000,0) -> 21.415 | N21: =N3 -> 5 | R21: Office Area (>250 square feet) | S21: =SUM(I3:I7)+SUM(I21:I25)+SUM(I39:I43) -> 0.61774943
A22: OfficeMedium | B22: =LEFT(B4,LEN(B4)-1)&"M" -> Open_Office_N_FloorM | C22: Office Area (>250 square feet) | D22: CAV with Reheat_North | E22: PVAV_FloorM | F22: VRF System_FloorM + DOAS | G22: Office | H22: =H4 -> Yes | I22: =J22/$J$57 -> 0.042850403 | J22: 2297.9873 | K22: =K4 -> 20681.886 | L22: =L4 -> 1 | M22: =IFERROR(N22*J22/1000,0) -> 11.489937 | N22: =N4 -> 5 | R22: Convention, Conference, Multipurpose and Meeting Area | S22: =I8+I26+I44 -> 0.062193833
A23: OfficeMedium | B23: =LEFT(B5,LEN(B5)-1)&"M" -> Enclosed_Office_W_FloorM | C23: Office Area (>250 square feet) | D23: CAV with Reheat_West | E23: PVAV_FloorM | F23: VRF System_FloorM + DOAS | G23: Office | H23: =H5 -> Yes | I23: =J23/$J$57 -> 0.030541079 | J23: 1637.8612 | K23: =K5 -> 14740.75 | L23: =L5 -> 1 | M23: =IFERROR(N23*J23/1000,0) -> 8.1893058 | N23: =N5 -> 5 | R23: Lobby, Main Entry | S23: =I9+I27+I45 -> 0.059251105
A24: OfficeMedium | B24: Enclosed_Office_E_FloorM | C24: Office Area (>250 square feet) | D24: CAV with Reheat_East | E24: PVAV_FloorM | F24: VRF System_FloorM + DOAS | G24: Office | H24: =H6 -> Yes | I24: =J24/$J$57 -> 0.030541079 | J24: 1637.8612 | K24: =K6 -> 14740.75 | L24: =L6 -> 1 | M24: =IFERROR(N24*J24/1000,0) -> 8.1893058 | N24: =N6 -> 5 | R24: Storage (General) | S24: =I10+I46+I28 -> 0.054998523
A25: OfficeMedium | B25: =LEFT(B7,LEN(B7)-1)&"M" -> Open_Office_S_FloorM | C25: Office Area (>250 square feet) | D25: CAV with Reheat_South | E25: PVAV_FloorM | F25: VRF System_FloorM + DOAS | G25: Office | H25: =H7 -> Yes | I25: =J25/$J$57 -> 0.022119126 | J25: 1186.2075 | K25: =K7 -> 10675.868 | L25: =L7 -> 1 | M25: =IFERROR(N25*J25/1000,0) -> 5.9310376 | N25: =N7 -> 5 | R25: Electrical, Mechanical, Telephone Rooms | S25: =I11+I29+I47 -> 0.019990458
A26: OfficeMedium | B26: =LEFT(B8,LEN(B8)-1)&"M" -> Conference_FloorM | C26: Convention, Conference, Multipurpose and Meeting Area | D26: CAV with Reheat_South | E26: PVAV_FloorM | F26: VRF System_FloorM + DOAS | G26: Office | H26: =H8 -> Yes | I26: =J26/$J$57 -> 0.020731278 | J26: 1111.7798 | K26: =K8 -> 10006.018 | L26: =L8 -> 1 | M26: =IFERROR(N26*J26/1000,0) -> 36.688734 | N26: =N8 -> 33 | R26: IT Room (EPD 12) | S26: =I12+I30+I48 -> 0.010009893
A27: OfficeMedium | B27: Lounge_FloorM | C27: Lounge, Breakroom, or Waiting Area | D27: CAV with Reheat_Core_Service | E27: PVAV_FloorM | F27: VRF System_FloorM + DOAS | G27: Office | H27: =H9 -> Yes | I27: =J27/$J$57 -> 0.019750368 | J27: 1059.1755 | K27: =K9 -> 9532.5792 | L27: =L9 -> 1 | M27: =IFERROR(N27*J27/1000,0) -> 15.887632 | N27: 15 | O27: NonRes ACM 2005, Appendix 5.4A assigns 2.5 occupants to kitchenette spaces, but because this room serves as a combined break/kitchenette area—and break rooms assume 33 occupants—we applied a midpoint value. The lounge overlaps functionally with the break area, so its occupant count (33) was reduced to 15 to keep overall loads balanced. | R27: Restrooms | S27: =I13+I31+I49 -> 0.036002248
A28: OfficeMedium | B28: =LEFT(B10,LEN(B10)-1)&"M" -> Storage_FloorM | C28: Storage (General) | D28: CAV with Reheat_Core_Service | E28: PVAV_FloorM | F28: VRF System_FloorM + DOAS | G28: Office | H28: =H10 -> Yes | I28: =J28/$J$57 -> 0.018332841 | J28: 983.15611 | K28: =K10 -> 8848.405 | L28: =L10 -> 1 | M28: =IFERROR(N28*J28/1000,0) -> 0 | N28: =N10 -> - | O28: Conditioned but with higher cooling setpoint | R28: Lounge, Breakroom, or Waiting Area | S28: =I14+I50+I32 -> 0.012997447
A29: OfficeMedium | B29: =LEFT(B11,LEN(B11)-1)&"M" -> Mechanical/Electrical_FloorM | C29: Electrical, Mechanical, Telephone Rooms | D29: CAV with Reheat_Core_Service | E29: PVAV_FloorM | F29: VRF System_FloorM + DOAS | G29: Ancillary | H29: =H11 -> Yes | I29: =J29/$J$57 -> 0.006663486 | J29: 357.35034 | K29: =K11 -> 3216.1531 | L29: =L11 -> 1 | M29: =IFERROR(N29*J29/1000,0) -> 0 | N29: =N11 -> - | O29: Conditioned but with higher cooling setpoint | R29: Stairwell | S29: =I15+I33+I51 -> 0.036998801
A30: OfficeMedium | B30: =LEFT(B12,LEN(B12)-1)&"M" -> IT-Room_FloorM | C30: IT Room (EPD 12) | D30: CAV with Reheat_Core_Service | E30: PVAV_FloorM | F30: VRF System_FloorM + DOAS | G30: Data | H30: =H12 -> Yes | I30: =J30/$J$57 -> 0.0033366309 | J30: 178.9373 | K30: =K12 -> 1610.4357 | L30: =L12 -> 1 | M30: =IFERROR(N30*J30/1000,0) -> 0.26840595 | N30: =N12 -> 1.5 | O30: Nonres ACM 2025, Appendix 5.4A | R30: Corridor Area | S30: =SUM(I16:I19)+SUM(I34:I37)+SUM(I52:I55) -> 0.089808258
A31: OfficeMedium | B31: =LEFT(B13,LEN(B13)-1)&"M" -> Restroom_FloorM | C31: Restrooms | G31: Office | H31: Yes | I31: =J31/$J$57 -> 0.012000749 | J31: 643.57783 | K31: =K13 -> 5792.2004 | L31: =L13 -> 1 | M31: =IFERROR(N31*J31/1000,0) -> 0 | N31: =N13 -> - | O31: Indirectly conditioned | R31: Total | S31: =SUM(B67:D76) -> 0
A32: OfficeMedium | B32: =LEFT(B14,LEN(B14)-1)&"M" -> BreakRoom/Kitchenette_FloorM | C32: Lounge, Breakroom, or Waiting Area | D32: CAV with Reheat_Core_Service | E32: PVAV_FloorM | F32: VRF System_FloorM + DOAS | G32: Office | H32: =H14 -> Yes | I32: =J32/$J$57 -> 0.0043324823 | J32: 232.34295 | K32: =K14 -> 2091.0866 | L32: =L14 -> 1 | M32: =IFERROR(N32*J32/1000,0) -> 7.6673175 | N32: 33 | O32: Number of People: T24: 33 for Breakroom
A33: OfficeMedium | B33: =LEFT(B15,LEN(B15)-1)&"M" -> Stairway_FloorM | C33: Stairwell | D33: CAV with Reheat_Core_Service | E33: PVAV_FloorM | F33: VRF System_FloorM + DOAS | G33: Ancillary | H33: =H15 -> Yes | I33: =J33/$J$57 -> 0.012332934 | J33: 661.39226 | K33: =K15 -> 5952.5303 | L33: =L15 -> 1 | M33: =IFERROR(N33*J33/1000,0) -> 0 | N33: =N15 -> -
A34: OfficeMedium | B34: =LEFT(B16,LEN(B16)-1)&"M" -> Corridor_W_FloorM | C34: Corridor Area | D34: CAV with Reheat_West | E34: PVAV_FloorM | F34: VRF System_FloorM + DOAS | G34: Office | H34: =H16 -> Yes | I34: =J34/$J$57 -> 0.0055940783 | J34: 300 | K34: =K16 -> 2700 | L34: =L16 -> 1 | M34: =IFERROR(N34*J34/1000,0) -> 1.5 | N34: =N16 -> 5
A35: OfficeMedium | B35: =LEFT(B17,LEN(B17)-1)&"M" -> Corridor_N_FloorM | C35: Corridor Area | D35: CAV with Reheat_North | E35: PVAV_FloorM | F35: VRF System_FloorM + DOAS | G35: Office | H35: =H17 -> Yes | I35: =J35/$J$57 -> 0.00937889 | J35: 502.9724 | K35: =K17 -> 4526.7516 | L35: =L17 -> 1 | M35: =IFERROR(N35*J35/1000,0) -> 2.514862 | N35: =N17 -> 5
A36: OfficeMedium | B36: =LEFT(B18,LEN(B18)-1)&"M" -> Corridor_E_FloorM | C36: Corridor Area | D36: CAV with Reheat_East | E36: PVAV_FloorM | F36: VRF System_FloorM + DOAS | G36: Office | H36: =H18 -> Yes | I36: =J36/$J$57 -> 0.0055793025 | J36: 299.2076 | K36: =K18 -> 2692.8684 | L36: =L18 -> 1 | M36: =IFERROR(N36*J36/1000,0) -> 1.496038 | N36: =N18 -> 5
A37: OfficeMedium | B37: =LEFT(B19,LEN(B19)-1)&"M" -> Corridor_S_FloorM | C37: Corridor Area | D37: CAV with Reheat_South | E37: PVAV_FloorM | F37: VRF System_FloorM + DOAS | G37: Office | H37: =H19 -> Yes | I37: =J37/$J$57 -> 0.00937889 | J37: 502.9724 | K37: =K19 -> 4526.7516 | L37: =L19 -> 1 | M37: =IFERROR(N37*J37/1000,0) -> 2.514862 | N37: =N19 -> 5
A38: OfficeMedium | B38: =LEFT(B20,LEN(B20)-1)&"M" -> Plenum_FloorM | C38: Plenum | D38: - | E38: - | F38: - | G38: Office | H38: =H20 -> No | J38: 17875.932 | K38: =K20 -> 71503.73 | L38: =L20 -> 1 | M38: =IFERROR(N38*J38/1000,0) -> 0 | N38: =N20 -> -
A39: OfficeMedium | B39: =LEFT(B3,LEN(B3)-1)&"T" -> Open_Office_Core_FloorT | C39: Office Area (>250 square feet) | D39: CAV with Reheat_Core | E39: PVAV_FloorT | F39: VRF System_FloorT + DOAS | G39: Office | H39: =H3 -> Yes | I39: =J39/$J$57 -> 0.079864791 | J39: 4283 | K39: =K3 -> 38547 | L39: =L3 -> 1 | M39: =IFERROR(N39*J39/1000,0) -> 21.415 | N39: =N3 -> 5
A40: OfficeMedium | B40: =LEFT(B4,LEN(B4)-1)&"T" -> Open_Office_N_FloorT | C40: Office Area (>250 square feet) | D40: CAV with Reheat_North | E40: PVAV_FloorT | F40: VRF System_FloorT + DOAS | G40: Office | H40: =H4 -> Yes | I40: =J40/$J$57 -> 0.042850403 | J40: 2297.9873 | K40: =K4 -> 20681.886 | L40: =L4 -> 1 | M40: =IFERROR(N40*J40/1000,0) -> 11.489937 | N40: =N4 -> 5
...

Sheet Envelope
A1: Envelope - OfficeMedium
A2: Element | B2: Prototype | C2: Assembly Type | D2: Construction | E2: Thermal Properties | F2: Vintage | G2: Selected T24 | H2: Notes | I2: CZ1 | J2: CZ2 | K2: CZ3 | L2: CZ4 | M2: CZ5 | N2: CZ6 | O2: CZ7 | P2: CZ8 | Q2: CZ9 | R2: CZ10 | S2: CZ11 | T2: CZ12 | U2: CZ13 | V2: CZ14 | W2: CZ15 | X2: CZ16
A3: External Wall | B3: OfficeMedium | C3: ExtWall_MetalFramed_NonRes | D3: Metal-frame walls + insulation + Gypsum board | E3: U-factor IP | F3: Pre 1978 | G3: N/A | H3: ASHRAE 90.1, 2022, Table A3.3.3.1, 3.5", R-0 | I3: 0.352 | J3: 0.352 | K3: 0.352 | L3: 0.352 | M3: 0.352 | N3: 0.352 | O3: 0.352 | P3: 0.352 | Q3: 0.352 | R3: 0.352 | S3: 0.352 | T3: 0.352 | U3: 0.352 | V3: 0.352 | W3: 0.352 | X3: 0.352
F4: 1978-1997 | G4: 1986 | H4: Low-rise office: Package A/ Heat Capacity was considered ~10 (BTU/F/ft2) | I4: =1/6.63 -> 0.15082956 | J4: =1/6.35 -> 0.15748031 | K4: =1/6.35 -> 0.15748031 | L4: =1/6.96 -> 0.14367816 | M4: =1/6.96 -> 0.14367816 | N4: =1/4.62 -> 0.21645022 | O4: =1/4.62 -> 0.21645022 | P4: =1/4.62 -> 0.21645022 | Q4: =1/4.62 -> 0.21645022 | R4: =1/4.62 -> 0.21645022 | S4: =1/5.37 -> 0.18621974 | T4: =1/5.37 -> 0.18621974 | U4: =1/5.37 -> 0.18621974 | V4: =1/6.3 -> 0.15873016 | W4: =1/6.3 -> 0.15873016 | X4: =1/6.63 -> 0.15082956
F5: 1998-2007 | G5: 2001 | H5: TABLE 1-H | I5: 0.182 | J5: 0.182 | K5: 0.189 | L5: 0.189 | M5: 0.189 | N5: 0.189 | O5: 0.189 | P5: 0.189 | Q5: 0.189 | R5: 0.182 | S5: 0.182 | T5: 0.182 | U5: 0.182 | V5: 0.182 | W5: 0.182 | X5: 0.182
F6: 2008-2018 | G6: 2013 | H6: TABLE 140.3-B | I6: 0.098 | J6: 0.062 | K6: 0.082 | L6: 0.062 | M6: 0.062 | N6: 0.098 | O6: 0.098 | P6: 0.062 | Q6: 0.062 | R6: 0.062 | S6: 0.062 | T6: 0.062 | U6: 0.062 | V6: 0.062 | W6: 0.062 | X6: 0.062
F7: 2019+ | G7: 2025 | H7: Table 140.3-B (In Nonres Section) | I7: 0.06 | J7: 0.055 | K7: 0.071 | L7: 0.055 | M7: 0.055 | N7: 0.06 | O7: 0.06 | P7: 0.055 | Q7: 0.055 | R7: 0.055 | S7: 0.055 | T7: 0.055 | U7: 0.055 | V7: 0.055 | W7: 0.055 | X7: 0.055
A8: Roof | B8: OfficeMedium | C8: FlatRoof_WoodFramedAndOther_NonRes | D8: Metal-Deck roof + insulation + Roof membrane | E8: U-factor IP | F8: Pre 1978 | G8: N/A | H8: Considering 30 years for roof/ insultation replacement. | I8: 0.057 | J8: 0.057 | K8: 0.057 | L8: 0.057 | M8: 0.057 | N8: 0.078 | O8: 0.078 | P8: 0.078 | Q8: 0.078 | R8: 0.078 | S8: 0.057 | T8: 0.057 | U8: 0.057 | V8: 0.057 | W8: 0.057 | X8: 0.057
F9: 1978-1997 | G9: 1992 | H9: Considering 30 years for roof/ insultation replacement. | I9: 0.057 | J9: 0.057 | K9: 0.057 | L9: 0.057 | M9: 0.057 | N9: 0.078 | O9: 0.078 | P9: 0.078 | Q9: 0.078 | R9: 0.078 | S9: 0.057 | T9: 0.057 | U9: 0.057 | V9: 0.057 | W9: 0.057 | X9: 0.057
F10: 1998-2007 | G10: 2001 | H10: TABLE 1-H | I10: 0.057 | J10: 0.057 | K10: 0.057 | L10: 0.057 | M10: 0.057 | N10: 0.078 | O10: 0.078 | P10: 0.078 | Q10: 0.078 | R10: 0.057 | S10: 0.057 | T10: 0.057 | U10: 0.057 | V10: 0.057 | W10: 0.057 | X10: 0.057
F11: 2008-2018 | G11: 2013 | H11: TABLE 140.3-B | I11: 0.049 | J11: 0.039 | K11: 0.039 | L11: 0.039 | M11: 0.049 | N11: 0.075 | O11: 0.067 | P11: 0.067 | Q11: 0.039 | R11: 0.039 | S11: 0.039 | T11: 0.039 | U11: 0.039 | V11: 0.039 | W11: 0.039 | X11: 0.039
F12: 2019+ | G12: 2025 | H12: Table 140.3-B (In Nonres Section) | I12: 0.028 | J12: 0.028 | K12: 0.028 | L12: 0.028 | M12: 0.028 | N12: 0.047 | O12: 0.047 | P12: 0.047 | Q12: 0.028 | R12: 0.028 | S12: 0.028 | T12: 0.028 | U12: 0.028 | V12: 0.028 | W12: 0.028 | X12: 0.028
A13: Windows | B13: OfficeMedium | C13: FixedWindow_NonRes | D13: CBECS 2018 shows that over 50 % of medium offices that were built before 2000 are single pane | E13: U-factor IP | F13: Pre 1978 | G13: N/A | H13: ASHRAE Handbook of Fundamentals for single pane (Table 4-Ch15) & T24, 2013 for double pane(50%-50%)* | I13: =1.12*0.5+I$16*0.5 -> 0.74 | J13: =1.12*0.5+J$16*0.5 -> 0.74 | K13: =1.12*0.5+K$16*0.5 -> 0.74 | L13: =1.12*0.5+L$16*0.5 -> 0.74 | M13: =1.12*0.5+M$16*0.5 -> 0.74 | N13: =1.12*0.5+N$16*0.5 -> 0.74 | O13: =1.12*0.5+O$16*0.5 -> 0.74 | P13: =1.12*0.5+P$16*0.5 -> 0.74 | ... X13: =1.12*0.5+X$16*0.5 -> 0.74
F14: 1978-1997 | G14: N/A | I14: =1.12*0.5+I$16*0.5 -> 0.74 | J14: =1.12*0.5+J$16*0.5 -> 0.74 | K14: =1.12*0.5+K$16*0.5 -> 0.74 | L14: =1.12*0.5+L$16*0.5 -> 0.74 | M14: =1.12*0.5+M$16*0.5 -> 0.74 | N14: =1.12*0.5+N$16*0.5 -> 0.74 | O14: =1.12*0.5+O$16*0.5 -> 0.74 | P14: =1.12*0.5+P$16*0.5 -> 0.74 | ... X14: =1.12*0.5+X$16*0.5 -> 0.74
D15: Double pane | F15: 1998-2007 | G15: 2001 | H15: TABLE 1-H | I15: 0.49 | J15: 0.49 | K15: 0.81 | L15: 0.81 | M15: 0.81 | N15: 0.81 | O15: 0.81 | P15: 0.81 | Q15: 0.81 | R15: 0.49 | S15: 0.49 | T15: 0.49 | U15: 0.49 | V15: 0.49 | W15: 0.49 | X15: 0.49
F16: 2008-2018 | G16: 2013 | H16: TABLE 140.3-B | I16: 0.36 | J16: 0.36 | K16: 0.36 | L16: 0.36 | M16: 0.36 | N16: 0.36 | O16: 0.36 | P16: 0.36 | Q16: 0.36 | R16: 0.36 | S16: 0.36 | T16: 0.36 | U16: 0.36 | V16: 0.36 | W16: 0.36 | X16: 0.36
F17: 2019+ | G17: 2025 | H17: Table 140.3-B (In Nonres Section) | I17: 0.36 | J17: 0.36 | K17: 0.36 | L17: 0.36 | M17: 0.36 | N17: 0.36 | O17: 0.36 | P17: 0.36 | Q17: 0.34 | R17: 0.36 | S17: 0.34 | T17: 0.34 | U17: 0.34 | V17: 0.34 | W17: 0.34 | X17: 0.36
B18: OfficeMedium | C18: FixedWindow_NonRes | D18: CBECS 2018 shows that over 50% of medium offices that were built before 2000 are single pane | E18: SHGC | F18: Pre 1978 | G18: N/A | H18: ASHRAE Handbook of Fundamentals for single pane (Table 10-Ch15), & T24 2013 for double pane(50%-50%)* | I18: =0.79*0.5+I$20*0.5 -> 0.61 | J18: =0.79*0.5+J$20*0.5 -> 0.55 | K18: =0.79*0.5+K$20*0.5 -> 0.6 | L18: =0.79*0.5+L$20*0.5 -> 0.6 | M18: =0.79*0.5+M$20*0.5 -> 0.6 | N18: =0.79*0.5+N$20*0.5 -> 0.565 | O18: =0.79*0.5+O$20*0.5 -> 0.565 | P18: =0.79*0.5+P$20*0.5 -> 0.565 | ... X18: =0.79*0.5+X$20*0.5 -> 0.61
F19: 1978-1997 | G19: N/A | I19: =I18 -> 0.61 | J19: =J18 -> 0.55 | K19: =K18 -> 0.6 | L19: =L18 -> 0.6 | M19: =M18 -> 0.6 | N19: =N18 -> 0.565 | O19: =O18 -> 0.565 | P19: =P18 -> 0.565 | ... X19: =X18 -> 0.61
D20: Double pane | F20: 1998-2007 | G20: 2001 | H20: WWR:30-40 / SHGC non-north (Non-north SHGC is more stringent than north and is therefore considered for all sides) | I20: 0.43 | J20: 0.31 | K20: 0.41 | L20: 0.41 | M20: 0.41 | N20: 0.34 | O20: 0.34 | P20: 0.34 | Q20: 0.34 | R20: 0.31 | S20: 0.31 | T20: 0.31 | U20: 0.31 | V20: 0.31 | W20: 0.31 | X20: 0.43
F21: 2008-2018 | G21: 2013 | H21: TABLE 140.3-B | I21: 0.25 | J21: 0.25 | K21: 0.25 | L21: 0.25 | M21: 0.25 | N21: 0.25 | O21: 0.25 | P21: 0.25 | Q21: 0.25 | R21: 0.25 | S21: 0.25 | T21: 0.25 | U21: 0.25 | V21: 0.25 | W21: 0.25 | X21: 0.25
F22: 2019+ | G22: 2025 | H22: Table 140.3-B (In Nonres Section) | I22: 0.25 | J22: 0.25 | K22: 0.25 | L22: 0.25 | M22: 0.25 | N22: 0.25 | O22: 0.25 | P22: 0.25 | Q22: 0.22 | R22: 0.25 | S22: 0.22 | T22: 0.22 | U22: 0.22 | V22: 0.22 | W22: 0.22 | X22: 0.25
C24: Infiltration
D25: Building | E25: Zones | F25: Vintage | G25: I_75 (cfm/ft²) 6-sdied Infiltration rate @ 75 pa | H25: Source | I25: I-design (cfm/ft²) (4-sided Infiltration rate at normal pressure) (Design flow rate approach and Flow/Exterior Wall Area calculation method)
C26: Infiltration | D26: OfficeMedium | F26: Pre 1978 | G26: 1.1 | H26: 2022 CASE report (Table 38) | I26: 0.3302
F27: 1978-1997 | G27: 1.1 | H27: 2022 CASE report (Table 38) | I27: 0.3302
F28: 1998-2007 | G28: 1.1 | H28: 2022 CASE report (Table 38) | I28: 0.3302
F29: 2008-2018 | G29: 1.0065* | H29: 2022 CASE report (Table 38) & T24, 2008-2016 (Table 140.3-C) | I29: 0.3021
F30: 2019+ | G30: 0.6** | H30: 2022 CASE report (Table 38) & T24,140.3(a)9Cii & T24, 2025 (Table 140.3-C) | I30: 0.1801
E31: Infiltration_rate_report_14May2025-Short-Version.docx
E32: * An air barrier was not required for guest rooms under T24, until the 2019 edition. However, to reflect typical construction practices, we assumed that all exterior walls are equipped with an air barrier where it was required for nonresidential walls.
E33: *** T24 require 0.4 cfm/ft² for tested condition but it also in section 140.3(a)9Cii says that if the air leakage requirements are not met, a visual inspection and diagnostic evaluation shall be completed , all observed leaks shall be sealed where such sealing can be made without destruction of existing building components, and buildings where the tested leakage rate exceeded 0.6 cfm/ft² of building shell area at 75 Pa have been retested to confirm leakage is below 0.6 cfm/ft² of building shell at 75 Pa.
A35: *Note for windows properties in vintage 1 &2 :
A36: We’ve considered a 50% single-pane and 50% double-pane mix (based on the 2013 requirements) for the window properties in Vintage 1 & 2 (pre-1998 buildings).
A37: Since we don't have California-specific data, the decision is based on the CBECS 2018 data, which indicates:
A38: - 40% of medium offices built before 1978 have mixed windows, while only 6% of offices from the second vintage (1978-1997) have mixed glass.
A39: - Pre-1978: Among those with either single or double-pane windows, 80% have single-pane windows, and 20% have double-pane windows.
A40: - 1978-1997: Among those with either single or double-pane windows, 55% have single-pane windows, and 45% have double-pane windows.
A41: - Pre 1999: Among those with either single or double-pane windows, 61% has single pane windows.
A42: Since we don't have California-specific data and CBECS data is for 2018, it's likely that a percentage of pre-1978 buildings have undergone retrofitting in the past 7 years and upgraded their windows. Based on this, we've decided to apply the 50%-50% mix for the window properties.

Sheet HVAC System
A1: HVAC system - OfficeMedium | I1: HVAC System Layout
A2: Vintage | B2: Space/Thermal Zone | C2: Heating | D2: Cooling | E2: Air Distribution | F2: Other systems | G2: Source
A3: Existing | B3: All Except IT Rooms | C3: Furnace (Gas) | D3: Packaged (DX) | E3: CAV with Reheat for the first two vintages VAV with Reheat for vintage 3 and 4 | F3: OA mix through air handler Economizer for Vintage 3 and 4 DCV for Vintage 4 (for qualifying high density rooms) | G3: CEUS 2022 + Engineering Judgement
B4: IT Room | C4: - | D4: DX Computer Room Air Conditioner (CRAC) | E4: CAV | F4: _ | G4: Engineering Judgement
A5: New Construction | B5: All Except IT Rooms | C5: VRF | D5: VRF | E5: VRF | F5: DOAS Economizer ERV DCV for qualifying high density rooms | G5: T24, 2025
B6: IT Room | C6: - | D6: DX Computer Room Air Conditioner (CRAC) | E6: CAV | F6: _ | G6: T24 2025
I9: First Floor | K9: Second and Third Floor
A10: Efficiency of HVAC System (Efficiency is capacity-dependent. The following table provides a general estimate of system efficiency based on preliminary simulations in one climate zone, or assuming cooling load based on rule of thumb)
A11: Vintage | B11: HVAC System Type | C11: Upgrade/Installed year | D11: DX Computer Room Air Conditioner (CRAC) | E11: Heating | F11: Cooling | G11: Source
A12: Pre 1978 | B12: Packaged CAV - DX with Gas Furnace | C12: 2008 | D12: 11 EER for <65 kBtu/h 10.4 EER for 65-135 kBtu/h 10.2 EER for 135-240 kBtu/h | E12: Thermal efficiency (Et) of 80% | F12: 10.1 EER for 65-135 kBtu/h 9.5 EER for 135-240 kBtu/h 9.3 EER & 9.7 IPLV for >240 kBtu/h | G12: T24, Table 112-A (2008) California Title 20 Appliance Efficiency Regulations, Table E-4, Standards for Gas- and Oil-Fired Central Furnaces (2008) CRAC: California Title 20 Appliance Efficiency Regulations, §1605.3(c)(2), Tables C-9 (2008)
A13: 1978-1997
A14: 1998-2007 | B14: Packaged VAV - DX with Gas Furnace | C14: 2008 | D14: 11 EER for <65 kBtu/h 10.4 EER for 65-135 kBtu/h 10.2 EER for 135-240 kBtu/h | E14: Thermal efficiency (Et) of 80% | F14: 10.1 EER for 65-135 kBtu/h 9.5 EER for 135-240 kBtu/h 9.3 EER & 9.7 IPLV for >240 kBtu/h
A15: 2008-2018 | B15: Packaged VAV - DX with Gas Furnace | C15: 2013 | D15: SCOP= 2.44 for <65 kBtu/h 2.34 for 65-240 kBtu/h 2.24 for >240 kBtu/h | E15: Thermal efficiency (Et) of 80% or 78% AFUE | F15: SEER 13 for <65 kBtu/h 11 EER & 11.2 IEER for 65-135 kBtu/h 10.8 EER & 11 IEER for 135-240 kBtu/h 9.8 EER & 9.9 IEER for >240 kBtu/h | G15: T24, Table 110.2-J & Table 110.2-A (2013) CRAC: 10 CFR §431.97(f)(1), Table 7 (2013)
A16: New Construction | B16: VRF | C16: 2025 | D16: NSenCOP= 2.09 for <65 kBtu/h 1.99 for 65-240 kBtu/h 1,81 for >240 kBtu/h | E16: 7.5 HSPF2 for <65 kBtu/h 3.3 COP for 65-135 kBtu/h 3.2 COP for 135-240 kBtu/h 3.2 COP for >240 kBtu/h | F16: 10.1 EER & 14.4 IEER for 65-135 kBtu/h 9.7 EER & 13.7 IEER for 135-240 kBtu/h 8.9 EER & 12.5 IEER for >240 kBtu/h | G16: T24, Table 110.2-G (2025) 10 CFR § 431.97 Table 16 (2025) CRAC: 10 CFR § 431.97, Table 13 (2025)
A22: Fan power
A23: Vintage | B23: Approach | C23: System | D23: Total Static Pressure (TSP) (in w.c.) | E23: Fan Efficiency [ACM 2025] | F23: Motor Efficiency | G23: Fan Power Index (W/cfm) | H23: Data Source | I23: Note
A24: Existing | B24: PNNL 90 1-2011, TSP | C24: CAV System <7,437 cfm | D24: 2.5 | E24: 0.65 | F24: According to PNNL 20405 section 5.2.2.5, the full-load efficiency of the motor serving the fan is taken from ASHRAE 90.1, 2004, Table 10.8, based on motor nameplate and assuming enclosed motors operating at 1,800 rotations per minute (rpm) Motor nameplate size in hp = brake horsepower (bhp) × 1.1 ( using a 10% oversizing factor) Brake horsepower (bhp) = (Supply cfm from sizing run × TSP in w.c.) / (6356 × fan efficiency) | G24: Fan power in W/cfm = (TSP in w.c. × 746) / (6356 × fan efficiency × motor and drive efficiency | H24: Fan power formula: PNNL 20405, 2010, section 5.2.2.5 TSP and fan efficiecncy: PNNL 20405, 2010, Table 5.11, 90.1-04ac values Motor and drive efficiency: ASHRAE 90.1, 2004, Table 10.8 | J24: PNNL 20405, 2010, Table 5.11
C25: CAV System >7,437 cfm | D25: 4.09 | E25: 0.65
C26: VAV System > 4,648 cfm | D26: 5.58 | E26: 0.65
A27: Brake horsepower (bhp) = (Supply cfm × TSP in w.c.) / (6356 × fan efficiency)
A28: Fan power (w/cfm) = (bhp × 746) / ( supply cfm × motor efficiency )
A29: New Construction | B29: ACM 2025 | C29: Small indoor fan at zone (for VRF) <1,600 cfm | D29: =G29*(0.855*E29)/746*6356 -> 1.6572674 | E29: 0.65 | F29: The full‑load efficiency of the motor serving the fan is taken from ACM 2025 Table 12 based on the cfm of the fan. Motor horsepower in hp = (Supply cfm from sizing run × fan power in W/cfm) / 746. Considering a maximum airflow of 1,600 cfm for the VRF indoor fan (based on the sizing run), the resulting motor power is less than 1 hp. Therefore, motor efficiency is 85.5% according to ACM 2025 Table 12. In larger fan, motor effiiceny is higher. | G29: 0.35 | H29: Fan power index (0.35 w/cfm): [T24, 2025, Section 140.4(a)3 D] Motot efficiency: [ ACM 2025, Table 12] | I29: 0.35 W/CFM is for the indoor unit fan. For main HVAC system fan (if applicable), the fan power must be determined using the 2025 ACM Table 13.
D30: TSP (E+ input) in w.c. = fan power in W/cfm × motor effciency × fan efficiecny × 6356 / 746
B41: 𝜇_𝑚𝑜𝑡𝑜𝑟 : Motor and drive efficiency | E41: (〖Fna power〗_(w/cfm)∗cfm∗μ_motor)/746

Sheet Thermostat
A1: Thermostat Setpoints: OfficeMedium
A2: Spaces/Zones | B2: Setpoint | C2: CZ1 | D2: CZ2 | E2: CZ3 | F2: CZ4 | G2: CZ5 | H2: CZ6 | I2: CZ7 | J2: CZ8 | K2: CZ9 | L2: CZ10 | M2: CZ11 | N2: CZ12 | O2: CZ13 | P2: CZ14 | Q2: CZ15 | R2: CZ16 | S2: Source
A3: All conditioned zones except server rooms, Stairway & Mechanical_Electrical | B3: Heating Setpoint (F) | C3: 70 | D3: 70 | E3: 70 | F3: 70 | G3: 70 | H3: 70 | I3: 70 | J3: 70 | K3: 70 | L3: 70 | M3: 70 | N3: 70 | O3: 70 | P3: 70 | Q3: 70 | R3: 70 | S3: T24 2022 - Appendix 5.4B
B4: Heating Setback (F) | C4: 60 | D4: 60 | E4: 60 | F4: 60 | G4: 60 | H4: 60 | I4: 60 | J4: 60 | K4: 60 | L4: 60 | M4: 60 | N4: 60 | O4: 60 | P4: 60 | Q4: 60 | R4: 60
B5: Cooling Setpoint (F) | C5: 75 | D5: 75 | E5: 75 | F5: 75 | G5: 75 | H5: 75 | I5: 75 | J5: 75 | K5: 75 | L5: 75 | M5: 75 | N5: 75 | O5: 75 | P5: 75 | Q5: 75 | R5: 75
B6: Cooling Setback (F) | C6: 85 | D6: 85 | E6: 85 | F6: 85 | G6: 85 | H6: 85 | I6: 85 | J6: 85 | K6: 85 | L6: 85 | M6: 85 | N6: 85 | O6: 85 | P6: 85 | Q6: 85 | R6: 85
A7: Stairway, and Mechanical_Electrical | B7: Heating Setpoint (F) | C7: 60 | D7: 60 | E7: 60 | F7: 60 | G7: 60 | H7: 60 | I7: 60 | J7: 60 | K7: 60 | L7: 60 | M7: 60 | N7: 60 | O7: 60 | P7: 60 | Q7: 60 | R7: 60 | S7: Enginnering Judgment (Semi‑conditioned space)
B8: Heating Setback (F) | C8: 60 | D8: 60 | E8: 60 | F8: 60 | G8: 60 | H8: 60 | I8: 60 | J8: 60 | K8: 60 | L8: 60 | M8: 60 | N8: 60 | O8: 60 | P8: 60 | Q8: 60 | R8: 60
B9: Cooling Setpoint (F) | C9: 85 | D9: 85 | E9: 85 | F9: 85 | G9: 85 | H9: 85 | I9: 85 | J9: 85 | K9: 85 | L9: 85 | M9: 85 | N9: 85 | O9: 85 | P9: 85 | Q9: 85 | R9: 85
B10: Cooling Setback (F) | C10: 85 | D10: 85 | E10: 85 | F10: 85 | G10: 85 | H10: 85 | I10: 85 | J10: 85 | K10: 85 | L10: 85 | M10: 85 | N10: 85 | O10: 85 | P10: 85 | Q10: 85 | R10: 85
A11: IT rooms | B11: Cooling Setpoint (F)* | C11: 80 | D11: 80 | E11: 80 | F11: 80 | G11: 80 | H11: 80 | I11: 80 | J11: 80 | K11: 80 | L11: 80 | M11: 80 | N11: 80 | O11: 80 | P11: 80 | Q11: 80 | R11: 80 | S11: Title 24, Part 6, 2025, section 140.9 (a) and PNNL ASHRAE 90.1 2022 Large Office prototype
B12: Heating Setpoint (F)* | C12: *The IT room with over 12 W/ft2 load doesn't require heating system as the equipment constantly generate enough heat.
B15: Note: The Medium Office prototype by PNNL also uses the same setpoints, except for one of the perimeter zones, which has a heating setpoint of 69 °F and a cooling setpoint of 76 °F during hours of 10:00-11:00, 12:00-13:00, and 14:00-15:00 .

Sheet Ventilation
A1: Outdoor Airflow Rate - OfficeMedium
A2: Space | B2: Number of People | C2: Floor Area (ft²) | D2: cfm/person (T24, 2025, Equation 120.1-F and Table 120.1-A) | E2: cfm/ft² (T24, 2025, Equation 120.1-F and Table 120.1-A) | F2: Required Exhaust Rate (T24, 2025, Table 120.1-B – Minimum Exhaust Rates) | G2: Total cfm Driven by People | H2: Total cfm Driven by Area | I2: Total cfm Driven by Exhaust | J2: Total cfm | K2: Note
A3: =Zones!B3 -> Open_Office_Core_FloorG | B3: =Zones!M3 -> 21.415 | C3: =Zones!J3 -> 4283 | D3: 15 | E3: 0.15 | G3: =B3*D3 -> 321.225 | H3: =C3*E3 -> 642.45 | I3: =F3 -> 0 | J3: =MAX(G3,H3,I3) -> 642.45 | K3: Office space/Occupancy Category - Office Buildings
A4: =Zones!B4 -> Open_Office_N_FloorG | B4: =Zones!M4 -> 11.489937 | C4: =Zones!J4 -> 2297.9873 | D4: 15 | E4: 0.15 | G4: =B4*D4 -> 172.34905 | H4: =C4*E4 -> 344.6981 | I4: =F4 -> 0 | J4: =MAX(G4,H4,I4) -> 344.6981 | K4: Office space/Occupancy Category - Office Buildings
A5: =Zones!B5 -> Enclosed_Office_W_FloorG | B5: =Zones!M5 -> 8.1893058 | C5: =Zones!J5 -> 1637.8612 | D5: 15 | E5: 0.15 | G5: =B5*D5 -> 122.83959 | H5: =C5*E5 -> 245.67917 | I5: =F5 -> 0 | J5: =MAX(G5,H5,I5) -> 245.67917 | K5: Office space/Occupancy Category - Office Buildings
A6: =Zones!B6 -> Enclosed_Office_E_FloorG | B6: =Zones!M6 -> 8.1893058 | C6: =Zones!J6 -> 1637.8612 | D6: 15 | E6: 0.15 | G6: =B6*D6 -> 122.83959 | H6: =C6*E6 -> 245.67917 | I6: =F6 -> 0 | J6: =MAX(G6,H6,I6) -> 245.67917 | K6: Office space/Occupancy Category - Office Buildings
A7: =Zones!B7 -> Open_Office_S_FloorG | B7: =Zones!M7 -> 5.9310376 | C7: =Zones!J7 -> 1186.2075 | D7: 15 | E7: 0.15 | G7: =B7*D7 -> 88.965563 | H7: =C7*E7 -> 177.93113 | I7: =F7 -> 0 | J7: =MAX(G7,H7,I7) -> 177.93113 | K7: Office space/Occupancy Category - Office Buildings
A8: =Zones!B8 -> Conference_FloorG | B8: =Zones!M8 -> 36.688734 | C8: =Zones!J8 -> 1111.7798 | D8: 15 | E8: 0.15 | G8: =B8*D8 -> 550.33101 | H8: =C8*E8 -> 166.76697 | I8: =F8 -> 0 | J8: =MAX(G8,H8,I8) -> 550.33101 | K8: Conference/meeting/Occupancy Category - General
A9: =Zones!B9 -> Lobby_FloorG | B9: =Zones!M9 -> 10.591755 | C9: =Zones!J9 -> 1059.1755 | D9: 15 | E9: 0.15 | G9: =B9*D9 -> 158.87632 | H9: =C9*E9 -> 158.87632 | I9: =F9 -> 0 | J9: =MAX(G9,H9,I9) -> 158.87632 | K9: Main entry lobbies/Occupancy Category - Office Buildings
A10: =Zones!B10 -> Storage_FloorG | B10: =Zones!M10 -> 0 | C10: =Zones!J10 -> 983.15611 | D10: 15 | E10: 0.15 | H10: =C10*E10 -> 147.47342 | I10: =F10 -> 0 | J10: =MAX(G10,H10,I10) -> 147.47342 | K10: Occupiable storage rooms for dry materials/Occupancy Category - Office Buildings
A11: =Zones!B11 -> Mechanical/Electrical_FloorG | B11: =Zones!M11 -> 0 | C11: =Zones!J11 -> 357.35034 | D11: 15 | E11: 0.15 | H11: =C11*E11 -> 53.602551 | I11: =F11 -> 0 | J11: =MAX(G11,H11,I11) -> 53.602551 | K11: All Other
A12: =Zones!B12 -> IT-Room_FloorG | B12: =Zones!M12 -> 0.26840595 | C12: =Zones!J12 -> 178.9373 | D12: 15 | E12: 0.15 | H12: =C12*E12 -> 26.840595 | I12: =F12 -> 0 | J12: =MAX(G12,H12,I12) -> 26.840595 | K12: Telephone/data entry/Occupancy Category - Office Buildings
A13: =Zones!B13 -> Restroom_FloorG | B13: =Zones!M13 -> 0 | C13: =Zones!J13 -> 643.57783 | D13: 15 | E13: 0.15 | F13: 4*50/70 cfm per unit | H13: =C13*E13 -> 96.536674 | I13: =4*50 -> 200 | J13: =MAX(G13,H13,I13) -> 200 | K13: All Other- Almost 1 unit per 30 occupant for exhaust fan
A14: =Zones!B14 -> BreakRoom/Kitchenette_FloorG | B14: =Zones!M14 -> 7.6673175 | C14: =Zones!J14 -> 232.34295 | D14: 15 | E14: 0.15 | G14: =B14*D14 -> 115.00976 | H14: =C14*E14 -> 34.851443 | I14: =F14 -> 0 | J14: =MAX(G14,H14,I14) -> 115.00976 | K14: Breakrooms/Occupancy Category - Office Buildings
A15: =Zones!B15 -> Stairway_FloorG | B15: =Zones!M15 -> 0 | C15: =Zones!J15 -> 661.39226 | D15: 15 | E15: 0.15 | H15: =C15*E15 -> 99.208839 | I15: =F15 -> 0 | J15: =MAX(G15,H15,I15) -> 99.208839 | K15: All Other
A16: =Zones!B16 -> Corridor_W_FloorG | B16: =Zones!M16 -> 1.5 | C16: =Zones!J16 -> 300 | D16: 15 | E16: 0.15 | G16: =B16*D16 -> 22.5 | H16: =C16*E16 -> 45 | I16: =F16 -> 0 | J16: =MAX(G16,H16,I16) -> 45 | K16: Corridors /Occupancy Category - General
A17: =Zones!B17 -> Corridor_N_FloorG | B17: =Zones!M17 -> 2.514862 | C17: =Zones!J17 -> 502.9724 | D17: 15 | E17: 0.15 | G17: =B17*D17 -> 37.72293 | H17: =C17*E17 -> 75.44586 | I17: =F17 -> 0 | J17: =MAX(G17,H17,I17) -> 75.44586 | K17: Corridors /Occupancy Category - General
A18: =Zones!B18 -> Corridor_E_FloorG | B18: =Zones!M18 -> 1.496038 | C18: =Zones!J18 -> 299.2076 | D18: 15 | E18: 0.15 | G18: =B18*D18 -> 22.44057 | H18: =C18*E18 -> 44.88114 | I18: =F18 -> 0 | J18: =MAX(G18,H18,I18) -> 44.88114 | K18: Corridors /Occupancy Category - General
A19: =Zones!B19 -> Corridor_S_FloorG | B19: =Zones!M19 -> 2.514862 | C19: =Zones!J19 -> 502.9724 | D19: 15 | E19: 0.15 | G19: =B19*D19 -> 37.72293 | H19: =C19*E19 -> 75.44586 | I19: =F19 -> 0 | J19: =MAX(G19,H19,I19) -> 75.44586 | K19: Corridors /Occupancy Category - General
A20: =Zones!B20 -> Plenum_FloorG | B20: =Zones!M20 -> 0 | C20: =Zones!J20 -> 17875.932 | E20: - | I20: =F20 -> 0 | J20: =MAX(G20,H20,I20) -> 0 | K20: -
A21: =Zones!B21 -> Open_Office_Core_FloorM | B21: =Zones!M21 -> 21.415 | C21: =Zones!J21 -> 4283 | D21: =D3 -> 15 | E21: =E3 -> 0.15 | G21: =B21*D21 -> 321.225 | H21: =C21*E21 -> 642.45 | I21: =F21 -> 0 | J21: =MAX(G21,H21,I21) -> 642.45 | K21: Office space/Occupancy Category - Office Buildings
A22: =Zones!B22 -> Open_Office_N_FloorM | B22: =Zones!M22 -> 11.489937 | C22: =Zones!J22 -> 2297.9873 | D22: =D4 -> 15 | E22: =E4 -> 0.15 | G22: =B22*D22 -> 172.34905 | H22: =C22*E22 -> 344.6981 | I22: =F22 -> 0 | J22: =MAX(G22,H22,I22) -> 344.6981 | K22: Office space/Occupancy Category - Office Buildings
A23: =Zones!B23 -> Enclosed_Office_W_FloorM | B23: =Zones!M23 -> 8.1893058 | C23: =Zones!J23 -> 1637.8612 | D23: =D5 -> 15 | E23: =E5 -> 0.15 | G23: =B23*D23 -> 122.83959 | H23: =C23*E23 -> 245.67917 | I23: =F23 -> 0 | J23: =MAX(G23,H23,I23) -> 245.67917 | K23: Office space/Occupancy Category - Office Buildings
A24: =Zones!B24 -> Enclosed_Office_E_FloorM | B24: =Zones!M24 -> 8.1893058 | C24: =Zones!J24 -> 1637.8612 | D24: =D6 -> 15 | E24: =E6 -> 0.15 | G24: =B24*D24 -> 122.83959 | H24: =C24*E24 -> 245.67917 | I24: =F24 -> 0 | J24: =MAX(G24,H24,I24) -> 245.67917 | K24: Office space/Occupancy Category - Office Buildings
A25: =Zones!B25 -> Open_Office_S_FloorM | B25: =Zones!M25 -> 5.9310376 | C25: =Zones!J25 -> 1186.2075 | D25: =D7 -> 15 | E25: =E7 -> 0.15 | G25: =B25*D25 -> 88.965563 | H25: =C25*E25 -> 177.93113 | I25: =F25 -> 0 | J25: =MAX(G25,H25,I25) -> 177.93113 | K25: Office space/Occupancy Category - Office Buildings
A26: =Zones!B26 -> Conference_FloorM | B26: =Zones!M26 -> 36.688734 | C26: =Zones!J26 -> 1111.7798 | D26: =D8 -> 15 | E26: =E8 -> 0.15 | G26: =B26*D26 -> 550.33101 | H26: =C26*E26 -> 166.76697 | I26: =F26 -> 0 | J26: =MAX(G26,H26,I26) -> 550.33101 | K26: Conference/meeting/Occupancy Category - General
A27: =Zones!B27 -> Lounge_FloorM | B27: =Zones!M27 -> 15.887632 | C27: =Zones!J27 -> 1059.1755 | D27: =D9 -> 15 | E27: =E9 -> 0.15 | G27: =B27*D27 -> 238.31448 | H27: =C27*E27 -> 158.87632 | I27: =F27 -> 0 | J27: =MAX(G27,H27,I27) -> 238.31448 | K27: Break rooms /Occupancy Category - Office Buildings
A28: =Zones!B28 -> Storage_FloorM | B28: =Zones!M28 -> 0 | C28: =Zones!J28 -> 983.15611 | D28: =D10 -> 15 | E28: =E10 -> 0.15 | H28: =C28*E28 -> 147.47342 | I28: =F28 -> 0 | J28: =MAX(G28,H28,I28) -> 147.47342 | K28: Occupiable storage rooms for dry materials/Occupancy Category - Office Buildings
A29: =Zones!B29 -> Mechanical/Electrical_FloorM | B29: =Zones!M29 -> 0 | C29: =Zones!J29 -> 357.35034 | D29: =D11 -> 15 | E29: =E11 -> 0.15 | H29: =C29*E29 -> 53.602551 | I29: =F29 -> 0 | J29: =MAX(G29,H29,I29) -> 53.602551 | K29: All Other
A30: =Zones!B30 -> IT-Room_FloorM | B30: =Zones!M30 -> 0.26840595 | C30: =Zones!J30 -> 178.9373 | D30: =D12 -> 15 | E30: =E12 -> 0.15 | H30: =C30*E30 -> 26.840595 | I30: =F30 -> 0 | J30: =MAX(G30,H30,I30) -> 26.840595 | K30: Telephone/data entry/Occupancy Category - Office Buildings
A31: =Zones!B31 -> Restroom_FloorM | B31: =Zones!M31 -> 0 | C31: =Zones!J31 -> 643.57783 | D31: =D13 -> 15 | E31: =E13 -> 0.15 | F31: 4*50/70 cfm per unit | H31: =C31*E31 -> 96.536674 | I31: =4*50 -> 200 | J31: =MAX(G31,H31,I31) -> 200 | K31: All Other
A32: =Zones!B32 -> BreakRoom/Kitchenette_FloorM | B32: =Zones!M32 -> 7.6673175 | C32: =Zones!J32 -> 232.34295 | D32: =D14 -> 15 | E32: =E14 -> 0.15 | G32: =B32*D32 -> 115.00976 | H32: =C32*E32 -> 34.851443 | I32: =F32 -> 0 | J32: =MAX(G32,H32,I32) -> 115.00976 | K32: Breakrooms/Occupancy Category - Office Buildings
A33: =Zones!B33 -> Stairway_FloorM | B33: =Zones!M33 -> 0 | C33: =Zones!J33 -> 661.39226 | D33: =D15 -> 15 | E33: =E15 -> 0.15 | H33: =C33*E33 -> 99.208839 | I33: =F33 -> 0 | J33: =MAX(G33,H33,I33) -> 99.208839 | K33: All Other
A34: =Zones!B34 -> Corridor_W_FloorM | B34: =Zones!M34 -> 1.5 | C34: =Zones!J34 -> 300 | D34: =D16 -> 15 | E34: =E16 -> 0.15 | G34: =B34*D34 -> 22.5 | H34: =C34*E34 -> 45 | I34: =F34 -> 0 | J34: =MAX(G34,H34,I34) -> 45 | K34: Corridors /Occupancy Category - General
A35: =Zones!B35 -> Corridor_N_FloorM | B35: =Zones!M35 -> 2.514862 | C35: =Zones!J35 -> 502.9724 | D35: =D17 -> 15 | E35: =E17 -> 0.15 | G35: =B35*D35 -> 37.72293 | H35: =C35*E35 -> 75.44586 | I35: =F35 -> 0 | J35: =MAX(G35,H35,I35) -> 75.44586 | K35: Corridors /Occupancy Category - General
A36: =Zones!B36 -> Corridor_E_FloorM | B36: =Zones!M36 -> 1.496038 | C36: =Zones!J36 -> 299.2076 | D36: =D18 -> 15 | E36: =E18 -> 0.15 | G36: =B36*D36 -> 22.44057 | H36: =C36*E36 -> 44.88114 | I36: =F36 -> 0 | J36: =MAX(G36,H36,I36) -> 44.88114 | K36: Corridors /Occupancy Category - General
A37: =Zones!B37 -> Corridor_S_FloorM | B37: =Zones!M37 -> 2.514862 | C37: =Zones!J37 -> 502.9724 | D37: =D19 -> 15 | E37: =E19 -> 0.15 | G37: =B37*D37 -> 37.72293 | H37: =C37*E37 -> 75.44586 | I37: =F37 -> 0 | J37: =MAX(G37,H37,I37) -> 75.44586 | K37: Corridors /Occupancy Category - General
A38: =Zones!B38 -> Plenum_FloorM | B38: =Zones!M38 -> 0 | C38: =Zones!J38 -> 17875.932 | D38: =D20 -> 0 | E38: =E20 -> - | I38: =F38 -> 0 | J38: =MAX(G38,H38,I38) -> 0 | K38: -
A39: =Zones!B39 -> Open_Office_Core_FloorT | B39: =Zones!M39 -> 21.415 | C39: =Zones!J39 -> 4283 | D39: =D3 -> 15 | E39: =E3 -> 0.15 | G39: =B39*D39 -> 321.225 | H39: =C39*E39 -> 642.45 | I39: =F39 -> 0 | J39: =MAX(G39,H39,I39) -> 642.45 | K39: Office space/Occupancy Category - Office Buildings
A40: =Zones!B40 -> Open_Office_N_FloorT | B40: =Zones!M40 -> 11.489937 | C40: =Zones!J40 -> 2297.9873 | D40: =D4 -> 15 | E40: =E4 -> 0.15 | G40: =B40*D40 -> 172.34905 | H40: =C40*E40 -> 344.6981 | I40: =F40 -> 0 | J40: =MAX(G40,H40,I40) -> 344.6981 | K40: Office space/Occupancy Category - Office Buildings
...

Sheet Water Heater
A1: Water Heater - OfficeMedium
A2: Vintage | B2: WH Type | C2: Efficiency | D2: Number of WH | E2: Tank Volume (gal) | F2: Tank Loss | G2: Source
A3: Existing | B3: Gas | C3: 0.8 | D3: 1 | E3: ="See table below for CZ-specific values: "&A73&", Storage Volume column (col F)" -> See table below for CZ-specific values: Climate Zone Water Heater Sizing and Loss Coefficients, Storage Volume column (col F) | F3: ="See table below: "&A73&", Standby Loss column (col G)" -> See table below: Climate Zone Water Heater Sizing and Loss Coefficients, Standby Loss column (col G) | G3: ="See table below for sources: "&A73 -> See table below for sources: Climate Zone Water Heater Sizing and Loss Coefficients
A4: New Construction | B4: Gas | C4: 0.8 | D4: 1 | E4: =E3 -> See table below for CZ-specific values: Climate Zone Water Heater Sizing and Loss Coefficients, Storage Volume column (col F) | F4: =F3 -> See table below: Climate Zone Water Heater Sizing and Loss Coefficients, Standby Loss column (col G) | G4: =G3 -> See table below for sources: Climate Zone Water Heater Sizing and Loss Coefficients
A8: Peak Hot Water Consumption
A9: Space Name | B9: Baseline WH Type [T24, 2022, Appendix 5.4A , sheet: "2022 SpaceFuncData-Input"] | C9: Total Area (ft²) | E9: Number of People | F9: Hot Water Usage Specification (gal/hr per person) [T24, 2022, Appendix 5.4A , sheet: "2022 SpaceFuncData-Input"] | G9: Peak Hot Water Usage (gal/hr) | H9: Peak Hot Water Usage (gal/min) | I9: Note
A10: =Zones!B3 -> Open_Office_Core_FloorG | B10: Gas* | C10: =Zones!J3*Zones!L3 -> 4283 | E10: =Zones!M3*Zones!L3 -> 21.415 | F10: 0.18 | G10: =E10*F10 -> 3.8547 | H10: =G10/60 -> 0.064245 | I10: For space types marked with an asterisk (the ‘*’ symbol), the water‑heater type is listed as electric in Appendix 5.4A, sheet ‘2022 SpaceFuncData‑Input.’ However, we modified the value based on CEUS data, which indicates that gas is the primary fuel type.
A11: =Zones!B4 -> Open_Office_N_FloorG | B11: Gas* | C11: =Zones!J4*Zones!L4 -> 2297.9873 | E11: =Zones!M4*Zones!L4 -> 11.489937 | F11: 0.18 | G11: =E11*F11 -> 2.0681886 | H11: =G11/60 -> 0.03446981
A12: =Zones!B5 -> Enclosed_Office_W_FloorG | B12: Gas* | C12: =Zones!J5*Zones!L5 -> 1637.8612 | E12: =Zones!M5*Zones!L5 -> 8.1893058 | F12: 0.18 | G12: =E12*F12 -> 1.474075 | H12: =G12/60 -> 0.024567917
A13: =Zones!B6 -> Enclosed_Office_E_FloorG | B13: Gas* | C13: =Zones!J6*Zones!L6 -> 1637.8612 | E13: =Zones!M6*Zones!L6 -> 8.1893058 | F13: 0.18 | G13: =E13*F13 -> 1.474075 | H13: =G13/60 -> 0.024567917
A14: =Zones!B7 -> Open_Office_S_FloorG | B14: Gas* | C14: =Zones!J7*Zones!L7 -> 1186.2075 | E14: =Zones!M7*Zones!L7 -> 5.9310376 | F14: 0.18 | G14: =E14*F14 -> 1.0675868 | H14: =G14/60 -> 0.017793113
A15: =Zones!B8 -> Conference_FloorG | B15: Gas* | C15: =Zones!J8*Zones!L8 -> 1111.7798 | E15: =Zones!M8*Zones!L8 -> 36.688734 | F15: 0.09 | G15: =E15*F15 -> 3.301986 | H15: =G15/60 -> 0.055033101
A16: =Zones!B9 -> Lobby_FloorG | B16: Gas | C16: =Zones!J9*Zones!L9 -> 1059.1755 | E16: =Zones!M9*Zones!L9 -> 10.591755 | F16: 0.09 | G16: =E16*F16 -> 0.95325792 | H16: =G16/60 -> 0.015887632
A17: =Zones!B10 -> Storage_FloorG | B17: Gas* | C17: =Zones!J10*Zones!L10 -> 983.15611 | F17: 0 | G17: =E17*F17 -> 0 | H17: =G17/60 -> 0
A18: =Zones!B11 -> Mechanical/Electrical_FloorG | B18: Gas* | C18: =Zones!J11*Zones!L11 -> 357.35034 | F18: 0.18 | G18: =E18*F18 -> 0 | H18: =G18/60 -> 0
A19: =Zones!B12 -> IT-Room_FloorG | B19: Gas* | C19: =Zones!J12*Zones!L12 -> 178.9373 | F19: 0.18 | G19: =E19*F19 -> 0 | H19: =G19/60 -> 0
A20: =Zones!B13 -> Restroom_FloorG | B20: Gas | C20: =Zones!J13*Zones!L13 -> 643.57783 | F20: 0 | G20: =E20*F20 -> 0 | H20: =G20/60 -> 0
A21: =Zones!B14 -> BreakRoom/Kitchenette_FloorG | B21: Gas | C21: =Zones!J14*Zones!L14 -> 232.34295 | E21: =Zones!M14*Zones!L14 -> 7.6673175 | F21: 0.578 | G21: =E21*F21 -> 4.4317095 | H21: =G21/60 -> 0.073861825
A22: =Zones!B15 -> Stairway_FloorG | B22: Gas* | C22: =Zones!J15*Zones!L15 -> 661.39226 | F22: 0 | G22: =E22*F22 -> 0 | H22: =G22/60 -> 0
A23: =Zones!B16 -> Corridor_W_FloorG | B23: Gas* | C23: =Zones!J16*Zones!L16 -> 300 | E23: =Zones!M16*Zones!L16 -> 1.5 | F23: 0 | G23: =E23*F23 -> 0 | H23: =G23/60 -> 0
A24: =Zones!B17 -> Corridor_N_FloorG | B24: Gas* | C24: =Zones!J17*Zones!L17 -> 502.9724 | E24: =Zones!M17*Zones!L17 -> 2.514862 | F24: 0 | G24: =E24*F24 -> 0 | H24: =G24/60 -> 0
A25: =Zones!B18 -> Corridor_E_FloorG | B25: Gas* | C25: =Zones!J18*Zones!L18 -> 299.2076 | E25: =Zones!M18*Zones!L18 -> 1.496038 | F25: 0 | G25: =E25*F25 -> 0 | H25: =G25/60 -> 0
A26: =Zones!B19 -> Corridor_S_FloorG | B26: Gas* | C26: =Zones!J19*Zones!L19 -> 502.9724 | E26: =Zones!M19*Zones!L19 -> 2.514862 | F26: 0 | G26: =E26*F26 -> 0 | H26: =G26/60 -> 0
A27: =Zones!B20 -> Plenum_FloorG | C27: =Zones!J20*Zones!L20 -> 17875.932 | F27: 0 | G27: =E27*F27 -> 0 | H27: =G27/60 -> 0
A28: =Zones!B21 -> Open_Office_Core_FloorM | B28: Gas* | C28: =Zones!J21*Zones!L21 -> 4283 | E28: =Zones!M21*Zones!L21 -> 21.415 | F28: 0.18 | G28: =E28*F28 -> 3.8547 | H28: =G28/60 -> 0.064245
A29: =Zones!B22 -> Open_Office_N_FloorM | B29: Gas* | C29: =Zones!J22*Zones!L22 -> 2297.9873 | E29: =Zones!M22*Zones!L22 -> 11.489937 | F29: 0.18 | G29: =E29*F29 -> 2.0681886 | H29: =G29/60 -> 0.03446981
A30: =Zones!B23 -> Enclosed_Office_W_FloorM | B30: Gas* | C30: =Zones!J23*Zones!L23 -> 1637.8612 | E30: =Zones!M23*Zones!L23 -> 8.1893058 | F30: 0.18 | G30: =E30*F30 -> 1.474075 | H30: =G30/60 -> 0.024567917
A31: =Zones!B24 -> Enclosed_Office_E_FloorM | B31: Gas* | C31: =Zones!J24*Zones!L24 -> 1637.8612 | E31: =Zones!M24*Zones!L24 -> 8.1893058 | F31: 0.18 | G31: =E31*F31 -> 1.474075 | H31: =G31/60 -> 0.024567917
A32: =Zones!B25 -> Open_Office_S_FloorM | B32: Gas* | C32: =Zones!J25*Zones!L25 -> 1186.2075 | E32: =Zones!M25*Zones!L25 -> 5.9310376 | F32: 0.18 | G32: =E32*F32 -> 1.0675868 | H32: =G32/60 -> 0.017793113
