Workbook
Name nonparticipating_forecastzone_scale_factor: #REF!
Name nonparticipating_forecastzone_scale_factor: 'Energy Usage'!#REF!
Name Space_Function: Data!$A$2:$A$76

Sheet Notes
A1: Data Sources
A2: Dataset | B2: Dodge 2023
B3: Commercial End-Use Survey (CEUS) 2022 | C3: https://www.energy.ca.gov/publications/2023/2022-california-commercial-end-use-survey-ceus-final-report
B4: Commercial Buildings Energy Consumption Survey (CBECS) 2018 | C4: https://www.eia.gov/consumption/commercial/data/2018/
B5: ComStock 2023 | C5: https://comstock.nlr.gov/page/datasets
A6: Prototypes | B6: California Energy Commission (CEC) Small Office prototype (CBECC 2022.3.1) | C6: https://bees.noresco.com/software2022.html
B7: Pacific Northwest National Laboratory (PNNL) Small Office prototype (90.1-2022) | C7: https://www.energycodes.gov/prototype-building-models#Commercial
B8: Database for Energy Efficient Resources (DEER) Small Office prototype (June 2023) | C8: https://github.com/sound-data/DEER-Prototypes-EnergyPlus
B9: Oak Ridge National Laboratory (ORNL) 2019 Small Office prototype zoning | C9: https://web.eecs.utk.edu/~jnew1/publications/2019_IBPSA_OpenStudioOffice.pdf
A10: Codes | B10: Title 24, part 6, referred to as T24 (1984, 1992,1998, 2001, 2005, 2008, 2013, 2016,2019, 2022, 2025) | C10: https://www.energy.ca.gov/publications/2025/2025-building-energy-efficiency-standards-residential-and-nonresidential | D10: 2025
C11: https://codes.iccsafe.org/codes/united-states/california | D11: 2010+
B12: Title 20 | C12: https://govt.westlaw.com/calregs/Document/I270DCA634B4011EFA8F7F119BAF97AD6?viewType=FullText&originationContext=documenttoc&transitionType=CategoryPageItem&contextData=(sc.Default)
B13: American Society of Heating, Refrigerating and Air-Conditioning Engineers (ASHRAE) 90.1 (2022) | C13: https://www.ashrae.org/technical-resources/standards-and-guidelines/read-only-versions-of-ashrae-standards
B14: Code of Federal Regulations (CFR) Title 10 (2010) | C14: https://www.govinfo.gov/content/pkg/FR-2009-03-23/pdf/FR-2009-03-23.pdf
B15: CFR Title 10 (2013) | C15: https://www.govinfo.gov/content/pkg/CFR-2013-title10-vol3/pdf/CFR-2013-title10-vol3-part431.pdf
B16: CFR Title 10 (2024) | C16: https://www.govinfo.gov/content/pkg/CFR-2024-title10-vol3/pdf/CFR-2024-title10-vol3-part431-subpartF.pdf
A17: Others | B17: Massachusetts uses commercial prototype for its stretch code energy analysis and the above ones are the supporting documents for small office prototype | C17: https://www.mass.gov/lists/stretch-energy-code-development-support-documentation
C18: https://www.mass.gov/doc/small-office-prototype-basis-of-design-report/download
B19: Alternative Calculation Method (ACM) (2022) | C19: https://www.energy.ca.gov/publications/2022/2022-nonresidential-and-multifamily-alternative-calculation-method-reference
B20: ACM (2025) | C20: https://www.energy.ca.gov/publications/2025/2025-nonresidential-and-multifamily-alternative-calculation-method-reference
B21: Title 24, 2025, Appendix B: Water Heating Calculation Method | C21: https://www.energy.ca.gov/sites/default/files/2025-11/CEC-400-2025-006-AP-B.pdf
B22: Nonres ACM 2022, Appendix 5.4A and Appendix 5.4B | C22: https://www.energy.ca.gov/publications/2022/2022-nonresidential-and-multifamily-alternative-calculation-method-reference
B23: 2022 Reduced infiltration Codes and Standards Enhancement (CASE) report | C23: https://title24stakeholders.com/wp-content/uploads/2020/10/2022-T24-Final-CASE-Report_Reduce-Infiltration.pdf
B24: 2019 Outdoor Lighting CASE Report | C24: https://title24stakeholders.com/wp-content/uploads/2016/10/T24-2019-CASE-Study-Results-Report-Outdoor-Sources_Final_with-Attachments.pdf
B25: PNNL 20405, 2011 | C25: https://www.pnnl.gov/main/publications/external/technical_reports/PNNL-20405.pdf
B26: Air leakage Memo, NORESCO, 2025 | C26: Infiltration_rate_report_14May2025-Short-Version.docx
B27: Yousefi, F., Athalye, R., (2025), "Determining Vintage Bins for Prototype Development: An Analysis of California Commercial Buildings," ASHRAE Annual Conference | C27: https://www.thefreelibrary.com/Determining+Vintage+Bins+for+Prototype+Development%3a+An+Analysis+of...-a0879271125
B28: Proposed Updates to Equipment Power Densities and Building Schedules for the 2028 Energy Code, referred to as "Plug load and schedules project with CEC, 2025" (Docket Number =25-BSTD-03 & TN=265693) | C28: https://efiling.energy.ca.gov/GetDocument.aspx?tn=265693&DocumentContentId=102545
B29: Yousefi, F., Athalye, R. (2026). "Developing a New Set of Prototypical Models for Office Buildings in California," IBPSA-USA Conference | C29: https://publications.ibpsa.org/conference/paper/?id=simbuild2026_1372
B30: ENERGY STAR certified commercial water heaters | C30: https://www.energystar.gov/productfinder/product/certified-commercial-water-heaters/results?fuel_filter=Gas&markets_filter=United+States
... B32: Grainger electric tank water heaters | C32: https://www.grainger.com/category/plumbing/water-heaters/electric-tank-water-heaters
A35: Construction Rate
F39: 1978-84 | G39: 1985-97 | H39: 1992-1997
E40: Construction rate (Dodge 2023 data for new small offices) | F40: 0.46536943 | G40: 0.53462988 | H40: 0.093651419
B47: Source:Dodge Construction Data, 2023 ( NEW small office built after 1967) (STC refers to building types in Dodge terminology).
A48: Notes
A49: OfficeSmall Prototype | B49: The Small Office prototype was developed to represent California office buildings below 25,000 ft². Based on California construction data, the existing CEC/PNNL Small Office geometry was retained because it aligned well with observed building stock characteristics. The prototype is modeled as a one-story building with a total floor area of 5,502 ft². Its zoning layout was updated using ORNL-based layouts, with modifications to better reflect current design practice and simplify the model. These changes included consolidating spaces, reducing the total number of thermal zones, and incorporating elevator space into the vertical circulation area. The resulting Small Office prototype includes approximately 49.6% office space, 8.3% conference space, 13.5% storage, 12.1% corridor, 8.3% lobby, 4.1% restroom, 2% breakroom, and 2.1% mechanical room. The same geometry and zoning layout are applied across vintages and California climate zones. Information about the geometry and underlying logic of the office prototypes can be found in this paper: "Yousefi, F., Athalye, R. (2026). ‘Developing a New Set of Prototypical Models for Office Buildings in California." IBPSA-USA Conference. The link is provided above in the Data Source section. The floor area was slightly modified in some spaces during the geometry‑drawing phase.
A50: 1986 is the representative year for the 1984-1997 vintage bin | B50: Most offices in this vintage bin were built after 1984 (more than 53% ) and the CA energy code did not noticeably change between 1984 and 1992. Edition 1986 included 6 prescriptive packages per CZ for office buildings compared to 1984 with 3 package per CZ. Also "Heat Capacity" for external wall is considered between 10.0 to 14.99 (BTU/F/ft²) Package A was selected for the thermal properties
A51: 2001 is the representative year for the 1998-2007 vintage bin | B51: Wall and roof prescriptive criteria from 1998 to 2005 remain unchanged except for CZ2 and 6 in 2001 code (the percentage of change is less than 10%). Since the construction rate between 1998-2005 is greater than the 2006-2007 period, the envelope properties of 1998 -2005 were chosen for envelope properties. Since the windows requirement considerably changed in the 2001 code, the nominated year for this vintage is 2001. It should be noticed that, only one Title 24 should be chosen within each vintage bin for building envelope properties since the entire envelope is built at once. We can't choose 1998 for walls and 2001 for windows. Wall and roof prescriptive criteria from 1998 to 2005 remain unchanged except for CZ2 and 6 in 2001 version (the percentage of change is less than 10%).
A52: 2013 is the representative year for the 2008-2018 vintage bin | B52: Wall properties remain unchanged from the 2008 code to the 2016 code but the roof did change. Although the 2016 code introduced improvement for roof in nearly all CZ and for wall in a few CZ, and construction activity surged between 2017 and 2018, the extended period from 2008 to 2016 resulted in a higher construction rate during that time . As a result, it was decided to select the code that was effective during 2008-2016. The 2013 code modified the solar reflectance requirement for low-sloped roof products ( by approximately 15%), and enhanced window properties. Therefore, the 2013 code was chosen as the representative code. Additionally, construction activity from 2014-2018 was higher compared to 2008-2013 period.

Sheet Prototype
A1: NORESCO, Updated September 2026
A2: OfficeSmall
A3: Characteristic | B3: Value | C3: Data Sources
A4: Building Type | B4: Small Office
A5: Building Category | B5: Nonresidential
A6: Version | B6: v2-0
A7: Vintages | B7: 4 Vintages: Pre-1978 , 1978-1997 ,1998-2007 , 2008-2018 New Construction (2019+) | C7: Based on the vintage‑bin analysis. A summary of the findings is presented in the following paper, with a link provided in the Notes tab:: Yousefi, F., Athalye, R. (2025). “Determining Vintage Bins for Prototype Development: An Analysis of California Commercial Buildings.” ASHRAE Annual Conference.
A8: Shape | C8: Assume rectangular shape; supported by CBECS, CEC, and PNNL. The logic behind the geometry of the CalBEM Office prototypes' shell is described in the following paper, with a link provided in the Notes tab: Yousefi, F., & Athalye, R. (2026). "Developing a New Set of Prototypical Models for Office Buildings in California", IBPSA-USA Conference.
A9: Total Floor Area (ft²) | B9: 5502 (90.8 ft x 60.6ft) | C9: Supported by Dodge 2023 data (Same as CEC and PNNL)
A10: Aspect Ratio | B10: 1.5 | C10: Assumption; same as CEC and PNNL Small Office prototype
A11: Number of Floors | B11: 1 | C11: Supported by Dodge 2023 data -(Same as CEC and PNNL) DEER considered two floors
A12: Roof type | B12: Tilted (Steep-Sloped) | C12: Supported by CBECS 2018 data (Same as CEC and PNNL)
A13: WWR | B13: 24.4% for South and 19.8% for the other three orientations | C13: Assumed based on CBECS data as well as CEC and PNNL Small Office prototype. CEC: overall 21.2% same as PNNL DEER: 33% in all directions CBECS: 11-25% (38% of samples have WWR of 11-25%; 33% have WWR 2-10%)
A14: Shading Geometry | B14: No Shades | C14: Assumption; same as CEC and PNNL Small Office prototype
A15: Floor to floor height (feet) | B15: 10 | C15: Assumption, standard ceiling height in office buildings; same as CEC and PNNL Small Office prototype.
A16: Floor to ceiling height (feet) | B16: 10 | C16: Assumption; same as CEC and PNNL Small Office prototype
A17: Glazing sill height (feet) | B17: 3 (top of the window is 8 ft high with 5 ft high glass) | C17: Assumption; same as CEC and PNNL Small Office prototype
A66: Background Data [To be deleted prior to publication]
D72: Equipment (Plug Load )- Prototypes comparison
D73: Unit | E73: CEC OffSml | F73: DEER OFS | G73: PNNL | H73: ComStock | I73: Note
D74: W/ft2 | E74: 1.5 | F74: 1.5 | G74: 0.63 | I74: PNNL considers higher load for electric equipment
D75: Yearly Load multiplier | E75: =SUM(Schedules!#REF!)*249+SUM(Schedules!#REF!)*52+SUM(Schedules!#REF!)*(364-249-52) -> #REF! | F75: =SUM(Schedules!#REF!)*249+SUM(Schedules!#REF!)*52+SUM(Schedules!#REF!)*(364-249-52) -> #REF! | G75: =SUM(Schedules!#REF!)*249+SUM(Schedules!#REF!)*52+SUM(Schedules!#REF!)*(364-249-52) -> #REF!

Sheet Zones
A1: ="Proposed Layout - "&Prototype!A2 -> Proposed Layout - OfficeSmall
A2: Building | B2: Space/Thermal Zone | C2: Space Type [Primarily from: T24, 2022 Appendix 5.4A] - See Notes column | D2: HVAC System Name | E2: Schedule Category | F2: Conditioned (Y/N) | G2: Area Fraction | H2: Area (ft²) | I2: Volume (ft³) | J2: Multipliers | K2: Number of People | L2: People (Persons/1,000 ft²) [T24, 2025,Table 120.1-A] | M2: Notes | O2: Thermal Zone Layout - Each space has its own thermal zone
A3: Office Small | B3: Open_Office_N | C3: Office Area (>250 square feet) | D3: AHU_N | E3: Office | F3: Yes | G3: =H3/$H$17 -> 0.16588271 | H3: 912.6975 | I3: =H3*10 -> 9126.975 | J3: 1 | K3: =L3*H3/1000 -> 4.5634875 | L3: 5
A4: Office Small | B4: Enclosed_Office_W | C4: Office Area (>250 square feet) | D4: AHU_W | E4: Office | F4: Yes | G4: =H4/$H$17 -> 0.16511254 | H4: 908.46 | I4: =H4*10 -> 9084.6 | J4: 1 | K4: =L4*H4/1000 -> 4.5423 | L4: 5
A5: Office Small | B5: Enclosed_Office_E | C5: Office Area (>250 square feet) | D5: AHU_E | E5: Office | F5: Yes | G5: =H5/$H$17 -> 0.16511254 | H5: 908.46 | I5: =H5*10 -> 9084.6 | J5: 1 | K5: =L5*H5/1000 -> 4.5423 | L5: 5
A6: Office Small | B6: Conference | C6: Convention, Conference, Multipurpose and Meeting Area | D6: AHU_S | E6: Office | F6: Yes | G6: =H6/$H$17 -> 0.08294158 | H6: 456.35 | I6: =H6*10 -> 4563.5 | J6: 1 | K6: =L6*H6/1000 -> 15.05955 | L6: 33
A7: Office Small | B7: Lobby_Lounge | C7: Lobby, Main Entry | D7: AHU_S | E7: Office | F7: Yes | G7: =H7/$H$17 -> 0.08294158 | H7: 456.35 | I7: =H7*10 -> 4563.5 | J7: 1 | K7: =L7*H7/1000 -> 4.5635 | L7: 10 | M7: For entrance lobbies, assumed 10 persons/1000 ft² based on ASHRAE 62.1 Table 6-1 T24 assumed 33 persons/1,000 ft² for main Entry lobbies & 5 persons/1000 ft² for reception area
A8: Office Small | B8: Storage | C8: Storage (General) | D8: AHU_W | E8: Office | F8: Yes | G8: =H8/$H$17 -> 0.13520158 | H8: 743.88791 | I8: =H8*10 -> 7438.8791 | J8: 1 | K8: =L8*H8/1000 -> 0 | L8: 0 | M8: Occupant load density for storage is based on T24, 2025, Appendix 5.4A. Conditioned but with higher cooling setpoint
A9: Office Small | B9: Mechanical_Electrical | C9: Electrical, Mechanical, Telephone Rooms | D9: AHU_S | E9: Ancillary | F9: Yes | G9: =H9/$H$17 -> 0.020761294 | H9: 114.23 | I9: =H9*10 -> 1142.3 | J9: 1 | L9: - | M9: Conditioned but with higher cooling setpoint
A10: Office Small | B10: Restroom | C10: Restrooms | E10: Office | F10: Yes | G10: =H10/$H$17 -> 0.040762874 | H10: 224.28 | I10: =H10*10 -> 2242.8 | J10: 1 | L10: - | M10: Indirectly conditioned
A11: Office Small | B11: Break_CopyRoom | C11: Lounge, Breakroom, or Waiting Area | D11: AHU_S | E11: Office | F11: Yes | G11: =H11/$H$17 -> 0.02000158 | H11: 110.05 | I11: =H11*10 -> 1100.5 | J11: 1 | K11: =L11*H11/1000 -> 3.63165 | L11: 33
A12: Office Small | B12: Corridor_W | C12: Corridor Area | D12: AHU_W | E12: Office | F12: Yes | G12: =H12/$H$17 -> 0.022220746 | H12: 122.26 | I12: =H12*10 -> 1222.6 | J12: 1 | K12: =L12*H12/1000 -> 0.6113 | L12: 5
A13: Office Small | B13: Corridor_N | C13: Corridor Area | D13: AHU_N | E13: Office | F13: Yes | G13: =H13/$H$17 -> 0.038420118 | H13: 211.39 | I13: =H13*10 -> 2113.9 | J13: 1 | K13: =L13*H13/1000 -> 1.05695 | L13: 5
A14: Office Small | B14: Corridor_E | C14: Corridor Area | D14: AHU_E | E14: Office | F14: Yes | G14: =H14/$H$17 -> 0.022220746 | H14: 122.26 | I14: =H14*10 -> 1222.6 | J14: 1 | K14: =L14*H14/1000 -> 0.6113 | L14: 5
A15: Office Small | B15: Corridor_S | C15: Corridor Area | D15: AHU_S | E15: Office | F15: Yes | G15: =H15/$H$17 -> 0.038420118 | H15: 211.39 | I15: =H15*10 -> 2113.9 | J15: 1 | K15: =L15*H15/1000 -> 1.05695 | L15: 5
A16: Office Small | B16: Attic | C16: Attic | D16: - | F16: No | G16: 1 | H16: 6114.3047 | I16: 25437.111 | J16: 1 | L16: -
A17: Total ( 1 Building) | B17: Total (14 Space) | C17: Total (9 Space) | D17: Total (4 HVAC system) | E17: Total (1 category) | F17: Total (4 Conditioned zones, 1 Unconditioned Zones) | G17: =SUM(G3:G15) -> 1 | H17: =SUM(H3:H15) -> 5502.0654 | I17: =SUM(I3:I16) -> 80457.765 | J17: 1
B19: Ref: Geometry and zones: ORNL 2019 small office prototype with modification | O19: Area Distribution By Space Type
B20: https://web.eecs.utk.edu/~jnew1/publications/2019_IBPSA_OpenStudioOffice.pdf | O20: Space Type | R20: % Area
B21: https://web.eecs.utk.edu/~jnew1/presentations/2019_IBPSA_OpenStudioOffice.pdf | O21: Office Area (>250 square feet) | R21: =SUM(G3:G5) -> 0.49610779
O22: Convention, Conference, Multipurpose and Meeting Area | R22: =G6 -> 0.08294158
O23: Lobby, Main Entry | R23: =G7 -> 0.08294158
O24: Storage (General) | R24: =G8 -> 0.13520158
O25: Electrical, Mechanical, Telephone Rooms | R25: =G9 -> 0.020761294
O26: Restrooms | R26: =G10 -> 0.040762874
O27: Lounge, Breakroom, or Waiting Area | R27: =G11 -> 0.02000158
O28: Corridor Area | R28: =SUM(G12:G15) -> 0.12128173
O29: Total | R29: =SUM(R21:R28) -> 1

Sheet Envelope
A1: ="Envelope - "&Prototype!A2 -> Envelope - OfficeSmall
A2: Element | B2: Prototype | C2: Assembly Type | D2: Construction | E2: Thermal Properties | F2: Vintage | G2: Selected T24 | H2: Notes | I2: CZ1 | J2: CZ2 | K2: CZ3 | L2: CZ4 | M2: CZ5 | N2: CZ6 | O2: CZ7 | P2: CZ8 | Q2: CZ9 | R2: CZ10 | S2: CZ11 | T2: CZ12 | U2: CZ13 | V2: CZ14 | W2: CZ15 | X2: CZ16
A3: External Wall | B3: OfficeSmall | C3: ExtWall_WoodFramed_NonRes | D3: Wood framed wall: Wood frame + insulation + Gypsum board | E3: U-factor IP | F3: Pre 1978 | G3: N/A | H3: Using ASHRAE 90.1, 2022 Table A3.4.3.1, 3.5", R-1.5 U-values and a 7.4% cumulative wall renovation rate through 2028, based on the average annual rate from CBECS 2003 and 2012 projected over 48 years. | I3: =I42*$I$44+I43*(1-$I$44) -> 0.1946 | J3: =J42*$I$44+J43*(1-$I$44) -> 0.191418 | K3: =K42*$I$44+K43*(1-$I$44) -> 0.195192 | L3: =L42*$I$44+L43*(1-$I$44) -> 0.191418 | M3: =M42*$I$44+M43*(1-$I$44) -> 0.1946 | N3: =N42*$I$44+N43*(1-$I$44) -> 0.195192 | O3: =O42*$I$44+O43*(1-$I$44) -> 0.195192 | P3: =P42*$I$44+P43*(1-$I$44) -> 0.1946 | ... X3: =X42*$I$44+X43*(1-$I$44) -> 0.191418
F4: 1978-1997 | G4: 1986 | H4: Table 2-53V-16: Package A/ Heat Capacity was considered 0-3.99 (BTU/F/ft²) | I4: =1/7.52 -> 0.13297872 | J4: =1/7.52 -> 0.13297872 | K4: =1/7.52 -> 0.13297872 | L4: =1/7.52 -> 0.13297872 | M4: =1/7.52 -> 0.13297872 | N4: =1/7.52 -> 0.13297872 | O4: =1/7.52 -> 0.13297872 | P4: =1/7.52 -> 0.13297872 | ... X4: =1/7.52 -> 0.13297872
F5: 1998-2007 | G5: 2001 | H5: Table 1-H | I5: 0.084 | J5: 0.084 | K5: 0.092 | L5: 0.092 | M5: 0.092 | N5: 0.092 | O5: 0.092 | P5: 0.092 | Q5: 0.092 | R5: 0.084 | S5: 0.084 | T5: 0.084 | U5: 0.084 | V5: 0.084 | W5: 0.084 | X5: 0.084
F6: 2008-2018 | G6: 2013 | H6: Table 140.3-B | I6: 0.102 | J6: 0.059 | K6: 0.11 | L6: 0.059 | M6: 0.102 | N6: 0.11 | O6: 0.11 | P6: 0.102 | Q6: 0.059 | R6: 0.059 | S6: 0.059 | T6: 0.059 | U6: 0.059 | V6: 0.059 | W6: 0.042 | X6: 0.059
F7: Existing | H7: Weighted average of all 4 vintages | I7: {=_xlfn.BYCOL(TRANSPOSE(Weights!$C$4:$F$19)*I3:X6,_xlfn.LAMBDA(_xlpm.c,SUM(_xlpm.c)))} -> 0.14336934 | J7: 0.1505756 | K7: 0.15957316 | L7: 0.15663464 | M7: 0.15606378 | N7: 0.15907356 | O7: 0.14825583 | P7: 0.16481685 | Q7: 0.16286488 | R7: 0.13009248 | S7: 0.12869445 | T7: 0.13262571 | U7: 0.13127339 | V7: 0.14234525 | W7: 0.11736183 | X7: 0.1303404
F8: 2019+ | G8: 2025 | H8: Table 140.3-B | I8: 0.078 | J8: 0.053 | K8: 0.102 | L8: 0.053 | M8: 0.095 | N8: 0.102 | O8: 0.102 | P8: 0.095 | Q8: 0.053 | R8: 0.053 | S8: 0.042 | T8: 0.053 | U8: 0.053 | V8: 0.053 | W8: 0.038 | X8: 0.053
A9: Flat Roof | B9: OfficeSmall | C9: AtticFloor Reversed | D9: Ceiling: Wood-frame roof + insulation + Acoustic tile/Gypsum board (Attic Roof: Asphalt shingle + Plywood) | E9: U-factor IP | F9: Pre 1978 | G9: 1992 | H9: Table 2-53V-16: Considering 30 years for roof/ insulation replacement. | I9: 0.057 | J9: 0.057 | K9: 0.057 | L9: 0.057 | M9: 0.057 | N9: 0.078 | O9: 0.078 | P9: 0.078 | Q9: 0.078 | R9: 0.078 | S9: 0.057 | T9: 0.057 | U9: 0.057 | V9: 0.057 | W9: 0.057 | X9: 0.057
F10: 1978-1997 | G10: 1992 | I10: 0.057 | J10: 0.057 | K10: 0.057 | L10: 0.057 | M10: 0.057 | N10: 0.078 | O10: 0.078 | P10: 0.078 | Q10: 0.078 | R10: 0.078 | S10: 0.057 | T10: 0.057 | U10: 0.057 | V10: 0.057 | W10: 0.057 | X10: 0.057
F11: 1998-2007 | G11: 2001 | H11: Table 1-H | I11: 0.057 | J11: 0.057 | K11: 0.057 | L11: 0.057 | M11: 0.057 | N11: 0.078 | O11: 0.078 | P11: 0.078 | Q11: 0.078 | R11: 0.057 | S11: 0.057 | T11: 0.057 | U11: 0.057 | V11: 0.057 | W11: 0.057 | X11: 0.057
F12: 2008-2018 | G12: 2013 | H12: Table 140.3-B | I12: 0.049 | J12: 0.039 | K12: 0.039 | L12: 0.039 | M12: 0.049 | N12: 0.075 | O12: 0.067 | P12: 0.067 | Q12: 0.039 | R12: 0.039 | S12: 0.039 | T12: 0.039 | U12: 0.039 | V12: 0.039 | W12: 0.039 | X12: 0.039
F13: Existing | H13: Weighted average of all 4 vintages | I13: {=_xlfn.BYCOL(TRANSPOSE(Weights!$C$4:$F$19)*I9:X12,_xlfn.LAMBDA(_xlpm.c,SUM(_xlpm.c)))} -> 0.05636875 | J13: 0.056057075 | K13: 0.056204388 | L13: 0.056203234 | M13: 0.056676628 | N13: 0.077856798 | O13: 0.077610801 | P13: 0.077642422 | Q13: 0.076239747 | R13: 0.069797964 | S13: 0.055605952 | T13: 0.055795735 | U13: 0.055246033 | V13: 0.055808861 | W13: 0.054505895 | X13: 0.055360241
F14: 2019+ | G14: 2025 | H14: Table 140.3-B | I14: 0.028 | J14: 0.028 | K14: 0.028 | L14: 0.028 | M14: 0.028 | N14: 0.047 | O14: 0.047 | P14: 0.047 | Q14: 0.028 | R14: 0.028 | S14: 0.028 | T14: 0.028 | U14: 0.028 | V14: 0.028 | W14: 0.028 | X14: 0.028
A15: Windows | B15: OfficeSmall | C15: FixedWindow_NonRes | D15: Mix Single and Double: CBECS 2018 shows that ~53% of small offices that were built before 2000 are single pane | E15: U-factor IP | F15: Pre 1978 | G15: N/A | H15: ASHRAE Handbook of Fundamentals (Table 10-Ch15) for single pane & T24, 2013 for double pane(53%-47%)* | I15: =1.12*0.53+I$17*0.47 -> 0.8239 | J15: =1.12*0.53+J$17*0.47 -> 0.8239 | K15: =1.12*0.53+K$17*0.47 -> 0.9743 | L15: =1.12*0.53+L$17*0.47 -> 0.9743 | M15: =1.12*0.53+M$17*0.47 -> 0.9743 | N15: =1.12*0.53+N$17*0.47 -> 0.9743 | O15: =1.12*0.53+O$17*0.47 -> 0.9743 | P15: =1.12*0.53+P$17*0.47 -> 0.9743 | ... X15: =1.12*0.53+X$17*0.47 -> 0.8239
F16: 1978-1997 | G16: N/A | I16: =1.12*0.53+I$17*0.47 -> 0.8239 | J16: =1.12*0.53+J$17*0.47 -> 0.8239 | K16: =1.12*0.53+K$17*0.47 -> 0.9743 | L16: =1.12*0.53+L$17*0.47 -> 0.9743 | M16: =1.12*0.53+M$17*0.47 -> 0.9743 | N16: =1.12*0.53+N$17*0.47 -> 0.9743 | O16: =1.12*0.53+O$17*0.47 -> 0.9743 | P16: =1.12*0.53+P$17*0.47 -> 0.9743 | ... X16: =1.12*0.53+X$17*0.47 -> 0.8239
D17: Double pane | F17: 1998-2007 | G17: 2001 | H17: Table 1-H | I17: 0.49 | J17: 0.49 | K17: 0.81 | L17: 0.81 | M17: 0.81 | N17: 0.81 | O17: 0.81 | P17: 0.81 | Q17: 0.81 | R17: 0.49 | S17: 0.49 | T17: 0.49 | U17: 0.49 | V17: 0.49 | W17: 0.49 | X17: 0.49
F18: 2008-2018 | G18: 2013 | H18: Table 140.3-B | I18: 0.36 | J18: 0.36 | K18: 0.36 | L18: 0.36 | M18: 0.36 | N18: 0.36 | O18: 0.36 | P18: 0.36 | Q18: 0.36 | R18: 0.36 | S18: 0.36 | T18: 0.36 | U18: 0.36 | V18: 0.36 | W18: 0.36 | X18: 0.36
F19: Existing | H19: Weighted average of all 4 vintages | I19: {=_xlfn.BYCOL(TRANSPOSE(Weights!$C$4:$F$19)*I15:X18,_xlfn.LAMBDA(_xlpm.c,SUM(_xlpm.c)))} -> 0.721503 | J19: 0.75743588 | K19: 0.92824775 | L19: 0.92940197 | M19: 0.93271218 | N19: 0.932244 | O19: 0.93468982 | P19: 0.94352366 | Q19: 0.93880647 | R19: 0.70774672 | S19: 0.69017369 | T19: 0.70449213 | U19: 0.69611556 | V19: 0.73255375 | W19: 0.66934726 | X19: 0.69598762
F20: 2019+ | G20: 2025 | H20: Table 140.3-B | I20: 0.36 | J20: 0.36 | K20: 0.36 | L20: 0.36 | M20: 0.36 | N20: 0.36 | O20: 0.36 | P20: 0.36 | Q20: 0.34 | R20: 0.36 | S20: 0.34 | T20: 0.34 | U20: 0.34 | V20: 0.34 | W20: 0.34 | X20: 0.36
B21: OfficeSmall | C21: FixedWindow_NonRes | D21: Mix Single and Double: CBECS 2018 shows that ~53% of small offices that were built before 2000 are single pane | E21: SHGC | F21: Pre 1978 | G21: N/A | H21: ASHRAE Handbook of Fundamentals (Table 10-Ch15) for single pane & T24, 2013 for double pane(53%-47%)* | I21: =0.79*0.53+I23*0.47 -> 0.6208 | J21: =0.79*0.53+J23*0.47 -> 0.5879 | K21: =0.79*0.53+K23*0.47 -> 0.6114 | L21: =0.79*0.53+L23*0.47 -> 0.6114 | M21: =0.79*0.53+M23*0.47 -> 0.6114 | N21: =0.79*0.53+N23*0.47 -> 0.602 | O21: =0.79*0.53+O23*0.47 -> 0.602 | P21: =0.79*0.53+P23*0.47 -> 0.602 | ... X21: =0.79*0.53+X23*0.47 -> 0.6208
F22: 1978-1997 | G22: 1986 | I22: =0.79*0.53+I23*0.47 -> 0.6208 | J22: =0.79*0.53+J23*0.47 -> 0.5879 | K22: =0.79*0.53+K23*0.47 -> 0.6114 | L22: =0.79*0.53+L23*0.47 -> 0.6114 | M22: =0.79*0.53+M23*0.47 -> 0.6114 | N22: =0.79*0.53+N23*0.47 -> 0.602 | O22: =0.79*0.53+O23*0.47 -> 0.602 | P22: =0.79*0.53+P23*0.47 -> 0.602 | ... X22: =0.79*0.53+X23*0.47 -> 0.6208
F23: 1998-2007 | G23: 2001 | H23: Table 1-H : WWR:20-30 / SHGC non-north | I23: 0.43 | J23: 0.36 | K23: 0.41 | L23: 0.41 | M23: 0.41 | N23: 0.39 | O23: 0.39 | P23: 0.39 | Q23: 0.39 | R23: 0.36 | S23: 0.36 | T23: 0.36 | U23: 0.36 | V23: 0.36 | W23: 0.36 | X23: 0.43
F24: 2008-2018 | G24: 2013 | H24: Table 140.3-B | I24: 0.25 | J24: 0.25 | K24: 0.25 | L24: 0.25 | M24: 0.25 | N24: 0.25 | O24: 0.25 | P24: 0.25 | Q24: 0.25 | R24: 0.25 | S24: 0.25 | T24: 0.25 | U24: 0.25 | V24: 0.25 | W24: 0.25 | X24: 0.25
F25: Existing | H25: Weighted average of all 4 vintages | I25: {=_xlfn.BYCOL(TRANSPOSE(Weights!$C$4:$F$19)*I21:X24,_xlfn.LAMBDA(_xlpm.c,SUM(_xlpm.c)))} -> 0.55394597 | J25: 0.54142139 | K25: 0.57225848 | L25: 0.57369837 | M25: 0.57625096 | N25: 0.5687679 | O25: 0.56648111 | P25: 0.57661293 | Q25: 0.57609029 | R25: 0.50667911 | S25: 0.4949792 | T25: 0.50497637 | U25: 0.49860946 | V25: 0.52414503 | W25: 0.47946444 | X25: 0.53807688
F26: 2019+ | G26: 2025 | H26: Table 140.3-B | I26: 0.25 | J26: 0.25 | K26: 0.25 | L26: 0.25 | M26: 0.25 | N26: 0.25 | O26: 0.25 | P26: 0.25 | Q26: 0.22 | R26: 0.25 | S26: 0.22 | T26: 0.22 | U26: 0.22 | V26: 0.22 | W26: 0.22 | X26: 0.25
C28: Infiltration
D29: Building | E29: Zones | F29: Vintage | G29: I_75 6-sided Infiltration rate @ 75 pa | H29: Note | I29: I-design (cfm/ft²) (4-sided Infiltration rate at normal pressure) (Design flow rate approach and Flow/Exterior Wall Area calculation method)
C30: Infiltration | D30: OfficeSmall | F30: Pre 1978 | G30: 1.1 | H30: 2022 CASE report (Table 38) | I30: =0.112*G30*$AA$32 -> 0.57095795 | Z30: Building 6 sided area= | AA30: =AA31+(2*AA33) -> 14032.96
F31: 1978-1997 | G31: 1.1 | H31: 2022 CASE report (Table 38) | I31: =0.112*G31*$AA$32 -> 0.57095795 | Z31: Building 4 sided area= | AA31: =AA35 -> 3028
F32: 1998-2007 | G32: 1.1 | H32: 2022 CASE report (Table 38) | I32: =0.112*G32*$AA$32 -> 0.57095795 | Z32: 6 sided /4 sided factor= | AA32: =AA30/AA31 -> 4.6343989
F33: 2008-2018 | G33: 1 | H33: 2022 CASE report (Table 38) & T24, 2008-2016 (Table 140.3-C) | I33: =0.112*G33*$AA$32 -> 0.51905268 | Z33: Floor Area | AA33: =90.8*60.6 -> 5502.48
F34: Existing | G34: 1.1 | H34: Same as Pre 2008 because of their higher weights | I34: =0.112*G34*$AA$32 -> 0.57095795 | Z34: height | AA34: =Prototype!B15 -> 10
F35: 2019+ | G35: 0.6* | H35: 2022 CASE report (Table 38) & T24, 2025 (Table 140.3-C) | I35: =0.112*0.6*$AA$32 -> 0.31143161 | Z35: Wall Area | AA35: =(90.8+60.6)*2*AA34*AA36 -> 3028
E36: Source: Title 24 air barrier requirements (all editions) and the standardized infiltration rate reported in the 2022 CASE report and Dodge 2023 data | Z36: Floor Number | AA36: 1
E37: * Better to consider 0.6 for New construction instead of being very stringent align with the Appendix G of ASHRAE 90.1 (which is almost 0.4)
E38: Air Leakage Memo: | G38: Infiltration_rate_report_14May2025-Short-Version.docx
A40: Pre-1978 U value calculation:
A41: External Wall | B41: OfficeSmall | C41: ExtWall_WoodFramed_NonRes | D41: Wood framed wall: Wood frame + insulation + Gypsum board | E41: U-factor IP | F41: Pre 1978 | G41: N/A | H41: ASHRAE 90.1, 2022 Table A3.4.3.1, 3.5", R-0 | I41: 0.292 | J41: 0.292 | K41: 0.292 | L41: 0.292 | M41: 0.292 | N41: 0.292 | O41: 0.292 | P41: 0.292 | Q41: 0.292 | R41: 0.292 | S41: 0.292 | T41: 0.292 | U41: 0.292 | V41: 0.292 | W41: 0.292 | X41: 0.292
H42: T24 (2008 U value) | I42: 0.102 | J42: 0.059 | K42: 0.11 | L42: 0.059 | M42: 0.102 | N42: 0.11 | O42: 0.11 | P42: 0.102 | Q42: 0.059 | R42: 0.059 | S42: 0.059 | T42: 0.059 | U42: 0.059 | V42: 0.059 | W42: 0.042 | X42: 0.059
...

Sheet HVAC System
A1: ="HVAC System - "&Prototype!A2 -> HVAC System - OfficeSmall | H1: HVAC System Layout
A2: Vintage | B2: Heating | C2: Cooling | D2: Air Distribution | E2: Other Systems | F2: Source
A3: Existing | B3: Furnace (Gas) | C3: Packaged (DX) | D3: Single Duct CAV | E3: OA mixing Economizer for Vintage 3 and 4 DCV for 4 (for qualifying high density rooms) | F3: CEUS 2022
A4: New Construction | B4: Packaged SZ HP | C4: Packaged SZ HP | D4: Single Duct CAV | E4: OA mixing Economizer DCV for qualifying high density rooms | F4: T24 2025
A10: Efficiency of HVAC System (Efficiency is capacity-dependent. The following table provides a general estimate of system efficiency based on what we saw in the existing prototype runs, or assuming cooling load based on rule of thumb)
A11: Vintage | B11: Upgrade Code | C11: Heating | D11: Cooling | E11: Source | G11: COP | H11: Source | I11: R (Adjustment factor)
A12: Pre 1978 | B12: 2008 | C12: Efficiency 80% | D12: SEER=13.0 for <65 kBtu/h 10.1 EER for 65-135 kBtu/h 9.5 EER for 135-240 kBtu/h 9.3 EER & 9.7 IPLV for >240 kBtu/h | E12: T24, Table 112-A (2008) 10 CFR § 431.97, Table 1 (2008) California Title 20 Appliance Efficiency Regulations, Table E-4, Standards for Gas- and Oil-Fired Central Furnaces (2008) | G12: =((9-0.2)/3.413+$I$12)/(1-$I$12) -> 3.0663373 | H12: PNNL,2010,"Technical Support Document: 50% Energy Savings for Small Office Buildings" | I12: 0.12
A13: 1978-1997 | G13: =((9-0.2)/3.413+$I$12)/(1-$I$12) -> 3.0663373
A14: 1998-2007 | G14: =((9-0.2)/3.413+$I$12)/(1-$I$12) -> 3.0663373
A15: 2008-2018 | B15: 2013 | C15: Efficiency 80% | D15: SEER 13 for <65 kBtu/h 11 EER & 11.2 IEER for 65-135 kBtu/h 10.8 EER & 11 IEER for 135-240 kBtu/h 9.8 EER & 9.9 IEER for >240 kBtu/h | E15: T24, 2013 Table 110.2-J & Table 110.2-A (2013) 10 CFR § 431.97(b) Table 1 (2013) | G15: =((9-0.2)/3.413+$I$12)/(1-$I$12) -> 3.0663373
A16: New Construction | B16: 2025 | C16: HSPF 8.0 for <65 kBtu/h COP 3.4 for 65-135 kBtu/h COP 3.3 for 135-240 kBtu/h COP 3.2 for >240 kBtu/h | D16: SEER 14 for <65 kBtu/h EER 10.8, IEER 13.9 for 65-135 kBtu/h EER 10.4, IEER = 13.3 135-240 kBtu/h EER 9.3, IEER=12.3 for >240 kBtu/h | E16: 10 CFR § 431.97(b) Table 1 (2025) Title 20 Appliance Efficiency Regulations, Section 1605.1, Table C-5 (2025) T24, Table 110.2-B (2025) | G16: =((-0.0182*13.4^2+1.1088*13.4)/3.413+I12)/(1-I12) -> 3.9952481
A21: Fan power
A22: Vintage | B22: Approach | C22: System | D22: Total Static Pressure (TSP) (in w.c.) | E22: Fan Efficiency [ACM 2025] | F22: Motor Efficiency | G22: Fan Power Index (W/cfm) | H22: Data Source
A23: Existing | B23: PNNL 90.1-2011, TSP | C23: CAV, design airflow < 7,437 cfm | D23: 2.5 | E23: 0.65 | F23: ASHRAE 90.1, 2004, Table 10.8 * | H23: Fan power formula: PNNL 20405, 2010, section 5.2.2.5 TSP and fan efficiency: PNNL 20405, 2010, Table 5.11, 90.1-04ac values Motor and drive efficiency: ASHRAE 90.1, 2004, Table 10.8 | I23: PNNL 20405, 2010, Table 5.11
A24: Brake horsepower (bhp) = (Supply cfm × TSP in w.c.) / (6356 × fan efficiency)
A25: Fan power (w/cfm) = (bhp × 746) / ( supply cfm × motor efficiency )
A26: New Construction | B26: ACM 2025 | C26: Packaged SZHP (System 3b), CAV, ≤5,000 cfm | D26: TSP = fan power × motor efficiency × fan efficiency × 6356 / 746 | E26: 0.65 | F26: 2025 ACM Table 12 ** | G26: 0.744 | H26: Fan power index: [ACM 2025, Table 13] Motor efficiency: [ACM 2025, Table 12]
A28: * According to PNNL 20405 section 5.2.2.5, the full-load efficiency of the motor serving the fan is taken from ASHRAE 90.1, 2004, Table 10.8, based on motor nameplate and assuming enclosed motors operating at 1,800 rotations per minute (rpm) Motor nameplate size (bhp) = brake horsepower (bhp) × 1.1 ( using a 10% oversizing factor)
A29: ** The full‑load efficiency of the motor serving the fan is taken from ACM 2025 Table 12 based on the cfm of the fan. Brake horsepower (bhp) = (Supply cfm from sizing run × fan power in W/cfm) / 746. Note: Same index as Hotel Small System 3b SZHP ≤5,000 cfm.

Sheet Thermostat
A1: ="Thermostat Setpoints - "&Prototype!A2 -> Thermostat Setpoints - OfficeSmall
A2: Spaces/Zones | B2: Setpoint | C2: CZ1 | D2: CZ2 | E2: CZ3 | F2: CZ4 | G2: CZ5 | H2: CZ6 | I2: CZ7 | J2: CZ8 | K2: CZ9 | L2: CZ10 | M2: CZ11 | N2: CZ12 | O2: CZ13 | P2: CZ14 | Q2: CZ15 | R2: CZ16 | S2: Source
A3: All conditioned zones except Storage & Mechanical_Electrical | B3: Heating Setpoint (F) | C3: 70 | D3: 70 | E3: 70 | F3: 70 | G3: 70 | H3: 70 | I3: 70 | J3: 70 | K3: 70 | L3: 70 | M3: 70 | N3: 70 | O3: 70 | P3: 70 | Q3: 70 | R3: 70 | S3: T24 2022 - Appendix 5.4B
B4: Heating Setback (F) | C4: 60 | D4: 60 | E4: 60 | F4: 60 | G4: 60 | H4: 60 | I4: 60 | J4: 60 | K4: 60 | L4: 60 | M4: 60 | N4: 60 | O4: 60 | P4: 60 | Q4: 60 | R4: 60
B5: Cooling Setpoint (F) | C5: 75 | D5: 75 | E5: 75 | F5: 75 | G5: 75 | H5: 75 | I5: 75 | J5: 75 | K5: 75 | L5: 75 | M5: 75 | N5: 75 | O5: 75 | P5: 75 | Q5: 75 | R5: 75
B6: Cooling Setback (F) | C6: 85 | D6: 85 | E6: 85 | F6: 85 | G6: 85 | H6: 85 | I6: 85 | J6: 85 | K6: 85 | L6: 85 | M6: 85 | N6: 85 | O6: 85 | P6: 85 | Q6: 85 | R6: 85
A7: Storage & Mechanical_Electrical | B7: Heating Setpoint (F) | C7: 60 | D7: 60 | E7: 60 | F7: 60 | G7: 60 | H7: 60 | I7: 60 | J7: 60 | K7: 60 | L7: 60 | M7: 60 | N7: 60 | O7: 60 | P7: 60 | Q7: 60 | R7: 60 | S7: Enginnering Judgment
B8: Heating Setback (F) | C8: 60 | D8: 60 | E8: 60 | F8: 60 | G8: 60 | H8: 60 | I8: 60 | J8: 60 | K8: 60 | L8: 60 | M8: 60 | N8: 60 | O8: 60 | P8: 60 | Q8: 60 | R8: 60
B9: Cooling Setpoint (F) | C9: 85 | D9: 85 | E9: 85 | F9: 85 | G9: 85 | H9: 85 | I9: 85 | J9: 85 | K9: 85 | L9: 85 | M9: 85 | N9: 85 | O9: 85 | P9: 85 | Q9: 85 | R9: 85
B10: Cooling Setback (F) | C10: 85 | D10: 85 | E10: 85 | F10: 85 | G10: 85 | H10: 85 | I10: 85 | J10: 85 | K10: 85 | L10: 85 | M10: 85 | N10: 85 | O10: 85 | P10: 85 | Q10: 85 | R10: 85
B12: Note: The Small Office prototypes by CEC and DEER both use the same setpoints.
B13: Note: The Small Office prototype by PNNL also uses the same setpoints, except for one of the perimeter zones, which has a heating setpoint of 69 °F and a cooling setpoint of 76 °F during hours of 10:00-11:00, 12:00-13:00, and 14:00-15:00 .

Sheet Ventilation
A1: ="Outdoor Airflow Rate - "&Prototype!A2 -> Outdoor Airflow Rate - OfficeSmall
A2: Space/Thermal Zone | B2: Number of People | C2: Floor Area (ft²) | D2: cfm/person (T24, 2025, Equation 120.1-F and Table 120.1-A) | E2: cfm/ft² (T24, 2025, Equation 120.1-F and Table 120.1-A) | F2: Required Exhaust Rate (T24, 2025, Table 120.1-B – Minimum Exhaust Rates) | G2: Total cfm Driven by People | H2: Total cfm Driven by Area | I2: Total cfm Driven by Exhaust | J2: Total cfm | K2: Notes
A3: =Zones!B3 -> Open_Office_N | B3: =Zones!K3 -> 4.5634875 | C3: =Zones!H3 -> 912.6975 | D3: 15 | E3: 0.15 | G3: =B3*D3 -> 68.452313 | H3: =C3*E3 -> 136.90462 | J3: =MAX(G3,H3,I3) -> 136.90462 | K3: Office space/Occupancy Category - Office Buildings | N3: AHU | O3: cfm
A4: =Zones!B4 -> Enclosed_Office_W | B4: =Zones!K4 -> 4.5423 | C4: =Zones!H4 -> 908.46 | D4: 15 | E4: 0.15 | G4: =B4*D4 -> 68.1345 | H4: =C4*E4 -> 136.269 | J4: =MAX(G4,H4,I4) -> 136.269 | K4: Office space/Occupancy Category - Office Buildings | N4: AHU_N | O4: =J3+J12 -> 155.24362
A5: =Zones!B5 -> Enclosed_Office_E | B5: =Zones!K5 -> 4.5423 | C5: =Zones!H5 -> 908.46 | D5: 15 | E5: 0.15 | G5: =B5*D5 -> 68.1345 | H5: =C5*E5 -> 136.269 | J5: =MAX(G5,H5,I5) -> 136.269 | K5: Office space/Occupancy Category - Office Buildings | N5: AHU_W | O5: =J4+J8+J12 -> 266.19119
A6: =Zones!B6 -> Conference | B6: =Zones!K6 -> 15.05955 | C6: =Zones!H6 -> 456.35 | D6: 15 | E6: 0.15 | G6: =B6*D6 -> 225.89325 | H6: =C6*E6 -> 68.4525 | J6: =MAX(G6,H6,I6) -> 225.89325 | K6: Conference/meeting/Occupancy Category - General | N6: AHU_E | O6: =J5+J10+J14 -> 204.608
A7: =Zones!B7 -> Lobby_Lounge | B7: =Zones!K7 -> 4.5635 | C7: =Zones!H7 -> 456.35 | D7: 15 | E7: 0.15 | G7: =B7*D7 -> 68.4525 | H7: =C7*E7 -> 68.4525 | J7: =MAX(G7,H7,I7) -> 68.4525 | K7: Main entry lobbies/Occupancy Category - Office Buildings | N7: AHU_S | O7: =J6+J7+J15+J11+J9 -> 397.6635
A8: =Zones!B8 -> Storage | B8: =Zones!K8 -> 0 | C8: =Zones!H8 -> 743.88791 | D8: 15 | E8: 0.15 | G8: =B8*D8 -> 0 | H8: =C8*E8 -> 111.58319 | J8: =MAX(G8,H8,I8) -> 111.58319 | K8: Occupiable storage rooms for dry materials/Occupancy Category - Office Buildings
A9: =Zones!B9 -> Mechanical_Electrical | B9: =Zones!K9 -> 0 | C9: =Zones!H9 -> 114.23 | D9: 15 | E9: 0.15 | G9: =B9*D9 -> 0 | H9: =C9*E9 -> 17.1345 | J9: =MAX(G9,H9,I9) -> 17.1345 | K9: All Other
A10: =Zones!B10 -> Restroom | B10: =Zones!K10 -> 0 | C10: =Zones!H10 -> 224.28 | D10: 15 | E10: 0.15 | F10: 2 * 25/50 per unit | G10: =B10*D10 -> 0 | H10: =C10*E10 -> 33.642 | I10: =2*25 -> 50 | J10: =MAX(G10,H10,I10) -> 50 | K10: All Other
A11: =Zones!B11 -> Break_CopyRoom | B11: =Zones!K11 -> 3.63165 | C11: =Zones!H11 -> 110.05 | D11: 15 | E11: 0.15 | G11: =B11*D11 -> 54.47475 | H11: =C11*E11 -> 16.5075 | J11: =MAX(G11,H11,I11) -> 54.47475 | K11: Breakrooms/Occupancy Category - Office Buildings
A12: =Zones!B12 -> Corridor_W | B12: =Zones!K12 -> 0.6113 | C12: =Zones!H12 -> 122.26 | D12: 15 | E12: 0.15 | G12: =B12*D12 -> 9.1695 | H12: =C12*E12 -> 18.339 | J12: =MAX(G12,H12,I12) -> 18.339 | K12: Corridors /Occupancy Category - General
A13: =Zones!B13 -> Corridor_N | B13: =Zones!K13 -> 1.05695 | C13: =Zones!H13 -> 211.39 | D13: 15 | E13: 0.15 | G13: =B13*D13 -> 15.85425 | H13: =C13*E13 -> 31.7085 | J13: =MAX(G13,H13,I13) -> 31.7085 | K13: Corridors /Occupancy Category - General
A14: =Zones!B14 -> Corridor_E | B14: =Zones!K14 -> 0.6113 | C14: =Zones!H14 -> 122.26 | D14: 15 | E14: 0.15 | G14: =B14*D14 -> 9.1695 | H14: =C14*E14 -> 18.339 | J14: =MAX(G14,H14,I14) -> 18.339 | K14: Corridors /Occupancy Category - General
A15: =Zones!B15 -> Corridor_S | B15: =Zones!K15 -> 1.05695 | C15: =Zones!H15 -> 211.39 | D15: 15 | E15: 0.15 | G15: =B15*D15 -> 15.85425 | H15: =C15*E15 -> 31.7085 | J15: =MAX(G15,H15,I15) -> 31.7085 | K15: Corridors /Occupancy Category - General
A16: =Zones!B16 -> Attic | B16: =Zones!K16 -> 0 | C16: =Zones!H16 -> 6114.3047 | G16: =B16*D16 -> 0 | H16: =C16*E16 -> 0 | J16: =MAX(G16,H16,I16) -> 0

Sheet Water Heater
A1: ="Water Heater - "&Prototype!A2 -> Water Heater - OfficeSmall
A2: Vintage | B2: WH Type | C2: Efficiency | D2: Number of WH | E2: Tank Volume (gal) | F2: Tank Loss | G2: Source
A3: Existing | B3: Gas | C3: 0.8 | D3: 1 | E3: See table below for CZ-specific values: Climate Zone Water Heater Sizing and Loss Coefficients, Storage Volume column (col F) | F3: See table below: Climate Zone Water Heater Sizing and Loss Coefficients, Standby Loss column (col G) | G3: See table below for sources: Climate Zone Water Heater Sizing and Loss Coefficients
A4: New Construction | B4: Gas | C4: 0.8 | D4: 1 | E4: =E3 -> See table below for CZ-specific values: Climate Zone Water Heater Sizing and Loss Coefficients, Storage Volume column (col F) | F4: =F3 -> See table below: Climate Zone Water Heater Sizing and Loss Coefficients, Standby Loss column (col G) | G4: =G3 -> See table below for sources: Climate Zone Water Heater Sizing and Loss Coefficients
A8: Peak Hot Water Consumption
A9: Space Name | B9: Baseline WH Type [T24, 2022, Appendix 5.4A , sheet: "2022 SpaceFuncData-Input"] | C9: Total Area (ft²) | D9: Number of People | E9: Hot Water Usage Specification (gal/hr per person) [T24, 2022, Appendix 5.4A , sheet: "2022 SpaceFuncData-Input"] | F9: Peak Hot Water Usage (gal/hr) | G9: Peak Hot Water Usage (gal/min) | H9: Note
A10: =Zones!B3 -> Open_Office_N | B10: Gas* | C10: =Zones!H3*Zones!J3 -> 912.6975 | D10: =Zones!K3*Zones!J3 -> 4.5634875 | E10: 0.18 | F10: =E10*D10 -> 0.82142775 | G10: =F10/60 -> 0.013690462 | H10: For space types marked with an asterisk (the ‘*’ symbol), the water‑heater type is listed as electric in Appendix 5.4A, sheet ‘2022 SpaceFuncData‑Input.’ However, we modified the value based on CEUS data, which indicates that gas is the primary fuel type.
A11: =Zones!B4 -> Enclosed_Office_W | B11: Gas* | C11: =Zones!H4*Zones!J4 -> 908.46 | D11: =Zones!K4*Zones!J4 -> 4.5423 | E11: 0.18 | F11: =E11*D11 -> 0.817614 | G11: =F11/60 -> 0.0136269
A12: =Zones!B5 -> Enclosed_Office_E | B12: Gas* | C12: =Zones!H5*Zones!J5 -> 908.46 | D12: =Zones!K5*Zones!J5 -> 4.5423 | E12: 0.18 | F12: =E12*D12 -> 0.817614 | G12: =F12/60 -> 0.0136269
A13: =Zones!B6 -> Conference | B13: Gas* | C13: =Zones!H6*Zones!J6 -> 456.35 | D13: =Zones!K6*Zones!J6 -> 15.05955 | E13: 0.09 | F13: =E13*D13 -> 1.3553595 | G13: =F13/60 -> 0.022589325
A14: =Zones!B7 -> Lobby_Lounge | B14: Gas | C14: =Zones!H7*Zones!J7 -> 456.35 | D14: =Zones!K7*Zones!J7 -> 4.5635 | E14: 0.09 | F14: =E14*D14 -> 0.410715 | G14: =F14/60 -> 0.00684525
A15: =Zones!B8 -> Storage | B15: Gas* | C15: =Zones!H8*Zones!J8 -> 743.88791 | D15: =Zones!K8*Zones!J8 -> 0 | E15: 0 | F15: =E15*D15 -> 0 | G15: =F15/60 -> 0
A16: =Zones!B9 -> Mechanical_Electrical | B16: Gas* | C16: =Zones!H9*Zones!J9 -> 114.23 | D16: =Zones!K9*Zones!J9 -> 0 | E16: 0.18 | F16: =E16*D16 -> 0 | G16: =F16/60 -> 0
A17: =Zones!B10 -> Restroom | B17: Gas | C17: =Zones!H10*Zones!J10 -> 224.28 | D17: =Zones!K10*Zones!J10 -> 0 | E17: 0 | F17: =E17*D17 -> 0 | G17: =F17/60 -> 0
A18: =Zones!B11 -> Break_CopyRoom | B18: Gas* | C18: =Zones!H11*Zones!J11 -> 110.05 | D18: =Zones!K11*Zones!J11 -> 3.63165 | E18: 0.09 | F18: =E18*D18 -> 0.3268485 | G18: =F18/60 -> 0.005447475
A19: =Zones!B12 -> Corridor_W | B19: Gas* | C19: =Zones!H12*Zones!J12 -> 122.26 | D19: =Zones!K12*Zones!J12 -> 0.6113 | E19: 0 | F19: =E19*D19 -> 0 | G19: =F19/60 -> 0
A20: =Zones!B13 -> Corridor_N | B20: Gas* | C20: =Zones!H13*Zones!J13 -> 211.39 | D20: =Zones!K13*Zones!J13 -> 1.05695 | E20: 0 | F20: =E20*D20 -> 0 | G20: =F20/60 -> 0
A21: =Zones!B14 -> Corridor_E | B21: Gas* | C21: =Zones!H14*Zones!J14 -> 122.26 | D21: =Zones!K14*Zones!J14 -> 0.6113 | E21: 0 | F21: =E21*D21 -> 0 | G21: =F21/60 -> 0
A22: =Zones!B15 -> Corridor_S | B22: Gas* | C22: =Zones!H15*Zones!J15 -> 211.39 | D22: =Zones!K15*Zones!J15 -> 1.05695 | E22: 0 | F22: =E22*D22 -> 0 | G22: =F22/60 -> 0
A23: =Zones!B16 -> Attic | B23: Gas | C23: =Zones!H16*Zones!J16 -> 6114.3047 | D23: =Zones!K16*Zones!J16 -> 0 | E23: 0 | F23: =E23*D23 -> 0 | G23: =F23/60 -> 0
A24: Total | B24: Gas storage | F24: =_xlfn.LET( _xlpm.g,SUMIF($B$10:$B$23,"Gas*",$F$10:$F$23), _xlpm.e,SUMIF($B$10:$B$23,"Electric*",$F$10:$F$23), IF(AND(_xlpm.g>0,_xlpm.e>0),_xlpm.g,IF(_xlpm.g>0,MAX(75,_xlpm.g),0))) -> 75 | H24: Minimum peak hot water usage is 75 gal according to ACM 2025
A25: Total | B25: Electric resistance | F25: =_xlfn.LET( _xlpm.g,SUMIF($B$10:$B$23,"Gas*",$F$10:$F$23), _xlpm.e,SUMIF($B$10:$B$23,"Electric*",$F$10:$F$23), IF(AND(_xlpm.g>0,_xlpm.e>0),_xlpm.e,IF(_xlpm.e>0,MAX(75,_xlpm.e),0))) -> 0
A29: Design supply temperature (°F) | B29: 135 | C29: Title 24 2022 Reference Appendices, Appendix 5.4B
A30: WH system factor | B30: 0.6 | C30: 2025 ACM §5.9.2 Rated Capacity
A31: Water mass conversion (lb/gal) | B31: 8.2877 | C31: 2025 ACM §5.9.2 Rated Capacity
A32: Reheat multiplier | B32: 0.4 | C32: 2025 ACM §5.9.2 Storage Volume
A33: Climate Zone Water Heater Sizing and Loss Coefficients
A34: Water Heater Name | B34: Climate Zone | C34: Minimum Monthly Mains Temp (°F) [T24 2022 - Appendix 5.4B] | D34: Heat Output (Btu/hr) [ACM, 2025, 5.9.2: Rated capacity section] | E34: WH Capacity (Btu/hr) [ACM, 2025, 5.9.2: Rated capacity section] | F34: Required Energy Input (Btu/hr) | G34: Storage Volume (gal) | H34: Standby Loss [Title 20, §1605.1 Table F-4; Appendix B: Water Heating Calculation Method] | J34: Off/On Cycle Loss Coefficient to Ambient Temp | L34: Source/Note
A35: WH_OfficeSamll | B35: CZ01 | C35: 47.9 | D35: =$F$24*($B$29-C35)*$B$31 -> 54139.4 | E35: =D35*$B$30 -> 32483.64 | F35: =_xlfn.LET(_xlpm.x,_xlfn.XLOOKUP(E35/$C$3,$A$56:$A$86,$A$56:$A$86,"",1),IF(_xlpm.x="",ROUNDUP(E35/$C$3,0),_xlpm.x)) -> 60000 | G35: =_xlfn.LET(_xlpm.v,MAX(30,$F$24*$B$32),_xlpm.x,_xlfn.XLOOKUP(_xlpm.v,$E$56:$E$74,$E$56:$E$74,"",1),IF(_xlpm.x="",ROUNDUP(_xlpm.v,0),_xlpm.x)) -> 34 | H35: =(F35/800)+110*SQRT(G35) -> 716.40471 | I35: Btu/hr | J35: =H35/70 -> 10.234353 | K35: Btu/h·°F | L35: Required Energy Input: vendor/available catalog size (Market data table). Storage Volume: standard/available catalog tank size (Market data table).
A36: WH_OfficeSamll | B36: CZ02 | C36: 50.8 | D36: =$F$24*($B$29-C36)*$B$31 -> 52336.825 | E36: =D36*$B$30 -> 31402.095 | F36: =_xlfn.LET(_xlpm.x,_xlfn.XLOOKUP(E36/$C$3,$A$56:$A$86,$A$56:$A$86,"",1),IF(_xlpm.x="",ROUNDUP(E36/$C$3,0),_xlpm.x)) -> 60000 | G36: =_xlfn.LET(_xlpm.v,MAX(30,$F$24*$B$32),_xlpm.x,_xlfn.XLOOKUP(_xlpm.v,$E$56:$E$74,$E$56:$E$74,"",1),IF(_xlpm.x="",ROUNDUP(_xlpm.v,0),_xlpm.x)) -> 34 | H36: =(F36/800)+110*SQRT(G36) -> 716.40471 | I36: Btu/hr | J36: =H36/70 -> 10.234353 | K36: Btu/h·°F
A37: WH_OfficeSamll | B37: CZ03 | C37: 52.2 | D37: =$F$24*($B$29-C37)*$B$31 -> 51466.617 | E37: =D37*$B$30 -> 30879.97 | F37: =_xlfn.LET(_xlpm.x,_xlfn.XLOOKUP(E37/$C$3,$A$56:$A$86,$A$56:$A$86,"",1),IF(_xlpm.x="",ROUNDUP(E37/$C$3,0),_xlpm.x)) -> 60000 | G37: =_xlfn.LET(_xlpm.v,MAX(30,$F$24*$B$32),_xlpm.x,_xlfn.XLOOKUP(_xlpm.v,$E$56:$E$74,$E$56:$E$74,"",1),IF(_xlpm.x="",ROUNDUP(_xlpm.v,0),_xlpm.x)) -> 34 | H37: =(F37/800)+110*SQRT(G37) -> 716.40471 | I37: Btu/hr | J37: =H37/70 -> 10.234353 | K37: Btu/h·°F
A38: WH_OfficeSamll | B38: CZ04 | C38: 52.7 | D38: =$F$24*($B$29-C38)*$B$31 -> 51155.828 | E38: =D38*$B$30 -> 30693.497 | F38: =_xlfn.LET(_xlpm.x,_xlfn.XLOOKUP(E38/$C$3,$A$56:$A$86,$A$56:$A$86,"",1),IF(_xlpm.x="",ROUNDUP(E38/$C$3,0),_xlpm.x)) -> 60000 | G38: =_xlfn.LET(_xlpm.v,MAX(30,$F$24*$B$32),_xlpm.x,_xlfn.XLOOKUP(_xlpm.v,$E$56:$E$74,$E$56:$E$74,"",1),IF(_xlpm.x="",ROUNDUP(_xlpm.v,0),_xlpm.x)) -> 34 | H38: =(F38/800)+110*SQRT(G38) -> 716.40471 | I38: Btu/hr | J38: =H38/70 -> 10.234353 | K38: Btu/h·°F
A39: WH_OfficeSamll | B39: CZ05 | C39: 51.6 | D39: =$F$24*($B$29-C39)*$B$31 -> 51839.563 | E39: =D39*$B$30 -> 31103.738 | F39: =_xlfn.LET(_xlpm.x,_xlfn.XLOOKUP(E39/$C$3,$A$56:$A$86,$A$56:$A$86,"",1),IF(_xlpm.x="",ROUNDUP(E39/$C$3,0),_xlpm.x)) -> 60000 | G39: =_xlfn.LET(_xlpm.v,MAX(30,$F$24*$B$32),_xlpm.x,_xlfn.XLOOKUP(_xlpm.v,$E$56:$E$74,$E$56:$E$74,"",1),IF(_xlpm.x="",ROUNDUP(_xlpm.v,0),_xlpm.x)) -> 34 | H39: =(F39/800)+110*SQRT(G39) -> 716.40471 | I39: Btu/hr | J39: =H39/70 -> 10.234353 | K39: Btu/h·°F
A40: WH_OfficeSamll | B40: CZ06 | C40: 56.8 | D40: =$F$24*($B$29-C40)*$B$31 -> 48607.36 | E40: =D40*$B$30 -> 29164.416 | F40: =_xlfn.LET(_xlpm.x,_xlfn.XLOOKUP(E40/$C$3,$A$56:$A$86,$A$56:$A$86,"",1),IF(_xlpm.x="",ROUNDUP(E40/$C$3,0),_xlpm.x)) -> 60000 | G40: =_xlfn.LET(_xlpm.v,MAX(30,$F$24*$B$32),_xlpm.x,_xlfn.XLOOKUP(_xlpm.v,$E$56:$E$74,$E$56:$E$74,"",1),IF(_xlpm.x="",ROUNDUP(_xlpm.v,0),_xlpm.x)) -> 34 | H40: =(F40/800)+110*SQRT(G40) -> 716.40471 | I40: Btu/hr | J40: =H40/70 -> 10.234353 | K40: Btu/h·°F
A41: WH_OfficeSamll | B41: CZ07 | C41: 58.4 | D41: =$F$24*($B$29-C41)*$B$31 -> 47612.836 | E41: =D41*$B$30 -> 28567.702 | F41: =_xlfn.LET(_xlpm.x,_xlfn.XLOOKUP(E41/$C$3,$A$56:$A$86,$A$56:$A$86,"",1),IF(_xlpm.x="",ROUNDUP(E41/$C$3,0),_xlpm.x)) -> 60000 | G41: =_xlfn.LET(_xlpm.v,MAX(30,$F$24*$B$32),_xlpm.x,_xlfn.XLOOKUP(_xlpm.v,$E$56:$E$74,$E$56:$E$74,"",1),IF(_xlpm.x="",ROUNDUP(_xlpm.v,0),_xlpm.x)) -> 34 | H41: =(F41/800)+110*SQRT(G41) -> 716.40471 | I41: Btu/hr | J41: =H41/70 -> 10.234353 | K41: Btu/h·°F
A42: WH_OfficeSamll | B42: CZ08 | C42: 58.4 | D42: =$F$24*($B$29-C42)*$B$31 -> 47612.836 | E42: =D42*$B$30 -> 28567.702 | F42: =_xlfn.LET(_xlpm.x,_xlfn.XLOOKUP(E42/$C$3,$A$56:$A$86,$A$56:$A$86,"",1),IF(_xlpm.x="",ROUNDUP(E42/$C$3,0),_xlpm.x)) -> 60000 | G42: =_xlfn.LET(_xlpm.v,MAX(30,$F$24*$B$32),_xlpm.x,_xlfn.XLOOKUP(_xlpm.v,$E$56:$E$74,$E$56:$E$74,"",1),IF(_xlpm.x="",ROUNDUP(_xlpm.v,0),_xlpm.x)) -> 34 | H42: =(F42/800)+110*SQRT(G42) -> 716.40471 | I42: Btu/hr | J42: =H42/70 -> 10.234353 | K42: Btu/h·°F
A43: WH_OfficeSamll | B43: CZ09 | C43: 57.6 | D43: =$F$24*($B$29-C43)*$B$31 -> 48110.098 | E43: =D43*$B$30 -> 28866.059 | F43: =_xlfn.LET(_xlpm.x,_xlfn.XLOOKUP(E43/$C$3,$A$56:$A$86,$A$56:$A$86,"",1),IF(_xlpm.x="",ROUNDUP(E43/$C$3,0),_xlpm.x)) -> 60000 | G43: =_xlfn.LET(_xlpm.v,MAX(30,$F$24*$B$32),_xlpm.x,_xlfn.XLOOKUP(_xlpm.v,$E$56:$E$74,$E$56:$E$74,"",1),IF(_xlpm.x="",ROUNDUP(_xlpm.v,0),_xlpm.x)) -> 34 | H43: =(F43/800)+110*SQRT(G43) -> 716.40471 | I43: Btu/hr | J43: =H43/70 -> 10.234353 | K43: Btu/h·°F
A44: WH_OfficeSamll | B44: CZ10 | C44: 57.1 | D44: =$F$24*($B$29-C44)*$B$31 -> 48420.887 | E44: =D44*$B$30 -> 29052.532 | F44: =_xlfn.LET(_xlpm.x,_xlfn.XLOOKUP(E44/$C$3,$A$56:$A$86,$A$56:$A$86,"",1),IF(_xlpm.x="",ROUNDUP(E44/$C$3,0),_xlpm.x)) -> 60000 | G44: =_xlfn.LET(_xlpm.v,MAX(30,$F$24*$B$32),_xlpm.x,_xlfn.XLOOKUP(_xlpm.v,$E$56:$E$74,$E$56:$E$74,"",1),IF(_xlpm.x="",ROUNDUP(_xlpm.v,0),_xlpm.x)) -> 34 | H44: =(F44/800)+110*SQRT(G44) -> 716.40471 | I44: Btu/hr | J44: =H44/70 -> 10.234353 | K44: Btu/h·°F
A45: WH_OfficeSamll | B45: CZ11 | C45: 50.5 | D45: =$F$24*($B$29-C45)*$B$31 -> 52523.299 | E45: =D45*$B$30 -> 31513.979 | F45: =_xlfn.LET(_xlpm.x,_xlfn.XLOOKUP(E45/$C$3,$A$56:$A$86,$A$56:$A$86,"",1),IF(_xlpm.x="",ROUNDUP(E45/$C$3,0),_xlpm.x)) -> 60000 | G45: =_xlfn.LET(_xlpm.v,MAX(30,$F$24*$B$32),_xlpm.x,_xlfn.XLOOKUP(_xlpm.v,$E$56:$E$74,$E$56:$E$74,"",1),IF(_xlpm.x="",ROUNDUP(_xlpm.v,0),_xlpm.x)) -> 34 | H45: =(F45/800)+110*SQRT(G45) -> 716.40471 | I45: Btu/hr | J45: =H45/70 -> 10.234353 | K45: Btu/h·°F
A46: WH_OfficeSamll | B46: CZ12 | C46: 51.4 | D46: =$F$24*($B$29-C46)*$B$31 -> 51963.879 | E46: =D46*$B$30 -> 31178.327 | F46: =_xlfn.LET(_xlpm.x,_xlfn.XLOOKUP(E46/$C$3,$A$56:$A$86,$A$56:$A$86,"",1),IF(_xlpm.x="",ROUNDUP(E46/$C$3,0),_xlpm.x)) -> 60000 | G46: =_xlfn.LET(_xlpm.v,MAX(30,$F$24*$B$32),_xlpm.x,_xlfn.XLOOKUP(_xlpm.v,$E$56:$E$74,$E$56:$E$74,"",1),IF(_xlpm.x="",ROUNDUP(_xlpm.v,0),_xlpm.x)) -> 34 | H46: =(F46/800)+110*SQRT(G46) -> 716.40471 | I46: Btu/hr | J46: =H46/70 -> 10.234353 | K46: Btu/h·°F
...

Sheet Interior Lights
A1: ="Interior Lighting - " & Prototype!A2 -> Interior Lighting - OfficeSmall
A2: Space Type | B2: New Construction | E2: Existing | H2: Note
B3: LPD (W/ft²) | C3: Additional LPD for Portable Lighting (W/ft²) | D3: Source | E3: LPD (W/ft²) | F3: Additional LPD for Portable Lighting (W/ft²) | G3: Source
A4: Office Area (>250 square feet) | B4: 0.6 | C4: =0.2*0.5 -> 0.1 | D4: T24, part 6, 2025, Table 140.6 C Technology : LED | E4: 0.75 | F4: - | G4: T24, part 6, 2013, Table 140.6 C Technology: 59% LED, 31% halogen, 7% CFL (Comstock 2023) | H4: It is assumed that 50% of the additional allowance lighting is in use.
A5: Convention, Conference, Multipurpose and Meeting Area | B5: 0.75 | E5: 1.4
A6: Lobby, Main Entry | B6: 0.7 | C6: 0.25 | E6: 1.5 | F6: 0.5
A7: Storage (General) | B7: 0.4 | E7: 0.6
A8: Electrical, Mechanical, Telephone Rooms | B8: 0.4 | E8: 0.7
A9: Restrooms | B9: 0.65 | E9: 0.65
A10: Lounge, Breakroom, or Waiting Area | B10: 0.55 | C10: =0.5*0.25 -> 0.125 | E10: 1.1 | H10: 2013 LPD is for "Lounge" area It is assumed that 50% of the additional allowance lighting is in use.
A11: Corridor Area | B11: 0.4 | E11: 0.6
A12: Attic
A14: According to CEUS, more than 80% of existing small office upgraded their lighting system between 2014-2018 and it conflicts the lighting generation considered by Comstock.
B17: Whole Building method
B18: 2025 | C18: 2013
A19: LPD for Office Building ((W/ft²) | B19: 0.6 | C19: 0.8 | D19: Ref: T24, Table 140.6 B

Sheet Ext Lighting
A1: ="Exterior Lighting - " & Prototype!A2 -> Exterior Lighting - OfficeSmall
A2: Motion Controlled Luminaires (W) | B2: Non-motion Controlled Luminaires (W) | C2: Total (W) | D2: Source
A3: =G12 -> 382.26279 | B3: =G13 -> 155.15145 | C3: =A3+B3 -> 537.41423 | D3: T24, 2022 & 2025 2019 Outdoor Lighting CASE report PNNL 90.1-2010 TSD
A5: Exterior Lighting
A6: Items (Assume LZ2) | B6: Assumptions [2019 Outdoor Lighting CASE Report & PNNL 90.1-2010 TSD] | D6: Unit | E6: Lighting Power Allowance [T24, 2025, Table 140.7-A & 140.7-B] | F6: Unit | G6: Exterior Lighting Power (W)
A7: IWA (Initial Wage Allowance) | E7: 200 | F7: (W) | G7: =$E7 -> 200
A8: Parking area | B8: 400 ft² for every parking space [2019 Lighting CASE report, Appendix H] 1 parking space per 250 ft² of gross building area [2019 Lighting CASE report,Table 38] | C8: =B19/250*400 -> 8803.3047 | D8: (ft²) | E8: 0.019 | F8: (W/ft²) | G8: =$E8*C8 -> 167.26279
A9: Building Entrance | B9: 1 building entrance (1 per 10,000 ft² footprint) | C9: 1 | D9: (count) | E9: 15 | F9: (W/ea) | G9: =E9*C9 -> 15
A10: Hardscape Ornamental Light | B10: 0.1 ft² per 1 ft² of gross building area for hardscape ornamental light [2019 Lighting CASE report,Table 36] | C10: =B19*0.1 -> 550.20654 | D10: (ft²) | E10: 0.007 | F10: (W/ft²) | G10: =E10*C10 -> 3.8514458
A11: Building façade | B11: 0.1 W per ft² of facade area Façade Area* = Perimeter × 0.5 × height (30 ft is the max height that is lit) The 0.5 factor assumes that only half of the perimeter walls are lit. -Formula is developed based on the 2019 Outdoor Lighting CASE report | C11: =B18*0.5*10 -> 1513 | D11: (ft²) | E11: 0.1 | F11: (W/ft²) | G11: =E11*C11 -> 151.3
A12: Motion controlled Luminaires | G12: =G8+G7+G9 -> 382.26279
A13: Non-motion-controlled Luminaires | G13: =G10+G11 -> 155.15145
A14: Total | G14: =G12+G13 -> 537.41423
A16: *Developed based on 2019 Outdoor Lighting CASE Report
A18: Perimeter (ft) | B18: =(90.8+60.5)*2 -> 302.6
A19: Total floor area (ft²) | B19: =Zones!H17 -> 5502.0654
A20: Floors (above ground) | B20: 1

Sheet Equipment
A1: ="Equipment - " & Prototype!A2 -> Equipment - OfficeSmall
A2: Space Name | B2: Plug load Power Density (W/ft²) | C2: Gas Power Density (Btu/hr-ft²) | D2: Refrigeration Power Density (W/ft²) | E2: Source
A3: Office Area (>250 square feet) | B3: 0.7 | E3: Proposed Updates to Equipment Power Densities and Schedules in the 2028 Energy Code Nonresidential and Multifamily Alternative Calculation Method (NRMFACM) Reference Manual, August 7, 2025
A4: Convention, Conference, Multipurpose and Meeting Area | B4: 1 | E4: T24 2022 - Appendix 5.4A
A5: Lobby, Main Entry | B5: 0.5
A6: Storage (General) | B6: 0.2
A7: Electrical, Mechanical, Telephone Rooms | B7: 3
A8: Restrooms | B8: 0
A9: Lounge, Breakroom, or Waiting Area | B9: 1
A10: Corridor Area | B10: 0

Sheet Schedules
A1: ="Schedules - "&Prototype!A2 -> Schedules - OfficeSmall
A2: Zone | B2: Schedule Category | C2: Schedule | D2: Source | E2: Type | F2: Hour
F3: 1 | G3: 2 | H3: 3 | I3: 4 | J3: 5 | K3: 6 | L3: 7 | M3: 8 | N3: 9 | O3: 10 | P3: 11 | Q3: 12 | R3: 13 | S3: 14 | T3: 15 | U3: 16 | V3: 17 | W3: 18 | X3: 19 | Y3: 20 | Z3: 21 | AA3: 22 | AB3: 23 | AC3: 24
A4: All zones excluding Mechanical | B4: Office | C4: Occupancy | D4: T24 2022 - Appendix 5.4B, [Office] Updated based on Plug load and schedules project with CEC, 2025 | E4: Weekday | F4: 0 | G4: 0 | H4: 0 | I4: 0 | J4: 0 | K4: 0 | L4: 0.1 | M4: 0.2 | N4: 0.95 | O4: 0.95 | P4: 0.95 | Q4: 0.95 | R4: 0.5 | S4: 0.95 | T4: 0.95 | U4: 0.95 | V4: 0.95 | W4: 0.3 | X4: 0.1 | Y4: 0.1 | Z4: 0.1 | AA4: 0.1 | AB4: 0.05 | AC4: 0.05
E5: Saturday | F5: 0 | G5: 0 | H5: 0 | I5: 0 | J5: 0 | K5: 0 | L5: 0.05 | M5: 0.05 | N5: 0.05 | O5: 0.05 | P5: 0.05 | Q5: 0.05 | R5: 0.05 | S5: 0.05 | T5: 0.05 | U5: 0.05 | V5: 0.05 | W5: 0.05 | X5: 0 | Y5: 0 | Z5: 0 | AA5: 0 | AB5: 0 | AC5: 0
E6: Sunday | F6: 0 | G6: 0 | H6: 0 | I6: 0 | J6: 0 | K6: 0 | L6: 0.05 | M6: 0.05 | N6: 0.05 | O6: 0.05 | P6: 0.05 | Q6: 0.05 | R6: 0.05 | S6: 0.05 | T6: 0.05 | U6: 0.05 | V6: 0.05 | W6: 0.05 | X6: 0 | Y6: 0 | Z6: 0 | AA6: 0 | AB6: 0 | AC6: 0
A7: =A4 -> All zones excluding Mechanical | B7: Office | C7: Lights | D7: T24 2022 - Appendix 5.4B, [Office] | E7: Weekday | F7: 0.05 | G7: 0.05 | H7: 0.05 | I7: 0.05 | J7: 0.05 | K7: 0.1 | L7: 0.1 | M7: 0.3 | N7: 0.65 | O7: 0.65 | P7: 0.65 | Q7: 0.65 | R7: 0.65 | S7: 0.65 | T7: 0.65 | U7: 0.65 | V7: 0.65 | W7: 0.35 | X7: 0.3 | Y7: 0.3 | Z7: 0.2 | AA7: 0.2 | AB7: 0.1 | AC7: 0.05
E8: Saturday | F8: 0.05 | G8: 0.05 | H8: 0.05 | I8: 0.05 | J8: 0.05 | K8: 0.05 | L8: 0.15 | M8: 0.15 | N8: 0.15 | O8: 0.15 | P8: 0.15 | Q8: 0.15 | R8: 0.15 | S8: 0.15 | T8: 0.15 | U8: 0.15 | V8: 0.15 | W8: 0.15 | X8: 0.05 | Y8: 0.05 | Z8: 0.05 | AA8: 0.05 | AB8: 0.05 | AC8: 0.05
E9: Sunday | F9: 0.05 | G9: 0.05 | H9: 0.05 | I9: 0.05 | J9: 0.05 | K9: 0.05 | L9: 0.15 | M9: 0.15 | N9: 0.15 | O9: 0.15 | P9: 0.15 | Q9: 0.15 | R9: 0.15 | S9: 0.15 | T9: 0.15 | U9: 0.15 | V9: 0.15 | W9: 0.15 | X9: 0.05 | Y9: 0.05 | Z9: 0.05 | AA9: 0.05 | AB9: 0.05 | AC9: 0.05
A10: =A7 -> All zones excluding Mechanical | B10: Office | C10: ElecEquipment | D10: Plug load and schedules project with CEC, 2025 | E10: Weekday | F10: 0.45 | G10: 0.45 | H10: 0.45 | I10: 0.45 | J10: 0.45 | K10: 0.45 | L10: 0.45 | M10: 0.74 | N10: 0.87 | O10: 0.9 | P10: 0.9 | Q10: 0.9 | R10: 0.9 | S10: 0.9 | T10: 0.9 | U10: 0.9 | V10: 0.9 | W10: 0.7 | X10: 0.5 | Y10: 0.5 | Z10: 0.5 | AA10: 0.45 | AB10: 0.45 | AC10: 0.45
E11: Saturday | F11: 0.43 | G11: 0.43 | H11: 0.43 | I11: 0.43 | J11: 0.43 | K11: 0.43 | L11: 0.43 | M11: 0.43 | N11: 0.43 | O11: 0.43 | P11: 0.43 | Q11: 0.43 | R11: 0.43 | S11: 0.43 | T11: 0.43 | U11: 0.43 | V11: 0.43 | W11: 0.43 | X11: 0.43 | Y11: 0.43 | Z11: 0.43 | AA11: 0.43 | AB11: 0.43 | AC11: 0.43
E12: Sunday | F12: 0.43 | G12: 0.43 | H12: 0.43 | I12: 0.43 | J12: 0.43 | K12: 0.43 | L12: 0.43 | M12: 0.43 | N12: 0.43 | O12: 0.43 | P12: 0.43 | Q12: 0.43 | R12: 0.43 | S12: 0.43 | T12: 0.43 | U12: 0.43 | V12: 0.43 | W12: 0.43 | X12: 0.43 | Y12: 0.43 | Z12: 0.43 | AA12: 0.43 | AB12: 0.43 | AC12: 0.43
A13: =A4 -> All zones excluding Mechanical | B13: Office | C13: HVACAvail | D13: T24 2022 - Appendix 5.4B, [Office] | E13: Weekday | F13: 0 | G13: 0 | H13: 0 | I13: 0 | J13: 0 | K13: 1 | L13: 1 | M13: 1 | N13: 1 | O13: 1 | P13: 1 | Q13: 1 | R13: 1 | S13: 1 | T13: 1 | U13: 1 | V13: 1 | W13: 1 | X13: 1 | Y13: 1 | Z13: 1 | AA13: 1 | AB13: 1 | AC13: 1
E14: Saturday | F14: 0 | G14: 0 | H14: 0 | I14: 0 | J14: 0 | K14: 1 | L14: 1 | M14: 1 | N14: 1 | O14: 1 | P14: 1 | Q14: 1 | R14: 1 | S14: 1 | T14: 1 | U14: 1 | V14: 1 | W14: 1 | X14: 1 | Y14: 0 | Z14: 0 | AA14: 0 | AB14: 0 | AC14: 0
E15: Sunday | F15: 0 | G15: 0 | H15: 0 | I15: 0 | J15: 0 | K15: 0 | L15: 0 | M15: 0 | N15: 0 | O15: 0 | P15: 0 | Q15: 0 | R15: 0 | S15: 0 | T15: 0 | U15: 0 | V15: 0 | W15: 0 | X15: 0 | Y15: 0 | Z15: 0 | AA15: 0 | AB15: 0 | AC15: 0
A16: =A4 -> All zones excluding Mechanical | B16: Office | C16: ServiceHotWater | D16: T24 2022 - Appendix 5.4B, [Office] | E16: Weekday | F16: 0.05 | G16: 0.05 | H16: 0.05 | I16: 0.05 | J16: 0.05 | K16: 0.08 | L16: 0.07 | M16: 0.19 | N16: 0.35 | O16: 0.38 | P16: 0.39 | Q16: 0.47 | R16: 0.57 | S16: 0.54 | T16: 0.34 | U16: 0.33 | V16: 0.44 | W16: 0.26 | X16: 0.21 | Y16: 0.15 | Z16: 0.17 | AA16: 0.08 | AB16: 0.05 | AC16: 0.05
E17: Saturday | F17: 0.04 | G17: 0.04 | H17: 0.04 | I17: 0.04 | J17: 0.04 | K17: 0.07 | L17: 0.04 | M17: 0.04 | N17: 0.04 | O17: 0.04 | P17: 0.04 | Q17: 0.06 | R17: 0.06 | S17: 0.09 | T17: 0.06 | U17: 0.04 | V17: 0.04 | W17: 0.04 | X17: 0.04 | Y17: 0.04 | Z17: 0.04 | AA17: 0.07 | AB17: 0.04 | AC17: 0.04
E18: Sunday | F18: 0.04 | G18: 0.04 | H18: 0.04 | I18: 0.04 | J18: 0.04 | K18: 0.07 | L18: 0.04 | M18: 0.04 | N18: 0.04 | O18: 0.04 | P18: 0.04 | Q18: 0.06 | R18: 0.06 | S18: 0.09 | T18: 0.06 | U18: 0.04 | V18: 0.04 | W18: 0.04 | X18: 0.04 | Y18: 0.04 | Z18: 0.04 | AA18: 0.07 | AB18: 0.04 | AC18: 0.04
A19: =A4 -> All zones excluding Mechanical | B19: Office | C19: Infiltration | D19: T24 2022 - Appendix 5.4B, [Office] Updated based on Plug load and schedules project with CEC, 202 | E19: Weekday | F19: 1 | G19: 1 | H19: 1 | I19: 1 | J19: 1 | K19: 0.25 | L19: 0.25 | M19: 0.25 | N19: 0.25 | O19: 0.25 | P19: 0.25 | Q19: 0.25 | R19: 0.25 | S19: 0.25 | T19: 0.25 | U19: 0.25 | V19: 0.25 | W19: 0.25 | X19: 0.25 | Y19: 0.25 | Z19: 0.25 | AA19: 0.25 | AB19: 0.25 | AC19: 0.25
