Workbook
Name Space_Function: Data!$A$2:$A$76

Sheet Notes
A1: Data Sources
A2: Dataset | B2: Dodge 2023
B3: Commercial End-Use Survey (CEUS) 2022 | C3: https://www.energy.ca.gov/publications/2023/2022-california-commercial-end-use-survey-ceus-final-report
B4: Commercial Buildings Energy Consumption Survey (CBECS) 2018 | C4: https://www.eia.gov/consumption/commercial/data/2018/
B5: ComStock 2023 | C5: https://comstock.nlr.gov/page/datasets
A6: ACM | B6: California Energy Commission (CEC) Large Office prototype (CBECC 2022.3.1) | C6: https://bees.noresco.com/software2022.html
B7: Pacific Northwest National Laboratory (PNNL) Large Office prototype (90.1-2022) | C7: https://www.energycodes.gov/prototype-building-models#Commercial
B8: Database for Energy Efficient Resources (DEER) Large prototype (June 2023) | C8: https://github.com/sound-data/DEER-Prototypes-EnergyPlus
B9: Oak Ridge National Laboratory (ORNL) 2019 Large Office prototype zoning | C9: https://www.sciencedirect.com/science/article/abs/pii/S0306261920312186
C10: https://publications.ibpsa.org/proceedings/simbuild/2020/papers/simbuild2020_C064.pdf
B11: Massachusetts Large Office prototype | C11: https://www.mass.gov/doc/large-office-prototype-basis-of-design-report/download
A12: Codes | B12: Title 24, part 6, referred to as T24 (1984, 2001, 2008, 2010, 2013, 2022, 2025) | C12: https://www.energy.ca.gov/publications/2025/2025-building-energy-efficiency-standards-residential-and-nonresidential | F12: 2025
C13: https://codes.iccsafe.org/codes/united-states/california | F13: 2010+
B14: American Society of Heating, Refrigerating and Air-Conditioning Engineers (ASHRAE) 90.1 (2022) | C14: https://www.ashrae.org/technical-resources/standards-and-guidelines/read-only-versions-of-ashrae-standards
B15: Code of Federal Regulations (CFR) Title 10 (2010) | C15: https://www.govinfo.gov/content/pkg/FR-2009-03-23/pdf/FR-2009-03-23.pdf
B16: CFR Title 10 (2024) | C16: https://www.govinfo.gov/content/pkg/CFR-2024-title10-vol3/pdf/CFR-2024-title10-vol3-part431-subpartF.pdf
B17: Title 20 | C17: https://govt.westlaw.com/calregs/Document/I270DCA634B4011EFA8F7F119BAF97AD6?viewType=FullText&originationContext=documenttoc&transitionType=CategoryPageItem&contextData=(sc.Default)
A18: Others | B18: Alternative Calculation Method (ACM) (2022) | C18: https://www.energy.ca.gov/publications/2022/2022-nonresidential-and-multifamily-alternative-calculation-method-reference
B19: ACM (2025) | C19: https://www.energy.ca.gov/publications/2025/2025-nonresidential-and-multifamily-alternative-calculation-method-reference
B20: Nonres ACM 2022, Appendix 5.4A and Appendix 5.4B | C20: https://www.energy.ca.gov/publications/2022/2022-nonresidential-and-multifamily-alternative-calculation-method-reference
B21: 2022 Reduced infiltration Codes and Standards Enhancement (CASE) report | C21: https://title24stakeholders.com/wp-content/uploads/2020/10/2022-T24-Final-CASE-Report_Reduce-Infiltration.pdf
B22: 2019 Outdoor Lighting CASE Report | C22: https://title24stakeholders.com/wp-content/uploads/2016/10/T24-2019-CASE-Study-Results-Report-Outdoor-Sources_Final_with-Attachments.pdf
B23: PNNL 20405, 2011 | C23: https://www.pnnl.gov/main/publications/external/technical_reports/PNNL-20405.pdf
B24: Air leakage Memo, NORESCO, 2025 | C24: Infiltration_rate_report_14May2025-Short-Version.docx
B25: Yousefi, F., Athalye, R., (2025), "Determining Vintage Bins for Prototype Development: An Analysis of California Commercial Buildings," ASHRAE Annual Conference | C25: https://www.thefreelibrary.com/Determining+Vintage+Bins+for+Prototype+Development%3a+An+Analysis+of...-a0879271125
B26: Proposed Updates to Equipment Power Densities and Building Schedules for the 2028 Energy Code, referred to as "Plug load and schedules project with CEC, 2025" (Docket Number =25-BSTD-03 & TN=265693) | C26: https://efiling.energy.ca.gov/GetDocument.aspx?tn=265693&DocumentContentId=102545
B27: Yousefi, F., Athalye, R. (2026). "Developing a New Set of Prototypical Models for Office Buildings in California," IBPSA-USA Conference | C27: https://publications.ibpsa.org/conference/paper/?id=simbuild2026_1372
B28: ENERGY STAR certified commercial water heaters | C28: https://www.energystar.gov/productfinder/product/certified-commercial-water-heaters/results?fuel_filter=Gas&markets_filter=United+States
B29: Grainger gas tank water heaters (sizes below commercial, e.g. 30–75 kBtu/h) | C29: https://www.grainger.com/category/plumbing/water-heaters/gas-tank-water-heaters
B30: Grainger electric tank water heaters | C30: https://www.grainger.com/category/plumbing/water-heaters/electric-tank-water-heaters
A32: Construction Rate
H34: Total Floor area (thousands of sf)
G35: Pre-1978 | H35: 1978-1997 | I35: 1998-2007 | J35: 2008-2018 | K35: 2019-2022
G36: New Construction (2019+) | H36: 248465.9 | I36: 93016.2 | J36: 62305.7 | K36: 27851.1
B44: Source: Dodge Construction Data, 2023 ( NEW large office built after 1967) (STC refers to building types in Dodge terminology).
A45: Notes
A46: OfficeLarge Prototype | B46: Information about the geometry and underlying logic of the office prototypes can be found in this paper: Yousefi, F., Athalye, R. (2026). ‘Developing a New Set of Prototypical Models for Office Buildings in California.’ IBPSA-USA Conference. The link is provided above in the Data Source section. The floor area was slightly modified in some spaces during the geometry‑drawing phase. Footprint (floor area of each story): Supported by Dodge 2023 data and consistent with the existing Large Office prototypes Zone configuration and floor plan layout: Based on the ORNL 2019 project, with modifications informed by engineering and architectural judgment (see the "Zones" tab for more details)
A47: Large office building is defined as any office building with a total area >150,000 sf, by analyzing Dodge 2023 data.
A48: Large office buildings cover approximately 52% of the floor area and 7% of the total number of the CA office buildings (according to the Dodge 2023 datasets).
A49: Only 2% of offices in CA have stories >6 and area <150,000. (according to the Dodge 2023 datasets)
...

Sheet Prototype
A1: NORESCO, Updated September 2026
A2: OfficeLarge
A3: Characteristic | B3: Value | C3: Data Sources
A4: Building Type | B4: Large Office
A5: Building Category | B5: Nonresidential
A6: Version | B6: v2-0
A7: Vintages | B7: 4 Vintages: Pre-1978 , 1978-1997 ,1998-2007 , 2008-2018 New Construction (2019+) | C7: Based on the vintage bin analysis. A summary of the findings is presented in the following paper, with a link provided in the Notes tab: Yousefi, F., Athalye, R. (2025). “Determining Vintage Bins for Prototype Development: An Analysis of California Commercial Buildings.” ASHRAE Annual Conference.
A8: Shape | C8: Assume number of floors based on the existing Large Office prototypes (PNNL, CEC) Assume rectangular shape; supported by CBECS, CEC, and PNNL The logic behind the geometry of the CalBEM Office prototypes' shell is described in the following paper, with a link provided in the Notes tab: Yousefi, F., & Athalye, R. (2026). "Developing a New Set of Prototypical Models for Office Buildings in California", IBPSA-USA Conference.
A9: Total Floor Area (ft2) | B9: 498,589 (240 ft *160 ft) | C9: Supported by Dodge 2023 data (Same as CEC and PNNL)
A10: Aspect Ratio | B10: 1.5 | C10: Assumption; same as CEC and PNNL Large Office prototype
A11: Number of Floors | B11: 12 Floor + basement | C11: Number of floors: based on the existing Large Office prototypes (PNNL,CEC)
A12: Roof type | B12: Flat | C12: Supported by CBECS 2018 data (Same as CEC and PNNL)
A13: WWR | B13: 40% of the above grade wall
A14: Window dimensions | B14: Even distribution
A15: Shading Geometry | B15: None
A16: Floor to floor height (feet) | B16: 13 | C16: Assumption, standard ceiling height in office buildings; same as CEC and PNNL Large Office prototype.
A17: Floor to ceiling height (feet) | B17: 9 | C17: Assumption; same as CEC and PNNL Large Office prototype
A18: Glazing sill height (feet) | B18: 3 | C18: Assumption; same as CEC and PNNL Large Office prototype

Sheet Zones
A1: ="Proposed Layout - "&Prototype!A2 -> Proposed Layout - OfficeLarge
A2: Building | B2: Space/ Thermal Zone | C2: Space Type [Primarily from: T24, 2022 Appendix 5.4A] - See Notes column | D2: HVAC System Name New Construction | E2: HVAC System Name Vintage 1-4 | F2: Schedule Category | G2: Conditioned (Y/N) | H2: Area Fraction | I2: Area (ft²) | J2: Volume (ft³) | K2: Multipliers | L2: Number of People | M2: People (Persons/1,000 ft²) [T24, 2025,Table 120.1-A] | N2: Notes | O2: Total area fraction | Q2: Thermal Zone Layout - Each space has its own thermal zone
A3: OfficeLarge | B3: Perimeter_Open_Office_N_Basement | C3: Office Area (>250 square feet) | D3: VAV With Reheat_Basement | E3: VAV_Basement | F3: Office | G3: Yes | H3: =I3/$I$82 -> 0.016882199 | I3: 8416.86 | J3: =I3*Prototype!$B$17 -> 75751.74 | K3: 1 | L3: =IFERROR(M3*I3/1000,"") -> 42.0843 | M3: 5 | O3: =K3*H3 -> 0.016882199
A4: OfficeLarge | B4: Perimeter_Open_Office_S_Basement | C4: Office Area (>250 square feet) | D4: VAV With Reheat_Basement | E4: VAV_Basement | F4: Office | G4: Yes | H4: =I4/$I$82 -> 0.0073454534 | I4: 3662.18 | J4: =I4*Prototype!$B$17 -> 32959.62 | K4: 1 | L4: =IFERROR(M4*I4/1000,"") -> 18.3109 | M4: =M3 -> 5 | O4: =K4*H4 -> 0.0073454534 | R4: Basement | V4: First Floor | Z4: Middle/Top Floors
A5: OfficeLarge | B5: Core_Enclosed_Office_Basement | C5: Office Area (>250 square feet) | D5: VAV With Reheat_Basement | E5: VAV_Basement | F5: Office | G5: Yes | H5: =I5/$I$82 -> 0.0074286924 | I5: 3703.68 | J5: =I5*Prototype!$B$17 -> 33333.12 | K5: 1 | L5: =IFERROR(M5*I5/1000,"") -> 18.5184 | M5: =M3 -> 5 | O5: =K5*H5 -> 0.0074286924
A6: OfficeLarge | B6: Server_Room_Basement | C6: Server Room (EPD 45) | D6: CRAH_ServerRoom_Basement | E6: CAV CW | F6: Data | G6: Yes | H6: =I6/$I$82 -> 0.016503391 | I6: 8228 | J6: =I6*Prototype!$B$17 -> 74052 | K6: 1 | L6: =IFERROR(M6*I6/1000,"") -> 12.342 | M6: 1.5 | N6: New space type defined for this prototype. | O6: =K6*H6 -> 0.016503391
A7: OfficeLarge | B7: Mech/Elec_Basement | C7: Electrical, Mechanical, Telephone Rooms | D7: VAV With Reheat_Basement | E7: VAV_Basement | F7: Ancillary | G7: Yes | H7: =I7/$I$82 -> 0.015961836 | I7: 7958 | J7: =I7*Prototype!$B$17 -> 71622 | K7: 1 | L7: =IFERROR(M7*I7/1000,"") -> 0 | M7: 0 | O7: =K7*H7 -> 0.015961836
A8: OfficeLarge | B8: Conference_Basement | C8: Convention, Conference, Multipurpose and Meeting Area | D8: VAV With Reheat_Basement | E8: VAV_Basement | F8: Office | G8: Yes | H8: =I8/$I$82 -> 0.0011627389 | I8: 579.7 | J8: =I8*Prototype!$B$17 -> 5217.3 | K8: 1 | L8: =IFERROR(M8*I8/1000,"") -> 19.1301 | M8: 33 | O8: =K8*H8 -> 0.0011627389
A9: OfficeLarge | B9: BreakRoom/FoodPrep_Basement | C9: Lounge, Breakroom, or Waiting Area | D9: VAV With Reheat_Basement | E9: VAV_Basement | F9: Office | G9: Yes | H9: =I9/$I$82 -> 0.0019516043 | I9: 973 | J9: =I9*Prototype!$B$17 -> 8757 | K9: 1 | L9: =IFERROR(M9*I9/1000,"") -> 32.109 | M9: 33 | O9: =K9*H9 -> 0.0019516043
A10: OfficeLarge | B10: Storage_Basement | C10: Storage (General) | D10: VAV With Reheat_Basement | E10: VAV_Basement | F10: Office | G10: Yes | H10: =I10/$I$82 -> 0.0024690903 | I10: 1231 | J10: =I10*Prototype!$B$17 -> 11079 | K10: 1 | L10: =IFERROR(M10*I10/1000,"") -> 0 | M10: 0 | N10: Occupant load density for storage is based on Title 24, 2025, Appendix 5.4A. | O10: =K10*H10 -> 0.0024690903
A11: OfficeLarge | B11: Restroom_Basement | C11: Restrooms | F11: Office | G11: Yes | H11: =I11/$I$82 -> 0.0019776791 | I11: 986 | J11: =I11*Prototype!$B$17 -> 8874 | K11: 1 | L11: =IFERROR(M11*I11/1000,"") -> 0 | M11: 0 | N11: Indirectly conditioned | O11: =K11*H11 -> 0.0019776791
A12: OfficeLarge | B12: Lobby/Lounge_Basement | C12: Lounge, Breakroom, or Waiting Area | D12: VAV With Reheat_Basement | E12: VAV_Basement | F12: Office | G12: Yes | H12: =I12/$I$82 -> 0.0014180722 | I12: 707 | J12: =I12*Prototype!$B$17 -> 6363 | K12: 1 | L12: =IFERROR(M12*I12/1000,"") -> 10.605 | M12: 15 | N12: Increased the ASHRAE 62.1 number of people (10) since this area is more of a lounge/lobby space and not main entry lobby. Number of People: 10 according to ASHRAE 62.1 Table 6-1 for main entry lobbies T24: 33 for main Entry lobbies & 5 for reception area | O12: =K12*H12 -> 0.0014180722
A13: OfficeLarge | B13: Stair/Elevator_Basement | C13: Stairwell | D13: VAV With Reheat_Basement | E13: VAV_Basement | F13: Ancillary | G13: Yes | H13: =I13/$I$82 -> 0.00188742 | I13: 941 | J13: =I13*Prototype!$B$17 -> 8469 | K13: 1 | L13: =IFERROR(M13*I13/1000,"") -> 0 | M13: 0 | O13: =K13*H13 -> 0.00188742
A14: OfficeLarge | B14: Corridor_W_Basement | C14: Corridor Area | D14: VAV With Reheat_Basement | E14: VAV_Basement | F14: Office | G14: Yes | H14: =I14/$I$82 -> 0.0014100491 | I14: 703 | J14: =I14*Prototype!$B$17 -> 6327 | K14: 1 | L14: =IFERROR(M14*I14/1000,"") -> 3.515 | M14: 5 | O14: =K14*H14 -> 0.0014100491
A15: OfficeLarge | B15: Corridor_E_Basement | C15: Corridor Area | D15: VAV With Reheat_Basement | E15: VAV_Basement | F15: Office | G15: Yes | H15: =I15/$I$82 -> 0.00052731425 | I15: 262.9 | J15: =I15*Prototype!$B$17 -> 2366.1 | K15: 1 | L15: =IFERROR(M15*I15/1000,"") -> 1.3145 | M15: 5 | O15: =K15*H15 -> 0.00052731425
A16: OfficeLarge | B16: Perimeter_Open_Office_N_FloorG | C16: Office Area (>250 square feet) | D16: VAV With Reheat_FloorG | E16: AHU VAV_FloorG | F16: Office | G16: Yes | H16: =I16/$I$82 -> 0.014303655 | I16: 7131.29 | J16: =I16*Prototype!$B$17 -> 64181.61 | K16: 1 | L16: =IFERROR(M16*I16/1000,"") -> 35.65645 | M16: =$M$3 -> 5 | O16: =K16*H16 -> 0.014303655
A17: OfficeLarge | B17: Perimeter_Open_Office_W_FloorG | C17: Office Area (>250 square feet) | D17: VAV With Reheat_FloorG | E17: AHU VAV_FloorG | F17: Office | G17: Yes | H17: =I17/$I$82 -> 0.011624922 | I17: 5795.77 | J17: =I17*Prototype!$B$17 -> 52161.93 | K17: 1 | L17: =IFERROR(M17*I17/1000,"") -> 28.97885 | M17: =$M$3 -> 5 | O17: =K17*H17 -> 0.011624922
A18: OfficeLarge | B18: Perimeter_Open_Office_E_FloorG | C18: Office Area (>250 square feet) | D18: VAV With Reheat_FloorG | E18: AHU VAV_FloorG | F18: Office | G18: Yes | H18: =I18/$I$82 -> 0.011784822 | I18: 5875.49 | J18: =I18*Prototype!$B$17 -> 52879.41 | K18: 1 | L18: =IFERROR(M18*I18/1000,"") -> 29.37745 | M18: =$M$3 -> 5 | O18: =K18*H18 -> 0.011784822
A19: OfficeLarge | B19: Perimeter_Enclosed_Office_NE_FloorG | C19: Office Area (>250 square feet) | D19: VAV With Reheat_FloorG | E19: AHU VAV_FloorG | F19: Office | G19: Yes | H19: =I19/$I$82 -> 0.0018400439 | I19: 917.38 | J19: =I19*Prototype!$B$17 -> 8256.42 | K19: 1 | L19: =IFERROR(M19*I19/1000,"") -> 4.5869 | M19: =$M$3 -> 5 | O19: =K19*H19 -> 0.0018400439
A20: OfficeLarge | B20: Perimeter_Enclosed_Office_NW_FloorG | C20: Office Area (>250 square feet) | D20: VAV With Reheat_FloorG | E20: AHU VAV_FloorG | F20: Office | G20: Yes | H20: =I20/$I$82 -> 0.0022689355 | I20: 1131.21 | J20: =I20*Prototype!$B$17 -> 10180.89 | K20: 1 | L20: =IFERROR(M20*I20/1000,"") -> 5.65605 | M20: =$M$3 -> 5 | O20: =K20*H20 -> 0.0022689355 | Q20: Basement | V20: First Floor | AA20: Middle/Top Floors
A21: OfficeLarge | B21: Core_Enclosed_Office_FloorG | C21: Office Area (>250 square feet) | D21: VAV With Reheat_FloorG | E21: AHU VAV_FloorG | F21: Office | G21: Yes | H21: =I21/$I$82 -> 0.006643638 | I21: 3312.28 | J21: =I21*Prototype!$B$17 -> 29810.52 | K21: 1 | L21: =IFERROR(M21*I21/1000,"") -> 16.5614 | M21: =$M$3 -> 5 | O21: =K21*H21 -> 0.006643638 | Q21: Area Distribution By Space Type | V21: Area Distribution By Space Type | AA21: Area Distribution By Space Type
A22: OfficeLarge | B22: Server_Room_FloorG | C22: Computer Room (EPD 20) | D22: CRAC DX Clg_FloorG | E22: CRAC DX Clg | F22: Data | G22: Yes | H22: =I22/$I$82 -> 0.00083658235 | I22: 417.09 | J22: =I22*Prototype!$B$17 -> 3753.81 | K22: 1 | L22: =IFERROR(M22*I22/1000,"") -> 0.625635 | M22: 1.5 | N22: New space type defined for this prototype. | O22: =K22*H22 -> 0.00083658235 | Q22: Space Type | R22: Area (ft2)​ | S22: % of footprint | V22: Space Type | W22: Area (ft2)​ | X22: % of footprint | AA22: Space Type | AB22: Area (ft2)​ | AC22: % of footprint
A23: OfficeLarge | B23: Mech/Elec_FloorG | C23: Electrical, Mechanical, Telephone Rooms | D23: VAV With Reheat_FloorG | E23: AHU VAV_FloorG | F23: Ancillary | G23: Yes | H23: =I23/$I$82 -> 0.0017028098 | I23: 848.96 | J23: =I23*Prototype!$B$17 -> 7640.64 | K23: 1 | L23: =IFERROR(M23*I23/1000,"") -> 0 | M23: 0 | O23: =K23*H23 -> 0.0017028098 | Q23: Open office​ | R23: =I3+I4 -> 12079.04 | S23: =R23/$R$36 -> 0.31494381 | V23: Open office​ | W23: =I17+I18+I16 -> 18802.55 | X23: =W23/$R$36 -> 0.49024978 | AA23: Open office​ | AB23: =I36+I37+I38+I39 -> 21287.86 | AC23: =AB23/$R$36 -> 0.55505071
A24: OfficeLarge | B24: Conference_FloorG | C24: Convention, Conference, Multipurpose and Meeting Area | D24: VAV With Reheat_FloorG | E24: AHU VAV_FloorG | F24: Office | G24: Yes | H24: =I24/$I$82 -> 0.0015841691 | I24: 789.81 | J24: =I24*Prototype!$B$17 -> 7108.29 | K24: 1 | L24: =IFERROR(M24*I24/1000,"") -> 26.06373 | M24: 33 | O24: =K24*H24 -> 0.0015841691 | Q24: Core Enclosed Office​ | R24: =I5 -> 3703.68 | S24: =R24/$R$36 -> 0.096568195 | V24: Core Enclosed Office​ | W24: =I21 -> 3312.28 | X24: =W24/$R$36 -> 0.086362996 | AA24: Core Enclosed Office​ | AB24: =I44 -> 3233 | AC24: =AB24/$R$36 -> 0.084295883
A25: OfficeLarge | B25: BreakRoom_FloorG | C25: Lounge, Breakroom, or Waiting Area | D25: VAV With Reheat_FloorG | E25: AHU VAV_FloorG | F25: Office | G25: Yes | H25: =I25/$I$82 -> 0.0012400209 | I25: 618.23 | J25: =I25*Prototype!$B$17 -> 5564.07 | K25: 1 | L25: =IFERROR(M25*I25/1000,"") -> 20.40159 | M25: 33 | O25: =K25*H25 -> 0.0012400209 | Q25: Perimeter Enclosed Office​ | R25: _ | S25: _ | V25: Perimeter Enclosed Office​ | W25: =I20+I19 -> 2048.59 | X25: =W25/$R$36 -> 0.053414075 | AA25: Perimeter Enclosed Office​ | AB25: =I40+I41+I42+I43 -> 4092.56 | AC25: =AB25/$R$36 -> 0.10670769
A26: OfficeLarge | B26: FoodPrep_FloorG | C26: Kitchen/Food Preparation Area | D26: VAV With Reheat_FloorG | E26: AHU VAV_FloorG | F26: Office | G26: Yes | H26: =I26/$I$82 -> 0.0018792766 | I26: 936.94 | J26: =I26*Prototype!$B$17 -> 8432.46 | K26: 1 | L26: =IFERROR(M26*I26/1000,"") -> 2.81082 | M26: 3 | O26: =K26*H26 -> 0.0018792766 | Q26: Conference​ | R26: =I8 -> 579.7 | S26: =R26/$R$36 -> 0.015114854 | V26: Conference​ | W26: =I24 -> 789.81 | X26: =W26/$R$36 -> 0.020593174 | AA26: Conference​ | AB26: =I47+I48+I49+I50 -> 2323.24 | AC26: =AB26/$R$36 -> 0.060575183
A27: OfficeLarge | B27: Storage_FloorG | C27: Storage (General) | D27: VAV With Reheat_FloorG | E27: AHU VAV_FloorG | F27: Office | G27: Yes | H27: =I27/$I$82 -> 0.0019235838 | I27: 959.03 | J27: =I27*Prototype!$B$17 -> 8631.27 | K27: 1 | L27: =IFERROR(M27*I27/1000,"") -> 0 | M27: 0 | N27: Occupant load density for storage is based on Title 24, 2025, Appendix 5.4A. | O27: =K27*H27 -> 0.0019235838 | Q27: Break + Food prep​ | R27: =I9 -> 973 | S27: =R27/$R$36 -> 0.025369593 | V27: Break + Food prep​ | W27: =I26+I25 -> 1555.17 | X27: =W27/$R$36 -> 0.040548849 | AA27: Break + Food prep​ | AB27: =I51 -> 910 | AC27: =AB27/$R$36 -> 0.023726957
A28: OfficeLarge | B28: Locker_FloorG | C28: Locker Room | D28: VAV With Reheat_FloorG | E28: AHU VAV_FloorG | F28: Office | G28: Yes | H28: =I28/$I$82 -> 0.0035406273 | I28: 1765.23 | J28: =I28*Prototype!$B$17 -> 15887.07 | K28: 1 | L28: =IFERROR(M28*I28/1000,"") -> 17.6523 | M28: 10 | N28: Based on 2022 CEC AP5 | O28: =K28*H28 -> 0.0035406273 | Q28: Storage​ | R28: =I10 -> 1231 | S28: =R28/$R$36 -> 0.032096577 | V28: Storage​+locker | W28: =I28+I27 -> 2724.26 | X28: =W28/$R$36 -> 0.07103121 | AA28: Storage​ | AB28: =I52 -> 738 | AC28: =AB28/$R$36 -> 0.019242302
A29: OfficeLarge | B29: Lobby_S_FloorG | C29: Lobby, Main Entry | D29: VAV With Reheat_FloorG | E29: AHU VAV_FloorG | F29: Office | G29: Yes | H29: =I29/$I$82 -> 0.0067406165 | I29: 3360.63 | J29: =I29*Prototype!$B$17 -> 30245.67 | K29: 1 | L29: =IFERROR(M29*I29/1000,"") -> 33.6063 | M29: 10 | N29: According to ASHRAE 62.1 Table 6-1 for main entry lobbies | O29: =K29*H29 -> 0.0067406165 | Q29: Mech/Elec​ | R29: =I7 -> 7958 | S29: =R29/$R$36 -> 0.20749355 | V29: Mech/Elec​ | W29: =I23 -> 848.96 | X29: =W29/$R$36 -> 0.022135426 | AA29: Mech/Elec​ | AB29: =I46 -> 1070 | AC29: =AB29/$R$36 -> 0.02789873
A30: OfficeLarge | B30: Lobby/Lounge_FloorG | C30: Lounge, Breakroom, or Waiting Area | D30: VAV With Reheat_FloorG | E30: AHU VAV_FloorG | F30: Office | G30: Yes | H30: =I30/$I$82 -> 0.0013717391 | I30: 683.9 | J30: =I30*Prototype!$B$17 -> 6155.1 | K30: 1 | L30: =IFERROR(M30*I30/1000,"") -> 10.2585 | M30: =M12 -> 15 | N30: Increased the ASHRAE 62.1 number of people (10) since this area is more of a lounge/lobby space and not main entry lobby. | O30: =K30*H30 -> 0.0013717391 | Q30: Server Room​ | R30: =I6 -> 8228 | S30: =R30/$R$36 -> 0.21453341 | V30: Server Room​ | W30: =I22 -> 417.09 | X30: =W30/$R$36 -> 0.010875029 | AA30: Server Room​ | AB30: =I45 -> 418 | AC30: =AB30/$R$36 -> 0.010898756
A31: OfficeLarge | B31: Restroom_FloorG | C31: Restrooms | F31: Office | G31: Yes | H31: =I31/$I$82 -> 0.0023188388 | I31: 1156.09 | J31: =I31*Prototype!$B$17 -> 10404.81 | K31: 1 | L31: =IFERROR(M31*I31/1000,"") -> 0 | M31: 0 | N31: Indirectly conditioned | O31: =K31*H31 -> 0.0023188388 | Q31: Corridor​ | R31: =I14+I15 -> 965.9 | S31: =R31/$R$36 -> 0.025184471 | V31: Corridor​ | W31: =I34+I33 -> 1804.63 | X31: =W31/$R$36 -> 0.047053164 | AA31: Corridor​ | AB31: =I56+I57 -> 1591.24 | AC31: =AB31/$R$36 -> 0.041489323
A32: OfficeLarge | B32: Stair/Elevator_FloorG | C32: Stairwell | D32: VAV With Reheat_FloorG | E32: AHU VAV_FloorG | F32: Ancillary | G32: Yes | H32: =I32/$I$82 -> 0.0017009044 | I32: 848.01 | J32: =I32*Prototype!$B$17 -> 7632.09 | K32: 1 | L32: =IFERROR(M32*I32/1000,"") -> 0 | M32: 0 | O32: =K32*H32 -> 0.0017009044 | Q32: Restroom​ | R32: =I11 -> 986 | S32: =R32/$R$36 -> 0.02570855 | V32: Restroom​ | W32: =I31 -> 1156.09 | X32: =W32/$R$36 -> 0.030143405 | AA32: Restroom​ | AB32: =I54 -> 1155 | AC32: =AB32/$R$36 -> 0.030114984
A33: OfficeLarge | B33: Corridor_W_FloorG | C33: Corridor Area | D33: VAV With Reheat_FloorG | E33: AHU VAV_FloorG | F33: Office | G33: Yes | H33: =I33/$I$82 -> 0.0020175336 | I33: 1005.87 | J33: =I33*Prototype!$B$17 -> 9052.83 | K33: 1 | L33: =IFERROR(M33*I33/1000,"") -> 5.02935 | M33: 5 | O33: =K33*H33 -> 0.0020175336 | Q33: Lobby​/Lounge | R33: =I12 -> 707 | S33: =R33/$R$36 -> 0.018434021 | V33: Lobby​/Lounge | W33: =I30+I29 -> 4044.53 | X33: =W33/$R$36 -> 0.10545538 | AA33: Lobby​/Lounge | AB33: =I53 -> 684 | AC33: =AB33/$R$36 -> 0.017834328
A34: OfficeLarge | B34: Corridor_E_FloorG | C34: Corridor Area | D34: VAV With Reheat_FloorG | E34: AHU VAV_FloorG | F34: Office | G34: Yes | H34: =I34/$I$82 -> 0.0016021207 | I34: 798.76 | J34: =I34*Prototype!$B$17 -> 7188.84 | K34: 1 | L34: =IFERROR(M34*I34/1000,"") -> 3.9938 | M34: 5 | O34: =K34*H34 -> 0.0016021207 | Q34: Stair/Elevator​ | R34: =I13 -> 941 | S34: =R34/$R$36 -> 0.024535238 | V34: Stair/Elevator​ | W34: =I32 -> 848.01 | X34: =W34/$R$36 -> 0.022110656 | AA34: Stair/Elevator​ | AB34: =I55 -> 848 | AC34: =AB34/$R$36 -> 0.022110396
A35: OfficeLarge | B35: Plenum_FloorG | C35: Plenum | D35: _ | E35: - | G35: No | I35: =38352.97 -> 38352.97 | J35: =I35*(Prototype!$B$16-Prototype!$B$17) -> 153411.88 | K35: 1 | L35: =IFERROR(M35*I35/1000,"") -> 0 | M35: 0 | O35: =K35*H35 -> 0 | Q35: Plenum​ | R35: =I35 -> 38352.97 | S35: =SUM(S23:S34) -> 0.99998227 | V35: Plenum​ | W35: =I35 -> 38352.97 | X35: =W35/$R$36 -> 0.99999922 | AA35: Plenum​ | AB35: 38,353 ​ | AC35: 1
A36: OfficeLarge | B36: Perimeter_Open_Office_N_FloorM | C36: Office Area (>250 square feet) | D36: VAV With Reheat_FloorM | E36: AHU VAV_FloorM | F36: Office | G36: Yes | H36: =I36/$I$82 -> 0.014303655 | I36: 7131.29 | J36: =I36*Prototype!$B$17 -> 64181.61 | K36: 10 | L36: =IFERROR(M36*I36/1000,"") -> 35.65645 | M36: 5 | O36: =K36*H36 -> 0.14303655 | Q36: Total | R36: 38353 | S36: =SUM(S23:S34) -> 0.99998227 | V36: Total | X36: =SUM(X23:X34) -> 0.99997314 | AA36: Total | AC36: =SUM(AC23:AC34) -> 0.99994525
A37: OfficeLarge | B37: Perimeter_Open_Office_S_FloorM | C37: Office Area (>250 square feet) | D37: VAV With Reheat_FloorM | E37: AHU VAV_FloorM | F37: Office | G37: Yes | H37: =I37/$I$82 -> 0.010504906 | I37: 5237.37 | J37: =I37*Prototype!$B$17 -> 47136.33 | K37: 10 | L37: =IFERROR(M37*I37/1000,"") -> 26.18685 | M37: =M3 -> 5 | O37: =K37*H37 -> 0.10504906
A38: OfficeLarge | B38: Perimeter_Open_Office_E_FloorM | C38: Office Area (>250 square feet) | D38: VAV With Reheat_FloorM | E38: AHU VAV_FloorM | F38: Office | G38: Yes | H38: =I38/$I$82 -> 0.0089666288 | I38: 4470.44 | J38: =I38*Prototype!$B$17 -> 40233.96 | K38: =K37 -> 10 | L38: =IFERROR(M38*I38/1000,"") -> 22.3522 | M38: =M3 -> 5 | O38: =K38*H38 -> 0.089666288
A39: OfficeLarge | B39: Perimeter_Open_Office_W_FloorM | C39: Office Area (>250 square feet) | D39: VAV With Reheat_FloorM | E39: AHU VAV_FloorM | F39: Office | G39: Yes | H39: =I39/$I$82 -> 0.0089231439 | I39: 4448.76 | J39: =I39*Prototype!$B$17 -> 40038.84 | K39: =K38 -> 10 | L39: =IFERROR(M39*I39/1000,"") -> 22.2438 | M39: =M3 -> 5 | O39: =K39*H39 -> 0.089231439 | Q39: Area Distribution By Space Type
A40: OfficeLarge | B40: Perimeter_Enclosed_Office_NE_FloorM | C40: Office Area (>250 square feet) | D40: VAV With Reheat_FloorM | E40: AHU VAV_FloorM | F40: Office | G40: Yes | H40: =I40/$I$82 -> 0.0018400439 | I40: 917.38 | J40: =I40*Prototype!$B$17 -> 8256.42 | K40: =K39 -> 10 | L40: =IFERROR(M40*I40/1000,"") -> 4.5869 | M40: =M3 -> 5 | O40: =K40*H40 -> 0.018400439 | Q40: Space Type | T40: % Area
...

Sheet Envelope
A1: ="Envelope - "&Prototype!A2 -> Envelope - OfficeLarge
A2: Element | B2: Prototype | C2: Assembly Type | D2: Construction | E2: Thermal Properties | F2: Vintage | G2: Selected T24 | H2: Notes | I2: CZ1 | J2: CZ2 | K2: CZ3 | L2: CZ4 | M2: CZ5 | N2: CZ6 | O2: CZ7 | P2: CZ8 | Q2: CZ9 | R2: CZ10 | S2: CZ11 | T2: CZ12 | U2: CZ13 | V2: CZ14 | W2: CZ15 | X2: CZ16
A3: External Wall | B3: OfficeLarge | C3: ExtWall_MetalFramed_NonRes | D3: Metal framed wall: Metal frame + insulation + Gypsum board | E3: U-factor IP | F3: Pre 1978 | G3: N/A | H3: Using DOE pre-1980 U-values and a 7.4% cumulative wall renovation rate through 2028, based on the average annual rate from CBECS 2003 and 2012 projected over 48 years. | I3: =I54*(1-$I$55)+I53*$I$55 -> 0.217454 | J3: =J54*(1-$I$55)+J53*$I$55 -> 0.21479 | K3: =K54*(1-$I$55)+K53*$I$55 -> 0.21627 | L3: =L54*(1-$I$55)+L53*$I$55 -> 0.21479 | M3: =M54*(1-$I$55)+M53*$I$55 -> 0.21479 | N3: =N54*(1-$I$55)+N53*$I$55 -> 0.217454 | O3: =O54*(1-$I$55)+O53*$I$55 -> 0.217454 | P3: =P54*(1-$I$55)+P53*$I$55 -> 0.21479 | ... X3: =X54*(1-$I$55)+X53*$I$55 -> 0.21479
F4: 1978-1997 | G4: 1986 | H4: High-rise office: Package A with heat capacity 0-3.99 (BTU/F/ft2) | I4: =1/7.4 -> 0.13513514 | J4: =1/7.4 -> 0.13513514 | K4: =1/7.4 -> 0.13513514 | L4: =1/7.4 -> 0.13513514 | M4: =1/7.4 -> 0.13513514 | N4: =1/7.4 -> 0.13513514 | O4: =1/7.4 -> 0.13513514 | P4: =1/7.4 -> 0.13513514 | ... X4: =1/7.4 -> 0.13513514 | Y4: These values have better performance than the next vintage
F5: 1998-2007 | G5: 2001 | H5: TABLE 1-H | I5: 0.182 | J5: 0.182 | K5: 0.189 | L5: 0.189 | M5: 0.189 | N5: 0.189 | O5: 0.189 | P5: 0.189 | Q5: 0.189 | R5: 0.182 | S5: 0.182 | T5: 0.182 | U5: 0.182 | V5: 0.182 | W5: 0.182 | X5: 0.182
F6: 2008-2018 | G6: 2013 | H6: TABLE 140.3-B | I6: 0.098 | J6: 0.062 | K6: 0.082 | L6: 0.062 | M6: 0.062 | N6: 0.098 | O6: 0.098 | P6: 0.062 | Q6: 0.062 | R6: 0.062 | S6: 0.062 | T6: 0.062 | U6: 0.062 | V6: 0.062 | W6: 0.062 | X6: 0.062
F7: Existing | H7: Weighted average of all 4 vintages | I7: {=_xlfn.BYCOL(TRANSPOSE(Weights!$C$4:$F$19)*I3:X6,_xlfn.LAMBDA(_xlpm.c,SUM(_xlpm.c)))} -> 0.18924155 | J7: 0.18102834 | K7: 0.17198393 | L7: 0.17002612 | M7: 0.14965441 | N7: 0.17002225 | O7: 0.15822291 | P7: 0.16769836 | Q7: 0.16782733 | R7: 0.1544061 | S7: 0.17874604 | T7: 0.16825889 | U7: 0.1934896 | V7: 0.15994628 | W7: 0.16062511 | X7: 0.16669266
F8: 2019+ | G8: 2025 | H8: Table 140.3-B (In Nonres Section) | I8: 0.06 | J8: 0.055 | K8: 0.071 | L8: 0.055 | M8: 0.055 | N8: 0.06 | O8: 0.06 | P8: 0.055 | Q8: 0.055 | R8: 0.055 | S8: 0.055 | T8: 0.055 | U8: 0.055 | V8: 0.055 | W8: 0.055 | X8: 0.055
A9: Roof | B9: OfficeLarge | C9: FlatRoof_WoodFramedAndOther_NonRes | D9: Metal deck roof: Metal deck + insulation + Roof membrane | E9: U-factor IP | F9: Pre 1978 | G9: N/A | H9: Considering 30 years for roof/ insulation replacement. | I9: =I10 -> 0.057 | J9: =J10 -> 0.057 | K9: =K10 -> 0.057 | L9: =L10 -> 0.057 | M9: =M10 -> 0.057 | N9: =N10 -> 0.078 | O9: =O10 -> 0.078 | P9: =P10 -> 0.078 | ... X9: =X10 -> 0.057
F10: 1978-1997 | G10: 1992 | I10: 0.057 | J10: 0.057 | K10: 0.057 | L10: 0.057 | M10: 0.057 | N10: 0.078 | O10: 0.078 | P10: 0.078 | Q10: 0.078 | R10: 0.078 | S10: 0.057 | T10: 0.057 | U10: 0.057 | V10: 0.057 | W10: 0.057 | X10: 0.057
F11: 1998-2007 | G11: 2001 | H11: TABLE 1-H | I11: 0.057 | J11: 0.057 | K11: 0.057 | L11: 0.057 | M11: 0.057 | N11: 0.078 | O11: 0.078 | P11: 0.078 | Q11: 0.078 | R11: 0.057 | S11: 0.057 | T11: 0.057 | U11: 0.057 | V11: 0.057 | W11: 0.057 | X11: 0.057
F12: 2008-2018 | G12: 2013 | H12: TABLE 140.3-B | I12: 0.049 | J12: 0.039 | K12: 0.039 | L12: 0.039 | M12: 0.049 | N12: 0.075 | O12: 0.067 | P12: 0.067 | Q12: 0.039 | R12: 0.039 | S12: 0.039 | T12: 0.039 | U12: 0.039 | V12: 0.039 | W12: 0.039 | X12: 0.039
F13: Existing | H13: Weighted average of all 4 vintages | I13: {=_xlfn.BYCOL(TRANSPOSE(Weights!$C$4:$F$19)*I9:X12,_xlfn.LAMBDA(_xlpm.c,SUM(_xlpm.c)))} -> 0.056694637 | J13: 0.056997044 | K13: 0.055521064 | L13: 0.055511841 | M13: 0.056752486 | N13: 0.077797386 | O13: 0.077219947 | P13: 0.077386796 | Q13: 0.075393743 | R13: 0.067987435 | S13: 0.055160434 | T13: 0.055314849 | U13: 0.056011139 | V13: 0.055793834 | W13: 0.053451975 | X13: 0.055656073
F14: 2019+ | G14: 2025 | H14: Table 140.3-B (In Nonres Section) | I14: 0.028 | J14: 0.028 | K14: 0.028 | L14: 0.028 | M14: 0.028 | N14: 0.047 | O14: 0.047 | P14: 0.047 | Q14: 0.028 | R14: 0.028 | S14: 0.028 | T14: 0.028 | U14: 0.028 | V14: 0.028 | W14: 0.028 | X14: 0.028
A15: Windows | B15: OfficeLarge | C15: FixedWindow_NonRes | D15: CBECS 2018 shows that ~50% of large offices that were built before 2000 are single pane | E15: U-factor IP | F15: Pre 1978 | G15: N/A | H15: ASHRAE Handbook of Fundamentals for single pane (Table 4-Ch15) & T24, 2013 for double pane(50%-50%)* | I15: =1.12*0.5+I$18*0.5 -> 0.74 | J15: =1.12*0.5+J$18*0.5 -> 0.74 | K15: =1.12*0.5+K$18*0.5 -> 0.74 | L15: =1.12*0.5+L$18*0.5 -> 0.74 | M15: =1.12*0.5+M$18*0.5 -> 0.74 | N15: =1.12*0.5+N$18*0.5 -> 0.74 | O15: =1.12*0.5+O$18*0.5 -> 0.74 | P15: =1.12*0.5+P$18*0.5 -> 0.74 | ... X15: =1.12*0.5+X$18*0.5 -> 0.74
F16: 1978-1997 | G16: N/A | I16: =1.12*0.5+I$18*0.5 -> 0.74 | J16: =1.12*0.5+J$18*0.5 -> 0.74 | K16: =1.12*0.5+K$18*0.5 -> 0.74 | L16: =1.12*0.5+L$18*0.5 -> 0.74 | M16: =1.12*0.5+M$18*0.5 -> 0.74 | N16: =1.12*0.5+N$18*0.5 -> 0.74 | O16: =1.12*0.5+O$18*0.5 -> 0.74 | P16: =1.12*0.5+P$18*0.5 -> 0.74 | ... X16: =1.12*0.5+X$18*0.5 -> 0.74
D17: Double pane | F17: 1998-2007 | G17: 2001 | H17: TABLE 1-H | I17: 0.49 | J17: 0.49 | K17: 0.81 | L17: 0.81 | M17: 0.81 | N17: 0.81 | O17: 0.81 | P17: 0.81 | Q17: 0.81 | R17: 0.49 | S17: 0.49 | T17: 0.49 | U17: 0.49 | V17: 0.49 | W17: 0.49 | X17: 0.49
F18: 2008-2018 | G18: 2013 | H18: TABLE 140.3-B | I18: 0.36 | J18: 0.36 | K18: 0.36 | L18: 0.36 | M18: 0.36 | N18: 0.36 | O18: 0.36 | P18: 0.36 | Q18: 0.36 | R18: 0.36 | S18: 0.36 | T18: 0.36 | U18: 0.36 | V18: 0.36 | W18: 0.36 | X18: 0.36
F19: Existing | H19: Weighted average of all 4 vintages | I19: {=_xlfn.BYCOL(TRANSPOSE(Weights!$C$4:$F$19)*I15:X18,_xlfn.LAMBDA(_xlpm.c,SUM(_xlpm.c)))} -> 0.70392657 | J19: 0.7039536 | K19: 0.72003281 | L19: 0.71988375 | M19: 0.73073806 | N19: 0.72572203 | O19: 0.72838696 | P19: 0.72733681 | Q19: 0.72143466 | R19: 0.62965758 | S19: 0.65883922 | T19: 0.66052866 | U19: 0.70816568 | V19: 0.65542443 | W19: 0.59484222 | X19: 0.64407311
F20: 2019+ | G20: 2025 | H20: Table 140.3-B (In Nonres Section) | I20: 0.36 | J20: 0.36 | K20: 0.36 | L20: 0.36 | M20: 0.36 | N20: 0.36 | O20: 0.36 | P20: 0.36 | Q20: 0.34 | R20: 0.36 | S20: 0.34 | T20: 0.34 | U20: 0.34 | V20: 0.34 | W20: 0.34 | X20: 0.36
C21: FixedWindow_NonRes | D21: CBECS 2018 shows that ~50% of large offices that were built before 2000 are single pane | E21: SHGC | F21: Pre 1978 | G21: N/A | H21: ASHRAE Handbook of Fundamentals for single pane (Table 10-Ch15) & T24, 2013 for double pane(50%-50%)* | I21: =0.79*0.5+I$24*0.5 -> 0.52 | J21: =0.79*0.5+J$24*0.5 -> 0.52 | K21: =0.79*0.5+K$24*0.5 -> 0.52 | L21: =0.79*0.5+L$24*0.5 -> 0.52 | M21: =0.79*0.5+M$24*0.5 -> 0.52 | N21: =0.79*0.5+N$24*0.5 -> 0.52 | O21: =0.79*0.5+O$24*0.5 -> 0.52 | P21: =0.79*0.5+P$24*0.5 -> 0.52 | ... X21: =0.79*0.5+X$24*0.5 -> 0.52
F22: 1978-1997 | G22: N/A | I22: =I21 -> 0.52 | J22: =J21 -> 0.52 | K22: =K21 -> 0.52 | L22: =L21 -> 0.52 | M22: =M21 -> 0.52 | N22: =N21 -> 0.52 | O22: =O21 -> 0.52 | P22: =P21 -> 0.52 | ... X22: =X21 -> 0.52
F23: 1998-2007 | G23: 2001 | H23: WWR:30-40 / SHGC non-north (Non-north SHGC is more stringent than north and is therefore considered for all sides) | I23: 0.43 | J23: 0.31 | K23: 0.41 | L23: 0.41 | M23: 0.41 | N23: 0.34 | O23: 0.34 | P23: 0.34 | Q23: 0.34 | R23: 0.31 | S23: 0.31 | T23: 0.31 | U23: 0.31 | V23: 0.31 | W23: 0.31 | X23: 0.43
F24: 2008-2018 | G24: 2013 | H24: TABLE 140.3-B | I24: 0.25 | J24: 0.25 | K24: 0.25 | L24: 0.25 | M24: 0.25 | N24: 0.25 | O24: 0.25 | P24: 0.25 | Q24: 0.25 | R24: 0.25 | S24: 0.25 | T24: 0.25 | U24: 0.25 | V24: 0.25 | W24: 0.25 | X24: 0.25
F25: Existing | H25: Weighted average of all 4 vintages | I25: {=_xlfn.BYCOL(TRANSPOSE(Weights!$C$4:$F$19)*I21:X24,_xlfn.LAMBDA(_xlpm.c,SUM(_xlpm.c)))} -> 0.50192927 | J25: 0.48972911 | K25: 0.48012987 | L25: 0.47991968 | M25: 0.50772621 | N25: 0.47248524 | O25: 0.46142234 | P25: 0.4830395 | Q25: 0.48439649 | R25: 0.43248115 | S25: 0.45685309 | T25: 0.45785016 | U25: 0.49596206 | V25: 0.45225337 | W25: 0.4077654 | X25: 0.47552126
F26: 2019+ | G26: 2025 | H26: Table 140.3-B (In Nonres Section) | I26: 0.25 | J26: 0.25 | K26: 0.25 | L26: 0.25 | M26: 0.25 | N26: 0.25 | O26: 0.25 | P26: 0.25 | Q26: 0.22 | R26: 0.25 | S26: 0.22 | T26: 0.22 | U26: 0.22 | V26: 0.22 | W26: 0.22 | X26: 0.25
C28: Infiltration rate at normal pressure (cfm/ft2) (Design flow rate approach and Flow/Exterior Wall Area calculation method)
D29: Building | E29: Zones | F29: Vintage | G29: I_75 (cfm/sf) 6-sdied Infiltration rate @ 75 pa | H29: Note | I29: I-design (cfm/ft2) (4-sided Infiltration rate at normal pressure) (Design flow rate approach and Flow/Exterior Wall Area calculation method)
C30: Infiltration | D30: OfficeLarge | F30: Pre 1978 | G30: 1.1 | H30: 2022 CASE report (Table 38) | I30: =0.112*G30*$AA$32 -> 0.1952729 | Z30: Building 4 sided area (ft2) | AA30: =AA34 -> 131119.63
F31: 1978-1997 | G31: 1.1 | H31: 2022 CASE report (Table 38) | I31: =0.112*G31*$AA$32 -> 0.1952729 | Z31: Building 6 sided area (ft2) | AA31: =AA34+(2*AA33) -> 207825.57
F32: 1998-2007 | G32: 1.1 | H32: 2022 CASE report (Table 38) | I32: =0.112*G32*$AA$32 -> 0.1952729 | Z32: 6 sided /4 sided factor | AA32: =AA31/AA30 -> 1.5850073
F33: 2008-2018 | G33: 1 | H33: 2022 CASE report (Table 38) & Title 24, part 6, 2008-2016 (Table 140.3-B) | I33: =0.112*G33*$AA$32 -> 0.17752082 | Z33: Floor or roof area (ft2) | AA33: =498588.6/13 -> 38352.969
F34: Existing | G34: 1.1 | H34: Same as Pre 2008 because of their higher weights | I34: =0.112*G34*$AA$32 -> 0.1952729 | Z34: Walls area (ft2) | AA34: =(SQRT(AA33/1.5)+1.5*SQRT(AA33/1.5))*2*164 -> 131119.63
F35: 2019+ | G35: 0.6 | H35: 2022 CASE report (Table 38) & Title 24, part 6, 2025 (Table 140.3-B) | I35: =0.112*G35*$AA$32 -> 0.10651249
E36: Source: Title 24 air barrier requirements (all editions) and the standardized infiltration rate reported in the 2022 CASE report and Dodge 2023 data
E37: Air Leakage Memo: | G37: Infiltration_rate_report_14May2025-Short-Version.docx
A40: *Note for windows properties in vintage 1 &2 :
A41: We’ve considered a 50% single-pane and 50% double-pane mix (based on the 2013 requirements) for the window properties in Vintage 1 & 2 (pre-1998 buildings).
A42: We don't have California-specific data, and the decision was based on the CBECS 2018 data, which indicates:
A43: - 30% of large offices built before 1978 have mixed windows, while only 16% of large offices from the second vintage (1978-1997) have mixed glass.
...

Sheet HVAC System
A1: ="HVAC system - "&Prototype!A2 -> HVAC system - OfficeLarge | I1: Existing HVAC System Layout _ Each floor is served by one HVAC system
A2: Vintage | B2: Zones | C2: Heating | D2: Cooling | E2: Air Distribution | F2: Other Systems | G2: Source | I2: Basement | N2: First Floor | S2: Middle/Top Floors
A3: Existing | B3: Server Room_B | C3: - | D3: built up CRAH with chilled water coils (Computer Room Air Handling unit) | E3: CAV | F3: Fluid Economizer for vintage 4 | G3: Engineering Judgement
B4: Server_Room_G Server_Room_M Server_Room_T | C4: - | D4: DX Computer Room Air Conditioner (CRAC) | E4: CAV | F4: _ | G4: Engineering Judgement
B5: All other conditioned zones | C5: Gas Boiler | D5: Chiller (it also serves the Server_Room_B zone) | E5: VAV with hydronic reheat | F5: OA mixing through air handler Economizer for Vintage 2, 3 and 4 DCV for Vintage 4 (for qualifying high density rooms) | G5: CEUS 2022
A6: New Construction | B6: Server Room_B | C6: - | D6: built up CRAH with chilled water coils (Computer Room Air Handling unit) | E6: CAV | F6: Fluid Economizer | G6: T24 2025
B7: Server_Room_G Server_Room_M Server_Room_T | C7: - | D7: DX Computer Room Air Conditioner (CRAC) | E7: CAV | F7: _ | G7: T24 2025
B8: All other conditioned zones | C8: Gas Boiler | D8: Chiller (it also serves the Server_Room_B zone) | E8: VAV with hydronic reheat | F8: OA mixing through air handler ERV Economizer DCV for qualifying high density rooms | G8: T24 2025
A13: Efficiency of HVAC System (Efficiency is capacity-dependent. The following table provides a general estimate of system efficiency based on preliminary simulations in one climate zone, or assuming cooling load based on rule of thumb)
B14: Upgrade/Installed year | C14: DX Computer Room Air Conditioner Server_Room_G/M/T (CRAC) | D14: Chiller | E14: Gas Boiler | F14: Heat Rejection (Cooling Tower) | G14: Sources | H14: Note
A15: Pre 1978 | B15: 2008 | C15: 11 EER for <65 kBtu/h 10.4 EER for 65-135 kBtu/h 10.2 EER for 135-240 kBtu/h | D15: Water Cooled, Electrically Operated, Centrifugal--≥ 300 tons 6.10 COP 6.40 IPLV | E15: 80% Ec | F15: Axial fan Open-circuit cooling tower--95°F entering water 85°F leaving water 75°F entering air wb--≥ 38.2 gpm/hp | G15: CRAC: California Title 20 Appliance Efficiency Regulations, §1605.3(c)(2), Tables C-9 (2008) T24, Table 112-D (for chiller COP)(2008) California Title 20 Appliance Efficiency Regulations, Table E-3 for Boiler Efficiency (2008) T24, Table 112-G (Performance Requirements for Heat Rejection Equipment) (2008) | H15: Two centrifugal chillers (Total cooling plant load > 600 tons) Two atmospheric boilers (no combustion air fans)
A16: 1978-1997
A17: 1998-2007
A18: 2008-2018 | B18: 2013 This system will be used for the Collapsed version | C18: SCOP= 2.44 for <65 kBtu/h 2.34 for 65-240 kBtu/h 2.24 for >240 kBtu/h | D18: Water Cooled, Electrically Operated, Centrifugal--≥ 300 tons and < 600 tons ≤ 0.600 kW/ton (Path B) ≤ 0.400 IPLV (Path B) | E18: Gas-Fired Boiler > 300,000 Btu/h and ≤2,500,000 Btu/h-- 80% Et Gas-Fired Boiler > 2,500,000 Btu/h -- 82% Ec < 300,000 Btu/h 82% AFUE | F18: Axial fan Open-circuit cooling tower--95°F entering water 85°F leaving water 75°F entering air wb--≥ 42.1 gpm/hp | G18: CRAC: 10 CFR §431.97(f)(1), Table 7 (2013) T24, Table 110.2-D (for chiller COP) (2013) T24, Table 110.2-K (for Boiler thermal efficiency) (2013) T24, Table 110.2-G (Performance Requirements for Heat Rejection Equipment) (2013) | H18: water-cooled centrifugal chillers Two Boilers each with capacity between 300-2,500 KBTU/hr
A19: New Construction | B19: 2025 | C19: NSenCOP= 2.09 for <65 kBtu/h 1.99 for 65-240 kBtu/h 1,81 for >240 kBtu/h | D19: Water Cooled, Electrically Operated, Positive displacement--≥ 300 tons and < 600 tons ≤ 0.625 kW/ton (Path B) ≤ 0.410 IPLV (Path B) | E19: Gas-Fired Boiler > 300,000 Btu/h and ≤2,500,000 Btu/h-- 80% Et Gas-Fired Boiler > 2,500,000 Btu/h -- 82% Ec | F19: Axial fan Open-circuit cooling tower--95°F entering water 85°F leaving water 75°F entering air wb--≥ 42.1 gpm/hp | G19: CRAC: 10 CFR § 431.97, Table 13 (2025) T24, Table 110.2-D (for chiller COP)(2025) 10 CFR 431.86 , section § 431.87 Table 1 (for Boiler thermal efficiency)(2025) T24, Table 110.2-E (Performance Requirements for Heat Rejection Equipment)(2025) | H19: Two water-cooled screw chillers (Each between 300-600 tons), Path B, Positive displacement chiller with design leaving fluid temperature ≤ 32°F Two Boilers each with capacity between 300-2,500 KBTU/hr
A20: Fan power
A21: Vintage | B21: Approach | C21: System | D21: Total Static Pressure (in. w.c.) | E21: Fan Efficiency | F21: Motor Efficiency | G21: Fan Power Index (W/cfm) | H21: Data Source
A22: Existing | B22: PNNL 90.1-2011, TSP | C22: CRAC/CRAH CAV < 7,437 cfm | D22: 2.5 | E22: 0.65 | F22: ASHRAE 90.1-2004 Table 10.8 | H22: PNNL 20405 Table 5.11
C23: CRAC/CRAH CAV >= 7,437 cfm | D23: 4.09
C24: VAV > 4,648 cfm | D24: 5.58
A25: New Construction | B25: ACM 2025 | C25: CRAC/CRAH | D25: TSP = fan power x motor efficiency x fan efficiency x 6356 / 746 | E25: 0.65 | F25: ACM 2025 Table 12 | G25: 0.58 | H25: Computer room fan power index
C26: System 6 VAV, by supply cfm | D26: TSP = fan power x motor efficiency x fan efficiency x 6356 / 746 | G26: 0.977 <=5,000; 1.013 <=10,000; 0.947 >10,000 | H26: ACM 2025 Table 13
B27: Background Data [To be deleted prior to publication]
B29: Existing prototypes:
B31: Space | C31: System No. | D31: System Type | E31: Fan Control | F31: Cooling Type | G31: Heating Type
A32: CBECC 2025 | B32: All Space | E32: VAV | F32: Chilled water | G32: Hot-water fossil fuel boiler
A33: CPUC 2024 | B33: All Space | E33: VAV | F33: Chiller water | G33: Gas Boiler
A34: PNNL ASHRAE 90.1- 2022 San Diego | B34: data center room | C34: 14. WSHP (CRAC) | D34: Water source heat pump (Computer room air conditioning unit) | E34: Constant volume | F34: Fluid cooler | G34: Hot-water fossil fuel boiler
B35: Basement (Except data center) | C35: 12. SZ-CV-HW | D35: Single-zone system | E35: Constant volume | F35: Chilled water | G35: Hot-water fossil fuel boiler
B36: Other spaces | C36: 7. VAV with reheat | D36: VAV with reheat | E36: VAV | F36: Chilled water | G36: Hot-water fossil fuel boiler
A37: Basement system in PNNL model is :SZ-CV-HW (Single zone system: CV fan control & Chilled water cooling & Hot-water fossil fuel boiler heating)
A38: Other floors system in PNNL model is: VAV Reheat ( VAV with Reheat: VA fan control & Chilled water cooling & Hot-water fossil fuel boiler heating )
A39: Dat center zone has its won system in PNNL model: WSHP (CRAC): Water source heat pump (Computer room air conditioning unit) system: CV fan control & Fluid cooler & Hot-water fossil fuel boiler heating
B41: CEUS 2022 data:
A42: Heating System
A43: Calculation method | B43: Building Type | C43: Fan Coil / Unit Ventilator | D43: Dual Duct Constant Air Volume | E43: Dual Duct Variable Air Volume | G43: Single Duct Constant Air Volume | H43: Single Duct Variable Air Volume
A44: Floorspace-Based | B44: Office, Large | D44: 0.03 | E44: 0.15 | G44: 0.43 | H44: 0.21
A45: Sites-Based | B45: Office, Large | C45: 0.13 | D45: 0.02 | E45: 0.07 | G45: 0.66 | H45: 0.12
A48: Chiller System
A49: Calculation method | B49: Building Type | C49: Boiler/ Hydronic | D49: Package System / Heat Pump | E49: Split-System / Heat Pump | G49: Ductless Mini-Split Heat Pump | H49: Room Heating
...

Sheet Thermostat
A1: ="Thermostat Setpoints - "&Prototype!A2 -> Thermostat Setpoints - OfficeLarge
A2: Spaces/Zones | B2: Setpoint | C2: CZ1 | D2: CZ2 | E2: CZ3 | F2: CZ4 | G2: CZ5 | H2: CZ6 | I2: CZ7 | J2: CZ8 | K2: CZ9 | L2: CZ10 | M2: CZ11 | N2: CZ12 | O2: CZ13 | P2: CZ14 | Q2: CZ15 | R2: CZ16 | S2: Source
A3: All conditioned zones except server rooms , Stairway, and Mechanical | B3: Heating Setpoint (F) | C3: 70 | D3: 70 | E3: 70 | F3: 70 | G3: 70 | H3: 70 | I3: 70 | J3: 70 | K3: 70 | L3: 70 | M3: 70 | N3: 70 | O3: 70 | P3: 70 | Q3: 70 | R3: 70 | S3: T24 2022 - Appendix 5.4B
B4: Heating Setback (F) | C4: 60 | D4: 60 | E4: 60 | F4: 60 | G4: 60 | H4: 60 | I4: 60 | J4: 60 | K4: 60 | L4: 60 | M4: 60 | N4: 60 | O4: 60 | P4: 60 | Q4: 60 | R4: 60
B5: Cooling Setpoint (F) | C5: 75 | D5: 75 | E5: 75 | F5: 75 | G5: 75 | H5: 75 | I5: 75 | J5: 75 | K5: 75 | L5: 75 | M5: 75 | N5: 75 | O5: 75 | P5: 75 | Q5: 75 | R5: 75
B6: Cooling Setback (F) * | C6: 85 | D6: 85 | E6: 85 | F6: 85 | G6: 85 | H6: 85 | I6: 85 | J6: 85 | K6: 85 | L6: 85 | M6: 85 | N6: 85 | O6: 85 | P6: 85 | Q6: 85 | R6: 85
A7: Server rooms | B7: Cooling Setpoint (F) | C7: 80 | D7: 80 | E7: 80 | F7: 80 | G7: 80 | H7: 80 | I7: 80 | J7: 80 | K7: 80 | L7: 80 | M7: 80 | N7: 80 | O7: 80 | P7: 80 | Q7: 80 | R7: 80 | S7: Title 24, Part 6, 2025, section 140.9 (a) and PNNL ASHRAE 90.1 2022 Large Office prototype
B8: Heating Setpoint (F) | C8: The Server room with 20 W/ft2 load would likely don't require heating system as the equipment constantly generate enough heat. **
A9: Stairway, and Mechanical_Electrical | B9: Heating Setpoint (F) | C9: 60 | D9: 60 | E9: 60 | F9: 60 | G9: 60 | H9: 60 | I9: 60 | J9: 60 | K9: 60 | L9: 60 | M9: 60 | N9: 60 | O9: 60 | P9: 60 | Q9: 60 | R9: 60 | S9: Engineering Judgment (Semi‑conditioned space)
B10: Heating Setback (F) | C10: 60 | D10: 60 | E10: 60 | F10: 60 | G10: 60 | H10: 60 | I10: 60 | J10: 60 | K10: 60 | L10: 60 | M10: 60 | N10: 60 | O10: 60 | P10: 60 | Q10: 60 | R10: 60
B11: Cooling Setpoint (F) | C11: 85 | D11: 85 | E11: 85 | F11: 85 | G11: 85 | H11: 85 | I11: 85 | J11: 85 | K11: 85 | L11: 85 | M11: 85 | N11: 85 | O11: 85 | P11: 85 | Q11: 85 | R11: 85
B12: Cooling Setback (F) | C12: 85 | D12: 85 | E12: 85 | F12: 85 | G12: 85 | H12: 85 | I12: 85 | J12: 85 | K12: 85 | L12: 85 | M12: 85 | N12: 85 | O12: 85 | P12: 85 | Q12: 85 | R12: 85
B14: *PNNL has considered 80 F for cooling setback of Large Office prototype (same as Medium Office). However cooling setback is 85 F in Small Office prototype !
B15: **PNNL has set the heating system temperature to 65°F for all of their data center zones.
A22: Background Data [To be deleted prior to publication]
A42: Heating/ CoolingSetpointsSchedules (existing prototypes extracted from the idf files (presented below)
B63: Heating | K63: Cooling
B64: CEC-2022 | F64: PNNL-2022 | K64: CEC-2022 | O64: PNNL-2022
B65: CEC-Weekday | C65: CEC-Saturday | D65: CEC-Sunday | F65: PNNL-Weekday | G65: PNNL-Saturday | H65: PNNL-Sunday | K65: CEC-Weekday | L65: CEC-Saturday | M65: CEC-Sunday | O65: PNNL-Weekday | P65: PNNL-Saturday | Q65: PNNL-Sunday
A66: 1 | B66: 60 | C66: 60 | D66: 60 | F66: 60.08 | G66: 60.08 | H66: 60.08 | K66: 85 | L66: 85 | M66: 85 | O66: 80.06 | P66: 80.06 | Q66: 80.06
A67: 2 | B67: 60 | C67: 60 | D67: 60 | F67: 60.08 | G67: 60.08 | H67: 60.08 | K67: 85 | L67: 85 | M67: 85 | O67: 80.06 | P67: 80.06 | Q67: 80.06
A68: 3 | B68: 60 | C68: 60 | D68: 60 | F68: 60.08 | G68: 60.08 | H68: 60.08 | K68: 85 | L68: 85 | M68: 85 | O68: 80.06 | P68: 80.06 | Q68: 80.06
A69: 4 | B69: 60 | C69: 60 | D69: 60 | F69: 60.08 | G69: 60.08 | H69: 60.08 | K69: 85 | L69: 85 | M69: 85 | O69: 80.06 | P69: 80.06 | Q69: 80.06
A70: 5 | B70: 60 | C70: 60 | D70: 60 | F70: 60.08 | G70: 60.08 | H70: 60.08 | K70: 85 | L70: 85 | M70: 85 | O70: 80.06 | P70: 80.06 | Q70: 80.06
A71: 6 | B71: 70 | C71: 70 | D71: 60 | F71: 64.04 | G71: 64.04 | H71: 60.08 | K71: 75 | L71: 75 | M71: 85 | O71: 78.08 | P71: 78.26 | Q71: 80.06
A72: 7 | B72: 70 | C72: 70 | D72: 60 | F72: 68 | G72: 68 | H72: 60.08 | K72: 75 | L72: 75 | M72: 85 | O72: 77 | P72: 77 | Q72: 80.06
A73: 8 | B73: 70 | C73: 70 | D73: 60 | F73: 69.8 | G73: 69.8 | H73: 60.08 | K73: 75 | L73: 75 | M73: 85 | O73: 75.2 | P73: 75.2 | Q73: 80.06
A74: 9 | B74: 70 | C74: 70 | D74: 60 | F74: 69.8 | G74: 69.8 | H74: 60.08 | K74: 75 | L74: 75 | M74: 85 | O74: 75.2 | P74: 75.2 | Q74: 80.06
A75: 10 | B75: 70 | C75: 70 | D75: 60 | F75: 69.8 | G75: 69.8 | H75: 60.08 | K75: 75 | L75: 75 | M75: 85 | O75: 75.2 | P75: 75.2 | Q75: 80.06
A76: 11 | B76: 70 | C76: 70 | D76: 60 | F76: 69.8 | G76: 69.8 | H76: 60.08 | K76: 75 | L76: 75 | M76: 85 | O76: 75.2 | P76: 75.2 | Q76: 80.06
A77: 12 | B77: 70 | C77: 70 | D77: 60 | F77: 69.8 | G77: 69.8 | H77: 60.08 | K77: 75 | L77: 75 | M77: 85 | O77: 75.2 | P77: 75.2 | Q77: 80.06
... A89: 24 | B89: 70 | C89: 60 | D89: 60 | F89: 60.08 | G89: 60.08 | H89: 60.08 | K89: 75 | L89: 85 | M89: 85 | O89: 80.06 | P89: 80.06 | Q89: 80.06

Sheet Ventilation
A1: ="Outdoor Airflow Rate - "&Prototype!A2 -> Outdoor Airflow Rate - OfficeLarge
A2: Space Name | B2: Number of People | C2: Floor Area (ft²) | D2: cfm/person (T24, 2025, Equation 120.1-F and Table 120.1-A) | E2: cfm/ft² (T24, 2025, Equation 120.1-F and Table 120.1-A) | F2: Required Exhaust Rate (T24, 2025, Table 120.1-B – Minimum Exhaust Rates) | G2: Total cfm Driven by People | H2: Total cfm Driven by Area | I2: Total cfm Driven by Exhaust | J2: Total cfm | K2: Note
A3: =Zones!B3 -> Perimeter_Open_Office_N_Basement | B3: =Zones!L3 -> 42.0843 | C3: =Zones!I3 -> 8416.86 | D3: 15 | E3: 0.15 | G3: =B3*D3 -> 631.2645 | H3: =C3*E3 -> 1262.529 | J3: =MAX(G3:I3) -> 1262.529 | K3: Office space/Occupancy Category - Office Buildings
A4: =Zones!B4 -> Perimeter_Open_Office_S_Basement | B4: =Zones!L4 -> 18.3109 | C4: =Zones!I4 -> 3662.18 | D4: 15 | E4: 0.15 | G4: =B4*D4 -> 274.6635 | H4: =C4*E4 -> 549.327 | J4: =MAX(G4:I4) -> 549.327 | K4: Office space/Occupancy Category - Office Buildings
A5: =Zones!B5 -> Core_Enclosed_Office_Basement | B5: =Zones!L5 -> 18.5184 | C5: =Zones!I5 -> 3703.68 | D5: 15 | E5: 0.15 | G5: =B5*D5 -> 277.776 | H5: =C5*E5 -> 555.552 | J5: =MAX(G5:I5) -> 555.552 | K5: Office space/Occupancy Category - Office Buildings
A6: =Zones!B6 -> Server_Room_Basement | B6: =Zones!L6 -> 12.342 | C6: =Zones!I6 -> 8228 | D6: 15 | E6: 0.15 | G6: =B6*D6 -> 185.13 | H6: =C6*E6 -> 1234.2 | J6: =MAX(G6:I6) -> 1234.2 | K6: Telephone/data entry/Occupancy Category - Office Buildings
A7: =Zones!B7 -> Mech/Elec_Basement | B7: =Zones!L7 -> 0 | C7: =Zones!I7 -> 7958 | D7: 15 | E7: 0.15 | G7: =B7*D7 -> 0 | H7: =C7*E7 -> 1193.7 | J7: =MAX(G7:I7) -> 1193.7 | K7: All Other
A8: =Zones!B8 -> Conference_Basement | B8: =Zones!L8 -> 19.1301 | C8: =Zones!I8 -> 579.7 | D8: 15 | E8: 0.15 | G8: =B8*D8 -> 286.9515 | H8: =C8*E8 -> 86.955 | J8: =MAX(G8:I8) -> 286.9515 | K8: Conference/meeting/Occupancy Category - General
A9: =Zones!B9 -> BreakRoom/FoodPrep_Basement | B9: =Zones!L9 -> 32.109 | C9: =Zones!I9 -> 973 | D9: 15 | E9: 0.15 | G9: =B9*D9 -> 481.635 | H9: =C9*E9 -> 145.95 | J9: =MAX(G9:I9) -> 481.635 | K9: Breakrooms/Occupancy Category - Office Buildings
A10: =Zones!B10 -> Storage_Basement | B10: =Zones!L10 -> 0 | C10: =Zones!I10 -> 1231 | D10: 15 | E10: 0.15 | G10: =B10*D10 -> 0 | H10: =C10*E10 -> 184.65 | J10: =MAX(G10:I10) -> 184.65 | K10: Occupiable storage rooms for dry materials/Occupancy Category - Office Buildings
A11: =Zones!B11 -> Restroom_Basement | B11: =Zones!L11 -> 0 | C11: =Zones!I11 -> 986 | D11: 15 | E11: 0.15 | F11: 5* 50/70 (cfm/unit) | G11: =B11*D11 -> 0 | H11: =C11*E11 -> 147.9 | I11: =5*50 -> 250 | J11: =MAX(G11:I11) -> 250 | K11: Almost 1 unit per 30 occupant for exhaust fan
A12: =Zones!B12 -> Lobby/Lounge_Basement | B12: =Zones!L12 -> 10.605 | C12: =Zones!I12 -> 707 | D12: 15 | E12: 0.15 | G12: =B12*D12 -> 159.075 | H12: =C12*E12 -> 106.05 | J12: =MAX(G12:I12) -> 159.075 | K12: Breakrooms/Occupancy Category - Office Buildings
A13: =Zones!B13 -> Stair/Elevator_Basement | B13: =Zones!L13 -> 0 | C13: =Zones!I13 -> 941 | D13: 15 | E13: 0.15 | G13: =B13*D13 -> 0 | H13: =C13*E13 -> 141.15 | J13: =MAX(G13:I13) -> 141.15 | K13: All Other
A14: =Zones!B14 -> Corridor_W_Basement | B14: =Zones!L14 -> 3.515 | C14: =Zones!I14 -> 703 | D14: 15 | E14: 0.15 | G14: =B14*D14 -> 52.725 | H14: =C14*E14 -> 105.45 | J14: =MAX(G14:I14) -> 105.45 | K14: Corridors /Occupancy Category - General
A15: =Zones!B15 -> Corridor_E_Basement | B15: =Zones!L15 -> 1.3145 | C15: =Zones!I15 -> 262.9 | D15: 15 | E15: 0.15 | G15: =B15*D15 -> 19.7175 | H15: =C15*E15 -> 39.435 | J15: =MAX(G15:I15) -> 39.435 | K15: Corridors /Occupancy Category - General
A16: =Zones!B16 -> Perimeter_Open_Office_N_FloorG | B16: =Zones!L16 -> 35.65645 | C16: =Zones!I16 -> 7131.29 | D16: 15 | E16: 0.15 | G16: =B16*D16 -> 534.84675 | H16: =C16*E16 -> 1069.6935 | J16: =MAX(G16:I16) -> 1069.6935 | K16: Office space/Occupancy Category - Office Buildings
A17: =Zones!B17 -> Perimeter_Open_Office_W_FloorG | B17: =Zones!L17 -> 28.97885 | C17: =Zones!I17 -> 5795.77 | D17: 15 | E17: 0.15 | G17: =B17*D17 -> 434.68275 | H17: =C17*E17 -> 869.3655 | J17: =MAX(G17:I17) -> 869.3655 | K17: Office space/Occupancy Category - Office Buildings
A18: =Zones!B18 -> Perimeter_Open_Office_E_FloorG | B18: =Zones!L18 -> 29.37745 | C18: =Zones!I18 -> 5875.49 | D18: 15 | E18: 0.15 | G18: =B18*D18 -> 440.66175 | H18: =C18*E18 -> 881.3235 | J18: =MAX(G18:I18) -> 881.3235 | K18: Office space/Occupancy Category - Office Buildings
A19: =Zones!B19 -> Perimeter_Enclosed_Office_NE_FloorG | B19: =Zones!L19 -> 4.5869 | C19: =Zones!I19 -> 917.38 | D19: 15 | E19: 0.15 | G19: =B19*D19 -> 68.8035 | H19: =C19*E19 -> 137.607 | J19: =MAX(G19:I19) -> 137.607 | K19: Office space/Occupancy Category - Office Buildings
A20: =Zones!B20 -> Perimeter_Enclosed_Office_NW_FloorG | B20: =Zones!L20 -> 5.65605 | C20: =Zones!I20 -> 1131.21 | D20: 15 | E20: 0.15 | G20: =B20*D20 -> 84.84075 | H20: =C20*E20 -> 169.6815 | J20: =MAX(G20:I20) -> 169.6815 | K20: Office space/Occupancy Category - Office Buildings
A21: =Zones!B21 -> Core_Enclosed_Office_FloorG | B21: =Zones!L21 -> 16.5614 | C21: =Zones!I21 -> 3312.28 | D21: 15 | E21: 0.15 | G21: =B21*D21 -> 248.421 | H21: =C21*E21 -> 496.842 | J21: =MAX(G21:I21) -> 496.842 | K21: Office space/Occupancy Category - Office Buildings
A22: =Zones!B22 -> Server_Room_FloorG | B22: =Zones!L22 -> 0.625635 | C22: =Zones!I22 -> 417.09 | D22: 15 | E22: 0.15 | G22: =B22*D22 -> 9.384525 | H22: =C22*E22 -> 62.5635 | J22: =MAX(G22:I22) -> 62.5635 | K22: Telephone/data entry/Occupancy Category - Office Buildings
A23: =Zones!B23 -> Mech/Elec_FloorG | B23: =Zones!L23 -> 0 | C23: =Zones!I23 -> 848.96 | D23: 15 | E23: 0.15 | G23: =B23*D23 -> 0 | H23: =C23*E23 -> 127.344 | J23: =MAX(G23:I23) -> 127.344 | K23: All Other
... A27: =Zones!B27 -> Storage_FloorG | B27: =Zones!L27 -> 0 | C27: =Zones!I27 -> 959.03 | D27: 15 | E27: 0.15 | G27: =B27*D27 -> 0 | H27: =C27*E27 -> 143.8545 | J27: =MAX(G27:I27) -> 143.8545 | K27: Occupiable storage rooms for dry materials/Occupancy Category - Office Buildings
A28: =Zones!B28 -> Locker_FloorG | B28: =Zones!L28 -> 17.6523 | C28: =Zones!I28 -> 1765.23 | D28: 15 | E28: 0.15 | F28: 0.25 (cfm/sf) | G28: =B28*D28 -> 264.7845 | H28: =C28*E28 -> 264.7845 | I28: =0.25*C28 -> 441.3075 | J28: =MAX(G28:I28) -> 441.3075 | K28: All Other
A29: =Zones!B29 -> Lobby_S_FloorG | B29: =Zones!L29 -> 33.6063 | C29: =Zones!I29 -> 3360.63 | D29: 15 | E29: 0.15 | G29: =B29*D29 -> 504.0945 | H29: =C29*E29 -> 504.0945 | J29: =MAX(G29:I29) -> 504.0945 | K29: Main entry lobbies/Occupancy Category - Office Buildings
A30: =Zones!B30 -> Lobby/Lounge_FloorG | B30: =Zones!L30 -> 10.2585 | C30: =Zones!I30 -> 683.9 | D30: 15 | E30: 0.15 | G30: =B30*D30 -> 153.8775 | H30: =C30*E30 -> 102.585 | J30: =MAX(G30:I30) -> 153.8775 | K30: Main entry lobbies/Occupancy Category - Office Buildings
A31: =Zones!B31 -> Restroom_FloorG | B31: =Zones!L31 -> 0 | C31: =Zones!I31 -> 1156.09 | D31: 15 | E31: 0.15 | F31: 8* 50/70 (cfm/unit) | G31: =B31*D31 -> 0 | H31: =C31*E31 -> 173.4135 | I31: =8*50 -> 400 | J31: =MAX(G31:I31) -> 400 | K31: All Other
A32: =Zones!B32 -> Stair/Elevator_FloorG | B32: =Zones!L32 -> 0 | C32: =Zones!I32 -> 848.01 | D32: 15 | E32: 0.15 | G32: =B32*D32 -> 0 | H32: =C32*E32 -> 127.2015 | J32: =MAX(G32:I32) -> 127.2015 | K32: All Other
A33: =Zones!B33 -> Corridor_W_FloorG | B33: =Zones!L33 -> 5.02935 | C33: =Zones!I33 -> 1005.87 | D33: 15 | E33: 0.15 | G33: =B33*D33 -> 75.44025 | H33: =C33*E33 -> 150.8805 | J33: =MAX(G33:I33) -> 150.8805 | K33: Corridors /Occupancy Category - General
A34: =Zones!B34 -> Corridor_E_FloorG | B34: =Zones!L34 -> 3.9938 | C34: =Zones!I34 -> 798.76 | D34: 15 | E34: 0.15 | G34: =B34*D34 -> 59.907 | H34: =C34*E34 -> 119.814 | J34: =MAX(G34:I34) -> 119.814 | K34: Corridors /Occupancy Category - General
A35: =Zones!B35 -> Plenum_FloorG | B35: =Zones!L35 -> 0 | C35: =Zones!I35 -> 38352.97 | G35: =B35*D35 -> 0 | H35: =C35*E35 -> 0 | J35: =MAX(G35:I35) -> 0 | K35: -
A36: =Zones!B36 -> Perimeter_Open_Office_N_FloorM | B36: =Zones!L36 -> 35.65645 | C36: =Zones!I36 -> 7131.29 | D36: 15 | E36: 0.15 | G36: =B36*D36 -> 534.84675 | H36: =C36*E36 -> 1069.6935 | J36: =MAX(G36:I36) -> 1069.6935 | K36: Office space/Occupancy Category - Office Buildings
A37: =Zones!B37 -> Perimeter_Open_Office_S_FloorM | B37: =Zones!L37 -> 26.18685 | C37: =Zones!I37 -> 5237.37 | D37: 15 | E37: 0.15 | G37: =B37*D37 -> 392.80275 | H37: =C37*E37 -> 785.6055 | J37: =MAX(G37:I37) -> 785.6055 | K37: Office space/Occupancy Category - Office Buildings
A38: =Zones!B38 -> Perimeter_Open_Office_E_FloorM | B38: =Zones!L38 -> 22.3522 | C38: =Zones!I38 -> 4470.44 | D38: 15 | E38: 0.15 | G38: =B38*D38 -> 335.283 | H38: =C38*E38 -> 670.566 | J38: =MAX(G38:I38) -> 670.566 | K38: Office space/Occupancy Category - Office Buildings
A39: =Zones!B39 -> Perimeter_Open_Office_W_FloorM | B39: =Zones!L39 -> 22.2438 | C39: =Zones!I39 -> 4448.76 | D39: 15 | E39: 0.15 | G39: =B39*D39 -> 333.657 | H39: =C39*E39 -> 667.314 | J39: =MAX(G39:I39) -> 667.314 | K39: Office space/Occupancy Category - Office Buildings
A40: =Zones!B40 -> Perimeter_Enclosed_Office_NE_FloorM | B40: =Zones!L40 -> 4.5869 | C40: =Zones!I40 -> 917.38 | D40: 15 | E40: 0.15 | G40: =B40*D40 -> 68.8035 | H40: =C40*E40 -> 137.607 | J40: =MAX(G40:I40) -> 137.607 | K40: Office space/Occupancy Category - Office Buildings
A41: =Zones!B41 -> Perimeter_Enclosed_Office_NW_FloorM | B41: =Zones!L41 -> 5.65605 | C41: =Zones!I41 -> 1131.21 | D41: 15 | E41: 0.15 | G41: =B41*D41 -> 84.84075 | H41: =C41*E41 -> 169.6815 | J41: =MAX(G41:I41) -> 169.6815 | K41: Office space/Occupancy Category - Office Buildings
A42: =Zones!B42 -> Perimeter_Enclosed_Office_SW_FloorM | B42: =Zones!L42 -> 5.05245 | C42: =Zones!I42 -> 1010.49 | D42: 15 | E42: 0.15 | G42: =B42*D42 -> 75.78675 | H42: =C42*E42 -> 151.5735 | J42: =MAX(G42:I42) -> 151.5735 | K42: Office space/Occupancy Category - Office Buildings
A43: =Zones!B43 -> Perimeter_Enclosed_Office_SE_FloorM | B43: =Zones!L43 -> 5.1674 | C43: =Zones!I43 -> 1033.48 | D43: 15 | E43: 0.15 | G43: =B43*D43 -> 77.511 | H43: =C43*E43 -> 155.022 | J43: =MAX(G43:I43) -> 155.022 | K43: Office space/Occupancy Category - Office Buildings
...

Sheet Water Heater
A1: Water Heater - OfficeLarge
A2: Vintage | B2: WH Type | C2: Efficiency | D2: Number of WH | E2: Tank Volume (gal) | F2: Tank Loss | G2: Source
A3: Existing | B3: Gas | C3: 0.8 | D3: =B92 -> 2 | E3: See table below for each WH: col F is storage volume EACH of N identical heaters (N in B91). Plant total volume = col L. | F3: See table below for each WH: col G is standby EACH of N identical heaters. Plant total UA = col N. | G3: See table below for sources: Climate Zone Water Heater Sizing and Loss Coefficients
