Workbook
Name nonparticipating_forecastzone_scale_factor: #REF!
Name nonparticipating_forecastzone_scale_factor: 'Energy Usage'!#REF!
Name Space_Function: Data!$A$2:$A$76

Sheet Notes
A1: Data Sources
A2: Dataset | B2: Dodge 2023
B3: Commercial End-Use Survey (CEUS) 2022 | C3: https://www.energy.ca.gov/publications/2023/2022-california-commercial-end-use-survey-ceus-final-report
B4: Commercial Buildings Energy Consumption Survey (CBECS) 2018 | C4: https://www.eia.gov/consumption/commercial/data/2018/index.php
B5: ComStock 2023 | C5: https://www.nrel.gov/buildings/comstock
A7: Prototype | B7: Pacific Northwest National Laboratory (PNNL) Outpatient prototype (90.1-2022) | C7: https://www.energycodes.gov/prototype-building-models#Commercial
A9: Codes | B9: Title 24, part 6, referred to as T24 (1984, 1992,1998, 2001, 2005, 2008, 2013, 2016,2019, 2022, 2025) | C9: https://www.energy.ca.gov/publications/2025/2025-building-energy-efficiency-standards-residential-and-nonresidential | D9: 2025
C10: https://codes.iccsafe.org/codes/united-states/california | D10: 2010+
B11: American Society of Heating, Refrigerating and Air-Conditioning Engineers (ASHRAE) 90.1 (2022) | C11: https://www.ashrae.org/technical-resources/standards-and-guidelines/read-only-versions-of-ashrae-standards
B12: Code of Federal Regulations (CFR) Title 10 (2008, 2010) | C12: https://www.govinfo.gov/content/pkg/FR-2009-03-23/pdf/FR-2009-03-23.pdf
B13: ASHRAE 170/OSHPD | C13: https://www.ashrae.org/technical-resources/bookstore/health-care-facilities-resources
B14: 2022 California Mechanical Code (Title 24, Part 4) | C14: https://up.codes/viewer/california/ca-mechanical-code-2022
B15: Facility Guidelines Institute Codes (FGI) 2022 Guidelines for Design and Construction of Outpatient Facilities | C15: https://onesource.fgicodes.org/products/2022-guidelines-for-design-and-construction-of-outpatient-facilities
A16: Other | B16: Alternative Calculation Method (ACM) (2022) | C16: https://www.energy.ca.gov/publications/2022/2022-nonresidential-and-multifamily-alternative-calculation-method-reference
B17: Nonres ACM 2022, Appendix 5.4A and Appendix 5.4B | C17: https://www.energy.ca.gov/publications/2022/2022-nonresidential-and-multifamily-alternative-calculation-method-reference
B18: 2022 Reduced infiltration CASE report | C18: https://title24stakeholders.com/wp-content/uploads/2020/10/2022-T24-Final-CASE-Report_Reduce-Infiltration.pdf
B19: 2019 Outdoor Lighting CASE Report | C19: https://title24stakeholders.com/wp-content/uploads/2016/10/T24-2019-CASE-Study-Results-Report-Outdoor-Sources_Final_with-Attachments.pdf
B20: PNNL 20405, 2011 | C20: https://www.pnnl.gov/main/publications/external/technical_reports/PNNL-20405.pdf
B21: PNNL-26949 | C21: https://www.pnnl.gov/main/publications/external/technical_reports/PNNL-26949.pdf
B22: Air leakage Memo, NORESCO, 2025 | C22: https://2050partners.sharepoint.com/:w:/r/sites/CalBEMCollaborativeEfforts/_layouts/15/Doc.aspx?sourcedoc=%7B3BEF8F74-7FAC-44F2-A70C-D76617660066%7D&file=Infiltration_rate_report_14May2025-Short-Version.docx&wdLOR=c494C5A60-5F8A-438B-874B-578DCB850072&action=default&mobileredirect=true
B23: 2019 High Efficiency Fume Hoods in Laboratory Spaces CASE Report | C23: https://title24stakeholders.com/wp-content/uploads/2017/09/2019-T24-CASE-Report_Fume-Hoods_Final_September-2017.pdf?
B24: Targeting 100! Envisioning the High Performance Hospital: Implications for a New, Low Energy, High Performance Prototype | C24: https://idl.be.uw.edu/wp-content/uploads/sites/32/2017/08/Targeting100_FullReport_063010.pdf
B25: ASHRAE's Advanced Energy Design Guide for Large Hospitals-50% (AEDG) | C25: https://www.ashrae.org/technical-resources/aedgs/50-percent-aedg-free-download
B26: American Hospital Association (AHA) Statistics data for Hospital | C26: https://www.ahadata.com/aha-hospital-statistics
B27: AEDG TSD: Bonnema, E., Doebber, I., Pless, S., Torcellini, P. (2010). NREL/TP-550-46314. | C27: https://docs.nlr.gov/docs/fy10osti/46314.pdf
B28: Yousefi, F., Athalye, R., (2025), "Determining Vintage Bins for Prototype Development: An Analysis of California Commercial Buildings," ASHRAE Annual Conference | C28: https://www.thefreelibrary.com/Determining+Vintage+Bins+for+Prototype+Development%3a+An+Analysis+of...-a0879271125
... B31: Grainger electric tank water heaters | C31: https://www.grainger.com/category/plumbing/water-heaters/electric-tank-water-heaters
A36: Construction Rate
A47: * the general healthcare trends which apply to the broader Healthcare category, not outpatient.
A49: Notes
A50: Outpatient | B50: An outpatient healthcare facility (also called an ambulatory care facility, outpatient clinic, or clinic) provides diagnostic, treatment, or surgical services to patients who go home the same day. There is no overnight inpatient stay. The building may be freestanding or attached to a hospital. It typically operates about 8–10 hours per day, not 24/7. FGI Guidelines for Design and Construction of Outpatient Facilities (2022), Part 2, splits this building family by program (surgery, imaging, urgent care, primary care, and others). Those programs do not share the same layout or HVAC, so they are not all represented by one energy model. This CalBEM prototype is a ~41,000 ft², three-story outpatient surgical/diagnostic building (PNNL/NREL geometry). Floor 1 is surgery and recovery; floors 2–3 are exam, office, and physical therapy. It represents FGI 2.7 Outpatient Surgery, with 2.3 Imaging, 2.2 General and Specialty Medical Services, and 2.12 Rehabilitation Therapy as they appear on that floor plan. HVAC follows healthcare ventilation (ASHRAE 170 / FGI / CMC Table 4-A) for procedure, imaging, and operating rooms. This prototype is not: a hospital (overnight / 24-hour inpatient care; CBECS inpatient mean 264,800 ft²); a medical office without diagnostic equipment (Office prototype); a typical small diagnostic medical office (CBECS mean 9,900 ft²); an urgent care, only, birth center, infusion, freestanding ED, endoscopy-only, dialysis, behavioral health, mobile unit, or dental facility (FGI 2.4–2.6, 2.8–2.11, 2.13–2.14). Those types would need a different layout and model.
A51: EIA, 2018 CBECS | B51: On average, hospitals were 264,800 square feet per building, but outpatient health care buildings averaged 13,700 square feet.
A52: Source | B52: https://www.eia.gov/consumption/commercial/

Sheet Prototype
A1: NORESCO, Updated September 2026
A2: Outpatient
A3: Characteristic | B3: Value | C3: Data Sources
A4: Building Type | B4: Outpatient
A5: Building Category | B5: Nonresidential
A6: Version | B6: v2-0
A7: Vintages | B7: 4 Vintages: Pre-1978 , 1978-1997 ,1998-2007 , 2008-2018 New Construction (2019+) | C7: Based on the vintage bin analysis. A summary of the findings is presented in the following paper, with a link provided in the Notes tab: Yousefi, F., Athalye, R. (2025). “Determining Vintage Bins for Prototype Development: An Analysis of California Commercial Buildings.” ASHRAE Annual Conference.
A8: Shape | C8: The analysis uses prototype geometry originally developed by PNNL.
A9: Total Floor Area (ft²) | B9: 40950 | C9: Assumption; based on AEDG TSD (Table ES-1 / Table 4-2 (41,000 ft²); Appendix D (40,946 ft²). Rounded.)
A10: Aspect Ratio | B10: n/a | C10: Assumption; based on AEDG TSD §4.2, Figures 4-5–4-7 (non-rectangular plates)
A11: Number of Floors | B11: 3 | C11: Assumption; based on AEDG TSD (Table ES-1 / Table 4-2
A12: Roof type | B12: Flat roof | C12: Assumption; based on AEDG TSD (Table ES-1 / Table 4-2 (insulation entirely above deck); §5.3
A13: WWR | B13: North: 20.5%, East:19.1%, South: 24.1%, West: 12.9% Average Total: 20% | C13: Assumption; based on AEDG TSD (Average: Table 4-2 / Table 5-1. By façade: Appendix D)
A14: Shading Geometry | B14: Fixed entrance canopy (12 ft) | C14: Assumption; based on review feedback
A15: Floor to floor height (feet) | B15: 10 ft | C15: Assumption; based on AEDG Table TSD (5-1 ceiling 10 ft; no plenums, §5.2.1)
A16: Floor to ceiling height (feet) | B16: 10 ft | C16: Assumption; based on AEDG Table TSD (5-1 ceiling 10 ft; no plenums, §5.2.1)
A17: Glazing sill height (feet) | B17: 3 ft (4 ft high windows) | C17: Typical window sill height-PNNL
A21: Above grade wall area (ft²) | B21: 16716.353
A22: Gross wall area (ft²) | B22: 16716.353
A23: Roof area (ft²) | B23: 14778.849
A24: Underground Gross Wall Area (ft²) | B24: 0

Sheet Zones
A1: ="Proposed Layout - "&Prototype!A2 -> Proposed Layout - Outpatient
A2: Building | B2: Space/ Thermal Zone | C2: Space Type Primarily from [T24, 2022 Appendix 5.4A] - See Notes column | D2: HVAC System Name | E2: Schedule Category | F2: Conditioned (Y/N) | G2: Area Fraction | H2: Area (ft²) | I2: Volume (ft³) | J2: Multipliers | K2: Number of People | L2: People (Persons/1,000 ft²) [T24, 2025,Table 120.1-A and NACM Appendix 5.4A] | M2: Notes
A3: Outpatient | B3: Floor 1 Anesthesia | C3: Healthcare Facility and Hospitals (Exam/Treatment Room) | D3: AHU-4 | E3: Health | F3: Yes | G3: =H3/$H$121 -> 0.0026376203 | H3: 108 | I3: 1080 | J3: 1 | K3: =ROUND(L3*H3/1000,0) -> 1 | L3: 5
A4: Outpatient | B4: Floor 1 Bio Haz | C4: Healthcare Facility and Hospitals (Medical Supply Room) | D4: AHU-1 | E4: Health | F4: Yes | G4: =H4/$H$121 -> 0.001367655 | H4: 56 | I4: 560 | J4: 1 | K4: =ROUND(L4*H4/1000,0) -> 0 | L4: 5
A5: Outpatient | B5: Floor 1 Café | C5: Dining Area (Cafeteria/Fast Food) | D5: AHU-1 | E5: Health | F5: Yes | G5: =H5/$H$121 -> 0.010257412 | H5: 420 | I5: 4200 | J5: 1 | K5: =ROUND(L5*H5/1000,0) -> 14 | L5: 33
A6: Outpatient | B6: Floor 1 Clean | C6: Healthcare Facility and Hospitals (Medical Supply Room) | D6: AHU-4 | E6: Health | F6: Yes | G6: =H6/$H$121 -> 0.0030772237 | H6: 126 | I6: 1260 | J6: 1 | K6: =ROUND(L6*H6/1000,0) -> 1 | L6: 5
A7: Outpatient | B7: Floor 1 Clean Work | C7: Healthcare Facility and Hospitals (Medical Supply Room) | D7: AHU-4 | E7: Health | F7: Yes | G7: =H7/$H$121 -> 0.0040296977 | H7: 165 | I7: 1650 | J7: 1 | K7: =ROUND(L7*H7/1000,0) -> 1 | L7: 5
A8: Outpatient | B8: Floor 1 Dictation | C8: Office Area (<250 square feet) | D8: AHU-1 | E8: Office | F8: Yes | G8: =H8/$H$121 -> 0.0030772237 | H8: 126 | I8: 1260 | J8: 1 | K8: =L8*H8/1000 -> 0.63 | L8: 5
A9: Outpatient | B9: Floor 1 Dressing Room | C9: Office Area (<250 square feet) | D9: AHU-1 | E9: Office | F9: Yes | G9: =H9/$H$121 -> 0.0010990085 | H9: 45 | I9: 450 | J9: 1 | K9: =L9*H9/1000 -> 0.225 | L9: 5
A10: Outpatient | B10: Floor 1 Electrical Room | C10: Electrical, Mechanical, Telephone Rooms | D10: AHU-1 | E10: Ancillary | F10: Yes | G10: =H10/$H$121 -> 0.0023933962 | H10: 98 | I10: 980 | J10: 1 | K10: =ROUND(L10*H10/1000,0) -> 0 | L10: 1.5
A11: Outpatient | B11: Floor 1 Elevator Pump Room | C11: Electrical, Mechanical, Telephone Rooms | D11: AHU-1 | E11: Ancillary | F11: Yes | G11: =H11/$H$121 -> 0.0022224393 | H11: 91 | I11: 910 | J11: 1 | K11: =ROUND(L11*H11/1000,0) -> 0 | L11: 1.5
A12: Outpatient | B12: Floor 1 Humid | C12: Office Area (<250 square feet) | D12: AHU-1 | E12: Office | F12: Yes | G12: =H12/$H$121 -> 0.0013188101 | H12: 54 | I12: 540 | J12: 1 | K12: =L12*H12/1000 -> 0.27 | L12: 5
A13: Outpatient | B13: Floor 1 IT Hall | C13: Corridor Area | D13: AHU-1 | E13: Health | F13: Yes | G13: =H13/$H$121 -> 0.0034191374 | H13: 140 | I13: 1400 | J13: 1 | K13: =ROUND(L13*H13/1000,0) -> 1 | L13: 5
A14: Outpatient | B14: Floor 1 IT Room | C14: Office Area (<250 square feet) | D14: AHU-1 | E14: Office | F14: Yes | G14: =H14/$H$121 -> 0.0027353099 | H14: 112 | I14: 1120 | J14: 1 | K14: =L14*H14/1000 -> 0.56 | L14: 5
A15: Outpatient | B15: Floor 1 Lobby | C15: Lobby, Main Entry | D15: AHU-1 | E15: Health | F15: Yes | G15: =H15/$H$121 -> 0.015190739 | H15: 622 | I15: 6220 | J15: 1 | K15: =ROUND(L15*H15/1000,0) -> 21 | L15: 33
A16: Outpatient | B16: Floor 1 Lobby Hall | C16: Corridor Area | D16: AHU-1 | E16: Health | F16: Yes | G16: =H16/$H$121 -> 0.0058613784 | H16: 240 | I16: 2400 | J16: 1 | K16: =ROUND(L16*H16/1000,0) -> 1 | L16: 5
A17: Outpatient | B17: Floor 1 Lobby Toilet | C17: Restrooms | E17: Health | F17: Yes | G17: =H17/$H$121 -> 0.0013188101 | H17: 54 | I17: 540 | J17: 1 | K17: =ROUND(L17*H17/1000,0) -> 0 | L17: 5 | M17: Indirectly conditioned
A18: Outpatient | B18: Floor 1 Locker Room | C18: Locker Room | D18: AHU-1 | E18: Health | F18: Yes | G18: =H18/$H$121 -> 0.016118791 | H18: 660 | I18: 6600 | J18: 1 | K18: =ROUND(L18*H18/1000,0) -> 7 | L18: 10
A19: Outpatient | B19: Floor 1 Locker Room Hall | C19: Corridor Area | D19: AHU-1 | E19: Health | F19: Yes | G19: =H19/$H$121 -> 0.012113515 | H19: 496 | I19: 4960 | J19: 1 | K19: =ROUND(L19*H19/1000,0) -> 2 | L19: 5
A20: Outpatient | B20: Floor 1 Lounge | C20: Lounge, Breakroom, or Waiting Area | D20: AHU-1 | E20: Health | F20: Yes | G20: =H20/$H$121 -> 0.0087920676 | H20: 360 | I20: 3600 | J20: 1 | K20: =ROUND(L20*H20/1000,0) -> 12 | L20: 33
A21: Outpatient | B21: Floor 1 Med Gas | C21: Healthcare Facility and Hospitals (Medical Supply Room) | D21: AHU-1 | E21: Health | F21: Yes | G21: =H21/$H$121 -> 0.001367655 | H21: 56 | I21: 560 | J21: 1 | K21: =ROUND(L21*H21/1000,0) -> 0 | L21: 5
A22: Outpatient | B22: Floor 1 MRI Control Room | C22: Healthcare Facility and Hospitals (Imaging Room) | D22: AHU-1 | E22: Health | F22: Yes | G22: =H22/$H$121 -> 0.0041029649 | H22: 168 | I22: 1680 | J22: 1 | K22: =ROUND(L22*H22/1000,0) -> 1 | L22: 5
A23: Outpatient | B23: Floor 1 MRI Hall | C23: Corridor Area | D23: AHU-1 | E23: Health | F23: Yes | G23: =H23/$H$121 -> 0.0035900943 | H23: 147 | I23: 1470 | J23: 1 | K23: =ROUND(L23*H23/1000,0) -> 1 | L23: 5
A24: Outpatient | B24: Floor 1 MRI Room | C24: Healthcare Facility and Hospitals (Imaging Room) | D24: AHU-1 | E24: Health | F24: Yes | G24: =H24/$H$121 -> 0.01074586 | H24: 440 | I24: 4400 | J24: 1 | K24: =ROUND(L24*H24/1000,0) -> 2 | L24: 5
A25: Outpatient | B25: Floor 1 MRI Toilet | C25: Restrooms | E25: Health | F25: Yes | G25: =H25/$H$121 -> 0.0013188101 | H25: 54 | I25: 540 | J25: 1 | K25: =ROUND(L25*H25/1000,0) -> 0 | L25: 5 | M25: Indirectly conditioned
A26: Outpatient | B26: Floor 1 Nourishment | C26: Kitchen/Food Preparation Area | D26: AHU-1 | E26: Health | F26: Yes | G26: =H26/$H$121 -> 0.0044448786 | H26: 182 | I26: 1820 | J26: 1 | K26: =ROUND(L26*H26/1000,0) -> 1 | L26: 3
A27: Outpatient | B27: Floor 1 Nurse Hall | C27: Corridor Area | D27: AHU-1 | E27: Health | F27: Yes | G27: =H27/$H$121 -> 0.012113515 | H27: 496 | I27: 4960 | J27: 1 | K27: =ROUND(L27*H27/1000,0) -> 2 | L27: 5
A28: Outpatient | B28: Floor 1 Nurse Janitor | C28: Storage (General) | D28: AHU-1 | E28: Health | F28: Yes | G28: =H28/$H$121 -> 0.0013188101 | H28: 54 | I28: 540 | J28: 1 | K28: =ROUND(L28*H28/1000,0) -> 0 | L28: 2
A29: Outpatient | B29: Floor 1 Nurse Station | C29: Healthcare Facility and Hospitals (Nurse's Station) | D29: AHU-1 | E29: Health | F29: Yes | G29: =H29/$H$121 -> 0.006374249 | H29: 261 | I29: 2610 | J29: 1 | K29: =ROUND(L29*H29/1000,0) -> 1 | L29: 5
A30: Outpatient | B30: Floor 1 Nurse Toilet | C30: Restrooms | E30: Health | F30: Yes | G30: =H30/$H$121 -> 0.0013188101 | H30: 54 | I30: 540 | J30: 1 | K30: =ROUND(L30*H30/1000,0) -> 0 | L30: 5 | M30: Indirectly conditioned
A31: Outpatient | B31: Floor 1 Office | C31: Office Area (>250 square feet) | D31: AHU-1 | E31: Office | F31: Yes | G31: =H31/$H$121 -> 0.011796024 | H31: 483 | I31: 4830 | J31: 1 | K31: =L31*H31/1000 -> 2.415 | L31: 5
A32: Outpatient | B32: Floor 1 Operating Room 1 | C32: Healthcare Facility and Hospitals (Operating Room) | D32: AHU-4 | E32: Health | F32: Yes | G32: =H32/$H$121 -> 0.011234309 | H32: 460 | I32: 4600 | J32: 1 | K32: =ROUND(L32*H32/1000,0) -> 2 | L32: 5
A33: Outpatient | B33: Floor 1 Operating Room 2 | C33: Healthcare Facility and Hospitals (Operating Room) | D33: AHU-4 | E33: Health | F33: Yes | G33: =H33/$H$121 -> 0.011722757 | H33: 480 | I33: 4800 | J33: 1 | K33: =ROUND(L33*H33/1000,0) -> 2 | L33: 5
A34: Outpatient | B34: Floor 1 Operating Room 3 | C34: Healthcare Facility and Hospitals (Operating Room) | D34: AHU-4 | E34: Health | F34: Yes | G34: =H34/$H$121 -> 0.011625067 | H34: 476 | I34: 4760 | J34: 1 | K34: =ROUND(L34*H34/1000,0) -> 2 | L34: 5
A35: Outpatient | B35: Floor 1 PACU | C35: Healthcare Facility and Hospitals (Recovery Room) | D35: AHU-4 | E35: Health | F35: Yes | G35: =H35/$H$121 -> 0.0026376203 | H35: 108 | I35: 1080 | J35: 1 | K35: =ROUND(L35*H35/1000,0) -> 1 | L35: 5
A36: Outpatient | B36: Floor 1 Pre-Op Hall | C36: Corridor Area | D36: AHU-4 | E36: Health | F36: Yes | G36: =H36/$H$121 -> 0.012895032 | H36: 528 | I36: 5280 | J36: 1 | K36: =ROUND(L36*H36/1000,0) -> 3 | L36: 5
A37: Outpatient | B37: Floor 1 Pre-Op Room 1 | C37: Healthcare Facility and Hospitals (Patient Room) | D37: AHU-4 | E37: Health | F37: Yes | G37: =H37/$H$121 -> 0.0046158355 | H37: 189 | I37: 1890 | J37: 1 | K37: =ROUND(L37*H37/1000,0) -> 1 | L37: 5
A38: Outpatient | B38: Floor 1 Pre-Op Room 2 | C38: Healthcare Facility and Hospitals (Patient Room) | D38: AHU-4 | E38: Health | F38: Yes | G38: =H38/$H$121 -> 0.0082547746 | H38: 338 | I38: 3380 | J38: 1 | K38: =ROUND(L38*H38/1000,0) -> 2 | L38: 5
A39: Outpatient | B39: Floor 1 Pre-Op Toilet | C39: Restrooms | E39: Health | F39: Yes | G39: =H39/$H$121 -> 0.0013188101 | H39: 54 | I39: 540 | J39: 1 | K39: =ROUND(L39*H39/1000,0) -> 0 | L39: 5 | M39: Indirectly conditioned
A40: Outpatient | B40: Floor 1 Procedure Room | C40: Healthcare Facility and Hospitals (Exam/Treatment Room) | D40: AHU-4 | E40: Health | F40: Yes | G40: =H40/$H$121 -> 0.0069603869 | H40: 285 | I40: 2850 | J40: 1 | K40: =ROUND(L40*H40/1000,0) -> 1 | L40: 5
...

Sheet Envelope
A1: ="Envelope - "&Prototype!A2 -> Envelope - Outpatient
A2: Element | B2: Prototype | C2: Assembly Type | D2: Construction | E2: Unit | F2: Vintage | G2: Selected T24 | H2: Notes | I2: CZ1 | J2: CZ2 | K2: CZ3 | L2: CZ4 | M2: CZ5 | N2: CZ6 | O2: CZ7 | P2: CZ8 | Q2: CZ9 | R2: CZ10 | S2: CZ11 | T2: CZ12 | U2: CZ13 | V2: CZ14 | W2: CZ15 | X2: CZ16
A3: External Wall | B3: =Prototype!A2 -> Outpatient | C3: ExtWall_MetalFramed_NonRes | D3: Metal framed wall: Metal frame + insulation + gypsum board (Same as PNNL model, Analysis for Building Envelopes and Mechanical Systems Using 2012 CBECS Data, PNNL-26949, March 2018.) | E3: U-value IP | F3: Pre 1978 | G3: N/A | H3: ASHRAE 90.1,2022 Table A3.3.3.1, 3.5", R-0 | I3: 0.352 | J3: 0.352 | K3: 0.352 | L3: 0.352 | M3: 0.352 | N3: 0.352 | O3: 0.352 | P3: 0.352 | Q3: 0.352 | R3: 0.352 | S3: 0.352 | T3: 0.352 | U3: 0.352 | V3: 0.352 | W3: 0.352 | X3: 0.352
F4: 1978-1997 | G4: 1986 | H4: Copied from High-rise office alternative requirements (Table 2-53W): Package A with heat capacity between 10-14.99 (Btu/F-ft²) *T24, 1986, Table 2-53BB presents U-factors less than the next vintage (for wall density of 26-40 lb/ft² & Degree day<3500)! | I4: 0.213 | J4: 0.227 | K4: 0.227 | L4: 0.217 | M4: 0.256 | N4: 0.256 | O4: 0.256 | P4: 0.256 | Q4: 0.256 | R4: 0.256 | S4: 0.238 | T4: 0.238 | U4: 0.238 | V4: 0.208 | W4: 0.208 | X4: 0.213
F5: 1998-2007 | G5: 2001 | H5: Table 1-H | I5: 0.182 | J5: 0.182 | K5: 0.189 | L5: 0.189 | M5: 0.189 | N5: 0.189 | O5: 0.189 | P5: 0.189 | Q5: 0.189 | R5: 0.182 | S5: 0.182 | T5: 0.182 | U5: 0.182 | V5: 0.182 | W5: 0.182 | X5: 0.182
F6: 2008-2018 | G6: 2013 | H6: Table 140.3-B | I6: 0.098 | J6: 0.062 | K6: 0.082 | L6: 0.062 | M6: 0.062 | N6: 0.098 | O6: 0.098 | P6: 0.062 | Q6: 0.062 | R6: 0.062 | S6: 0.062 | T6: 0.062 | U6: 0.062 | V6: 0.062 | W6: 0.062 | X6: 0.062
F7: 2019+ | G7: 2025 | H7: Table 140.3-B | I7: 0.06 | J7: 0.055 | K7: 0.071 | L7: 0.055 | M7: 0.055 | N7: 0.06 | O7: 0.06 | P7: 0.055 | Q7: 0.055 | R7: 0.055 | S7: 0.055 | T7: 0.055 | U7: 0.055 | V7: 0.055 | W7: 0.055 | X7: 0.055
A8: Roof | B8: =$B$3 -> Outpatient | C8: FlatRoof_WoodFramedAndOther_NonRes | D8: Metal deck roof: Roof membrane + roof insulation + metal decking (Same as PNNL) | E8: U-value IP | F8: Pre 1978 | G8: N/A | H8: Considering 30 years for roof/ insulation replacement. | I8: 0.057 | J8: 0.057 | K8: 0.057 | L8: 0.057 | M8: 0.057 | N8: 0.078 | O8: 0.078 | P8: 0.078 | Q8: 0.078 | R8: 0.078 | S8: 0.057 | T8: 0.057 | U8: 0.057 | V8: 0.057 | W8: 0.057 | X8: 0.057
F9: 1978-1997 | G9: 1992 | I9: 0.057 | J9: 0.057 | K9: 0.057 | L9: 0.057 | M9: 0.057 | N9: 0.078 | O9: 0.078 | P9: 0.078 | Q9: 0.078 | R9: 0.078 | S9: 0.057 | T9: 0.057 | U9: 0.057 | V9: 0.057 | W9: 0.057 | X9: 0.057
F10: 1998-2007 | G10: 2001 | H10: Table 1-H | I10: 0.057 | J10: 0.057 | K10: 0.057 | L10: 0.057 | M10: 0.057 | N10: 0.078 | O10: 0.078 | P10: 0.078 | Q10: 0.078 | R10: 0.057 | S10: 0.057 | T10: 0.057 | U10: 0.057 | V10: 0.057 | W10: 0.057 | X10: 0.057
F11: 2008-2018 | G11: 2013 | H11: Table 140.3-B | I11: 0.049 | J11: 0.039 | K11: 0.039 | L11: 0.039 | M11: 0.049 | N11: 0.075 | O11: 0.067 | P11: 0.067 | Q11: 0.039 | R11: 0.039 | S11: 0.039 | T11: 0.039 | U11: 0.039 | V11: 0.039 | W11: 0.039 | X11: 0.039
F12: New Construction | G12: 2025 | H12: Table 140.3-B | I12: 0.038 | J12: 0.038 | K12: 0.038 | L12: 0.038 | M12: 0.038 | N12: 0.038 | O12: 0.038 | P12: 0.038 | Q12: 0.038 | R12: 0.038 | S12: 0.038 | T12: 0.038 | U12: 0.038 | V12: 0.038 | W12: 0.038 | X12: 0.038
A13: Windows | B13: =$B$3 -> Outpatient | C13: FixedWindow_NonRes | D13: Single pane | E13: U-value IP | F13: Pre 1978 | G13: N/A | H13: ASHRAE Handbook of Fundamentals (Table 4-Ch15) for single pane & T24, 2013 for double pane(88%-12%)* | I13: =0.88*1.12+0.12*0.36 -> 1.0288 | J13: =0.88*1.12+0.12*0.36 -> 1.0288 | K13: =0.88*1.12+0.12*0.36 -> 1.0288 | L13: =0.88*1.12+0.12*0.36 -> 1.0288 | M13: =0.88*1.12+0.12*0.36 -> 1.0288 | N13: =0.88*1.12+0.12*0.36 -> 1.0288 | O13: =0.88*1.12+0.12*0.36 -> 1.0288 | P13: =0.88*1.12+0.12*0.36 -> 1.0288 | ... X13: =0.88*1.12+0.12*0.36 -> 1.0288
F14: 1978-1997 | G14: N/A | I14: =0.88*1.12+0.12*0.36 -> 1.0288 | J14: =0.88*1.12+0.12*0.36 -> 1.0288 | K14: =0.88*1.12+0.12*0.36 -> 1.0288 | L14: =0.88*1.12+0.12*0.36 -> 1.0288 | M14: =0.88*1.12+0.12*0.36 -> 1.0288 | N14: =0.88*1.12+0.12*0.36 -> 1.0288 | O14: =0.88*1.12+0.12*0.36 -> 1.0288 | P14: =0.88*1.12+0.12*0.36 -> 1.0288 | ... X14: =0.88*1.12+0.12*0.36 -> 1.0288
D15: Double pane | F15: 1998-2007 | G15: 2001 | H15: Table 1-H | I15: 0.49 | J15: 0.49 | K15: 0.81 | L15: 0.81 | M15: 0.81 | N15: 0.81 | O15: 0.81 | P15: 0.81 | Q15: 0.81 | R15: 0.49 | S15: 0.49 | T15: 0.49 | U15: 0.49 | V15: 0.49 | W15: 0.49 | X15: 0.49
F16: 2008-2018 | G16: 2013 | H16: Table 140.3-B | I16: 0.36 | J16: 0.36 | K16: 0.36 | L16: 0.36 | M16: 0.36 | N16: 0.36 | O16: 0.36 | P16: 0.36 | Q16: 0.36 | R16: 0.36 | S16: 0.36 | T16: 0.36 | U16: 0.36 | V16: 0.36 | W16: 0.36 | X16: 0.36
F17: 2019+ | G17: 2025 | H17: Table 140.3-B | I17: 0.36 | J17: 0.36 | K17: 0.36 | L17: 0.36 | M17: 0.36 | N17: 0.36 | O17: 0.36 | P17: 0.36 | Q17: 0.34 | R17: 0.36 | S17: 0.34 | T17: 0.34 | U17: 0.34 | V17: 0.34 | W17: 0.34 | X17: 0.36
B18: =$B$3 -> Outpatient | C18: FixedWindow_NonRes | D18: Single pane | E18: SHGC | F18: Pre 1978 | G18: N/A | H18: ASHRAE Handbook of Fundamentals (Table 10-Ch15) for single pane & T24, 2013 for double pane(88%-12%)* | I18: =0.79*0.88+0.12*I21 -> 0.7252 | J18: =0.79*0.88+0.12*J21 -> 0.7252 | K18: =0.79*0.88+0.12*K21 -> 0.7252 | L18: =0.79*0.88+0.12*L21 -> 0.7252 | M18: =0.79*0.88+0.12*M21 -> 0.7252 | N18: =0.79*0.88+0.12*N21 -> 0.7252 | O18: =0.79*0.88+0.12*O21 -> 0.7252 | P18: =0.79*0.88+0.12*P21 -> 0.7252 | ... X18: =0.79*0.88+0.12*X21 -> 0.7252
F19: 1978-1997 | G19: N/A | I19: =0.79*0.88+0.12*I21 -> 0.7252 | J19: =0.79*0.88+0.12*J21 -> 0.7252 | K19: =0.79*0.88+0.12*K21 -> 0.7252 | L19: =0.79*0.88+0.12*L21 -> 0.7252 | M19: =0.79*0.88+0.12*M21 -> 0.7252 | N19: =0.79*0.88+0.12*N21 -> 0.7252 | O19: =0.79*0.88+0.12*O21 -> 0.7252 | P19: =0.79*0.88+0.12*P21 -> 0.7252 | ... X19: =0.79*0.88+0.12*X21 -> 0.7252
D20: Double pane | F20: 1998-2007 | G20: 2001 | H20: Table 1-H (Non North, WWR:11-20% ) | I20: 0.43 | J20: 0.36 | K20: 0.55 | L20: 0.55 | M20: 0.55 | N20: 0.61 | O20: 0.61 | P20: 0.61 | Q20: 0.61 | R20: 0.36 | S20: 0.36 | T20: 0.36 | U20: 0.36 | V20: 0.36 | W20: 0.36 | X20: 0.43
F21: 2008-2018 | G21: 2013 | H21: Table 140.3-B | I21: 0.25 | J21: 0.25 | K21: 0.25 | L21: 0.25 | M21: 0.25 | N21: 0.25 | O21: 0.25 | P21: 0.25 | Q21: 0.25 | R21: 0.25 | S21: 0.25 | T21: 0.25 | U21: 0.25 | V21: 0.25 | W21: 0.25 | X21: 0.25
F22: 2019+ | G22: 2025 | H22: Table 140.3-B | I22: 0.25 | J22: 0.25 | K22: 0.25 | L22: 0.25 | M22: 0.25 | N22: 0.25 | O22: 0.25 | P22: 0.25 | Q22: 0.22 | R22: 0.25 | S22: 0.22 | T22: 0.22 | U22: 0.22 | V22: 0.22 | W22: 0.22 | X22: 0.25
A23: *(According to CBECS 2018, ~ 88% of windows of healthcare buildings built before 2000 are single pane)
C25: Infiltration
D26: Building | E26: Zones | F26: Vintage | G26: I_75 6-sdied Infiltration rate @ 75 pa | H26: Note | I26: I-design (cfm/ft²) (4-sided Infiltration rate at normal pressure) (Design flow rate approach and Flow/Exterior Wall Area calculation method)
C27: Infiltration | D27: Outpatient | F27: Pre 1978 | G27: 1.1 | H27: 2022 CASE report (Table 38) | I27: 0.341
F28: 1978-1997 | G28: 1.1 | H28: 2022 CASE report (Table 38) | I28: 0.341
F29: 1998-2007 | G29: 1.1 | H29: 2022 CASE report (Table 38) | I29: 0.341
F30: 2008-2018 | G30: 1 | H30: 2022 CASE report (Table 38) & T24, 2008-2016 (Table 140.3-B)--Air barrier is required in CZ 10-16 | I30: 0.3121
F31: 2019+ | G31: 0.6 | H31: 2022 CASE report (Table 38) & T24, 2025 (Table 140.3-B)--Air barrier is required in all CZs | I31: 0.186
E32: Source: Title 24 air barrier requirements (all editions) and the standardized infiltration rate reported in the 2022 CASE report and Dodge 2023 data
E33: Air Leakage Memo: | G33: Infiltration_rate_report_14May2025-Short-Version.docx

Sheet Thermostat
A1: ="Thermostat - "&Prototype!A2 -> Thermostat - Outpatient
A2: Setpoint | B2: CZ1 | C2: CZ2 | D2: CZ3 | E2: CZ4 | F2: CZ5 | G2: CZ6 | H2: CZ7 | I2: CZ8 | J2: CZ9 | K2: CZ10 | L2: CZ11 | M2: CZ12 | N2: CZ13 | O2: CZ14 | P2: CZ15 | Q2: CZ16 | R2: Source | S2: Note
A3: Health Heating Setpoint (F) | B3: 70 | C3: 70 | D3: 70 | E3: 70 | F3: 70 | G3: 70 | H3: 70 | I3: 70 | J3: 70 | K3: 70 | L3: 70 | M3: 70 | N3: 70 | O3: 70 | P3: 70 | Q3: 70 | R3: T24 2022 - Appendix 5.4B | S3: PNNL Healthcare-Outpatient prototype use this setpoints: Administration zones: 72°F Cooling/70°F Heating, Critical zones: 72°F Cooling/70°F Heating, Operating rooms: 65°F Cooling/65°F Heating---PNNL Healthcare-Outpatient prototype use this setbacks: 77°F Cooling/65°F Heating, Critical zones: no setback, Operating rooms: 72°F Cooling/65°F Heating
A4: Health Heating Setback (F) | B4: 70 | C4: 70 | D4: 70 | E4: 70 | F4: 70 | G4: 70 | H4: 70 | I4: 70 | J4: 70 | K4: 70 | L4: 70 | M4: 70 | N4: 70 | O4: 70 | P4: 70 | Q4: 70
A5: Health Cooling Setpoint (F) | B5: 75 | C5: 75 | D5: 75 | E5: 75 | F5: 75 | G5: 75 | H5: 75 | I5: 75 | J5: 75 | K5: 75 | L5: 75 | M5: 75 | N5: 75 | O5: 75 | P5: 75 | Q5: 75
A6: Health Cooling Setback (F) | B6: 75 | C6: 75 | D6: 75 | E6: 75 | F6: 75 | G6: 75 | H6: 75 | I6: 75 | J6: 75 | K6: 75 | L6: 75 | M6: 75 | N6: 75 | O6: 75 | P6: 75 | Q6: 75
A7: Kitchen Heating Setpoint (F) | B7: 66 | C7: 66 | D7: 66 | E7: 66 | F7: 66 | G7: 66 | H7: 66 | I7: 66 | J7: 66 | K7: 66 | L7: 66 | M7: 66 | N7: 66 | O7: 66 | P7: 66 | Q7: 66 | R7: PNNL 09.1, 2022 Restaurant prototype
A8: Kitchen Heating Setback (F) | B8: 60 | C8: 60 | D8: 60 | E8: 60 | F8: 60 | G8: 60 | H8: 60 | I8: 60 | J8: 60 | K8: 60 | L8: 60 | M8: 60 | N8: 60 | O8: 60 | P8: 60 | Q8: 60
A9: Kitchen Cooling Setpoint (F) | B9: 79 | C9: 79 | D9: 79 | E9: 79 | F9: 79 | G9: 79 | H9: 79 | I9: 79 | J9: 79 | K9: 79 | L9: 79 | M9: 79 | N9: 79 | O9: 79 | P9: 79 | Q9: 79
A10: Kitchen Cooling Setback (F) | B10: 86 | C10: 86 | D10: 86 | E10: 86 | F10: 86 | G10: 86 | H10: 86 | I10: 86 | J10: 86 | K10: 86 | L10: 86 | M10: 86 | N10: 86 | O10: 86 | P10: 86 | Q10: 86
A11: Ancillary Heating Setpoint (F) | B11: 60 | C11: 60 | D11: 60 | E11: 60 | F11: 60 | G11: 60 | H11: 60 | I11: 60 | J11: 60 | K11: 60 | L11: 60 | M11: 60 | N11: 60 | O11: 60 | P11: 60 | Q11: 60 | R11: Enginnering Judgment
A12: Ancillary Heating Setback (F) | B12: 60 | C12: 60 | D12: 60 | E12: 60 | F12: 60 | G12: 60 | H12: 60 | I12: 60 | J12: 60 | K12: 60 | L12: 60 | M12: 60 | N12: 60 | O12: 60 | P12: 60 | Q12: 60
A13: Ancillary Cooling Setpoint (F) | B13: 85 | C13: 85 | D13: 85 | E13: 85 | F13: 85 | G13: 85 | H13: 85 | I13: 85 | J13: 85 | K13: 85 | L13: 85 | M13: 85 | N13: 85 | O13: 85 | P13: 85 | Q13: 85
A14: Ancillary Cooling Setback (F) | B14: 85 | C14: 85 | D14: 85 | E14: 85 | F14: 85 | G14: 85 | H14: 85 | I14: 85 | J14: 85 | K14: 85 | L14: 85 | M14: 85 | N14: 85 | O14: 85 | P14: 85 | Q14: 85

Sheet HVAC System
A1: ="HVAC System - "&Prototype!A2 -> HVAC System - Outpatient
A2: Vintage | B2: Spaces | C2: Heating | D2: Cooling | E2: Air Distribution | F2: Source | G2: Note
A3: Existing | B3: Conditioned zones | C3: Gas Boiler for Hydronic Reheat and Gas Furnace for Heating | D3: RTU DX | E3: Single Duct CAV--Outdoor air often supplied through RTU economizers or dedicated OA section | F3: CEUS 2022 (Other system based on T24 and Engineering judgement) | G3: Packaged RTU
A4: New Construction | B4: Conditioned zones | C4: Gas Boiler for Hydronic Reheat and Gas Furnace for Heating | D4: RTU DX | E4: VAV + Hydronic Reheat | F4: T24 2025 ACM 2025, Table 2 and 3 | G4: System 5 – PVAV
A8: Efficiency of HVAC system (Efficiency is capacity-dependent. The following table provides a general estimate of system efficiency based on preliminary simulations in one climate zone, or assuming cooling load based on rule of thumb)
A9: Vintage | B9: Upgrade/Installed year | C9: DX Cooling | D9: Gas Furnace | E9: Gas Boiler | F9: Source | G9: Note
A10: Pre 1978 | B10: 2008 | C10: EER=9.5 (≥ 240,000 Btu/h and < 760,000 Btu/h) | D10: ≥225,000 Btu/h--80% Et | E10: 80% Ec | F10: T24, 2008 , Table 112-A (for DX Coil) -Title 24-2008 §111 / Title 20 Table E-3 (and 10 CFR 431.87 as in effect through March 1, 2012) for Boiler Efficiency- 10 CFR 431.77, in force since 1 Jan 1994 for furnace efficiency
A11: 1978-1997
A12: 1998-2007
A13: 2008-2018 | B13: 2013 | C13: EER=10 (≥ 240,000 Btu/h and < 760,000 Btu/h) | D13: 80% Et | E13: Gas-Fired Boiler > 300,000 Btu/h and ≤2,500,000 Btu/h-- 80% Et Gas-Fired Boiler > 2,500,000 Btu/h -- 82% Ec | F13: T24, 2013 , Table 110.2-A (for DX Coil) -Table 110.2-J (for Gas Furnace thermal efficiency) - - Table 110.2-K (for Boiler thermal efficiency).
A14: New Construction | B14: 2025 | C14: EER=10 (≥ 240,000 Btu/h and < 760,000 Btu/h) | D14: 81% Et | E14: Gas-Fired Boiler > 300,000 Btu/h and ≤2,500,000 Btu/h-- 80% Et Gas-Fired Boiler > 2,500,000 Btu/h -- 82% Ec | F14: T24, 2025 , Table 110.2-A (for DX Coil) - - 10 CFR 431.86 , section § 431.87 Table 1 (for Boiler thermal efficiency) --Title 24-2008 §111 / Title 20 Table E-3 (and 10 CFR 431.87 as in effect through March 1, 2012)
D16: * Et = Thermal efficiency | E16: * Ec = Combustion efficiency
A19: Fan power
A20: Vintage | B20: Approach | C20: System | D20: Total Static Pressure (TSP) (in w.c.) | E20: Fan Efficiency [ACM 2025] | F20: Motor Efficiency | G20: Fan Power Index (W/cfm) | H20: Data Source | I20: Note
A21: Existing | B21: PNNL 90.1-2011, TSP | C21: Packaged RTU-CAV | D21: 4.09 | E21: 0.65 | F21: ASHRAE 90.1, 2004, Table 10.8 * | H21: Fan power formula: PNNL 20405, 2010, section 5.2.2.5 TSP and fan efficiency: PNNL 20405, 2010, Table 5.11, 90.1-04ac values Motor efficiency: ASHRAE 90.1, 2004, Table 10.8
A22: Brake horsepower (bhp) = (Supply cfm × TSP in w.c.) / (6356 × fan efficiency)
A23: Fan power (w/cfm) = (bhp × 746) / ( supply cfm × motor efficiency )
A24: New Construction | B24: ACM 2025 | C24: Packaged RTU-CAV >5,000 cfm; <= 10,000 cfm | D24: TSP (in w.c.) = fan power (W/cfm) × motor efficiency × fan efficiency × 6356 / 746 | E24: 0.65 | F24: 2025 ACM Table 12 ** | G24: 0.78 | H24: Fan power index: [ACM 2025, Table 13] Motot efficiency: [ ACM 2025, Table 12]
C25: Packaged RTU-CAV >10,000 cfm | D25: TSP (in w.c.) = fan power (W/cfm) × motor efficiency × fan efficiency × 6356 / 746 | G25: 0.748
C26: System 5-PVAV System >5,000 cfm; <= 10,000 cfm | D26: TSP (in w.c.) = fan power (W/cfm) × motor efficiency × fan efficiency × 6356 / 746 | G26: 1.013
C27: System 5-PVAV System >10,000 cfm | D27: TSP = fan power × motor efficiency × fan efficiency × 6356 / 746 | G27: 0.946
A29: * According to PNNL 20405 section 5.2.2.5, the full-load efficiency of the motor serving the fan is taken from ASHRAE 90.1, 2004, Table 10.8, based on motor nameplate and assuming enclosed motors operating at 1,800 rotations per minute (rpm) Motor nameplate size (bhp) = brake horsepower (bhp) × 1.1 ( using a 10% oversizing factor)
A30: ** The full‑load efficiency of the motor serving the fan is taken from ACM 2025 Table 12 based on the cfm of the fan. Brake horsepower (bhp) = (Supply cfm from sizing run × fan power in W/cfm) / 746.

Sheet Ventilation
A1: ="Outdoor Airflow Rate - "&Prototype!A2 -> Outdoor Airflow Rate - Outpatient
A2: Space Type | B2: Space/Thermal Zone | C2: Number of People | D2: Floor Area (ft²) | E2: cfm/person [T24, 2025, Equation 120.1-F and Table 120.1-A] | F2: cfm/ft² [T24, 2025, Equation 120.1-F and Table 120.1-A] | G2: Required Exhaust Rate (cfm/ft²) [T24, 2025, Table 120.1-B – minimum exhaust rates OR CMC Table 4-A for Healthcare] | H2: Required Exhaust Rate (cfm) [T24, 2025, Table 120.1-B – minimum exhaust rates] | I2: Min OA Ventilation Requirement (cfm/ft²) [Table 4-A, 2022 California Mechanical Code]* | J2: Total cfm Driven by People | K2: Total cfm Driven by Area | L2: Total cfm Driven by Exhaust | M2: Total cfm | N2: Note
A3: =Zones!C3 -> Healthcare Facility and Hospitals (Exam/Treatment Room) | B3: =Zones!B3 -> Floor 1 Anesthesia | C3: =Zones!K3 -> 1 | D3: =Zones!H3 -> 108 | E3: 15 | F3: =VLOOKUP(A3,A$175:E$197,5,FALSE) -> n/a | G3: 1.33 | I3: =VLOOKUP(A3,A$175:H$197,8,FALSE) -> 0.33333333 | J3: =E3*C3 -> 15 | K3: =IF(F3="n/a",D3*I3,F3*D3) -> 36 | L3: =G3*D3 -> 143.64 | M3: =MAX(J3:L3) -> 143.64 | N3: All Room air exhausted directly to the outdoor, according to Table 4-A, 2022 California Mechanical Code).
A4: =Zones!C4 -> Healthcare Facility and Hospitals (Medical Supply Room) | B4: =Zones!B4 -> Floor 1 Bio Haz | C4: =Zones!K4 -> 0 | D4: =Zones!H4 -> 56 | E4: 15 | F4: =VLOOKUP(A4,A$175:E$197,5,FALSE) -> n/a | I4: =VLOOKUP(A4,A$175:H$197,8,FALSE) -> 0.33333333 | J4: =E4*C4 -> 0 | K4: =IF(F4="n/a",D4*I4,F4*D4) -> 18.666667 | L4: =G4*D4 -> 0 | M4: =MAX(J4:L4) -> 18.666667
A5: =Zones!C5 -> Dining Area (Cafeteria/Fast Food) | B5: =Zones!B5 -> Floor 1 Café | C5: =Zones!K5 -> 14 | D5: =Zones!H5 -> 420 | E5: 15 | F5: =VLOOKUP(A5,A$175:E$197,5,FALSE) -> 0.15 | I5: =VLOOKUP(A5,A$175:H$197,8,FALSE) -> 0 | J5: =E5*C5 -> 210 | K5: =IF(F5="n/a",D5*I5,F5*D5) -> 63 | L5: =G5*D5 -> 0 | M5: =MAX(J5:L5) -> 210
A6: =Zones!C6 -> Healthcare Facility and Hospitals (Medical Supply Room) | B6: =Zones!B6 -> Floor 1 Clean | C6: =Zones!K6 -> 1 | D6: =Zones!H6 -> 126 | E6: 15 | F6: =VLOOKUP(A6,A$175:E$197,5,FALSE) -> n/a | I6: =VLOOKUP(A6,A$175:H$197,8,FALSE) -> 0.33333333 | J6: =E6*C6 -> 15 | K6: =IF(F6="n/a",D6*I6,F6*D6) -> 42 | L6: =G6*D6 -> 0 | M6: =MAX(J6:L6) -> 42
A7: =Zones!C7 -> Healthcare Facility and Hospitals (Medical Supply Room) | B7: =Zones!B7 -> Floor 1 Clean Work | C7: =Zones!K7 -> 1 | D7: =Zones!H7 -> 165 | E7: 15 | F7: =VLOOKUP(A7,A$175:E$197,5,FALSE) -> n/a | I7: =VLOOKUP(A7,A$175:H$197,8,FALSE) -> 0.33333333 | J7: =E7*C7 -> 15 | K7: =IF(F7="n/a",D7*I7,F7*D7) -> 55 | L7: =G7*D7 -> 0 | M7: =MAX(J7:L7) -> 55
A8: =Zones!C8 -> Office Area (<250 square feet) | B8: =Zones!B8 -> Floor 1 Dictation | C8: =Zones!K8 -> 0.63 | D8: =Zones!H8 -> 126 | E8: 15 | F8: =VLOOKUP(A8,A$175:E$197,5,FALSE) -> 0.15 | I8: =VLOOKUP(A8,A$175:H$197,8,FALSE) -> 0 | J8: =E8*C8 -> 9.45 | K8: =IF(F8="n/a",D8*I8,F8*D8) -> 18.9 | L8: =G8*D8 -> 0 | M8: =MAX(J8:L8) -> 18.9
A9: =Zones!C9 -> Office Area (<250 square feet) | B9: =Zones!B9 -> Floor 1 Dressing Room | C9: =Zones!K9 -> 0.225 | D9: =Zones!H9 -> 45 | E9: 15 | F9: =VLOOKUP(A9,A$175:E$197,5,FALSE) -> 0.15 | I9: =VLOOKUP(A9,A$175:H$197,8,FALSE) -> 0 | J9: =E9*C9 -> 3.375 | K9: =IF(F9="n/a",D9*I9,F9*D9) -> 6.75 | L9: =G9*D9 -> 0 | M9: =MAX(J9:L9) -> 6.75
A10: =Zones!C10 -> Electrical, Mechanical, Telephone Rooms | B10: =Zones!B10 -> Floor 1 Electrical Room | C10: =Zones!K10 -> 0 | D10: =Zones!H10 -> 98 | E10: 15 | F10: =VLOOKUP(A10,A$175:E$197,5,FALSE) -> n/a | I10: =VLOOKUP(A10,A$175:H$197,8,FALSE) -> 0 | J10: =E10*C10 -> 0 | K10: =IF(F10="n/a",D10*I10,F10*D10) -> 0 | L10: =G10*D10 -> 0 | M10: =MAX(J10:L10) -> 0
A11: =Zones!C11 -> Electrical, Mechanical, Telephone Rooms | B11: =Zones!B11 -> Floor 1 Elevator Pump Room | C11: =Zones!K11 -> 0 | D11: =Zones!H11 -> 91 | E11: 15 | F11: =VLOOKUP(A11,A$175:E$197,5,FALSE) -> n/a | I11: =VLOOKUP(A11,A$175:H$197,8,FALSE) -> 0 | J11: =E11*C11 -> 0 | K11: =IF(F11="n/a",D11*I11,F11*D11) -> 0 | L11: =G11*D11 -> 0 | M11: =MAX(J11:L11) -> 0
A12: =Zones!C12 -> Office Area (<250 square feet) | B12: =Zones!B12 -> Floor 1 Humid | C12: =Zones!K12 -> 0.27 | D12: =Zones!H12 -> 54 | E12: 15 | F12: =VLOOKUP(A12,A$175:E$197,5,FALSE) -> 0.15 | I12: =VLOOKUP(A12,A$175:H$197,8,FALSE) -> 0 | J12: =E12*C12 -> 4.05 | K12: =IF(F12="n/a",D12*I12,F12*D12) -> 8.1 | L12: =G12*D12 -> 0 | M12: =MAX(J12:L12) -> 8.1
A13: =Zones!C13 -> Corridor Area | B13: =Zones!B13 -> Floor 1 IT Hall | C13: =Zones!K13 -> 1 | D13: =Zones!H13 -> 140 | E13: 15 | F13: =VLOOKUP(A13,A$175:E$197,5,FALSE) -> 0.15 | I13: =VLOOKUP(A13,A$175:H$197,8,FALSE) -> 0 | J13: =E13*C13 -> 15 | K13: =IF(F13="n/a",D13*I13,F13*D13) -> 21 | L13: =G13*D13 -> 0 | M13: =MAX(J13:L13) -> 21
A14: =Zones!C14 -> Office Area (<250 square feet) | B14: =Zones!B14 -> Floor 1 IT Room | C14: =Zones!K14 -> 0.56 | D14: =Zones!H14 -> 112 | E14: 15 | F14: =VLOOKUP(A14,A$175:E$197,5,FALSE) -> 0.15 | I14: =VLOOKUP(A14,A$175:H$197,8,FALSE) -> 0 | J14: =E14*C14 -> 8.4 | K14: =IF(F14="n/a",D14*I14,F14*D14) -> 16.8 | L14: =G14*D14 -> 0 | M14: =MAX(J14:L14) -> 16.8
A15: =Zones!C15 -> Lobby, Main Entry | B15: =Zones!B15 -> Floor 1 Lobby | C15: =Zones!K15 -> 21 | D15: =Zones!H15 -> 622 | E15: 15 | F15: =VLOOKUP(A15,A$175:E$197,5,FALSE) -> 0.15 | I15: =VLOOKUP(A15,A$175:H$197,8,FALSE) -> 0 | J15: =E15*C15 -> 315 | K15: =IF(F15="n/a",D15*I15,F15*D15) -> 93.3 | L15: =G15*D15 -> 0 | M15: =MAX(J15:L15) -> 315
A16: =Zones!C16 -> Corridor Area | B16: =Zones!B16 -> Floor 1 Lobby Hall | C16: =Zones!K16 -> 1 | D16: =Zones!H16 -> 240 | E16: 15 | F16: =VLOOKUP(A16,A$175:E$197,5,FALSE) -> 0.15 | I16: =VLOOKUP(A16,A$175:H$197,8,FALSE) -> 0 | J16: =E16*C16 -> 15 | K16: =IF(F16="n/a",D16*I16,F16*D16) -> 36 | L16: =G16*D16 -> 0 | M16: =MAX(J16:L16) -> 36
A17: =Zones!C17 -> Restrooms | B17: =Zones!B17 -> Floor 1 Lobby Toilet | C17: =Zones!K17 -> 0 | D17: =Zones!H17 -> 54 | E17: 15 | F17: =VLOOKUP(A11,A$175:E$197,5,FALSE) -> n/a | H17: 50 | I17: =VLOOKUP(A17,A$175:H$197,8,FALSE) -> 0 | J17: =E17*C17 -> 0 | K17: =IF(F17="n/a",D17*I17,F17*D17) -> 0 | L17: 50 | M17: 0 | N17: *Restrooms in California per 2025 T24 and CALGreen (Part 11) require mechanical exhaust ventilation, but they do not require additional dedicated outdoor air (OA) beyond that local exhaust. Bathroom exhaust and exhaust fan energy will be captured in the models. We will assume make-up air is drawn from adjacent spaces.
A18: =Zones!C18 -> Locker Room | B18: =Zones!B18 -> Floor 1 Locker Room | C18: =Zones!K18 -> 7 | D18: =Zones!H18 -> 660 | E18: 15 | F18: =VLOOKUP(A18,A$175:E$197,5,FALSE) -> n/a | G18: 0.25 | I18: =VLOOKUP(A18,A$175:H$197,8,FALSE) -> 0 | J18: =E18*C18 -> 105 | K18: =IF(F18="n/a",D18*I18,F18*D18) -> 0 | L18: =G18*D18 -> 165 | M18: =MAX(J18:L18) -> 165
A19: =Zones!C19 -> Corridor Area | B19: =Zones!B19 -> Floor 1 Locker Room Hall | C19: =Zones!K19 -> 2 | D19: =Zones!H19 -> 496 | E19: 15 | F19: =VLOOKUP(A19,A$175:E$197,5,FALSE) -> 0.15 | I19: =VLOOKUP(A19,A$175:H$197,8,FALSE) -> 0 | J19: =E19*C19 -> 30 | K19: =IF(F19="n/a",D19*I19,F19*D19) -> 74.4 | L19: =H19*D19 -> 0 | M19: =MAX(J19:L19) -> 74.4
A20: =Zones!C20 -> Lounge, Breakroom, or Waiting Area | B20: =Zones!B20 -> Floor 1 Lounge | C20: =Zones!K20 -> 12 | D20: =Zones!H20 -> 360 | E20: 15 | F20: =VLOOKUP(A20,A$175:E$197,5,FALSE) -> 0.15 | I20: =VLOOKUP(A20,A$175:H$197,8,FALSE) -> 0 | J20: =E20*C20 -> 180 | K20: =IF(F20="n/a",D20*I20,F20*D20) -> 54 | L20: =H20*D20 -> 0 | M20: =MAX(J20:L20) -> 180
A21: =Zones!C21 -> Healthcare Facility and Hospitals (Medical Supply Room) | B21: =Zones!B21 -> Floor 1 Med Gas | C21: =Zones!K21 -> 0 | D21: =Zones!H21 -> 56 | E21: 15 | F21: =VLOOKUP(A21,A$175:E$197,5,FALSE) -> n/a | I21: =VLOOKUP(A21,A$175:H$197,8,FALSE) -> 0.33333333 | J21: =E21*C21 -> 0 | K21: =IF(F21="n/a",D21*I21,F21*D21) -> 18.666667 | L21: =H21*D21 -> 0 | M21: =MAX(J21:L21) -> 18.666667
A22: =Zones!C22 -> Healthcare Facility and Hospitals (Imaging Room) | B22: =Zones!B22 -> Floor 1 MRI Control Room | C22: =Zones!K22 -> 1 | D22: =Zones!H22 -> 168 | E22: 15 | F22: =VLOOKUP(A22,A$175:E$197,5,FALSE) -> n/a | G22: 2.02 | I22: =VLOOKUP(A22,A$175:H$197,8,FALSE) -> 0.33333333 | J22: =E22*C22 -> 15 | K22: =IF(F22="n/a",D22*I22,F22*D22) -> 56 | L22: =G22*D22 -> 339.36 | M22: =MAX(J22:L22) -> 339.36 | N22: Exhaust Rate assumed according to PNNL outpatient model.The PNNL outpatient model used ASHRAE 170 / CMC Table 4-A (Negative Pressure Soiled utility/workroom or soiled holding , exhaust Required))
A23: =Zones!C23 -> Corridor Area | B23: =Zones!B23 -> Floor 1 MRI Hall | C23: =Zones!K23 -> 1 | D23: =Zones!H23 -> 147 | E23: 15 | F23: =VLOOKUP(A23,A$175:E$197,5,FALSE) -> 0.15 | I23: =VLOOKUP(A23,A$175:H$197,8,FALSE) -> 0 | J23: =E23*C23 -> 15 | K23: =IF(F23="n/a",D23*I23,F23*D23) -> 22.05 | L23: =H23*D23 -> 0 | M23: =MAX(J23:L23) -> 22.05
A24: =Zones!C24 -> Healthcare Facility and Hospitals (Imaging Room) | B24: =Zones!B24 -> Floor 1 MRI Room | C24: =Zones!K24 -> 2 | D24: =Zones!H24 -> 440 | E24: 15 | F24: =VLOOKUP(A24,A$175:E$197,5,FALSE) -> n/a | G24: 2.02 | I24: =VLOOKUP(A24,A$175:H$197,8,FALSE) -> 0.33333333 | J24: =E24*C24 -> 30 | K24: =IF(F24="n/a",D24*I24,F24*D24) -> 146.66667 | L24: =G24*D24 -> 888.8 | M24: =MAX(J24:L24) -> 888.8 | N24: Exhaust Rate assumed according to PNNL outpatient model.The PNNL outpatient model used ASHRAE 170 / CMC Table 4-A (Negative Pressure X-ray room , exhaust Required))
A25: =Zones!C25 -> Restrooms | B25: =Zones!B25 -> Floor 1 MRI Toilet | C25: =Zones!K25 -> 0 | D25: =Zones!H25 -> 54 | E25: 15 | F25: =VLOOKUP(A11,A$175:E$197,5,FALSE) -> n/a | H25: 50 | I25: =VLOOKUP(A25,A$175:H$197,8,FALSE) -> 0 | J25: =E25*C25 -> 0 | K25: =IF(F25="n/a",D25*I25,F25*D25) -> 0 | L25: =H25 -> 50 | M25: =MAX(J25:L25) -> 50 | N25: Toilet rooms, intermittent exhaust 50 cfm per toilet
A26: =Zones!C26 -> Kitchen/Food Preparation Area | B26: =Zones!B26 -> Floor 1 Nourishment | C26: =Zones!K26 -> 1 | D26: =Zones!H26 -> 182 | E26: 15 | F26: =VLOOKUP(A26,A$175:E$197,5,FALSE) -> 0.15 | G26: 0.3 | I26: =VLOOKUP(A26,A$175:H$197,8,FALSE) -> 0 | J26: =E26*C26 -> 15 | K26: =IF(F26="n/a",D26*I26,F26*D26) -> 27.3 | L26: =G26*D26 -> 54.6 | M26: =MAX(J26:L26) -> 54.6
A27: =Zones!C27 -> Corridor Area | B27: =Zones!B27 -> Floor 1 Nurse Hall | C27: =Zones!K27 -> 2 | D27: =Zones!H27 -> 496 | E27: 15 | F27: =VLOOKUP(A27,A$175:E$197,5,FALSE) -> 0.15 | I27: =VLOOKUP(A27,A$175:H$197,8,FALSE) -> 0 | J27: =E27*C27 -> 30 | K27: =IF(F27="n/a",D27*I27,F27*D27) -> 74.4 | L27: =H27*D27 -> 0 | M27: =MAX(J27:L27) -> 74.4
A28: =Zones!C28 -> Storage (General) | B28: =Zones!B28 -> Floor 1 Nurse Janitor | C28: =Zones!K28 -> 0 | D28: =Zones!H28 -> 54 | E28: 15 | F28: =VLOOKUP(A28,A$175:E$197,5,FALSE) -> 0.15 | I28: =VLOOKUP(A28,A$175:H$197,8,FALSE) -> 0 | J28: =E28*C28 -> 0 | K28: =IF(F28="n/a",D28*I28,F28*D28) -> 8.1 | L28: =H28*D28 -> 0 | M28: =MAX(J28:L28) -> 8.1
A29: =Zones!C29 -> Healthcare Facility and Hospitals (Nurse's Station) | B29: =Zones!B29 -> Floor 1 Nurse Station | C29: =Zones!K29 -> 1 | D29: =Zones!H29 -> 261 | E29: 15 | F29: =VLOOKUP(A29,A$175:E$197,5,FALSE) -> n/a | I29: =VLOOKUP(A29,A$175:H$197,8,FALSE) -> 0.33333333 | J29: =E29*C29 -> 15 | K29: =IF(F29="n/a",D29*I29,F29*D29) -> 87 | L29: =H29*D29 -> 0 | M29: =MAX(J29:L29) -> 87
A30: =Zones!C30 -> Restrooms | B30: =Zones!B30 -> Floor 1 Nurse Toilet | C30: =Zones!K30 -> 0 | D30: =Zones!H30 -> 54 | E30: 15 | F30: =VLOOKUP(A11,A$175:E$197,5,FALSE) -> n/a | H30: 50 | I30: =VLOOKUP(A30,A$175:H$197,8,FALSE) -> 0 | J30: =E30*C30 -> 0 | K30: =IF(F30="n/a",D30*I30,F30*D30) -> 0 | L30: =H30 -> 50 | M30: =MAX(J30:L30) -> 50 | N30: Toilet rooms, intermittent exhaust 50 cfm per toilet
A31: =Zones!C31 -> Office Area (>250 square feet) | B31: =Zones!B31 -> Floor 1 Office | C31: =Zones!K31 -> 2.415 | D31: =Zones!H31 -> 483 | E31: 15 | F31: =VLOOKUP(A31,A$175:E$197,5,FALSE) -> 0.15 | I31: =VLOOKUP(A31,A$175:H$197,8,FALSE) -> 0 | J31: =E31*C31 -> 36.225 | K31: =IF(F31="n/a",D31*I31,F31*D31) -> 72.45 | L31: =H31*D31 -> 0 | M31: =MAX(J31:L31) -> 72.45
A32: =Zones!C32 -> Healthcare Facility and Hospitals (Operating Room) | B32: =Zones!B32 -> Floor 1 Operating Room 1 | C32: =Zones!K32 -> 2 | D32: =Zones!H32 -> 460 | E32: 15 | F32: =VLOOKUP(A32,A$175:E$197,5,FALSE) -> n/a | I32: =VLOOKUP(A32,A$175:H$197,8,FALSE) -> 0.66666667 | J32: =E32*C32 -> 30 | K32: =IF(F32="n/a",D32*I32,F32*D32) -> 306.66667 | L32: =H32*D32 -> 0 | M32: =MAX(J32:L32) -> 306.66667
A33: =Zones!C33 -> Healthcare Facility and Hospitals (Operating Room) | B33: =Zones!B33 -> Floor 1 Operating Room 2 | C33: =Zones!K33 -> 2 | D33: =Zones!H33 -> 480 | E33: 15 | F33: =VLOOKUP(A33,A$175:E$197,5,FALSE) -> n/a | I33: =VLOOKUP(A33,A$175:H$197,8,FALSE) -> 0.66666667 | J33: =E33*C33 -> 30 | K33: =IF(F33="n/a",D33*I33,F33*D33) -> 320 | L33: =H33*D33 -> 0 | M33: =MAX(J33:L33) -> 320
A34: =Zones!C34 -> Healthcare Facility and Hospitals (Operating Room) | B34: =Zones!B34 -> Floor 1 Operating Room 3 | C34: =Zones!K34 -> 2 | D34: =Zones!H34 -> 476 | E34: 15 | F34: =VLOOKUP(A34,A$175:E$197,5,FALSE) -> n/a | I34: =VLOOKUP(A34,A$175:H$197,8,FALSE) -> 0.66666667 | J34: =E34*C34 -> 30 | K34: =IF(F34="n/a",D34*I34,F34*D34) -> 317.33333 | L34: =H34*D34 -> 0 | M34: =MAX(J34:L34) -> 317.33333
A35: =Zones!C35 -> Healthcare Facility and Hospitals (Recovery Room) | B35: =Zones!B35 -> Floor 1 PACU | C35: =Zones!K35 -> 1 | D35: =Zones!H35 -> 108 | E35: 15 | F35: =VLOOKUP(A35,A$175:E$197,5,FALSE) -> n/a | I35: =VLOOKUP(A35,A$175:H$197,8,FALSE) -> 0.33333333 | J35: =E35*C35 -> 15 | K35: =IF(F35="n/a",D35*I35,F35*D35) -> 36 | L35: =H35*D35 -> 0 | M35: =MAX(J35:L35) -> 36
A36: =Zones!C36 -> Corridor Area | B36: =Zones!B36 -> Floor 1 Pre-Op Hall | C36: =Zones!K36 -> 3 | D36: =Zones!H36 -> 528 | E36: 15 | F36: =VLOOKUP(A36,A$175:E$197,5,FALSE) -> 0.15 | I36: =VLOOKUP(A36,A$175:H$197,8,FALSE) -> 0 | J36: =E36*C36 -> 45 | K36: =IF(F36="n/a",D36*I36,F36*D36) -> 79.2 | L36: =H36*D36 -> 0 | M36: =MAX(J36:L36) -> 79.2
A37: =Zones!C37 -> Healthcare Facility and Hospitals (Patient Room) | B37: =Zones!B37 -> Floor 1 Pre-Op Room 1 | C37: =Zones!K37 -> 1 | D37: =Zones!H37 -> 189 | E37: 15 | F37: =VLOOKUP(A37,A$175:E$197,5,FALSE) -> n/a | I37: =VLOOKUP(A37,A$175:H$197,8,FALSE) -> 0.33333333 | J37: =E37*C37 -> 15 | K37: =IF(F37="n/a",D37*I37,F37*D37) -> 63 | L37: =H37*D37 -> 0 | M37: =MAX(J37:L37) -> 63
A38: =Zones!C38 -> Healthcare Facility and Hospitals (Patient Room) | B38: =Zones!B38 -> Floor 1 Pre-Op Room 2 | C38: =Zones!K38 -> 2 | D38: =Zones!H38 -> 338 | E38: 15 | F38: =VLOOKUP(A38,A$175:E$197,5,FALSE) -> n/a | I38: =VLOOKUP(A38,A$175:H$197,8,FALSE) -> 0.33333333 | J38: =E38*C38 -> 30 | K38: =IF(F38="n/a",D38*I38,F38*D38) -> 112.66667 | L38: =H38*D38 -> 0 | M38: =MAX(J38:L38) -> 112.66667
A39: =Zones!C39 -> Restrooms | B39: =Zones!B39 -> Floor 1 Pre-Op Toilet | C39: =Zones!K39 -> 0 | D39: =Zones!H39 -> 54 | E39: 15 | F39: =VLOOKUP(A11,A$175:E$197,5,FALSE) -> n/a | H39: 50 | I39: =VLOOKUP(A39,A$175:H$197,8,FALSE) -> 0 | J39: =E39*C39 -> 0 | K39: =IF(F39="n/a",D39*I39,F39*D39) -> 0 | L39: =H39 -> 50 | M39: =MAX(J39:L39) -> 50 | N39: Toilet rooms, intermittent exhaust 50 cfm per toilet
A40: =Zones!C40 -> Healthcare Facility and Hospitals (Exam/Treatment Room) | B40: =Zones!B40 -> Floor 1 Procedure Room | C40: =Zones!K40 -> 1 | D40: =Zones!H40 -> 285 | E40: 15 | F40: =VLOOKUP(A40,A$175:E$197,5,FALSE) -> n/a | I40: =VLOOKUP(A40,A$175:H$197,8,FALSE) -> 0.33333333 | J40: =E40*C40 -> 15 | K40: =IF(F40="n/a",D40*I40,F40*D40) -> 95 | L40: =H40*D40 -> 0 | M40: =MAX(J40:L40) -> 95
...

Sheet Water Heater
A1: ="Water Heater - "&Prototype!A2 -> Water Heater - Outpatient
A2: Vintage | B2: WH Type | C2: Efficiency | D2: Number of WH | E2: Tank Volume (gal) | F2: Tank Loss | G2: Source
A3: Existing | B3: Gas | C3: 0.8 | D3: 1 | E3: See table below for CZ-specific values: Climate Zone Water Heater Sizing and Loss Coefficients, Storage Volume column (col F) | F3: See table below: Climate Zone Water Heater Sizing and Loss Coefficients, Standby Loss column (col G) | G3: See table below for sources: Climate Zone Water Heater Sizing and Loss Coefficients
A4: New Construction | B4: Gas | C4: 0.8 | D4: 1 | E4: =E3 -> See table below for CZ-specific values: Climate Zone Water Heater Sizing and Loss Coefficients, Storage Volume column (col F) | F4: =F3 -> See table below: Climate Zone Water Heater Sizing and Loss Coefficients, Standby Loss column (col G) | G4: =G3 -> See table below for sources: Climate Zone Water Heater Sizing and Loss Coefficients
A7: Peak Hot Water Consumption
A8: Space Name | B8: Baseline WH Type [CEUS 2022] | C8: Total Area (ft²) | E8: Number of People | F8: Hot Water Usage Specification (gal/hr per person) [T24, 2022, Appendix 5.4A , sheet: "2022 SpaceFuncData-Input"] | G8: Peak Hot Water Usage (gal/hr) | H8: Peak Hot Water Usage (gal/min) | I8: Note
A9: =Zones!B3 -> Floor 1 Anesthesia | B9: Gas | C9: =Zones!H3 -> 108 | E9: =Zones!K3 -> 1 | F9: =VLOOKUP(Zones!C3,'Water Heater'!$A$205:$B$226, 2, FALSE) -> 0.24 | G9: =F9*E9 -> 0.24 | H9: =G9/60 -> 0.004 | I9: For space types marked with an asterisk (the ‘*’ symbol), the water‑heater type is listed as electric in Appendix 5.4A, sheet ‘2022 SpaceFuncData‑Input.’ However, we modified the value based on CEUS data, which indicates that gas is the primary fuel type.
A10: =Zones!B4 -> Floor 1 Bio Haz | B10: Gas | C10: =Zones!H4 -> 56 | E10: =Zones!K4 -> 0 | F10: =VLOOKUP(Zones!C4,'Water Heater'!$A$205:$B$226, 2, FALSE) -> 0.24 | G10: =F10*E10 -> 0 | H10: =G10/60 -> 0
A11: =Zones!B5 -> Floor 1 Café | B11: Gas | C11: =Zones!H5 -> 420 | E11: =Zones!K5 -> 14 | F11: =VLOOKUP(Zones!C5,'Water Heater'!$A$205:$B$226, 2, FALSE) -> 0.578 | G11: =F11*E11 -> 8.092 | H11: =G11/60 -> 0.13486667
A12: =Zones!B6 -> Floor 1 Clean | B12: Gas | C12: =Zones!H6 -> 126 | E12: =Zones!K6 -> 1 | F12: =VLOOKUP(Zones!C6,'Water Heater'!$A$205:$B$226, 2, FALSE) -> 0.24 | G12: =F12*E12 -> 0.24 | H12: =G12/60 -> 0.004
A13: =Zones!B7 -> Floor 1 Clean Work | B13: Gas | C13: =Zones!H7 -> 165 | E13: =Zones!K7 -> 1 | F13: =VLOOKUP(Zones!C7,'Water Heater'!$A$205:$B$226, 2, FALSE) -> 0.24 | G13: =F13*E13 -> 0.24 | H13: =G13/60 -> 0.004
A14: =Zones!B8 -> Floor 1 Dictation | B14: Gas | C14: =Zones!H8 -> 126 | E14: =Zones!K8 -> 0.63 | F14: =VLOOKUP(Zones!C8,'Water Heater'!$A$205:$B$226, 2, FALSE) -> 0.18 | G14: =F14*E14 -> 0.1134 | H14: =G14/60 -> 0.00189
A15: =Zones!B9 -> Floor 1 Dressing Room | B15: Gas | C15: =Zones!H9 -> 45 | E15: =Zones!K9 -> 0.225 | F15: =VLOOKUP(Zones!C9,'Water Heater'!$A$205:$B$226, 2, FALSE) -> 0.18 | G15: =F15*E15 -> 0.0405 | H15: =G15/60 -> 0.000675
A16: =Zones!B10 -> Floor 1 Electrical Room | B16: Gas | C16: =Zones!H10 -> 98 | E16: =Zones!K10 -> 0 | F16: =VLOOKUP(Zones!C10,'Water Heater'!$A$205:$B$226, 2, FALSE) -> 0.18 | G16: =F16*E16 -> 0 | H16: =G16/60 -> 0
A17: =Zones!B11 -> Floor 1 Elevator Pump Room | B17: Gas | C17: =Zones!H11 -> 91 | E17: =Zones!K11 -> 0 | F17: =VLOOKUP(Zones!C11,'Water Heater'!$A$205:$B$226, 2, FALSE) -> 0.18 | G17: =F17*E17 -> 0 | H17: =G17/60 -> 0
A18: =Zones!B12 -> Floor 1 Humid | B18: Gas | C18: =Zones!H12 -> 54 | E18: =Zones!K12 -> 0.27 | F18: =VLOOKUP(Zones!C12,'Water Heater'!$A$205:$B$226, 2, FALSE) -> 0.18 | G18: =F18*E18 -> 0.0486 | H18: =G18/60 -> 0.00081
A19: =Zones!B13 -> Floor 1 IT Hall | B19: Gas | C19: =Zones!H13 -> 140 | E19: =Zones!K13 -> 1 | F19: =VLOOKUP(Zones!C13,'Water Heater'!$A$205:$B$226, 2, FALSE) -> 0 | G19: =F19*E19 -> 0 | H19: =G19/60 -> 0
A20: =Zones!B14 -> Floor 1 IT Room | B20: Gas | C20: =Zones!H14 -> 112 | E20: =Zones!K14 -> 0.56 | F20: =VLOOKUP(Zones!C14,'Water Heater'!$A$205:$B$226, 2, FALSE) -> 0.18 | G20: =F20*E20 -> 0.1008 | H20: =G20/60 -> 0.00168
A21: =Zones!B15 -> Floor 1 Lobby | B21: Gas | C21: =Zones!H15 -> 622 | E21: =Zones!K15 -> 21 | F21: =VLOOKUP(Zones!C15,'Water Heater'!$A$205:$B$226, 2, FALSE) -> 0.09 | G21: =F21*E21 -> 1.89 | H21: =G21/60 -> 0.0315
... A123: =Zones!B117 -> NE Stair | B123: Gas | C123: =Zones!H117 -> 168 | E123: =Zones!K117 -> 1 | F123: =VLOOKUP(Zones!C117,'Water Heater'!$A$205:$B$226, 2, FALSE) -> 0 | G123: =F123*E123 -> 0 | H123: =G123/60 -> 0
A124: =Zones!B118 -> NW Elevator | B124: Gas | C124: =Zones!H118 -> 140 | E124: =Zones!K118 -> 0 | F124: 0 | G124: =F124*E124 -> 0 | H124: =G124/60 -> 0
A125: =Zones!B119 -> NW Stair | B125: Gas | C125: =Zones!H119 -> 192 | E125: =Zones!K119 -> 1 | F125: =VLOOKUP(Zones!C119,'Water Heater'!$A$205:$B$226, 2, FALSE) -> 0 | G125: =F125*E125 -> 0 | H125: =G125/60 -> 0
A126: =Zones!B120 -> SW Stair | B126: Gas | C126: =Zones!H120 -> 96 | E126: =Zones!K120 -> 0 | F126: =VLOOKUP(Zones!C120,'Water Heater'!$A$205:$B$226, 2, FALSE) -> 0 | G126: =F126*E126 -> 0 | H126: =G126/60 -> 0
A127: Total | B127: Gas storage | G127: =_xlfn.LET( _xlpm.g,SUMIF($B$9:$B$126,"Gas*",$G$9:$G$126), _xlpm.e,SUMIF($B$9:$B$126,"Electric*",$G$9:$G$126), IF(AND(_xlpm.g>0,_xlpm.e>0),_xlpm.g,IF(_xlpm.g>0,MAX(75,_xlpm.g),0))) -> 75 | I127: Minimum peak hot water usage is 75 gal according to ACM 2025
A128: Total | B128: Electric resistance | G128: =_xlfn.LET( _xlpm.g,SUMIF($B$9:$B$126,"Gas*",$G$9:$G$126), _xlpm.e,SUMIF($B$9:$B$126,"Electric*",$G$9:$G$126), IF(AND(_xlpm.g>0,_xlpm.e>0),_xlpm.e,IF(_xlpm.e>0,MAX(75,_xlpm.e),0))) -> 0
A132: Design supply temperature (°F) | B132: 135 | C132: CEC-400-2022-009-CMF-REV2-AP5.4B
A133: WH system factor | B133: 0.6 | C133: 2025 ACM §5.9.2 Rated Capacity
A134: Water mass conversion (lb/gal) | B134: 8.2877 | C134: 2025 ACM §5.9.2 Rated Capacity
A135: Reheat multiplier | B135: 0.4 | C135: 2025 ACM §5.9.2 Storage Volume
A136: Climate Zone Water Heater Sizing and Loss Coefficients
A137: Climate Zone | B137: Minimum Monthly Mains Temp (°F) [T24 2022 - Appendix 5.4B] | C137: Heat Output (Btu/hr) [ACM, 2025, 5.9.2: Rated capacity section] | E137: WH Capacity (Btu/hr) [ACM, 2025, 5.9.2: Rated capacity section] | F137: Required Energy Input (Btu/hr) | G137: Storage Volume (gal) | H137: Standby Loss [Title 20, §1605.1 Table F-4; Appendix B: Water Heating Calculation Method] | J137: Off/On Cycle Loss Coefficient to Ambient Temp | L137: Source/Note
A138: CZ01 | B138: 47.9 | C138: =$G$127*($B$132-B138)*$B$134 -> 54139.4 | E138: =C138*$B$133 -> 32483.64 | F138: =_xlfn.LET(_xlpm.x,_xlfn.XLOOKUP(E138/$C$3,$A$159:$A$189,$A$159:$A$189,"",1),IF(_xlpm.x="",ROUNDUP(E138/$C$3,0),_xlpm.x)) -> 60000 | G138: =_xlfn.LET(_xlpm.v,MAX(30,$G$127*$B$135),_xlpm.x,_xlfn.XLOOKUP(_xlpm.v,$F$159:$F$177,$F$159:$F$177,"",1),IF(_xlpm.x="",ROUNDUP(_xlpm.v,0),_xlpm.x)) -> 34 | H138: =(F138/800)+110*SQRT(G138) -> 716.40471 | I138: Btu/hr | J138: =H138/70 -> 10.234353 | K138: Btu/h·°F | L138: Required Energy Input: vendor/available catalog size (Market data table). Storage Volume: standard/available catalog tank size (Market data table).
A139: CZ02 | B139: 50.8 | C139: =$G$127*($B$132-B139)*$B$134 -> 52336.825 | E139: =C139*$B$133 -> 31402.095 | F139: =_xlfn.LET(_xlpm.x,_xlfn.XLOOKUP(E139/$C$3,$A$159:$A$189,$A$159:$A$189,"",1),IF(_xlpm.x="",ROUNDUP(E139/$C$3,0),_xlpm.x)) -> 60000 | G139: =_xlfn.LET(_xlpm.v,MAX(30,$G$127*$B$135),_xlpm.x,_xlfn.XLOOKUP(_xlpm.v,$F$159:$F$177,$F$159:$F$177,"",1),IF(_xlpm.x="",ROUNDUP(_xlpm.v,0),_xlpm.x)) -> 34 | H139: =(F139/800)+110*SQRT(G139) -> 716.40471 | I139: Btu/hr | J139: =H139/70 -> 10.234353 | K139: Btu/h·°F
A140: CZ03 | B140: 52.2 | C140: =$G$127*($B$132-B140)*$B$134 -> 51466.617 | E140: =C140*$B$133 -> 30879.97 | F140: =_xlfn.LET(_xlpm.x,_xlfn.XLOOKUP(E140/$C$3,$A$159:$A$189,$A$159:$A$189,"",1),IF(_xlpm.x="",ROUNDUP(E140/$C$3,0),_xlpm.x)) -> 60000 | G140: =_xlfn.LET(_xlpm.v,MAX(30,$G$127*$B$135),_xlpm.x,_xlfn.XLOOKUP(_xlpm.v,$F$159:$F$177,$F$159:$F$177,"",1),IF(_xlpm.x="",ROUNDUP(_xlpm.v,0),_xlpm.x)) -> 34 | H140: =(F140/800)+110*SQRT(G140) -> 716.40471 | I140: Btu/hr | J140: =H140/70 -> 10.234353 | K140: Btu/h·°F
A141: CZ04 | B141: 52.7 | C141: =$G$127*($B$132-B141)*$B$134 -> 51155.828 | E141: =C141*$B$133 -> 30693.497 | F141: =_xlfn.LET(_xlpm.x,_xlfn.XLOOKUP(E141/$C$3,$A$159:$A$189,$A$159:$A$189,"",1),IF(_xlpm.x="",ROUNDUP(E141/$C$3,0),_xlpm.x)) -> 60000 | G141: =_xlfn.LET(_xlpm.v,MAX(30,$G$127*$B$135),_xlpm.x,_xlfn.XLOOKUP(_xlpm.v,$F$159:$F$177,$F$159:$F$177,"",1),IF(_xlpm.x="",ROUNDUP(_xlpm.v,0),_xlpm.x)) -> 34 | H141: =(F141/800)+110*SQRT(G141) -> 716.40471 | I141: Btu/hr | J141: =H141/70 -> 10.234353 | K141: Btu/h·°F
A142: CZ05 | B142: 51.6 | C142: =$G$127*($B$132-B142)*$B$134 -> 51839.563 | E142: =C142*$B$133 -> 31103.738 | F142: =_xlfn.LET(_xlpm.x,_xlfn.XLOOKUP(E142/$C$3,$A$159:$A$189,$A$159:$A$189,"",1),IF(_xlpm.x="",ROUNDUP(E142/$C$3,0),_xlpm.x)) -> 60000 | G142: =_xlfn.LET(_xlpm.v,MAX(30,$G$127*$B$135),_xlpm.x,_xlfn.XLOOKUP(_xlpm.v,$F$159:$F$177,$F$159:$F$177,"",1),IF(_xlpm.x="",ROUNDUP(_xlpm.v,0),_xlpm.x)) -> 34 | H142: =(F142/800)+110*SQRT(G142) -> 716.40471 | I142: Btu/hr | J142: =H142/70 -> 10.234353 | K142: Btu/h·°F
A143: CZ06 | B143: 56.8 | C143: =$G$127*($B$132-B143)*$B$134 -> 48607.36 | E143: =C143*$B$133 -> 29164.416 | F143: =_xlfn.LET(_xlpm.x,_xlfn.XLOOKUP(E143/$C$3,$A$159:$A$189,$A$159:$A$189,"",1),IF(_xlpm.x="",ROUNDUP(E143/$C$3,0),_xlpm.x)) -> 60000 | G143: =_xlfn.LET(_xlpm.v,MAX(30,$G$127*$B$135),_xlpm.x,_xlfn.XLOOKUP(_xlpm.v,$F$159:$F$177,$F$159:$F$177,"",1),IF(_xlpm.x="",ROUNDUP(_xlpm.v,0),_xlpm.x)) -> 34 | H143: =(F143/800)+110*SQRT(G143) -> 716.40471 | I143: Btu/hr | J143: =H143/70 -> 10.234353 | K143: Btu/h·°F
A144: CZ07 | B144: 58.4 | C144: =$G$127*($B$132-B144)*$B$134 -> 47612.836 | E144: =C144*$B$133 -> 28567.702 | F144: =_xlfn.LET(_xlpm.x,_xlfn.XLOOKUP(E144/$C$3,$A$159:$A$189,$A$159:$A$189,"",1),IF(_xlpm.x="",ROUNDUP(E144/$C$3,0),_xlpm.x)) -> 60000 | G144: =_xlfn.LET(_xlpm.v,MAX(30,$G$127*$B$135),_xlpm.x,_xlfn.XLOOKUP(_xlpm.v,$F$159:$F$177,$F$159:$F$177,"",1),IF(_xlpm.x="",ROUNDUP(_xlpm.v,0),_xlpm.x)) -> 34 | H144: =(F144/800)+110*SQRT(G144) -> 716.40471 | I144: Btu/hr | J144: =H144/70 -> 10.234353 | K144: Btu/h·°F
A145: CZ08 | B145: 58.4 | C145: =$G$127*($B$132-B145)*$B$134 -> 47612.836 | E145: =C145*$B$133 -> 28567.702 | F145: =_xlfn.LET(_xlpm.x,_xlfn.XLOOKUP(E145/$C$3,$A$159:$A$189,$A$159:$A$189,"",1),IF(_xlpm.x="",ROUNDUP(E145/$C$3,0),_xlpm.x)) -> 60000 | G145: =_xlfn.LET(_xlpm.v,MAX(30,$G$127*$B$135),_xlpm.x,_xlfn.XLOOKUP(_xlpm.v,$F$159:$F$177,$F$159:$F$177,"",1),IF(_xlpm.x="",ROUNDUP(_xlpm.v,0),_xlpm.x)) -> 34 | H145: =(F145/800)+110*SQRT(G145) -> 716.40471 | I145: Btu/hr | J145: =H145/70 -> 10.234353 | K145: Btu/h·°F
A146: CZ09 | B146: 57.6 | C146: =$G$127*($B$132-B146)*$B$134 -> 48110.098 | E146: =C146*$B$133 -> 28866.059 | F146: =_xlfn.LET(_xlpm.x,_xlfn.XLOOKUP(E146/$C$3,$A$159:$A$189,$A$159:$A$189,"",1),IF(_xlpm.x="",ROUNDUP(E146/$C$3,0),_xlpm.x)) -> 60000 | G146: =_xlfn.LET(_xlpm.v,MAX(30,$G$127*$B$135),_xlpm.x,_xlfn.XLOOKUP(_xlpm.v,$F$159:$F$177,$F$159:$F$177,"",1),IF(_xlpm.x="",ROUNDUP(_xlpm.v,0),_xlpm.x)) -> 34 | H146: =(F146/800)+110*SQRT(G146) -> 716.40471 | I146: Btu/hr | J146: =H146/70 -> 10.234353 | K146: Btu/h·°F
...

Sheet Interior Lights
A1: ="Interior Lighting - "&Prototype!A2 -> Interior Lighting - Outpatient
A2: Space | B2: New Construction | E2: Existing | H2: Notes
