Workbook
Name nonparticipating_forecastzone_scale_factor: #REF!
Name nonparticipating_forecastzone_scale_factor: #REF!
Name nonparticipating_forecastzone_scale_factor: 'Energy Usage'!#REF!
Name Space_Function: Data!$A$2:$A$76

Sheet Notes
A1: Data Sources
A2: Dataset | B2: Dodge 2023
B3: CEUS 2022
B4: CBECS 2018
B5: ComStock 2023
A6: Prototype | B6: CEC prototype (CBECC 2022.3.1) | C6: https://bees.noresco.com/software2022.html
B7: PNNL prototype (90.1-2022) | C7: https://www.energycodes.gov/prototype-building-models#Commercial
B8: DEER prototype (June 2023) | C8: https://github.com/sound-data/DEER-Prototypes-EnergyPlus
A10: Codes | B10: Title 24, part 6, referred to as T24 (1986, 1992, 2001, 2007, 2013, 2016, 2019, 2022, 2025)
B11: ASHRAE 90.1 (2022)
A13: Others | B13: ACM (2013, 2019, 2022, 2025)
B14: Title 24, 2022 - Appendix 5.4A and Appendix 5.4B | C14: https://www.energy.ca.gov/publications/2022/2022-nonresidential-and-multifamily-alternative-calculation-method-reference
B15: 2022 Reduced infiltration CASE report | C15: https://title24stakeholders.com/wp-content/uploads/2020/10/2022-T24-Final-CASE-Report_Reduce-Infiltration.pdf
B16: 2019 Outdoor Lighting CASE Report | C16: https://title24stakeholders.com/wp-content/uploads/2016/10/T24-2019-CASE-Study-Results-Report-Outdoor-Sources_Final_with-Attachments.pdf
B17: PNNL 20405, 2011 | C17: https://www.pnnl.gov/main/publications/external/technical_reports/PNNL-20405.pdf
B18: Air leakage Memo, NORESCO, 2025 | C18: https://2050partners.sharepoint.com/:w:/r/sites/CalBEMCollaborativeEfforts/_layouts/15/Doc.aspx?sourcedoc=%7B3BEF8F74-7FAC-44F2-A70C-D76617660066%7D&file=Infiltration_rate_report_14May2025-Short-Version.docx&action=default&mobileredirect=true
B19: Design Guide: Advanced Water Heating for Foodservice (2022) (by GTI and Frontier funded by SoCalGas and Pacific Gas and Electric Company | C19: https://caenergywise.com/design-guides/hot-water/Technical_Design_Guide.pdf
B20: Design Guide 1: Improving Commercial Kitchen Ventilation System Performance : Selecting & Sizing Exhaust Hoods referred as CKV (2004) (by SCE) | C20: https://www.streivor.com/wp-content/uploads/2020/11/CKV-Design-Guide-1-Selecting-and-Sizing-Exhaust-Hoods.pdf
B21: Proposed Updates to Equipment Power Densities and Building Schedules for the 2028 Energy Code, referred to as "Plug load and schedules project with CEC, 2025" (Docket Number =25-BSTD-03 & TN=265693) | C21: https://efiling.energy.ca.gov/GetDocument.aspx?tn=265693&DocumentContentId=102545
A22: Water Heater | B22: ENERGY STAR certified commercial water heaters (gas storage input ≥76 kBtu/h; ES tank sizes) | C22: =HYPERLINK("https://www.energystar.gov/productfinder/product/certified-commercial-water-heaters/results?fuel_filter=Gas&markets_filter=United+States","ENERGY STAR product finder — gas") -> ENERGY STAR product finder — gas
B23: ENERGY STAR commercial WH dataset (download) | C23: =HYPERLINK("https://data.energystar.gov/Active-Specifications/ENERGY-STAR-Certified-Commercial-Water-Heaters/xmq6-bm79","ENERGY STAR dataset xmq6-bm79") -> ENERGY STAR dataset xmq6-bm79
B24: ENERGY STAR commercial WH eligibility (gas storage >75 kBtu/h) | C24: =HYPERLINK("https://www.energystar.gov/products/water_heaters/commercial_water_heaters/key_product_criteria","ENERGY STAR key product criteria") -> ENERGY STAR key product criteria
B25: Grainger gas tank water heaters (sizes below ES commercial, e.g. 30–75 kBtu/h) | C25: =HYPERLINK("https://www.grainger.com/category/plumbing/water-heaters/gas-tank-water-heaters","Grainger — gas tank WH") -> Grainger — gas tank WH
B26: Grainger electric tank water heaters (kW ladder, tank gallons) | C26: =HYPERLINK("https://www.grainger.com/category/plumbing/water-heaters/electric-tank-water-heaters","Grainger — electric tank WH") -> Grainger — electric tank WH
B27: ES commercial electric = heat pumps only; not used for resistance tank list | C27: =HYPERLINK("https://www.energystar.gov/productfinder/product/certified-commercial-water-heaters/results?fuel_filter=Electric&markets_filter=United+States","ENERGY STAR — electric (HPWH)") -> ENERGY STAR — electric (HPWH)
A36: Notes
A40: EIS, 2018: | B40: U.S. Energy Information Administration - EIA - Independent Statistics and Analysis
A71: Dodge Construction data , 2023

Sheet Prototype
A1: NORESCO, Updated September 2026
A2: RestaurantSitDown
A3: Characteristic | B3: Value | C3: Data Sources
A4: Building Type | B4: Sit Down Restaurant
A5: Building Category | B5: Nonresidential
A6: Vintages | B6: 4 Vintages: Pre-1978 , 1978-1997 ,1998-2007 , 2008-2018 New Construction (2019+) | C6: Based on the vintage bin analysis. A summary of the findings is presented in the following paper, with a link provided in the Notes tab: Yousefi, F., Athalye, R. (2025). “Determining Vintage Bins for Prototype Development: An Analysis of California Commercial Buildings.” ASHRAE Annual Conference.
A7: Shape | C7: PNNL prototype, 2022
A8: Total Floor Area (ft²) | B8: 5,502.1 (74.18 ft * 74.18 ft) | C8: PNNL prototype, 2022
A9: Aspect Ratio | B9: 1 | C9: PNNL prototype, 2022
A10: Number of Floors | B10: 1 | C10: PNNL prototype, 2022
A11: Roof type | B11: Attic (17°) | C11: PNNL prototype, 2022, suppoerted by CBECS 2018
A12: WWR | B12: Average 17.11% (South: 28% , East: 20.22% ,North: 0% ,West: 20.22% | C12: PNNL prototype, 2022
A13: Shading Geometry | B13: No shades | C13: PNNL prototype, 2021
A14: Floor to floor height (ft) | B14: N/A | C14: PNNL prototype, 2022
A15: Floor to ceiling height (ft) | B15: 10 | C15: PNNL prototype, 2022
A16: Glazing sill height (ft) | B16: 3.5 (top of the window is 6.5 ft high with 3 ft high glass) | C16: PNNL prototype, 2022
A22: Background Data [To be deleted prior to publication]
A24: Kitchen height: 10 ft
A25: https://www.naksinc.com/ceiling-height-and-cooking-equipment-specifications-for-hoods-an-in-depth-look/
A27: Existing public prototypes
C28: PNNL (Sit down) | D28: CPUC (Sit down) | F28: CEC (Small Restaurant)
A29: Geometry | B29: Whole building
A30: Floor area (ft²) | B30: Total | C30: 5502 | D30: 5602 | F30: 2500
A31: Height (ft) | B31: All | C31: 10 | D31: 10 | F31: 10
A32: Zones | C32: Dining 73% (4001.46 ft2), Kitchen 27% (1500.54 ft2), Attic (NOT conditioned) | D32: Dining 54% , Kitchen 29% , Waiting Area 14% , Restroom 4% (200 sf) | F32: Dining 50% , Kitchen 50%, Attic (NOT conditioned)
A33: Internal Load
A34: People (person/ft²) | B34: Dining | C34: 0.07 | D34: 0.033 | F34: 0.033
B35: Kitchen | C35: 0.005 (7.5 People) | D35: 0.0025 | F35: 0.0025
B36: Other zones (if any) | D36: 0.0033 Lobby & 0.005 Restroom | F36: -
A37: Lights (W/ft²) | B37: Dining | C37: 0.48 | D37: 0.4 | F37: 0.45
B38: Kitchen | C38: 0.78 | D38: 0.95 | F38: 0.95
B39: Other zones (if any) | D39: 0.7 Lobby & 0.65 Restroom
A40: Ext lights (W) | C40: 1509 (204 and 1305) | F40: -
A41: Gas Equipment (Btu/h-ft2) | B41: Kitchen | C41: 194.7 (292,164 Btu/h) | D41: 17.5 | F41: 32.4
A42: Electric Equipment (W/ft²) | B42: Dining | C42: 5.7 (22833 W) | D42: 0.5 | F42: 0.75 (0.5 receptacle & 0.25 refrigerator )
B43: Kitchen | C43: 35.91 (53,277 W Receptacle & 313 W ReachIn Refrigerator & 277 W ReachInFreezer) | D43: 2.62 (1.5 receptacle & 1.12 refrigerator) | F43: 2.62 (1.5 receptacle & 1.12 refrigerator)
B44: Other zones (if any) | D44: 0.5 Lobby
A46: Refrigerator | B46: Kitchen | C46: In addition to the Reachin freezer and refrigerator load defined as electric load, it has : 2 Case refrigerator : 716 and 763 Btu/hr-ft for 8 and 10 ft cases 2.5 COP for design compressor rack 1126 Btu/h for fan power of design compressor | D46: Refrigerator loads are defined as electric equipment load for kitchen | F46: Two Refrigerator loads are defined as electric equipment load for dining and kitchen
A48: Heating Sizing Factor | C48: H&C: 1.2 | D48: H: 2.5 , C: 2.3 | F48: H&C:1
A49: HVAC | B49: Dining | C49: PSZ AC: CAV no reheat, DX cooling coil: multi speed, Gas heating coil | D49: Single Zone VAV Reheat (Sys7)+ 1 DX cooling coil:multi speed + 1 water heating coil (+ 1 water heating coil for Reheat) Boiler (2 objects) | F49: (BaseAirSys 13): VAV no Reheat +DX cooling coil:two speed, Gas Heating coil
...

Sheet Zones
A1: ="Proposed Layout - "&Prototype!A2 -> Proposed Layout - RestaurantSitDown
A2: Building | B2: Space/Thermal Zone | C2: Space Type [Primarily from: T24, 2022 Appendix 5.4A] - See Notes column | D2: HVAC Zone | E2: Schedule Category | F2: Conditioned (Y/N) | G2: Area Fraction | H2: Area (ft²) | I2: Volume (ft³) | J2: Multipliers | K2: Number of People | L2: People (Persons/1,000 ft²) [T24, 2025,Table 120.1-A] | M2: Notes | O2: Kitchen (North) , Dining (south)
A3: RestaurantSitDown | B3: Dining | C3: Dining Area (Bar/Lounge and Fine Dining) | D3: AHU_1 | E3: Restaurant | F3: Y | G3: =H3/$H$6 -> 0.7272724 | H3: 4001.46 | I3: =H3*Prototype!$B$15 -> 40014.6 | J3: 1 | K3: =L3*H3/1000 -> 132.04818 | L3: 33
A4: RestaurantSitDown | B4: Kitchen | C4: Kitchen/Food Preparation Area | D4: AHU_2 | E4: Kitchen | F4: Y | G4: =H4/$H$6 -> 0.2727276 | H4: 1500.55 | I4: =H4*Prototype!$B$15 -> 15005.5 | J4: 1 | K4: =L4*H4/1000 -> 4.50165 | L4: 3
A5: RestaurantSitDown | B5: Attic | C5: Attic | D5: n/a | F5: N | H5: =H6 -> 5502.01 | I5: =H5*Prototype!$B$15 -> 55020.1 | J5: 1 | K5: =L5*H5/1000 -> 0
A6: Total (1 Building) | B6: Total (3 Space) | C6: Total (3 space type) | D6: Total ( 2 HVAC Zones) | E6: Total (2 category) | F6: Total (2 Conditioned zones) | G6: =SUM(G3:G4) -> 1 | H6: =SUM(H3:H4) -> 5502.01 | I6: =SUM(I3:I4) -> 55020.1
A19: Background Data [To be deleted prior to publication]

Sheet Envelope
A1: ="Envelope - "&Prototype!A2 -> Envelope - RestaurantSitDown
A2: Element | B2: Prototype | C2: Assembly Type | D2: Construction | E2: Thermal properties | F2: Vintage | G2: Selected T24 | H2: Notes | I2: CZ1 | J2: CZ2 | K2: CZ3 | L2: CZ4 | M2: CZ5 | N2: CZ6 | O2: CZ7 | P2: CZ8 | Q2: CZ9 | R2: CZ10 | S2: CZ11 | T2: CZ12 | U2: CZ13 | V2: CZ14 | W2: CZ15 | X2: CZ16
A3: External Wall | B3: =Prototype!A2 -> RestaurantSitDown | C3: ExtWall_MetalFramed_NonRes | D3: Metal framed wall: stucco + insulation + Metal frame + gypsum board | E3: U-factor IP | F3: Pre 1978 | G3: N/A | H3: Using DOE pre-1980 U-values and a 9.6% cumulative wall renovation rate through 2028, based on the average annual rate from CBECS 2003 and 2012 projected over 48 years. | I3: =I46*(1-$I$47)+I45*$I$47 -> 0.214616 | J3: =J46*(1-$I$47)+J45*$I$47 -> 0.21116 | K3: =K46*(1-$I$47)+K45*$I$47 -> 0.21308 | L3: =L46*(1-$I$47)+L45*$I$47 -> 0.21116 | M3: =M46*(1-$I$47)+M45*$I$47 -> 0.21116 | N3: =N46*(1-$I$47)+N45*$I$47 -> 0.214616 | O3: =O46*(1-$I$47)+O45*$I$47 -> 0.214616 | P3: =P46*(1-$I$47)+P45*$I$47 -> 0.21116 | ... X3: =X46*(1-$I$47)+X45*$I$47 -> 0.21116
F4: 1978-1997 | G4: 1986 | H4: Copied from low-rise office alternative table: Package A with heat capacity of 0.0-3.99 (Btu/F-ft²) | I4: =1/7.52 -> 0.13297872 | J4: =1/7.52 -> 0.13297872 | K4: =1/7.52 -> 0.13297872 | L4: =1/7.52 -> 0.13297872 | M4: =1/7.52 -> 0.13297872 | N4: =1/7.52 -> 0.13297872 | O4: =1/7.52 -> 0.13297872 | P4: =1/7.52 -> 0.13297872 | ... X4: =1/7.52 -> 0.13297872 | Y4: These values have better performance than the next vintage
F5: 1998-2007 | G5: 2001 | H5: Table 1-H | I5: 0.182 | J5: 0.182 | K5: 0.189 | L5: 0.189 | M5: 0.189 | N5: 0.189 | O5: 0.189 | P5: 0.189 | Q5: 0.189 | R5: 0.182 | S5: 0.182 | T5: 0.182 | U5: 0.182 | V5: 0.182 | W5: 0.182 | X5: 0.182
F6: 2008-2018 | G6: 2013 | H6: Table 140.3-B | I6: 0.098 | J6: 0.062 | K6: 0.082 | L6: 0.062 | M6: 0.062 | N6: 0.098 | O6: 0.098 | P6: 0.062 | Q6: 0.062 | R6: 0.062 | S6: 0.062 | T6: 0.062 | U6: 0.062 | V6: 0.062 | W6: 0.062 | X6: 0.062
F7: Existing | H7: Weighted average of all 4 vintages | I7: {=_xlfn.BYCOL(TRANSPOSE(Weights!$C$4:$F$19)*I3:X6,_xlfn.LAMBDA(_xlpm.c,SUM(_xlpm.c)))} -> 0.16715337 | J7: 0.17496963 | K7: 0.17799138 | L7: 0.17633584 | M7: 0.17326673 | N7: 0.17697511 | O7: 0.16862306 | P7: 0.17804854 | Q7: 0.17652484 | R7: 0.15371017 | S7: 0.16443894 | T7: 0.16138386 | U7: 0.15573984 | V7: 0.16324872 | W7: 0.1479374 | X7: 0.15482115
F8: 2019+ | G8: 2025 | H8: Table 140.3-B | I8: 0.06 | J8: 0.055 | K8: 0.071 | L8: 0.055 | M8: 0.055 | N8: 0.06 | O8: 0.06 | P8: 0.055 | Q8: 0.055 | R8: 0.055 | S8: 0.055 | T8: 0.055 | U8: 0.055 | V8: 0.055 | W8: 0.055 | X8: 0.055
A9: Ceiling/Roof | B9: =B3 -> RestaurantSitDown | C9: AtticFloor Reversed | D9: Attic roof (no insulation): asphalt shingles + gypsum board Ceiling (wood-joist): insulation + gypsum board | E9: U-factor IP | F9: Pre 1978 | G9: N/A | H9: Considering 30 years for roof/ insulation replacement. | I9: =I10 -> 0.057 | J9: =J10 -> 0.057 | K9: =K10 -> 0.057 | L9: =L10 -> 0.057 | M9: =M10 -> 0.057 | N9: =N10 -> 0.078 | O9: =O10 -> 0.078 | P9: =P10 -> 0.078 | ... X9: =X10 -> 0.057
F10: 1978-1997 | G10: 1992 | I10: 0.057 | J10: 0.057 | K10: 0.057 | L10: 0.057 | M10: 0.057 | N10: 0.078 | O10: 0.078 | P10: 0.078 | Q10: 0.078 | R10: 0.078 | S10: 0.057 | T10: 0.057 | U10: 0.057 | V10: 0.057 | W10: 0.057 | X10: 0.057
F11: 1998-2007 | G11: 2001 | H11: Table 1-H | I11: 0.057 | J11: 0.057 | K11: 0.057 | L11: 0.057 | M11: 0.057 | N11: 0.078 | O11: 0.078 | P11: 0.078 | Q11: 0.078 | R11: 0.057 | S11: 0.057 | T11: 0.057 | U11: 0.057 | V11: 0.057 | W11: 0.057 | X11: 0.057
F12: 2008-2018 | G12: 2013 | H12: Table 140.3-B (Wood Framed and Other) | I12: 0.049 | J12: 0.039 | K12: 0.039 | L12: 0.039 | M12: 0.049 | N12: 0.075 | O12: 0.067 | P12: 0.067 | Q12: 0.039 | R12: 0.039 | S12: 0.039 | T12: 0.039 | U12: 0.039 | V12: 0.039 | W12: 0.039 | X12: 0.039
F13: Existing | H13: Weighted average of all 4 vintages | I13: {=_xlfn.BYCOL(TRANSPOSE(Weights!$C$4:$F$19)*I9:X12,_xlfn.LAMBDA(_xlpm.c,SUM(_xlpm.c)))} -> 0.056060016 | J13: 0.055949258 | K13: 0.056015102 | L13: 0.056040492 | M13: 0.056520509 | N13: 0.077877529 | O13: 0.077327822 | P13: 0.077469898 | Q13: 0.07669515 | R13: 0.070944626 | S13: 0.055087237 | T13: 0.054985008 | U13: 0.054399403 | V13: 0.05561858 | W13: 0.055108357 | X13: 0.055066422
F14: 2019+ | G14: 2025 | H14: Table 140.3-B (Wood Framed and Other) | I14: 0.028 | J14: 0.028 | K14: 0.028 | L14: 0.028 | M14: 0.028 | N14: 0.047 | O14: 0.047 | P14: 0.047 | Q14: 0.028 | R14: 0.028 | S14: 0.028 | T14: 0.028 | U14: 0.028 | V14: 0.028 | W14: 0.028 | X14: 0.028
A15: Windows | B15: =B3 -> RestaurantSitDown | C15: FixedWindow_NonRes | D15: Single Pane (CBECS 2018, ~ 30 % of windows of Restaurant built before 2000 are single pane) | E15: U-factor IP | F15: Pre 1978 | G15: N/A | H15: 2021 ASHRAE Handbook of Fundamentals for single pane (Table 4- Ch15, Section 15.9) & T24, 2013 Table 140.3-B for double pane (30%-70%) | I15: =0.3*1.12+0.7*I18 -> 0.588 | J15: =0.3*1.12+0.7*J18 -> 0.588 | K15: =0.3*1.12+0.7*K18 -> 0.588 | L15: =0.3*1.12+0.7*L18 -> 0.588 | M15: =0.3*1.12+0.7*M18 -> 0.588 | N15: =0.3*1.12+0.7*N18 -> 0.588 | O15: =0.3*1.12+0.7*O18 -> 0.588 | P15: =0.3*1.12+0.7*P18 -> 0.588 | ... X15: =0.3*1.12+0.7*X18 -> 0.588
F16: 1978-1997 | G16: N/A | I16: =I15 -> 0.588 | J16: =J15 -> 0.588 | K16: =K15 -> 0.588 | L16: =L15 -> 0.588 | M16: =M15 -> 0.588 | N16: =N15 -> 0.588 | O16: =O15 -> 0.588 | P16: =P15 -> 0.588 | ... X16: =X15 -> 0.588 | Y16: These vintages have better performance because of partial retrofit
D17: Double pane | F17: 1998-2007 | G17: 2001 | H17: Table 1-H | I17: 0.49 | J17: 0.49 | K17: 0.81 | L17: 0.81 | M17: 0.81 | N17: 0.81 | O17: 0.81 | P17: 0.81 | Q17: 0.81 | R17: 0.49 | S17: 0.49 | T17: 0.49 | U17: 0.49 | V17: 0.49 | W17: 0.49 | X17: 0.49
F18: 2008-2018 | G18: 2013 | H18: Table 140.3-B | I18: 0.36 | J18: 0.36 | K18: 0.36 | L18: 0.36 | M18: 0.36 | N18: 0.36 | O18: 0.36 | P18: 0.36 | Q18: 0.36 | R18: 0.36 | S18: 0.36 | T18: 0.36 | U18: 0.36 | V18: 0.36 | W18: 0.36 | X18: 0.36
F19: Existing | H19: Weighted average of all 4 vintages | I19: {=_xlfn.BYCOL(TRANSPOSE(Weights!$C$4:$F$19)*I15:X18,_xlfn.LAMBDA(_xlpm.c,SUM(_xlpm.c)))} -> 0.54628941 | J19: 0.56629336 | K19: 0.60430606 | L19: 0.60309789 | M19: 0.61557117 | N19: 0.59541892 | O19: 0.59565955 | P19: 0.59562945 | Q19: 0.59545346 | R19: 0.5509934 | S19: 0.54445557 | T19: 0.54296586 | U19: 0.53769166 | V19: 0.55498636 | W19: 0.54751823 | X19: 0.54394227
F20: 2019+ | G20: 2025 | H20: Table 140.3-B | I20: 0.36 | J20: 0.36 | K20: 0.36 | L20: 0.36 | M20: 0.36 | N20: 0.36 | O20: 0.36 | P20: 0.36 | Q20: 0.34 | R20: 0.36 | S20: 0.34 | T20: 0.34 | U20: 0.34 | V20: 0.34 | W20: 0.34 | X20: 0.36
D21: Single Pane (CBECS 2018, ~ 30 % of windows of Restaurant built before 2000 are single pane) | E21: SHGC | F21: Pre 1978 | G21: N/A | H21: 2021 ASHRAE Handbook of Fundamentals for single pane (Table 10- Ch15, Section 15.22) & T24, 2013 Table 140.3-B for double pane (30%-70%) | I21: =0.79*0.3+I24*0.7 -> 0.412 | J21: =0.79*0.3+J24*0.7 -> 0.412 | K21: =0.79*0.3+K24*0.7 -> 0.412 | L21: =0.79*0.3+L24*0.7 -> 0.412 | M21: =0.79*0.3+M24*0.7 -> 0.412 | N21: =0.79*0.3+N24*0.7 -> 0.412 | O21: =0.79*0.3+O24*0.7 -> 0.412 | P21: =0.79*0.3+P24*0.7 -> 0.412 | ... X21: =0.79*0.3+X24*0.7 -> 0.412
F22: 1978-1997 | G22: N/A | I22: =I21 -> 0.412 | J22: =J21 -> 0.412 | K22: =K21 -> 0.412 | L22: =L21 -> 0.412 | M22: =M21 -> 0.412 | N22: =N21 -> 0.412 | O22: =O21 -> 0.412 | P22: =P21 -> 0.412 | ... X22: =X21 -> 0.412 | Y22: These vintages have better performance because of partial retrofit
D23: Double pane | F23: 1998-2007 | G23: 2001 | H23: Table 1-H (Non North, 10-20% total WWR) | I23: 0.43 | J23: 0.36 | K23: 0.55 | L23: 0.55 | M23: 0.55 | N23: 0.61 | O23: 0.61 | P23: 0.61 | Q23: 0.61 | R23: 0.36 | S23: 0.36 | T23: 0.36 | U23: 0.36 | V23: 0.36 | W23: 0.36 | X23: 0.43
F24: 2008-2018 | G24: 2013 | H24: Table 140.3-B | I24: 0.25 | J24: 0.25 | K24: 0.25 | L24: 0.25 | M24: 0.25 | N24: 0.25 | O24: 0.25 | P24: 0.25 | Q24: 0.25 | R24: 0.25 | S24: 0.25 | T24: 0.25 | U24: 0.25 | V24: 0.25 | W24: 0.25 | X24: 0.25
F25: Existing | H25: Weighted average of all 4 vintages | I25: {=_xlfn.BYCOL(TRANSPOSE(Weights!$C$4:$F$19)*I21:X24,_xlfn.LAMBDA(_xlpm.c,SUM(_xlpm.c)))} -> 0.39570592 | J25: 0.39808764 | K25: 0.42102708 | L25: 0.42030465 | M25: 0.4279239 | N25: 0.42030508 | O25: 0.42135835 | P25: 0.42079739 | Q25: 0.4200312 | R25: 0.38872416 | S25: 0.38453577 | T25: 0.38351235 | U25: 0.37937925 | V25: 0.39133442 | W25: 0.38620899 | X25: 0.39819151
F26: 2019+ | G26: 2025 | H26: Table 140.3-B | I26: 0.25 | J26: 0.25 | K26: 0.25 | L26: 0.25 | M26: 0.25 | N26: 0.25 | O26: 0.25 | P26: 0.25 | Q26: 0.22 | R26: 0.25 | S26: 0.22 | T26: 0.22 | U26: 0.22 | V26: 0.22 | W26: 0.22 | X26: 0.25
C28: Infiltration
D29: Building | E29: Zones | F29: Vintage | G29: I_75 (cfm/ft2) 6-sdied Infiltration rate @ 75 pa | H29: Source | I29: I-design (cfm/ft²) (4-sided Infiltration rate at normal pressure) (Design flow rate approach and Flow/Exterior Wall Area calculation method)
C30: Infiltration | D30: RestaurantSitDown | F30: Pre 1978 | G30: 1.1 | H30: 2022 CASE report (Table 38) | I30: =0.112*G30*$F$41 -> 0.580272
F31: 1978-1997 | G31: 1.1 | H31: 2022 CASE report (Table 38) | I31: =0.112*G31*$F$41 -> 0.580272
F32: 1998-2007 | G32: 1.1 | H32: 2022 CASE report (Table 38) | I32: =0.112*G32*$F$41 -> 0.580272
F33: 2008-2018 | G33: 1 | H33: 2022 CASE report (Table 38) & T24, 2008-2016 (Table 140.3-B) | I33: =0.112*G33*$F$41 -> 0.52752
F34: Existing | H34: Same as Pre 2008 because of their higher weights | I34: =I32 -> 0.580272
F35: 2019+ | G35: 0.6 | H35: 2022 CASE report (Table 38) & T24, 2025 (Table 140.3-B) | I35: =0.112*G35*$F$41 -> 0.316512
E36: Source: T24 air barrier requirements (all editions) , the standardized infiltration rate reported in the 2022 CASE report, and Dodge 2023 data
E37: Infiltration_rate_report_14May2025-Short-Version.docx
E39: 6 sided area | F39: =(74.2*4)*10+(74.2^2)*2 -> 13979.28
E40: 4 sided area | F40: =(74.2*4)*10 -> 2968
E41: 6 sided/4sided fraction | F41: =F39/F40 -> 4.71
A43: Pre-1978 exterior wall U value calculation
...

Sheet HVAC System
A1: ="HVAC system - "&Prototype!A2 -> HVAC system - RestaurantSitDown
A2: Vintage | B2: Space/Thermal Zone | C2: Heating | D2: Cooling | E2: Air Distribution | F2: Other Systems | G2: Source
A3: Existing | B3: Dining | C3: Gas Furnace (PSZAC) | D3: DX Coil (PSZAC) | E3: CAV (PSZAC) | F3: Economizer for after 2008 | G3: CEUS 2022 + Engineering Judgement
B4: Kitchen | C4: Gas Furnace (PSZAC) | D4: DX Coil (PSZAC) | E4: CAV (PSZAC) | F4: Makeup Air Unit (Combo with RTU) to supply make-up air exceeding transfer air from dining space (can be included in system13b)
A5: New Construction | B5: Dining | C5: Gas Furnace (PSZAC) | D5: DX Coil (PSZAC) | E5: CAV (PSZAC) | F5: Economizer | G5: T24, 2025
B6: Kitchen | C6: Gas Furnace (PSZAC) | D6: DX Coil (PSZAC) | E6: CAV (PSZAC) | F6: HR-Makeup Air Unit (systems that integrate make-up air and heat recovery functions) (can be included in system13b)
A7: *CPUC considers Boiler in the Dining space for heating
A11: Efficiency of HVAC system (Efficiency is capacity-dependent. The following table provides a general estimate of system efficiency based on preliminary simulations in one climate zone, or assuming cooling load based on rule of thumb)
A12: Vintage | B12: Upgrade/Installed year | C12: Gas Furnace | D12: Dining DX cooling (>=65,000 and < 135,000 Btu/h ) | E12: Kitchen DX cooling (>=65,000 and < 135,000 Btu/h ) | F12: Source | G12: Note
A13: Pre 1978 | B13: 2008 | C13: Efficiency 80% | D13: EER 10.3 | E13: EER 10.3 | F13: T24, 2008, Table 112-A | G13: Econ Max Position=0.9. *Econ Max Position is set to below 1 to approximate effects of not having fault detection and diagnostics (FDD) requirements, which began in 2013. It can be modeled in E+ either by: - Reducing Maximum Outdoor Air Flow Rate in Controller:OutdoorAir. - Or using FaultModel objects to simulate pre-2013 “no FDD” conditions
A14: 1978-1997
A15: 1998-2007
A16: 2008-2018 | B16: 2013 | C16: Efficiency 80% | D16: EER 11.2 | E16: EER 11.2 | F16: T24, 2013, Table 110.2-A | G16: Econ Max Position=0.9
A17: New Construction | B17: 2025 | C17: Efficiency 80% | D17: EER 11.2 | E17: EER 11.2 | F17: T24, 2025, Table 110.2-A | G17: - Econ Max Position=1 - Deduct 0.2 from the required EERs and IEERs for units with a heating section other than electric resistance heat.
A21: Fan Power
A22: Vintage | B22: Approach | C22: System | D22: Total Static Pressure (TSP) (in w.c.) | E22: Fan Efficiency [ACM 2025] | F22: Motor Efficiency | G22: Fan Power Index (W/cfm) | H22: Data Source
A23: Existing | B23: PNNL TSP | C23: CAV Kitchen (system <7,437 cfm) | D23: 2.5 | E23: 0.65 | F23: ASHRAE 90.1, 2004, Table 10.8 * | H23: Fan power formula: PNNL 20405, 2010, section 5.2.2.5 TSP and fan efficiency: PNNL 20405, 2010, Table 5.11, 90.1-04ac values Motor and drive efficiency: ASHRAE 90.1, 2004, Table 10.8
C24: CAV Dining (system <7,437 cfm) CAV Dining (system >7,437 cfm) | D24: 2.5 (system <7,437 cfm) 4.46 (system >7,437 cfm) | E24: 0.65
A25: Brake horsepower (bhp) = (Supply cfm × TSP in w.c.) / (6356 × fan efficiency)
A26: Fan power (w/cfm) = (bhp × 746) / ( supply cfm × motor efficiency )
A27: New Construction | B27: ACM 2025 | C27: PSZAC (system 13b), CAV kitchen, ≤5,000 cfm | D27: TSP = fan power × motor efficiency × fan efficiency × 6356 / 746 | E27: 0.65 | F27: 2025 ACM Table 12 ** | G27: 0.614 | H27: Fan power index: [ACM 2025, Table 13] Motor efficiency: [ACM 2025, Table 12]
C28: PSZAC (System 13b), CAV Kitchen, >5,000 and <=10,000 cfm | D28: TSP = fan power × motor efficiency × fan efficiency × 6356 / 747 | G28: 0.596
C29: PSZAC (System 3a), CAV dining, ≤5,000 cfm | D29: TSP = fan power × motor efficiency × fan efficiency × 6356 / 746 | G29: 0.8
C30: PSZAC (System 3a), CAV dining, >5,000 and <=10,000 cfm | D30: TSP = fan power × motor efficiency × fan efficiency × 6356 / 746 | G30: 0.78
A32: * According to PNNL 20405 section 5.2.2.5, the full-load efficiency of the motor serving the fan is taken from ASHRAE 90.1, 2004, Table 10.8, based on motor nameplate and assuming enclosed motors operating at 1,800 rotations per minute (rpm) Motor nameplate size (bhp) = brake horsepower (bhp) × 1.1 ( using a 10% oversizing factor)
A33: ** The full‑load efficiency of the motor serving the fan is taken from ACM 2025 Table 12 based on the motor nameplate horsepower. Brake horsepower (bhp) = (Supply cfm from sizing run × fan power in W/cfm) / 746. Note: PSZAC with gas furnace (System 3a SZAC) ≤5,000 cfm. Same index as Restaurant Sit-Down kitchen. Dining fans above 5,000 cfm and at or below 10,000 cfm use 0.780 W/cfm.

Sheet Thermostat
A1: ="Thermostat Setpoints - "&Prototype!A2 -> Thermostat Setpoints - RestaurantSitDown
A2: Space/Thermal Zone | B2: Setpoint | C2: CZ1 | D2: CZ2 | E2: CZ3 | F2: CZ4 | G2: CZ5 | H2: CZ6 | I2: CZ7 | J2: CZ8 | K2: CZ9 | L2: CZ10 | M2: CZ11 | N2: CZ12 | O2: CZ13 | P2: CZ14 | Q2: CZ15 | R2: CZ16 | S2: Source
A3: Dining | B3: Heating Setpoint (F) | C3: 70 | D3: 70 | E3: 70 | F3: 70 | G3: 70 | H3: 70 | I3: 70 | J3: 70 | K3: 70 | L3: 70 | M3: 70 | N3: 70 | O3: 70 | P3: 70 | Q3: 70 | R3: 70 | S3: T24 2022 - Appendix 5.4B
B4: Heating Setback (F) | C4: 60 | D4: 60 | E4: 60 | F4: 60 | G4: 60 | H4: 60 | I4: 60 | J4: 60 | K4: 60 | L4: 60 | M4: 60 | N4: 60 | O4: 60 | P4: 60 | Q4: 60 | R4: 60
B5: Cooling Setpoint (F) | C5: 75 | D5: 75 | E5: 75 | F5: 75 | G5: 75 | H5: 75 | I5: 75 | J5: 75 | K5: 75 | L5: 75 | M5: 75 | N5: 75 | O5: 75 | P5: 75 | Q5: 75 | R5: 75
B6: Cooling Setback (F) | C6: 85 | D6: 85 | E6: 85 | F6: 85 | G6: 85 | H6: 85 | I6: 85 | J6: 85 | K6: 85 | L6: 85 | M6: 85 | N6: 85 | O6: 85 | P6: 85 | Q6: 85 | R6: 85
A7: Kitchen | B7: Heating Setpoint (F) | C7: 66 | D7: 66 | E7: 66 | F7: 66 | G7: 66 | H7: 66 | I7: 66 | J7: 66 | K7: 66 | L7: 66 | M7: 66 | N7: 66 | O7: 66 | P7: 66 | Q7: 66 | R7: 66 | S7: PNNL 09.1, 2022 Restaurant prototype
B8: Heating Setback (F) | C8: 60 | D8: 60 | E8: 60 | F8: 60 | G8: 60 | H8: 60 | I8: 60 | J8: 60 | K8: 60 | L8: 60 | M8: 60 | N8: 60 | O8: 60 | P8: 60 | Q8: 60 | R8: 60
B9: Cooling Setpoint (F) | C9: 79 | D9: 79 | E9: 79 | F9: 79 | G9: 79 | H9: 79 | I9: 79 | J9: 79 | K9: 79 | L9: 79 | M9: 79 | N9: 79 | O9: 79 | P9: 79 | Q9: 79 | R9: 79
B10: Cooling Setback (F) | C10: 86 | D10: 86 | E10: 86 | F10: 86 | G10: 86 | H10: 86 | I10: 86 | J10: 86 | K10: 86 | L10: 86 | M10: 86 | N10: 86 | O10: 86 | P10: 86 | Q10: 86 | R10: 86
A12: PNNL's comfort range in kitchen is 4 F wider : 66 -79 F (with Heating setback of 60 F and Cooling setback of 86 F)
A13: PNNL comfort range in Dining is 70 -75 F (with Heating setback of 60 F and Cooling setback of 86 F)
A15: CPUC comfort range is 70 -75 F (with Heating setback of 60 F and Cooling setback of 85 F)

Sheet Ventilation
A1: ="Outdoor Airflow Rate - "&Prototype!A2 -> Outdoor Airflow Rate - RestaurantSitDown
A2: Space/Thermal Zone | B2: Number of People | C2: Floor Area (ft²) | D2: cfm/person [T24, 2025, Equation 120.1-F and Table 120.1-A] | E2: cfm/ft² [T24, 2025, Equation 120.1-F and Table 120.1-A] | F2: Required Exhaust Rate [T24, 2025, Table 120.1-B – minimum exhaust rates] | G2: Total cfm Driven by People | H2: Total cfm Driven by Area | I2: Total cfm Driven by Exhaust | J2: Total cfm | K2: Notes
A3: =Zones!B3 -> Dining | B3: =Zones!K3 -> 132.04818 | C3: =Zones!H3 -> 4001.46 | D3: 15 | E3: 0.15 | F3: 4 restroom, each 25/50 cfm pr unit | G3: =B3*D3 -> 1980.7227 | H3: =C3*E3 -> 600.219 | I3: =4*50 -> 200 | J3: =MAX(G3:I3) -> 1980.7227
A4: =Zones!B4 -> Kitchen | B4: =Zones!K4 -> 4.50165 | C4: =Zones!H4 -> 1500.55 | D4: 15 | E4: 0.15 | F4: 0.7 cfm/ft2 | G4: =B4*D4 -> 67.52475 | H4: =C4*E4 -> 225.0825 | I4: =0.7*C4 -> 1050.385 | J4: =MAX(G4:I4) -> 1050.385
A5: =Zones!B5 -> Attic
A7: Fine storage is defined for normal inventory that doesn't require an extra exhaust rate based on the space functions in T24, Part6, 2025, Table 120.1 B.
A10: Exhaust hood
A11: Type of Hood | C11: Max Exhaust Flow Rate (cfm/ft) [T24, 2025, Table 140.9-C] | D11: Hood Length (ft) * [CKV, 2004] & | E11: Hood Exhaust Rate (cfm) | F11: Note
A12: Type I , wall-mounted canopy, medium duty hood | C12: 210 | D12: =B26 -> 21.5 | E12: =D12*C12 -> 4515
A14: Efficiency of exhaust fan is 50% (according to ACM, 2025, section 5.7.3)
A16: Quick Service Restaurant Hood Appliance
A17: Appliance | C17: Length (ft) | D17: Source
A18: Fryers side | B18: 3 | C18: 3.75 | D18: CKV Design Guide, 2004 (with equipment of a casual dining restaurant) *Charbroiler length is extended from 3 to 4
A19: Fryer drip station (doesn't generate heat or grease but still need to be covered) | B19: 1 | C19: 1.25
A20: Griddle | B20: 1 | C20: 6
A21: Prep surface | B21: 1 | C21: 1
A22: Open range burners (top) | B22: 4 | C22: 2
A23: Charbroiler | B23: 1 | C23: 4
A24: Convection oven | B24: 1 | C24: 2.5 | D24: added from the list of fast food restaurant
A25: Total cooking line length (ft) | B25: =SUM(C18:C24) -> 20.5
A26: Hood length (ft) (+1 ft buffer) | B26: =B25+1 -> 21.5
A33: Background Data [To be deleted prior to publication]
A35: T24, 2025:
E36: ACM 2025, 5.7.3: EXHAUST FAN CONTROL METHOD
A69: 202 Commercial Kitchen Design Guide by SCE
A70: CKV Design Guide
A85: Kitchen photos from google browsing

Sheet Interior Lights
A1: ="Interior Lighting - "&Prototype!A2 -> Interior Lighting - RestaurantSitDown
A2: Space Type | B2: New Construction | E2: Existing
B3: LPD (W/ft²) | C3: Additional LPD for Portable Lighting (W/ft²) | D3: Source | E3: LPD (W/ft²) | F3: Additional LPD for Portable Lighting (W/ft²) | G3: Source
A4: =Zones!C3 -> Dining Area (Bar/Lounge and Fine Dining) | B4: 0.45 | C4: 0.35 (decorative/Display) | D4: T24, 2025, Table 140.6-C (Area category method) | E4: 1 | F4: 0.5 (Ornamental) | G4: T24, 2016, Table 140.6-C (Area category method) LPD of "All other spaces" is considered for storage space
A5: =Zones!C4 -> Kitchen/Food Preparation Area | B5: 0.95 | E5: 1.2
A6: =Zones!C5 -> Attic
A19: Background Data [To be deleted prior to publication]
A23: Existing | B23: Whole Building | C23: All other building | D23: 0.4 | F23: T24, 2019, Table 140.6 B
B24: Area Category | C24: =Zones!B31 -> 0 | D24: 0.65 | F24: T24, 2019, Table 140.6-C
C25: =Zones!B32 -> 0 | D25: 0.4
C26: =Zones!B33 -> 0 | D26: 0.4
A28: Existing | B28: Whole Building | C28: All other building | D28: 0.5 | F28: T24, 2016, Table 140.6 B
B29: Area Category | C29: ZONE1 OFFICE | D29: 0.75 | F29: T24, 2016, Table 140.6-C
C30: ZONE2 FINE STORAGE | D30: 0.5
C31: ZONE3 BULK STORAGE | D31: 0.5
A33: Existing | B33: Whole Building | C33: All other building | D33: 0.6 | F33: T24, 2013, Table 140.6 B
B34: Area Category | C34: ZONE1 OFFICE | D34: 0.75 | F34: T24, 2013, Table 140.6-C
C35: ZONE2 FINE STORAGE | D35: 0.6
C36: ZONE3 BULK STORAGE | D36: 0.6

Sheet Water Heater
A1: ="Water Heater Summary - "&Prototype!A2 -> Water Heater Summary - RestaurantSitDown
A2: Vintage | B2: WH Type | C2: Efficiency | D2: Number of WH | E2: Tank Volume (gal) | F2: Tank Loss | G2: Source
A3: Existing | B3: Gas | C3: 0.8 | D3: 1 | E3: See table below for CZ-specific values: Climate Zone Water Heater Sizing and Loss Coefficients, Storage Volume column (col F) | F3: See table below: Climate Zone Water Heater Sizing and Loss Coefficients, Standby Loss column (col G) | G3: See table below for sources: Climate Zone Water Heater Sizing and Loss Coefficients
A4: New Construction | B4: Gas | C4: 0.8 | D4: 1 | E4: =E3 -> See table below for CZ-specific values: Climate Zone Water Heater Sizing and Loss Coefficients, Storage Volume column (col F) | F4: =F3 -> See table below: Climate Zone Water Heater Sizing and Loss Coefficients, Standby Loss column (col G) | G4: =G3 -> See table below for sources: Climate Zone Water Heater Sizing and Loss Coefficients
A7: Peak Hot Water Consumption
A8: Space Name | B8: Baseline WH Type | C8: Total Area (ft²) | D8: Number of People | E8: Hot Water Usage Specification (gal/hr per person) | F8: Peak Hot Water Usage (gal/hr) | G8: Peak Hot Water Usage (gal/min) | H8: Note
A9: =Zones!B3 -> Dining | B9: Gas | C9: =Zones!H3 -> 4001.46 | D9: =Zones!K3 -> 132.04818 | E9: =0.578*0.2 -> 0.1156 | F9: =D9*E9 -> 15.26477 | G9: =F9/60 -> 0.25441283 | H9: For space types marked with an asterisk (the ‘*’ symbol), the water‑heater type is listed as electric in Appendix 5.4A, sheet ‘2022 SpaceFuncData‑Input.’ However, we modified the value based on CEUS data, which indicates that gas is the primary fuel type.
A10: =Zones!B4 -> Kitchen | B10: Gas | C10: =Zones!H4 -> 1500.55 | D10: =Zones!K4 -> 4.50165 | E10: 0.58 | F10: 162 | G10: =F10/60 -> 2.7
A11: Total | B11: Gas storage | F11: {=_xlfn.LET( _xlpm.g,SUMIF($B$9:$B$10,"Gas*",$F$9:$F$10), _xlpm.e,SUMIF($B$9:$B$10,"Electric*",$F$9:$F$10), IF(AND(_xlpm.g>0,_xlpm.e>0),_xlpm.g,IF(_xlpm.g>0,MAX(75,_xlpm.g),0)))} -> 177.26477 | H11: Minimum peak hot water usage is 75 gal according to ACM 2025
A12: Total | B12: Electric resistance | F12: =_xlfn.LET( _xlpm.g,SUMIF($B$9:$B$10,"Gas*",$F$9:$F$10), _xlpm.e,SUMIF($B$9:$B$10,"Electric*",$F$9:$F$10), IF(AND(_xlpm.g>0,_xlpm.e>0),_xlpm.e,IF(_xlpm.e>0,MAX(75,_xlpm.e),0))) -> 0
A16: Design supply temperature (°F) | B16: 135 | C16: CEC-400-2022-009-CMF-REV2-AP5.4B
A17: WH system factor | B17: 0.6 | C17: 2025 ACM §5.9.2 Rated Capacity
A18: Water mass conversion (lb/gal) | B18: 8.2877 | C18: 2025 ACM §5.9.2 Rated Capacity
A19: Reheat multiplier | B19: 0.4 | C19: 2025 ACM §5.9.2 Storage Volume
A20: Climate Zone Water Heater Sizing and Loss Coefficients
A21: Climate Zone | B21: Minimum Monthly Mains Temp (°F) [T24 2022 - Appendix 5.4B] | C21: Heat Output (Btu/hr) [ACM, 2025, 5.9.2: Rated capacity section] | D21: WH Capacity (Btu/hr) [ACM, 2025, 5.9.2: Rated capacity section] | E21: Required Energy Input (Btu/hr) | F21: Storage Volume (gal) | G21: Standby Loss [Title 20, §1605.1 Table F-4; Appendix B: Water Heating Calculation Method] | I21: Off/On Cycle Loss Coefficient to Ambient Temp | K21: Source/Note
A22: CZ01 | B22: 47.9 | C22: =$F$11*($B$16-B22)*$B$18 -> 127960.11 | D22: =C22*$B$17 -> 76776.066 | E22: =_xlfn.LET(_xlpm.x,_xlfn.XLOOKUP(D22/$C$3,$A$43:$A$73,$A$43:$A$73,"",1),IF(_xlpm.x="",ROUNDUP(D22/$C$3,0),_xlpm.x)) -> 99900 | F22: =_xlfn.LET(_xlpm.v,MAX(30,$F$11*$B$19),_xlpm.x,_xlfn.XLOOKUP(_xlpm.v,$E$43:$E$61,$E$43:$E$61,"",1),IF(_xlpm.x="",ROUNDUP(_xlpm.v,0),_xlpm.x)) -> 72 | G22: =(E22/800)+110*SQRT(F22) -> 1058.256 | H22: Btu/hr | I22: =G22/70 -> 15.117942 | J22: Btu/h·°F | K22: Required Energy Input: vendor/available catalog size (Market data table). Storage Volume: standard/available catalog tank size (Market data table).
A23: CZ02 | B23: 50.8 | C23: =$F$11*($B$16-B23)*$B$18 -> 123699.67 | D23: =C23*$B$17 -> 74219.803 | E23: =_xlfn.LET(_xlpm.x,_xlfn.XLOOKUP(D23/$C$3,$A$43:$A$73,$A$43:$A$73,"",1),IF(_xlpm.x="",ROUNDUP(D23/$C$3,0),_xlpm.x)) -> 99900 | F23: =_xlfn.LET(_xlpm.v,MAX(30,$F$11*$B$19),_xlpm.x,_xlfn.XLOOKUP(_xlpm.v,$E$43:$E$61,$E$43:$E$61,"",1),IF(_xlpm.x="",ROUNDUP(_xlpm.v,0),_xlpm.x)) -> 72 | G23: =(E23/800)+110*SQRT(F23) -> 1058.256 | H23: Btu/hr | I23: =G23/70 -> 15.117942 | J23: Btu/h·°F
A24: CZ03 | B24: 52.2 | C24: =$F$11*($B$16-B24)*$B$18 -> 121642.91 | D24: =C24*$B$17 -> 72985.744 | E24: =_xlfn.LET(_xlpm.x,_xlfn.XLOOKUP(D24/$C$3,$A$43:$A$73,$A$43:$A$73,"",1),IF(_xlpm.x="",ROUNDUP(D24/$C$3,0),_xlpm.x)) -> 99900 | F24: =_xlfn.LET(_xlpm.v,MAX(30,$F$11*$B$19),_xlpm.x,_xlfn.XLOOKUP(_xlpm.v,$E$43:$E$61,$E$43:$E$61,"",1),IF(_xlpm.x="",ROUNDUP(_xlpm.v,0),_xlpm.x)) -> 72 | G24: =(E24/800)+110*SQRT(F24) -> 1058.256 | H24: Btu/hr | I24: =G24/70 -> 15.117942 | J24: Btu/h·°F
A25: CZ04 | B25: 52.7 | C25: =$F$11*($B$16-B25)*$B$18 -> 120908.35 | D25: =C25*$B$17 -> 72545.009 | E25: =_xlfn.LET(_xlpm.x,_xlfn.XLOOKUP(D25/$C$3,$A$43:$A$73,$A$43:$A$73,"",1),IF(_xlpm.x="",ROUNDUP(D25/$C$3,0),_xlpm.x)) -> 99900 | F25: =_xlfn.LET(_xlpm.v,MAX(30,$F$11*$B$19),_xlpm.x,_xlfn.XLOOKUP(_xlpm.v,$E$43:$E$61,$E$43:$E$61,"",1),IF(_xlpm.x="",ROUNDUP(_xlpm.v,0),_xlpm.x)) -> 72 | G25: =(E25/800)+110*SQRT(F25) -> 1058.256 | H25: Btu/hr | I25: =G25/70 -> 15.117942 | J25: Btu/h·°F
A26: CZ05 | B26: 51.6 | C26: =$F$11*($B$16-B26)*$B$18 -> 122524.38 | D26: =C26*$B$17 -> 73514.626 | E26: =_xlfn.LET(_xlpm.x,_xlfn.XLOOKUP(D26/$C$3,$A$43:$A$73,$A$43:$A$73,"",1),IF(_xlpm.x="",ROUNDUP(D26/$C$3,0),_xlpm.x)) -> 99900 | F26: =_xlfn.LET(_xlpm.v,MAX(30,$F$11*$B$19),_xlpm.x,_xlfn.XLOOKUP(_xlpm.v,$E$43:$E$61,$E$43:$E$61,"",1),IF(_xlpm.x="",ROUNDUP(_xlpm.v,0),_xlpm.x)) -> 72 | G26: =(E26/800)+110*SQRT(F26) -> 1058.256 | H26: Btu/hr | I26: =G26/70 -> 15.117942 | J26: Btu/h·°F
A27: CZ06 | B27: 56.8 | C27: =$F$11*($B$16-B27)*$B$18 -> 114884.97 | D27: =C27*$B$17 -> 68930.98 | E27: =_xlfn.LET(_xlpm.x,_xlfn.XLOOKUP(D27/$C$3,$A$43:$A$73,$A$43:$A$73,"",1),IF(_xlpm.x="",ROUNDUP(D27/$C$3,0),_xlpm.x)) -> 99900 | F27: =_xlfn.LET(_xlpm.v,MAX(30,$F$11*$B$19),_xlpm.x,_xlfn.XLOOKUP(_xlpm.v,$E$43:$E$61,$E$43:$E$61,"",1),IF(_xlpm.x="",ROUNDUP(_xlpm.v,0),_xlpm.x)) -> 72 | G27: =(E27/800)+110*SQRT(F27) -> 1058.256 | H27: Btu/hr | I27: =G27/70 -> 15.117942 | J27: Btu/h·°F
A28: CZ07 | B28: 58.4 | C28: =$F$11*($B$16-B28)*$B$18 -> 112534.38 | D28: =C28*$B$17 -> 67520.628 | E28: =_xlfn.LET(_xlpm.x,_xlfn.XLOOKUP(D28/$C$3,$A$43:$A$73,$A$43:$A$73,"",1),IF(_xlpm.x="",ROUNDUP(D28/$C$3,0),_xlpm.x)) -> 99900 | F28: =_xlfn.LET(_xlpm.v,MAX(30,$F$11*$B$19),_xlpm.x,_xlfn.XLOOKUP(_xlpm.v,$E$43:$E$61,$E$43:$E$61,"",1),IF(_xlpm.x="",ROUNDUP(_xlpm.v,0),_xlpm.x)) -> 72 | G28: =(E28/800)+110*SQRT(F28) -> 1058.256 | H28: Btu/hr | I28: =G28/70 -> 15.117942 | J28: Btu/h·°F
A29: CZ08 | B29: 58.4 | C29: =$F$11*($B$16-B29)*$B$18 -> 112534.38 | D29: =C29*$B$17 -> 67520.628 | E29: =_xlfn.LET(_xlpm.x,_xlfn.XLOOKUP(D29/$C$3,$A$43:$A$73,$A$43:$A$73,"",1),IF(_xlpm.x="",ROUNDUP(D29/$C$3,0),_xlpm.x)) -> 99900 | F29: =_xlfn.LET(_xlpm.v,MAX(30,$F$11*$B$19),_xlpm.x,_xlfn.XLOOKUP(_xlpm.v,$E$43:$E$61,$E$43:$E$61,"",1),IF(_xlpm.x="",ROUNDUP(_xlpm.v,0),_xlpm.x)) -> 72 | G29: =(E29/800)+110*SQRT(F29) -> 1058.256 | H29: Btu/hr | I29: =G29/70 -> 15.117942 | J29: Btu/h·°F
A30: CZ09 | B30: 57.6 | C30: =$F$11*($B$16-B30)*$B$18 -> 113709.67 | D30: =C30*$B$17 -> 68225.804 | E30: =_xlfn.LET(_xlpm.x,_xlfn.XLOOKUP(D30/$C$3,$A$43:$A$73,$A$43:$A$73,"",1),IF(_xlpm.x="",ROUNDUP(D30/$C$3,0),_xlpm.x)) -> 99900 | F30: =_xlfn.LET(_xlpm.v,MAX(30,$F$11*$B$19),_xlpm.x,_xlfn.XLOOKUP(_xlpm.v,$E$43:$E$61,$E$43:$E$61,"",1),IF(_xlpm.x="",ROUNDUP(_xlpm.v,0),_xlpm.x)) -> 72 | G30: =(E30/800)+110*SQRT(F30) -> 1058.256 | H30: Btu/hr | I30: =G30/70 -> 15.117942 | J30: Btu/h·°F
A31: CZ10 | B31: 57.1 | C31: =$F$11*($B$16-B31)*$B$18 -> 114444.23 | D31: =C31*$B$17 -> 68666.539 | E31: =_xlfn.LET(_xlpm.x,_xlfn.XLOOKUP(D31/$C$3,$A$43:$A$73,$A$43:$A$73,"",1),IF(_xlpm.x="",ROUNDUP(D31/$C$3,0),_xlpm.x)) -> 99900 | F31: =_xlfn.LET(_xlpm.v,MAX(30,$F$11*$B$19),_xlpm.x,_xlfn.XLOOKUP(_xlpm.v,$E$43:$E$61,$E$43:$E$61,"",1),IF(_xlpm.x="",ROUNDUP(_xlpm.v,0),_xlpm.x)) -> 72 | G31: =(E31/800)+110*SQRT(F31) -> 1058.256 | H31: Btu/hr | I31: =G31/70 -> 15.117942 | J31: Btu/h·°F
A32: CZ11 | B32: 50.5 | C32: =$F$11*($B$16-B32)*$B$18 -> 124140.41 | D32: =C32*$B$17 -> 74484.244 | E32: =_xlfn.LET(_xlpm.x,_xlfn.XLOOKUP(D32/$C$3,$A$43:$A$73,$A$43:$A$73,"",1),IF(_xlpm.x="",ROUNDUP(D32/$C$3,0),_xlpm.x)) -> 99900 | F32: =_xlfn.LET(_xlpm.v,MAX(30,$F$11*$B$19),_xlpm.x,_xlfn.XLOOKUP(_xlpm.v,$E$43:$E$61,$E$43:$E$61,"",1),IF(_xlpm.x="",ROUNDUP(_xlpm.v,0),_xlpm.x)) -> 72 | G32: =(E32/800)+110*SQRT(F32) -> 1058.256 | H32: Btu/hr | I32: =G32/70 -> 15.117942 | J32: Btu/h·°F
A33: CZ12 | B33: 51.4 | C33: =$F$11*($B$16-B33)*$B$18 -> 122818.2 | D33: =C33*$B$17 -> 73690.92 | E33: =_xlfn.LET(_xlpm.x,_xlfn.XLOOKUP(D33/$C$3,$A$43:$A$73,$A$43:$A$73,"",1),IF(_xlpm.x="",ROUNDUP(D33/$C$3,0),_xlpm.x)) -> 99900 | F33: =_xlfn.LET(_xlpm.v,MAX(30,$F$11*$B$19),_xlpm.x,_xlfn.XLOOKUP(_xlpm.v,$E$43:$E$61,$E$43:$E$61,"",1),IF(_xlpm.x="",ROUNDUP(_xlpm.v,0),_xlpm.x)) -> 72 | G33: =(E33/800)+110*SQRT(F33) -> 1058.256 | H33: Btu/hr | I33: =G33/70 -> 15.117942 | J33: Btu/h·°F
A34: CZ13 | B34: 51.7 | C34: =$F$11*($B$16-B34)*$B$18 -> 122377.47 | D34: =C34*$B$17 -> 73426.479 | E34: =_xlfn.LET(_xlpm.x,_xlfn.XLOOKUP(D34/$C$3,$A$43:$A$73,$A$43:$A$73,"",1),IF(_xlpm.x="",ROUNDUP(D34/$C$3,0),_xlpm.x)) -> 99900 | F34: =_xlfn.LET(_xlpm.v,MAX(30,$F$11*$B$19),_xlpm.x,_xlfn.XLOOKUP(_xlpm.v,$E$43:$E$61,$E$43:$E$61,"",1),IF(_xlpm.x="",ROUNDUP(_xlpm.v,0),_xlpm.x)) -> 72 | G34: =(E34/800)+110*SQRT(F34) -> 1058.256 | H34: Btu/hr | I34: =G34/70 -> 15.117942 | J34: Btu/h·°F
... A37: CZ16 | B37: 41.4 | C37: =$F$11*($B$16-B37)*$B$18 -> 137509.37 | D37: =C37*$B$17 -> 82505.624 | E37: =_xlfn.LET(_xlpm.x,_xlfn.XLOOKUP(D37/$C$3,$A$43:$A$73,$A$43:$A$73,"",1),IF(_xlpm.x="",ROUNDUP(D37/$C$3,0),_xlpm.x)) -> 120000 | F37: =_xlfn.LET(_xlpm.v,MAX(30,$F$11*$B$19),_xlpm.x,_xlfn.XLOOKUP(_xlpm.v,$E$43:$E$61,$E$43:$E$61,"",1),IF(_xlpm.x="",ROUNDUP(_xlpm.v,0),_xlpm.x)) -> 72 | G37: =(E37/800)+110*SQRT(F37) -> 1083.381 | H37: Btu/hr | I37: =G37/70 -> 15.476871 | J37: Btu/h·°F
A41: Market data
A42: Catalog gas input (Btu/h) | B42: Input source | C42: Elec resistance tank (kW) | D42: Elec resistance (Btu/h) | E42: Catalog gas tank (gal) | F42: Tank source | G42: Elec tank (gal) | H42: Elec tank source | I42: =HYPERLINK("#'Note'!A1","Sources and links → Note tab") -> Sources and links → Note tab
A43: 60000 | B43: Grainger | C43: 1.5 | D43: 5118 | E43: 34 | F43: ENERGY STAR | G43: 6 | H43: Grainger
A44: 75100 | B44: Grainger | C44: 2 | D44: 6824 | E44: 35 | F44: Grainger | G44: 10 | H44: Grainger
A45: 76000 | B45: Both | C45: 3 | D45: 10236 | E45: 48 | F45: Grainger | G45: 15 | H45: Grainger
A46: 80000 | B46: Grainger | C46: 4.5 | D46: 15355 | E46: 50 | F46: Both | G46: 20 | H46: Grainger
A47: 99900 | B47: ENERGY STAR | C47: 6 | D47: 20473 | E47: 55 | F47: ENERGY STAR | G47: 28 | H47: Grainger
A48: 100000 | B48: Both | C48: 8 | D48: 27297 | E48: 60 | F48: ENERGY STAR | G48: 30 | H48: Grainger
A49: 120000 | B49: ENERGY STAR | C49: 9 | D49: 30709 | E49: 65 | F49: Both | G49: 36 | H49: Grainger
A50: 125000 | B50: Both | C50: 10 | D50: 34121 | E50: 72 | F50: Grainger | G50: 40 | H50: Grainger
...

Sheet Equipment
A1: ="Equipment - "&Prototype!A2 -> Equipment - RestaurantSitDown
A2: Space Type | B2: Plug Load Power Density (W/ft²) | C2: ReachIn Refrigerator and ReachInFreezer Power (W) - 24/7 | D2: Refrigerator Power Density (W/ft²) | E2: Gas Power Density (Btu/hr-ft²) | F2: Source
A3: =Zones!C3 -> Dining Area (Bar/Lounge and Fine Dining) | B3: 0.5 | D3: 0.25 | F3: Others inputs: T24 2025 - Appendix 5.4A: "2022 SpaceFuncData-Input"
A4: =Zones!C4 -> Kitchen/Food Preparation Area | B4: 1.5 | C4: 590 | D4: 1.12 | E4: =17.54*5500/1200 -> 80.391667 | F4: ReachIn Refrigerator and ReachInFreezer: [PNNL ASHRAE 90.1 2022 SitDown prototype] Other inputs: T24 2025 - Appendix 5.4A: "2022 SpaceFuncData-Input" Plug load density is confirmed by the findings Plug load and schedules project with CEC, 2025
A5: =Zones!C5 -> Attic
A6: *ReachIn Refrigerator and ReachInFreezer Power is based on PNNL model. It doesn’t exist in the CPUC model.
A7: * Gas load is very low compared to PNNL model (194 Btu/hr-ft2 for Kitchen)
A8: Refrigerator load will be simulated as equipment load
G9: =F9/Schedules!AG59/1200 -> 0

Sheet Ext Lighting
A1: ="Exterior Lighting - "&Prototype!A2 -> Exterior Lighting - RestaurantSitDown
A2: Motion Controlled Luminaires (W) | B2: Non-motion Controlled Luminaires (W) | C2: Total (W) | D2: Source
A3: =G18 -> 760.85557 | B3: =G19 -> 136.86347 | C3: =B3+A3 -> 897.71904 | D3: T24, 2022
A8: Exterior Lighting
A9: Items (Assume LZ2) | B9: Assumptions [2019 Outdoor Lighting CASE Report & PNNL 90.1-2010 TSD] | D9: Unit | E9: Lighting Power Allowance [T24, 2025, Table 140.7-A & 140.7-B] | F9: Unit | G9: Exterior Lighting Power (W)
A10: IWA (Initial Wattage Allowance) | E10: 200 | F10: (W) | G10: =$E10 -> 200
A11: Parking area | B11: 400 ft² for every parking space 1 parking space per 250 ft² of gross building area | C11: =B25/250*400 -> 8803.216 | D11: (ft²) | E11: 0.019 | F11: (W/ft²) | G11: =$E11*C11 -> 167.2611
A12: Building Entrance | B12: 2 building entrance (1 per 10,000 ft² footprint) | C12: 1 | D12: (count) | E12: 15 | F12: (W/ea) | G12: =E12*C12 -> 15
A13: Hardscape Ornamental Light | B13: 0.1 ft² per 1 ft² of gross building area for hardscape ornamental light | C13: =B25*0.1 -> 550.201 | D13: (ft²) | E13: 0.007 | F13: (W/ft²) | G13: =E13*C13 -> 3.851407
A14: Building façade | B14: 0.1 W per 1 ft² of facade area Façade Area = Perimeter × 0.5 × 10 ft (10 ft is the building height ) * The 0.5 factor assumes that only half of the perimeter walls are lit. -Formula is developed based on the 2019 Outdoor Lighting CASE report | C14: =B24*0.5*B27 -> 1000 | D14: (ft²) | E14: 0.1 | F14: (W/ft²) | G14: =E14*C14 -> 100
A15: Drive up windows | B15: 1 per 1500 ft² of gross building area | C15: =ROUND(B25/1500,0) -> 4 | D15: (count) | E15: 30 | F15: (W/ea) | G15: =E15*C15 -> 120
A16: Outdoor dining | B16: 1 ft² per 5 ft² of gross building area | C16: =1/5*B25 -> 1100.402 | D16: (ft²) | E16: 0.03 | F16: (W/ft²) | G16: =E16*C16 -> 33.01206
A17: Sales canopy | B17: 0.1 ft² per 1 ft² of gross building area | C17: =0.1*B25 -> 550.201 | D17: (ft²) | E17: 0.47 | F17: (W/ft²) | G17: =E17*C17 -> 258.59447 | H17: *This row is newly added. The CASE report didn’t include it for 'restaurant' — they probably meant fast food.
A18: Motion controlled Luminaires | G18: =G11+G10+G12+G15+G17 -> 760.85557
A19: Non-motion-controlled Luminaires | G19: =G13+G14+G16 -> 136.86347
A20: TOTAL | G20: =G18+G19 -> 897.71904
A24: Perimeter (ft) | B24: =(50+50)*2 -> 200
A25: Total floor area (ft²) | B25: =Zones!H6 -> 5502.01
A26: Floors | B26: 1
A27: Height (ft) | B27: 10
A34: Title 24, 2025

Sheet Schedules
A1: ="Schedules - "&Prototype!A2 -> Schedules - RestaurantSitDown
A2: Zone | B2: Schedule Category | C2: Schedule | D2: Source | E2: Type | F2: Hour
F3: 1 | G3: 2 | H3: 3 | I3: 4 | J3: 5 | K3: 6 | L3: 7 | M3: 8 | N3: 9 | O3: 10 | P3: 11 | Q3: 12 | R3: 13 | S3: 14 | T3: 15 | U3: 16 | V3: 17 | W3: 18 | X3: 19 | Y3: 20 | Z3: 21 | AA3: 22 | AB3: 23 | AC3: 24
A4: Dining | B4: Restaurant | C4: Occupancy | D4: PNNL, ASHRAE 90.1, 2022 RestaurantSitDown prototype (It has higher occupancy rate during morning compared to T24 2022 - Appendix 5.4B) | E4: Weekday | F4: 0.05 | G4: 0 | H4: 0 | I4: 0 | J4: 0 | K4: 0.05 | L4: 0.1 | M4: 0.4 | N4: 0.4 | O4: 0.4 | P4: 0.2 | Q4: 0.5 | R4: 0.8 | S4: 0.7 | T4: 0.4 | U4: 0.2 | V4: 0.25 | W4: 0.5 | X4: 0.8 | Y4: 0.8 | Z4: 0.8 | AA4: 0.5 | AB4: 0.35 | AC4: 0.2
E5: Saturday | F5: 0.05 | G5: 0 | H5: 0 | I5: 0 | J5: 0 | K5: 0 | L5: 0.05 | M5: 0.5 | N5: 0.5 | O5: 0.4 | P5: 0.2 | Q5: 0.45 | R5: 0.5 | S5: 0.5 | T5: 0.35 | U5: 0.3 | V5: 0.3 | W5: 0.3 | X5: 0.7 | Y5: 0.9 | Z5: 0.7 | AA5: 0.65 | AB5: 0.55 | AC5: 0.35
E6: Sunday | F6: 0.05 | G6: 0 | H6: 0 | I6: 0 | J6: 0 | K6: 0 | L6: 0.05 | M6: 0.5 | N6: 0.5 | O6: 0.2 | P6: 0.2 | Q6: 0.3 | R6: 0.5 | S6: 0.5 | T6: 0.3 | U6: 0.2 | V6: 0.25 | W6: 0.35 | X6: 0.55 | Y6: 0.65 | Z6: 0.7 | AA6: 0.35 | AB6: 0.2 | AC6: 0.2
A7: =A4 -> Dining | B7: Restaurant | C7: Lights | D7: T24 2022 - Appendix 5.4B, [Restaurant] Updated based on the equipment schedule from the plug load and schedule project with CEC | E7: Weekday | F7: 0.15 | G7: 0.15 | H7: 0.15 | I7: 0.15 | J7: 0.15 | K7: 0.2 | L7: 0.3 | M7: =M10-5% -> 0.67 | N7: =N10-5% -> 0.73 | O7: =O10-5% -> 0.75 | P7: =P10-5% -> 0.85 | Q7: =Q10-5% -> 0.85 | R7: =R10-5% -> 0.85 | S7: =S10-5% -> 0.83 | T7: =T10-5% -> 0.72 | ... AB7: =AB10-5% -> 0.57 | AC7: 0.3
E8: Saturday | F8: =F11 -> 0.15 | G8: 0.15 | H8: 0.15 | I8: 0.15 | J8: 0.15 | K8: =K11 -> 0.2 | L8: 0.3 | M8: =M11-5% -> 0.67 | N8: =N11-5% -> 0.73 | O8: =O11-5% -> 0.75 | P8: =P11-5% -> 0.85 | Q8: =Q11-5% -> 0.85 | R8: =R11-5% -> 0.85 | S8: =S11-5% -> 0.83 | T8: =T11-5% -> 0.72 | ... AB8: =AB11-5% -> 0.57 | AC8: 0.3
E9: Sunday | F9: 0.2 | G9: 0.15 | H9: 0.15 | I9: 0.15 | J9: 0.15 | K9: 0.15 | L9: 0.3 | M9: =M12-5% -> 0.67 | N9: =N12-5% -> 0.73 | O9: =O12-5% -> 0.75 | P9: =P12-5% -> 0.85 | Q9: =Q12-5% -> 0.85 | R9: =R12-5% -> 0.85 | S9: =S12-5% -> 0.83 | T9: =T12-5% -> 0.72 | ... AB9: =AB12-5% -> 0.57 | AC9: 0.3
A10: =A4 -> Dining | B10: Restaurant | C10: ElecEquipment | D10: Plug load and schedules project with CEC, 2025 | E10: Weekday | F10: 0.15 | G10: 0.15 | H10: 0.15 | I10: 0.15 | J10: 0.15 | K10: 0.2 | L10: 0.3 | M10: 0.72 | N10: 0.78 | O10: 0.8 | P10: 0.9 | Q10: 0.9 | R10: 0.9 | S10: 0.88 | T10: 0.77 | U10: 0.7 | V10: 0.72 | W10: 0.8 | X10: 0.9 | Y10: 0.9 | Z10: 0.9 | AA10: 0.8 | AB10: 0.62 | AC10: 0.3
E11: Saturday | F11: 0.15 | G11: 0.15 | H11: 0.15 | I11: 0.15 | J11: 0.15 | K11: 0.2 | L11: 0.3 | M11: 0.72 | N11: 0.78 | O11: 0.8 | P11: 0.9 | Q11: 0.9 | R11: 0.9 | S11: 0.88 | T11: 0.77 | U11: 0.7 | V11: 0.72 | W11: 0.8 | X11: 0.9 | Y11: 0.9 | Z11: 0.9 | AA11: 0.8 | AB11: 0.62 | AC11: 0.3
E12: Sunday | F12: 0.2 | G12: 0.15 | H12: 0.15 | I12: 0.15 | J12: 0.15 | K12: 0.15 | L12: 0.3 | M12: 0.72 | N12: 0.78 | O12: 0.8 | P12: 0.9 | Q12: 0.9 | R12: 0.9 | S12: 0.88 | T12: 0.77 | U12: 0.7 | V12: 0.72 | W12: 0.8 | X12: 0.9 | Y12: 0.9 | Z12: 0.9 | AA12: 0.8 | AB12: 0.62 | AC12: 0.3
A13: =A4 -> Dining | B13: Restaurant | C13: HVACAvail | D13: T24 2022 - Appendix 5.4B , [Restaurant] Updated based on the adopted PNNL occupancy | E13: Weekday | F13: 1 | G13: 0 | H13: 0 | I13: 0 | J13: 1 | K13: 1 | L13: 1 | M13: 1 | N13: 1 | O13: 1 | P13: 1 | Q13: 1 | R13: 1 | S13: 1 | T13: 1 | U13: 1 | V13: 1 | W13: 1 | X13: 1 | Y13: 1 | Z13: 1 | AA13: 1 | AB13: 1 | AC13: 1
E14: Saturday | F14: 1 | G14: 0 | H14: 0 | I14: 0 | J14: 0 | K14: 1 | L14: 1 | M14: 1 | N14: 1 | O14: 1 | P14: 1 | Q14: 1 | R14: 1 | S14: 1 | T14: 1 | U14: 1 | V14: 1 | W14: 1 | X14: 1 | Y14: 1 | Z14: 1 | AA14: 1 | AB14: 1 | AC14: 1
E15: Sunday | F15: 1 | G15: 0 | H15: 0 | I15: 0 | J15: 0 | K15: 1 | L15: 1 | M15: 1 | N15: 1 | O15: 1 | P15: 1 | Q15: 1 | R15: 1 | S15: 1 | T15: 1 | U15: 1 | V15: 1 | W15: 1 | X15: 1 | Y15: 1 | Z15: 1 | AA15: 1 | AB15: 1 | AC15: 1
A16: =A7 -> Dining | B16: Restaurant | C16: ServiceHotWater | D16: T24 2022 - Appendix 5.4B, [Restaurant] Updated based on the adopted PNNL occupancy | E16: Weekday | F16: 0.2 | G16: 0 | H16: 0 | I16: 0 | J16: 0 | K16: 0.3 | L16: 0.3 | M16: 0.6 | N16: 0.55 | O16: 0.45 | P16: 0.4 | Q16: 0.45 | R16: 0.4 | S16: 0.35 | T16: 0.3 | U16: 0.3 | V16: 0.3 | W16: 0.4 | X16: 0.55 | Y16: 0.6 | Z16: 0.5 | AA16: 0.55 | AB16: 0.45 | AC16: 0.25
E17: Saturday | F17: 0.2 | G17: 0 | H17: 0 | I17: 0 | J17: 0 | K17: 0 | L17: 0.3 | M17: 0.3 | N17: 0.3 | O17: 0.5 | P17: 0.45 | Q17: 0.5 | R17: 0.5 | S17: 0.45 | T17: 0.4 | U17: 0.4 | V17: 0.35 | W17: 0.4 | X17: 0.55 | Y17: 0.55 | Z17: 0.5 | AA17: 0.55 | AB17: 0.4 | AC17: 0.3
E18: Sunday | F18: 0.25 | G18: 0 | H18: 0 | I18: 0 | J18: 0 | K18: 0 | L18: 0.3 | M18: 0.3 | N18: 0.3 | O18: 0.5 | P18: 0.5 | Q18: 0.5 | R18: 0.4 | S18: 0.4 | T18: 0.3 | U18: 0.3 | V18: 0.3 | W18: 0.4 | X18: 0.5 | Y18: 0.5 | Z18: 0.4 | AA18: 0.5 | AB18: 0.4 | AC18: 0.2
A19: =A4 -> Dining | B19: Restaurant | C19: Infiltration | D19: T24 2022 - Appendix 5.4B, [Restaurant] Updated based on the adopted PNNL occupancy | E19: Weekday | F19: 0.25 | G19: 0 | H19: 0 | I19: 1 | J19: 0.25 | K19: 0.25 | L19: 0.25 | M19: 0.25 | N19: 0.25 | O19: 0.25 | P19: 0.25 | Q19: 0.25 | R19: 0.25 | S19: 0.25 | T19: 0.25 | U19: 0.25 | V19: 0.25 | W19: 0.25 | X19: 0.25 | Y19: 0.25 | Z19: 0.25 | AA19: 0.25 | AB19: 0.25 | AC19: 0.25
E20: Saturday | F20: 0.25 | G20: 0 | H20: 0 | I20: 1 | J20: 1 | K20: 0.25 | L20: 0.25 | M20: 0.25 | N20: 0.25 | O20: 0.25 | P20: 0.25 | Q20: 0.25 | R20: 0.25 | S20: 0.25 | T20: 0.25 | U20: 0.25 | V20: 0.25 | W20: 0.25 | X20: 0.25 | Y20: 0.25 | Z20: 0.25 | AA20: 0.25 | AB20: 0.25 | AC20: 0.25
E21: Sunday | F21: 0.25 | G21: 0 | H21: 0 | I21: 1 | J21: 1 | K21: 0.25 | L21: 0.25 | M21: 0.25 | N21: 0.25 | O21: 0.25 | P21: 0.25 | Q21: 0.25 | R21: 0.25 | S21: 0.25 | T21: 0.25 | U21: 0.25 | V21: 0.25 | W21: 0.25 | X21: 0.25 | Y21: 0.25 | Z21: 0.25 | AA21: 0.25 | AB21: 0.25 | AC21: 0.25
A22: Kitchen | B22: Restaurant | C22: Refrigeration | D22: T24 2022 - Appendix 5.4B, [Restaurant] | E22: Weekday | F22: 0.9 | G22: 0.9 | H22: 0.9 | I22: 0.9 | J22: 0.9 | K22: 0.9 | L22: 0.9 | M22: 0.9 | N22: 0.9 | O22: 0.9 | P22: 0.9 | Q22: 0.9 | R22: 0.9 | S22: 0.9 | T22: 0.9 | U22: 0.9 | V22: 0.9 | W22: 0.9 | X22: 0.9 | Y22: 0.9 | Z22: 0.9 | AA22: 0.9 | AB22: 0.9 | AC22: 0.9
E23: Saturday | F23: 0.9 | G23: 0.9 | H23: 0.9 | I23: 0.9 | J23: 0.9 | K23: 0.9 | L23: 0.9 | M23: 0.9 | N23: 0.9 | O23: 0.9 | P23: 0.9 | Q23: 0.9 | R23: 0.9 | S23: 0.9 | T23: 0.9 | U23: 0.9 | V23: 0.9 | W23: 0.9 | X23: 0.9 | Y23: 0.9 | Z23: 0.9 | AA23: 0.9 | AB23: 0.9 | AC23: 0.9
E24: Sunday | F24: 0.9 | G24: 0.9 | H24: 0.9 | I24: 0.9 | J24: 0.9 | K24: 0.9 | L24: 0.9 | M24: 0.9 | N24: 0.9 | O24: 0.9 | P24: 0.9 | Q24: 0.9 | R24: 0.9 | S24: 0.9 | T24: 0.9 | U24: 0.9 | V24: 0.9 | W24: 0.9 | X24: 0.9 | Y24: 0.9 | Z24: 0.9 | AA24: 0.9 | AB24: 0.9 | AC24: 0.9
A25: =A4 -> Dining | B25: =B16 -> Restaurant | C25: HtgSetpt | D25: T24 2022 - Appendix 5.4B, [Restaurant] | E25: Weekday | F25: =IF(F13=1,Thermostat!$C$3,Thermostat!$C$4) -> 70 | G25: =IF(G13=1,Thermostat!$C$3,Thermostat!$C$4) -> 60 | H25: =IF(H13=1,Thermostat!$C$3,Thermostat!$C$4) -> 60 | I25: =IF(I13=1,Thermostat!$C$3,Thermostat!$C$4) -> 60 | J25: =IF(J13=1,Thermostat!$C$3,Thermostat!$C$4) -> 70 | K25: =IF(K13=1,Thermostat!$C$3,Thermostat!$C$4) -> 70 | L25: =IF(L13=1,Thermostat!$C$3,Thermostat!$C$4) -> 70 | M25: =IF(M13=1,Thermostat!$C$3,Thermostat!$C$4) -> 70 | ... AC25: =IF(AC13=1,Thermostat!$C$3,Thermostat!$C$4) -> 70
E26: Saturday | F26: =IF(F14=1,Thermostat!$C$3,Thermostat!$C$4) -> 70 | G26: =IF(G14=1,Thermostat!$C$3,Thermostat!$C$4) -> 60 | H26: =IF(H14=1,Thermostat!$C$3,Thermostat!$C$4) -> 60 | I26: =IF(I14=1,Thermostat!$C$3,Thermostat!$C$4) -> 60 | J26: =IF(J14=1,Thermostat!$C$3,Thermostat!$C$4) -> 60 | K26: =IF(K14=1,Thermostat!$C$3,Thermostat!$C$4) -> 70 | L26: =IF(L14=1,Thermostat!$C$3,Thermostat!$C$4) -> 70 | M26: =IF(M14=1,Thermostat!$C$3,Thermostat!$C$4) -> 70 | ... AC26: =IF(AC14=1,Thermostat!$C$3,Thermostat!$C$4) -> 70
E27: Sunday | F27: =IF(F15=1,Thermostat!$C$3,Thermostat!$C$4) -> 70 | G27: =IF(G15=1,Thermostat!$C$3,Thermostat!$C$4) -> 60 | H27: =IF(H15=1,Thermostat!$C$3,Thermostat!$C$4) -> 60 | I27: =IF(I15=1,Thermostat!$C$3,Thermostat!$C$4) -> 60 | J27: =IF(J15=1,Thermostat!$C$3,Thermostat!$C$4) -> 60 | K27: =IF(K15=1,Thermostat!$C$3,Thermostat!$C$4) -> 70 | L27: =IF(L15=1,Thermostat!$C$3,Thermostat!$C$4) -> 70 | M27: =IF(M15=1,Thermostat!$C$3,Thermostat!$C$4) -> 70 | ... AC27: =IF(AC15=1,Thermostat!$C$3,Thermostat!$C$4) -> 70
A28: =A4 -> Dining | B28: =B19 -> Restaurant | C28: ClgSetpt | D28: T24 2022 - Appendix 5.4B, [Restaurant] | E28: Weekday | F28: =IF(F13=1,Thermostat!$C$5,Thermostat!$C$6) -> 75 | G28: =IF(G13=1,Thermostat!$C$5,Thermostat!$C$6) -> 85 | H28: =IF(H13=1,Thermostat!$C$5,Thermostat!$C$6) -> 85 | I28: =IF(I13=1,Thermostat!$C$5,Thermostat!$C$6) -> 85 | J28: =IF(J13=1,Thermostat!$C$5,Thermostat!$C$6) -> 75 | K28: =IF(K13=1,Thermostat!$C$5,Thermostat!$C$6) -> 75 | L28: =IF(L13=1,Thermostat!$C$5,Thermostat!$C$6) -> 75 | M28: =IF(M13=1,Thermostat!$C$5,Thermostat!$C$6) -> 75 | ... AC28: =IF(AC13=1,Thermostat!$C$5,Thermostat!$C$6) -> 75
E29: Saturday | F29: =IF(F14=1,Thermostat!$C$5,Thermostat!$C$6) -> 75 | G29: =IF(G14=1,Thermostat!$C$5,Thermostat!$C$6) -> 85 | H29: =IF(H14=1,Thermostat!$C$5,Thermostat!$C$6) -> 85 | I29: =IF(I14=1,Thermostat!$C$5,Thermostat!$C$6) -> 85 | J29: =IF(J14=1,Thermostat!$C$5,Thermostat!$C$6) -> 85 | K29: =IF(K14=1,Thermostat!$C$5,Thermostat!$C$6) -> 75 | L29: =IF(L14=1,Thermostat!$C$5,Thermostat!$C$6) -> 75 | M29: =IF(M14=1,Thermostat!$C$5,Thermostat!$C$6) -> 75 | ... AC29: =IF(AC14=1,Thermostat!$C$5,Thermostat!$C$6) -> 75
E30: Sunday | F30: =IF(F15=1,Thermostat!$C$5,Thermostat!$C$6) -> 75 | G30: =IF(G15=1,Thermostat!$C$5,Thermostat!$C$6) -> 85 | H30: =IF(H15=1,Thermostat!$C$5,Thermostat!$C$6) -> 85 | I30: =IF(I15=1,Thermostat!$C$5,Thermostat!$C$6) -> 85 | J30: =IF(J15=1,Thermostat!$C$5,Thermostat!$C$6) -> 85 | K30: =IF(K15=1,Thermostat!$C$5,Thermostat!$C$6) -> 75 | L30: =IF(L15=1,Thermostat!$C$5,Thermostat!$C$6) -> 75 | M30: =IF(M15=1,Thermostat!$C$5,Thermostat!$C$6) -> 75 | ... AC30: =IF(AC15=1,Thermostat!$C$5,Thermostat!$C$6) -> 75
A31: Kitchen
A32: Kitchen | B32: Kitchen | C32: occupancy | D32: PNNL, ASHRAE 90.1, 2022 RestaurantSitDown prototype (It has higher occupancy rate during morning compared to T24 2022 - Appendix 5.4B) | E32: Weekday | F32: 0.05 | G32: 0 | H32: 0 | I32: 0 | J32: 0 | K32: 0.05 | L32: 0.1 | M32: 0.4 | N32: 0.4 | O32: 0.4 | P32: 0.2 | Q32: 0.5 | R32: 0.8 | S32: 0.7 | T32: 0.4 | U32: 0.2 | V32: 0.25 | W32: 0.5 | X32: 0.8 | Y32: 0.8 | Z32: 0.8 | AA32: 0.5 | AB32: 0.35 | AC32: 0.2
E33: Saturday | F33: 0.05 | G33: 0 | H33: 0 | I33: 0 | J33: 0 | K33: 0 | L33: 0.05 | M33: 0.5 | N33: 0.5 | O33: 0.4 | P33: 0.2 | Q33: 0.45 | R33: 0.5 | S33: 0.5 | T33: 0.35 | U33: 0.3 | V33: 0.3 | W33: 0.3 | X33: 0.7 | Y33: 0.9 | Z33: 0.7 | AA33: 0.65 | AB33: 0.55 | AC33: 0.35
E34: Sunday | F34: 0.05 | G34: 0 | H34: 0 | I34: 0 | J34: 0 | K34: 0 | L34: 0.05 | M34: 0.5 | N34: 0.5 | O34: 0.2 | P34: 0.2 | Q34: 0.3 | R34: 0.5 | S34: 0.5 | T34: 0.3 | U34: 0.2 | V34: 0.25 | W34: 0.35 | X34: 0.55 | Y34: 0.65 | Z34: 0.7 | AA34: 0.35 | AB34: 0.2 | AC34: 0.2
A35: Kitchen | B35: Kitchen | C35: Lights | D35: T24 2022 - Appendix 5.4B, [Restaurant] Updated based on the equipment schedule from the plug load and schedule project with CEC | E35: Weekday | F35: 0.15 | G35: 0.15 | H35: 0.15 | I35: 0.15 | J35: 0.15 | K35: 0.2 | L35: 0.3 | M35: =M38-5% -> 0.67 | N35: =N38-5% -> 0.73 | O35: =O38-5% -> 0.75 | P35: =P38-5% -> 0.85 | Q35: =Q38-5% -> 0.85 | R35: =R38-5% -> 0.85 | S35: =S38-5% -> 0.83 | T35: =T38-5% -> 0.72 | ... AB35: =AB38-5% -> 0.57 | AC35: 0.3
E36: Saturday | F36: =F39 -> 0.15 | G36: 0.15 | H36: 0.15 | I36: 0.15 | J36: 0.15 | K36: =K39 -> 0.2 | L36: 0.3 | M36: =M39-5% -> 0.67 | N36: =N39-5% -> 0.73 | O36: =O39-5% -> 0.75 | P36: =P39-5% -> 0.85 | Q36: =Q39-5% -> 0.85 | R36: =R39-5% -> 0.85 | S36: =S39-5% -> 0.83 | T36: =T39-5% -> 0.72 | ... AB36: =AB39-5% -> 0.57 | AC36: 0.3
E37: Sunday | F37: 0.2 | G37: 0.15 | H37: 0.15 | I37: 0.15 | J37: 0.15 | K37: 0.15 | L37: 0.3 | M37: =M40-5% -> 0.67 | N37: =N40-5% -> 0.73 | O37: =O40-5% -> 0.75 | P37: =P40-5% -> 0.85 | Q37: =Q40-5% -> 0.85 | R37: =R40-5% -> 0.85 | S37: =S40-5% -> 0.83 | T37: =T40-5% -> 0.72 | ... AB37: =AB40-5% -> 0.57 | AC37: 0.3
A38: Kitchen | B38: Kitchen | C38: ElecEquipment | D38: Plug load and schedules project with CEC, 2025 | E38: Weekday | F38: 0.15 | G38: 0.15 | H38: 0.15 | I38: 0.15 | J38: 0.15 | K38: 0.2 | L38: 0.3 | M38: 0.72 | N38: 0.78 | O38: 0.8 | P38: 0.9 | Q38: 0.9 | R38: 0.9 | S38: 0.88 | T38: 0.77 | U38: 0.7 | V38: 0.72 | W38: 0.8 | X38: 0.9 | Y38: 0.9 | Z38: 0.9 | AA38: 0.8 | AB38: 0.62 | AC38: 0.3 | AM38: =(SUM(F38:AC38)*5+SUM(F39:AC40))*52 -> 5292.56
E39: Saturday | F39: 0.15 | G39: 0.15 | H39: 0.15 | I39: 0.15 | J39: 0.15 | K39: 0.2 | L39: 0.3 | M39: 0.72 | N39: 0.78 | O39: 0.8 | P39: 0.9 | Q39: 0.9 | R39: 0.9 | S39: 0.88 | T39: 0.77 | U39: 0.7 | V39: 0.72 | W39: 0.8 | X39: 0.9 | Y39: 0.9 | Z39: 0.9 | AA39: 0.8 | AB39: 0.62 | AC39: 0.3
E40: Sunday | F40: 0.2 | G40: 0.15 | H40: 0.15 | I40: 0.15 | J40: 0.15 | K40: 0.15 | L40: 0.3 | M40: 0.72 | N40: 0.78 | O40: 0.8 | P40: 0.9 | Q40: 0.9 | R40: 0.9 | S40: 0.88 | T40: 0.77 | U40: 0.7 | V40: 0.72 | W40: 0.8 | X40: 0.9 | Y40: 0.9 | Z40: 0.9 | AA40: 0.8 | AB40: 0.62 | AC40: 0.3
...

Sheet Energy Usage
A1: ="CalBEM Energy Consumption - "&Prototype!A2 -> CalBEM Energy Consumption - RestaurantSitDown | I1: National Average (EnergyStar Portfolio Manager) | N1: CEUS Energy Consumption - Restaurant
