Workbook
Name nonparticipating_forecastzone_scale_factor: #REF!
Name nonparticipating_forecastzone_scale_factor: 'Energy Usage'!#REF!

Sheet Notes
A1: Data Sources
A2: Dataset | C2: DSA Drawings for relocatable schools
B3: Berkeley Lab article | C3: https://www2.lbl.gov/Science-Articles/Archive/EETD-portable-classrooms.html
B4: California Portable Classroom Study | C4: https://ww2.arb.ca.gov/sites/default/files/classic/research/apr/reports/l3006.pdf
B5: California Legislature Environmental Health Conditions in California's Portable Classrooms | C5: https://ww2.arb.ca.gov/sites/default/files/2020-05/pcs_v3_es_03-23-04.pdf
A6: Codes | B6: Title 24, part 6, referred to as T24 (1984, 2001, 2007, 2013, 2016, 2022, 2025)
B7: ASHRAE 90.1 (2022)
B8: CFR Title 10 (2008, 2010, 2025)
A9: Other | B9: ACM 2022
B10: T24 2022 - Appendix 5.4A and Appendix 5.4B | C10: https://www.energy.ca.gov/publications/2022/2022-nonresidential-and-multifamily-alternative-calculation-method-reference
B11: 2022 Reduced infiltration CASE report | C11: https://title24stakeholders.com/wp-content/uploads/2020/10/2022-T24-Final-CASE-Report_Reduce-Infiltration.pdf
B12: 2019 Outdoor Lighting CASE Report | C12: https://title24stakeholders.com/wp-content/uploads/2016/10/T24-2019-CASE-Study-Results-Report-Outdoor-Sources_Final_with-Attachments.pdf
B13: 2019 High Efficiency Fume Hoods in Laboratory Spaces CASE Report | C13: https://title24stakeholders.com/wp-content/uploads/2017/09/2019-T24-CASE-Report_Fume-Hoods_Final_September-2017.pdf?
B14: PNNL 20405, 2011 | C14: https://www.pnnl.gov/main/publications/external/technical_reports/PNNL-20405.pdf
B15: Air leakage Memo, NORESCO, 2025 | C15: Infiltration_rate_report_14May2025-Short-Version.docx
B16: BARD Engineering Specification Guide for SPVHP | C16: BARD Engineering Specification Guide for SPVHP
A18: Construction Rate
A31: Notes

Sheet Prototype
A1: NORESCO, Updated September 2026
A2: SchoolRelocatable
A3: Characteristic | B3: Value | C3: Data Sources
A4: Building Type | B4: Relocatable School
A5: Building Category | B5: Nonresidential
A6: Version | B6: v2-0
A7: Vintages | B7: 4 Vintages: Pre-1978, 1978-1997,1998-2007, 2008-2018 New Construction (2019+) | C7: Based on the vintage bin analysis. A summary of the findings is presented in the following paper, with a link provided in the Notes tab: Yousefi, F., Athalye, R. (2025). “Determining Vintage Bins for Prototype Development: An Analysis of California Commercial Buildings.” ASHRAE Annual Conference.
A8: Shape | C8: The analysis uses prototype geometry originally developed by CEC.
A9: Total Floor Area (ft²) | B9: 1920.19 | C9: Same as CEC prototype
A10: Aspect Ratio | B10: =40/24 -> 1.6666667
A11: Number of Floors | B11: 1
A12: Roof type | B12: Flat
A13: WWR | B13: 0.0515 | C13: Same as CEC prototype
A14: Shading Geometry | B14: No Shades
A15: Floor to floor height (feet) | B15: 12 ft | C15: Typical height
A16: Floor to ceiling height (feet) | B16: 12 ft | C16: Typical height
A17: Glazing sill height (feet) | B17: 2.9 ft | C17: Typical sill height
A21: Above grade wall area (ft²) | B21: 1536.15
A22: Gross wall area (ft²) | B22: =B21+B24 -> 1920.15
A23: Roof area (ft²) | B23: 960.09
A24: Underground Gross Wall Area (ft²) | B24: =(72+120)*2 -> 384

Sheet Zones
A1: ="Proposed Layout - "&Prototype!A2 -> Proposed Layout - SchoolRelocatable
A2: Building | B2: Space/Thermal Zone | C2: Space Type [Primarily from: T24, 2022 Appendix 5.4A] - See Notes column | D2: Space/Thermal Zone | E2: HVAC System Name/AHU Name | F2: Schedule Category | G2: Conditioned (Y/N) | H2: Area Fraction | I2: Area (ft²) | J2: Volume (ft³) | K2: Multipliers | L2: Number of People | M2: People (Persons/1,000 ft²) [T24, 2025,Table 120.1-A] | N2: Notes
A3: SchoolRelocatable | B3: Classroom | C3: Classroom, Lecture, Training, Vocational Areas | D3: Classroom | E3: System 5 | F3: Classroom | G3: Yes | H3: =I3/$I$5 -> 0.5 | I3: 960 | J3: 11521.69 | K3: 1 | L3: =M3*I3/1000 -> 24 | M3: 25
A4: SchoolRelocatable | B4: Crawlspace | C4: Unoccupied-Exclude from Gross Floor Area | D4: Crawlspace | G4: No | H4: =I4/$I$5 -> 0.5 | I4: 960 | J4: 2884 | K4: 1
A5: Total (1 Building) | B5: Total (2 spaces) | C5: Total (2 Space types) | D5: Total (2 spaces) | E5: Total ( 1 HVAC zone) | F5: Total (1 Schedule categories) | G5: Total (1 Conditioned zones) | H5: =I5/$I$5 -> 1 | I5: =SUM(I3:I4) -> 1920 | J5: =SUM(J3:J4) -> 14405.69 | L5: =SUM(L3:L4) -> 24 | M5: =M3 -> 25

Sheet Envelope
A1: ="Envelope - "&Prototype!A2 -> Envelope - SchoolRelocatable
A2: Element | B2: Prototype | C2: Assembly Type | D2: Construction | E2: Thermal Properties | F2: Vintage | G2: Selected T24 | H2: Notes | I2: CZ1 | J2: CZ2 | K2: CZ3 | L2: CZ4 | M2: CZ5 | N2: CZ6 | O2: CZ7 | P2: CZ8 | Q2: CZ9 | R2: CZ10 | S2: CZ11 | T2: CZ12 | U2: CZ13 | V2: CZ14 | W2: CZ15 | X2: CZ16
A3: External Wall | B3: =Prototype!$A$2 -> SchoolRelocatable | C3: ExtWall_MetalFramed_NonRes | D3: Metal framed wall: Metal frame+ insulation + Gypsum board | E3: U-factor IP | F3: Pre 1978 | G3: N/A | H3: Using DOE pre-1980 U-value of 0.227 for school and a 9.2% cumulative wall renovation rate through 2028, based on the average annual rate from CBECS 2003 and 2012 projected over 48 years. | I3: =I45*(1-$I$46)-I44*$I$46 -> 0.1971 | J3: =J45*(1-$I$46)-J44*$I$46 -> 0.200412 | K3: =K45*(1-$I$46)-K44*$I$46 -> 0.198572 | L3: =L45*(1-$I$46)-L44*$I$46 -> 0.200412 | M3: =M45*(1-$I$46)-M44*$I$46 -> 0.200412 | N3: =N45*(1-$I$46)-N44*$I$46 -> 0.1971 | O3: =O45*(1-$I$46)-O44*$I$46 -> 0.1971 | P3: =P45*(1-$I$46)-P44*$I$46 -> 0.200412 | ... X3: =X45*(1-$I$46)-X44*$I$46 -> 0.200412
F4: 1978-1997 | G4: 1992 | H4: TABLE NO. 1-I metal-framed | I4: 0.182 | J4: 0.189 | K4: 0.189 | L4: 0.189 | M4: 0.189 | N4: 0.189 | O4: 0.189 | P4: 0.189 | Q4: 0.189 | R4: 0.189 | S4: 0.182 | T4: 0.182 | U4: 0.182 | V4: 0.182 | W4: 0.182 | X4: 0.182
F5: 1998-2007 | G5: 2001 | H5: TABLE 1-H-NonRes Bldgs | I5: 0.182 | J5: 0.182 | K5: 0.189 | L5: 0.189 | M5: 0.189 | N5: 0.189 | O5: 0.189 | P5: 0.189 | Q5: 0.189 | R5: 0.182 | S5: 0.182 | T5: 0.182 | U5: 0.182 | V5: 0.182 | W5: 0.182 | X5: 0.182
F6: 2008-2018 | G6: 2013 | H6: TABLE 140.3-B-NonRes Bldgs | I6: 0.098 | J6: 0.062 | K6: 0.082 | L6: 0.062 | M6: 0.062 | N6: 0.098 | O6: 0.098 | P6: 0.062 | Q6: 0.062 | R6: 0.062 | S6: 0.062 | T6: 0.062 | U6: 0.062 | V6: 0.062 | W6: 0.062 | X6: 0.062
F7: Existing | H7: Weighted average of all 4 vintages | I7: {=_xlfn.BYCOL(TRANSPOSE(Weights!$C$4:$F$19)*I3:X6,_xlfn.LAMBDA(_xlpm.c,SUM(_xlpm.c)))} -> 0.18765387 | J7: 0.1969387 | K7: 0.19533033 | L7: 0.19701631 | M7: 0.19419811 | N7: 0.19042591 | O7: 0.16913688 | P7: 0.19228621 | Q7: 0.19405971 | R7: 0.17588171 | S7: 0.18972921 | T7: 0.18754155 | U7: 0.18035227 | V7: 0.17980181 | W7: 0.18001191 | X7: 0.17866633
F8: 2019+ | G8: 2025 | H8: TABLE 140.3-B-NonRes Bldgs | I8: 0.06 | J8: 0.055 | K8: 0.071 | L8: 0.055 | M8: 0.055 | N8: 0.06 | O8: 0.06 | P8: 0.055 | Q8: 0.055 | R8: 0.055 | S8: 0.055 | T8: 0.055 | U8: 0.055 | V8: 0.055 | W8: 0.055 | X8: 0.055
A9: Roof | B9: =Prototype!$A$2 -> SchoolRelocatable | C9: FlatRoof_WoodFramedAndOther_NonRes | D9: Metal framed roof: steel truss + cavity insulation + plywood deck + above deck insulation + membrane + coverboard | E9: U-value IP | F9: Pre 1978 | G9: N/A | H9: Considering 30 years for roof/ insulation replacement. | I9: 0.057 | J9: 0.057 | K9: 0.057 | L9: 0.057 | M9: 0.057 | N9: 0.078 | O9: 0.078 | P9: 0.078 | Q9: 0.078 | R9: 0.078 | S9: 0.057 | T9: 0.057 | U9: 0.057 | V9: 0.057 | W9: 0.057 | X9: 0.057
F10: 1978-1997 | G10: 1986 | I10: 0.057 | J10: 0.057 | K10: 0.057 | L10: 0.057 | M10: 0.057 | N10: 0.078 | O10: 0.078 | P10: 0.078 | Q10: 0.078 | R10: 0.078 | S10: 0.057 | T10: 0.057 | U10: 0.057 | V10: 0.057 | W10: 0.057 | X10: 0.057
F11: 1998-2007 | G11: 2001 | H11: Table 1-H | I11: 0.057 | J11: 0.057 | K11: 0.057 | L11: 0.057 | M11: 0.057 | N11: 0.078 | O11: 0.078 | P11: 0.078 | Q11: 0.078 | R11: 0.057 | S11: 0.057 | T11: 0.057 | U11: 0.057 | V11: 0.057 | W11: 0.057 | X11: 0.057
F12: 2008-2018 | G12: 2013 | H12: Table 140.3-B | I12: 0.049 | J12: 0.039 | K12: 0.039 | L12: 0.039 | M12: 0.049 | N12: 0.075 | O12: 0.067 | P12: 0.067 | Q12: 0.039 | R12: 0.039 | S12: 0.039 | T12: 0.039 | U12: 0.039 | V12: 0.039 | W12: 0.039 | X12: 0.039
F13: Existing | H13: Weighted average of all 4 vintages | I13: {=_xlfn.BYCOL(TRANSPOSE(Weights!$C$4:$F$19)*I9:X12,_xlfn.LAMBDA(_xlpm.c,SUM(_xlpm.c)))} -> 0.05673101 | J13: 0.056746801 | K13: 0.056870688 | L13: 0.05687717 | M13: 0.05693769 | N13: 0.077860757 | O13: 0.075304949 | P13: 0.077576533 | Q13: 0.077065993 | R13: 0.066517197 | S13: 0.056650881 | T13: 0.056429947 | U13: 0.055726048 | V13: 0.055137688 | W13: 0.056116529 | X13: 0.05513234
F14: 2019+ | G14: 2025 | H14: Table 140.3-B | I14: 0.028 | J14: 0.028 | K14: 0.028 | L14: 0.028 | M14: 0.028 | N14: 0.047 | O14: 0.047 | P14: 0.047 | Q14: 0.028 | R14: 0.028 | S14: 0.028 | T14: 0.028 | U14: 0.028 | V14: 0.028 | W14: 0.028 | X14: 0.028
A15: Windows_Nonrs | B15: =Prototype!$A$2 -> SchoolRelocatable | C15: OperableWindow_NonRes | D15: Single pane | E15: U-factor IP | F15: Pre 1978 | G15: N/A | H15: ASHRAE Handbook of Fundamentals (Table 4-Ch15) for operable single pane & T24, 2013 for double pane (58%-42%) | I15: =0.58*1.23+0.42*I18 -> 0.9066 | J15: =0.58*1.23+0.42*J18 -> 0.9066 | K15: =0.58*1.23+0.42*K18 -> 0.9066 | L15: =0.58*1.23+0.42*L18 -> 0.9066 | M15: =0.58*1.23+0.42*M18 -> 0.9066 | N15: =0.58*1.23+0.42*N18 -> 0.9066 | O15: =0.58*1.23+0.42*O18 -> 0.9066 | P15: =0.58*1.23+0.42*P18 -> 0.9066 | ... X15: =0.58*1.23+0.42*X18 -> 0.9066
F16: 1978-1997 | G16: N/A | I16: =0.58*1.23+0.42*I18 -> 0.9066 | J16: =0.58*1.23+0.42*J18 -> 0.9066 | K16: =0.58*1.23+0.42*K18 -> 0.9066 | L16: =0.58*1.23+0.42*L18 -> 0.9066 | M16: =0.58*1.23+0.42*M18 -> 0.9066 | N16: =0.58*1.23+0.42*N18 -> 0.9066 | O16: =0.58*1.23+0.42*O18 -> 0.9066 | P16: =0.58*1.23+0.42*P18 -> 0.9066 | ... X16: =0.58*1.23+0.42*X18 -> 0.9066
D17: Double pane | F17: 1998-2007 | G17: 2001 | H17: Table1-H | I17: 0.49 | J17: 0.49 | K17: 0.81 | L17: 0.81 | M17: 0.81 | N17: 0.81 | O17: 0.81 | P17: 0.81 | Q17: 0.81 | R17: 0.49 | S17: 0.49 | T17: 0.49 | U17: 0.49 | V17: 0.49 | W17: 0.49 | X17: 0.49
F18: 2008-2018 | G18: 2013 | H18: Table 140.3-B | I18: 0.46 | J18: 0.46 | K18: 0.46 | L18: 0.46 | M18: 0.46 | N18: 0.46 | O18: 0.46 | P18: 0.46 | Q18: 0.46 | R18: 0.46 | S18: 0.46 | T18: 0.46 | U18: 0.46 | V18: 0.46 | W18: 0.46 | X18: 0.46
F19: Existing | H19: Weighted average of all 4 vintages | I19: {=_xlfn.BYCOL(TRANSPOSE(Weights!$C$4:$F$19)*I15:X18,_xlfn.LAMBDA(_xlpm.c,SUM(_xlpm.c)))} -> 0.85495539 | J19: 0.88432079 | K19: 0.90180402 | L19: 0.90255839 | M19: 0.9007678 | N19: 0.87534283 | O19: 0.7781825 | P19: 0.87875045 | Q19: 0.88746713 | R19: 0.71666223 | S19: 0.86305126 | T19: 0.84701725 | U19: 0.80918545 | V19: 0.79739375 | W19: 0.66487383 | X19: 0.80161374
F20: 2019+ | G20: 2025 | H20: Table 140.3-B | I20: 0.46 | J20: 0.46 | K20: 0.46 | L20: 0.46 | M20: 0.46 | N20: 0.46 | O20: 0.46 | P20: 0.46 | Q20: 0.46 | R20: 0.46 | S20: 0.46 | T20: 0.46 | U20: 0.46 | V20: 0.46 | W20: 0.46 | X20: 0.46
B21: =Prototype!$A$2 -> SchoolRelocatable | C21: OperableWindow_NonRes | D21: Single pane | E21: SHGC | F21: Pre 1978 | G21: N/A | H21: ASHRAE Handbook of Fundamentals (Table 4-Ch15) for operable single pane & T24, 2013 for double pane (58%-42%) | I21: =0.79*0.58+0.42*I24 -> 0.5506 | J21: =0.79*0.58+0.42*J24 -> 0.5506 | K21: =0.79*0.58+0.42*K24 -> 0.5506 | L21: =0.79*0.58+0.42*L24 -> 0.5506 | M21: =0.79*0.58+0.42*M24 -> 0.5506 | N21: =0.79*0.58+0.42*N24 -> 0.5506 | O21: =0.79*0.58+0.42*O24 -> 0.5506 | P21: =0.79*0.58+0.42*P24 -> 0.5506 | ... X21: =0.79*0.58+0.42*X24 -> 0.5506
F22: 1978-1997 | G22: N/A | I22: =0.79*0.58+0.42*I24 -> 0.5506 | J22: =0.79*0.58+0.42*J24 -> 0.5506 | K22: =0.79*0.58+0.42*K24 -> 0.5506 | L22: =0.79*0.58+0.42*L24 -> 0.5506 | M22: =0.79*0.58+0.42*M24 -> 0.5506 | N22: =0.79*0.58+0.42*N24 -> 0.5506 | O22: =0.79*0.58+0.42*O24 -> 0.5506 | P22: =0.79*0.58+0.42*P24 -> 0.5506 | ... X22: =0.79*0.58+0.42*X24 -> 0.5506
D23: Double pane | F23: 1998-2007 | G23: 2001 | H23: Table 1-H (based on non north with WWR 30-40% ) | I23: 0.45 | J23: 0.39 | K23: 0.51 | L23: 0.51 | M23: 0.51 | N23: 0.475 | O23: 0.475 | P23: 0.475 | Q23: 0.475 | R23: 0.39 | S23: 0.39 | T23: 0.39 | U23: 0.39 | V23: 0.39 | W23: 0.39 | X23: 0.45
F24: 2008-2018 | G24: 2013 | H24: Table 140.3-B (100% fixed, 0% operable) | I24: 0.22 | J24: 0.22 | K24: 0.22 | L24: 0.22 | M24: 0.22 | N24: 0.22 | O24: 0.22 | P24: 0.22 | Q24: 0.22 | R24: 0.22 | S24: 0.22 | T24: 0.22 | U24: 0.22 | V24: 0.22 | W24: 0.22 | X24: 0.22
F25: Existing | H25: Weighted average of all 4 vintages | I25: {=_xlfn.BYCOL(TRANSPOSE(Weights!$C$4:$F$19)*I21:X24,_xlfn.LAMBDA(_xlpm.c,SUM(_xlpm.c)))} -> 0.53063904 | J25: 0.53978271 | K25: 0.54755774 | L25: 0.54792623 | M25: 0.54703578 | N25: 0.5270157 | O25: 0.45473313 | P25: 0.5295328 | Q25: 0.53607939 | R25: 0.4590403 | S25: 0.53073899 | T25: 0.52261318 | U25: 0.50183328 | V25: 0.49210884 | W25: 0.44963793 | X25: 0.50213518
F26: 2019+ | G26: 2025 | H26: Table 140.3-B (100% fixed, 0% operable) | I26: 0.22 | J26: 0.22 | K26: 0.22 | L26: 0.22 | M26: 0.22 | N26: 0.22 | O26: 0.22 | P26: 0.22 | Q26: 0.22 | R26: 0.22 | S26: 0.22 | T26: 0.22 | U26: 0.22 | V26: 0.22 | W26: 0.22 | X26: 0.22
A27: * California Legislature Environmental Health Conditions in California's Portable Classrooms
C29: Infiltration
D30: Building | E30: Zones | F30: Vintage | G30: I_75 6-Sided Infiltration rate @ 75 pa | H30: Note | I30: I-design (cfm/ft²) (4-sided Infiltration rate at normal pressure) (Design flow rate approach and Flow/Exterior Wall Area calculation method) | AU30: 0.028 | AW30: 0.028
C31: Infiltration | D31: SchoolRelocatable | E31: Classroom | F31: Pre 1978 | G31: 1.1 | H31: 2022 CASE report (Table 38) | I31: 0.308
F32: 1978-1997 | G32: 1.1 | H32: 2022 CASE report (Table 38) | I32: 0.308
F33: 1998-2007 | G33: 1.1 | H33: 2022 CASE report (Table 38) | I33: 0.308
F34: 2008-2018 | G34: 1 | H34: 2022 CASE report (Table 38) & T24, 2008-2016 (Table 140.3-B)--Air barrier is required in CZ 10-16 | I34: 0.2818
F35: Existing | H35: Same as Pre 2008 because of their higher weights | I35: =I33 -> 0.308
F36: 2019+ | G36: 0.6 | H36: 2022 CASE report (Table 38) & T24, 2025 (Table 140.3-B)--Air barrier is required in all CZs | I36: 0.168
E37: Source: T24 air barrier requirements (all editions) and the standardized infiltration rate reported in the 2022 CASE report and Dodge 2023 data
E38: Air Leakage Memo: | G38: Infiltration_rate_report_14May2025-Short-Version.docx
A42: Pre-1978 exterior wall U value calculation:
A43: External Wall | B43: SchoolRelocatable | C43: ExtWall_MetalFramed_NonRes | D43: Metal framed wall: Metal frame + insulation + Gypsum board | E43: U-value IP | F43: Pre 1978 | G43: N/A | H43: ASHRAE 90.1-2022 Table A3.3.3.1 (metal-framed), 3.5 in., R-0 | I43: 0.352 | J43: 0.352 | K43: 0.352 | L43: 0.352 | M43: 0.352 | N43: 0.352 | O43: 0.352 | P43: 0.352 | Q43: 0.352 | R43: 0.352 | S43: 0.352 | T43: 0.352 | U43: 0.352 | V43: 0.352 | W43: 0.352 | X43: 0.352
H44: T24 2008 (U value): Metal framed wall Nonres | I44: 0.098 | J44: 0.062 | K44: 0.082 | L44: 0.062 | M44: 0.062 | N44: 0.098 | O44: 0.098 | P44: 0.062 | Q44: 0.062 | R44: 0.062 | S44: 0.062 | T44: 0.062 | U44: 0.062 | V44: 0.062 | W44: 0.062 | X44: 0.062
...

Sheet HVAC System
A1: ="HVAC system - "&Prototype!A2 -> HVAC system - SchoolRelocatable
A2: Vintage | B2: Zones | C2: Heating | D2: Cooling | E2: Air Distribution | F2: Other System | G2: Source | H2: Note
A3: Existing | B3: Classroom, Lecture, Training, Vocational Areas | C3: SPVHP | D3: DX Coil | E3: CAV | F3: Economizer* Fix Dry bulb; integrated; High DB Temperature Lockout: 75 °F | G3: ACM 2025 | H3: System 3b
A4: New Construction | B4: Classroom, Lecture, Training, Vocational Areas | C4: SPVHP | D4: DX Coil | E4: CAV | F4: Economizer* Fix Dry bulb; integrated; High DB Temperature Lockout: 75 °F | G4: ACM 2025 | H4: System 3b
A9: Efficiency of HVAC system (Efficiency is capacity-dependent. The following table provides a general estimate of system efficiency based on preliminary simulations in one climate zone, or assuming cooling load based on rule of thumb)
A10: Vintage | B10: Upgrade/Installed year | C10: Heating DX | D10: Supplementary Heating Coil | E10: Cooling DX | F10: Source | H10: Note
A11: Pre 1978 | B11: 2008 | C11: COP = 3 | D11: Efficiency: 100% (Electric) | E11: EER = 9.0 | F11: 10 CFR 431.97, Table 10 to paragraph (e)(2): SPVHP <65,000 Btu/h → EER 9.0, COP 3.0 (federal standard effective Jan 1, 2010; used here for legacy/vintage modeling consistency) | H11: System 3b
A12: 1978-1997
A13: 1998-2007
A14: 2008-2018 | B14: 2013 | C14: COP = 3 | D14: Efficiency: 100% (Electric) | E14: EER = 9.0 | F14: 10 CFR 431.97, Table 10 to paragraph (e)(2): SPVHP <65,000 Btu/h → EER 9.0, COP 3.0 (still governing in 2013; later update came in 2019)
A15: New Construction | B15: 2025 | C15: COP = 3.3 | D15: Efficiency: 100% (Electric) | E15: EER = 11.0 | F15: CEC 2025 Space-Conditioning Efficiency Tables, Table 5 (row: SPVHP <65,000 Btu/h → EER 11.0, COP 3.3, test AHRI 390). The table cites 10 CFR 431 Subpart F as the federal basis | H15: System 3b
A18: Fan power
A19: Vintage | B19: Approach | C19: System | D19: Total Static Pressure (TSP) (in w.c.) | E19: Fan Efficiency [ACM 2025] | F19: Motor Efficiency | G19: Fan Power Index (W/cfm) | H19: Data Source
A20: Existing | B20: PNNL 90.1-2011, TSP | C20: CAV, SPVHP classroom, design airflow < 7,437 cfm | D20: 2.5 | E20: 0.65 | F20: ASHRAE 90.1, 2004, Table 10.8 * | H20: Fan power formula: PNNL 20405, 2010, section 5.2.2.5 TSP and fan efficiency: PNNL 20405, 2010, Table 5.11, 90.1-04ac values Motor and drive efficiency: ASHRAE 90.1, 2004, Table 10.8 | I20: PNNL 20405, 2010, Table 5.11
A21: Brake horsepower (bhp) = (Supply cfm × TSP in w.c.) / (6356 × fan efficiency)
A22: Fan power (w/cfm) = (bhp × 746) / ( supply cfm × motor efficiency )
A23: New Construction | B23: ACM 2025 | C23: SPVHP (System 3b), CAV classroom, ≤5,000 cfm | D23: TSP = fan power × motor efficiency × fan efficiency × 6356 / 746 | E23: 0.65 | F23: 2025 ACM Table 12 ** | G23: 0.744 | H23: Fan power index: [ACM 2025, Table 13] Motor efficiency: [ACM 2025, Table 12]
A25: * According to PNNL 20405 section 5.2.2.5, the full-load efficiency of the motor serving the fan is taken from ASHRAE 90.1, 2004, Table 10.8, based on motor nameplate and assuming enclosed motors operating at 1,800 rotations per minute (rpm) Motor nameplate size (bhp) = brake horsepower (bhp) × 1.1 ( using a 10% oversizing factor)
A26: ** The full‑load efficiency of the motor serving the fan is taken from ACM 2025 Table 12 based on the cfm of the fan. Brake horsepower (bhp) = (Supply cfm from sizing run × fan power in W/cfm) / 746. Note: Same index as Hotel Small System 3b SZHP ≤5,000 cfm.
A31: Background Data [To be deleted prior to publication]

Sheet Thermostat
A1: ="Thermostat Setpoints - "&Prototype!A2 -> Thermostat Setpoints - SchoolRelocatable
A2: Setpoint | B2: CZ1 | C2: CZ2 | D2: CZ3 | E2: CZ4 | F2: CZ5 | G2: CZ6 | H2: CZ7 | I2: CZ8 | J2: CZ9 | K2: CZ10 | L2: CZ11 | M2: CZ12 | N2: CZ13 | O2: CZ14 | P2: CZ15 | Q2: CZ16 | R2: Source
A3: School Heating Setpoint (F) | B3: 70 | C3: 70 | D3: 70 | E3: 70 | F3: 70 | G3: 70 | H3: 70 | I3: 70 | J3: 70 | K3: 70 | L3: 70 | M3: 70 | N3: 70 | O3: 70 | P3: 70 | Q3: 70 | R3: T24 2022 - Appendix 5.4B
A4: School Heating Setback (F) | B4: 60 | C4: 60 | D4: 60 | E4: 60 | F4: 60 | G4: 60 | H4: 60 | I4: 60 | J4: 60 | K4: 60 | L4: 60 | M4: 60 | N4: 60 | O4: 60 | P4: 60 | Q4: 60
A5: School Cooling Setpoint (F) | B5: 75 | C5: 75 | D5: 75 | E5: 75 | F5: 75 | G5: 75 | H5: 75 | I5: 75 | J5: 75 | K5: 75 | L5: 75 | M5: 75 | N5: 75 | O5: 75 | P5: 75 | Q5: 75 | R5: T24 2022 - Appendix 5.4B
A6: School Cooling Setback (F) | B6: 85 | C6: 85 | D6: 85 | E6: 85 | F6: 85 | G6: 85 | H6: 85 | I6: 85 | J6: 85 | K6: 85 | L6: 85 | M6: 85 | N6: 85 | O6: 85 | P6: 85 | Q6: 85

Sheet Ventilation
A1: ="Outdoor Airflow Rate - "&Prototype!A2 -> Outdoor Airflow Rate - SchoolRelocatable
A2: Space Type | B2: Space/Thermal Zone | C2: Number of People | D2: Floor Area (ft²) | E2: cfm/person [T24, 2025, Equation 120.1-F and Table 120.1-A] | F2: cfm/ft² [T24, 2025, Equation 120.1-F and Table 120.1-A] | G2: Required exhaust rate-CFM/ft²- [T24, 2025, Table 120.1-B – minimum exhaust rates] | H2: Total cfm driven by people | I2: Total cfm driven by area | J2: Total cfm driven by exhaust | K2: Total cfm | L2: Notes
A3: =Zones!C3 -> Classroom, Lecture, Training, Vocational Areas | B3: =Zones!D3 -> Classroom | C3: =Zones!L3 -> 24 | D3: =Zones!I3 -> 960 | E3: 15 | F3: 0.15 | H3: =C3*E3 -> 360 | I3: =D3*F3 -> 144 | J3: =G3*D3 -> 0 | K3: =MAX(H3,I3,J3) -> 360
A4: =Zones!C4 -> Unoccupied-Exclude from Gross Floor Area | B4: =Zones!D4 -> Crawlspace | C4: =Zones!L4 -> 0 | D4: =Zones!I4 -> 960 | H4: =C4*E4 -> 0 | I4: =D4*F4 -> 0 | J4: =G4*D4 -> 0 | K4: =MAX(H4,I4,J4) -> 0
B5: =Zones!D5 -> Total (2 spaces) | C5: =Zones!L5 -> 24 | D5: =Zones!I5 -> 1920 | H5: =SUM(H3:H4) -> 360 | I5: =SUM(I3:I4) -> 144 | J5: =SUM(J3:J4) -> 0 | K5: =SUM(K3:K4) -> 360

Sheet Water Heater
A1: ="Water Heater -"&Prototype!A2 -> Water Heater -SchoolRelocatable
A2: Vintage | B2: WH Type | C2: Efficiency | D2: Number of WH | E2: Tank Volume (gal) | F2: Tank Loss | G2: Source | H2: Notes
A3: Existing | B3: Electric | C3: 1 | D3: 1 | E3: ="See "&A26&" Table, Storage Volume column (col F)" -> See CZ05 Table, Storage Volume column (col F) | F3: See Climate Zone Water Heater Sizing and Loss Coefficients Table, Standby Loss column (col G) | H3: Electric kept for Existing: a relocatable classroom normally has no gas service, so the gas storage water heater used for the permanent school prototypes (CEUS 2022) is not applied here.
A4: New Construction | B4: Electric | C4: 1 | D4: 1 | E4: =E3 -> See CZ05 Table, Storage Volume column (col F) | F4: See Climate Zone Water Heater Sizing and Loss Coefficients Table, Standby Loss column (col G) | H4: Section 1605.1. Federal and State Standards for Federally-Regulated Appliances. Electric storage standby loss: Title 20 Table F-4 (0.30 + 27/Vm %/hr).
A7: Peak Hot Water Consumption
A8: Space Name | B8: Baseline WH Type [T24, 2022, Appendix 5.4A , sheet: "2022 SpaceFuncData-Input"] | C8: New Construction: Baseline WH Type ACM 2025 | D8: Total Area (ft²) | E8: Number of People | F8: Hot Water Usage Specification (gal/hr per person) [T24, 2022, Appendix 5.4A , sheet: "2022 SpaceFuncData-Input"] | G8: Peak Hot Water Usage (gal/hr) | H8: Peak Hot Water Usage (gal/min)
A9: =Zones!D3 -> Classroom | B9: Electric | C9: Electric | D9: =Zones!I3 -> 960 | E9: =Zones!L3 -> 24 | F9: 0.18 | G9: =F9*E9 -> 4.32 | H9: =G9/60 -> 0.072
A10: Total | D10: =SUM(D9:D9) -> 960 | E10: =SUM(E9:E9) -> 24 | F10: =F9 -> 0.18 | G10: =SUM(G9:G9) -> 4.32 | H10: =G10/60 -> 0.072
B11: Gas storage | G11: =_xlfn.LET( _xlpm.g,SUMIF($B$9:$B$10,"Gas*",$F$9:$F$10), _xlpm.e,SUMIF($B$9:$B$10,"Electric*",$F$9:$F$10), IF(AND(_xlpm.g>0,_xlpm.e>0),_xlpm.g,IF(_xlpm.g>0,MAX(75,_xlpm.g),0))) -> 0 | H11: Minimum peak hot water usage is 75 gal according to ACM 2025
B12: Electric resistance | G12: =_xlfn.LET( _xlpm.g,SUMIF($B$9:$B$10,"Gas*",$F$9:$F$10), _xlpm.e,SUMIF($B$9:$B$10,"Electric*",$F$9:$F$10), IF(AND(_xlpm.g>0,_xlpm.e>0),_xlpm.e,IF(_xlpm.e>0,MAX(75,_xlpm.e),0))) -> 75
A14: Maximum flow rate (GPM) | B14: 0.5 | C14: CALGreen §5.303.3.4.1 (Title 24, Part 11, 2025)
A15: Design supply temperature (°F) | B15: 135 | C15: Title 24 2022 Reference Appendices, Appendix 5.4B
A16: WH system factor | B16: 0.6 | C16: Not used for tankless (column D = C). 2025 ACM §5.9.2 storage system factor.
A17: Water mass conversion (lb/gal) | B17: 8.2877 | C17: 2025 ACM §5.9.2 Rated Capacity
A18: Tankless storage volume (gal) | B18: 2 | C18: Title 20 instantaneous class (storage typically <2 gal); scorecard uses 2.
A20: Climate Zone Water Heater Sizing and Loss Coefficients
A21: Climate Zone | B21: Minimum Monthly Mains Temp (°F) [T24 2022 - Appendix 5.4B] | C21: Heat Output (Btu/hr) [ACM, 2025, 5.9.2: Rated capacity section] | D21: WH Capacity (Btu/hr) [ACM, 2025, 5.9.2: Rated capacity section] | E21: Required Energy Input (Btu/hr) | F21: Storage Volume (gal) | G21: Standby Loss [Title 20, §1605.1 Table F-4; Appendix B: Water Heating Calculation Method] | I21: Off/On Cycle Loss Coefficient to Ambient Temp | K21: Source/Note
A22: CZ01 | B22: 47.9 | C22: =$B$14*60*($B$15-B22)*$B$17 -> 21655.76 | D22: =C22 -> 21655.76 | E22: =_xlfn.LET(_xlpm.x,_xlfn.XLOOKUP(D22,$B$43:$B$49,$B$43:$B$49,"",1),IF(_xlpm.x="",D22,_xlpm.x)) -> 27296 | F22: =$B$18 -> 2 | G22: 0 | H22: %/hr | I22: 0 | J22: Btu/h·°F | K22: Required Energy Input: vendor/available catalog size (Market data table). Storage Volume: standard/available catalog tank size (Market data table).
A23: CZ02 | B23: 50.8 | C23: =$B$14*60*($B$15-B23)*$B$17 -> 20934.73 | D23: =C23 -> 20934.73 | E23: =_xlfn.LET(_xlpm.x,_xlfn.XLOOKUP(D23,$B$43:$B$49,$B$43:$B$49,"",1),IF(_xlpm.x="",D23,_xlpm.x)) -> 27296 | F23: =$B$18 -> 2 | G23: 0 | H23: %/hr | I23: 0 | J23: Btu/h·°F
A24: CZ03 | B24: 52.2 | C24: =$B$14*60*($B$15-B24)*$B$17 -> 20586.647 | D24: =C24 -> 20586.647 | E24: =_xlfn.LET(_xlpm.x,_xlfn.XLOOKUP(D24,$B$43:$B$49,$B$43:$B$49,"",1),IF(_xlpm.x="",D24,_xlpm.x)) -> 27296 | F24: =$B$18 -> 2 | G24: 0 | H24: %/hr | I24: 0 | J24: Btu/h·°F
A25: CZ04 | B25: 52.7 | C25: =$B$14*60*($B$15-B25)*$B$17 -> 20462.331 | D25: =C25 -> 20462.331 | E25: =_xlfn.LET(_xlpm.x,_xlfn.XLOOKUP(D25,$B$43:$B$49,$B$43:$B$49,"",1),IF(_xlpm.x="",D25,_xlpm.x)) -> 20472 | F25: =$B$18 -> 2 | G25: 0 | H25: %/hr | I25: 0 | J25: Btu/h·°F
A26: CZ05 | B26: 51.6 | C26: =$B$14*60*($B$15-B26)*$B$17 -> 20735.825 | D26: =C26 -> 20735.825 | E26: =_xlfn.LET(_xlpm.x,_xlfn.XLOOKUP(D26,$B$43:$B$49,$B$43:$B$49,"",1),IF(_xlpm.x="",D26,_xlpm.x)) -> 27296 | F26: =$B$18 -> 2 | G26: 0 | H26: %/hr | I26: 0 | J26: Btu/h·°F
A27: CZ06 | B27: 56.8 | C27: =$B$14*60*($B$15-B27)*$B$17 -> 19442.944 | D27: =C27 -> 19442.944 | E27: =_xlfn.LET(_xlpm.x,_xlfn.XLOOKUP(D27,$B$43:$B$49,$B$43:$B$49,"",1),IF(_xlpm.x="",D27,_xlpm.x)) -> 20472 | F27: =$B$18 -> 2 | G27: 0 | H27: %/hr | I27: 0 | J27: Btu/h·°F
A28: CZ07 | B28: 58.4 | C28: =$B$14*60*($B$15-B28)*$B$17 -> 19045.135 | D28: =C28 -> 19045.135 | E28: =_xlfn.LET(_xlpm.x,_xlfn.XLOOKUP(D28,$B$43:$B$49,$B$43:$B$49,"",1),IF(_xlpm.x="",D28,_xlpm.x)) -> 20472 | F28: =$B$18 -> 2 | G28: 0 | H28: %/hr | I28: 0 | J28: Btu/h·°F
A29: CZ08 | B29: 58.4 | C29: =$B$14*60*($B$15-B29)*$B$17 -> 19045.135 | D29: =C29 -> 19045.135 | E29: =_xlfn.LET(_xlpm.x,_xlfn.XLOOKUP(D29,$B$43:$B$49,$B$43:$B$49,"",1),IF(_xlpm.x="",D29,_xlpm.x)) -> 20472 | F29: =$B$18 -> 2 | G29: 0 | H29: %/hr | I29: 0 | J29: Btu/h·°F
A30: CZ09 | B30: 57.6 | C30: =$B$14*60*($B$15-B30)*$B$17 -> 19244.039 | D30: =C30 -> 19244.039 | E30: =_xlfn.LET(_xlpm.x,_xlfn.XLOOKUP(D30,$B$43:$B$49,$B$43:$B$49,"",1),IF(_xlpm.x="",D30,_xlpm.x)) -> 20472 | F30: =$B$18 -> 2 | G30: 0 | H30: %/hr | I30: 0 | J30: Btu/h·°F
A31: CZ10 | B31: 57.1 | C31: =$B$14*60*($B$15-B31)*$B$17 -> 19368.355 | D31: =C31 -> 19368.355 | E31: =_xlfn.LET(_xlpm.x,_xlfn.XLOOKUP(D31,$B$43:$B$49,$B$43:$B$49,"",1),IF(_xlpm.x="",D31,_xlpm.x)) -> 20472 | F31: =$B$18 -> 2 | G31: 0 | H31: %/hr | I31: 0 | J31: Btu/h·°F
A32: CZ11 | B32: 50.5 | C32: =$B$14*60*($B$15-B32)*$B$17 -> 21009.319 | D32: =C32 -> 21009.319 | E32: =_xlfn.LET(_xlpm.x,_xlfn.XLOOKUP(D32,$B$43:$B$49,$B$43:$B$49,"",1),IF(_xlpm.x="",D32,_xlpm.x)) -> 27296 | F32: =$B$18 -> 2 | G32: 0 | H32: %/hr | I32: 0 | J32: Btu/h·°F
A33: CZ12 | B33: 51.4 | C33: =$B$14*60*($B$15-B33)*$B$17 -> 20785.552 | D33: =C33 -> 20785.552 | E33: =_xlfn.LET(_xlpm.x,_xlfn.XLOOKUP(D33,$B$43:$B$49,$B$43:$B$49,"",1),IF(_xlpm.x="",D33,_xlpm.x)) -> 27296 | F33: =$B$18 -> 2 | G33: 0 | H33: %/hr | I33: 0 | J33: Btu/h·°F
A34: CZ13 | B34: 51.7 | C34: =$B$14*60*($B$15-B34)*$B$17 -> 20710.962 | D34: =C34 -> 20710.962 | E34: =_xlfn.LET(_xlpm.x,_xlfn.XLOOKUP(D34,$B$43:$B$49,$B$43:$B$49,"",1),IF(_xlpm.x="",D34,_xlpm.x)) -> 27296 | F34: =$B$18 -> 2 | G34: 0 | H34: %/hr | I34: 0 | J34: Btu/h·°F
... A37: CZ16 | B37: 41.4 | C37: =$B$14*60*($B$15-B37)*$B$17 -> 23271.862 | D37: =C37 -> 23271.862 | E37: =_xlfn.LET(_xlpm.x,_xlfn.XLOOKUP(D37,$B$43:$B$49,$B$43:$B$49,"",1),IF(_xlpm.x="",D37,_xlpm.x)) -> 27296 | F37: =$B$18 -> 2 | G37: 0 | H37: %/hr | I37: 0 | J37: Btu/h·°F
A41: Market data
A42: Catalog input (kW) | B42: Input (Btu/h) | C42: Max GPM | D42: UEF | E42: Source | F42: =HYPERLINK("#'Note'!A1","Sources and links → Note tab") -> Sources and links → Note tab
A43: 2.5 | B43: =A43*3412 -> 8530 | C43: 0.5 | D43: 0.99 | E43: Grainger
A44: 4.5 | B44: =A44*3412 -> 15354 | C44: 0.5 | D44: 0.99 | E44: Grainger
A45: 6 | B45: =A45*3412 -> 20472 | C45: 0.7 | D45: 0.99 | E45: Grainger
A46: 8 | B46: =A46*3412 -> 27296 | C46: 1 | D46: 0.93 | E46: Grainger
A47: 11 | B47: =A47*3412 -> 37532 | C47: 1.5 | D47: 0.93 | E47: Grainger
A48: 18 | B48: =A48*3412 -> 61416 | C48: 2 | D48: 0.93 | E48: Grainger
A49: 27 | B49: =A49*3412 -> 92124 | C49: 2.5 | D49: 0.93 | E49: Grainger

Sheet Interior Lights
A1: ="Interior Lighting - "&Prototype!A2 -> Interior Lighting - SchoolRelocatable
A2: Space Type | B2: New Construction | E2: Existing | H2: Notes
B3: Lighting density (W/ft²) | C3: Additional lighting power allowance (W/ftÂ²) [Table 140.6-C footnoted allowance] | D3: Source | E3: LPD (W/ft²) | F3: Additional lighting power allowance (W/ftÂ²) [Table 140.6-C footnoted allowance] | G3: Source
A4: =Zones!C3 -> Classroom, Lecture, Training, Vocational Areas | B4: 0.6 | D4: T24, 2025, Table 140.6 C (Area category method) | E4: 1.2 | G4: T24, 2016, Table 140.6 C (Area category method)
A5: =Zones!C4 -> Unoccupied-Exclude from Gross Floor Area | B5: 0 | E5: 0
A7: Additional allowances are the full Table 140.6-C value for the footnoted lighting system (New Construction: T24 2025; Existing: T24 2016). The allowance only applies where that lighting system is installed. White board/chalk board allowances are per linear foot and are not included.

Sheet Ext Lighting
A1: ="Exterior Lighting - "&Prototype!A2 -> Exterior Lighting - SchoolRelocatable
A2: Motion Controlled Luminaires (W) | B2: Non-motion Controlled Luminaires (W) | C2: Total (W) | D2: Source
A3: =G14 -> 200 | B3: =G15 -> 307.87207 | C3: =A3+B3 -> 507.87207 | D3: T24, 2022 & 2025 2019 Outdoor Lighting CASE report PNNL 90.1-2010 TSD
A7: ="Exterior Lighting" -> Exterior Lighting
A8: Items (Assume LZ2) | B8: Assumptions [2019 Outdoor Lighting CASE Report & PNNL 90.1-2010 TS] | D8: Unit | E8: Lighting Power Allowance [T24, 2025, Table 140.7-A & 140.7-B] | F8: Unit | G8: Exterior Lighting Power (W)
A9: IWA (Initial Wattage Allowance) | E9: 200 | F9: (W) | G9: =$E9 -> 200
A10: Parking area | B10: 400 ft² for every parking space 1 parking space per 830 ft² of gross building area | C10: 0 | D10: (ft²) | E10: 0.019 | F10: (W/ft²) | G10: =E10*C10 -> 0
A11: Building Entrance | B11: 5 building entrance per PNNL Model (1 per 10,000 ft² footprint) | C11: 0 | D11: (count) | E11: 15 | F11: (W/ea) | G11: =E11*C11 -> 0
A12: Hardscape Ornamental Light | B12: 0.1 ft² per 1 ft² of gross building area for hardscape ornamental light | C12: =B24*0.1 -> 96.0095 | D12: (ft²) | E12: 0.007 | F12: (W/ft²) | G12: =E12*C12 -> 0.6720665
A13: Building façade | B13: 0.1 W per 1 ft² of facade area Façade Area = Perimeter × 0.5 × max ( height and 30) (30 ft is the max height that is lit) * The 0.5 factor assumes that only half of the perimeter walls are lit. -Formula is developed based on the 2019 Outdoor Lighting CASE report | C13: =0.5*4*(B23*B20) -> 3072 | D13: (ft²) | E13: 0.1 | F13: (W/ft²) | G13: =E13*C13 -> 307.2
A14: Motion Controlled Luminaires (W) | G14: =G10+G9+G11 -> 200
A15: Non-motion-controlled Luminaires | G15: =G12+G13 -> 307.87207
A16: Total | G16: =G14+G15 -> 507.87207
A20: Max Height (ft) | B20: 12
A21: Building footprint | B21: =B24/2 -> 480.0475
A22: Floors | B22: 1
A23: Perimeter(ft) | B23: =(24+40)*2 -> 128
A24: Total floor area (ft²) | B24: =Prototype!B9/2 -> 960.095

Sheet Equipment
A1: ="Equipment - "&Prototype!A2 -> Equipment - SchoolRelocatable
A2: Space Type | B2: Plug load Power Density (W/ft²) | C2: Gas Power Density (Btu/hr-ft²) | D2: Refrigeration Power Density (W/ft²) | E2: Source
A3: =Zones!C3 -> Classroom, Lecture, Training, Vocational Areas | B3: 0.8 | C3: 0 | D3: 0 | E3: T24 2022 - Appendix 5.4A
A4: =Zones!C4 -> Unoccupied-Exclude from Gross Floor Area | B4: 0 | C4: 0 | D4: 0

Sheet Schedules
A1: ="Schedules - "&Prototype!A2 -> Schedules - SchoolRelocatable
A2: Zone | B2: Schedule Category | C2: Schedule | D2: Source | E2: Type | F2: Hour
F3: 1 | G3: 2 | H3: 3 | I3: 4 | J3: 5 | K3: 6 | L3: 7 | M3: 8 | N3: 9 | O3: 10 | P3: 11 | Q3: 12 | R3: 13 | S3: 14 | T3: 15 | U3: 16 | V3: 17 | W3: 18 | X3: 19 | Y3: 20 | Z3: 21 | AA3: 22 | AB3: 23 | AC3: 24
A4: All zones (single classroom zone) | B4: Classroom | C4: Occupancy | D4: T24 2022 - Appendix 5.4B [School] | E4: Weekday | F4: 0 | G4: 0 | H4: 0 | I4: 0 | J4: 0 | K4: 0 | L4: 0 | M4: 0.05 | N4: 0.75 | O4: 0.9 | P4: 0.9 | Q4: 0.8 | R4: 0.8 | S4: 0.8 | T4: 0.8 | U4: 0.45 | V4: 0.15 | W4: 0.05 | X4: 0.15 | Y4: 0.2 | Z4: 0.2 | AA4: 0.1 | AB4: 0 | AC4: 0
E5: Saturday | F5: 0 | G5: 0 | H5: 0 | I5: 0 | J5: 0 | K5: 0 | L5: 0 | M5: 0 | N5: 0.1 | O5: 0.1 | P5: 0.1 | Q5: 0.1 | R5: 0.1 | S5: 0 | T5: 0 | U5: 0 | V5: 0 | W5: 0 | X5: 0 | Y5: 0 | Z5: 0 | AA5: 0 | AB5: 0 | AC5: 0
E6: Sunday | F6: 0 | G6: 0 | H6: 0 | I6: 0 | J6: 0 | K6: 0 | L6: 0 | M6: 0 | N6: 0 | O6: 0 | P6: 0 | Q6: 0 | R6: 0 | S6: 0 | T6: 0 | U6: 0 | V6: 0 | W6: 0 | X6: 0 | Y6: 0 | Z6: 0 | AA6: 0 | AB6: 0 | AC6: 0
A7: All zones (single classroom zone) | B7: Classroom | C7: Lights | D7: T24 2022 - Appendix 5.4B [School] | E7: Weekday | F7: 0.05 | G7: 0.05 | H7: 0.05 | I7: 0.05 | J7: 0.05 | K7: 0.05 | L7: 0.05 | M7: 0.3 | N7: 0.6 | O7: 0.65 | P7: 0.65 | Q7: 0.65 | R7: 0.55 | S7: 0.55 | T7: 0.55 | U7: 0.5 | V7: 0.35 | W7: 0.35 | X7: 0.35 | Y7: 0.35 | Z7: 0.35 | AA7: 0.3 | AB7: 0.05 | AC7: 0.05
E8: Saturday | F8: 0.05 | G8: 0.05 | H8: 0.05 | I8: 0.05 | J8: 0.05 | K8: 0.05 | L8: 0.05 | M8: 0.05 | N8: 0.15 | O8: 0.15 | P8: 0.15 | Q8: 0.15 | R8: 0.15 | S8: 0.05 | T8: 0.05 | U8: 0.05 | V8: 0.05 | W8: 0.05 | X8: 0.05 | Y8: 0.05 | Z8: 0.05 | AA8: 0.05 | AB8: 0.05 | AC8: 0.05
E9: Sunday | F9: 0.05 | G9: 0.05 | H9: 0.05 | I9: 0.05 | J9: 0.05 | K9: 0.05 | L9: 0.05 | M9: 0.05 | N9: 0.05 | O9: 0.05 | P9: 0.05 | Q9: 0.05 | R9: 0.05 | S9: 0.05 | T9: 0.05 | U9: 0.05 | V9: 0.05 | W9: 0.05 | X9: 0.05 | Y9: 0.05 | Z9: 0.05 | AA9: 0.05 | AB9: 0.05 | AC9: 0.05
A10: All zones (single classroom zone) | B10: Classroom | C10: ElecEquipment | D10: T24 2022 - Appendix 5.4B [School] | E10: Weekday | F10: 0.05 | G10: 0.05 | H10: 0.05 | I10: 0.05 | J10: 0.05 | K10: 0.05 | L10: 0.05 | M10: 0.3 | N10: 0.85 | O10: 0.95 | P10: 0.95 | Q10: 0.95 | R10: 0.8 | S10: 0.8 | T10: 0.8 | U10: 0.7 | V10: 0.5 | W10: 0.5 | X10: 0.35 | Y10: 0.35 | Z10: 0.35 | AA10: 0.3 | AB10: 0.05 | AC10: 0.05
E11: Saturday | F11: 0.05 | G11: 0.05 | H11: 0.05 | I11: 0.05 | J11: 0.05 | K11: 0.05 | L11: 0.05 | M11: 0.05 | N11: 0.15 | O11: 0.15 | P11: 0.15 | Q11: 0.15 | R11: 0.15 | S11: 0.05 | T11: 0.05 | U11: 0.05 | V11: 0.05 | W11: 0.05 | X11: 0.05 | Y11: 0.05 | Z11: 0.05 | AA11: 0.05 | AB11: 0.05 | AC11: 0.05
E12: Sunday | F12: 0.05 | G12: 0.05 | H12: 0.05 | I12: 0.05 | J12: 0.05 | K12: 0.05 | L12: 0.05 | M12: 0.05 | N12: 0.05 | O12: 0.05 | P12: 0.05 | Q12: 0.05 | R12: 0.05 | S12: 0.05 | T12: 0.05 | U12: 0.05 | V12: 0.05 | W12: 0.05 | X12: 0.05 | Y12: 0.05 | Z12: 0.05 | AA12: 0.05 | AB12: 0.05 | AC12: 0.05
A13: All zones (single classroom zone) | B13: Classroom | C13: ServiceHotWater | D13: T24 2022 - Appendix 5.4B [School] | E13: Weekday | F13: 0.05 | G13: 0.05 | H13: 0.05 | I13: 0.05 | J13: 0.05 | K13: 0.05 | L13: 0.05 | M13: 0.1 | N13: 0.34 | O13: 0.6 | P13: 0.63 | Q13: 0.72 | R13: 0.79 | S13: 0.83 | T13: 0.61 | U13: 0.65 | V13: 0.1 | W13: 0.1 | X13: 0.19 | Y13: 0.25 | Z13: 0.22 | AA13: 0.22 | AB13: 0.12 | AC13: 0.09
E14: Saturday | F14: 0.03 | G14: 0.03 | H14: 0.03 | I14: 0.03 | J14: 0.03 | K14: 0.03 | L14: 0.03 | M14: 0.03 | N14: 0.03 | O14: 0.05 | P14: 0.05 | Q14: 0.05 | R14: 0.05 | S14: 0.03 | T14: 0.03 | U14: 0.03 | V14: 0.03 | W14: 0.03 | X14: 0.03 | Y14: 0.03 | Z14: 0.03 | AA14: 0.03 | AB14: 0.03 | AC14: 0.03
E15: Sunday | F15: 0.03 | G15: 0.03 | H15: 0.03 | I15: 0.03 | J15: 0.03 | K15: 0.03 | L15: 0.03 | M15: 0.03 | N15: 0.05 | O15: 0.05 | P15: 0.05 | Q15: 0.05 | R15: 0.05 | S15: 0.05 | T15: 0.03 | U15: 0.03 | V15: 0.03 | W15: 0.03 | X15: 0.03 | Y15: 0.03 | Z15: 0.03 | AA15: 0.03 | AB15: 0.03 | AC15: 0.03
A16: All zones (single classroom zone) | B16: Classroom | C16: GasEquipment | D16: T24 2022 - Appendix 5.4B [School] | E16: Weekday | F16: 0 | G16: 0 | H16: 0 | I16: 0 | J16: 0 | K16: 0 | L16: 0 | M16: 0.5 | N16: 0.5 | O16: 0.75 | P16: 0.9 | Q16: 0.9 | R16: 0.9 | S16: 0 | T16: 0 | U16: 0 | V16: 0 | W16: 0 | X16: 0 | Y16: 0 | Z16: 0 | AA16: 0 | AB16: 0 | AC16: 0
E17: Saturday | F17: 0 | G17: 0 | H17: 0 | I17: 0 | J17: 0 | K17: 0 | L17: 0 | M17: 0 | N17: 0 | O17: 0 | P17: 0 | Q17: 0 | R17: 0 | S17: 0 | T17: 0 | U17: 0 | V17: 0 | W17: 0 | X17: 0 | Y17: 0 | Z17: 0 | AA17: 0 | AB17: 0 | AC17: 0
E18: Sunday | F18: 0 | G18: 0 | H18: 0 | I18: 0 | J18: 0 | K18: 0 | L18: 0 | M18: 0 | N18: 0 | O18: 0 | P18: 0 | Q18: 0 | R18: 0 | S18: 0 | T18: 0 | U18: 0 | V18: 0 | W18: 0 | X18: 0 | Y18: 0 | Z18: 0 | AA18: 0 | AB18: 0 | AC18: 0
A19: All zones (single classroom zone) | B19: Classroom | C19: Refrigeration | D19: T24 2022 - Appendix 5.4B [School] | E19: Weekday | F19: 0.9 | G19: 0.9 | H19: 0.9 | I19: 0.9 | J19: 0.9 | K19: 0.9 | L19: 0.9 | M19: 0.9 | N19: 0.9 | O19: 0.9 | P19: 0.9 | Q19: 0.9 | R19: 0.9 | S19: 0.9 | T19: 0.9 | U19: 0.9 | V19: 0.9 | W19: 0.9 | X19: 0.9 | Y19: 0.9 | Z19: 0.9 | AA19: 0.9 | AB19: 0.9 | AC19: 0.9
E20: Saturday | F20: 0.9 | G20: 0.9 | H20: 0.9 | I20: 0.9 | J20: 0.9 | K20: 0.9 | L20: 0.9 | M20: 0.9 | N20: 0.9 | O20: 0.9 | P20: 0.9 | Q20: 0.9 | R20: 0.9 | S20: 0.9 | T20: 0.9 | U20: 0.9 | V20: 0.9 | W20: 0.9 | X20: 0.9 | Y20: 0.9 | Z20: 0.9 | AA20: 0.9 | AB20: 0.9 | AC20: 0.9
E21: Sunday | F21: 0.9 | G21: 0.9 | H21: 0.9 | I21: 0.9 | J21: 0.9 | K21: 0.9 | L21: 0.9 | M21: 0.9 | N21: 0.9 | O21: 0.9 | P21: 0.9 | Q21: 0.9 | R21: 0.9 | S21: 0.9 | T21: 0.9 | U21: 0.9 | V21: 0.9 | W21: 0.9 | X21: 0.9 | Y21: 0.9 | Z21: 0.9 | AA21: 0.9 | AB21: 0.9 | AC21: 0.9
A22: All zones (single classroom zone) | B22: Classroom | C22: HVACAvail | D22: T24 2022 - Appendix 5.4B [School] | E22: Weekday | F22: 0 | G22: 0 | H22: 0 | I22: 0 | J22: 0 | K22: 0 | L22: 1 | M22: 1 | N22: 1 | O22: 1 | P22: 1 | Q22: 1 | R22: 1 | S22: 1 | T22: 1 | U22: 1 | V22: 1 | W22: 1 | X22: 1 | Y22: 1 | Z22: 1 | AA22: 1 | AB22: 0 | AC22: 0
E23: Saturday | F23: 0 | G23: 0 | H23: 0 | I23: 0 | J23: 0 | K23: 0 | L23: 0 | M23: 1 | N23: 1 | O23: 1 | P23: 1 | Q23: 1 | R23: 1 | S23: 0 | T23: 0 | U23: 0 | V23: 0 | W23: 0 | X23: 0 | Y23: 0 | Z23: 0 | AA23: 0 | AB23: 0 | AC23: 0
E24: Sunday | F24: 0 | G24: 0 | H24: 0 | I24: 0 | J24: 0 | K24: 0 | L24: 0 | M24: 0 | N24: 0 | O24: 0 | P24: 0 | Q24: 0 | R24: 0 | S24: 0 | T24: 0 | U24: 0 | V24: 0 | W24: 0 | X24: 0 | Y24: 0 | Z24: 0 | AA24: 0 | AB24: 0 | AC24: 0
A25: All zones (single classroom zone) | B25: Classroom | C25: HtgSetpt | D25: T24 2022 - Appendix 5.4B [School] | E25: Weekday | F25: 60 | G25: 60 | H25: 60 | I25: 60 | J25: 60 | K25: 60 | L25: 70 | M25: 70 | N25: 70 | O25: 70 | P25: 70 | Q25: 70 | R25: 70 | S25: 70 | T25: 70 | U25: 70 | V25: 70 | W25: 70 | X25: 70 | Y25: 70 | Z25: 70 | AA25: 70 | AB25: 60 | AC25: 60
E26: Saturday | F26: 60 | G26: 60 | H26: 60 | I26: 60 | J26: 60 | K26: 60 | L26: 60 | M26: 70 | N26: 70 | O26: 70 | P26: 70 | Q26: 70 | R26: 70 | S26: 60 | T26: 60 | U26: 60 | V26: 60 | W26: 60 | X26: 60 | Y26: 60 | Z26: 60 | AA26: 60 | AB26: 60 | AC26: 60
E27: Sunday | F27: 60 | G27: 60 | H27: 60 | I27: 60 | J27: 60 | K27: 60 | L27: 60 | M27: 60 | N27: 60 | O27: 60 | P27: 60 | Q27: 60 | R27: 60 | S27: 60 | T27: 60 | U27: 60 | V27: 60 | W27: 60 | X27: 60 | Y27: 60 | Z27: 60 | AA27: 60 | AB27: 60 | AC27: 60
A28: All zones (single classroom zone) | B28: Classroom | C28: ClgSetpt | D28: T24 2022 - Appendix 5.4B [School] | E28: Weekday | F28: 85 | G28: 85 | H28: 85 | I28: 85 | J28: 85 | K28: 85 | L28: 75 | M28: 75 | N28: 75 | O28: 75 | P28: 75 | Q28: 75 | R28: 75 | S28: 75 | T28: 75 | U28: 75 | V28: 75 | W28: 75 | X28: 75 | Y28: 75 | Z28: 75 | AA28: 75 | AB28: 85 | AC28: 85
E29: Saturday | F29: 85 | G29: 85 | H29: 85 | I29: 85 | J29: 85 | K29: 85 | L29: 85 | M29: 75 | N29: 75 | O29: 75 | P29: 75 | Q29: 75 | R29: 75 | S29: 85 | T29: 85 | U29: 85 | V29: 85 | W29: 85 | X29: 85 | Y29: 85 | Z29: 85 | AA29: 85 | AB29: 85 | AC29: 85
E30: Sunday | F30: 85 | G30: 85 | H30: 85 | I30: 85 | J30: 85 | K30: 85 | L30: 85 | M30: 85 | N30: 85 | O30: 85 | P30: 85 | Q30: 85 | R30: 85 | S30: 85 | T30: 85 | U30: 85 | V30: 85 | W30: 85 | X30: 85 | Y30: 85 | Z30: 85 | AA30: 85 | AB30: 85 | AC30: 85
A31: All zones (single classroom zone) | B31: Classroom | C31: Infiltration | D31: T24 2022 - Appendix 5.4B [School] (0.25 while the HVAC is on, 1.0 otherwise) | E31: Weekday | F31: 1 | G31: 1 | H31: 1 | I31: 1 | J31: 1 | K31: 1 | L31: 0.25 | M31: 0.25 | N31: 0.25 | O31: 0.25 | P31: 0.25 | Q31: 0.25 | R31: 0.25 | S31: 0.25 | T31: 0.25 | U31: 0.25 | V31: 0.25 | W31: 0.25 | X31: 0.25 | Y31: 0.25 | Z31: 0.25 | AA31: 0.25 | AB31: 1 | AC31: 1
E32: Saturday | F32: 1 | G32: 1 | H32: 1 | I32: 1 | J32: 1 | K32: 1 | L32: 1 | M32: 0.25 | N32: 0.25 | O32: 0.25 | P32: 0.25 | Q32: 0.25 | R32: 0.25 | S32: 1 | T32: 1 | U32: 1 | V32: 1 | W32: 1 | X32: 1 | Y32: 1 | Z32: 1 | AA32: 1 | AB32: 1 | AC32: 1
E33: Sunday | F33: 1 | G33: 1 | H33: 1 | I33: 1 | J33: 1 | K33: 1 | L33: 1 | M33: 1 | N33: 1 | O33: 1 | P33: 1 | Q33: 1 | R33: 1 | S33: 1 | T33: 1 | U33: 1 | V33: 1 | W33: 1 | X33: 1 | Y33: 1 | Z33: 1 | AA33: 1 | AB33: 1 | AC33: 1
A34: Other
B35: Building | C35: ExtLightingNonMotionCtrl | E35: Weekday | F35: 1 | G35: 1 | H35: 1 | I35: 1 | J35: 1 | K35: 1 | L35: 1 | M35: 1 | N35: 1 | O35: 1 | P35: 1 | Q35: 1 | R35: 1 | S35: 1 | T35: 1 | U35: 1 | V35: 1 | W35: 1 | X35: 1 | Y35: 1 | Z35: 1 | AA35: 1 | AB35: 1 | AC35: 1
E36: Saturday | F36: 1 | G36: 1 | H36: 1 | I36: 1 | J36: 1 | K36: 1 | L36: 1 | M36: 1 | N36: 1 | O36: 1 | P36: 1 | Q36: 1 | R36: 1 | S36: 1 | T36: 1 | U36: 1 | V36: 1 | W36: 1 | X36: 1 | Y36: 1 | Z36: 1 | AA36: 1 | AB36: 1 | AC36: 1
E37: Sunday | F37: 1 | G37: 1 | H37: 1 | I37: 1 | J37: 1 | K37: 1 | L37: 1 | M37: 1 | N37: 1 | O37: 1 | P37: 1 | Q37: 1 | R37: 1 | S37: 1 | T37: 1 | U37: 1 | V37: 1 | W37: 1 | X37: 1 | Y37: 1 | Z37: 1 | AA37: 1 | AB37: 1 | AC37: 1
B38: Building | C38: ExtLightingMotionCtrl | E38: Weekday | F38: 0 | G38: 0 | H38: 0 | I38: 0 | J38: 0 | K38: 1 | L38: 1 | M38: 1 | N38: 1 | O38: 1 | P38: 1 | Q38: 1 | R38: 1 | S38: 1 | T38: 1 | U38: 1 | V38: 1 | W38: 1 | X38: 1 | Y38: 1 | Z38: 1 | AA38: 1 | AB38: 0 | AC38: 0
E39: Saturday | F39: 0 | G39: 0 | H39: 0 | I39: 0 | J39: 0 | K39: 1 | L39: 1 | M39: 1 | N39: 1 | O39: 1 | P39: 1 | Q39: 1 | R39: 1 | S39: 1 | T39: 1 | U39: 1 | V39: 1 | W39: 1 | X39: 1 | Y39: 1 | Z39: 1 | AA39: 1 | AB39: 1 | AC39: 1
E40: Sunday | F40: 0 | G40: 0 | H40: 0 | I40: 0 | J40: 0 | K40: 1 | L40: 1 | M40: 1 | N40: 1 | O40: 1 | P40: 1 | Q40: 1 | R40: 1 | S40: 1 | T40: 1 | U40: 1 | V40: 1 | W40: 1 | X40: 1 | Y40: 1 | Z40: 1 | AA40: 1 | AB40: 1 | AC40: 1
...

Sheet Energy Usage
A1: ="CalBEM Energy Consumption - "&Prototype!B4 -> CalBEM Energy Consumption - Relocatable School | N1: ="Energy Consumption - "&Prototype!A2 -> Energy Consumption - SchoolRelocatable
A2: Prototype | B2: CZ | C2: CalBEM Electricity EUI (KBTU/ft²) | D2: CalBEM Gas EUI (KBTU/ft²) | E2: CalBEM Total EUI (KBTU/ft²) | F2: New Construction Electricity EUI (KBTU/ft²) | G2: New Construction Gas EUI (KBTU/ft²) | H2: New Construction Total EUI (KBTU/ft²) | I2: National Average | J2: Acceptable Range (25% Higher) | K2: Acceptable Range (25% Lower) | L2: National Average Acceptable EUI Range | N2: Prototype | O2: CZ | P2: Total Floorspace (Thousand of ft²) | Q2: CEUS 2023 Electricity EUI (kBtu/ft²) | R2: CEUS 2023 Gas EUI (kBtu/ft²) | S2: CEUS 2023 Total EUI (kBtu/ft²) | T2: Acceptable Range (25% Higher) | U2: Acceptable Range (25% Lower) | V2: CEUS 2022 Acceptable EUI Range
A3: =Prototype!B4 -> Relocatable School | B3: 1 | I3: 51.3 | J3: =I3*1.25 -> 64.125 | K3: =I3*0.75 -> 38.475 | L3: =J3-K3 -> 25.65 | N3: =Prototype!B4 -> Relocatable School | O3: 1 | P3: 7618.5337 | Q3: 32.349176 | R3: 12.848137 | S3: =Q3+R3 -> 45.197312 | T3: =S3*1.25 -> 56.49664 | U3: =S3*0.75 -> 33.897984 | V3: =T3-U3 -> 22.598656
B4: 2 | I4: 51.3 | J4: =I4*1.25 -> 64.125 | K4: =I4*0.75 -> 38.475 | L4: =J4-K4 -> 25.65 | O4: 2 | P4: 11477.671 | Q4: 15.421598 | R4: 12.913999 | S4: =Q4+R4 -> 28.335597 | T4: =S4*1.25 -> 35.419497 | U4: =S4*0.75 -> 21.251698 | V4: =T4-U4 -> 14.167799
B5: 3 | I5: 51.3 | J5: =I5*1.25 -> 64.125 | K5: =I5*0.75 -> 38.475 | L5: =J5-K5 -> 25.65 | O5: 3 | P5: 46411.86 | Q5: 20.479595 | R5: 12.799248 | S5: =Q5+R5 -> 33.278843 | T5: =S5*1.25 -> 41.598554 | U5: =S5*0.75 -> 24.959132 | V5: =T5-U5 -> 16.639421
B6: 4 | I6: 51.3 | J6: =I6*1.25 -> 64.125 | K6: =I6*0.75 -> 38.475 | L6: =J6-K6 -> 25.65 | O6: 4 | P6: 23032.968 | Q6: 21.49373 | R6: 13.019767 | S6: =Q6+R6 -> 34.513497 | T6: =S6*1.25 -> 43.141871 | U6: =S6*0.75 -> 25.885123 | V6: =T6-U6 -> 17.256749
B7: 5 | I7: 51.3 | J7: =I7*1.25 -> 64.125 | K7: =I7*0.75 -> 38.475 | L7: =J7-K7 -> 25.65 | O7: 5 | P7: 5978.4428 | Q7: 11.998072 | R7: 11.585185 | S7: =Q7+R7 -> 23.583257 | T7: =S7*1.25 -> 29.479072 | U7: =S7*0.75 -> 17.687443 | V7: =T7-U7 -> 11.791629
B8: 6 | I8: 51.3 | J8: =I8*1.25 -> 64.125 | K8: =I8*0.75 -> 38.475 | L8: =J8-K8 -> 25.65 | O8: 6 | P8: 57755.959 | Q8: 22.607349 | R8: 9.9467421 | S8: =Q8+R8 -> 32.554091 | T8: =S8*1.25 -> 40.692614 | U8: =S8*0.75 -> 24.415568 | V8: =T8-U8 -> 16.277046
B9: 7 | I9: 51.3 | J9: =I9*1.25 -> 64.125 | K9: =I9*0.75 -> 38.475 | L9: =J9-K9 -> 25.65 | O9: 7 | P9: 35149.993 | Q9: 24.848388 | R9: 6.9700357 | S9: =Q9+R9 -> 31.818424 | T9: =S9*1.25 -> 39.77303 | U9: =S9*0.75 -> 23.863818 | V9: =T9-U9 -> 15.909212
B10: 8 | I10: 51.3 | J10: =I10*1.25 -> 64.125 | K10: =I10*0.75 -> 38.475 | L10: =J10-K10 -> 25.65 | O10: 8 | P10: 92353.411 | Q10: 22.935329 | R10: 8.842203 | S10: =Q10+R10 -> 31.777532 | T10: =S10*1.25 -> 39.721915 | U10: =S10*0.75 -> 23.833149 | V10: =T10-U10 -> 15.888766
B11: 9 | I11: 51.3 | J11: =I11*1.25 -> 64.125 | K11: =I11*0.75 -> 38.475 | L11: =J11-K11 -> 25.65 | O11: 9 | P11: 141795.45 | Q11: 26.797343 | R11: 10.089067 | S11: =Q11+R11 -> 36.88641 | T11: =S11*1.25 -> 46.108013 | U11: =S11*0.75 -> 27.664808 | V11: =T11-U11 -> 18.443205
B12: 10 | I12: 51.3 | J12: =I12*1.25 -> 64.125 | K12: =I12*0.75 -> 38.475 | L12: =J12-K12 -> 25.65 | O12: 10 | P12: 92589.867 | Q12: 22.490401 | R12: 10.108975 | S12: =Q12+R12 -> 32.599376 | T12: =S12*1.25 -> 40.74922 | U12: =S12*0.75 -> 24.449532 | V12: =T12-U12 -> 16.299688
B13: 11 | I13: 51.3 | J13: =I13*1.25 -> 64.125 | K13: =I13*0.75 -> 38.475 | L13: =J13-K13 -> 25.65 | O13: 11 | P13: 33810.488 | Q13: 26.928661 | R13: 8.760437 | S13: =Q13+R13 -> 35.689098 | T13: =S13*1.25 -> 44.611373 | U13: =S13*0.75 -> 26.766824 | V13: =T13-U13 -> 17.844549
B14: 12 | I14: 51.3 | J14: =I14*1.25 -> 64.125 | K14: =I14*0.75 -> 38.475 | L14: =J14-K14 -> 25.65 | O14: 12 | P14: 108342.43 | Q14: 31.799594 | R14: 12.230299 | S14: =Q14+R14 -> 44.029893 | T14: =S14*1.25 -> 55.037366 | U14: =S14*0.75 -> 33.02242 | V14: =T14-U14 -> 22.014946
B15: 13 | I15: 51.3 | J15: =I15*1.25 -> 64.125 | K15: =I15*0.75 -> 38.475 | L15: =J15-K15 -> 25.65 | O15: 13 | P15: 46676.808 | Q15: 32.656044 | R15: 15.473534 | S15: =Q15+R15 -> 48.129578 | T15: =S15*1.25 -> 60.161972 | U15: =S15*0.75 -> 36.097183 | V15: =T15-U15 -> 24.064789
... B18: 16 | I18: 51.3 | J18: =I18*1.25 -> 64.125 | K18: =I18*0.75 -> 38.475 | L18: =J18-K18 -> 25.65 | O18: 16 | P18: 85267.89 | Q18: 27.026911 | R18: 11.652927 | S18: =Q18+R18 -> 38.679837 | T18: =S18*1.25 -> 48.349796 | U18: =S18*0.75 -> 29.009878 | V18: =T18-U18 -> 19.339919
Q20: Ref: CEUS 2022 Report
Q21: And by applying FZ-CZ multipliers for converting FZ data to CZ data

Sheet Weights
A1: ="% of Floor Area per CZ and Vintage Bin - Schools" -> % of Floor Area per CZ and Vintage Bin - Schools | J1: ="% of floor area per CZ and vintage bin - School" -> % of floor area per CZ and vintage bin - School
A2: Prototype | B2: CZ | C2: Vintage Bin | J2: Prototype | K2: Vintage Bin | L2: CZ
C3: Pre-1978 | D3: 1978-1997 | E3: 1998-2007 | F3: 2008-2018 | G3: Not available | L3: 1 | M3: 2 | N3: 3 | O3: 4 | P3: 5 | Q3: 6 | R3: 7 | S3: 8 | T3: 9 | U3: 10 | V3: 11 | W3: 12 | X3: 13 | Y3: 14 | Z3: 15 | AA3: 16
A4: School | B4: 1 | C4: 0.5614751 | D4: 0.3169793 | E4: 0.0879218 | F4: 0.0336238 | H4: =SUM(C4:F4) -> 1 | J4: School | K4: Pre-1978 | L4: 0.008977 | M4: 0.021094 | N4: 0.072235 | O4: 0.037625 | P4: 0.006802 | Q4: 0.084541 | R4: 0.02215 | S4: 0.138845 | T4: 0.211244 | U4: 0.066481 | V4: 0.038749 | W4: 0.115342 | X4: 0.036419 | Y4: 0.026538 | Z4: 0.024347 | AA4: 0.088611
B5: 2 | C5: 0.8757394 | D5: 0.071795 | E5: 0.0383992 | F5: 0.0140663 | H5: =SUM(C5:F5) -> 0.9999999 | K5: 1978-1997 | L5: 0.011899 | M5: 0.00406 | N5: 0.05368 | O5: 0.023209 | P5: 0.012539 | Q5: 0.041865 | R5: 0.044692 | S5: 0.061343 | T5: 0.124937 | U5: 0.095931 | V5: 0.058408 | W5: 0.18781 | X5: 0.091876 | Y5: 0.021377 | Z5: 0.057022 | AA5: 0.109352
B6: 3 | C6: 0.7416427 | D6: 0.2347382 | E6: 0.0164353 | F6: 0.0071837 | H6: =SUM(C6:F6) -> 0.9999999 | K6: 1998-2007 | L6: 0.004957 | M6: 0.003262 | N6: 0.005645 | O6: 0.001754 | P6: 0.001078 | Q6: 0.046589 | R6: 0.051164 | S6: 0.075404 | T6: 0.09166 | U6: 0.227399 | V6: 0.020951 | W6: 0.087443 | X6: 0.054569 | Y6: 0.025505 | Z6: 0.21378 | AA6: 0.08884
B7: 4 | C7: 0.7783863 | D7: 0.2044994 | E7: 0.0102904 | F7: 0.0068239 | H7: =SUM(C7:F7) -> 1 | K7: 2008-2018 | L7: 0.005003 | M7: 0.003153 | N7: 0.006512 | O7: 0.00307 | P7: 0.00091 | Q7: 0.05236 | R7: 0.16821 | S7: 0.069444 | T7: 0.066329 | U7: 0.209328 | V7: 0.012806 | W7: 0.067006 | X7: 0.064526 | Y7: 0.046051 | Z7: 0.052484 | AA7: 0.172807
B8: 5 | C8: 0.5421735 | D8: 0.425672 | E8: 0.0243657 | F8: 0.0077888 | H8: =SUM(C8:F8) -> 1
B9: 6 | C9: 0.6974838 | D9: 0.1471111 | E9: 0.1089907 | F9: 0.0464144 | H9: =SUM(C9:F9) -> 1 | K9: Total | L9: 0.0088 | M9: 0.013257 | N9: 0.053607 | O9: 0.026604 | P9: 0.006905 | Q9: 0.066711 | R9: 0.0406 | S9: 0.106672 | T9: 0.16378 | U9: 0.106945 | V9: 0.039046 | W9: 0.125117 | X9: 0.053914 | Y9: 0.026321 | Z9: 0.063234 | AA9: 0.098488
B10: 7 | C10: 0.300278 | D10: 0.2580444 | E10: 0.1966736 | F10: 0.2450039 | H10: =SUM(C10:F10) -> 0.9999999
B11: 8 | C11: 0.7163803 | D11: 0.134804 | E11: 0.1103187 | F11: 0.038497 | H11: =SUM(C11:F11) -> 1
B12: 9 | C12: 0.7098858 | D12: 0.1788227 | E12: 0.0873426 | F12: 0.0239489 | H12: =SUM(C12:F12) -> 1
B13: 10 | C13: 0.3421363 | D13: 0.2102751 | E13: 0.3318416 | F13: 0.1157471 | H13: =SUM(C13:F13) -> 1.0000001
B14: 11 | C14: 0.5462009 | D14: 0.3506622 | E14: 0.0837416 | F14: 0.0193952 | H14: =SUM(C14:F14) -> 0.9999999
B15: 12 | C15: 0.5073814 | D15: 0.3518777 | E15: 0.1090713 | F15: 0.0316696 | H15: =SUM(C15:F15) -> 1
B16: 13 | C16: 0.3717839 | D16: 0.3994804 | E16: 0.1579606 | F16: 0.0707751 | H16: =SUM(C16:F16) -> 1
B17: 14 | C17: 0.5549221 | D17: 0.1903914 | E17: 0.1512247 | F17: 0.1034618 | H17: =SUM(C17:F17) -> 1
B18: 15 | C18: 0.2119104 | D18: 0.2113885 | E18: 0.5276196 | F18: 0.0490814 | H18: =SUM(C18:F18) -> 0.9999999
B19: 16 | C19: 0.495188 | D19: 0.2602765 | E19: 0.1407766 | F19: 0.1037589 | H19: =SUM(C19:F19) -> 1
B20: Statewide | C20: 0.5503824 | D20: 0.2344179 | E20: 0.1560647 | F20: 0.059135 | H20: =SUM(C20:F20) -> 1
A22: Ref: CEUS 2022 dataset: School group
A25: Background Data [To be deleted prior to publication]

Sheet PV
A1: ="PV - "&Prototype!A2 -> PV - SchoolRelocatable
A2: TBD

Sheet EV Charger
A1: ="EV Charger - "&Prototype!A2 -> EV Charger - SchoolRelocatable
A2: TBD
A11: Background Data [To be deleted prior to publication]

Sheet Data
A1: Space Function
A2: Aging Eye/Low-vision (Corridor Area)
A3: Aging Eye/Low-vision (Dining)
A4: Aging Eye/Low-vision (Lobby, Main Entry)
A5: Aging Eye/Low-vision (Lounge/Waiting Area)
A6: Aging Eye/Low-vision (Multipurpose Room)
A7: Aging Eye/Low-vision (Religious Worship Area)
A8: Aging Eye/Low-vision (Restroom)
A9: Aging Eye/Low-vision (Stairwell)
A10: Audience Seating Area
A11: Auditorium Area
A12: Auto Repair / Maintenance Area
... A80: Unoccupied-Exclude from Gross Floor Area
