Workbook
Name Space_Function: Data!$A$2:$A$76

Sheet Notes
A1: Data Sources
A2: Dataset | B2: Dodge 2023
B3: CEUS 2022
B4: CBECS 2018
B5: ComStock 2023
A6: Prototype | B6: CEC prototype (CBECC 2022.3.1) | C6: https://bees.noresco.com/software2022.html
B7: PNNL prototype (90.1-2022) | C7: https://www.energycodes.gov/prototype-building-models#Commercial
B8: DEER prototype (June 2023) | C8: https://github.com/sound-data/DEER-Prototypes-EnergyPlus
A10: Codes | B10: Title 24, part 6, referred to as T24 (1986, 1992, 2001, 2007, 2013, 2016, 2019, 2022, 2025)
B11: ASHRAE 90.1 (2022)
B12: CFR Title 10 (2009) | C12: https://www.govinfo.gov/content/pkg/FR-2009-03-23/pdf/FR-2009-03-23.pdf
B13: CFR Title 10 ( 2013) | C13: https://www.govinfo.gov/content/pkg/CFR-2013-title10-vol3/pdf/CFR-2013-title10-vol3-part431.pdf
B14: CFR Title 10 ( 2024) | C14: https://www.govinfo.gov/content/pkg/CFR-2024-title10-vol3/pdf/CFR-2024-title10-vol3-part431-subpartF.pdf
A16: Others | B16: ACM (2013, 2019, 2022, 2025)
B17: Title 24, 2022 - Appendix 5.4A and Appendix 5.4B | C17: https://www.energy.ca.gov/publications/2022/2022-nonresidential-and-multifamily-alternative-calculation-method-reference
B18: 2022 Reduced infiltration CASE report | C18: https://title24stakeholders.com/wp-content/uploads/2020/10/2022-T24-Final-CASE-Report_Reduce-Infiltration.pdf
B19: 2019 Outdoor Lighting CASE Report | C19: https://title24stakeholders.com/wp-content/uploads/2016/10/T24-2019-CASE-Study-Results-Report-Outdoor-Sources_Final_with-Attachments.pdf
B20: PNNL 20405, 2011 | C20: https://www.pnnl.gov/main/publications/external/technical_reports/PNNL-20405.pdf
B21: Air leakage Memo, NORESCO, 2025 | C21: https://2050partners.sharepoint.com/:w:/r/sites/CalBEMCollaborativeEfforts/_layouts/15/Doc.aspx?sourcedoc=%7B3BEF8F74-7FAC-44F2-A70C-D76617660066%7D&file=Infiltration_rate_report_14May2025-Short-Version.docx&action=default&mobileredirect=true
B22: Proposed Updates to Equipment Power Densities and Building Schedules for the 2028 Energy Code, referred to as "Plug load and schedules project with CEC, 2025" (Docket Number =25-BSTD-03 & TN=265693) | C22: https://efiling.energy.ca.gov/GetDocument.aspx?tn=265693&DocumentContentId=102545
B23: PNNL 17056, 2007: Technical Support Document: The Development of the Advanced Energy Design Guide for Small Warehouse and Self-Storage Buildings | C23: https://www.pnnl.gov/main/publications/external/technical_reports/PNNL-17056.pdf
B24: NEEA, CBSA-4-2019, "Commercial Building Stock Assessment 4 (2019) Final Report ", by CADMUS, Aaron James in 2020. | C24: https://neea.org/wp-content/uploads/2025/03/CBSA-4-2019-Final-Report.pdf
A25: Water Heater | B25: ENERGY STAR certified commercial water heaters (gas storage input ≥76 kBtu/h; ES tank sizes) | C25: =HYPERLINK("https://www.energystar.gov/productfinder/product/certified-commercial-water-heaters/results?fuel_filter=Gas&markets_filter=United+States","ENERGY STAR product finder — gas") -> ENERGY STAR product finder — gas
B26: ENERGY STAR commercial WH dataset (download) | C26: =HYPERLINK("https://data.energystar.gov/Active-Specifications/ENERGY-STAR-Certified-Commercial-Water-Heaters/xmq6-bm79","ENERGY STAR dataset xmq6-bm79") -> ENERGY STAR dataset xmq6-bm79
B27: ENERGY STAR commercial WH eligibility (gas storage >75 kBtu/h) | C27: =HYPERLINK("https://www.energystar.gov/products/water_heaters/commercial_water_heaters/key_product_criteria","ENERGY STAR key product criteria") -> ENERGY STAR key product criteria
B28: Grainger gas tank water heaters (sizes below ES commercial, e.g. 30–75 kBtu/h) | C28: =HYPERLINK("https://www.grainger.com/category/plumbing/water-heaters/gas-tank-water-heaters","Grainger — gas tank WH") -> Grainger — gas tank WH
B29: Grainger electric tank water heaters (kW ladder, tank gallons) | C29: =HYPERLINK("https://www.grainger.com/category/plumbing/water-heaters/electric-tank-water-heaters","Grainger — electric tank WH") -> Grainger — electric tank WH
B30: ES commercial electric = heat pumps only; not used for resistance tank list | C30: =HYPERLINK("https://www.energystar.gov/productfinder/product/certified-commercial-water-heaters/results?fuel_filter=Electric&markets_filter=United+States","ENERGY STAR — electric (HPWH)") -> ENERGY STAR — electric (HPWH)
A32: Notes
A33: Warehouse | B33: A mixed use distribution warehouse with conditioned fine storage for temperature sensitive goods and a bulk storage for general inventory that only needs freeze protection.
B36: Construction rate based on Dodge 2023
B74: Warehouse (STC:3)
A75: Year | B75: Total floor area (k ft2) | C75: Count
A76: 1967 | B76: 5361.9 | C76: 152
A77: 1968 | B77: 8271 | C77: 452
A78: 1969 | B78: 13593.6 | C78: 655
A79: 1970 | B79: 14323.7 | C79: 601
A80: 1971 | B80: 13719.8 | C80: 592
A81: 1972 | B81: 16513.9 | C81: 687
A82: 1973 | B82: 27619.6 | C82: 920
...

Sheet Prototype
A1: NORESCO, Updated September 2026
A2: Warehouse
A3: Characteristic | B3: Value | C3: Data Sources
A4: Building Type | B4: Warehouse
A5: Building Category | B5: Nonresidential
A6: Version | B6: v2-0
A7: Vintages | B7: 4 Vintages: Pre-1978 , 1978-1997 ,1998-2007 , 2008-2018 New Construction (2019+) | C7: Based on the vintage bin analysis. A summary of the findings is presented in the following paper, with a link provided in the Notes tab: Yousefi, F., Athalye, R. (2025). “Determining Vintage Bins for Prototype Development: An Analysis of California Commercial Buildings.” ASHRAE Annual Conference.
A8: Shape | C8: Same as CBECC 2022
A9: Total Floor Area (ft²) | B9: 52,045 (330 ft * 150 ft plus 2,550 ft² floor , see Zones tab) The space above the office zone (lower-right zone, 2,550 ft²) is designated as storage and is part of the Fine Storage zone. | C9: Same as CBECC 2022 (supported by Dodge 2023)
A10: Aspect Ratio | B10: 2.2 | C10: Same as CBECC 2022
A11: Number of Floors | B11: 1
A12: Roof type | B12: Flat
A13: WWR | B13: 0.0071 | C13: Same as CBECC 2022
A14: Shading Geometry | B14: No shades
A15: Floor to floor height (ft) | B15: 28 | C15: Same as CBECC 2022
A16: Floor to ceiling height (ft) | B16: 14 (office) | C16: Same as CBECC 2022
A17: Glazing sill height (ft) | B17: 3 (Top of the window is 8 ft with 5 ft high glass) | C17: Same as CBECC 2022
A24: Existing public prototypes
B25: PNNL | C25: CEC | D25: CPUC Storage conditioned | E25: CPUC Refrigerated Warehouse (not under warehouse)
A26: Geometry
A27: Roof area (ft²) | B27: 49495.17 | C27: 49495.29 | D27: 499990.41 | E27: 499990.41
A28: Height (ft) | B28: 28 | C28: 28 | D28: 48 | E28: 48
A30: People | B30: 200 ft²/person Office | C30: 0.005 person/ft² Office | D30: 0.001 person/ft² North storage | E30: =100/50000 -> 0.002
B31: 30 people Fine storage | C31: 0.001 person/ft² Fine storage | D31: 0.001 person/ft² Soth storage
B32: 69 people Bulk storage | C32: 0.001 person/ft² Bulk storage
A33: Lights (W/ft²) | B33: 0.57 Office | C33: 0.6 Office | D33: 0.4 North storage
B34: 0.62 Fine storage | C34: 0.4 Fine storage | D34: 0.4 South storage
B35: 0.30 Bulk storage | C35: 0.4 Bulk storage
A36: Ext lights (W) | B36: 119 Office | C36: - | D36: -
B37: 2,955 Fine storage
B38: 694 Bulk storage
A39: Electric Equipment | B39: 1,912 W Office | C39: 1.5 W/ft² Office | D39: 0.2 W/ft² North storage
C40: 0.2 W/ft² Fine storage | D40: 0.2 W/ft² South storage
B41: 8,200 Bulk W storage | C41: 0.2 W/ft² Bulk storage
A43: Heating Sizing Factor | B43: H&C: 1.2 | C43: H&C:1 | D43: H: 2.5 , C: 2.3
A44: HVAC | B44: Office: CAV no reheat, DX cooling coil: multi speed, Gas heating coil | C44: Office (sys7or3b): VAV+DX cooling coil+DX heating coil +Electric Heating coil | D44: MZ VAV Reheat + 1 Water cooling coil +1 Water heating coil+ 2 water heating coil for Reheat at terminal units, serving 2 zones
B45: Fine storage; CAV no reheat, DX cooling coil: multi speed, Gas heating coil | C45: Fine storage (sys7or3a):VAV+DX cooling coil: Gas Heating coil | D45: - Boiler
B46: Bulk storage: CAV+ Unit heater (Gas heating coil) | C46: Bulk storage (sys9): CAV+Gas Heating coil | D46: -Chiller
B47: + (DX coil:multi speed high temperature Radiant (Always Off))
A48: Thermostat setpoint (F) | B48: Office: 70H , 75C (setback: 60H , 85C) | C48: Office: 70H , 75C (setback: 60H , 85C) | D48: North: 70H, 75C (setback: 60H , 85C)
...

Sheet Zones
A1: ="Proposed Layout - "&Prototype!A2 -> Proposed Layout - Warehouse
A2: Building | B2: Space/Thermal Zone | C2: Space Type [Primarily from: T24, 2022 Appendix 5.4A] - See Notes column | D2: HVAC Zone | E2: Schedule Category | F2: Conditioned (Y/N) | G2: Area Fraction | H2: Area (ft²) | I2: Volume (ft³) | J2: Multipliers | K2: Number of People | L2: People (Persons/1,000 ft²) [T24, 2025,Table 120.1-A] | M2: Notes
A3: Warehouse | B3: Office | C3: Office Area (>250 square feet) | D3: AHU_1 | E3: Office | F3: Y | G3: =H3/$H$6 -> 0.048991229 | H3: 2549.75 | I3: =H3*14 -> 35696.5 | J3: 1 | K3: =L3*H3/1000 -> 12.74875 | L3: 5
A4: Warehouse | B4: FineStorage | C4: Storage, Commercial/Industrial (Warehouse) | D4: AHU_2 | E4: FineStorage | F4: Y | G4: =H4/$H$6 -> 0.2881841 | H4: =12448.8+2549.75 -> 14998.55 | I4: =(H4-H3)*28+H3*(Prototype!B15-14) -> 384262.9 | J4: 1 | K4: =L4*H4/1000 -> 14.99855 | L4: 1
A5: Warehouse | B5: BulkStorage | C5: Storage, Commercial/Industrial (Warehouse) | D5: AHU_3 | E5: BulkStorage | F5: Y | G5: =H5/$H$6 -> 0.66282467 | H5: 34496.73 | I5: =H5*Prototype!B15 -> 965908.44 | J5: 1 | K5: =L5*H5/1000 -> 34.49673 | L5: 1
A6: Toal (1 Building) | B6: Total (3 Space) | C6: Total (2 space type) | D6: Total (3 HVAC Zones) | F6: Total (3 Conditioned zones) | G6: =SUM(G3:G5) -> 1 | H6: =SUM(H3:H5) -> 52045.03 | I6: =SUM(I3:I5) -> 1385867.8 | K6: =SUM(K3:K5) -> 62.24403

Sheet Envelope
A1: ="Envelope - "&Prototype!A2 -> Envelope - Warehouse
A2: Element | B2: Prototype | C2: Assembly Type | D2: Construction | E2: Thermal properties | F2: Vintage | G2: Selected T24 | H2: Note | I2: CZ1 | J2: CZ2 | K2: CZ3 | L2: CZ4 | M2: CZ5 | N2: CZ6 | O2: CZ7 | P2: CZ8 | Q2: CZ9 | R2: CZ10 | S2: CZ11 | T2: CZ12 | U2: CZ13 | V2: CZ14 | W2: CZ15 | X2: CZ16
A3: External Wall | B3: Warehouse | C3: ExtWall_MetalBuilding_NonRes | D3: Metal building: Metal surface + Continuous Insulation + Metal panel | E3: U-factor IP | F3: Pre 1978 | G3: N/A | H3: Using 1) DOE pre 1980 warehouse prototype U value of 0.301, and 2) a 5.1% cumulative wall renovation rate through 2028, based on the average annual rate from CBECS 2003 and 2012 projected over 48 years. | I3: =I63*(1-$I$64)+I62*$I$64 -> 0.291412 | J3: =J63*(1-$I$64)+J62*$I$64 -> 0.28876 | K3: =K63*(1-$I$64)+K62*$I$64 -> 0.291412 | L3: =L63*(1-$I$64)+L62*$I$64 -> 0.28876 | M3: =M63*(1-$I$64)+M62*$I$64 -> 0.28876 | N3: =N63*(1-$I$64)+N62*$I$64 -> 0.291412 | O3: =O63*(1-$I$64)+O62*$I$64 -> 0.291412 | P3: =P63*(1-$I$64)+P62*$I$64 -> 0.28876 | ... X3: =X63*(1-$I$64)+X62*$I$64 -> 0.28876
F4: 1978-1997 | G4: 1986 | H4: . Minimum of the previous vintage and U values calculated from the 1986 code based on HDD and Degree North Latitude | I4: =MIN($E$84,I3) -> 0.291412 | J4: =MIN($E$84,J3) -> 0.28876 | K4: =MIN($E$84,K3) -> 0.291412 | L4: =MIN($E$84,L3) -> 0.28876 | M4: =MIN($E$84,M3) -> 0.28876 | N4: =MIN($E$84,N3) -> 0.291412 | O4: =MIN($E$84,O3) -> 0.291412 | P4: =MIN($E$84,P3) -> 0.28876 | ... X4: =MIN($E$84,X3) -> 0.28876
F5: 1998-2007 | G5: 2001 | H5: Table 1-H (Metal frame) | I5: 0.182 | J5: 0.182 | K5: 0.189 | L5: 0.189 | M5: 0.189 | N5: 0.189 | O5: 0.189 | P5: 0.189 | Q5: 0.189 | R5: 0.182 | S5: 0.182 | T5: 0.182 | U5: 0.182 | V5: 0.182 | W5: 0.182 | X5: 0.182
F6: 2008-2018 | G6: 2013 | H6: Table 140.3-B | I6: 0.113 | J6: 0.061 | K6: 0.113 | L6: 0.061 | M6: 0.061 | N6: 0.113 | O6: 0.113 | P6: 0.061 | Q6: 0.061 | R6: 0.061 | S6: 0.061 | T6: 0.061 | U6: 0.061 | V6: 0.061 | W6: 0.057 | X6: 0.061
F7: Existing | H7: Weighted average of all 4 vintages | I7: {=_xlfn.BYCOL(TRANSPOSE(Weights!$C$4:$F$19)*I3:X6,_xlfn.LAMBDA(_xlpm.c,SUM(_xlpm.c)))} -> 0.21533399 | J7: 0.18736575 | K7: 0.25967326 | L7: 0.26207513 | M7: 0.22257083 | N7: 0.27015556 | O7: 0.25823972 | P7: 0.26638942 | Q7: 0.26786532 | R7: 0.18225466 | S7: 0.2150341 | T7: 0.22085246 | U7: 0.22389828 | V7: 0.21265127 | W7: 0.16506634 | X7: 0.19564478
F8: 2019+ | G8: 2025 | H8: Table 140.3-B | I8: 0.098 | J8: 0.053 | K8: 0.098 | L8: 0.053 | M8: 0.053 | N8: 0.098 | O8: 0.098 | P8: 0.053 | Q8: 0.053 | R8: 0.053 | S8: 0.053 | T8: 0.053 | U8: 0.053 | V8: 0.053 | W8: 0.053 | X8: 0.053
A9: Roof | B9: Warehouse | C9: FlatRoof_WoodFramedAndOther_NonRes | D9: Metal deck roof: Roof Membrane + Continuous Insulation + Metal Decking | E9: U-factor IP | F9: Pre 1978 | G9: N/A | H9: Considering 30 years for roof/ insulation replacement. | I9: =I10 -> 0.057 | J9: =J10 -> 0.057 | K9: =K10 -> 0.057 | L9: =L10 -> 0.057 | M9: =M10 -> 0.057 | N9: =N10 -> 0.078 | O9: =O10 -> 0.078 | P9: =P10 -> 0.078 | ... X9: =X10 -> 0.057
F10: 1978-1997 | G10: 1992 | I10: 0.057 | J10: 0.057 | K10: 0.057 | L10: 0.057 | M10: 0.057 | N10: 0.078 | O10: 0.078 | P10: 0.078 | Q10: 0.078 | R10: 0.078 | S10: 0.057 | T10: 0.057 | U10: 0.057 | V10: 0.057 | W10: 0.057 | X10: 0.057
F11: 1998-2007 | G11: 2001 | H11: Table 1-H | I11: 0.057 | J11: 0.057 | K11: 0.057 | L11: 0.057 | M11: 0.057 | N11: 0.078 | O11: 0.078 | P11: 0.078 | Q11: 0.078 | R11: 0.057 | S11: 0.057 | T11: 0.057 | U11: 0.057 | V11: 0.057 | W11: 0.057 | X11: 0.057
F12: 2008-2018 | G12: 2013 | H12: Table 140.3-B | I12: 0.065 | J12: 0.065 | K12: 0.065 | L12: 0.065 | M12: 0.065 | N12: 0.065 | O12: 0.065 | P12: 0.065 | Q12: 0.065 | R12: 0.065 | S12: 0.065 | T12: 0.065 | U12: 0.065 | V12: 0.065 | W12: 0.065 | X12: 0.065
F13: Existing | H13: Weighted average of all 4 vintages | I13: {=_xlfn.BYCOL(TRANSPOSE(Weights!$C$4:$F$19)*I9:X12,_xlfn.LAMBDA(_xlpm.c,SUM(_xlpm.c)))} -> 0.058997174 | J13: 0.059905407 | K13: 0.057335323 | L13: 0.057144949 | M13: 0.057472026 | N13: 0.077478972 | O13: 0.07754828 | P13: 0.077450467 | Q13: 0.077563366 | R13: 0.064284818 | S13: 0.058707353 | T13: 0.05848718 | U13: 0.058226375 | V13: 0.057989818 | W13: 0.059543332 | X13: 0.058297147
F14: 2019+ | G14: 2025 | H14: Table 140.3-B | I14: 0.038 | J14: 0.038 | K14: 0.038 | L14: 0.038 | M14: 0.038 | N14: 0.038 | O14: 0.038 | P14: 0.038 | Q14: 0.038 | R14: 0.038 | S14: 0.038 | T14: 0.038 | U14: 0.038 | V14: 0.038 | W14: 0.038 | X14: 0.038
A15: Windows | B15: Warehouse | C15: FixedWindow_NonRes | D15: Single Pane (CBECS 2018, ~ 50 % of warehouse that were built before 2000 are single pane) | E15: U-factor IP | F15: Pre 1978 | G15: N/A | H15: ASHRAE Handbook of Fundamentals for single pane (Table 4- CH15) & T24 2013 for double pane (50%-50%) | I15: =0.5*1.12+0.5*I18 -> 0.74 | J15: =0.5*1.12+0.5*J18 -> 0.74 | K15: =0.5*1.12+0.5*K18 -> 0.74 | L15: =0.5*1.12+0.5*L18 -> 0.74 | M15: =0.5*1.12+0.5*M18 -> 0.74 | N15: =0.5*1.12+0.5*N18 -> 0.74 | O15: =0.5*1.12+0.5*O18 -> 0.74 | P15: =0.5*1.12+0.5*P18 -> 0.74 | ... X15: =0.5*1.12+0.5*X18 -> 0.74
F16: 1978-1997 | G16: N/A | I16: =I15 -> 0.74 | J16: =J15 -> 0.74 | K16: =K15 -> 0.74 | L16: =L15 -> 0.74 | M16: =M15 -> 0.74 | N16: =N15 -> 0.74 | O16: =O15 -> 0.74 | P16: =P15 -> 0.74 | ... X16: =X15 -> 0.74
D17: Double pane | F17: 1998-2007 | G17: 2001 | H17: Table 1-H | I17: 0.49 | J17: 0.49 | K17: 0.81 | L17: 0.81 | M17: 0.81 | N17: 0.81 | O17: 0.81 | P17: 0.81 | Q17: 0.81 | R17: 0.49 | S17: 0.49 | T17: 0.49 | U17: 0.49 | V17: 0.49 | W17: 0.49 | X17: 0.49
F18: 2008-2018 | G18: 2013 | H18: Table 140.3-B | I18: 0.36 | J18: 0.36 | K18: 0.36 | L18: 0.36 | M18: 0.36 | N18: 0.36 | O18: 0.36 | P18: 0.36 | Q18: 0.36 | R18: 0.36 | S18: 0.36 | T18: 0.36 | U18: 0.36 | V18: 0.36 | W18: 0.36 | X18: 0.36
F19: Existing | H19: Weighted average of all 4 vintages | I19: {=_xlfn.BYCOL(TRANSPOSE(Weights!$C$4:$F$19)*I15:X18,_xlfn.LAMBDA(_xlpm.c,SUM(_xlpm.c)))} -> 0.57307168 | J19: 0.55825648 | K19: 0.74065411 | L19: 0.74894317 | M19: 0.75459304 | N19: 0.73441169 | O19: 0.7452322 | P19: 0.7328781 | Q19: 0.73653057 | R19: 0.52548245 | S19: 0.60008292 | T19: 0.60948745 | U19: 0.61162068 | V19: 0.58074918 | W19: 0.50217771 | X19: 0.54681589
F20: 2019+ | G20: 2025 | H20: Table 140.3-B | I20: 0.36 | J20: 0.36 | K20: 0.36 | L20: 0.36 | M20: 0.36 | N20: 0.36 | O20: 0.36 | P20: 0.36 | Q20: 0.34 | R20: 0.36 | S20: 0.34 | T20: 0.34 | U20: 0.34 | V20: 0.34 | W20: 0.34 | X20: 0.36
D21: Single Pane (CBECS 2018, ~ 50 % of warehouse that were built before 2000 are single pane) | E21: SHGC | F21: Pre 1978 | G21: N/A | H21: ASHRAE Handbook of Fundamentals for single pane (Table 10-Ch15) & T24 2013 for double pane (50%-50%) | I21: =0.79*0.5+I24*0.5 -> 0.52 | J21: =0.79*0.5+J24*0.5 -> 0.52 | K21: =0.79*0.5+K24*0.5 -> 0.52 | L21: =0.79*0.5+L24*0.5 -> 0.52 | M21: =0.79*0.5+M24*0.5 -> 0.52 | N21: =0.79*0.5+N24*0.5 -> 0.52 | O21: =0.79*0.5+O24*0.5 -> 0.52 | P21: =0.79*0.5+P24*0.5 -> 0.52 | ... X21: =0.79*0.5+X24*0.5 -> 0.52
F22: 1978-1997 | G22: N/A | I22: =I21 -> 0.52 | J22: =J21 -> 0.52 | K22: =K21 -> 0.52 | L22: =L21 -> 0.52 | M22: =M21 -> 0.52 | N22: =N21 -> 0.52 | O22: =O21 -> 0.52 | P22: =P21 -> 0.52 | ... X22: =X21 -> 0.52
D23: Double pane | F23: 1998-2007 | G23: 2001 | H23: Table 1-H (Non north 0-10%) | I23: 0.49 | J23: 0.47 | K23: 0.61 | L23: 0.61 | M23: 0.61 | N23: 0.61 | O23: 0.61 | P23: 0.61 | Q23: 0.61 | R23: 0.47 | S23: 0.47 | T23: 0.47 | U23: 0.47 | V23: 0.46 | W23: 0.46 | X23: 0.49
F24: 2008-2018 | G24: 2013 | H24: Table 140.3-B | I24: 0.25 | J24: 0.25 | K24: 0.25 | L24: 0.25 | M24: 0.25 | N24: 0.25 | O24: 0.25 | P24: 0.25 | Q24: 0.25 | R24: 0.25 | S24: 0.25 | T24: 0.25 | U24: 0.25 | V24: 0.25 | W24: 0.25 | X24: 0.25
F25: Existing | H25: Weighted average of all 4 vintages | I25: {=_xlfn.BYCOL(TRANSPOSE(Weights!$C$4:$F$19)*I21:X24,_xlfn.LAMBDA(_xlpm.c,SUM(_xlpm.c)))} -> 0.44394788 | J25: 0.41319517 | K25: 0.5300027 | L25: 0.53545877 | M25: 0.55165889 | N25: 0.52157508 | O25: 0.53432197 | P25: 0.52008268 | Q25: 0.5228805 | R25: 0.43296157 | S25: 0.45061328 | T25: 0.45783337 | U25: 0.46458454 | V25: 0.45965736 | W25: 0.40607918 | X25: 0.46043315
F26: 2019+ | G26: 2025 | H26: Table 140.3-B | I26: 0.25 | J26: 0.25 | K26: 0.25 | L26: 0.25 | M26: 0.25 | N26: 0.25 | O26: 0.25 | P26: 0.25 | Q26: 0.22 | R26: 0.25 | S26: 0.22 | T26: 0.22 | U26: 0.22 | V26: 0.22 | W26: 0.22 | X26: 0.25
A27: Skylight | B27: Warehouse | C27: Skylight | D27: Translucent | E27: U-factor IP | F27: Pre 1978 | G27: 1992 | H27: Table 1-I | I27: 0.85 | J27: 1.31 | K27: 1.31 | L27: 1.31 | M27: 1.31 | N27: 1.31 | O27: 1.31 | P27: 1.31 | Q27: 1.31 | R27: 1.31 | S27: 0.85 | T27: 0.85 | U27: 0.85 | V27: 0.85 | W27: 0.85 | X27: 0.85
F28: 1978-1997 | G28: 1992 | I28: =I27 -> 0.85 | J28: =J27 -> 1.31 | K28: =K27 -> 1.31 | L28: =L27 -> 1.31 | M28: =M27 -> 1.31 | N28: =N27 -> 1.31 | O28: =O27 -> 1.31 | P28: =P27 -> 1.31 | ... X28: =X27 -> 0.85
D29: Plastic curb mounted | F29: 1998-2007 | G29: 2001 | H29: Table 1-H | I29: 0.87 | J29: 1.1 | K29: 1.3 | L29: 1.3 | M29: 1.3 | N29: 1.3 | O29: 1.3 | P29: 1.3 | Q29: 1.3 | R29: 1.1 | S29: 1.1 | T29: 1.1 | U29: 1.1 | V29: 1.1 | W29: 1.1 | X29: 0.87
F30: 2008-2018 | G30: 2013 | H30: Table 140.3-B | I30: 0.88 | J30: 0.88 | K30: 0.88 | L30: 0.88 | M30: 0.88 | N30: 0.88 | O30: 0.88 | P30: 0.88 | Q30: 0.88 | R30: 0.88 | S30: 0.88 | T30: 0.88 | U30: 0.88 | V30: 0.88 | W30: 0.88 | X30: 0.88
F31: Existing | H31: Weighted average of all 4 vintages | I31: {=_xlfn.BYCOL(TRANSPOSE(Weights!$C$4:$F$19)*I27:X30,_xlfn.LAMBDA(_xlpm.c,SUM(_xlpm.c)))} -> 0.86325441 | J31: 1.1170956 | K31: 1.289607 | L31: 1.2999473 | M31: 1.2793409 | N31: 1.2913887 | O31: 1.2924247 | P31: 1.2905458 | Q31: 1.2942298 | R31: 1.1045983 | S31: 0.9152204 | T31: 0.91544842 | U31: 0.92472541 | V31: 0.96594627 | W31: 0.97655152 | X31: 0.86538996
F32: 2019+ | G32: 2025 | H32: Table 140.3-B | I32: 0.88 | J32: 0.88 | K32: 0.88 | L32: 0.88 | M32: 0.88 | N32: 0.88 | O32: 0.88 | P32: 0.88 | Q32: 0.88 | R32: 0.88 | S32: 0.88 | T32: 0.88 | U32: 0.88 | V32: 0.88 | W32: 0.88 | X32: 0.88
D33: Translucent | E33: SHGC | F33: Pre 1978 | G33: 1992 | H33: Table 1-I | I33: 0.81 | J33: 0.86 | K33: 0.86 | L33: 0.86 | M33: 0.86 | N33: 0.86 | O33: 0.86 | P33: 0.86 | Q33: 0.86 | R33: 0.86 | S33: 0.81 | T33: 0.81 | U33: 0.81 | V33: 0.81 | W33: 0.81 | X33: 0.81
F34: 1978-1997 | G34: 1992 | I34: =I33 -> 0.81 | J34: =J33 -> 0.86 | K34: =K33 -> 0.86 | L34: =L33 -> 0.86 | M34: =M33 -> 0.86 | N34: =N33 -> 0.86 | O34: =O33 -> 0.86 | P34: =P33 -> 0.86 | ... X34: =X33 -> 0.81
D35: Plastic curb mounted | F35: 1998-2007 | G35: 2001 | H35: Table 1-H (For SSR 2.1-5%) | I35: 0.58 | J35: 0.62 | K35: 0.65 | L35: 0.65 | M35: 0.65 | N35: 0.62 | O35: 0.62 | P35: 0.62 | Q35: 0.62 | R35: 0.62 | S35: 0.62 | T35: 0.62 | U35: 0.62 | V35: 0.58 | W35: 0.58 | X35: 0.58
F36: 2008-2018 | G36: 2013 | H36: There is no requirement in the code (considered same as 2001) | I36: =I35 -> 0.58 | J36: =J35 -> 0.62 | K36: =K35 -> 0.65 | L36: =L35 -> 0.65 | M36: =M35 -> 0.65 | N36: =N35 -> 0.62 | O36: =O35 -> 0.62 | P36: =P35 -> 0.62 | ... X36: =X35 -> 0.58
F37: Existing | H37: Weighted average of all 4 vintages | I37: {=_xlfn.BYCOL(TRANSPOSE(Weights!$C$4:$F$19)*I33:X36,_xlfn.LAMBDA(_xlpm.c,SUM(_xlpm.c)))} -> 0.68628369 | J37: 0.73085058 | K37: 0.80145063 | L37: 0.80870912 | M37: 0.73656656 | N37: 0.81732419 | O37: 0.78845029 | P37: 0.81919858 | Q37: 0.82007494 | R37: 0.6824551 | S37: 0.72474882 | T37: 0.72917713 | U37: 0.72757745 | V37: 0.67828703 | W37: 0.6292263 | X37: 0.65166288
F38: 2019+ | G38: 2025 | H38: There is no requirement in the code (considered same as 2001) | I38: =I35 -> 0.58 | J38: =J35 -> 0.62 | K38: =K35 -> 0.65 | L38: =L35 -> 0.65 | M38: =M35 -> 0.65 | N38: =N35 -> 0.62 | O38: =O35 -> 0.62 | P38: =P35 -> 0.62 | ... X38: =X35 -> 0.58
C40: Infiltration
D41: Building | E41: Zones | F41: Vintage | G41: I_75 (cfm/ft2) 6-sided Infiltration rate @ 75 pa | H41: Source | I41: I-design (cfm/ft²) (4-sided Infiltration rate at normal pressure) (Design flow rate approach and Flow/Exterior Wall Area calculation method)
...

Sheet HVAC System
A1: ="HVAC system - "&Prototype!A2 -> HVAC system - Warehouse
A2: Vintage | B2: Space/Thermal Zone | C2: Heating | D2: Cooling | E2: Air Distribution | F2: Other Systems | G2: Source
A3: Existing | B3: Office | C3: Furnace (Gas) | D3: DX (RTU) | E3: CAV | G3: CEUS 2022 + Engineering Judgement
B4: Fine Storage | C4: Furnace (Gas) | D4: DX (RTU) | E4: CAV
B5: Bulk Storage | C5: Unit Heater (Gas) (lower heating setpoint ) | D5: None | E5: CAV | F5: Exhaust fan
A6: New Construction | B6: Office | C6: HP | D6: DX (RTU) | E6: CAV | G6: T24, 2025
B7: Fine Storage | C7: HP | D7: DX (RTU) | E7: CAV
B8: Bulk Storage | C8: Unit Heater (Gas) (lower heating setpoint) | D8: None | E8: CAV | F8: Exhaust fan
A12: Efficiency of HVAC system (Efficiency is capacity-dependent. The following table provides a general estimate of system efficiency based on preliminary simulations in one climate zone, or assuming cooling load based on rule of thumb)
A13: Vintage | B13: Upgrade/Installed year | C13: Gas Furnace | D13: DX Cooling | E13: HP | F13: Unit Heater | G13: Source
A14: Pre 1978 | B14: 2008 | C14: Thermal Efficiency of 80% | D14: EER=9.0 when system <65 kBtu/h EER=9.7 when system >65 & <135 kBtu/h EER=9.5 when system >135 & <240 kBtu/h | F14: 80% gas efficiency, no cooling | G14: T24, 2008 for systems >65 kBtu/hr CFR 2009 for systems <65 kBtu/hr
A15: 1978-1997
A16: 1998-2007
A17: 2008-2018 | B17: 2013 | C17: Thermal Efficiency of 80% | D17: EER=9.0 when system <65 kBtu/h EER=11.2 when system >65 & <135 kBtu/h EER=11 when system >135 & <240 kBtu/h | F17: 80% gas efficiency, no cooling | G17: 10 CFR 2013 (431.97, Table 1) / T24, 2025, ACM 2013
A18: New Construction | B18: 2025 | E18: SEER2=13.4 / Cop=3.3, EER=11 when system <65 kBtu/h EER=11 when system >65 & <135 kBtu/h EER=10.6 when system >135 & <240 kBtu/h | F18: 80% gas efficiency, no cooling | G18: 10 CFR 2024 / T24, 2025, ACM 2025
A22: Fan Power
A23: Vintage | B23: Approach | C23: System | D23: Total Static Pressure (TSP) (in w.c.) | E23: Fan Efficiency [ACM 2025] | F23: Motor Efficiency | G23: Fan Power Index (W/cfm) | H23: Data Source
A24: Existing | B24: PNNL 90.1-2011, TSP | C24: CAV Office | D24: 2.5 (system <7,437 cfm) | E24: 0.65 | F24: ASHRAE 90.1, 2004, Table 10.8 * | H24: Fan power formula: PNNL 20405, 2010, section 5.2.2.5 TSP and fan efficiency: PNNL 20405, 2010, Table 5.11, 90.1-04ac values Motor efficiency: ASHRAE 90.1, 2004, Table 10.8
C25: CAV Fine Storage | D25: 2.5 (system <7,437 cfm) 4.09 (system >7,437 cfm | E25: 0.65
C26: Unit heater in Bulk Storage | D26: 0.2 | E26: 0.65
A27: Brake horsepower (bhp) = (Supply cfm × TSP in w.c.) / (6356 × fan efficiency)
A28: Fan power (w/cfm) = (bhp × 746) / ( supply cfm × motor efficiency )
A29: New Construction | B29: ACM 2025 | C29: HP Office (system <5,000 cfm) | D29: TSP = fan power × motor efficiency × fan efficiency × 6356 / 746 | E29: 0.65 | F29: 2025 ACM Table 12 ** | G29: 0.744 (system <5,000 cfm in office space | H29: Fan power index: [ACM 2025, Table 13] Motor efficiency: [ACM 2025, Table 12]
C30: HP Fine Storage, >10,000 cfm | D30: TSP = fan power × motor efficiency × fan efficiency × 6356 / 746 | G30: 0.676
C31: Unit heater in Bulk Storage | D31: TSP = fan power × motor efficiency × fan efficiency × 6356 / 745 | G31: 0.62 (5,000-10,000 cfm) 0.605 (>10,000 cfm)
A33: * According to PNNL 20405 section 5.2.2.5, the full-load efficiency of the motor serving the fan is taken from ASHRAE 90.1, 2004, Table 10.8, based on motor nameplate and assuming enclosed motors operating at 1,800 rotations per minute (rpm) Motor nameplate size (bhp) = brake horsepower (bhp) × 1.1 ( using a 10% oversizing factor)
A34: "** The full‑load efficiency of the motor serving the fan is taken from ACM 2025 Table 12 based on the cfm of the fan. Brake horsepower (bhp) = (Supply cfm from sizing run × fan power in W/cfm) / 746. Note: ACM System 6 VAV >10,000 cfm."

Sheet Thermostat
A1: ="Thermostat Setpoints - "&Prototype!A2 -> Thermostat Setpoints - Warehouse
A2: Space/Thermal Zone | B2: Setpoint | C2: CZ1 | D2: CZ2 | E2: CZ3 | F2: CZ4 | G2: CZ5 | H2: CZ6 | I2: CZ7 | J2: CZ8 | K2: CZ9 | L2: CZ10 | M2: CZ11 | N2: CZ12 | O2: CZ13 | P2: CZ14 | Q2: CZ15 | R2: CZ16 | S2: Source
A3: =Zones!B3 -> Office | B3: Heating Setpoint (F) | C3: 70 | D3: 70 | E3: 70 | F3: 70 | G3: 70 | H3: 70 | I3: 70 | J3: 70 | K3: 70 | L3: 70 | M3: 70 | N3: 70 | O3: 70 | P3: 70 | Q3: 70 | R3: 70 | S3: T24 2022 - Appendix 5.4B
B4: Heating Setback (F) | C4: 60 | D4: 60 | E4: 60 | F4: 60 | G4: 60 | H4: 60 | I4: 60 | J4: 60 | K4: 60 | L4: 60 | M4: 60 | N4: 60 | O4: 60 | P4: 60 | Q4: 60 | R4: 60
B5: Cooling Setpoint (F) | C5: 75 | D5: 75 | E5: 75 | F5: 75 | G5: 75 | H5: 75 | I5: 75 | J5: 75 | K5: 75 | L5: 75 | M5: 75 | N5: 75 | O5: 75 | P5: 75 | Q5: 75 | R5: 75
B6: Cooling Setback (F) | C6: 85 | D6: 85 | E6: 85 | F6: 85 | G6: 85 | H6: 85 | I6: 85 | J6: 85 | K6: 85 | L6: 85 | M6: 85 | N6: 85 | O6: 85 | P6: 85 | Q6: 85 | R6: 85
A7: =Zones!B4 -> FineStorage | B7: Heating Setpoint (F) | C7: 70 | D7: 70 | E7: 70 | F7: 70 | G7: 70 | H7: 70 | I7: 70 | J7: 70 | K7: 70 | L7: 70 | M7: 70 | N7: 70 | O7: 70 | P7: 70 | Q7: 70 | R7: 70 | S7: T24 2022 - Appendix 5.4B
B8: Heating Setback (F) | C8: 60 | D8: 60 | E8: 60 | F8: 60 | G8: 60 | H8: 60 | I8: 60 | J8: 60 | K8: 60 | L8: 60 | M8: 60 | N8: 60 | O8: 60 | P8: 60 | Q8: 60 | R8: 60
B9: Cooling Setpoint (F) | C9: 75 | D9: 75 | E9: 75 | F9: 75 | G9: 75 | H9: 75 | I9: 75 | J9: 75 | K9: 75 | L9: 75 | M9: 75 | N9: 75 | O9: 75 | P9: 75 | Q9: 75 | R9: 75
B10: Cooling Setback (F) | C10: 85 | D10: 85 | E10: 85 | F10: 85 | G10: 85 | H10: 85 | I10: 85 | J10: 85 | K10: 85 | L10: 85 | M10: 85 | N10: 85 | O10: 85 | P10: 85 | Q10: 85 | R10: 85
A11: =Zones!B5 -> BulkStorage | B11: Heating Setpoint (F)* | C11: 50 | D11: 50 | E11: 50 | F11: 50 | G11: 50 | H11: 50 | I11: 50 | J11: 50 | K11: 50 | L11: 50 | M11: 50 | N11: 50 | O11: 50 | P11: 50 | Q11: 50 | R11: 50 | S11: PNNL ASHRAE 90.1 2022, Warehouse prototype
A13: * Bulk storage is defined as a general inventory space that only needs freeze protection.

Sheet Ventilation
A1: ="Outdoor Airflow Rate - "&Prototype!A2 -> Outdoor Airflow Rate - Warehouse
A2: Space/Thermal Zone | B2: Number of People | C2: Floor Area (ft²) | D2: cfm/person [T24, 2025, Equation 120.1-F and Table 120.1-A] | E2: cfm/ft² [T24, 2025, Equation 120.1-F and Table 120.1-A] | F2: Required Exhaust Rate [T24, 2025, Table 120.1-B – minimum exhaust rates] | G2: Total cfm Driven by People | H2: Total cfm Driven by Area | I2: Total cfm Driven by Exhaust | J2: Total cfm | K2: Notes
A3: =Zones!B3 -> Office | B3: =Zones!K3 -> 12.74875 | C3: =Zones!H3 -> 2549.75 | D3: 15 | E3: 0.15 | F3: - | G3: =B3*D3 -> 191.23125 | H3: =C3*E3 -> 382.4625 | I3: =F3 -> - | J3: =MAX(G3:I3) -> 382.4625
A4: =Zones!B4 -> FineStorage | B4: =Zones!K4 -> 14.99855 | C4: =Zones!H4 -> 14998.55 | D4: 15 | E4: 0.15 | F4: - | G4: =B4*D4 -> 224.97825 | H4: =C4*E4 -> 2249.7825 | I4: =F4 -> - | J4: =MAX(G4:I4) -> 2249.7825
A5: =Zones!B5 -> BulkStorage | B5: =Zones!K5 -> 34.49673 | C5: =Zones!H5 -> 34496.73 | D5: 15 | E5: 0.15 | F5: - | G5: =B5*D5 -> 517.45095 | H5: =C5*E5 -> 5174.5095 | I5: =F5 -> - | J5: =MAX(G5:I5) -> 5174.5095 | K5: This amount of OA cfm appear low. May be updated with further research.
A7: Fine storage is defined for normal inventory that doesn't require an extra exhaust rate based on the space functions in T24, Part6, 2025, Table 120.1 B.

Sheet Water Heater
A1: ="Water Heater - "&Prototype!A2 -> Water Heater - Warehouse
A2: Vintage | B2: WH Type | C2: Efficiency | D2: Number of WH | E2: Tank Volume (gal) | F2: Tank Loss | G2: Source
A3: Existing | B3: Electric resistance WH | C3: 1 | D3: 1 | E3: See table below for CZ-specific values: Climate Zone Water Heater Sizing and Loss Coefficients, Storage Volume column (col G) | F3: See table below: Climate Zone Water Heater Sizing and Loss Coefficients, Standby Loss column (col H) | G3: See table below for sources: Climate Zone Water Heater Sizing and Loss Coefficients
A4: New Construction | B4: Electric resistance WH | C4: 1 | D4: 1 | E4: See table below for CZ-specific values: Climate Zone Water Heater Sizing and Loss Coefficients, Storage Volume column (col G) | F4: See table below: Climate Zone Water Heater Sizing and Loss Coefficients, Standby Loss column (col H) | G4: See table below for sources: Climate Zone Water Heater Sizing and Loss Coefficients
A7: Peak Hot Water Consumption
A8: Space Name | B8: Baseline WH Type [T24, 2022, Appendix 5.4A , sheet: "2022 SpaceFuncData-Input"] | C8: Total Area (ft²) | D8: Number of People | E8: Hot Water Usage Specification (gal/hr per person) [T24, 2022, Appendix 5.4A , sheet: "2022 SpaceFuncData-Input"] | F8: Peak Hot Water Usage (gal/hr) | G8: Peak Hot Water Usage (gal/min) | H8: Note
A9: =Zones!B3 -> Office | B9: Electric | C9: =Zones!H3 -> 2549.75 | D9: =Zones!K3 -> 12.74875 | E9: 0.18 | F9: =D9*E9 -> 2.294775 | G9: =F9/60 -> 0.03824625 | H9: For space types marked with an asterisk (the ‘*’ symbol), the water‑heater type is listed as electric in Appendix 5.4A, sheet ‘2022 SpaceFuncData‑Input.’ However, we modified the value based on CEUS data, which indicates that gas is the primary fuel type.
A10: =Zones!B4 -> FineStorage | B10: Electric | C10: =Zones!H4 -> 14998.55 | D10: =Zones!K4 -> 14.99855 | E10: 0.18 | F10: =D10*E10 -> 2.699739 | G10: =F10/60 -> 0.04499565
A11: =Zones!B5 -> BulkStorage | B11: Electric | C11: =Zones!H5 -> 34496.73 | D11: =Zones!K5 -> 34.49673 | E11: 0.18 | F11: =D11*E11 -> 6.2094114 | G11: =F11/60 -> 0.10349019
A12: Total | B12: Gas storage | F12: =_xlfn.LET( _xlpm.g,SUMIF($B$9:$B$11,"Gas*",$F$9:$F$11), _xlpm.e,SUMIF($B$9:$B$11,"Electric*",$F$9:$F$11), IF(AND(_xlpm.g>0,_xlpm.e>0),_xlpm.g,IF(_xlpm.g>0,MAX(75,_xlpm.g),0))) -> 0 | H12: Minimum peak hot water usage is 75 gal according to ACM 2025
A13: Total | B13: Electric resistance | F13: =_xlfn.LET( _xlpm.g,SUMIF($B$9:$B$11,"Gas*",$F$9:$F$11), _xlpm.e,SUMIF($B$9:$B$11,"Electric*",$F$9:$F$11), IF(AND(_xlpm.g>0,_xlpm.e>0),_xlpm.e,IF(_xlpm.e>0,MAX(75,_xlpm.e),0))) -> 75
A17: Design supply temperature (°F) | B17: 135 | C17: CEC-400-2022-009-CMF-REV2-AP5.4B
A18: WH system factor | B18: 0.6 | C18: 2025 ACM §5.9.2 Rated Capacity
A19: Water mass conversion (lb/gal) | B19: 8.2877 | C19: 2025 ACM §5.9.2 Rated Capacity
A20: Reheat multiplier | B20: 0.4 | C20: 2025 ACM §5.9.2 Storage Volume
A21: Climate Zone Water Heater Sizing and Loss Coefficients
A22: Climate Zone | B22: Minimum Monthly Mains Temp (°F) [T24 2022 - Appendix 5.4B] | C22: Heat Output (Btu/hr) [ACM, 2025, 5.9.2: Rated capacity section] | D22: WH Capacity (Btu/hr) [ACM, 2025, 5.9.2: Rated capacity section] | E22: Required Energy Input (Btu/hr) | F22: Storage Volume (gal) | G22: Standby Loss [Title 20, §1605.1 Table F-4; Appendix B: Water Heating Calculation Method] | I22: Off/On Cycle Loss Coefficient to Ambient Temp | K22: Source/Note
A23: CZ01 | B23: 47.9 | C23: =$F$13*($B$17-B23)*$B$19 -> 54139.4 | D23: =C23*$B$18 -> 32483.64 | E23: =_xlfn.LET(_xlpm.x,_xlfn.XLOOKUP(D23,$D$44:$D$58,$D$44:$D$58,"",1),IF(_xlpm.x="",ROUNDUP(D23,0),_xlpm.x)) -> 34121 | F23: =_xlfn.LET(_xlpm.v,MAX(30,$F$13*$B$20),_xlpm.x,_xlfn.XLOOKUP(_xlpm.v,$G$44:$G$58,$G$44:$G$58,"",1),IF(_xlpm.x="",ROUNDUP(_xlpm.v,0),_xlpm.x)) -> 30 | G23: =0.3+27/F23 -> 1.2 | H23: =IF($F$13>0,"%/hr","Btu/hr") -> %/hr | I23: =0.0834*G23*F23 -> 3.0024 | J23: Btu/h·°F | K23: Required Energy Input: vendor/available catalog size (Market data table). Storage Volume: standard/available catalog tank size (Market data table).
A24: CZ02 | B24: 50.8 | C24: =$F$13*($B$17-B24)*$B$19 -> 52336.825 | D24: =C24*$B$18 -> 31402.095 | E24: =_xlfn.LET(_xlpm.x,_xlfn.XLOOKUP(D24,$D$44:$D$58,$D$44:$D$58,"",1),IF(_xlpm.x="",ROUNDUP(D24,0),_xlpm.x)) -> 34121 | F24: =_xlfn.LET(_xlpm.v,MAX(30,$F$13*$B$20),_xlpm.x,_xlfn.XLOOKUP(_xlpm.v,$G$44:$G$58,$G$44:$G$58,"",1),IF(_xlpm.x="",ROUNDUP(_xlpm.v,0),_xlpm.x)) -> 30 | G24: =0.3+27/F24 -> 1.2 | H24: =IF($F$13>0,"%/hr","Btu/hr") -> %/hr | I24: =0.0834*G24*F24 -> 3.0024 | J24: Btu/h·°F
A25: CZ03 | B25: 52.2 | C25: =$F$13*($B$17-B25)*$B$19 -> 51466.617 | D25: =C25*$B$18 -> 30879.97 | E25: =_xlfn.LET(_xlpm.x,_xlfn.XLOOKUP(D25,$D$44:$D$58,$D$44:$D$58,"",1),IF(_xlpm.x="",ROUNDUP(D25,0),_xlpm.x)) -> 34121 | F25: =_xlfn.LET(_xlpm.v,MAX(30,$F$13*$B$20),_xlpm.x,_xlfn.XLOOKUP(_xlpm.v,$G$44:$G$58,$G$44:$G$58,"",1),IF(_xlpm.x="",ROUNDUP(_xlpm.v,0),_xlpm.x)) -> 30 | G25: =0.3+27/F25 -> 1.2 | H25: =IF($F$13>0,"%/hr","Btu/hr") -> %/hr | I25: =0.0834*G25*F25 -> 3.0024 | J25: Btu/h·°F
A26: CZ04 | B26: 52.7 | C26: =$F$13*($B$17-B26)*$B$19 -> 51155.828 | D26: =C26*$B$18 -> 30693.497 | E26: =_xlfn.LET(_xlpm.x,_xlfn.XLOOKUP(D26,$D$44:$D$58,$D$44:$D$58,"",1),IF(_xlpm.x="",ROUNDUP(D26,0),_xlpm.x)) -> 30709 | F26: =_xlfn.LET(_xlpm.v,MAX(30,$F$13*$B$20),_xlpm.x,_xlfn.XLOOKUP(_xlpm.v,$G$44:$G$58,$G$44:$G$58,"",1),IF(_xlpm.x="",ROUNDUP(_xlpm.v,0),_xlpm.x)) -> 30 | G26: =0.3+27/F26 -> 1.2 | H26: =IF($F$13>0,"%/hr","Btu/hr") -> %/hr | I26: =0.0834*G26*F26 -> 3.0024 | J26: Btu/h·°F
A27: CZ05 | B27: 51.6 | C27: =$F$13*($B$17-B27)*$B$19 -> 51839.563 | D27: =C27*$B$18 -> 31103.738 | E27: =_xlfn.LET(_xlpm.x,_xlfn.XLOOKUP(D27,$D$44:$D$58,$D$44:$D$58,"",1),IF(_xlpm.x="",ROUNDUP(D27,0),_xlpm.x)) -> 34121 | F27: =_xlfn.LET(_xlpm.v,MAX(30,$F$13*$B$20),_xlpm.x,_xlfn.XLOOKUP(_xlpm.v,$G$44:$G$58,$G$44:$G$58,"",1),IF(_xlpm.x="",ROUNDUP(_xlpm.v,0),_xlpm.x)) -> 30 | G27: =0.3+27/F27 -> 1.2 | H27: =IF($F$13>0,"%/hr","Btu/hr") -> %/hr | I27: =0.0834*G27*F27 -> 3.0024 | J27: Btu/h·°F
A28: CZ06 | B28: 56.8 | C28: =$F$13*($B$17-B28)*$B$19 -> 48607.36 | D28: =C28*$B$18 -> 29164.416 | E28: =_xlfn.LET(_xlpm.x,_xlfn.XLOOKUP(D28,$D$44:$D$58,$D$44:$D$58,"",1),IF(_xlpm.x="",ROUNDUP(D28,0),_xlpm.x)) -> 30709 | F28: =_xlfn.LET(_xlpm.v,MAX(30,$F$13*$B$20),_xlpm.x,_xlfn.XLOOKUP(_xlpm.v,$G$44:$G$58,$G$44:$G$58,"",1),IF(_xlpm.x="",ROUNDUP(_xlpm.v,0),_xlpm.x)) -> 30 | G28: =0.3+27/F28 -> 1.2 | H28: =IF($F$13>0,"%/hr","Btu/hr") -> %/hr | I28: =0.0834*G28*F28 -> 3.0024 | J28: Btu/h·°F
A29: CZ07 | B29: 58.4 | C29: =$F$13*($B$17-B29)*$B$19 -> 47612.836 | D29: =C29*$B$18 -> 28567.702 | E29: =_xlfn.LET(_xlpm.x,_xlfn.XLOOKUP(D29,$D$44:$D$58,$D$44:$D$58,"",1),IF(_xlpm.x="",ROUNDUP(D29,0),_xlpm.x)) -> 30709 | F29: =_xlfn.LET(_xlpm.v,MAX(30,$F$13*$B$20),_xlpm.x,_xlfn.XLOOKUP(_xlpm.v,$G$44:$G$58,$G$44:$G$58,"",1),IF(_xlpm.x="",ROUNDUP(_xlpm.v,0),_xlpm.x)) -> 30 | G29: =0.3+27/F29 -> 1.2 | H29: =IF($F$13>0,"%/hr","Btu/hr") -> %/hr | I29: =0.0834*G29*F29 -> 3.0024 | J29: Btu/h·°F
A30: CZ08 | B30: 58.4 | C30: =$F$13*($B$17-B30)*$B$19 -> 47612.836 | D30: =C30*$B$18 -> 28567.702 | E30: =_xlfn.LET(_xlpm.x,_xlfn.XLOOKUP(D30,$D$44:$D$58,$D$44:$D$58,"",1),IF(_xlpm.x="",ROUNDUP(D30,0),_xlpm.x)) -> 30709 | F30: =_xlfn.LET(_xlpm.v,MAX(30,$F$13*$B$20),_xlpm.x,_xlfn.XLOOKUP(_xlpm.v,$G$44:$G$58,$G$44:$G$58,"",1),IF(_xlpm.x="",ROUNDUP(_xlpm.v,0),_xlpm.x)) -> 30 | G30: =0.3+27/F30 -> 1.2 | H30: =IF($F$13>0,"%/hr","Btu/hr") -> %/hr | I30: =0.0834*G30*F30 -> 3.0024 | J30: Btu/h·°F
A31: CZ09 | B31: 57.6 | C31: =$F$13*($B$17-B31)*$B$19 -> 48110.098 | D31: =C31*$B$18 -> 28866.059 | E31: =_xlfn.LET(_xlpm.x,_xlfn.XLOOKUP(D31,$D$44:$D$58,$D$44:$D$58,"",1),IF(_xlpm.x="",ROUNDUP(D31,0),_xlpm.x)) -> 30709 | F31: =_xlfn.LET(_xlpm.v,MAX(30,$F$13*$B$20),_xlpm.x,_xlfn.XLOOKUP(_xlpm.v,$G$44:$G$58,$G$44:$G$58,"",1),IF(_xlpm.x="",ROUNDUP(_xlpm.v,0),_xlpm.x)) -> 30 | G31: =0.3+27/F31 -> 1.2 | H31: =IF($F$13>0,"%/hr","Btu/hr") -> %/hr | I31: =0.0834*G31*F31 -> 3.0024 | J31: Btu/h·°F
A32: CZ10 | B32: 57.1 | C32: =$F$13*($B$17-B32)*$B$19 -> 48420.887 | D32: =C32*$B$18 -> 29052.532 | E32: =_xlfn.LET(_xlpm.x,_xlfn.XLOOKUP(D32,$D$44:$D$58,$D$44:$D$58,"",1),IF(_xlpm.x="",ROUNDUP(D32,0),_xlpm.x)) -> 30709 | F32: =_xlfn.LET(_xlpm.v,MAX(30,$F$13*$B$20),_xlpm.x,_xlfn.XLOOKUP(_xlpm.v,$G$44:$G$58,$G$44:$G$58,"",1),IF(_xlpm.x="",ROUNDUP(_xlpm.v,0),_xlpm.x)) -> 30 | G32: =0.3+27/F32 -> 1.2 | H32: =IF($F$13>0,"%/hr","Btu/hr") -> %/hr | I32: =0.0834*G32*F32 -> 3.0024 | J32: Btu/h·°F
A33: CZ11 | B33: 50.5 | C33: =$F$13*($B$17-B33)*$B$19 -> 52523.299 | D33: =C33*$B$18 -> 31513.979 | E33: =_xlfn.LET(_xlpm.x,_xlfn.XLOOKUP(D33,$D$44:$D$58,$D$44:$D$58,"",1),IF(_xlpm.x="",ROUNDUP(D33,0),_xlpm.x)) -> 34121 | F33: =_xlfn.LET(_xlpm.v,MAX(30,$F$13*$B$20),_xlpm.x,_xlfn.XLOOKUP(_xlpm.v,$G$44:$G$58,$G$44:$G$58,"",1),IF(_xlpm.x="",ROUNDUP(_xlpm.v,0),_xlpm.x)) -> 30 | G33: =0.3+27/F33 -> 1.2 | H33: =IF($F$13>0,"%/hr","Btu/hr") -> %/hr | I33: =0.0834*G33*F33 -> 3.0024 | J33: Btu/h·°F
A34: CZ12 | B34: 51.4 | C34: =$F$13*($B$17-B34)*$B$19 -> 51963.879 | D34: =C34*$B$18 -> 31178.327 | E34: =_xlfn.LET(_xlpm.x,_xlfn.XLOOKUP(D34,$D$44:$D$58,$D$44:$D$58,"",1),IF(_xlpm.x="",ROUNDUP(D34,0),_xlpm.x)) -> 34121 | F34: =_xlfn.LET(_xlpm.v,MAX(30,$F$13*$B$20),_xlpm.x,_xlfn.XLOOKUP(_xlpm.v,$G$44:$G$58,$G$44:$G$58,"",1),IF(_xlpm.x="",ROUNDUP(_xlpm.v,0),_xlpm.x)) -> 30 | G34: =0.3+27/F34 -> 1.2 | H34: =IF($F$13>0,"%/hr","Btu/hr") -> %/hr | I34: =0.0834*G34*F34 -> 3.0024 | J34: Btu/h·°F
A35: CZ13 | B35: 51.7 | C35: =$F$13*($B$17-B35)*$B$19 -> 51777.406 | D35: =C35*$B$18 -> 31066.443 | E35: =_xlfn.LET(_xlpm.x,_xlfn.XLOOKUP(D35,$D$44:$D$58,$D$44:$D$58,"",1),IF(_xlpm.x="",ROUNDUP(D35,0),_xlpm.x)) -> 34121 | F35: =_xlfn.LET(_xlpm.v,MAX(30,$F$13*$B$20),_xlpm.x,_xlfn.XLOOKUP(_xlpm.v,$G$44:$G$58,$G$44:$G$58,"",1),IF(_xlpm.x="",ROUNDUP(_xlpm.v,0),_xlpm.x)) -> 30 | G35: =0.3+27/F35 -> 1.2 | H35: =IF($F$13>0,"%/hr","Btu/hr") -> %/hr | I35: =0.0834*G35*F35 -> 3.0024 | J35: Btu/h·°F
... A38: CZ16 | B38: 41.4 | C38: =$F$13*($B$17-B38)*$B$19 -> 58179.654 | D38: =C38*$B$18 -> 34907.792 | E38: =_xlfn.LET(_xlpm.x,_xlfn.XLOOKUP(D38,$D$44:$D$58,$D$44:$D$58,"",1),IF(_xlpm.x="",ROUNDUP(D38,0),_xlpm.x)) -> 40946 | F38: =_xlfn.LET(_xlpm.v,MAX(30,$F$13*$B$20),_xlpm.x,_xlfn.XLOOKUP(_xlpm.v,$G$44:$G$58,$G$44:$G$58,"",1),IF(_xlpm.x="",ROUNDUP(_xlpm.v,0),_xlpm.x)) -> 30 | G38: =0.3+27/F38 -> 1.2 | H38: =IF($F$13>0,"%/hr","Btu/hr") -> %/hr | I38: =0.0834*G38*F38 -> 3.0024 | J38: Btu/h·°F
A42: Market data
A43: Catalog gas input (Btu/h) | B43: Input source | C43: Elec resistance tank (kW) | D43: Elec resistance (Btu/h) | E43: Catalog gas tank (gal) | F43: Tank source | G43: Elec tank (gal) | H43: Elec tank source | I43: =HYPERLINK("#'Note'!A1","Sources and links → Note tab") -> Sources and links → Note tab
A44: 60000 | B44: Grainger | C44: 1.5 | D44: 5118 | E44: 34 | F44: ENERGY STAR | G44: 6 | H44: Grainger
A45: 75100 | B45: Grainger | C45: 2 | D45: 6824 | E45: 35 | F45: Grainger | G45: 10 | H45: Grainger
A46: 76000 | B46: Both | C46: 3 | D46: 10236 | E46: 48 | F46: Grainger | G46: 15 | H46: Grainger
A47: 80000 | B47: Grainger | C47: 4.5 | D47: 15355 | E47: 50 | F47: Both | G47: 20 | H47: Grainger
A48: 99900 | B48: ENERGY STAR | C48: 6 | D48: 20473 | E48: 55 | F48: ENERGY STAR | G48: 28 | H48: Grainger
A49: 100000 | B49: Both | C49: 8 | D49: 27297 | E49: 60 | F49: ENERGY STAR | G49: 30 | H49: Grainger
A50: 120000 | B50: ENERGY STAR | C50: 9 | D50: 30709 | E50: 65 | F50: Both | G50: 36 | H50: Grainger
...

Sheet Interior Lights
A1: ="Interior Lighting - "&Prototype!A2 -> Interior Lighting - Warehouse
A2: Space Type | B2: New Construction | E2: Existing | H2: Notes
B3: LPD (W/ft²) | C3: Additional LPD for Portable Lighting (W/ft²) | D3: Source | E3: LPD (W/ft²) | F3: Additional LPD for Portable Lighting (W/ft²) | G3: Source
A4: Office Area (>250 square feet) | B4: 0.6 | C4: 0.1 | D4: T24, 2025, Table 140.6-C (Area category method) | E4: 0.75 | G4: T24, 2016, Table 140.6-C (Area category method) LPD of "All other spaces" is considered for storage space | H4: It is assumed that 50% of the additional allowance lighting is in use.
A5: Storage, Commercial/Industrial (Warehouse) | B5: 0.4 | E5: 0.5
A28: Background Data [To be deleted prior to publication]
A32: Existing | B32: Whole Building | C32: All other building | D32: 0.4 | F32: T24, 2019, Table 140.6 B
B33: Area Category | C33: =Zones!C23 -> 0 | D33: 0.65 | F33: T24, 2019, Table 140.6-C
C34: =Zones!C24 -> 0 | D34: 0.4
C35: =Zones!C25 -> 0 | D35: 0.4
A37: Existing | B37: Whole Building | C37: All other building | D37: 0.5 | F37: T24, 2016, Table 140.6 B
B38: Area Category | C38: ZONE1 OFFICE | D38: 0.75 | F38: T24, 2016, Table 140.6-C
C39: ZONE2 FINE STORAGE | D39: 0.5
C40: ZONE3 BULK STORAGE | D40: 0.5
A42: Existing | B42: Whole Building | C42: All other building | D42: 0.6 | F42: T24, 2013, Table 140.6 B
B43: Area Category | C43: ZONE1 OFFICE | D43: 0.75 | F43: T24, 2013, Table 140.6-C
C44: ZONE2 FINE STORAGE | D44: 0.6
C45: ZONE3 BULK STORAGE | D45: 0.6

Sheet Equipment
A1: ="Equipment - "&Prototype!A2 -> Equipment - Warehouse
A2: Space Type | B2: Plug Load Power Density (W/ft²) | C2: Destratification Fan Load Power Density (W/ft²) | D2: Forklift Load Power Density (W/ft²) | E2: Source
A3: Office Area (>250 square feet) | B3: 0.7 | E3: Plug load and schedules project with CEC, 2025
A4: Storage, Commercial/Industrial (Warehouse) | B4: 0.2 | C4: 0.09 | D4: =10*5*0.7*1000/50000 -> 0.7 | E4: Plug load: T24 2022 - Appendix 5.4A: "Space Use Data-T24N-2023" Destratification: Electricity usage of destratification fans. Assumptions: 2 ACH (Bulk Storage: 32,197 cfm (965,908*2/60) FineStorage:12808 cfm (384,263*2/60)) , 3 HVLS fans each ~15,000 cfm and 1.5 kw for each: Total 0.09 w/sf https://continentalfan.com/wp-content/uploads/2022/12/Destratification_Fans_Wholesale_Ventilation_Products.pdf? Forklift: Electricity usage for charging forklift machines/robots, distributed to both storage spaces. Assumption: 5 chargers each 10 K , 0.7 diversity
A5: Storage, Commercial/Industrial (Warehouse) | E5: Electricity usage of destratification fans. Assumptions: 2 ACH (Bulk Storage: 32,197 cfm (965,908*2/60) FineStorage:12808 cfm (384,263*2/60)) , 3 HVLS fans each ~15,000 cfm and 1.5 kw for each: Total 0.09 w/sf https://continentalfan.com/wp-content/uploads/2022/12/Destratification_Fans_Wholesale_Ventilation_Products.pdf? | F5: https://continentalfan.com/destratification-fan-application-guide/?utm
A6: Storage, Commercial/Industrial (Warehouse) | E6: Electricity usage for charging forklift machines/robots, distributed to both storage spaces. Assumption: 5 chargers each 10 K , 0.7 diversity | F6: U.S. Department of Energy, Better Buildings, "Battery Charging Basics for Forklifts" Pacific Northwest National Laboratory (PNNL), "Warehouse Energy Use: Characterization and Opportunities" Class I–III electric forklift chargers typically draw 4–10 kW each. Fast/Opportunity chargers may draw 10–20 kW, but 4–8 kW is most common. | G6: (From DOE BB resources / charger efficiency studies) : "Industrial battery chargers for Class I–III forklifts commonly draw 4 to 8 kW during bulk charging."
A20: Background Data [To be deleted prior to publication]

Sheet Ext Lighting
A1: ="Exterior Lighting - "&Prototype!A2 -> Exterior Lighting - Warehouse
A2: Motion Controlled Luminaires (W) | B2: Non-motion Controlled Luminaires (W) | C2: Total (W) | D2: Source
A3: =G15 -> 751.5569 | B3: =G16 -> 1380.4315 | C3: =B3+A3 -> 2131.9884 | D3: T24, 2022
A8: Exterior Lighting
A9: Items (Assume LZ2) | B9: Assumptions [2019 Outdoor Lighting CASE Report & PNNL 90.1-2010 TSD] | D9: Unit | E9: Lighting Power Allowance [T24, 2025, Table 140.7-A & 140.7-B] | F9: Unit | G9: Exterior Lighting Power (W)
A10: IWA (Initial Wattage Allowance) | E10: 200 | F10: (W) | G10: =$E10 -> 200
A11: Parking area | B11: 400 ft² for every parking space 1 parking space per 830 ft² of gross building area | C11: =B22/830*400 -> 25081.942 | D11: (ft²) | E11: 0.019 | F11: (W/ft²) | G11: =$E11*C11 -> 476.5569
A12: Building Entrance | B12: 5 building entrance (1 per 10,000 ft² footprint) | C12: =5 -> 5 | D12: (count) | E12: 15 | F12: (W/ea) | G12: =E12*C12 -> 75
A13: Hardscape Ornamental Light | B13: 0.1 ft² per 1 ft² of gross building area for hardscape ornamental light | C13: =B22*0.1 -> 5204.503 | D13: (ft²) | E13: 0.007 | F13: (W/ft²) | G13: =E13*C13 -> 36.431521
A14: Building façade | B14: 0.1 W per 1 ft² of facade area Façade Area = Perimeter × 0.5 × 28 ft (30 ft is the max height that is lit) * The 0.5 factor assumes that only half of the perimeter walls are lit. -Formula is developed based on the 2019 Outdoor Lighting CASE report | C14: =B21*0.5*28 -> 13440 | D14: (ft²) | E14: 0.1 | F14: (W/ft²) | G14: =E14*C14 -> 1344
A15: Motion controlled Luminaires | G15: =G11+G10+G12 -> 751.5569
A16: Non-motion-controlled Luminaires | G16: =G13+G14 -> 1380.4315
A17: TOTAL | G17: =G15+G16 -> 2131.9884
A19: *Developed based on 2019 Outdoor Lighting CASE Report
A21: Perimeter (ft) | B21: =(330+150)*2 -> 960
A22: Total floor area (ft²) | B22: =Zones!H6 -> 52045.03
A23: Floors | B23: 1

Sheet Schedules
A1: ="Schedules - "&Prototype!A2 -> Schedules - Warehouse
A2: Zone | B2: Schedule Category | C2: Schedule | D2: Source | E2: Type | F2: Hour
F3: 1 | G3: 2 | H3: 3 | I3: 4 | J3: 5 | K3: 6 | L3: 7 | M3: 8 | N3: 9 | O3: 10 | P3: 11 | Q3: 12 | R3: 13 | S3: 14 | T3: 15 | U3: 16 | V3: 17 | W3: 18 | X3: 19 | Y3: 20 | Z3: 21 | AA3: 22 | AB3: 23 | AC3: 24
A4: Fine storage | B4: FineStorage | C4: Occupancy | D4: T24 2022 - Appendix 5.4B, [Warehouse] (Start and end hours of weekday schedule has been shifted to stay align with the plug load project with CEC) with Saturday Occupied. | E4: Weekday | F4: 0 | G4: 0 | H4: 0 | I4: 0 | J4: 0 | K4: 0.15 | L4: 0.7 | M4: 0.9 | N4: 0.9 | O4: 0.9 | P4: 0.9 | Q4: 0.9 | R4: 0.5 | S4: 0.85 | T4: 0.85 | U4: 0.2 | V4: 0 | W4: 0 | X4: 0 | Y4: 0 | Z4: 0 | AA4: 0 | AB4: 0 | AC4: 0
E5: Saturday | F5: =F4 -> 0 | G5: =G4 -> 0 | H5: =H4 -> 0 | I5: =I4 -> 0 | J5: =J4 -> 0 | K5: =K4 -> 0.15 | L5: =L4 -> 0.7 | M5: =M4 -> 0.9 | ... AC5: =AC4 -> 0
E6: Sunday | F6: 0 | G6: 0 | H6: 0 | I6: 0 | J6: 0 | K6: 0 | L6: 0 | M6: 0 | N6: 0 | O6: 0 | P6: 0 | Q6: 0 | R6: 0 | S6: 0 | T6: 0 | U6: 0 | V6: 0 | W6: 0 | X6: 0 | Y6: 0 | Z6: 0 | AA6: 0 | AB6: 0 | AC6: 0
A7: =A4 -> Fine storage | B7: =B4 -> FineStorage | C7: Lights | D7: T24 2022 - Appendix 5.4B, [Warehouse] (Start and end hours of weekday schedule has been shifted to stay align with the plug load project with CEC) with Saturday Occupied. | E7: Weekday | F7: 0.05 | G7: 0.05 | H7: 0.05 | I7: 0.05 | J7: 0.05 | K7: 0.45 | L7: 0.55 | M7: 0.55 | N7: 0.55 | O7: 0.55 | P7: 0.55 | Q7: 0.55 | R7: 0.55 | S7: 0.55 | T7: 0.55 | U7: 0.55 | V7: 0.3 | W7: 0.05 | X7: 0.05 | Y7: 0.05 | Z7: 0.05 | AA7: 0.05 | AB7: 0.05 | AC7: 0.05
E8: Saturday | F8: =F7 -> 0.05 | G8: =G7 -> 0.05 | H8: =H7 -> 0.05 | I8: =I7 -> 0.05 | J8: =J7 -> 0.05 | K8: =K7 -> 0.45 | L8: =L7 -> 0.55 | M8: =M7 -> 0.55 | ... AC8: =AC7 -> 0.05
E9: Sunday | F9: 0.05 | G9: 0.05 | H9: 0.05 | I9: 0.05 | J9: 0.05 | K9: 0.05 | L9: 0.05 | M9: 0.05 | N9: 0.05 | O9: 0.05 | P9: 0.05 | Q9: 0.05 | R9: 0.05 | S9: 0.05 | T9: 0.05 | U9: 0.05 | V9: 0.05 | W9: 0.05 | X9: 0.05 | Y9: 0.05 | Z9: 0.05 | AA9: 0.05 | AB9: 0.05 | AC9: 0.05
A10: =A4 -> Fine storage | B10: =B4 -> FineStorage | C10: ElecEquipment | D10: Plug load and schedules project with CEC, 2025 (weekday) *New weekday schedule starts at 6 and ends at 17 instead of 8-18 in the Appendix 5.4B with Saturday Occupied. T24 2022 - Appendix 5.4B (weekend) | E10: Weekday | F10: 0.05 | G10: 0.05 | H10: 0.05 | I10: 0.05 | J10: 0.05 | K10: 0.5 | L10: 0.9 | M10: 0.9 | N10: 0.9 | O10: 0.9 | P10: 0.9 | Q10: 0.9 | R10: 0.9 | S10: 0.9 | T10: 0.9 | U10: 0.65 | V10: 0.25 | W10: 0.05 | X10: 0.05 | Y10: 0.05 | Z10: 0.05 | AA10: 0.05 | AB10: 0.05 | AC10: 0.05
E11: Saturday | F11: =F10 -> 0.05 | G11: =G10 -> 0.05 | H11: =H10 -> 0.05 | I11: =I10 -> 0.05 | J11: =J10 -> 0.05 | K11: =K10 -> 0.5 | L11: =L10 -> 0.9 | M11: =M10 -> 0.9 | ... AC11: =AC10 -> 0.05
E12: Sunday | F12: 0.05 | G12: 0.05 | H12: 0.05 | I12: 0.05 | J12: 0.05 | K12: 0.05 | L12: 0.05 | M12: 0.05 | N12: 0.05 | O12: 0.05 | P12: 0.05 | Q12: 0.05 | R12: 0.05 | S12: 0.05 | T12: 0.05 | U12: 0.05 | V12: 0.05 | W12: 0.05 | X12: 0.05 | Y12: 0.05 | Z12: 0.05 | AA12: 0.05 | AB12: 0.05 | AC12: 0.05
A13: =A4 -> Fine storage | B13: =B4 -> FineStorage | C13: HVACAvail | D13: T24 2022 - Appendix 5.4B, [Warehouse] (Start and end hours of weekday schedule has been shifted to stay align with the plug load project with CEC) with Saturday Occupied. | E13: Weekday | F13: 0 | G13: 0 | H13: 0 | I13: 0 | J13: 1 | K13: 1 | L13: 1 | M13: 1 | N13: 1 | O13: 1 | P13: 1 | Q13: 1 | R13: 1 | S13: 1 | T13: 1 | U13: 1 | V13: 0 | W13: 0 | X13: 0 | Y13: 0 | Z13: 0 | AA13: 0 | AB13: 0 | AC13: 0
E14: Saturday | F14: =F13 -> 0 | G14: =G13 -> 0 | H14: =H13 -> 0 | I14: =I13 -> 0 | J14: =J13 -> 1 | K14: =K13 -> 1 | L14: =L13 -> 1 | M14: =M13 -> 1 | ... AC14: =AC13 -> 0
E15: Sunday | F15: 0 | G15: 0 | H15: 0 | I15: 0 | J15: 0 | K15: 0 | L15: 0 | M15: 0 | N15: 0 | O15: 0 | P15: 0 | Q15: 0 | R15: 0 | S15: 0 | T15: 0 | U15: 0 | V15: 0 | W15: 0 | X15: 0 | Y15: 0 | Z15: 0 | AA15: 0 | AB15: 0 | AC15: 0
A16: =A4 -> Fine storage | B16: =B4 -> FineStorage | C16: ServiceHotWater | D16: T24 2022 - Appendix 5.4B, [Warehouse] (Start and end hours of weekday schedule has been shifted to stay align with the plug load project with CEC) with Saturday Occupied. | E16: Weekday | F16: 0.02 | G16: 0.02 | H16: 0.02 | I16: 0.05 | J16: 0.07 | K16: 0.1 | L16: 0.3 | M16: 0.36 | N16: 0.36 | O16: 0.36 | P16: 0.36 | Q16: 0.46 | R16: 0.57 | S16: 0.43 | T16: 0.4 | U16: 0.3 | V16: 0.18 | W16: 0.18 | X16: 0.03 | Y16: 0.03 | Z16: 0.03 | AA16: 0.03 | AB16: 0.03 | AC16: 0.03
E17: Saturday | F17: =F16 -> 0.02 | G17: =G16 -> 0.02 | H17: =H16 -> 0.02 | I17: =I16 -> 0.05 | J17: =J16 -> 0.07 | K17: =K16 -> 0.1 | L17: =L16 -> 0.3 | M17: =M16 -> 0.36 | ... AC17: =AC16 -> 0.03
E18: Sunday | F18: 0.02 | G18: 0.02 | H18: 0.02 | I18: 0.02 | J18: 0.02 | K18: 0.02 | L18: 0.02 | M18: 0.02 | N18: 0.02 | O18: 0.02 | P18: 0.02 | Q18: 0.02 | R18: 0.04 | S18: 0.04 | T18: 0.02 | U18: 0.02 | V18: 0.02 | W18: 0.02 | X18: 0.02 | Y18: 0.02 | Z18: 0.02 | AA18: 0.02 | AB18: 0.02 | AC18: 0.02
A19: =A4 -> Fine storage | B19: =B4 -> FineStorage | C19: Infiltration | E19: Weekday | F19: 1 | G19: 1 | H19: 1 | I19: 1 | J19: 1 | K19: 1 | L19: 1 | M19: 1 | N19: 1 | O19: 1 | P19: 1 | Q19: 1 | R19: 1 | S19: 1 | T19: 1 | U19: 1 | V19: 1 | W19: 1 | X19: 1 | Y19: 1 | Z19: 1 | AA19: 1 | AB19: 1 | AC19: 1
E20: Saturday | F20: 1 | G20: 1 | H20: 1 | I20: 1 | J20: 1 | K20: 1 | L20: 1 | M20: 1 | N20: 1 | O20: 1 | P20: 1 | Q20: 1 | R20: 1 | S20: 1 | T20: 1 | U20: 1 | V20: 1 | W20: 1 | X20: 1 | Y20: 1 | Z20: 1 | AA20: 1 | AB20: 1 | AC20: 1
E21: Sunday | F21: 1 | G21: 1 | H21: 1 | I21: 1 | J21: 1 | K21: 1 | L21: 1 | M21: 1 | N21: 1 | O21: 1 | P21: 1 | Q21: 1 | R21: 1 | S21: 1 | T21: 1 | U21: 1 | V21: 1 | W21: 1 | X21: 1 | Y21: 1 | Z21: 1 | AA21: 1 | AB21: 1 | AC21: 1
A22: =A4 -> Fine storage | B22: =B4 -> FineStorage | C22: HtgSetpt | D22: T24 2022 - Appendix 5.4B, [Warehouse] with Saturday Occupied. | E22: Weekday | F22: =IF(F13=1,Thermostat!$C$7,Thermostat!$C$8) -> 60 | G22: =IF(G13=1,Thermostat!$C$7,Thermostat!$C$8) -> 60 | H22: =IF(H13=1,Thermostat!$C$7,Thermostat!$C$8) -> 60 | I22: =IF(I13=1,Thermostat!$C$7,Thermostat!$C$8) -> 60 | J22: =IF(J13=1,Thermostat!$C$7,Thermostat!$C$8) -> 70 | K22: =IF(K13=1,Thermostat!$C$7,Thermostat!$C$8) -> 70 | L22: =IF(L13=1,Thermostat!$C$7,Thermostat!$C$8) -> 70 | M22: =IF(M13=1,Thermostat!$C$7,Thermostat!$C$8) -> 70 | ... AC22: =IF(AC13=1,Thermostat!$C$7,Thermostat!$C$8) -> 60
E23: Saturday | F23: =IF(F14=1,Thermostat!$C$7,Thermostat!$C$8) -> 60 | G23: =IF(G14=1,Thermostat!$C$7,Thermostat!$C$8) -> 60 | H23: =IF(H14=1,Thermostat!$C$7,Thermostat!$C$8) -> 60 | I23: =IF(I14=1,Thermostat!$C$7,Thermostat!$C$8) -> 60 | J23: =IF(J14=1,Thermostat!$C$7,Thermostat!$C$8) -> 70 | K23: =IF(K14=1,Thermostat!$C$7,Thermostat!$C$8) -> 70 | L23: =IF(L14=1,Thermostat!$C$7,Thermostat!$C$8) -> 70 | M23: =IF(M14=1,Thermostat!$C$7,Thermostat!$C$8) -> 70 | ... AC23: =IF(AC14=1,Thermostat!$C$7,Thermostat!$C$8) -> 60
E24: Sunday | F24: =IF(F15=1,Thermostat!$C$7,Thermostat!$C$8) -> 60 | G24: =IF(G15=1,Thermostat!$C$7,Thermostat!$C$8) -> 60 | H24: =IF(H15=1,Thermostat!$C$7,Thermostat!$C$8) -> 60 | I24: =IF(I15=1,Thermostat!$C$7,Thermostat!$C$8) -> 60 | J24: =IF(J15=1,Thermostat!$C$7,Thermostat!$C$8) -> 60 | K24: =IF(K15=1,Thermostat!$C$7,Thermostat!$C$8) -> 60 | L24: =IF(L15=1,Thermostat!$C$7,Thermostat!$C$8) -> 60 | M24: =IF(M15=1,Thermostat!$C$7,Thermostat!$C$8) -> 60 | ... AC24: =IF(AC15=1,Thermostat!$C$7,Thermostat!$C$8) -> 60
A25: =A4 -> Fine storage | B25: =B4 -> FineStorage | C25: ClgSetpt | D25: T24 2022 - Appendix 5.4B, [Warehouse] with Saturday Occupied. | E25: Weekday | F25: =IF(F13=1,Thermostat!$C$9,Thermostat!$C$10) -> 85 | G25: =IF(G13=1,Thermostat!$C$9,Thermostat!$C$10) -> 85 | H25: =IF(H13=1,Thermostat!$C$9,Thermostat!$C$10) -> 85 | I25: =IF(I13=1,Thermostat!$C$9,Thermostat!$C$10) -> 85 | J25: =IF(J13=1,Thermostat!$C$9,Thermostat!$C$10) -> 75 | K25: =IF(K13=1,Thermostat!$C$9,Thermostat!$C$10) -> 75 | L25: =IF(L13=1,Thermostat!$C$9,Thermostat!$C$10) -> 75 | M25: =IF(M13=1,Thermostat!$C$9,Thermostat!$C$10) -> 75 | ... AC25: =IF(AC13=1,Thermostat!$C$9,Thermostat!$C$10) -> 85
E26: Saturday | F26: =IF(F14=1,Thermostat!$C$9,Thermostat!$C$10) -> 85 | G26: =IF(G14=1,Thermostat!$C$9,Thermostat!$C$10) -> 85 | H26: =IF(H14=1,Thermostat!$C$9,Thermostat!$C$10) -> 85 | I26: =IF(I14=1,Thermostat!$C$9,Thermostat!$C$10) -> 85 | J26: =IF(J14=1,Thermostat!$C$9,Thermostat!$C$10) -> 75 | K26: =IF(K14=1,Thermostat!$C$9,Thermostat!$C$10) -> 75 | L26: =IF(L14=1,Thermostat!$C$9,Thermostat!$C$10) -> 75 | M26: =IF(M14=1,Thermostat!$C$9,Thermostat!$C$10) -> 75 | ... AC26: =IF(AC14=1,Thermostat!$C$9,Thermostat!$C$10) -> 85
E27: Sunday | F27: =IF(F15=1,Thermostat!$C$9,Thermostat!$C$10) -> 85 | G27: =IF(G15=1,Thermostat!$C$9,Thermostat!$C$10) -> 85 | H27: =IF(H15=1,Thermostat!$C$9,Thermostat!$C$10) -> 85 | I27: =IF(I15=1,Thermostat!$C$9,Thermostat!$C$10) -> 85 | J27: =IF(J15=1,Thermostat!$C$9,Thermostat!$C$10) -> 85 | K27: =IF(K15=1,Thermostat!$C$9,Thermostat!$C$10) -> 85 | L27: =IF(L15=1,Thermostat!$C$9,Thermostat!$C$10) -> 85 | M27: =IF(M15=1,Thermostat!$C$9,Thermostat!$C$10) -> 85 | ... AC27: =IF(AC15=1,Thermostat!$C$9,Thermostat!$C$10) -> 85
A28: BulkStorage
A29: Bulk storage | B29: BulkStorage | C29: Occupancy | D29: T24 2022 - Appendix 5.4B, [Warehouse] (Start and end hours of weekday schedule has been shifted to stay align with the plug load project with CEC) with Saturday Occupied. | E29: Weekday | F29: 0 | G29: 0 | H29: 0 | I29: 0 | J29: 0 | K29: 0.15 | L29: 0.7 | M29: 0.9 | N29: 0.9 | O29: 0.9 | P29: 0.9 | Q29: 0.9 | R29: 0.5 | S29: 0.85 | T29: 0.85 | U29: 0.2 | V29: 0 | W29: 0 | X29: 0 | Y29: 0 | Z29: 0 | AA29: 0 | AB29: 0 | AC29: 0
E30: Saturday | F30: 0 | G30: 0 | H30: 0 | I30: 0 | J30: 0 | K30: 0.15 | L30: 0.7 | M30: 0.9 | N30: 0.9 | O30: 0.9 | P30: 0.9 | Q30: 0.9 | R30: 0.5 | S30: 0.85 | T30: 0.85 | U30: 0.2 | V30: 0 | W30: 0 | X30: 0 | Y30: 0 | Z30: 0 | AA30: 0 | AB30: 0 | AC30: 0
E31: Sunday | F31: 0 | G31: 0 | H31: 0 | I31: 0 | J31: 0 | K31: 0 | L31: 0 | M31: 0 | N31: 0 | O31: 0 | P31: 0 | Q31: 0 | R31: 0 | S31: 0 | T31: 0 | U31: 0 | V31: 0 | W31: 0 | X31: 0 | Y31: 0 | Z31: 0 | AA31: 0 | AB31: 0 | AC31: 0
A32: =A29 -> Bulk storage | B32: =B29 -> BulkStorage | C32: Lights | D32: T24 2022 - Appendix 5.4B, [Warehouse] (Start and end hours of weekday schedule has been shifted to stay align with the plug load project with CEC) with Saturday Occupied. | E32: Weekday | F32: 0.05 | G32: 0.05 | H32: 0.05 | I32: 0.05 | J32: 0.05 | K32: 0.45 | L32: 0.55 | M32: 0.55 | N32: 0.55 | O32: 0.55 | P32: 0.55 | Q32: 0.55 | R32: 0.55 | S32: 0.55 | T32: 0.55 | U32: 0.55 | V32: 0.3 | W32: 0.05 | X32: 0.05 | Y32: 0.05 | Z32: 0.05 | AA32: 0.05 | AB32: 0.05 | AC32: 0.05
E33: Saturday | F33: 0.05 | G33: 0.05 | H33: 0.05 | I33: 0.05 | J33: 0.05 | K33: 0.45 | L33: 0.55 | M33: 0.55 | N33: 0.55 | O33: 0.55 | P33: 0.55 | Q33: 0.55 | R33: 0.55 | S33: 0.55 | T33: 0.55 | U33: 0.55 | V33: 0.3 | W33: 0.05 | X33: 0.05 | Y33: 0.05 | Z33: 0.05 | AA33: 0.05 | AB33: 0.05 | AC33: 0.05
E34: Sunday | F34: 0.05 | G34: 0.05 | H34: 0.05 | I34: 0.05 | J34: 0.05 | K34: 0.05 | L34: 0.05 | M34: 0.05 | N34: 0.05 | O34: 0.05 | P34: 0.05 | Q34: 0.05 | R34: 0.05 | S34: 0.05 | T34: 0.05 | U34: 0.05 | V34: 0.05 | W34: 0.05 | X34: 0.05 | Y34: 0.05 | Z34: 0.05 | AA34: 0.05 | AB34: 0.05 | AC34: 0.05
A35: =A29 -> Bulk storage | B35: =B29 -> BulkStorage | C35: ElecEquipment | D35: Plug load and schedules project with CEC, 2025 (weekday) *New weekday schedule starts at 6 and ends at 17 instead of 8-18 in the Appendix 5.4B with Saturday Occupied. T24 2022 - Appendix 5.4B (Sunday) | E35: Weekday | F35: 0.05 | G35: 0.05 | H35: 0.05 | I35: 0.05 | J35: 0.05 | K35: 0.5 | L35: 0.9 | M35: 0.9 | N35: 0.9 | O35: 0.9 | P35: 0.9 | Q35: 0.9 | R35: 0.9 | S35: 0.9 | T35: 0.9 | U35: 0.65 | V35: 0.25 | W35: 0.05 | X35: 0.05 | Y35: 0.05 | Z35: 0.05 | AA35: 0.05 | AB35: 0.05 | AC35: 0.05
E36: Saturday | F36: 0.05 | G36: 0.05 | H36: 0.05 | I36: 0.05 | J36: 0.05 | K36: 0.5 | L36: 0.9 | M36: 0.9 | N36: 0.9 | O36: 0.9 | P36: 0.9 | Q36: 0.9 | R36: 0.9 | S36: 0.9 | T36: 0.9 | U36: 0.65 | V36: 0.25 | W36: 0.05 | X36: 0.05 | Y36: 0.05 | Z36: 0.05 | AA36: 0.05 | AB36: 0.05 | AC36: 0.05
E37: Sunday | F37: 0.05 | G37: 0.05 | H37: 0.05 | I37: 0.05 | J37: 0.05 | K37: 0.05 | L37: 0.05 | M37: 0.05 | N37: 0.05 | O37: 0.05 | P37: 0.05 | Q37: 0.05 | R37: 0.05 | S37: 0.05 | T37: 0.05 | U37: 0.05 | V37: 0.05 | W37: 0.05 | X37: 0.05 | Y37: 0.05 | Z37: 0.05 | AA37: 0.05 | AB37: 0.05 | AC37: 0.05
A38: =A29 -> Bulk storage | B38: =B29 -> BulkStorage | C38: HVACAvail | D38: Developed based on Unit Heater | E38: Weekday | F38: 1 | G38: 1 | H38: 1 | I38: 1 | J38: 1 | K38: 1 | L38: 1 | M38: 1 | N38: 1 | O38: 1 | P38: 1 | Q38: 1 | R38: 1 | S38: 1 | T38: 1 | U38: 1 | V38: 1 | W38: 1 | X38: 1 | Y38: 1 | Z38: 1 | AA38: 1 | AB38: 1 | AC38: 1
E39: Saturday | F39: 1 | G39: 1 | H39: 1 | I39: 1 | J39: 1 | K39: 1 | L39: 1 | M39: 1 | N39: 1 | O39: 1 | P39: 1 | Q39: 1 | R39: 1 | S39: 1 | T39: 1 | U39: 1 | V39: 1 | W39: 1 | X39: 1 | Y39: 1 | Z39: 1 | AA39: 1 | AB39: 1 | AC39: 1
